Workbook
Name jop: #REF!
Name kol: #REF!
Name RISKTOTASS: SUM('[6]Calculation of Risk Weighted As'!$C$38:$F$38)
Name RISKTOTASS: SUM('[7]Calculation of Risk Weighted As'!$C$41:$G$41)
Name TwentyLargestData: #REF!
Name Е: #REF!

Sheet Asset quality
A1: АКТИВЛАР ТАСНИФИ ВА УЛАР БЎЙИЧА ЯРАТИЛГАН ЭҲТИМОЛИЙ ЙЎҚОТИШЛАРНИ ҚОПЛАШ ЗАХИРАЛАРИ ТЎҒРИСИДА ҲИСОБОТ | S1: 2-жадвал | V1: №1
B3: "MKBANK" | Q3: 45289 | T3: минг. сўмда
A4: № | B4: Активлар таркиби* | C4: Қолдиқ | D4: Сифат тоифаси | I4: Муддати ўтган қарздорлик (брутто) | O4: Зарарларни қоплаш захираси
I5: Жами | J5: 30 кунгача | K5: 31дан 90 кунгача | L5: 91дан 180 кунгача | M5: 181 дан 365 кунгача | N5: 366 кун ва ундан ортиқ | O5: ҳақиқатдан яратилган захиралар
O6: Жами | P6: сифат тоифаси бўйича
D7: I | E7: II | F7: III | G7: IV | H7: V | P7: I | Q7: II | R7: III | S7: IV | T7: V
A8: А | B8: Б | C8: В | D8: Г | E8: Д | F8: Е | G8: Ж | H8: З | I8: И | J8: К | K8: Л | L8: М | M8: Н | N8: О | O8: П | P8: Р | Q8: С | R8: Т | S8: У | T8: Ф
B9: Жами активлар | C9: =SUM(C10:C58)+C60-C59 -> 19061519219 | D9: =SUM(D10:D58)-D59+D60 -> 14896225607 | E9: =SUM(E10:E58)-E59+E60 -> 3532847141 | F9: =SUM(F10:F58)-F59+F60 -> 102373443 | G9: =SUM(G10:G58)-G59+G60 -> 237587084 | H9: =SUM(H10:H58)-H59+H60 -> 525217870 | I9: =SUM(I10:I60) -> 1.1508243e+09 | J9: =SUM(J10:J60) -> 68401026 | K9: =SUM(K10:K60) -> 1.8925848e+08 | L9: =SUM(L10:L60) -> 3.4506088e+08 | M9: =SUM(M10:M60) -> 1.19695e+08 | N9: =SUM(N10:N60) -> 4.2840896e+08 | O9: =SUM(O10:O60) -> 232731926 | P9: =SUM(P10:P60) -> 0 | ... T9: =SUM(T10:T60) -> 103010246
A10: 1 | B10: Кассадаги нақд пул ва бошқа тўлов ҳужжатлари | C10: =SUM(D10:H10)-O10+P10 -> 722231783 | D10: 722231783 | I10: =SUM(J10:N10) -> 0 | O10: =SUM(P10:T10) -> 0 | U10: 10100
A11: 2 | B11: Банкнинг Марказий банкдаги маблағлар | C11: =SUM(D11:H11)-O11+P11 -> 307687193 | D11: 307687193 | I11: =SUM(J11:N11) -> 0 | O11: =SUM(P11:T11) -> 0 | U11: 10300
A12: 3 | B12: Бошқа банклар ва молиявий ташкилотлардан олиниши лозим бўлган маблағлар | C12: =SUM(D12:H12)-O12+P12 -> 1069350609 | D12: 1069350609 | I12: =SUM(J12:N12) -> 0 | O12: =SUM(P12:T12) -> 0 | U12: 10500
A13: 4 | B13: Фойда ёки зарар орқали ҳаққоний қийматда баҳоланадиган қимматли қоғозлар | C13: =SUM(D13:H13)-O13+P13 -> 0 | D13: 0 | I13: =SUM(J13:N13) -> 0 | O13: =SUM(P13:T13) -> 0 | U13: 10700
A14: 5 | B14: Бошқа умумлашган даромад орқали ҳаққоний қийматда баҳоланадиган қимматли қоғозларга қилинган инвестициялар | C14: =SUM(D14:H14)-O14+P14 -> 10000000 | D14: 10000000 | I14: =SUM(J14:N14) -> 0 | O14: =SUM(P14:T14) -> 0 | U14: 10800
A15: 6 | B15: Олди-сотдига мўлжалланган қимматбаҳо металлар, тошлар ва тангалар | C15: =SUM(D15:H15)-O15+P15 -> 175 | D15: 175 | I15: =SUM(J15:N15) -> 0 | O15: =SUM(P15:T15) -> 0 | U15: 10900
A16: 7 | B16: Сотиб олинган дебиторлик қарзлари — Факторинг | C16: =SUM(D16:H16)-O16+P16 -> 0 | D16: 0 | E16: 0 | F16: 0 | G16: 0 | H16: 188313 | I16: =SUM(J16:N16) -> 188313.39 | J16: 0 | K16: 0 | L16: 0 | M16: 0 | N16: 188313.39 | O16: =SUM(P16:T16) -> 188313 | P16: 0 | Q16: 0 | R16: 0 | S16: 0 | T16: 188313 | U16: 11100
A17: 8 | B17: Мижозларнинг аккредитив ва/ёки траст ҳужжатлари билан кафолатланган тратталари бўйича мажбуриятлари | C17: =SUM(D17:H17)-O17+P17 -> 0 | I17: =SUM(J17:N17) -> 0 | O17: =SUM(P17:T17) -> 0 | U17: 11500
A18: 9 | B18: Банкнинг тўланмаган акцептлари бўйича мижозларнинг мажбуриятлари | C18: =SUM(D18:H18)-O18+P18 -> 0 | I18: =SUM(J18:N18) -> 0 | O18: =SUM(P18:T18) -> 0 | U18: 11700
A19: 10 | B19: РЕПО битимлари бўйича сотиб олинган қимматли қоғозлар | C19: =SUM(D19:H19)-O19+P19 -> 0 | I19: =SUM(J19:N19) -> 0 | O19: =SUM(P19:T19) -> 0 | U19: 11800
A20: 11 | B20: Марказий банкка берилган қисқа муддатли кредитлар | C20: =SUM(D20:H20)-O20+P20 -> 0 | I20: =SUM(J20:N20) -> 0 | O20: =SUM(P20:T20) -> 0 | U20: 11900
A21: 12 | B21: Бошқа банкларга берилган қисқа муддатли кредитлар | C21: =SUM(D21:H21)-O21+P21 -> 0 | I21: =SUM(J21:N21) -> 0 | O21: =SUM(P21:T21) -> 0 | U21: 12100
A22: 13 | B22: Ҳукуматга берилган қисқа муддатли кредитлар | C22: =SUM(D22:H22)-O22+P22 -> 0 | I22: =SUM(J22:N22) -> 0 | O22: =SUM(P22:T22) -> 0 | U22: 12300
A23: 14 | B23: Бюджет ташкилотларига берилган қисқа муддатли кредитлар | C23: =SUM(D23:H23)-O23+P23 -> 0 | I23: =SUM(J23:N23) -> 0 | O23: =SUM(P23:T23) -> 0 | U23: 12400
A24: 15 | B24: Жисмоний шахсларга берилган қисқа муддатли кредитлар | C24: =SUM(D24:H24)-O24+P24 -> 425176266 | D24: 412878943 | E24: 8233005 | F24: 812628 | G24: 600797 | H24: 4867251 | I24: =SUM(J24:N24) -> 9222923.7 | J24: 614966.23 | K24: 1577800.4 | L24: 2676034.7 | M24: 1533693.3 | N24: 2820429 | O24: =SUM(P24:T24) -> 2216358 | Q24: 0 | R24: 78616 | S24: 103414 | T24: 2034328 | U24: 12500
A25: 16 | B25: Якка тартибдаги тадбиркорларга берилган қисқа муддатли кредитлар | C25: =SUM(D25:H25)-O25+P25 -> 58493535 | D25: 58046354 | E25: 566231 | F25: 4821 | G25: 0 | H25: 530788 | I25: =SUM(J25:N25) -> 977242.75 | J25: 27635.768 | K25: 136860.09 | L25: 142936.23 | M25: 24051.19 | N25: 645759.47 | O25: =SUM(P25:T25) -> 654659 | P25: 0 | Q25: 127187 | R25: 650 | S25: 0 | T25: 526822 | U25: 12600
A26: 17 | B26: Давлат корхоналари, ташкилотлари ва муассасаларига берилган қисқа муддатли кредитлар | C26: =SUM(D26:H26)-O26+P26 -> 65476564 | D26: 65129467 | E26: 372934 | F26: 0 | G26: 0 | H26: 160630 | I26: =SUM(J26:N26) -> 695115.15 | J26: 322180.71 | K26: 0 | L26: 372934.44 | M26: 0 | N26: 0 | O26: =SUM(P26:T26) -> 186467 | P26: 0 | Q26: 25837 | R26: 0 | S26: 0 | T26: 160630 | U26: 12700
A27: 18 | B27: Тадбиркорлик фаолиятини қўллаб-қувватлаш давлат жамғармаси кўмагида берилган қисқа муддатли кредитлар | C27: =SUM(D27:H27)-O27+P27 -> 0 | I27: =SUM(J27:N27) -> 0 | O27: =SUM(P27:T27) -> 0 | U27: 12800
A28: 19 | B28: Чет эл капитали иштирокидаги корхоналарга берилган қисқа муддатли кредитлар | C28: =SUM(D28:H28)-O28+P28 -> 79896470 | D28: 17234047 | E28: 69624915 | F28: 0 | G28: 0 | H28: 0 | I28: =SUM(J28:N28) -> 34812458 | J28: 0 | K28: 34812458 | L28: 0 | M28: 0 | N28: 0 | O28: =SUM(P28:T28) -> 6962492 | P28: 0 | Q28: 6962492 | R28: 0 | S28: 0 | T28: 0 | U28: 12900
A29: 20 | B29: Нодавлат нотижорат ташкилотларига берилган қисқа муддатли кредитлар | C29: =SUM(D29:H29)-O29+P29 -> 7852 | D29: 7852 | E29: 0 | F29: 0 | G29: 0 | H29: 0 | I29: =SUM(J29:N29) -> 0 | O29: =SUM(P29:T29) -> 0 | P29: 0 | Q29: 0 | R29: 0 | S29: 0 | T29: 0 | U29: 13000
A30: 21 | B30: Хусусий корхоналар, хўжалик ширкатлари ва жамиятларга берилган қисқа муддатли кредитлар | C30: =SUM(D30:H30)-O30+P30 -> 920456713 | D30: 755509507 | E30: 166440486 | F30: 402455 | G30: 327356 | H30: 25190542 | I30: =SUM(J30:N30) -> 1.4392598e+08 | J30: 40474767 | K30: 17150279 | L30: 24795502 | M30: 30977563 | N30: 30527873 | O30: =SUM(P30:T30) -> 27413633 | Q30: 4247993 | R30: 0 | S30: 31519 | T30: 23134121 | U30: 13100
A31: 22 | B31: Банк бўлмаган молиявий муассасаларга берилган қисқа муддатли кредитлар | C31: =SUM(D31:H31)-O31+P31 -> 0 | I31: =SUM(J31:N31) -> 0 | O31: =SUM(P31:T31) -> 0 | U31: 13200
A32: 23 | B32: Давлат эҳтиёжлари учун харид қилинадиган қишлоқ хўжалиги маҳсулотларини етиштириш учун берилган қисқа муддатли кредитлар | C32: =SUM(D32:H32)-O32+P32 -> 0 | I32: =SUM(J32:N32) -> 0 | O32: =SUM(P32:T32) -> 0 | U32: 13300
A33: 24 | B33: Давлат эҳтиёжлари учун харид қилинадиган қишлоқ хўжалиги маҳсулотларини етиштириш учун берилган узоқ муддатли кредитлар | C33: =SUM(D33:H33)-O33+P33 -> 0 | I33: =SUM(J33:N33) -> 0 | O33: =SUM(P33:T33) -> 0 | U33: 14300
A34: 25 | B34: Тадбиркорлик фаолиятини қўллаб-қувватлаш давлат жамғармаси кўмагида берилган узоқ муддатли кредитлар | C34: =SUM(D34:H34)-O34+P34 -> 123032250 | D34: 92009867 | E34: 34340214 | F34: 0 | G34: 0 | H34: 1302169 | I34: =SUM(J34:N34) -> 9170690.8 | J34: 331867.08 | K34: 805452 | L34: 2456847.4 | M34: 0 | N34: 5576524.3 | O34: =SUM(P34:T34) -> 4620000 | Q34: 4620000 | R34: 0 | S34: 0 | T34: 0 | U34: 14400
A35: 26 | B35: Бошқа банкларга берилган узоқ муддатли кредитлар | C35: =SUM(D35:H35)-O35+P35 -> 0 | I35: =SUM(J35:N35) -> 0 | O35: =SUM(P35:T35) -> 0 | U35: 14500
A36: 27 | B36: Ҳукуматга берилган узоқ муддатли кредитлар | C36: =SUM(D36:H36)-O36+P36 -> 0 | I36: =SUM(J36:N36) -> 0 | O36: =SUM(P36:T36) -> 0 | U36: 14700
A37: 28 | B37: Бюджет ташкилотларига берилган узоқ муддатли кредитлар | C37: =SUM(D37:H37)-O37+P37 -> 0 | I37: =SUM(J37:N37) -> 0 | O37: =SUM(P37:T37) -> 0 | U37: 14800
A38: 29 | B38: Жисмоний шахсларга берилган узоқ муддатли кредитлар | C38: =SUM(D38:H38)-O38+P38 -> 4857087022 | D38: 3653185804 | E38: 854918773 | F38: 87962499 | G38: 194591739 | H38: 119676221 | I38: =SUM(J38:N38) -> 3.5510053e+08 | J38: 9211463.4 | K38: 43737031 | L38: 1.2488588e+08 | M38: 28171152 | N38: 1.4909501e+08 | O38: =SUM(P38:T38) -> 53248014 | Q38: 25961664 | R38: 1411187 | S38: 10581755 | T38: 15293408 | U38: 14900
A39: 30 | B39: Якка тартибдаги тадбиркорларга берилган узоқ муддатли кредитлар | C39: =SUM(D39:H39)-O39+P39 -> 105193961 | D39: 36246760 | E39: 64616688 | F39: 3434982 | G39: 7406493 | H39: 3710752 | I39: =SUM(J39:N39) -> 47356782 | J39: 407695.25 | K39: 3175984.6 | L39: 4888103.1 | M39: 1266102.5 | N39: 37618896 | O39: =SUM(P39:T39) -> 10221714 | P39: 0 | Q39: 8772407 | R39: 36649 | S39: 694225 | T39: 718433 | U39: 15000
A40: 31 | B40: Давлат корхоналари, ташкилотлари ва муассасаларига берилган узоқ муддатли кредитлар | C40: =SUM(D40:H40)-O40+P40 -> 75404162 | D40: 54547769 | E40: 20472399 | F40: 0 | G40: 0 | H40: 383994 | I40: =SUM(J40:N40) -> 5926832.1 | J40: 0 | K40: 579612.4 | L40: 199408.52 | M40: 5147811.2 | N40: 0 | O40: =SUM(P40:T40) -> 0 | U40: 15100
A41: 32 | B41: Нодавлат нотижорат ташкилотларига берилган узоқ муддатли кредитлар | C41: =SUM(D41:H41)-O41+P41 -> 5139565 | D41: 5046825 | E41: 92740 | F41: 0 | G41: 0 | H41: 0 | I41: =SUM(J41:N41) -> 6245.7815 | J41: 1463.9969 | K41: 4781.7846 | L41: 0 | M41: 0 | N41: 0 | O41: =SUM(P41:T41) -> 0 | U41: 15200
...

Sheet Income 
A1: МОЛИЯВИЙ НАТИЖАЛАР ТЎҒРИСИДА ҲИСОБОТ | E1: 3-жадвал
B3: =+'Asset quality'!B3 -> "MKBANK" | D3: =+'Asset quality'!Q3 -> 45289 | E3: =+'Asset quality'!T3 -> минг. сўмда
A4: № | B4: Кўрсаткичлар | C4: Жами | D4: миллий валютада | E4: хорижий валютада (экв. сўмда)
A5: 1. | B5: ФОИЗЛИ ДАРОМАДЛАР
A6: a. | B6: Марказий банкдаги ҳисобварақлар бўйича фоизли даромадлар | C6: =+D6+E6 -> 32946849 | D6: 32946849 | E6: 0 | G6: =+'Analysis of Interest'!C17 -> 32946849
A7: б. | B7: Бошқа банклардаги ҳисобварақлар бўйича фоизли даромадлар | C7: =+D7+E7 -> 57718507 | D7: 57718507 | E7: 0 | G7: =+'Analysis of Interest'!C18 -> 57718507
A8: в. | B8: Амортизацияланган қиймати бўйича баҳоланадиган қарз қимматли қоғозларга қилинган инвестициялар бўйича фоизли даромадлар | C8: =+D8+E8 -> 0 | D8: 0 | E8: 0
A9: г. | B9: Қимматли қоғозлар ва уларга қилинган инвестициялар бўйича фоизли даромадлар | C9: =+D9+E9 -> 43218594 | D9: 43218594 | E9: 0 | G9: =+'Analysis of Interest'!C28 -> 43218594
A10: д. | B10: Мижозларнинг мажбуриятлари бўйича ҳисобланган фоизлар | C10: =+D10+E10 -> 0 | D10: 0 | E10: 0
A11: е. | B11: Банкнинг тўланмаган акцептлари юзасидан мижозлар мажбуриятлари бўйича фоизли даромадлар | C11: =+D11+E11 -> 0 | D11: 0 | E11: 0
A12: ж. | B12: Кредит ва лизинг операциялари бўйича фоизлар, дисконтлар (чегирмалар) ва бадаллар | C12: =+D12+E12 -> 2137567249 | D12: 2137567249 | E12: 0 | G12: =+'Analysis of Interest'!C14 -> 2137567249
A13: з. | B13: Қимматли қоғозлар билан амалга оширилган РЕПО битимлари бўйича фоизли даромадлар | C13: =+D13+E13 -> 0 | D13: 0 | E13: 0 | G13: =+'Analysis of Interest'!C39 -> 0
A14: и. | B14: Бошқа фоизли даромадлар | C14: =+D14+E14 -> 948265285 | D14: 948265285 | E14: 0 | G14: =+'Analysis of Interest'!C40 -> 948265285
A15: к. | B15: Жами фоизли даромадлар | C15: =SUM(C6:C14) -> 3219716484 | D15: =SUM(D6:D14) -> 3219716484 | E15: =SUM(E6:E14) -> 0 | G15: =+'Analysis of Interest'!C42 -> 3219716484
A17: 2. | B17: ФОИЗЛИ ХAРAЖAТЛAР
A18: а. | B18: Талаб қилиб олингунча сақланадиган депозитлар бўйича фоизли харажатлар | C18: =+D18+E18 -> 35914220 | D18: 35914220 | E18: 0 | G18: =+'Analysis of Interest'!C52 -> 35914220
A19: б. | B19: Муддатли депозитлар бўйича фоизли харажатлар | C19: =+D19+E19 -> 789793935 | D19: 789793935 | E19: 0 | G19: =+'Analysis of Interest'!C61 -> 789793935
A20: в. | B20: Марказий банкнинг ҳисобварақлари бўйича фоизли харажатлар | C20: =+D20+E20 -> 0 | D20: 0 | E20: 0
A21: г. | B21: Бошқа банкларнинг ҳисобварақлари бўйича фоизли харажатлар | C21: =+D21+E21 -> 240156601 | D21: 240156601 | E21: 0
A22: д. | B22: Жами депозитлар бўйича фоизли харажатлар | C22: =SUM(C18:C21) -> 1065864756 | D22: =SUM(D18:D21) -> 1065864756 | E22: =SUM(E18:E21) -> 0
A23: е. | B23: Кредитлар бўйича фоизли харажатлар | C23: =+D23+E23 -> 511342153 | D23: 511342153 | E23: 0 | G23: =+'Analysis of Interest'!C67 -> 511342153
A24: ж. | B24: Қимматли қоғозлар билан амалга оширилган РЕПО битимлари бўйича фоизли харажатлар | C24: =+D24+E24 -> 0 | D24: 0 | E24: 0 | G24: =+'Analysis of Interest'!C68 -> 0
A25: з. | B25: Бошқа фоизли харажатлар | C25: =+D25+E25 -> 898623953 | D25: 898623953 | E25: 0
A26: и. | B26: Жами кредит ва бошқа қарздорликлар бўйича фоизли харажатлар | C26: =SUM(C23:C25) -> 1409966106 | D26: =SUM(D23:D25) -> 1409966106 | E26: =SUM(E23:E25) -> 0
A27: к. | B27: Жами фоизли харажатлар | C27: =C26+C22 -> 2475830862 | D27: =D26+D22 -> 2475830862 | E27: =E26+E22 -> 0 | G27: =+'Analysis of Interest'!C72 -> 2475830862
A29: 3. | B29: Активлар бўйича эҳтимолий йўқотишларга қарши яратилган захираларни баҳолашдан олдинги соф даромад | C29: =C15-C27 -> 743885622 | D29: =D15-D27 -> 743885622 | E29: =E15-E27 -> 0
A30: а. | B30: Минус: Кредит ва лизинглар бўйича кўрилиши мумкин бўлган зарарларни баҳолаш | C30: =+D30+E30 -> 401409141 | D30: 401409141 | E30: 0
A31: б. | B31: Минус: Қимматли қоғозлар бўйича кўрилиши мумкин бўлган зарарларни баҳолаш | C31: =+D31+E31 -> 0 | D31: 0 | E31: 0
A32: в. | B32: Минус: Инвестициялар бўйича кўрилиши мумкин бўлган зарарларни баҳолаш | C32: =+D32+E32 -> 0 | D32: 0 | E32: 0
A33: г. | B33: Минус: Бошқа активлар бўйича кўрилиши мумкин бўлган зарарларни баҳолаш | C33: =+D33+E33 -> 886772 | D33: 886772 | E33: 0
A34: д. | B34: Активлар бўйича эҳтимолий зарарларни баҳолашдан кейинги соф даромад | C34: =C29-C30-C31-C32-C33 -> 341589709 | D34: =D29-D30-D31-D32-D33 -> 341589709 | E34: =E29-E30-E31-E32-E33 -> 0
A36: 4. | B36: ФОИЗСИЗ ДАРОМАДЛАР
A37: а. | B37: Кўрсатилган хизматлар ва воситачилик учун олинган даромадлар | C37: =+D37+E37 -> 191647281 | D37: 191647281 | E37: 0
A38: б. | B38: Хорижий валюталардаги фойда | C38: =+D38+E38 -> 844239856 | D38: 0 | E38: 844239856
A39: в. | B39: Тижорат операцияларидан олинган фойда | C39: =+D39+E39 -> 0 | D39: 0 | E39: 0
A40: г. | B40: Инвестициядан олинган фойда ва дивидендлар | C40: =+D40+E40 -> 0 | D40: 0 | E40: 0
A41: д. | B41: Активлар бўйича эҳтимолий йўқотишларга қарши яратилган захираларни қайтарилиши | C41: =+D41+E41 -> 365514209 | D41: 365514209 | E41: 0
A42: е. | B42: Ҳисобдан чиқарилган кредитлар қайтарилиши билан боғлиқ даромадлар | C42: =+D42+E42 -> 0 | D42: 0 | E42: 0
A43: ж. | B43: Бошқа фоизсиз даромадлар | C43: =+D43+E43 -> 78128123 | D43: 78128123 | E43: 0
A44: е. | B44: Жами фоизсиз даромадлар | C44: =SUM(C37:C43) -> 1479529469 | D44: =SUM(D37:D43) -> 635289613 | E44: =SUM(E37:E43) -> 844239856
...

Sheet Analysis of Interest
B1: ФОИЗЛИ ДАРОМАД ВА ХАРАЖАТЛАР ТАҲЛИЛИ | C1: 4-жадвал
B3: =+'Asset quality'!B3 -> "MKBANK" | C3: =+'Asset quality'!Q3 -> 45289
A4: № | B4: Кўрсаткичлар | C4: =+'Asset quality'!T3 -> минг. сўмда
A5: 1. | B5: КРЕДИТ ВА ЛИЗИНГ ОПЕРАЦИЯЛАРИ БЎЙИЧА ФОИЗЛИ ДАРОМАДЛАР
A6: a. | B6: Марказий банкка берилган қисқа муддатли кредитлар | C6: 0
A7: б. | B7: Бошқа банкларга берилган кредитлар | C7: 2315
A8: в. | B8: Ҳукуматга берилган кредитлар | C8: 990
A9: г. | B9: Жисмоний шахсларга берилган кредит ва лизинглар | C9: 876925506
A10: д. | B10: Давлат корхоналарига берилган кредит ва лизинглар | C10: 3150180
A11: е. | B11: Қўшма ва чет эл капитали иштирокидаги корхоналарга берилган кредит ва лизинглар | C11: 12799531
A12: ж. | B12: Хусусий корхоналар, хўжалик ширкатлари ва жамиятларга берилган кредит ва лизинглар | C12: 1198466170
A13: з. | B13: Бошқа кредит ва лизинглар | C13: 46222557
A14: и. | B14: Жами кредит ва лизинг операциялари бўйича фоизли даромад | C14: =SUM(C6:C13) -> 2137567249 | E14: =+'Income '!C12 -> 2137567249
A16: 2. | B16: ВАКИЛЛИК ҲИСОБВАРАҚЛАРИ БЎЙИЧА ФОИЗЛИ ДАРОМАДЛАР
A17: a. | B17: Марказий банкдаги ҳисобварақлар бўйича фоизли даромадлар | C17: 32946849 | E17: =+'Income '!C6 -> 32946849
A18: б. | B18: Бошқа банклардаги ҳисобварақлар бўйича фоизли даромадлар | C18: 57718507 | E18: =+'Income '!C7 -> 57718507
B19: Жами вакиллик ҳисобварағи бўйича фоизли даромадлар | C19: =SUM(C17:C18) -> 90665356
A21: 3. | B21: ҚИММАТЛИ ҚОҒОЗЛАР ВА УЛАРГА ҚИЛИНГАН ИНВЕСТИЦИЯЛАР БЎЙИЧА ФОИЗЛИ ДАРОМАДЛАР
A22: a. | B22: Давлат қимматли қоғозлари | C22: 2734099
A23: б. | B23: Марказий банкнинг облигациялари ва бошқа қимматли қоғозлари | C23: 40109700
A24: в. | B24: Давлат корхоналарининг қарз қимматли қоғозлари бўйича фоизли даромадлар | C24: 374795
A25: г. | B25: Еврооблигациялар бўйича фоизли даромадлар | C25: 0
A26: д. | B26: Хусусий корхоналарнинг қимматли қоғозлари | C26: 0
A27: е. | B27: Бошқа қимматли қоғозлар | C27: 0
A28: ж. | B28: Жами олди-сотди қимматли қоғозлар бўйича фоизли даромадлар | C28: =SUM(C22:C27) -> 43218594 | E28: =+'Income '!C9 -> 43218594
A30: 4. | B30: ИНВЕСТИЦИЯЛАР БЎЙИЧА ФОИЗЛИ ДАРОМАДЛАР
A31: a. | B31: Давлат қимматли қоғозлари | C31: 0
A32: б. | B32: Марказий банкнинг облигациялари ва бошқа қарз қимматли қоғозларига қилинган инвестициялар бўйича фоизли даромадлар | C32: 0
A33: в. | B33: Корхоналарнинг қарз қимматли қоғозларига қилинган инвестициялар бўйича фоизли даромадлар | C33: 0
A34: г. | B34: Еврооблигациялар | C34: 0
A35: д. | B35: Бошқа қимматли қоғозлар | C35: 0
A36: е. | B36: Жами инвестициялар бўйича фоизли даромадлар | C36: =SUM(C31:C35) -> 0
A38: 5. | B38: БОШҚА ФОИЗЛИ ДАРОМАДЛАР
A39: a. | B39: Қимматли қоғозлар билан амалга оширилган репо битимлари бўйича фоизли даромадлар | C39: 0
A40: б. | B40: Бошқа фоизли даромадлар | C40: 948265285 | E40: =+'Income '!C14 -> 948265285
A42: 6. | B42: ЖАМИ ФОИЗЛИ ДАРОМАДЛАР | C42: =C14+C19+C28+C36+C39+C40 -> 3219716484 | E42: =+'Income '!C15 -> 3219716484
A44: 7. | B44: ДЕПОЗИТЛАР БЎЙИЧА ФОИЗЛИ ХАРАЖАТЛАР
A45: A. | B45: Талаб қилиб олингунча сақланадиган депозитлар
A46: a. | B46: Ҳукумат | C46: 0
A47: б. | B47: Жисмоний шахслар | C47: 98
...

Sheet Changes in Equity
A1: ХУСУСИЙ КАПИТАЛДАГИ ЎЗГАРИШЛАР | C1: 7-жадвал
B3: =+'Asset quality'!B3 -> "MKBANK" | C3: =+'Asset quality'!Q3 -> 45289
A4: № | B4: Кўрсаткичлар | C4: =+'Asset quality'!T3 -> минг. сўмда
A5: 1. | B5: Ўтган йил учун дастлабки ҳисобланган умумий капитал | C5: 3643911080
A6: 2. | B6: Хусусий капиталдаги ўтган йил учун ҳисоботларда кўрсатилмаган тузатишлар, (соф) | C6: 0
A7: 3. | B7: Ўтган календар йили якуни бўйича балансдаги тузатишлар (3=1-2 ) | C7: =SUM(C5:C6) -> 3643911080
A8: 4. | B8: Йил бошидан соф фойда (зарар) | C8: =+'Income '!C77 -> 41104897 | D8: =+[8]Balance!$C$76 -> 41104897 | E8: =+C8-D8 -> 0
A9: 5. | B9: Жорий йилда сотиш, айирбошлаш, сотиб олиш ёки қайтиб сотиб олиш (соф кирим) | C9: 0
A10: 6. | B10: Жорий йил учун бошланғич қийматига нисбатан баҳолаш қийматининг ошган суммаси | C10: 248593711
A11: 7. | B11: МИНУС: Имтиёзли акциялар бўйича эълон қилинган пул дивидендлари | C11: 0
A12: 8. | B12: МИНУС: Оддий акциялар бўйича эълон қилинган пуллик дивидендлар | C12: -1178075.3
A13: 9. | B13: Жорий йилнинг соф хусусий капиталига таъсир этувчи бошқа моддалар | C13: -1179757.3
A14: 10. | B14: Жорий давр якуни бўйича жами хусусий капитал | C14: =C7+SUM(C8:C10)-SUM(C11:C12)+C13 -> 3933608006 | D14: =+[8]Balance!$C$77 -> 3933608006 | E14: =+C14-D14 -> 0
B16: Бошқарув Раис имзоси:
B18: Бош бухгалтер имзоси:

Sheet Loans Receivable
A1: ИҚТИСОДИЁТ ТАРМОҚЛАРИ, МИЖОЗЛАР ТУРЛАРИ, ВА ТАЪМИНОТ ТУРЛАРИ БЎЙИЧА АЖРАТИЛГАН КРЕДИТЛАР ВА ЛИЗИНГЛАР ҲИСОБОТИ | W1: 8-жадвал
B3: =+'Asset quality'!B3 -> "MKBANK" | T3: =+'Asset quality'!Q3 -> 45289 | X3: =+'Asset quality'!T3 -> минг. сўмда
A4: № | B4: Иқтисодиёт тармоқлари бўйича | C4: Кредит суммаси | D4: шундан | F4: шундан муаммоли кредитлар | J4: шундан
D5: миллий валютада | E5: хорижий валютада (экв. сўмда) | F5: NPL | G5: шундан | J5: Депозитлар | K5: Ўзбекистон Республикаси Ҳукумати тамонидан кафолатланган кредитлар | L5: шундан | M5: Транспорт воситалари | N5: Инвентарлар | O5: Кўчмас мулк | P5: шундан | R5: Асбоб ускуналар | S5: Векселлар (облигациялар) | T5: Акциялар | U5: Учинчи шахс кафолати | V5: Учинчи шахс кафиллиги | W5: Суғурта полиси | X5: Таъминотсиз | Y5: Бошқа кафолатлар
G6: Қониқарсиз | H6: Шубҳали | I6: Умидсиз | L6: Ўзбекистон Республикаси Ҳукумати томонидан кафолатланган хорижий валютадаги (эквивалент сўмда) кредитлар | P6: турар жой (хонадон) | Q6: тижорат кўчмас мулки
A7: Код | B7: (А) | C7: (Б) | D7: (Б1) | E7: (Б3) | F7: (В) | G7: (В1) | H7: (В2) | I7: (В3) | J7: (Г) | K7: (Д) | L7: (Д1) | M7: (Е) | N7: (Ж) | O7: (З) | P7: (З1) | Q7: (З2) | R7: (И) | S7: (К) | T7: (Л) | U7: (М) | V7: (Н) | W7: (О) | X7: (П) | Y7: (Р)
B8: Саноат
A9: 10 | B9: Давлат корхоналари | C9: =SUM(J9:Y9)-L9-P9-Q9 -> 255215979 | D9: 187225762 | E9: 67990217 | F9: =+G9+H9+I9 -> 13388155 | G9: 643789 | H9: 1185186 | I9: 11559180 | J9: 0 | K9: 0 | L9: 0 | M9: 4201830 | N9: 0 | O9: =+P9+Q9 -> 175522229 | P9: 38529009 | Q9: 136993220 | R9: 0 | S9: 0 | T9: 0 | U9: 0 | V9: 13349067 | W9: 62142853 | X9: 0 | Y9: 0
A10: =A9+10 -> 20 | B10: Қўшма ва чет эл капитали иштирокидаги корхоналар | C10: =SUM(J10:Y10)-L10-P10-Q10 -> 0 | D10: 0 | E10: 0 | F10: =+G10+H10+I10 -> 0 | G10: 0 | H10: 0 | I10: 0 | J10: 0 | K10: 0 | L10: 0 | M10: 0 | N10: 0 | O10: =+P10+Q10 -> 0 | P10: 0 | Q10: 0 | R10: 0 | S10: 0 | T10: 0 | U10: 0 | V10: 0 | W10: 0 | X10: 0 | Y10: 0
A11: =A10+10 -> 30 | B11: Хусусий корхоналар | C11: =SUM(J11:Y11)-L11-P11-Q11 -> 3540525008 | D11: 1389448180 | E11: 2151076828 | F11: =+G11+H11+I11 -> 153377059 | G11: 8187192 | H11: 13369206 | I11: 131820661 | J11: 1372550 | K11: 0 | L11: 0 | M11: 98198279 | N11: 0 | O11: =+P11+Q11 -> 2331622496 | P11: 436278092 | Q11: 1895344404 | R11: 10589654 | S11: 0 | T11: 0 | U11: 0 | V11: 73992605 | W11: 1000804480 | X11: 2836292 | Y11: 21108652
A12: =A11+10 -> 40 | B12: Ҳукумат | C12: =SUM(J12:Y12)-L12-P12-Q12 -> 0 | D12: 0 | E12: 0 | F12: =+G12+H12+I12 -> 0 | G12: 0 | H12: 0 | I12: 0 | J12: 0 | K12: 0 | L12: 0 | M12: 0 | N12: 0 | O12: =+P12+Q12 -> 0 | P12: 0 | Q12: 0 | R12: 0 | S12: 0 | T12: 0 | U12: 0 | V12: 0 | W12: 0 | X12: 0 | Y12: 0
A13: =A12+10 -> 50 | B13: Бошқалар | C13: =SUM(J13:Y13)-L13-P13-Q13 -> 0 | D13: 0 | E13: 0 | F13: =+G13+H13+I13 -> 0 | G13: 0 | H13: 0 | I13: 0 | J13: 0 | K13: 0 | L13: 0 | M13: 0 | N13: 0 | O13: =+P13+Q13 -> 0 | P13: 0 | Q13: 0 | R13: 0 | S13: 0 | T13: 0 | U13: 0 | V13: 0 | W13: 0 | X13: 0 | Y13: 0
A14: =A13+10 -> 60 | B14: Жами | C14: =SUM(J14:Y14)-L14-P14-Q14 -> 3795740987 | D14: =SUM(D9:D13) -> 1576673942 | E14: =SUM(E9:E13) -> 2219067045 | F14: =+G14+H14+I14 -> 166765214 | G14: =SUM(G9:G13) -> 8830981 | H14: =SUM(H9:H13) -> 14554392 | I14: =SUM(I9:I13) -> 143379841 | J14: =SUM(J9:J13) -> 1372550 | K14: =SUM(K9:K13) -> 0 | L14: =SUM(L9:L13) -> 0 | M14: =SUM(M9:M13) -> 102400109 | N14: =SUM(N9:N13) -> 0 | ... Y14: =SUM(Y9:Y13) -> 21108652
B15: Қишлоқ хўжалиги
A16: 70 | B16: Давлат корхоналари | C16: =SUM(J16:Y16)-L16-P16-Q16 -> 431018747 | D16: 398355798 | E16: 32662949 | F16: =+G16+H16+I16 -> 9936616 | G16: 430335 | H16: 1453194 | I16: 8053087 | J16: 0 | K16: 0 | L16: 0 | M16: 4788966 | N16: 0 | O16: =+P16+Q16 -> 317209190 | P16: 8205447 | Q16: 309003743 | R16: 180563 | S16: 0 | T16: 0 | U16: 0 | V16: 10090837 | W16: 95597710 | X16: 3151481 | Y16: 0
A17: =A16+10 -> 80 | B17: Қўшма ва чет эл капитали иштирокидаги корхоналар | C17: =SUM(J17:Y17)-L17-P17-Q17 -> 0 | D17: 0 | E17: 0 | F17: =+G17+H17+I17 -> 0 | G17: 0 | H17: 0 | I17: 0 | J17: 0 | K17: 0 | L17: 0 | M17: 0 | N17: 0 | O17: =+P17+Q17 -> 0 | P17: 0 | Q17: 0 | R17: 0 | S17: 0 | T17: 0 | U17: 0 | V17: 0 | W17: 0 | X17: 0 | Y17: 0
A18: =A17+10 -> 90 | B18: Хусусий корхоналар | C18: =SUM(J18:Y18)-L18-P18-Q18 -> 0 | D18: 0 | E18: 0 | F18: =+G18+H18+I18 -> 0 | G18: 0 | H18: 0 | I18: 0 | J18: 0 | K18: 0 | L18: 0 | M18: 0 | N18: 0 | O18: =+P18+Q18 -> 0 | P18: 0 | Q18: 0 | R18: 0 | S18: 0 | T18: 0 | U18: 0 | V18: 0 | W18: 0 | X18: 0 | Y18: 0
A19: =A18+10 -> 100 | B19: Фермер хўжалиги | C19: =SUM(J19:Y19)-L19-P19-Q19 -> 2040311629 | D19: 1203292058 | E19: 837019571 | F19: =+G19+H19+I19 -> 145908631 | G19: 1489360 | H19: 13336598 | I19: 131082673 | J19: 27029 | K19: 0 | L19: 0 | M19: 41220804 | N19: 0 | O19: =+P19+Q19 -> 1848457994 | P19: 554382161 | Q19: 1294075833 | R19: 4240000 | S19: 0 | T19: 0 | U19: 0 | V19: 49466323 | W19: 82815565 | X19: 1715302 | Y19: 12368612
A20: =A19+10 -> 110 | B20: Ҳукумат | C20: =SUM(J20:Y20)-L20-P20-Q20 -> 0 | D20: 0 | E20: 0 | F20: =+G20+H20+I20 -> 0 | G20: 0 | H20: 0 | I20: 0 | J20: 0 | K20: 0 | L20: 0 | M20: 0 | N20: 0 | O20: =+P20+Q20 -> 0 | P20: 0 | Q20: 0 | R20: 0 | S20: 0 | T20: 0 | U20: 0 | V20: 0 | W20: 0 | X20: 0 | Y20: 0
A21: =A20+10 -> 120 | B21: Бошқалар | C21: =SUM(J21:Y21)-L21-P21-Q21 -> 0 | D21: 0 | E21: 0 | F21: =+G21+H21+I21 -> 0 | G21: 0 | H21: 0 | I21: 0 | J21: 0 | K21: 0 | L21: 0 | M21: 0 | N21: 0 | O21: =+P21+Q21 -> 0 | P21: 0 | Q21: 0 | R21: 0 | S21: 0 | T21: 0 | U21: 0 | V21: 0 | W21: 0 | X21: 0 | Y21: 0
A22: =A21+10 -> 130 | B22: Жами | C22: =SUM(J22:Y22)-L22-P22-Q22 -> 2471330376 | D22: =SUM(D16:D21) -> 1601647856 | E22: =SUM(E16:E21) -> 869682520 | F22: =+G22+H22+I22 -> 145908631 | G22: =SUM(G17:G21) -> 1489360 | H22: =SUM(H17:H21) -> 13336598 | I22: =SUM(I17:I21) -> 131082673 | J22: =SUM(J16:J21) -> 27029 | K22: =SUM(K16:K21) -> 0 | L22: =SUM(L16:L21) -> 0 | M22: =SUM(M16:M21) -> 46009770 | N22: =SUM(N16:N21) -> 0 | O22: =SUM(O16:O21) -> 2165667184 | P22: =SUM(P16:P21) -> 562587608 | Q22: =SUM(Q16:Q21) -> 1603079576 | ... Y22: =SUM(Y16:Y21) -> 12368612
B23: Транспорт ва коммуникация
A24: 140 | B24: Давлат корхоналари | C24: =SUM(J24:Y24)-L24-P24-Q24 -> 35773291 | D24: 32846606 | E24: 2926685 | F24: =+G24+H24+I24 -> 2393969 | G24: 15461 | H24: 36224 | I24: 2342284 | J24: 0 | K24: 0 | L24: 0 | M24: 2113853 | N24: 0 | O24: =+P24+Q24 -> 14244520 | P24: 472796 | Q24: 13771724 | R24: 0 | S24: 0 | T24: 0 | U24: 0 | V24: 11250 | W24: 19403668 | X24: 0 | Y24: 0
A25: =A24+10 -> 150 | B25: Қўшма ва чет эл капитали иштирокидаги корхоналар | C25: =SUM(J25:Y25)-L25-P25-Q25 -> 0 | D25: 0 | E25: 0 | F25: =+G25+H25+I25 -> 0 | G25: 0 | H25: 0 | I25: 0 | J25: 0 | K25: 0 | L25: 0 | M25: 0 | N25: 0 | O25: =+P25+Q25 -> 0 | P25: 0 | Q25: 0 | R25: 0 | S25: 0 | T25: 0 | U25: 0 | V25: 0 | W25: 0 | X25: 0 | Y25: 0
A26: =A25+10 -> 160 | B26: Хусусий корхоналар | C26: =SUM(J26:Y26)-L26-P26-Q26 -> 239945668 | D26: 189846822 | E26: 50098846 | F26: =+G26+H26+I26 -> 1269834 | G26: 200642 | H26: 183671 | I26: 885521 | J26: 19225 | K26: 0 | L26: 0 | M26: 89077399 | N26: 0 | O26: =+P26+Q26 -> 135426918 | P26: 70569015 | Q26: 64857903 | R26: 0 | S26: 0 | T26: 0 | U26: 0 | V26: 2782834 | W26: 10952390 | X26: 0 | Y26: 1686902
A27: =A26+10 -> 170 | B27: Ҳукумат | C27: =SUM(J27:Y27)-L27-P27-Q27 -> 0 | D27: 0 | E27: 0 | F27: =+G27+H27+I27 -> 0 | G27: 0 | H27: 0 | I27: 0 | J27: 0 | K27: 0 | L27: 0 | M27: 0 | N27: 0 | O27: =+P27+Q27 -> 0 | P27: 0 | Q27: 0 | R27: 0 | S27: 0 | T27: 0 | U27: 0 | V27: 0 | W27: 0 | X27: 0 | Y27: 0
A28: =A27+10 -> 180 | B28: Бошқалар | C28: =SUM(J28:Y28)-L28-P28-Q28 -> 0 | D28: 0 | E28: 0 | F28: =+G28+H28+I28 -> 0 | G28: 0 | H28: 0 | I28: 0 | J28: 0 | K28: 0 | L28: 0 | M28: 0 | N28: 0 | O28: =+P28+Q28 -> 0 | P28: 0 | Q28: 0 | R28: 0 | S28: 0 | T28: 0 | U28: 0 | V28: 0 | W28: 0 | X28: 0 | Y28: 0
A29: =A28+10 -> 190 | B29: Жами | C29: =SUM(J29:Y29)-L29-P29-Q29 -> 275718959 | D29: =SUM(D24:D28) -> 222693428 | E29: =SUM(E24:E28) -> 53025531 | F29: =+G29+H29+I29 -> 3663803 | G29: =SUM(G24:G28) -> 216103 | H29: =SUM(H24:H28) -> 219895 | I29: =SUM(I24:I28) -> 3227805 | J29: =SUM(J24:J28) -> 19225 | K29: =SUM(K24:K28) -> 0 | L29: =SUM(L24:L28) -> 0 | M29: =SUM(M24:M28) -> 91191252 | N29: =SUM(N24:N28) -> 0 | ... Y29: =SUM(Y24:Y28) -> 1686902
B30: Қурилиш соҳаси
A31: 200 | B31: Давлат корхоналари | C31: =SUM(J31:Y31)-L31-P31-Q31 -> 319748497 | D31: 314936713 | E31: 4811784 | F31: =+G31+H31+I31 -> 6523567 | G31: 0 | H31: 0 | I31: 6523567 | J31: 0 | K31: 0 | L31: 0 | M31: 40413 | N31: 0 | O31: =+P31+Q31 -> 303042540 | P31: 8746960 | Q31: 294295580 | R31: 0 | S31: 0 | T31: 0 | U31: 0 | V31: 586037 | W31: 14879507 | X31: 1200000 | Y31: 0
A32: =A31+10 -> 210 | B32: Қўшма ва чет эл капитали иштирокидаги корхоналар | C32: =SUM(J32:Y32)-L32-P32-Q32 -> 0 | D32: 0 | E32: 0 | F32: =+G32+H32+I32 -> 0 | G32: 0 | H32: 0 | I32: 0 | J32: 0 | K32: 0 | L32: 0 | M32: 0 | N32: 0 | O32: =+P32+Q32 -> 0 | P32: 0 | Q32: 0 | R32: 0 | S32: 0 | T32: 0 | U32: 0 | V32: 0 | W32: 0 | X32: 0 | Y32: 0
A33: =A32+10 -> 220 | B33: Хусусий корхоналар | C33: =SUM(J33:Y33)-L33-P33-Q33 -> 539189754 | D33: 461413299 | E33: 77776455 | F33: =+G33+H33+I33 -> 33771021 | G33: 0 | H33: 119955 | I33: 33651066 | J33: 0 | K33: 0 | L33: 0 | M33: 7564094 | N33: 0 | O33: =+P33+Q33 -> 490472145 | P33: 95560811 | Q33: 394911334 | R33: 0 | S33: 0 | T33: 0 | U33: 0 | V33: 27108216 | W33: 689806 | X33: 0 | Y33: 13355493
A34: =A33+10 -> 230 | B34: Ҳукумат | C34: =SUM(J34:Y34)-L34-P34-Q34 -> 0 | D34: 0 | E34: 0 | F34: =+G34+H34+I34 -> 0 | G34: 0 | H34: 0 | I34: 0 | J34: 0 | K34: 0 | L34: 0 | M34: 0 | N34: 0 | O34: =+P34+Q34 -> 0 | P34: 0 | Q34: 0 | R34: 0 | S34: 0 | T34: 0 | U34: 0 | V34: 0 | W34: 0 | X34: 0 | Y34: 0
A35: =A34+10 -> 240 | B35: Бошқалар | C35: =SUM(J35:Y35)-L35-P35-Q35 -> 0 | D35: 0 | E35: 0 | F35: =+G35+H35+I35 -> 0 | G35: 0 | H35: 0 | I35: 0 | J35: 0 | K35: 0 | L35: 0 | M35: 0 | N35: 0 | O35: =+P35+Q35 -> 0 | P35: 0 | Q35: 0 | R35: 0 | S35: 0 | T35: 0 | U35: 0 | V35: 0 | W35: 0 | X35: 0 | Y35: 0
A36: =A35+10 -> 250 | B36: Жами | C36: =SUM(J36:Y36)-L36-P36-Q36 -> 858938251 | D36: =SUM(D31:D35) -> 776350012 | E36: =SUM(E31:E35) -> 82588239 | F36: =+G36+H36+I36 -> 40294588 | G36: =SUM(G31:G35) -> 0 | H36: =SUM(H31:H35) -> 119955 | I36: =SUM(I31:I35) -> 40174633 | J36: =SUM(J31:J35) -> 0 | K36: =SUM(K31:K35) -> 0 | L36: =SUM(L31:L35) -> 0 | M36: =SUM(M31:M35) -> 7604507 | N36: =SUM(N31:N35) -> 0 | ... Y36: =SUM(Y31:Y35) -> 13355493
B37: Савдо ва умумий хизмат
A38: 260 | B38: Давлат корхоналари | C38: =SUM(J38:Y38)-L38-P38-Q38 -> 134737593 | D38: 130400927 | E38: 4336666 | F38: =+G38+H38+I38 -> 7960072 | G38: 166421 | H38: 134362 | I38: 7659289 | J38: 0 | K38: 0 | L38: 0 | M38: 5835243 | N38: 0 | O38: =+P38+Q38 -> 85769691 | P38: 2323087 | Q38: 83446604 | R38: 0 | S38: 0 | T38: 0 | U38: 0 | V38: 993534 | W38: 42010453 | X38: 128672 | Y38: 0
A39: =A38+10 -> 270 | B39: Қўшма ва чет эл капитали иштирокидаги корхоналар | C39: =SUM(J39:Y39)-L39-P39-Q39 -> 0 | D39: 0 | E39: 0 | F39: =+G39+H39+I39 -> 0 | G39: 0 | H39: 0 | I39: 0 | J39: 0 | K39: 0 | L39: 0 | M39: 0 | N39: 0 | O39: =+P39+Q39 -> 0 | P39: 0 | Q39: 0 | R39: 0 | S39: 0 | T39: 0 | U39: 0 | V39: 0 | W39: 0 | X39: 0 | Y39: 0
A40: =A39+10 -> 280 | B40: Хусусий корхоналар | C40: =SUM(J40:Y40)-L40-P40-Q40 -> 790202202 | D40: 525551459 | E40: 264650743 | F40: =+G40+H40+I40 -> 39855973 | G40: 677142 | H40: 2760900 | I40: 36417931 | J40: 381593 | K40: 0 | L40: 0 | M40: 25312843 | N40: 0 | O40: =+P40+Q40 -> 688644285 | P40: 230340524 | Q40: 458303761 | R40: 1399681 | S40: 0 | T40: 0 | U40: 0 | V40: 13816187 | W40: 49038034 | X40: 5767065 | Y40: 5842514
A41: =A40+10 -> 290 | B41: Ҳукумат | C41: =SUM(J41:Y41)-L41-P41-Q41 -> 0 | D41: 0 | E41: 0 | F41: =+G41+H41+I41 -> 0 | G41: 0 | H41: 0 | I41: 0 | J41: 0 | K41: 0 | L41: 0 | M41: 0 | N41: 0 | O41: =+P41+Q41 -> 0 | P41: 0 | Q41: 0 | R41: 0 | S41: 0 | T41: 0 | U41: 0 | V41: 0 | W41: 0 | X41: 0 | Y41: 0
...

Sheet Aging Analysis
A1: ОЛИНИШИ ЛОЗИМ БЎЛГАН МУДДАТИ ЎТГАН КРЕДИТ ВА МОЛИЯВИЙ ЛИЗИНГ ТАҲЛИЛИ | X1: 9-жадвал
B3: =+'Asset quality'!B3 -> "MKBANK" | T3: =+'Asset quality'!Q3 -> 45289 | X3: =+'Asset quality'!T3 -> минг. сўмда
A4: № | B4: Кўрсаткичлар | C4: Жами кредит суммаси | D4: % | E4: Шартлари қайта кўрилган кредит ва лизинглар | F4: % | G4: Суд жараёнидаги қарздорликлар | H4: % | I4: Муддати ўтган | K4: % | L4: шу жумладан, кечиктирилган муддати бўйича
L5: 1-30 кун | N5: 31-60 кун | P5: 61-90 кун | R5: 91-180 кун | T5: 181-365 кун | V5: 366-730 кун | X5: 2 йилдан ортиқ
I6: асосий қарздорлик | J6: фоиз тўловлари | L6: асосий қарздорлик | M6: фоиз тўловлари | N6: асосий қарздорлик | O6: фоиз тўловлари | P6: асосий қарздорлик | Q6: фоиз тўловлари | R6: асосий қарздорлик | S6: фоиз тўловлари | T6: асосий қарздорлик | U6: фоиз тўловлари | V6: асосий қарздорлик | W6: фоиз тўловлари | X6: асосий қарздорлик | Y6: фоиз тўловлари
B7: (А) | C7: (Б) | D7: (В) | E7: (Г) | F7: (Д) | G7: (Е) | H7: (Ж) | I7: (З) | J7: (З1) | K7: (И) | L7: (К) | M7: (К1) | N7: (Л) | O7: (Л1) | P7: (М) | Q7: (М1) | R7: (Н) | S7: (Н1) | T7: (О) | U7: (О1) | V7: (П) | W7: (П1) | X7: (Р) | Y7: (Р1)
B8: Мижозлар тури бўйича
A9: 1 | B9: Марказий банк | C9: =+'Loans Receivable'!C79 -> 0 | D9: =IF(C$22=0,"",C9/C$22) -> 0 | F9: =IF(E$22=0,"",E9/E$22) -> 0 | H9: =IF($G$22=0,"",G9/$G$22) -> 0 | I9: =+L9+N9+P9+R9+T9+V9+X9 -> 0 | J9: =+M9+O9+T9+S9+U9+W9+Y9 -> 0 | K9: =IF($Z$22=0,"",Z9/$Z$22) -> 0 | Z9: =+I9+J9 -> 0 | AA9: =+C9-Z9 -> 0
A10: 2 | B10: Бошқа банклар | C10: =+'Loans Receivable'!C78 -> 0 | D10: =IF(C$22=0,"",C10/C$22) -> 0 | F10: =IF(E$22=0,"",E10/E$22) -> 0 | H10: =IF($G$22=0,"",G10/$G$22) -> 0 | I10: =+L10+N10+P10+R10+T10+V10+X10 -> 0 | J10: =+M10+O10+Q10+S10+U10+W10+Y10 -> 0 | K10: =IF($Z$22=0,"",Z10/$Z$22) -> 0 | Z10: =+I10+J10 -> 0
A11: 3 | B11: Ҳукумат | C11: =+'Loans Receivable'!C80 -> 0 | D11: =IF(C$22=0,"",C11/C$22) -> 0 | F11: =IF(E$22=0,"",E11/E$22) -> 0 | H11: =IF($G$22=0,"",G11/$G$22) -> 0 | I11: =+L11+N11+P11+R11+T11+V11+X11 -> 0 | J11: =+M11+O11+Q11+S11+U11+W11+Y11 -> 0 | K11: =IF($Z$22=0,"",Z11/$Z$22) -> 0 | Z11: =+I11+J11 -> 0
A12: 4 | B12: Жисмоний шахслар | C12: =+'Loans Receivable'!C73 -> 5341704946 | D12: =IF(C$22=0,"",C12/C$22) -> 0.36999897 | F12: =IF(E$22=0,"",E12/E$22) -> 0 | G12: 3977285 | H12: =IF($G$22=0,"",G12/$G$22) -> 0.074387316 | I12: =+L12+N12+P12+R12+T12+V12+X12 -> 3.6432345e+08 | J12: =+M12+O12+Q12+S12+U12+W12+Y12 -> 1.3386996e+08 | K12: =IF($Z$22=0,"",Z12/$Z$22) -> 0.28466891 | L12: 9826429.6 | M12: 3594078.2 | N12: 13529542 | O12: 4672011.6 | P12: 31785289 | Q12: 8717909.8 | R12: 29704845 | S12: 7763751.7 | T12: 1.2751872e+08 | U12: 36146422 | V12: 1.0823383e+08 | W12: 50326503 | X12: 43724792 | Y12: 22649280 | Z12: =+I12+J12 -> 4.9819341e+08
A13: 5 | B13: Давлат корхоналари | C13: =+'Loans Receivable'!C74 -> 1199739271 | D13: =IF(C$22=0,"",C13/C$22) -> 0.083101238 | F13: =IF(E$22=0,"",E13/E$22) -> 0 | G13: 2220687 | H13: =IF($G$22=0,"",G13/$G$22) -> 0.041533595 | I13: =+L13+N13+P13+R13+T13+V13+X13 -> 81755894 | J13: =+M13+O13+Q13+S13+U13+W13+Y13 -> 45414555 | K13: =IF($Z$22=0,"",Z13/$Z$22) -> 0.072665501 | L13: 4535326.3 | M13: 1705687.7 | N13: 2581526.6 | O13: 4285442.1 | P13: 11260829 | Q13: 5050803.1 | R13: 8945492.3 | S13: 1615883.9 | T13: 16900520 | U13: 8019372.4 | V13: 24105435 | W13: 12817570 | X13: 13426764 | Y13: 11919796 | Z13: =+I13+J13 -> 1.2717045e+08
A14: 6 | B14: Қўшма ва чет эл капитали иштирокидаги корхоналар | C14: =+'Loans Receivable'!C75 -> 0 | D14: =IF(C$22=0,"",C14/C$22) -> 0 | F14: =IF(E$22=0,"",E14/E$22) -> 0 | H14: =IF($G$22=0,"",G14/$G$22) -> 0 | I14: =+L14+N14+P14+R14+T14+V14+X14 -> 0 | J14: =+M14+O14+Q14+S14+U14+W14+Y14 -> 0 | K14: =IF($Z$22=0,"",Z14/$Z$22) -> 0 | Z14: =+I14+J14 -> 0
A15: 7 | B15: Хусусий корхоналар | C15: =+'Loans Receivable'!C76 -> 5278406950 | D15: =IF(C$22=0,"",C15/C$22) -> 0.36561457 | E15: 12486 | F15: =IF(E$22=0,"",E15/E$22) -> 1 | G15: 25852066 | H15: =IF($G$22=0,"",G15/$G$22) -> 0.4835122 | I15: =+L15+N15+P15+R15+T15+V15+X15 -> 5.2308635e+08 | J15: =+M15+O15+Q15+S15+U15+W15+Y15 -> 2.6297654e+08 | K15: =IF($Z$22=0,"",Z15/$Z$22) -> 0.44915823 | L15: 46151208 | M15: 17773555 | N15: 59250194 | O15: 6322014.1 | P15: 54709094 | Q15: 29950811 | R15: 61692372 | S15: 17108407 | T15: 1.2398225e+08 | U15: 66724859 | V15: 1.3623172e+08 | W15: 93369127 | X15: 41069518 | Y15: 31727770 | Z15: =+I15+J15 -> 7.860629e+08
A16: 8 | B16: Фермер хўжаликлари | C16: =+'Loans Receivable'!C77 -> 2040311629 | D16: =IF(C$22=0,"",C16/C$22) -> 0.14132439 | F16: =IF(E$22=0,"",E16/E$22) -> 0 | G16: 12003593 | H16: =IF($G$22=0,"",G16/$G$22) -> 0.22450367 | I16: =+L16+N16+P16+R16+T16+V16+X16 -> 1.2854511e+08 | J16: =+M16+O16+Q16+S16+U16+W16+Y16 -> 1.1687264e+08 | K16: =IF($Z$22=0,"",Z16/$Z$22) -> 0.14023229 | L16: 5821568.8 | M16: 12246629 | N16: 3187629.8 | O16: 4642067.6 | P16: 6667619.5 | Q16: 5543098.4 | R16: 12109880 | S16: 16724476 | T16: 29762871 | U16: 33096710 | V16: 57616029 | W16: 36163098 | X16: 13379507 | Y16: 8456557 | Z16: =+I16+J16 -> 2.4541774e+08
A17: 9 | B17: Нобанк молиявий институтлар | C17: =+'Loans Receivable'!C81 -> 0 | D17: =IF(C$22=0,"",C17/C$22) -> 0 | F17: =IF(E$22=0,"",E17/E$22) -> 0 | H17: =IF($G$22=0,"",G17/$G$22) -> 0 | I17: =+L17+N17+P17+R17+T17+V17+X17 -> 0 | J17: =+M17+O17+Q17+S17+U17+W17+Y17 -> 0 | K17: =IF($Z$22=0,"",Z17/$Z$22) -> 0 | Z17: =+I17+J17 -> 0
A18: 10 | B18: Нодавлат нотижорат ташкилотлар | C18: =+'Loans Receivable'!C82 -> 576917739 | D18: =IF(C$22=0,"",C18/C$22) -> 0.039960831 | F18: =IF(E$22=0,"",E18/E$22) -> 0 | G18: 9413616 | H18: =IF($G$22=0,"",G18/$G$22) -> 0.17606323 | I18: =+L18+N18+P18+R18+T18+V18+X18 -> 53113543 | J18: =+M18+O18+Q18+S18+U18+W18+Y18 -> 40122088 | K18: =IF($Z$22=0,"",Z18/$Z$22) -> 0.053275064 | L18: 2066493.2 | M18: 411736.52 | N18: 2754274.5 | O18: 1496311.1 | P18: 3532481.6 | Q18: 4525963.2 | R18: 7242414.6 | S18: 2929248.5 | T18: 9589893.2 | U18: 10847337 | V18: 19917724 | W18: 8737800.5 | X18: 8010262.5 | Y18: 11173691 | Z18: =+I18+J18 -> 93235631
A19: 11 | B19: Бюджет ташкилотлари | C19: =+'Loans Receivable'!C83 -> 0 | D19: =IF(C$22=0,"",C19/C$22) -> 0 | F19: =IF(E$22=0,"",E19/E$22) -> 0 | H19: =IF($G$22=0,"",G19/$G$22) -> 0 | I19: =+L19+N19+P19+R19+T19+V19+X19 -> 0 | J19: =+M19+O19+Q19+S19+U19+W19+Y19 -> 0 | K19: =IF($Z$22=0,"",Z19/$Z$22) -> 0 | Z19: =+I19+J19 -> 0
A20: 12 | B20: Бошқалар | C20: =+'Loans Receivable'!C84 -> 0 | D20: =IF(C$22=0,"",C20/C$22) -> 0 | F20: =IF(E$22=0,"",E20/E$22) -> 0 | H20: =IF($G$22=0,"",G20/$G$22) -> 0 | I20: =+L20+N20+P20+R20+T20+V20+X20 -> 0 | J20: =+M20+O20+Q20+S20+U20+W20+Y20 -> 0 | K20: =IF($Z$22=0,"",Z20/$Z$22) -> 0 | Z20: =+I20+J20 -> 0
Z21: =+I21+J21 -> 0
A22: 13 | B22: Жами кредит ва лизинг суммаси | C22: =SUM(C9:C20) -> 14437080535 | D22: =IF(C$22=0,"",C22/C$22) -> 1 | E22: =SUM(E9:E20) -> 12486 | F22: =IF(E$22=0,"",E22/E$22) -> 1 | G22: =SUM(G9:G20) -> 53467247 | H22: =IF($G$22=0,"",G22/$G$22) -> 1 | I22: =SUM(I9:I20) -> 1.1508243e+09 | J22: =SUM(J9:J20) -> 5.9925578e+08 | K22: =IF($Z$22=0,"",Z22/$Z$22) -> 1 | L22: =SUM(L9:L20) -> 68401026 | M22: =SUM(M9:M20) -> 35731687 | N22: =SUM(N9:N20) -> 81303167 | O22: =SUM(O9:O20) -> 21417846 | P22: =SUM(P9:P20) -> 1.0795531e+08 | Q22: =SUM(Q9:Q20) -> 53788585 | R22: =SUM(R9:R20) -> 1.19695e+08 | S22: =SUM(S9:S20) -> 46141767 | ... Y22: =SUM(Y9:Y20) -> 85927094 | Z22: =+I22+J22 -> 1.7500801e+09
Z23: =+I23+J23 -> 0
B24: Иқтисодиёт соҳалари бўйича | Z24: =+I24+J24 -> 0
A25: 14 | B25: Саноат | C25: =+'Loans Receivable'!C14 -> 3795740987 | D25: =IF(C$35=0,"",C25/C$35) -> 0.26291611 | F25: =IF($E$35=0,"",E25/$E$35) -> 0 | G25: 9453815 | H25: =IF($G$35=0,"",G25/$G$35) -> 0.17681507 | I25: =+L25+N25+P25+R25+T25+V25+X25 -> 3.4098348e+08 | J25: =+M25+O25+Q25+S25+U25+W25+Y25 -> 1.6332911e+08 | K25: =IF($Z$35=0,"",Z25/$Z$35) -> 0.28816543 | L25: 44009050 | M25: 12905226 | N25: 43804780 | O25: 4994670.1 | P25: 43472965 | Q25: 19848115 | R25: 35102549 | S25: 9510326.8 | T25: 74681886 | U25: 33401620 | V25: 61644152 | W25: 59462800 | X25: 38268098 | Y25: 23206354 | Z25: =+I25+J25 -> 5.0431259e+08
A26: 15 | B26: Қишлоқ хўжалиги | C26: =+'Loans Receivable'!C22 -> 2471330376 | D26: =IF(C$35=0,"",C26/C$35) -> 0.17117937 | E26: 12486 | F26: =IF($E$35=0,"",E26/$E$35) -> 1 | G26: 12281602 | H26: =IF($G$35=0,"",G26/$G$35) -> 0.22970328 | I26: =+L26+N26+P26+R26+T26+V26+X26 -> 1.5180165e+08 | J26: =+M26+O26+Q26+S26+U26+W26+Y26 -> 1.3249419e+08 | K26: =IF($Z$35=0,"",Z26/$Z$35) -> 0.16244733 | L26: 7541771.2 | M26: 12325569 | N26: 3913354.6 | O26: 8251106.7 | P26: 10263963 | Q26: 7422508.7 | R26: 12824394 | S26: 17444477 | T26: 39356418 | U26: 36802670 | V26: 63131286 | W26: 39667587 | X26: 14770460 | Y26: 10580276 | Z26: =+I26+J26 -> 2.8429584e+08
A27: 16 | B27: Транспорт ва коммуникация | C27: =+'Loans Receivable'!C29 -> 275718959 | D27: =IF(C$35=0,"",C27/C$35) -> 0.019097972 | F27: =IF($E$35=0,"",E27/$E$35) -> 0 | G27: 155044 | H27: =IF($G$35=0,"",G27/$G$35) -> 0.002899794 | I27: =+L27+N27+P27+R27+T27+V27+X27 -> 20588201 | J27: =+M27+O27+Q27+S27+U27+W27+Y27 -> 9965169 | K27: =IF($Z$35=0,"",Z27/$Z$35) -> 0.017458269 | L27: 302598.37 | M27: 185581.85 | N27: 564911.84 | O27: 333757.53 | P27: 2496051.8 | Q27: 474411.25 | R27: 325433.5 | S27: 54846.13 | T27: 1587845.8 | U27: 6474908.2 | V27: 14890259 | W27: 2001811 | X27: 421101.11 | Y27: 439853 | Z27: =+I27+J27 -> 30553370
A28: 17 | B28: Қурилиш соҳаси | C28: =+'Loans Receivable'!C36 -> 858938251 | D28: =IF(C$35=0,"",C28/C$35) -> 0.059495287 | F28: =IF($E$35=0,"",E28/$E$35) -> 0 | G28: 12044740 | H28: =IF($G$35=0,"",G28/$G$35) -> 0.22527324 | I28: =+L28+N28+P28+R28+T28+V28+X28 -> 71229502 | J28: =+M28+O28+Q28+S28+U28+W28+Y28 -> 46069494 | K28: =IF($Z$35=0,"",Z28/$Z$35) -> 0.067024929 | L28: 1252866.4 | M28: 2815440.5 | N28: 11718293 | O28: 113172.66 | P28: 1023509.6 | Q28: 3724203.7 | R28: 10124955 | S28: 2101186.9 | T28: 14294701 | U28: 9070557.3 | V28: 29783790 | W28: 22745881 | X28: 3031387.6 | Y28: 5499052 | Z28: =+I28+J28 -> 1.17299e+08
A29: 18 | B29: Савдо ва умумий овқатланиш | C29: =+'Loans Receivable'!C43 -> 924939795 | D29: =IF(C$35=0,"",C29/C$35) -> 0.064066955 | F29: =IF($E$35=0,"",E29/$E$35) -> 0 | G29: 5706643 | H29: =IF($G$35=0,"",G29/$G$35) -> 0.10673157 | I29: =+L29+N29+P29+R29+T29+V29+X29 -> 1.3311575e+08 | J29: =+M29+O29+Q29+S29+U29+W29+Y29 -> 65813964 | K29: =IF($Z$35=0,"",Z29/$Z$35) -> 0.11366892 | L29: 2720238.9 | M29: 2070163.9 | N29: 4447857.8 | O29: 1486854.1 | P29: 14214958 | Q29: 8503674.7 | R29: 24049595 | S29: 6214733.9 | T29: 33599010 | U29: 18758828 | V29: 43361332 | W29: 16931487 | X29: 10722763 | Y29: 11848223 | Z29: =+I29+J29 -> 1.9892972e+08
A30: 19 | B30: Моддий ва техник таъминотни ривожлантириш | C30: =+'Loans Receivable'!C50 -> 191245213 | D30: =IF(C$35=0,"",C30/C$35) -> 0.013246807 | F30: =IF($E$35=0,"",E30/$E$35) -> 0 | G30: 434503 | H30: =IF($G$35=0,"",G30/$G$35) -> 0.0081265265 | I30: =+L30+N30+P30+R30+T30+V30+X30 -> 15643199 | J30: =+M30+O30+Q30+S30+U30+W30+Y30 -> 7589287.8 | K30: =IF($Z$35=0,"",Z30/$Z$35) -> 0.013275099 | L30: 681578.03 | M30: 1421949.5 | N30: 570153.01 | O30: 69388.926 | P30: 1166096.1 | Q30: 571799 | R30: 320818.49 | S30: 123196.42 | T30: 7100208.6 | U30: 3332358.6 | V30: 5142364.8 | W30: 1540230.3 | X30: 661980.49 | Y30: 530365 | Z30: =+I30+J30 -> 23232487
A31: 20 | B31: Уй-жой коммунал хизмати | C31: =+'Loans Receivable'!C58 -> 573303150 | D31: =IF(C$35=0,"",C31/C$35) -> 0.039710463 | F31: =IF($E$35=0,"",E31/$E$35) -> 0 | G31: 8577767 | H31: =IF($G$35=0,"",G31/$G$35) -> 0.16043031 | I31: =+L31+N31+P31+R31+T31+V31+X31 -> 51749146 | J31: =+M31+O31+Q31+S31+U31+W31+Y31 -> 38680042 | K31: =IF($Z$35=0,"",Z31/$Z$35) -> 0.051671456 | L31: 2066493.2 | M31: 411736.52 | N31: 2754274.5 | O31: 1496311.1 | P31: 3532481.6 | Q31: 4525963.2 | R31: 7242414.6 | S31: 2928716.4 | T31: 9480415.1 | U31: 10847337 | V31: 18662804 | W31: 7296286.2 | X31: 8010262.5 | Y31: 11173691 | Z31: =+I31+J31 -> 90429188
A32: 21 | B32: Бошқа соҳалар | C32: =+'Loans Receivable'!C70 -> 4158858 | D32: =IF(C$35=0,"",C32/C$35) -> 0.0002880678 | F32: =IF($E$35=0,"",E32/$E$35) -> 0 | G32: 835848 | H32: =IF($G$35=0,"",G32/$G$35) -> 0.015632898 | I32: =+L32+N32+P32+R32+T32+V32+X32 -> 1389967.3 | J32: =+M32+O32+Q32+S32+U32+W32+Y32 -> 1444561.2 | K32: =IF($Z$35=0,"",Z32/$Z$35) -> 0.0016196564 | L32: 0 | M32: 1941.0349 | N32: 0 | O32: 573.74542 | P32: 0 | Q32: 0 | R32: 0 | S32: 532.10098 | T32: 135047.88 | U32: 0 | V32: 1254919.4 | W32: 1441514.3 | X32: 0 | Y32: 0 | Z32: =+I32+J32 -> 2834528.5
A33: 22 | B33: Жисмоний шахслар | C33: =+'Loans Receivable'!C71 -> 5341704946 | D33: =IF(C$35=0,"",C33/C$35) -> 0.36999897 | F33: =IF($E$35=0,"",E33/$E$35) -> 0 | G33: 3977285 | H33: =IF($G$35=0,"",G33/$G$35) -> 0.074387316 | I33: =+L33+N33+P33+R33+T33+V33+X33 -> 3.6432345e+08 | J33: =+M33+O33+Q33+S33+U33+W33+Y33 -> 1.3386996e+08 | K33: =IF($Z$35=0,"",Z33/$Z$35) -> 0.28466891 | L33: 9826429.6 | M33: 3594078.2 | N33: 13529542 | O33: 4672011.6 | P33: 31785289 | Q33: 8717909.8 | R33: 29704845 | S33: 7763751.7 | T33: 1.2751872e+08 | U33: 36146422 | V33: 1.0823383e+08 | W33: 50326503 | X33: 43724792 | Y33: 22649280 | Z33: =+I33+J33 -> 4.9819341e+08
Z34: =+I34+J34 -> 0
A35: 23 | B35: Жами кредит ва лизинг суммаси | C35: =SUM(C25:C33) -> 14437080535 | D35: =IF(C$35=0,"",C35/C$35) -> 1 | E35: =SUM(E25:E33) -> 12486 | F35: =IF($E$35=0,"",E35/$E$35) -> 1 | G35: =SUM(G25:G33) -> 53467247 | H35: =IF($G$35=0,"",G35/$G$35) -> 1 | I35: =SUM(I25:I33) -> 1.1508243e+09 | J35: =SUM(J25:J33) -> 5.9925578e+08 | K35: =IF($Z$35=0,"",Z35/$Z$35) -> 1 | L35: =SUM(L25:L33) -> 68401026 | M35: =SUM(M25:M33) -> 35731687 | N35: =SUM(N25:N33) -> 81303167 | O35: =SUM(O25:O33) -> 21417846 | P35: =SUM(P25:P33) -> 1.0795531e+08 | Q35: =SUM(Q25:Q33) -> 53788585 | R35: =SUM(R25:R33) -> 1.19695e+08 | S35: =SUM(S25:S33) -> 46141767 | ... Y35: =SUM(Y25:Y33) -> 85927094 | Z35: =+I35+J35 -> 1.7500801e+09
B37: Бошқарув Раис имзоси:
B39: Бош бухгалтер имзоси:
G42: =+'[8]Bank Assets Analysis'!$S$31 -> 41579224

Sheet Asset Classification
A1: АКТИВЛАР СИФАТИ БЎЙИЧА ТАСНИФЛАНИШИ ТЎҒРИСИДА ҲИСОБОТ | Z1: 10-жадвал
B3: =+'Asset quality'!B3 -> "MKBANK" | U3: =+'Asset quality'!Q3 -> 45289 | AB3: =+'Asset quality'!T3 -> минг. сўмда
A4: № | B4: Кўрсаткичлар | C4: Жами суммаси | D4: шундан, хорижий валютада (экв. сўмда) | E4: Стандарт | F4: шундан, хорижий валютада (экв. сўмда) | G4: Стандарт активлар бўйича яратилган захиралар (1%) | H4: шундан, хорижий валютада (экв. сўмда) | I4: Субстандарт | J4: шундан, хорижий валютада (экв. сўмда) | K4: Махсус захиралар (мин 10%) | L4: шундан, хорижий валютада (экв. сўмда) | M4: Қониқарсиз | N4: шундан, хорижий валютада (экв. сўмда) | O4: Махсус захиралар (мин 25%) | P4: шундан, хорижий валютада (экв. сўмда) | Q4: Шубҳали | R4: шундан, хорижий валютада (экв. сўмда) | S4: Махсус захиралар (мин 50%) | T4: шундан, хорижий валютада (экв. сўмда) | U4: Умидсиз | V4: шундан, хорижий валютада (экв. сўмда) | W4: Махсус захиралар (мин 100%) | X4: шундан, хорижий валютада (экв. сўмда) | Y4: Жами махсус захиралар суммаси | Z4: шундан, хорижий валютада (экв. сўмда) | AA4: ҳисобот ойида балансдан ташқари ҳисобдан чиқарилган кредитлар | AB4: ҳисобот ойида балансдан ташқари қайтган кредитлар суммаси
A5: (А) | B5: (Б) | C5: (В) | D5: (В1) | E5: (Г) | F5: (Г1) | G5: (Д) | H5: (Д1) | I5: (Е) | J5: (Е1) | K5: (Ж) | L5: (Ж1) | M5: (З) | N5: (З1) | O5: (И) | P5: (И1) | Q5: (К) | R5: (К1) | S5: (Л) | T5: (Л1) | U5: (М) | V5: (М1) | W5: (Н) | X5: (Н1) | Y5: О=Ж+И+Л+Н | Z5: (О1)=(Ж1)+(И1)+(Л1)+(Н1) | AA5: П | AB5: Р
B6: Мижозлар тури бўйича
A7: 1 | B7: Марказий банк | C7: =E7+I7+M7+Q7+U7 -> 0 | D7: =F7+J7+N7+R7+V7 -> 0 | Y7: =+W7+S7+O7+K7 -> 0 | Z7: =+X7+T7+P7+L7 -> 0 | AC7: =+'Aging Analysis'!C9 -> 0 | AD7: =+C7-AC7 -> 0
B8: шундан, таъминланмаган қисми | C8: =E8+I8+M8+Q8+U8 -> 0 | D8: =F8+J8+N8+R8+V8 -> 0 | Y8: =+W8+S8+O8+K8 -> 0 | Z8: =+X8+T8+P8+L8 -> 0
A9: 2 | B9: Бошқа банклар | C9: =E9+I9+M9+Q9+U9 -> 0 | D9: =F9+J9+N9+R9+V9 -> 0 | Y9: =+W9+S9+O9+K9 -> 0 | Z9: =+X9+T9+P9+L9 -> 0 | AC9: =+'Aging Analysis'!C10 -> 0 | AD9: =+C9-AC9 -> 0
B10: шундан, таъминланмаган қисми | C10: =E10+I10+M10+Q10+U10 -> 0 | D10: =F10+J10+N10+R10+V10 -> 0 | Y10: =+W10+S10+O10+K10 -> 0 | Z10: =+X10+T10+P10+L10 -> 0
A11: 3 | B11: Ҳукумат | C11: =E11+I11+M11+Q11+U11 -> 0 | D11: =F11+J11+N11+R11+V11 -> 0 | Y11: =+W11+S11+O11+K11 -> 0 | Z11: =+X11+T11+P11+L11 -> 0 | AC11: =+'Aging Analysis'!C11 -> 0 | AD11: =+C11-AC11 -> 0
B12: шундан, таъминланмаган қисми | C12: =E12+I12+M12+Q12+U12 -> 0 | D12: =F12+J12+N12+R12+V12 -> 0 | Y12: =+W12+S12+O12+K12 -> 0 | Z12: =+X12+T12+P12+L12 -> 0
A13: 4 | B13: Жисмоний шахслар | C13: =E13+I13+M13+Q13+U13 -> 5341704946 | D13: =F13+J13+N13+R13+V13 -> 0 | E13: 4070042033 | F13: 0 | G13: 0 | H13: 0 | I13: 863151778 | J13: 0 | K13: 28934162 | L13: 0 | M13: 88775127 | N13: 0 | O13: 1489803 | P13: 0 | Q13: 195192536 | R13: 0 | S13: 10685170 | T13: 0 | U13: 124543472 | V13: 0 | W13: 17327736 | X13: 0 | Y13: =+W13+S13+O13+K13 -> 58436871 | Z13: =+X13+T13+P13+L13 -> 0 | AC13: =+'Aging Analysis'!C12 -> 5341704946 | AD13: =+C13-AC13 -> 0
B14: шундан, таъминланмаган қисми | C14: =E14+I14+M14+Q14+U14 -> 0 | D14: =F14+J14+N14+R14+V14 -> 0 | Y14: =+W14+S14+O14+K14 -> 0 | Z14: =+X14+T14+P14+L14 -> 0
A15: 5 | B15: Давлат корхоналари | C15: =E15+I15+M15+Q15+U15 -> 1199739271 | D15: =F15+J15+N15+R15+V15 -> 114668975 | E15: 911268510 | F15: 61663564 | G15: 0 | H15: 2385741 | I15: 247891297 | J15: 48924829 | K15: 8313641 | L15: 2730256 | M15: 1280431 | N15: 0 | O15: 7941 | P15: 0 | Q15: 3115877 | R15: 0 | S15: 242835 | T15: 0 | U15: 36183156 | V15: 4080582 | W15: 7695045 | X15: 0 | Y15: =+W15+S15+O15+K15 -> 16259462 | Z15: =+X15+T15+P15+L15 -> 2730256 | AC15: =+'Aging Analysis'!C13 -> 1199739271 | AD15: =+C15-AC15 -> 0
B16: шундан, таъминланмаган қисми | C16: =E16+I16+M16+Q16+U16 -> 0 | D16: =F16+J16+N16+R16+V16 -> 0 | Y16: =+W16+S16+O16+K16 -> 0 | Z16: =+X16+T16+P16+L16 -> 0
A17: 6 | B17: Қўшма ва чет эл капитали иштирокидаги корхоналар | C17: =E17+I17+M17+Q17+U17 -> 0 | D17: =F17+J17+N17+R17+V17 -> 0 | E17: 0 | F17: 0 | G17: 0 | H17: 0 | I17: 0 | J17: 0 | K17: 0 | L17: 0 | M17: 0 | N17: 0 | O17: 0 | P17: 0 | Q17: 0 | R17: 0 | S17: 0 | T17: 0 | U17: 0 | V17: 0 | W17: 0 | X17: 0 | Y17: =+W17+S17+O17+K17 -> 0 | Z17: =+X17+T17+P17+L17 -> 0 | AC17: =+'Aging Analysis'!C14 -> 0 | AD17: =+C17-AC17 -> 0
B18: шундан, таъминланмаган қисми | C18: =E18+I18+M18+Q18+U18 -> 0 | D18: =F18+J18+N18+R18+V18 -> 0 | Y18: =+W18+S18+O18+K18 -> 0 | Z18: =+X18+T18+P18+L18 -> 0
A19: 7 | B19: Хусусий корхоналар | C19: =E19+I19+M19+Q19+U19 -> 5278406950 | D19: =F19+J19+N19+R19+V19 -> 2593821408 | E19: 3478272583 | F19: 1601034767 | G19: 0 | H19: 1711119 | I19: 1563477802 | J19: 903590781 | K19: 41327287 | L19: 11999892 | M19: 9364090 | N19: 741198 | O19: 174786 | P19: 74120 | Q19: 17172757 | R19: 0 | S19: 1263394 | T19: 0 | U19: 210119718 | V19: 88454662 | W19: 42589985 | X19: 1614435 | Y19: =+W19+S19+O19+K19 -> 85355452 | Z19: =+X19+T19+P19+L19 -> 13688447 | AC19: =+'Aging Analysis'!C15 -> 5278406950 | AD19: =+C19-AC19 -> 0
B20: шундан, таъминланмаган қисми | C20: =E20+I20+M20+Q20+U20 -> 0 | D20: =F20+J20+N20+R20+V20 -> 0 | Y20: =+W20+S20+O20+K20 -> 0 | Z20: =+X20+T20+P20+L20 -> 0
A21: 8 | B21: Фермер хўжалиги | C21: =E21+I21+M21+Q21+U21 -> 2040311629 | D21: =F21+J21+N21+R21+V21 -> 837019572 | E21: 1267573459 | F21: 561724428 | G21: 0 | H21: 0 | I21: 626829539 | J21: 222683588 | K21: 26820213 | L21: 9563296 | M21: 1489360 | N21: 87920 | O21: 12637 | P21: 0 | Q21: 13336598 | R21: 3072659 | S21: 322547 | T21: 0 | U21: 131082673 | V21: 49450977 | W21: 30395565 | X21: 2518007 | Y21: =+W21+S21+O21+K21 -> 57550962 | Z21: =+X21+T21+P21+L21 -> 12081303 | AC21: =+'Aging Analysis'!C16 -> 2040311629 | AD21: =+C21-AC21 -> 0
B22: шундан, таъминланмаган қисми | C22: =E22+I22+M22+Q22+U22 -> 0 | D22: =F22+J22+N22+R22+V22 -> 0 | Y22: =+W22+S22+O22+K22 -> 0 | Z22: =+X22+T22+P22+L22 -> 0
A23: 9 | B23: Нобанк молиявий институтлар | C23: =E23+I23+M23+Q23+U23 -> 0 | D23: =F23+J23+N23+R23+V23 -> 0 | E23: 0 | F23: 0 | G23: 0 | H23: 0 | I23: 0 | J23: 0 | K23: 0 | L23: 0 | M23: 0 | N23: 0 | O23: 0 | P23: 0 | Q23: 0 | R23: 0 | S23: 0 | T23: 0 | U23: 0 | V23: 0 | W23: 0 | X23: 0 | Y23: =+W23+S23+O23+K23 -> 0 | Z23: =+X23+T23+P23+L23 -> 0 | AC23: =+'Aging Analysis'!C17 -> 0 | AD23: =+C23-AC23 -> 0
B24: шундан, таъминланмаган қисми | C24: =E24+I24+M24+Q24+U24 -> 0 | D24: =F24+J24+N24+R24+V24 -> 0 | Y24: =+W24+S24+O24+K24 -> 0 | Z24: =+X24+T24+P24+L24 -> 0
A25: 10 | B25: Нодавлат нотижорат ташкилотлар | C25: =E25+I25+M25+Q25+U25 -> 576917739 | D25: =F25+J25+N25+R25+V25 -> 145454138 | E25: 311898412 | F25: 46069707 | G25: 0 | H25: 0 | I25: 231496725 | J25: 98548583 | K25: 3314543 | L25: 374416 | M25: 1464435 | N25: 0 | O25: 31536 | P25: 0 | Q25: 8769316 | R25: 0 | S25: 33046 | T25: 0 | U25: 23288851 | V25: 835848 | W25: 5001915 | X25: 0 | Y25: =+W25+S25+O25+K25 -> 8381040 | Z25: =+X25+T25+P25+L25 -> 374416 | AC25: =+'Aging Analysis'!C18 -> 576917739 | AD25: =+C25-AC25 -> 0
B26: шундан, таъминланмаган қисми | C26: =E26+I26+M26+Q26+U26 -> 0 | D26: =F26+J26+N26+R26+V26 -> 0 | Y26: =+W26+S26+O26+K26 -> 0 | Z26: =+X26+T26+P26+L26 -> 0
A27: 11 | B27: Бюджет ташкилотлари | C27: =E27+I27+M27+Q27+U27 -> 0 | D27: =F27+J27+N27+R27+V27 -> 0 | E27: 0 | F27: 0 | G27: 0 | H27: 0 | I27: 0 | J27: 0 | K27: 0 | L27: 0 | M27: 0 | N27: 0 | O27: 0 | P27: 0 | Q27: 0 | R27: 0 | S27: 0 | T27: 0 | U27: 0 | V27: 0 | W27: 0 | X27: 0 | Y27: =+W27+S27+O27+K27 -> 0 | Z27: =+X27+T27+P27+L27 -> 0 | AC27: =+'Aging Analysis'!C19 -> 0 | AD27: =+C27-AC27 -> 0
B28: шундан, таъминланмаган қисми | C28: =E28+I28+M28+Q28+U28 -> 0 | D28: =F28+J28+N28+R28+V28 -> 0 | Y28: =+W28+S28+O28+K28 -> 0 | Z28: =+X28+T28+P28+L28 -> 0
A29: 12 | B29: Бошқалар | C29: =E29+I29+M29+Q29+U29 -> 0 | D29: =F29+J29+N29+R29+V29 -> 0 | E29: 0 | F29: 0 | G29: 0 | H29: 0 | I29: 0 | J29: 0 | K29: 0 | L29: 0 | M29: 0 | N29: 0 | O29: 0 | P29: 0 | Q29: 0 | R29: 0 | S29: 0 | T29: 0 | U29: 0 | V29: 0 | W29: 0 | X29: 0 | Y29: =+W29+S29+O29+K29 -> 0 | Z29: =+X29+T29+P29+L29 -> 0 | AC29: =+'Aging Analysis'!C20 -> 0 | AD29: =+C29-AC29 -> 0
B30: шундан, таъминланмаган қисми | C30: =E30+I30+M30+Q30+U30 -> 0 | D30: =F30+J30+N30+R30+V30 -> 0 | Y30: =+W30+S30+O30+K30 -> 0 | Z30: =+X30+T30+P30+L30 -> 0
A31: 13 | B31: Жами кредит ва лизинг суммаси | C31: =+C7+C9+C11+C13+C15+C17+C19+C21+C23+C25+C27+C29 -> 14437080535 | D31: =+D7+D9+D11+D13+D15+D17+D19+D21+D23+D25+D27+D29 -> 3690964093 | E31: =+E7+E9+E11+E13+E15+E17+E19+E21+E23+E25+E27+E29 -> 10039054997 | F31: =+F7+F9+F11+F13+F15+F17+F19+F21+F23+F25+F27+F29 -> 2270492466 | G31: =+G7+G9+G11+G13+G15+G17+G19+G21+G23+G25+G27+G29 -> 0 | H31: =+H7+H9+H11+H13+H15+H17+H19+H21+H23+H25+H27+H29 -> 4096860 | I31: =+I7+I9+I11+I13+I15+I17+I19+I21+I23+I25+I27+I29 -> 3532847141 | J31: =+J7+J9+J11+J13+J15+J17+J19+J21+J23+J25+J27+J29 -> 1273747781 | ... AB31: =+AB7+AB9+AB11+AB13+AB15+AB17+AB19+AB21+AB23+AB25+AB27+AB29 -> 0 | AC31: =+'Loans Receivable'!C85 -> 14437080535 | AD31: =+C31-AC31 -> 0
B32: шундан, таъминланмаган қисми | C32: =+C8+C10+C12+C14+C16+C18+C20+C22+C24+C26+C28+C30 -> 0 | D32: =+D8+D10+D12+D14+D16+D18+D20+D22+D24+D26+D28+D30 -> 0 | E32: =+E8+E10+E12+E14+E16+E18+E20+E22+E24+E26+E28+E30 -> 0 | F32: =+F8+F10+F12+F14+F16+F18+F20+F22+F24+F26+F28+F30 -> 0 | G32: =+G8+G10+G12+G14+G16+G18+G20+G22+G24+G26+G28+G30 -> 0 | H32: =+H8+H10+H12+H14+H16+H18+H20+H22+H24+H26+H28+H30 -> 0 | I32: =+I8+I10+I12+I14+I16+I18+I20+I22+I24+I26+I28+I30 -> 0 | J32: =+J8+J10+J12+J14+J16+J18+J20+J22+J24+J26+J28+J30 -> 0 | ... Z32: =+Z8+Z10+Z12+Z14+Z16+Z18+Z20+Z22+Z24+Z26+Z28+Z30 -> 0
B33: Иқтисодиёт соҳалари бўйича
A35: 14 | B35: Саноат | C35: =E35+I35+M35+Q35+U35 -> 3795740987 | D35: =F35+J35+N35+R35+V35 -> 2219067047 | E35: 2482256422 | F35: 1354737090 | G35: 0 | H35: 1711119 | I35: 1146719349 | J35: 785678275 | K35: 26683979 | L35: 12526875 | M35: 8830983 | N35: 741198 | O35: 94765 | P35: 74120 | Q35: 14554391 | R35: 0 | S35: 1183984 | T35: 0 | U35: 143379842 | V35: 77910484 | W35: 20153888 | X35: 1614435 | Y35: =+W35+S35+O35+K35 -> 48116616 | Z35: =+X35+T35+P35+L35 -> 14215430 | AC35: =+'Aging Analysis'!C25 -> 3795740987 | AD35: =+C35-AC35 -> 0
B36: шундан, таъминланмаган қисми | C36: =E36+I36+M36+Q36+U36 -> 0 | D36: =F36+J36+N36+R36+V36 -> 0 | Y36: =+W36+S36+O36+K36 -> 0 | Z36: =+X36+T36+P36+L36 -> 0
A37: 15 | B37: Қишлоқ хўжалиги | C37: =E37+I37+M37+Q37+U37 -> 2471330376 | D37: =F37+J37+N37+R37+V37 -> 869682520 | E37: 1581710576 | F37: 578535182 | G37: 0 | H37: 2385741 | I37: 733774554 | J37: 238535782 | K37: 32726795 | L37: 11385369 | M37: 1919694 | N37: 87920 | O37: 20577 | P37: 0 | Q37: 14789792 | R37: 3072659 | S37: 351320 | T37: 0 | U37: 139135760 | V37: 49450977 | W37: 30395565 | X37: 2518007 | Y37: =+W37+S37+O37+K37 -> 63494257 | Z37: =+X37+T37+P37+L37 -> 13903376 | AC37: =+'Aging Analysis'!C26 -> 2471330376 | AD37: =+C37-AC37 -> 0
B38: шундан, таъминланмаган қисми | C38: =E38+I38+M38+Q38+U38 -> 0 | D38: =F38+J38+N38+R38+V38 -> 0 | Y38: =+W38+S38+O38+K38 -> 0 | Z38: =+X38+T38+P38+L38 -> 0
A39: 16 | B39: Транспорт ва коммуникация | C39: =E39+I39+M39+Q39+U39 -> 275718959 | D39: =F39+J39+N39+R39+V39 -> 53025531 | E39: 210574404 | F39: 24884473 | G39: 0 | H39: 0 | I39: 61480751 | J39: 28141058 | K39: 853868 | L39: 309611 | M39: 216103 | N39: 0 | O39: 38761 | P39: 0 | Q39: 219896 | R39: 0 | S39: 7131 | T39: 0 | U39: 3227805 | V39: 0 | W39: 408641 | X39: 0 | Y39: =+W39+S39+O39+K39 -> 1308401 | Z39: =+X39+T39+P39+L39 -> 309611 | AC39: =+'Aging Analysis'!C27 -> 275718959 | AD39: =+C39-AC39 -> 0
B40: шундан, таъминланмаган қисми | C40: =E40+I40+M40+Q40+U40 -> 0 | D40: =F40+J40+N40+R40+V40 -> 0 | Y40: =+W40+S40+O40+K40 -> 0 | Z40: =+X40+T40+P40+L40 -> 0
A41: 17 | B41: Қурилиш соҳаси | C41: =E41+I41+M41+Q41+U41 -> 858938251 | D41: =F41+J41+N41+R41+V41 -> 82588239 | E41: 694890599 | F41: 61281531 | G41: 0 | H41: 0 | I41: 123753064 | J41: 17679241 | K41: 3707142 | L41: 64911 | M41: 0 | N41: 0 | O41: 0 | P41: 0 | Q41: 119955 | R41: 0 | S41: 0 | T41: 0 | U41: 40174633 | V41: 3627467 | W41: 13620276 | X41: 0 | Y41: =+W41+S41+O41+K41 -> 17327418 | Z41: =+X41+T41+P41+L41 -> 64911 | AC41: =+'Aging Analysis'!C28 -> 858938251 | AD41: =+C41-AC41 -> 0
B42: шундан, таъминланмаган қисми | C42: =E42+I42+M42+Q42+U42 -> 0 | D42: =F42+J42+N42+R42+V42 -> 0 | Y42: =+W42+S42+O42+K42 -> 0 | Z42: =+X42+T42+P42+L42 -> 0
...

Sheet Asset Provisioning
A1: АКТИВЛАР ВА УЛАРНИНГ ТАСНИФИ БЎЙИЧА ШАКЛЛАНТИРИЛГАН ЗАХИРАЛАР | AT1: 10 А-жадвал
B3: =+'Asset quality'!B3 -> "MKBANK" | AH3: =+'Asset quality'!Q3 -> 45289 | AU3: =+'Asset quality'!T3 -> минг. сўмда
A4: № | B4: Кўрсаткичлар | C4: Жами суммаси | D4: шундан, хорижий валютада (экв. сўмда) | E4: Стандарт | F4: шундан, хорижий валютада (экв. сўмда) | G4: Стандарт активлар бўйича яратилган захиралар (мин 1%) | J4: Субстандарт | K4: шундан, хорижий валютада (экв. сўмда) | L4: Субстандарт активлар бўйича яратилган захиралар (мин 10%) | O4: шундан, хорижий валютада (экв. сўмда) | R4: Қониқарсиз | S4: шундан, хорижий валютада (экв. сўмда) | T4: Қониқарсиз активлар бўйича яратилган захиралар (мин 25%) | W4: шундан, хорижий валютада (экв. сўмда) | Z4: Шубҳали | AA4: шундан, хорижий валютада (экв. сўмда) | AB4: Шубҳали активлар бўйича яратилган захиралар (мин 50%) | AE4: шундан, хорижий валютада (экв. сўмда) | AH4: Умидсиз | AI4: шундан, хорижий валютада (экв. сўмда) | AJ4: Умидсиз активлар бўйича яратилган захиралар (мин 100%) | AM4: шундан, хорижий валютада (экв. сўмда) | AP4: Жами махсус захиралар суммаси | AS4: шундан, хорижий валютада (экв. сўмда)
