Workbook
Name jop: #REF!
Name kol: #REF!
Name RISKTOTASS: SUM('[6]Calculation of Risk Weighted As'!$C$38:$F$38)
Name RISKTOTASS: SUM('[7]Calculation of Risk Weighted As'!$C$41:$G$41)
Name TwentyLargestData: #REF!
Name Е: #REF!

Sheet Asset quality
A1: ИНФОРМАЦИЯ О КАЧЕСТВЕ АКТИВОВ, ОЦЕНИВАЕМЫХ В ЦЕЛЯХ СОЗДАНИЯ РЕЗЕРВА НА ВОЗМОЖНЫЕ ПОТЕРИ | R1: Таблица-2 | U1: №4
B3: "Микрокредитбанк" | P3: 44560 | S3: тыс. сум
A4: № | B4: Состав активов* | C4: Остаток | D4: Категория качества | I4: Просроченная задолженность (брутто) | N4: Резерв на возможные потери
I5: итого | J5: до 30 дней | K5: от 31 до 90 дней | L5: от 91 до 180 дней | M5: свыше 180 дней | N5: фактически сформированный
N6: итого | O6: по категориям качества
D7: I | E7: II | F7: III | G7: IV | H7: V | O7: I | P7: II | Q7: III | R7: IV | S7: V
A8: А | B8: Б | C8: В | D8: Г | E8: Д | F8: Е | G8: Ж | H8: З | I8: И | J8: К | K8: Л | L8: М | M8: Н | N8: О | O8: П | P8: Р | Q8: С | R8: Т | S8: У
B9: ВСЕГО АКТИВОВ | C9: =SUM(C10:C60) -> 13483353628 | D9: =SUM(D10:D60) -> 12077945561 | E9: =SUM(E10:E60) -> 987112434 | F9: =SUM(F10:F60) -> 238045786 | G9: =SUM(G10:G60) -> 79824583 | H9: =SUM(H10:H60) -> 324379884 | I9: =SUM(I10:I60) -> 5.2554761e+08 | J9: =SUM(J10:J60) -> 29459953 | ... S9: =SUM(S10:S60) -> 58157915
A10: 1 | B10: Кассовая наличность и другие платежные документы | C10: =SUM(D10:H10)-N10+O10 -> 296970170 | D10: 296970170 | I10: =SUM(J10:M10) -> 0 | N10: =SUM(O10:S10) -> 0 | T10: 10100
A11: 2 | B11: К получению из ЦБРУ | C11: =SUM(D11:H11)-N11+O11 -> 580486618 | D11: 580486618 | I11: =SUM(J11:M11) -> 0 | N11: =SUM(O11:S11) -> 0 | T11: 10300
A12: 3 | B12: К получению из других банков | C12: =SUM(D12:H12)-N12+O12 -> 530524890 | D12: 531246576 | I12: =SUM(J12:M12) -> 0 | N12: =SUM(O12:S12) -> 721686 | P12: 721686 | T12: 10500
A13: 4 | B13: Ценные бумаги для купли и продажи | C13: =SUM(D13:H13)-N13+O13 -> 507168618 | D13: 507168618 | I13: =SUM(J13:M13) -> 0 | N13: =SUM(O13:S13) -> 0 | T13: 10700
A14: 5 | B14: Инвестиции в ценные бумаги, имеющиеся в наличии для продажи | C14: =SUM(D14:H14)-N14+O14 -> 0 | I14: =SUM(J14:M14) -> 0 | N14: =SUM(O14:S14) -> 0 | T14: 10800
A15: 6 | B15: Драгоценные металлы, камни и монеты для купли и продажи | C15: =SUM(D15:H15)-N15+O15 -> 175 | D15: 175 | I15: =SUM(J15:M15) -> 0 | N15: =SUM(O15:S15) -> 0 | T15: 10900
A16: 7 | B16: Купленные дебиторские задолженности - Факторинг | C16: =SUM(D16:H16)-N16+O16 -> 88085139 | D16: 86150000 | E16: 146063 | F16: 2213814 | G16: 0 | H16: -150000 | I16: =SUM(J16:M16) -> 2657377 | J16: 0 | K16: 0 | L16: 0 | M16: 2657377 | N16: =SUM(O16:S16) -> 274738 | O16: 0 | P16: 18357 | Q16: 246381 | R16: 0 | S16: 10000 | T16: 11100
A17: 8 | B17: Купленные векселя | C17: =SUM(D17:H17)-N17+O17 -> 0 | I17: =SUM(J17:M17) -> 0 | N17: =SUM(O17:S17) -> 0 | T17: 11300
A18: 9 | B18: Обязательства клиентов по траттам под аккредитив и/или трастовые документы | C18: =SUM(D18:H18)-N18+O18 -> 0 | I18: =SUM(J18:M18) -> 0 | N18: =SUM(O18:S18) -> 0 | T18: 11500
A19: 10 | B19: Обязательства лиентов по непогашенным акцептам банка | C19: =SUM(D19:H19)-N19+O19 -> 0 | I19: =SUM(J19:M19) -> 0 | N19: =SUM(O19:S19) -> 0 | T19: 11700
A20: 11 | B20: Купленные по сделкам РЕПО ценные бумаги | C20: =SUM(D20:H20)-N20+O20 -> 0 | I20: =SUM(J20:M20) -> 0 | N20: =SUM(O20:S20) -> 0 | T20: 11800
A21: 12 | B21: Краткосрочные кредиты, предоставленные ЦБРУ | C21: =SUM(D21:H21)-N21+O21 -> 0 | I21: =SUM(J21:M21) -> 0 | N21: =SUM(O21:S21) -> 0 | T21: 11900
A22: 13 | B22: Краткосрочные кредиты, предоставленные другим банкам | C22: =SUM(D22:H22)-N22+O22 -> 0 | I22: =SUM(J22:M22) -> 0 | N22: =SUM(O22:S22) -> 0 | T22: 12100
A23: 14 | B23: Краткосрочные кредиты, предоставленные правительству | C23: =SUM(D23:H23)-N23+O23 -> 0 | I23: =SUM(J23:M23) -> 0 | N23: =SUM(O23:S23) -> 0 | T23: 12300
A24: 15 | B24: Краткосрочные кредиты, предоставленные бюджетным организациям | C24: =SUM(D24:H24)-N24+O24 -> 0 | I24: =SUM(J24:M24) -> 0 | N24: =SUM(O24:S24) -> 0 | T24: 12400
A25: 16 | B25: Краткосрочные кредиты, предоставленные физическим лицам | C25: =SUM(D25:H25)-N25+O25 -> 223618998 | D25: 215030215 | E25: 6153590 | F25: 1059885 | G25: 613516 | H25: 6496805 | I25: =SUM(J25:M25) -> 11422396 | J25: 769491.31 | K25: 994300.39 | L25: 1209303 | M25: 8449301.8 | N25: =SUM(O25:S25) -> 5735013 | P25: 624744 | Q25: 264971 | R25: 306758 | S25: 4538540 | T25: 12500
A26: 17 | B26: Краткосрочные кредиты, предоставленные индивидуальным предпринимателям | C26: =SUM(D26:H26)-N26+O26 -> 58425837 | D26: 56422695 | E26: 1714441 | F26: 223298 | G26: 3284 | H26: 547243 | I26: =SUM(J26:M26) -> 2215730.8 | J26: 176420.07 | K26: 368824.22 | L26: 414783.01 | M26: 1255703.5 | N26: =SUM(O26:S26) -> 485124 | P26: 171444 | Q26: 55824 | R26: 1642 | S26: 256214 | T26: 12600
A27: 18 | B27: Краткосрочные кредиты, предоставленные государственным предприятиям, организациям и учреждениям | C27: =SUM(D27:H27)-N27+O27 -> 194269273 | D27: 188555881 | E27: 3244733 | F27: 2555556 | G27: 0 | H27: 183333 | I27: =SUM(J27:M27) -> 6428066.1 | J27: 0 | K27: 0 | L27: 444444.45 | M27: 5983621.7 | N27: =SUM(O27:S27) -> 270230 | P27: 14674 | Q27: 255556 | R27: 0 | S27: 0 | T27: 12700
A28: 19 | B28: Краткосрочные кредиты, предоставленные при содействии Государственного фонда поддержки развития предпринимательской деятельности | C28: =SUM(D28:H28)-N28+O28 -> 0 | I28: =SUM(J28:M28) -> 0 | N28: =SUM(O28:S28) -> 0 | T28: 12800
A29: 20 | B29: Краткосрочные кредиты, предоставленные предприятиям с участием иностранного капитала | C29: =SUM(D29:H29)-N29+O29 -> 3119234 | D29: 3004325 | E29: 127677 | F29: 0 | G29: 0 | H29: 0 | I29: =SUM(J29:M29) -> 0 | J29: 0 | K29: 0 | L29: 0 | M29: 0 | N29: =SUM(O29:S29) -> 12768 | P29: 12768 | Q29: 0 | R29: 0 | S29: 0 | T29: 12900
A30: 21 | B30: Краткосрочные кредиты, предоставленные негосударственным некоммерческим организациям | C30: =SUM(D30:H30)-N30+O30 -> 35783 | D30: 35783 | I30: =SUM(J30:M30) -> 0 | N30: =SUM(O30:S30) -> 0 | T30: 13000
A31: 22 | B31: Краткосрочные кредиты, предоставленные частным предприятиям, хозяйственным товариществам и обществам | C31: =SUM(D31:H31)-N31+O31 -> 605381210 | D31: 543208972 | E31: 53402042 | F31: 9718689 | G31: 4001 | H31: 7417828 | I31: =SUM(J31:M31) -> 75150752 | J31: 3365231.2 | K31: 15904653 | L31: 13772101 | M31: 42108767 | N31: =SUM(O31:S31) -> 8370322 | P31: 7506446 | Q31: 609345 | R31: 2001 | S31: 252530 | T31: 13100
A32: 23 | B32: Краткосрочные кредиты, предоставленные небанковским финансовым институтам | C32: =SUM(D32:H32)-N32+O32 -> 21600 | D32: 21600 | E32: 0 | F32: 0 | G32: 0 | H32: 0 | I32: =SUM(J32:M32) -> 0 | J32: 0 | K32: 0 | L32: 0 | M32: 0 | N32: =SUM(O32:S32) -> 0 | P32: 0 | Q32: 0 | R32: 0 | S32: 0 | T32: 13200
A33: 24 | B33: Краткосрочные кредиты, предоставленные для производства сельскохозяйственной продукции, закупаемой для государственных нужд | C33: =SUM(D33:H33)-N33+O33 -> 0 | I33: =SUM(J33:M33) -> 0 | N33: =SUM(O33:S33) -> 0 | T33: 13300
A34: 25 | B34: Долгосрочные кредиты, предоставленные для производства сельскохозяйственной продукции, закупаемой для государственных нужд | C34: =SUM(D34:H34)-N34+O34 -> 0 | I34: =SUM(J34:M34) -> 0 | N34: =SUM(O34:S34) -> 0 | T34: 14300
A35: 26 | B35: Долгосрочные кредиты, предоставленные при содействии Государственного фонда поддержки развития предпринимательской деятельности | C35: =SUM(D35:H35)-N35+O35 -> 73822747 | D35: 73635161 | E35: 63680 | F35: 42823 | G35: 0 | H35: 98157 | I35: =SUM(J35:M35) -> 204660.47 | J35: 0 | K35: 63680.021 | L35: 42823.289 | M35: 98157.16 | N35: =SUM(O35:S35) -> 17074 | P35: 6368 | Q35: 10706 | R35: 0 | S35: 0 | T35: 14400
A36: 27 | B36: Долгосрочные кредиты, предоставленные другим банкам | C36: =SUM(D36:H36)-N36+O36 -> 0 | I36: =SUM(J36:M36) -> 0 | N36: =SUM(O36:S36) -> 0 | T36: 14500
A37: 28 | B37: Долгосрочные кредиты, предоставленные правительству | C37: =SUM(D37:H37)-N37+O37 -> 0 | I37: =SUM(J37:M37) -> 0 | N37: =SUM(O37:S37) -> 0 | T37: 14700
A38: 29 | B38: Долгосрочные кредиты, предоставленные бюджетным организациям | C38: =SUM(D38:H38)-N38+O38 -> 0 | I38: =SUM(J38:M38) -> 0 | N38: =SUM(O38:S38) -> 0 | T38: 14800
A39: 30 | B39: Долгосрочные кредиты, предоставленные физическим лицам | C39: =SUM(D39:H39)-N39+O39 -> 2740002132 | D39: 2241664352 | E39: 273179063 | F39: 49463882 | G39: 60496634 | H39: 230323975 | I39: =SUM(J39:M39) -> 1.7312444e+08 | J39: 7731407.5 | K39: 24738799 | L39: 30219634 | M39: 1.104346e+08 | N39: =SUM(O39:S39) -> 115125774 | P39: 27298146 | Q39: 11987298 | R39: 29070764 | S39: 46769566 | T39: 14900
A40: 31 | B40: Долгосрочные кредиты, предоставленные индивидуальным предпринимателям | C40: =SUM(D40:H40)-N40+O40 -> 233254582 | D40: 175109896 | E40: 22450098 | F40: 3626845 | G40: 7413242 | H40: 34877578 | I40: =SUM(J40:M40) -> 44494777 | J40: 1087054.7 | K40: 3573730.8 | L40: 5430489.6 | M40: 34403502 | N40: =SUM(O40:S40) -> 10223077 | P40: 2090826 | Q40: 876059 | R40: 3577727 | S40: 3678465 | T40: 15000
A41: 32 | B41: Долгосрочные кредиты, предоставленные государственным предприятиям, организациям и учреждениям | C41: =SUM(D41:H41)-N41+O41 -> 126208157 | D41: 70827876 | E41: 59950526 | F41: 1282051 | G41: 0 | H41: 270962 | I41: =SUM(J41:M41) -> 4807129.6 | J41: 206250 | K41: 0 | L41: 3047866.8 | M41: 1553012.8 | N41: =SUM(O41:S41) -> 6123258 | P41: 5995053 | Q41: 128205 | R41: 0 | S41: 0 | T41: 15100
...

Sheet Income 
B1: ОТЧЕТ О ФИНАНСОВЫХ РЕЗУЛЬТАТАХ | D1: Таблица-3
B3: =+'Asset quality'!B3 -> "Микрокредитбанк" | C3: =+'Asset quality'!P3 -> 44560 | E3: в тыс. сум
A4: № | B4: Категории | C4: Итого | D4: в национальной валюте | E4: в иностранной валюте (в экв. в сумах)
A5: 1. | B5: 1. ПРОЦЕНТНЫЕ ДОХОДЫ
A6: a. | B6: Процентные доходы по счетам в ЦБРУ | C6: =+D6+E6 -> 11869803 | D6: 11869803
A7: б. | B7: Процентные доходы по счетам в других банках | C7: =+D7+E7 -> 28944280 | D7: 28944280
A8: в. | B8: Процентные доходы по купленным векселям | C8: =+D8+E8 -> 0 | D8: 0
A9: г. | B9: Процентные доходы по инвестициям | C9: =+D9+E9 -> 0 | D9: 0
A10: д. | B10: Процентные доходы по счетам купли-продажи ценных бумаг | C10: =+D10+E10 -> 44382395 | D10: 44382395
A11: е. | B11: Процентные доходы по обязательствам клиентов | C11: =+D11+E11 -> 0 | D11: 0
A12: ж. | B12: Процентные доходы по обяз-вам клиентов по непогашенным акцептам этого банка | C12: =+D12+E12 -> 0 | D12: 0
A13: з. | B13: Процент, Дисконт (Скидки) и взносы по кредитным и лизинговым операциям | C13: =+D13+E13 -> 1385765541 | D13: 1385765541
A14: и. | B14: Процентные доходы по соглашениям о покупке ценных бумаг с обратным выкупом | C14: =+D14+E14 -> 0 | D14: 0
A15: к. | B15: Другие процентные доходы | C15: =+D15+E15 -> 721832881 | D15: 721832881
A16: л. | B16: Итого процентных доходов | C16: =SUM(C6:C15) -> 2192794900 | D16: =SUM(D6:D15) -> 2192794900 | E16: =SUM(E6:E15) -> 0 | G16: =+'Analysis of Interest'!C42 -> 2192794900
A18: 2. | B18: ПРОЦЕНТНЫЕ РАСХОДЫ
A19: а. | B19: Процентные расходы по депозитам до востребования | C19: =+D19+E19 -> 10598750 | D19: 10598750
A20: б. | B20: Процентные расходы по срочным депозитам | C20: =+D20+E20 -> 315483464 | D20: 315483464
A21: в. | B21: Процентные расходы по счетам к оплате в ЦБРУ | C21: =+D21+E21 -> 0 | D21: 0
A22: г. | B22: Процентные расходы по счетам к оплате в другие банки | C22: =+D22+E22 -> 153216785 | D22: 153216785
A23: д. | B23: Итого процентных расходов по депозитам | C23: =SUM(C19:C22) -> 479298999 | D23: =SUM(D19:D22) -> 479298999 | E23: =SUM(E19:E22) -> 0
A24: е. | B24: Процентные расходы по кредитам к оплате | C24: =+D24+E24 -> 368022621 | D24: 368022621
A25: ж. | B25: Процентные расходы по соглашениям о продаже ц/б с последующим выкупом | C25: =+D25+E25 -> 0 | D25: 0
A26: з. | B26: Другие процентные расходы | C26: =+D26+E26 -> 720214053 | D26: 720214053
A27: и. | B27: Итого процентных расходов по займам | C27: =SUM(C24:C26) -> 1088236674 | D27: =SUM(D24:D26) -> 1088236674 | E27: =SUM(E24:E26) -> 0
A28: л. | B28: Итого процентных расходов | C28: =C27+C23 -> 1567535673 | D28: =D27+D23 -> 1567535673 | E28: =E27+E23 -> 0 | G28: =+'Analysis of Interest'!C72 -> 1567535673
A30: 3. | B30: ЧИСТЫЕ ПРОЦЕНТНЫЕ ДОХОДЫ ДО ОЦЕНКИ ВОЗМОЖНЫХ УБЫТКОВ ПО АКТИВАМ | C30: =C16-C28 -> 625259227 | D30: =D16-D28 -> 625259227 | E30: =E16-E28 -> 0
A31: а. | B31: Минус: Оценка возможных убытков по кредитам и лизингу | C31: =+D31+E31 -> 432519815 | D31: 432519815
A32: б. | B32: Минус: Оценка возможных убытков по в ценным бумагам | C32: =+D32+E32 -> 0 | D32: 0 | E32: 0
A33: в. | B33: Минус: Оценка возможных убытков по инвестициям | C33: =+D33+E33 -> 0 | D33: 0 | E33: 0
A34: г. | B34: Минус: Оценка возможных убытков по другим активам | C34: =+D34+E34 -> 2000 | D34: 2000 | E34: 0
A35: д. | B35: Чистые процентные доходы после оценки возможных убытков по кредитам и лизингу | C35: =C30-C31-C32-C33-C34 -> 192737412 | D35: =D30-D31-D32-D33-D34 -> 192737412 | E35: =E30-E31-E32-E33-E34 -> 0
A37: 4. | B37: БЕСПРОЦЕНТНЫЕ ДОХОДЫ
A38: а. | B38: Доходы от комиссий и платы за услуги | C38: =+D38+E38 -> 125051652 | D38: 125051652
A39: б. | B39: Прибыль в иностранной валюте | C39: =+D39+E39 -> 186840469 | D39: 0 | E39: 186840469
A40: в. | B40: Прибыль от коммерческих операций | C40: =+D40+E40 -> 0 | D40: 0
A41: г. | B41: Прибыль и дивиденды от инвестиций | C41: =+D41+E41 -> 167042 | D41: 167042
A42: д. | B42: Другие беспроцентные доходы | C42: =+D42+E42 -> 236403493 | D42: 236403493
B43: в том числе | D43: 0
A44: д1. | B44: Возврат резервов, с формированных на покрытие потерь по активам | C44: =+D44+E44 -> 0 | D44: 0
...

Sheet Analysis of Interest
B1: АНАЛИЗ ПРОЦЕНТНЫХ ДОХОДОВ И РАСХОДОВ | C1: Таблица-4
B3: =+'Asset quality'!B3 -> "Микрокредитбанк" | C3: =+'Asset quality'!P3 -> 44560
A4: № | B4: Категория | C4: в тыс. сум
A5: 1 . | B5: ПРОЦЕНТНЫЕ ДОХОДЫ ПО КРЕДИТНЫМ И ЛИЗИНГОВЫМ ОПЕРАЦИЯМ
A6: a. | B6: Кредиты и лизинговые операции ЦБРУ | C6: 0
A7: б. | B7: Кредиты и лизинговые операции другим банкам | C7: 11697
A8: в. | B8: Кредиты и лизинговые операции Правительству | C8: 32083
A9: г. | B9: Кредиты и лизинговые операции физическим лицам | C9: 496488310
A10: д. | B10: Кредиты и лизинговые операции государственным предприятиям | C10: 25507020
A11: е. | B11: Кредиты и лизинговые операции совместным и иностранным предприятиям | C11: 30412235
A12: ж. | B12: Кредиты и лизинговые операции частным товариществам и корпорациям | C12: 778891183
A13: з. | B13: Другие кредиты и лизинговые операции | C13: 54423014
A14: и. | B14: ИТОГО ПРОЦЕНТНЫХ ДОХОДОВ ПО КРЕДИТНЫМ И ЛИЗИНГОВЫМ ОПЕРАЦИЯМ | C14: =SUM(C6:C13) -> 1385765542
A16: 2. | B16: ПРОЦЕНТНЫЕ ДОХОДЫ ПО КОРРЕСПОНДЕНТСКИМ СЧЕТАМ
A17: a. | B17: К получению из ЦБРУ | C17: 11869803
A18: б. | B18: К получению из других банков | C18: 28944280
B19: ИТОГО ПРОЦЕНТНЫХ ДОХОДОВ ПО КОРРЕСПОНДЕНТСКИМ СЧЕТАМ | C19: =SUM(C17:C18) -> 40814083
A21: 3. | B21: ПРОЦЕНТНЫЕ ДОХОДЫ ПО СЧЕТАМ КУПЛИ-ПРОДАЖИ Ц/Б
A22: a. | B22: Государственные казначейские ценные бумаги | C22: 13519097
A23: б. | B23: Облигации и ценные бумаги ЦБРУ | C23: 30863299
A24: в. | B24: Ценные бумаги государственных корпораций | C24: 0
A25: г. | B25: Еврооблигации | C25: 0
A26: д. | B26: Частные ценные бумаги | C26: 0
A27: е. | B27: Другие ценные бумаги | C27: 0
A28: ж. | B28: ИТОГО ПРОЦЕНТНЫХ ДОХОДОВ ПО СЧЕТАМ КУПЛИ-ПРОДАЖИ Ц/Б | C28: =SUM(C22:C27) -> 44382396
A30: 4. | B30: ПРОЦЕНТНЫЕ ДОХОДЫ ПО ИНВЕСТИЦИЯМ
A31: a. | B31: Государственные облигации | C31: 0
A32: б. | B32: Облигации и ценные бумаги ЦБРУ | C32: 0
A33: в. | B33: Частные облигации | C33: 0
A34: г. | B34: Еврооблигации | C34: 0
A35: д. | B35: Другие ценные бумаги | C35: 0
A36: е. | B36: ИТОГО ПРОЦЕНТНЫХ ДОХОДОВ ПО ИНВЕСТИЦИЯМ | C36: =SUM(C31:C35) -> 0
A38: 5. | B38: ДРУГИЕ ПРОЦЕНТНЫЕ ДОХОДЫ
A39: a. | B39: Процентные доходы по соглашениям о покупке ц/б c обратным выкупом | C39: 0
A40: б. | B40: Другие процентные доходы | C40: 721832879
A42: 6. | B42: ИТОГО ПРОЦЕНТНЫХ ДОХОДОВ | C42: =C14+C19+C28+C36+C39+C40 -> 2192794900
A44: 7. | B44: ПРОЦЕНТНЫЕ РАСХОДЫ ПО ДЕПОЗИТАМ
A45: A. | B45: Депозиты до востребования
A46: a. | B46: Правительство | C46: 0
A47: б. | B47: Физические лица | C47: 125439
...

Sheet Changes in Equity
B1: ИЗМЕНЕНИЯ В СОБСТВЕННОМ КАПИТАЛЕ | C1: Таблица-7
B3: =+'Asset quality'!B3 -> "Микрокредитбанк" | C3: =+'Asset quality'!P3 -> 44560
A4: № | B4: Категория | C4: в тыс. сум
A5: 1. | B5: Итого собственного капитала первоначально определенного за прошлый год | C5: 1625105476
A6: 2. | B6: Исправления в собственном капитале не показанные в отчете за прошлый год, чистые | C6: 0
A7: 3. | B7: Исправленный баланс на конец прошлого календарного года (сумма строк 1 и 2) | C7: =SUM(C5:C6) -> 1625105476
A8: 4. | B8: Чистый прибыль (убыток) по состоянию на дату от начала года | C8: =+'Income '!C79 -> 38443086 | D8: =+[8]Balance!$C$76 -> 38443086
A9: 5. | B9: Продажа, Обмен, Приобретение или выкуп акций, за текущий год (чистая выручка) | C9: 555413966
A10: 6. | B10: Изменения в оценочной стоимости прироста над первонач. стоимостью, за текущий год (чистые) | C10: 8940159
A11: 7. | B11: МИНУС: Денежные дивиденды объявленные по привилегированным акциям | C11: 0
A12: 8. | B12: МИНУС: Денежные дивиденды объявленные по обыкновенным акциям | C12: 0
A13: 9. | B13: Другие статьи влияющие на собственный капитал за текущий год (чистые) | C13: 93193543
A14: 10. | B14: Итого собственного капитала на конец текущего периода (сумма строк с 3 по 10) | C14: =C7+SUM(C8:C10)-SUM(C11:C12)+C13 -> 2321096230 | D14: =+[8]Balance!$C$77 -> 2321096230
B16: Подпись Председателя правления:
B18: Подпись Главного Бухгалтера:

Sheet Loans Receivable
A1: КРЕДИТЫ И ЛИЗИНГИ К ПОЛУЧЕНИЮ ПО ОТРАСЛЯМ ЭКОНОМИКИ, ТИПАМ КЛИЕНТОВ И ПО ТИПУ ОБЕСПЕЧЕНИЯ | W1: Таблица-8
B3: =+'Asset quality'!B3 -> "Микрокредитбанк" | T3: =+'Asset quality'!P3 -> 44560 | X3: тыс. сум
A4: № | B4: Отрасль экономики | C4: Сумма кредита | D4: в национальной валюте | F4: в иностранной валюте (в экв. в сумах) | H4: из них | J4: из них
D5: Сумма | E5: средне-взвешенные процентные ставки | F5: Сумма | G5: средне-взвешенные процентные ставки | H5: Начисляемые кредиты | I5: Кредиты переведённые в статус ненаращивания процентов | J5: Депозиты | K5: Гарантированные Правительством Республики Узбекистан | L5: из них | M5: Транспортные средства | N5: Инвентарь | O5: Недвижимость | P5: из них | R5: Оборудование | S5: Векселя (облигации) | T5: Акции | U5: Гарантия третьей стороны | V5: Поручительства третьей стороны | W5: Страховой полис | X5: Необеспеченные | Y5: Другое обеспечение
L6: Гарантированные Правительством Республики Узбекистан в иностранной валюте (экв.сум) | P6: жилая недвижимость | Q6: коммерческая недвижимость
A7: Код | B7: (А) | C7: (Б) | D7: (Б1) | E7: (Б2) | F7: (Б3) | G7: (Б4) | H7: (В) | I7: (Г) | J7: (Д) | K7: (Е) | L7: (Е1) | M7: (Ж) | N7: (З) | O7: (И) | P7: (И1) | Q7: (И2) | R7: (К) | S7: (Л) | T7: (М) | U7: (Н) | V7: (О) | W7: (П) | X7: (Р) | Y7: (С)
B8: Промышленность
A9: 10 | B9: Физические лица | C9: =SUM(J9:Y9)-L9-P9-Q9 -> 317557 | D9: 317557 | E9: 0.069527593 | F9: 0 | G9: 0 | H9: 317557 | J9: 0 | K9: 0 | L9: 0 | M9: 0 | N9: 0 | O9: =+P9+Q9 -> 15608 | P9: 8242 | Q9: 7366 | R9: 0 | S9: 0 | T9: 0 | U9: 0 | V9: 301948 | W9: 1 | X9: 0 | Y9: 0
A10: =A9+10 -> 20 | B10: Государственные предприятия | C10: =SUM(J10:Y10)-L10-P10-Q10 -> 22820466 | D10: 22820466 | E10: 0.14019927 | F10: 0 | G10: 0 | H10: 22820466 | I10: 0 | J10: 0 | K10: 0 | L10: 0 | M10: 0 | N10: 0 | O10: =+P10+Q10 -> 22787466 | P10: 75790 | Q10: 22711676 | R10: 0 | S10: 0 | T10: 0 | U10: 0 | V10: 0 | W10: 0 | X10: 0 | Y10: 33000
A11: =A10+10 -> 30 | B11: Совместные и иностранные предприятия | C11: =SUM(J11:Y11)-L11-P11-Q11 -> 137504047 | D11: 59208913 | E11: 0.19965753 | F11: 78295134 | G11: 0.10209576 | H11: 137504047 | I11: 0 | J11: 0 | K11: 0 | L11: 0 | M11: 2102759 | N11: 0 | O11: =+P11+Q11 -> 114120728 | P11: 532057 | Q11: 113588671 | R11: 0 | S11: 0 | T11: 0 | U11: 0 | V11: 3658743 | W11: 17621817 | X11: 0 | Y11: 0
A12: =A11+10 -> 40 | B12: Частные товарищества и корпорации | C12: =SUM(J12:Y12)-L12-P12-Q12 -> 1778208889 | D12: 569285347 | E12: 0.15047854 | F12: 1208923542 | G12: 0.092408985 | H12: 1778208889 | I12: 0 | J12: 0 | K12: 0 | L12: 0 | M12: 85786723 | N12: 193542 | O12: =+P12+Q12 -> 1395778149 | P12: 244109980 | Q12: 1151668169 | R12: 6392129 | S12: 0 | T12: 0 | U12: 2398337 | V12: 65874031 | W12: 221658892 | X12: 0 | Y12: 127086
A13: =A12+10 -> 50 | B13: Правительство | C13: =SUM(J13:Y13)-L13-P13-Q13 -> 0 | D13: 0 | E13: 0 | F13: 0 | G13: 0 | H13: 0 | J13: 0 | K13: 0 | L13: 0 | M13: 0 | N13: 0 | O13: =+P13+Q13 -> 0 | P13: 0 | Q13: 0 | R13: 0 | S13: 0 | T13: 0 | U13: 0 | V13: 0 | W13: 0 | X13: 0 | Y13: 0
A14: =A13+10 -> 60 | B14: Прочие | C14: =SUM(J14:Y14)-L14-P14-Q14 -> 0 | D14: 0 | E14: 0 | F14: 0 | G14: 0 | H14: 0 | J14: 0 | K14: 0 | L14: 0 | M14: 0 | N14: 0 | O14: =+P14+Q14 -> 0 | P14: 0 | Q14: 0 | R14: 0 | S14: 0 | T14: 0 | U14: 0 | V14: 0 | W14: 0 | X14: 0 | Y14: 0
A15: =A14+10 -> 70 | B15: Итого по промышленности | C15: =SUM(J15:Y15)-L15-P15-Q15 -> 1938850959 | D15: =SUM(D9:D14) -> 651632283 | E15: =IFERROR(((D9*E9)/D15)+((D10*E10)/D15)+((D11*E11)/D15)+((D12*E12)/D15)+((D13*E13)/D15)+((D14*E14)/D15),0) -> 0.15454763 | F15: =SUM(F9:F14) -> 1287218676 | G15: =IFERROR(((F9*G9)/F15)+((F10*G10)/F15)+((F11*G11)/F15)+((F12*G12)/F15)+((F13*G13)/F15)+((F14*G14)/F15),0) -> 0.092998183 | H15: =SUM(H9:H14) -> 1938850959 | I15: =SUM(I9:I14) -> 0 | J15: =SUM(J9:J14) -> 0 | K15: =SUM(K9:K14) -> 0 | L15: =SUM(L9:L14) -> 0 | M15: =SUM(M9:M14) -> 87889482 | N15: =SUM(N9:N14) -> 193542 | O15: =SUM(O9:O14) -> 1532701951 | ... Y15: =SUM(Y9:Y14) -> 160086
B16: Сельское хозяйство
A17: =A15+10 -> 80 | B17: Физические лица | C17: =SUM(J17:Y17)-L17-P17-Q17 -> 718619875 | D17: 718619875 | E17: 0.12699006 | F17: 0 | G17: 0 | H17: 718619875 | J17: 0 | K17: 0 | L17: 0 | M17: 105660 | N17: 0 | O17: =+P17+Q17 -> 31919 | P17: 2362 | Q17: 29557 | R17: 0 | S17: 0 | T17: 0 | U17: 0 | V17: 42013547 | W17: 676468749 | X17: 0 | Y17: 0
A18: =A17+10 -> 90 | B18: Государственные предприятия | C18: =SUM(J18:Y18)-L18-P18-Q18 -> 60257114 | D18: 60257114 | E18: 0.06010176 | F18: 0 | G18: 0 | H18: 60257114 | J18: 0 | K18: 0 | L18: 0 | M18: 0 | N18: 0 | O18: =+P18+Q18 -> 0 | P18: 0 | Q18: 0 | R18: 0 | S18: 0 | T18: 0 | U18: 0 | V18: 60257114 | W18: 0 | X18: 0 | Y18: 0
A19: =A18+10 -> 100 | B19: Совместные и иностранные предприятия | C19: =SUM(J19:Y19)-L19-P19-Q19 -> 186094751 | D19: 54086623 | E19: 0.18239675 | F19: 132008128 | G19: 0.07468252 | H19: 186094751 | J19: 0 | K19: 0 | L19: 0 | M19: 2354384 | N19: 0 | O19: =+P19+Q19 -> 181552478 | P19: 124613918 | Q19: 56938560 | R19: 0 | S19: 0 | T19: 0 | U19: 0 | V19: 1529230 | W19: 658659 | X19: 0 | Y19: 0
A20: =A19+10 -> 110 | B20: Частные товарищества и корпорации | C20: =SUM(J20:Y20)-L20-P20-Q20 -> 1241497805 | D20: 747400850 | E20: 0.16824605 | F20: 494096955 | G20: 0.074502216 | H20: 1241497805 | J20: 182126 | K20: 0 | L20: 0 | M20: 78812903 | N20: 0 | O20: =+P20+Q20 -> 1121491152 | P20: 78658888 | Q20: 1042832264 | R20: 1688445 | S20: 0 | T20: 0 | U20: 3149182 | V20: 12886598 | W20: 22505399 | X20: 0 | Y20: 782000
A21: =A20+10 -> 120 | B21: Фермерское хозяйство | C21: =SUM(J21:Y21)-L21-P21-Q21 -> 261233028 | D21: 183647166 | E21: 0.17259636 | F21: 77585862 | G21: 0.058612516 | H21: 261233028 | J21: 0 | K21: 0 | L21: 0 | M21: 18195003 | N21: 0 | O21: =+P21+Q21 -> 238623096 | P21: 18218837 | Q21: 220404259 | R21: 689586 | S21: 0 | T21: 0 | U21: 254467 | V21: 2962803 | W21: 508073 | X21: 0 | Y21: 0
A22: =A21+10 -> 130 | B22: Правительство | C22: =SUM(J22:Y22)-L22-P22-Q22 -> 0 | D22: 0 | E22: 0 | F22: 0 | G22: 0 | H22: 0 | J22: 0 | K22: 0 | L22: 0 | M22: 0 | N22: 0 | O22: =+P22+Q22 -> 0 | P22: 0 | Q22: 0 | R22: 0 | S22: 0 | T22: 0 | U22: 0 | V22: 0 | W22: 0 | X22: 0 | Y22: 0
A23: =A22+10 -> 140 | B23: Прочие | C23: =SUM(J23:Y23)-L23-P23-Q23 -> 0 | D23: 0 | E23: 0 | F23: 0 | G23: 0 | H23: 0 | I23: 0 | J23: 0 | K23: 0 | L23: 0 | M23: 0 | N23: 0 | O23: =+P23+Q23 -> 0 | P23: 0 | Q23: 0 | R23: 0 | S23: 0 | T23: 0 | U23: 0 | V23: 0 | W23: 0 | X23: 0 | Y23: 0
A24: =A23+10 -> 150 | B24: Итого по сельскому хозяйству | C24: =SUM(J24:Y24)-L24-P24-Q24 -> 2467702573 | D24: =SUM(D17:D23) -> 1764011628 | E24: =IFERROR(((D17*E17)/D24)+((D18*E18)/D24)+((D19*E19)/D24)+((D20*E20)/D24)+((D21*E21)/D24)+((D22*E22)/D24)+((D23*E23)/D24),0) -> 0.14863192 | F24: =SUM(F17:F23) -> 703690945 | G24: =IFERROR(((F17*G17)/F24)+((F18*G18)/F24)+((F19*G19)/F24)+((F20*G20)/F24)+((F21*G21)/F24)+((F22*G22)/F24)+((F23*G23)/F24),0) -> 0.072784112 | H24: =SUM(H17:H23) -> 2467702573 | I24: =SUM(I17:I23) -> 0 | J24: =SUM(J17:J23) -> 182126 | K24: =SUM(K17:K23) -> 0 | L24: =SUM(L17:L23) -> 0 | M24: =SUM(M17:M23) -> 99467950 | N24: =SUM(N17:N23) -> 0 | O24: =SUM(O17:O23) -> 1541698645 | ... Y24: =SUM(Y17:Y23) -> 782000
B25: Транспорт и коммуникации
A26: =A24+10 -> 160 | B26: Физические лица | C26: =SUM(J26:Y26)-L26-P26-Q26 -> 81876843 | D26: 81876843 | E26: 0.26392372 | F26: 0 | G26: 0 | H26: 81876843 | I26: 0 | J26: 0 | K26: 0 | L26: 0 | M26: 74458738 | N26: 0 | O26: =+P26+Q26 -> 7232 | P26: 0 | Q26: 7232 | R26: 0 | S26: 0 | T26: 0 | U26: 0 | V26: 2699930 | W26: 4680999 | X26: 0 | Y26: 29944
A27: =A26+10 -> 170 | B27: Государственные предприятия | C27: =SUM(J27:Y27)-L27-P27-Q27 -> 177970 | D27: 177970 | E27: 0.24357156 | F27: 0 | G27: 0 | H27: 177970 | I27: 0 | J27: 0 | K27: 0 | L27: 0 | M27: 177970 | N27: 0 | O27: =+P27+Q27 -> 0 | P27: 0 | Q27: 0 | R27: 0 | S27: 0 | T27: 0 | U27: 0 | V27: 0 | W27: 0 | X27: 0 | Y27: 0
A28: =A27+10 -> 180 | B28: Совместные и иностранные предприятия | C28: =SUM(J28:Y28)-L28-P28-Q28 -> 51350503 | D28: 4748565 | E28: 0.25153388 | F28: 46601938 | G28: 0.09 | H28: 51350503 | I28: 0 | J28: 0 | K28: 0 | L28: 0 | M28: 1316965 | N28: 0 | O28: =+P28+Q28 -> 50025005 | P28: 46736581 | Q28: 3288424 | R28: 0 | S28: 0 | T28: 0 | U28: 0 | V28: 8533 | W28: 0 | X28: 0 | Y28: 0
A29: =A28+10 -> 190 | B29: Частные товарищества и корпорации | C29: =SUM(J29:Y29)-L29-P29-Q29 -> 217089423 | D29: 109957217 | E29: 0.21988682 | F29: 107132206 | G29: 0.10715919 | H29: 217089423 | I29: 0 | J29: 0 | K29: 0 | L29: 0 | M29: 76743633 | N29: 0 | O29: =+P29+Q29 -> 133991772 | P29: 25915845 | Q29: 108075927 | R29: 0 | S29: 0 | T29: 0 | U29: 2493110 | V29: 2082997 | W29: 1777911 | X29: 0 | Y29: 0
A30: =A29+10 -> 200 | B30: Правительство | C30: =SUM(J30:Y30)-L30-P30-Q30 -> 0 | D30: 0 | E30: 0 | F30: 0 | G30: 0 | H30: 0 | I30: 0 | J30: 0 | K30: 0 | L30: 0 | M30: 0 | N30: 0 | O30: =+P30+Q30 -> 0 | P30: 0 | Q30: 0 | R30: 0 | S30: 0 | T30: 0 | U30: 0 | V30: 0 | W30: 0 | X30: 0 | Y30: 0
A31: =A30+10 -> 210 | B31: Прочие | C31: =SUM(J31:Y31)-L31-P31-Q31 -> 0 | D31: 0 | E31: 0 | F31: 0 | G31: 0 | H31: 0 | I31: 0 | J31: 0 | K31: 0 | L31: 0 | M31: 0 | N31: 0 | O31: =+P31+Q31 -> 0 | P31: 0 | Q31: 0 | R31: 0 | S31: 0 | T31: 0 | U31: 0 | V31: 0 | W31: 0 | X31: 0 | Y31: 0
A32: =A31+10 -> 220 | B32: Итого по транспорту и коммуникациям | C32: =SUM(J32:Y32)-L32-P32-Q32 -> 350494739 | D32: =SUM(D26:D31) -> 196760595 | E32: =IFERROR(((D26*E26)/D32)+((D27*E27)/D32)+((D28*E28)/D32)+((D29*E29)/D32)+((D30*E30)/D32)+((D31*E31)/D32),0) -> 0.23899683 | F32: =SUM(F26:F31) -> 153734144 | G32: =IFERROR(((F26*G26)/F32)+((F27*G27)/F32)+((F28*G28)/F32)+((F29*G29)/F32)+((F30*G30)/F32)+((F31*G31)/F32),0) -> 0.10195767 | H32: =SUM(H26:H31) -> 350494739 | I32: =SUM(I26:I31) -> 0 | J32: =SUM(J26:J31) -> 0 | K32: =SUM(K26:K31) -> 0 | L32: =SUM(L26:L31) -> 0 | M32: =SUM(M26:M31) -> 152697306 | N32: =SUM(N26:N31) -> 0 | O32: =SUM(O26:O31) -> 184024009 | ... Y32: =SUM(Y26:Y31) -> 29944
B33: Строительство
A34: =A32+10 -> 230 | B34: Физические лица | C34: =SUM(J34:Y34)-L34-P34-Q34 -> 100075 | D34: 100075 | E34: 0.15 | F34: 0 | G34: 0 | H34: 100075 | I34: 0 | J34: 0 | K34: 0 | L34: 0 | M34: 0 | N34: 0 | O34: =+P34+Q34 -> 0 | P34: 0 | Q34: 0 | R34: 0 | S34: 0 | T34: 0 | U34: 0 | V34: 0 | W34: 100075 | X34: 0 | Y34: 0
A35: =A34+10 -> 240 | B35: Государственные предприятия | C35: =SUM(J35:Y35)-L35-P35-Q35 -> 0 | D35: 0 | E35: 0 | F35: 0 | G35: 0 | H35: 0 | I35: 0 | J35: 0 | K35: 0 | L35: 0 | M35: 0 | N35: 0 | O35: =+P35+Q35 -> 0 | P35: 0 | Q35: 0 | R35: 0 | S35: 0 | T35: 0 | U35: 0 | V35: 0 | W35: 0 | X35: 0 | Y35: 0
A36: =A35+10 -> 250 | B36: Совместные и иностранные предприятия | C36: =SUM(J36:Y36)-L36-P36-Q36 -> 6302115 | D36: 6302115 | E36: 0.21840345 | F36: 0 | G36: 0 | H36: 6302115 | I36: 0 | J36: 0 | K36: 0 | L36: 0 | M36: 0 | N36: 0 | O36: =+P36+Q36 -> 2455000 | P36: 0 | Q36: 2455000 | R36: 0 | S36: 0 | T36: 0 | U36: 3833334 | V36: 3763 | W36: 10018 | X36: 0 | Y36: 0
A37: =A36+10 -> 260 | B37: Частные товарищества и корпорации | C37: =SUM(J37:Y37)-L37-P37-Q37 -> 333663985 | D37: 315322973 | E37: 0.13051106 | F37: 18341012 | G37: 0.076986422 | H37: 333663985 | I37: 0 | J37: 0 | K37: 0 | L37: 0 | M37: 3310867 | N37: 0 | O37: =+P37+Q37 -> 327755173 | P37: 51181312 | Q37: 276573861 | R37: 1587702 | S37: 0 | T37: 0 | U37: 49958 | V37: 133086 | W37: 827199 | X37: 0 | Y37: 0
A38: =A37+10 -> 270 | B38: Правительство | C38: =SUM(J38:Y38)-L38-P38-Q38 -> 0 | D38: 0 | E38: 0 | F38: 0 | G38: 0 | H38: 0 | I38: 0 | J38: 0 | K38: 0 | L38: 0 | M38: 0 | N38: 0 | O38: =+P38+Q38 -> 0 | P38: 0 | Q38: 0 | R38: 0 | S38: 0 | T38: 0 | U38: 0 | V38: 0 | W38: 0 | X38: 0 | Y38: 0
A39: =A38+10 -> 280 | B39: Прочие | C39: =SUM(J39:Y39)-L39-P39-Q39 -> 0 | D39: 0 | E39: 0 | F39: 0 | G39: 0 | H39: 0 | I39: 0 | J39: 0 | K39: 0 | L39: 0 | M39: 0 | N39: 0 | O39: =+P39+Q39 -> 0 | P39: 0 | Q39: 0 | R39: 0 | S39: 0 | T39: 0 | U39: 0 | V39: 0 | W39: 0 | X39: 0 | Y39: 0
A40: =A39+10 -> 290 | B40: Итого по строительству | C40: =SUM(J40:Y40)-L40-P40-Q40 -> 340066175 | D40: =SUM(D34:D39) -> 321725163 | E40: =IFERROR(((D34*E34)/D40)+((D35*E35)/D40)+((D36*E36)/D40)+((D37*E37)/D40)+((D38*E38)/D40)+((D39*E39)/D40),0) -> 0.1322388 | F40: =SUM(F34:F39) -> 18341012 | G40: =IFERROR(((F34*G34)/F40)+((F35*G35)/F40)+((F36*G36)/F40)+((F37*G37)/F40)+((F38*G38)/F40)+((F39*G39)/F40),0) -> 0.076986422 | H40: =SUM(H34:H39) -> 340066175 | I40: =SUM(I34:I39) -> 0 | J40: =SUM(J34:J39) -> 0 | K40: =SUM(K34:K39) -> 0 | L40: =SUM(L34:L39) -> 0 | M40: =SUM(M34:M39) -> 3310867 | N40: =SUM(N34:N39) -> 0 | O40: =SUM(O34:O39) -> 330210173 | ... Y40: =SUM(Y34:Y39) -> 0
B41: Торговля и общественное питание
...

Sheet Aging Analysis
A1: АНАЛИЗ ПРОСРОЧЕННЫХ КРЕДИТОВ И ФИНАНСОВОГО ЛИЗИНГА К ПОЛУЧЕНИЮ | X1: Таблица-9
B3: =+'Asset quality'!B3 -> "Микрокредитбанк" | T3: =+'Asset quality'!P3 -> 44560 | X3: тыс. сум
A4: № | B4: Характеристики | C4: Всего задолжность по кредитам | D4: % | E4: Реструктуризированные кредиты | F4: % | G4: В ходе судебного разбирательства | H4: % | I4: Просроченная задолжность | K4: % | L4: в том числе, анализ временной задолженности
L5: 1-30 дней | N5: 31-60 дней | P5: 61-90 дней | R5: 91-180 дней | T5: 181-365 дней | V5: 366-730 дней | X5: Свыше 2 лет
I6: основной долг | J6: процент | L6: основной долг | M6: процент | N6: основной долг | O6: процент | P6: основной долг | Q6: процент | R6: основной долг | S6: процент | T6: основной долг | U6: процент | V6: основной долг | W6: процент | X6: основной долг | Y6: процент
B7: (А) | C7: (Б) | D7: (В) | E7: (Г) | F7: (Д) | G7: (Е) | H7: (Ж) | I7: (З) | J7: (З1) | K7: (И) | L7: (К) | M7: (К1) | N7: (Л) | O7: (Л1) | P7: (М) | Q7: (М1) | R7: (Н) | S7: (Н1) | T7: (О) | U7: (О1) | V7: (П) | W7: (П1) | X7: (Р) | Y7: (Р1)
B8: По типу клиента
A9: 1 | B9: Центральный банк | C9: =+'Loans Receivable'!C86 -> 0 | D9: =IF(C$22=0,"",C9/C$22) -> 0 | E9: 0 | F9: =IF(E$22=0,"",E9/E$22) -> 0 | H9: =IF($G$22=0,"",G9/$G$22) | I9: =+L9+N9+P9+R9+T9+V9+X9 -> 0 | J9: =+M9+O9+T9+S9+U9+W9+Y9 -> 0 | K9: =IF($Z$22=0,"",Z9/$Z$22) -> 0 | Z9: =+I9+J9 -> 0
A10: 2 | B10: Другие банки | C10: =+'Loans Receivable'!C85 -> 0 | D10: =IF(C$22=0,"",C10/C$22) -> 0 | E10: 0 | F10: =IF(E$22=0,"",E10/E$22) -> 0 | H10: =IF($G$22=0,"",G10/$G$22) | I10: =+L10+N10+P10+R10+T10+V10+X10 -> 0 | J10: =+M10+O10+Q10+S10+U10+W10+Y10 -> 0 | K10: =IF($Z$22=0,"",Z10/$Z$22) -> 0 | Z10: =+I10+J10 -> 0
A11: 3 | B11: Правительство | C11: =+'Loans Receivable'!C87 -> 0 | D11: =IF(C$22=0,"",C11/C$22) -> 0 | E11: 0 | F11: =IF(E$22=0,"",E11/E$22) -> 0 | H11: =IF($G$22=0,"",G11/$G$22) | I11: =+L11+N11+P11+R11+T11+V11+X11 -> 0 | J11: =+M11+O11+Q11+S11+U11+W11+Y11 -> 0 | K11: =IF($Z$22=0,"",Z11/$Z$22) -> 0 | Z11: =+I11+J11 -> 0
A12: 4 | B12: Физические лица | C12: =+'Loans Receivable'!C80 -> 3084481917 | D12: =IF(C$22=0,"",C12/C$22) -> 0.28518075 | E12: 0 | F12: =IF(E$22=0,"",E12/E$22) -> 0 | G12: 0 | H12: =IF($G$22=0,"",G12/$G$22) | I12: =+L12+N12+P12+R12+T12+V12+X12 -> 1.8454683e+08 | J12: =+M12+O12+Q12+S12+U12+W12+Y12 -> 65998931 | K12: =IF($Z$22=0,"",Z12/$Z$22) -> 0.33068994 | L12: 8500898.8 | M12: 2916788 | N12: 13429970 | O12: 3207650.7 | P12: 12303129 | Q12: 3448255.4 | R12: 31428937 | S12: 14084377 | T12: 84155549 | U12: 21885432 | V12: 34717330 | W12: 20450813 | X12: 11020.92 | Y12: 5614.9629 | Z12: =+I12+J12 -> 2.5054577e+08
A13: 5 | B13: Государственные предприятия | C13: =+'Loans Receivable'!C81 -> 237969866 | D13: =IF(C$22=0,"",C13/C$22) -> 0.022001888 | E13: 0 | F13: =IF(E$22=0,"",E13/E$22) -> 0 | H13: =IF($G$22=0,"",G13/$G$22) | I13: =+L13+N13+P13+R13+T13+V13+X13 -> 10614906 | J13: =+M13+O13+Q13+S13+U13+W13+Y13 -> 1227032.8 | K13: =IF($Z$22=0,"",Z13/$Z$22) -> 0.015629919 | L13: 206250 | M13: 42092.973 | N13: 0 | O13: 0 | P13: 0 | R13: 3492311.2 | S13: 66301 | T13: 6916345.1 | U13: 1118638.8 | Z13: =+I13+J13 -> 11841939
A14: 6 | B14: Совместные и иностранные предприятия | C14: =+'Loans Receivable'!C82 -> 455620953 | D14: =IF(C$22=0,"",C14/C$22) -> 0.04212517 | E14: 127677 | F14: =IF(E$22=0,"",E14/E$22) -> 0.0036195308 | H14: =IF($G$22=0,"",G14/$G$22) | I14: =+L14+N14+P14+R14+T14+V14+X14 -> 10634713 | J14: =+M14+O14+Q14+S14+U14+W14+Y14 -> 4365814.1 | K14: =IF($Z$22=0,"",Z14/$Z$22) -> 0.019798871 | L14: 138203.16 | M14: 222599.53 | N14: 366822.17 | O14: 544433.64 | P14: 445825.42 | Q14: 554470.33 | R14: 1390799 | S14: 836387 | T14: 5277431.6 | U14: 328359.57 | V14: 3015631.4 | W14: 1879564 | X14: 0 | Y14: 0 | Z14: =+I14+J14 -> 15000527
A15: 7 | B15: Частные товарищества и корпорации | C15: =+'Loans Receivable'!C83 -> 6772953254 | D15: =IF(C$22=0,"",C15/C$22) -> 0.62620432 | E15: 34975065 | F15: =IF(E$22=0,"",E15/E$22) -> 0.99151236 | G15: 0 | H15: =IF($G$22=0,"",G15/$G$22) | I15: =+L15+N15+P15+R15+T15+V15+X15 -> 3.1147711e+08 | J15: =+M15+O15+Q15+S15+U15+W15+Y15 -> 1.5170629e+08 | K15: =IF($Z$22=0,"",Z15/$Z$22) -> 0.61134576 | L15: 20305619 | M15: 7658085.6 | N15: 27658030 | O15: 19250147 | P15: 21441601 | Q15: 12827965 | R15: 53387292 | S15: 48361062 | T15: 1.2554405e+08 | U15: 26975578 | V15: 62500448 | W15: 35805099 | X15: 640075.11 | Y15: 828354.1 | Z15: =+I15+J15 -> 4.631834e+08
A16: 8 | B16: Фермерское хозяйство | C16: =+'Loans Receivable'!C84 -> 261233028 | D16: =IF(C$22=0,"",C16/C$22) -> 0.024152721 | E16: 171720 | F16: =IF(E$22=0,"",E16/E$22) -> 0.0048681111 | G16: 0 | H16: =IF($G$22=0,"",G16/$G$22) | I16: =+L16+N16+P16+R16+T16+V16+X16 -> 8213758.5 | J16: =+M16+O16+Q16+S16+U16+W16+Y16 -> 5222760.1 | K16: =IF($Z$22=0,"",Z16/$Z$22) -> 0.01773457 | L16: 308981.67 | M16: 248770.43 | N16: 1493994.3 | O16: 313670.3 | P16: 854264.51 | Q16: 958830.08 | R16: 1213740.1 | S16: 2090631 | T16: 3343139.2 | U16: 611642.07 | V16: 999638.71 | W16: 821599 | X16: 0 | Y16: 177617.18 | Z16: =+I16+J16 -> 13436519
A17: 9 | B17: Небанковские финансовые институты | C17: =+'Loans Receivable'!C88 -> 0 | D17: =IF(C$22=0,"",C17/C$22) -> 0 | E17: 0 | F17: =IF(E$22=0,"",E17/E$22) -> 0 | H17: =IF($G$22=0,"",G17/$G$22) | I17: =+L17+N17+P17+R17+T17+V17+X17 -> 0 | J17: =+M17+O17+Q17+S17+U17+W17+Y17 -> 0 | K17: =IF($Z$22=0,"",Z17/$Z$22) -> 0 | Z17: =+I17+J17 -> 0
A18: 10 | B18: Негосударственные некоммерческие организации | C18: =+'Loans Receivable'!C89 -> 3603902 | D18: =IF(C$22=0,"",C18/C$22) -> 0.00033320457 | E18: 0 | F18: =IF(E$22=0,"",E18/E$22) -> 0 | H18: =IF($G$22=0,"",G18/$G$22) | I18: =+L18+N18+P18+R18+T18+V18+X18 -> 60283.094 | J18: =+M18+O18+Q18+S18+U18+W18+Y18 -> 9822.2658 | K18: =IF($Z$22=0,"",Z18/$Z$22) -> 9.2530549e-05 | M18: 235.4941 | N18: 35783.093 | P18: 24500.001 | Q18: 9586.7717 | Z18: =+I18+J18 -> 70105.36
A19: 11 | B19: Бюджетные организации | C19: =+'Loans Receivable'!C90 -> 0 | D19: =IF(C$22=0,"",C19/C$22) -> 0 | E19: 0 | F19: =IF(E$22=0,"",E19/E$22) -> 0 | H19: =IF($G$22=0,"",G19/$G$22) | I19: =+L19+N19+P19+R19+T19+V19+X19 -> 0 | J19: =+M19+O19+Q19+S19+U19+W19+Y19 -> 0 | K19: =IF($Z$22=0,"",Z19/$Z$22) -> 0 | Z19: =+I19+J19 -> 0
A20: 12 | B20: Прочие | C20: =+'Loans Receivable'!C91 -> 21091 | D20: =IF(C$22=0,"",C20/C$22) -> 1.9500024e-06 | E20: 0 | F20: =IF(E$22=0,"",E20/E$22) -> 0 | H20: =IF($G$22=0,"",G20/$G$22) | I20: =+L20+N20+P20+R20+T20+V20+X20 -> 0 | J20: =+M20+O20+Q20+S20+U20+W20+Y20 -> 3567304.9 | K20: =IF($Z$22=0,"",Z20/$Z$22) -> 0.0047084086 | M20: 3567304.9 | Z20: =+I20+J20 -> 3567304.9
Z21: =+I21+J21 -> 0
A22: 13 | B22: Итого кредита и лизинга | C22: =SUM(C9:C20) -> 10815884011 | D22: =IF(C$22=0,"",C22/C$22) -> 1 | E22: =SUM(E9:E20) -> 35274462 | F22: =IF(E$22=0,"",E22/E$22) -> 1 | G22: =SUM(G9:G20) -> 0 | H22: =IF($G$22=0,"",G22/$G$22) | I22: =SUM(I9:I20) -> 5.2554761e+08 | J22: =SUM(J9:J20) -> 2.3209796e+08 | K22: =IF($Z$22=0,"",Z22/$Z$22) -> 1 | L22: =SUM(L9:L20) -> 29459953 | M22: =SUM(M9:M20) -> 14655877 | N22: =SUM(N9:N20) -> 42984600 | O22: =SUM(O9:O20) -> 23315902 | P22: =SUM(P9:P20) -> 35069321 | Q22: =SUM(Q9:Q20) -> 17799108 | R22: =SUM(R9:R20) -> 90913078 | S22: =SUM(S9:S20) -> 65438758 | ... Y22: =SUM(Y9:Y20) -> 1011586.2 | Z22: =+I22+J22 -> 7.5764556e+08
Z23: =+I23+J23 -> 0
B24: По сектору экономики | F24: =IF(E$22=0,"",E24/E$22) -> 0 | Z24: =+I24+J24 -> 0
A25: 14 | B25: Промышленность | C25: =+'Loans Receivable'!C15 -> 1938850959 | D25: =IF(C$34=0,"",C25/C$34) -> 0.17925959 | F25: =IF($E$34=0,"",E25/$E$34) -> 0 | G25: 0 | H25: =IF($G$34=0,"",G25/$G$34) | I25: =+L25+N25+P25+R25+T25+V25+X25 -> 97234274 | J25: =+M25+O25+Q25+S25+U25+W25+Y25 -> 44950490 | K25: =IF($Z$34=0,"",Z25/$Z$34) -> 0.1876666 | L25: 7299629.8 | M25: 3400527.5 | N25: 4822803.5 | O25: 10415508 | P25: 3490382 | Q25: 2000018.1 | R25: 12161596 | S25: 5877150 | T25: 35757105 | U25: 7447424.6 | V25: 33604172 | W25: 15795144 | X25: 98585.5 | Y25: 14718.538 | Z25: =+I25+J25 -> 1.4218476e+08
A26: 15 | B26: Сельское хозяйство | C26: =+'Loans Receivable'!C24 -> 2467702573 | D26: =IF(C$34=0,"",C26/C$34) -> 0.22815542 | E26: 2147373 | F26: =IF($E$34=0,"",E26/$E$34) -> 0.060876138 | G26: 0 | H26: =IF($G$34=0,"",G26/$G$34) | I26: =+L26+N26+P26+R26+T26+V26+X26 -> 1.4343956e+08 | J26: =+M26+O26+Q26+S26+U26+W26+Y26 -> 59134309 | K26: =IF($Z$34=0,"",Z26/$Z$34) -> 0.26737287 | L26: 3645928.6 | M26: 1919905.3 | N26: 9491083.7 | O26: 3472339.9 | P26: 7786073.7 | Q26: 4639978.9 | R26: 28983127 | S26: 21754408 | T26: 68553677 | U26: 11054462 | V26: 24977226 | W26: 15995510 | X26: 2445.5278 | Y26: 297704.19 | Z26: =+I26+J26 -> 2.0257387e+08
A27: 16 | B27: Транспорт и коммуникации | C27: =+'Loans Receivable'!C32 -> 350494739 | D27: =IF(C$34=0,"",C27/C$34) -> 0.032405556 | F27: =IF($E$34=0,"",E27/$E$34) -> 0 | G27: 0 | H27: =IF($G$34=0,"",G27/$G$34) | I27: =+L27+N27+P27+R27+T27+V27+X27 -> 20970386 | J27: =+M27+O27+Q27+S27+U27+W27+Y27 -> 9307263.2 | K27: =IF($Z$34=0,"",Z27/$Z$34) -> 0.039962815 | L27: 3216056.5 | M27: 652730.72 | N27: 1739359.6 | O27: 776794.77 | P27: 1157110.3 | Q27: 419073.93 | R27: 2614850.6 | S27: 3168542 | T27: 6923476.8 | U27: 1457673.4 | V27: 4778043 | W27: 2473836 | X27: 541489.61 | Y27: 358612.47 | Z27: =+I27+J27 -> 30277650
A28: 17 | B28: Строительство | C28: =+'Loans Receivable'!C40 -> 340066175 | D28: =IF(C$34=0,"",C28/C$34) -> 0.031441367 | E28: 15089714 | F28: =IF($E$34=0,"",E28/$E$34) -> 0.42778013 | G28: 0 | H28: =IF($G$34=0,"",G28/$G$34) | I28: =+L28+N28+P28+R28+T28+V28+X28 -> 23008527 | J28: =+M28+O28+Q28+S28+U28+W28+Y28 -> 14218009 | K28: =IF($Z$34=0,"",Z28/$Z$34) -> 0.0491345 | L28: 436391.56 | M28: 190574.64 | N28: 2658900.4 | O28: 394605.56 | P28: 1515937.6 | Q28: 1742662.6 | R28: 3248678 | S28: 7100816 | T28: 14052126 | U28: 2631654.8 | V28: 1096493.7 | W28: 2045473 | X28: 0 | Y28: 112221.89 | Z28: =+I28+J28 -> 37226536
A29: 18 | B29: Торговля и общественное питание | C29: =+'Loans Receivable'!C48 -> 1152185836 | D29: =IF(C$34=0,"",C29/C$34) -> 0.1065272 | E29: 17026031 | F29: =IF($E$34=0,"",E29/$E$34) -> 0.48267302 | G29: 0 | H29: =IF($G$34=0,"",G29/$G$34) | I29: =+L29+N29+P29+R29+T29+V29+X29 -> 97009727 | J29: =+M29+O29+Q29+S29+U29+W29+Y29 -> 29835886 | K29: =IF($Z$34=0,"",Z29/$Z$34) -> 0.16742078 | L29: 5334362.4 | M29: 807857 | N29: 8603582.3 | O29: 1834895.6 | P29: 7643971.2 | Q29: 3849088.4 | R29: 15089228 | S29: 6403911 | T29: 46579887 | U29: 7904119.7 | V29: 13758696 | W29: 8813300 | X29: 0 | Y29: 222714.2 | Z29: =+I29+J29 -> 1.2684561e+08
A30: 19 | B30: Материально-техническое снабжение и сбыт | C30: =+'Loans Receivable'!C56 -> 1377552811 | D30: =IF(C$34=0,"",C30/C$34) -> 0.12736387 | E30: 1011344 | F30: =IF($E$34=0,"",E30/$E$34) -> 0.028670714 | G30: 0 | H30: =IF($G$34=0,"",G30/$G$34) | I30: =+L30+N30+P30+R30+T30+V30+X30 -> 47293183 | J30: =+M30+O30+Q30+S30+U30+W30+Y30 -> 26183070 | K30: =IF($Z$34=0,"",Z30/$Z$34) -> 0.096979718 | L30: 2155998.9 | M30: 1434120.2 | N30: 3858075 | O30: 2788353 | P30: 4225188.6 | Q30: 1692237.5 | R30: 11649451 | S30: 7092444 | T30: 17668342 | U30: 6276899.1 | V30: 7736126.7 | W30: 6899016 | X30: 0 | Y30: 0 | Z30: =+I30+J30 -> 73476253
A31: 20 | B31: Жилищно-коммунальные услуги | C31: =+'Loans Receivable'!C65 -> 2082182 | D31: =IF(C$34=0,"",C31/C$34) -> 0.00019251149 | F31: =IF($E$34=0,"",E31/$E$34) -> 0 | G31: 0 | H31: =IF($G$34=0,"",G31/$G$34) | I31: =+L31+N31+P31+R31+T31+V31+X31 -> 24500.001 | J31: =+M31+O31+Q31+S31+U31+W31+Y31 -> 192165.9 | K31: =IF($Z$34=0,"",Z31/$Z$34) -> 0.00028597264 | M31: 182579.13 | O31: 0 | P31: 24500.001 | Q31: 9586.7717 | S31: 0 | U31: 0 | W31: 0 | Y31: 0 | Z31: =+I31+J31 -> 216665.9
A32: 21 | B32: Другие сектора | C32: =+'Loans Receivable'!C78 -> 3186948736 | D32: =IF(C$34=0,"",C32/C$34) -> 0.29465449 | F32: =IF($E$34=0,"",E32/$E$34) -> 0 | G32: 0 | H32: =IF($G$34=0,"",G32/$G$34) | I32: =+L32+N32+P32+R32+T32+V32+X32 -> 96567447 | J32: =+M32+O32+Q32+S32+U32+W32+Y32 -> 48276763 | K32: =IF($Z$34=0,"",Z32/$Z$34) -> 0.19117674 | L32: 7371585.4 | M32: 6067582.4 | N32: 11810795 | O32: 3633405.7 | P32: 9226157.2 | Q32: 3446461.4 | R32: 17166147 | S32: 14041487 | T32: 35701897 | U32: 14147416 | V32: 15282290 | W32: 6934796 | X32: 8575.3919 | Y32: 5614.9629 | Z32: =+I32+J32 -> 1.4484421e+08
S33: 0 | Z33: =+I33+J33 -> 0
A34: 22 | B34: Итого кредита и лизинга | C34: =SUM(C25:C32) -> 10815884011 | D34: =IF(C$34=0,"",C34/C$34) -> 1 | E34: =SUM(E25:E32) -> 35274462 | F34: =IF($E$34=0,"",E34/$E$34) -> 1 | G34: =SUM(G25:G32) -> 0 | H34: =IF($G$34=0,"",G34/$G$34) | I34: =SUM(I25:I32) -> 5.2554761e+08 | J34: =SUM(J25:J32) -> 2.3209796e+08 | K34: =IF($Z$34=0,"",Z34/$Z$34) -> 1 | L34: =SUM(L25:L32) -> 29459953 | M34: =SUM(M25:M32) -> 14655877 | N34: =SUM(N25:N32) -> 42984600 | O34: =SUM(O25:O32) -> 23315902 | P34: =SUM(P25:P32) -> 35069321 | Q34: =SUM(Q25:Q32) -> 17799108 | R34: =SUM(R25:R32) -> 90913078 | S34: =SUM(S25:S32) -> 65438758 | ... Y34: =SUM(Y25:Y32) -> 1011586.2 | Z34: =+I34+J34 -> 7.5764556e+08
B37: Подпись Председателя правления:
B39: Подпись Главного Бухгалтера:

Sheet Asset Classification
A1: ОТЧЕТ О КЛАССИФИКАЦИИ АКТИВОВ ПО СТЕПЕНИ РИСКА | W1: Таблица-10
B2: =+'Asset quality'!B3 -> "Микрокредитбанк" | U2: =+'Asset quality'!P3 -> 44560 | Z2: тыс. сум
A3: № | B3: Статьи баланса | C3: Общая сумма | D3: из них, в иностранной валюте (в экв. в сумах) | E3: Стандартные | F3: из них, в иностранной валюте (в экв. в сумах) | G3: Общие резервы (1%) | H3: из них, в иностранной валюте (в экв. в сумах) | I3: Субстандартные | J3: из них, в иностранной валюте (в экв. в сумах) | K3: Специальные резервы (мин 10%) | L3: из них, в иностранной валюте (в экв. в сумах) | M3: Неудовлетворительные | N3: из них, в иностранной валюте (в экв. в сумах) | O3: Специальные резервы (мин 25%) | P3: из них, в иностранной валюте (в экв. в сумах) | Q3: Сомнительные | R3: из них, в иностранной валюте (в экв. в сумах) | S3: Специальные резервы (мин 50%) | T3: из них, в иностранной валюте (в экв. в сумах) | U3: Безнадежные | V3: из них, в иностранной валюте (в экв. в сумах) | W3: Специальные резервы (100%) | X3: из них, в иностранной валюте (в экв. в сумах) | Y3: Совокупная сумма специальных резервов | Z3: из них, в иностранной валюте (в экв. в сумах) | AA3: списанные кредиты за баланс в отчётном месяце | AB3: возврат списанных кредитов в отчётном месяце
A4: (А) | B4: (Б) | C4: (В) | D4: (В1) | E4: (Г) | F4: (Г1) | G4: (Д) | H4: (Д1) | I4: (Е) | J4: (Е1) | K4: (Ж) | L4: (Ж1) | M4: (З) | N4: (З1) | O4: (И) | P4: (И1) | Q4: (К) | R4: (К1) | S4: (Л) | T4: (Л1) | U4: (М) | V4: (М1) | W4: (Н) | X4: (Н1) | Y4: О=Ж+И+Л+Н | Z4: (О1)=(Ж1)+(И1)+(Л1)+(Н1) | AA4: П | AB4: Р
B5: По типу клиента
A6: 1 | B6: Центральный банк | C6: =E6+I6+M6+Q6+U6 -> 0 | D6: =F6+J6+N6+R6+V6 -> 0 | Y6: =+W6+S6+O6+K6 -> 0 | Z6: =+X6+T6+P6+L6 -> 0 | AC6: =+'Aging Analysis'!C9 -> 0
B7: из них необеспеченные | C7: =E7+I7+M7+Q7+U7 -> 0 | D7: =F7+J7+N7+R7+V7 -> 0 | Y7: =+W7+S7+O7+K7 -> 0 | Z7: =+X7+T7+P7+L7 -> 0
A8: 2 | B8: Другие банки | C8: =E8+I8+M8+Q8+U8 -> 0 | D8: =F8+J8+N8+R8+V8 -> 0 | Y8: =+W8+S8+O8+K8 -> 0 | Z8: =+X8+T8+P8+L8 -> 0 | AC8: =+'Aging Analysis'!C10 -> 0
B9: из них необеспеченные | C9: =E9+I9+M9+Q9+U9 -> 0 | D9: =F9+J9+N9+R9+V9 -> 0 | Y9: =+W9+S9+O9+K9 -> 0 | Z9: =+X9+T9+P9+L9 -> 0
A10: 3 | B10: Правительство | C10: =E10+I10+M10+Q10+U10 -> 0 | D10: =F10+J10+N10+R10+V10 -> 0 | Y10: =+W10+S10+O10+K10 -> 0 | Z10: =+X10+T10+P10+L10 -> 0 | AC10: =+'Aging Analysis'!C11 -> 0
B11: из них необеспеченные | C11: =E11+I11+M11+Q11+U11 -> 0 | D11: =F11+J11+N11+R11+V11 -> 0 | Y11: =+W11+S11+O11+K11 -> 0 | Z11: =+X11+T11+P11+L11 -> 0
A12: 4 | B12: Физические лица | C12: =E12+I12+M12+Q12+U12 -> 3084481917 | D12: =F12+J12+N12+R12+V12 -> 0 | E12: 2457104568 | F12: 0 | G12: 0 | H12: 0 | I12: 279332652 | J12: 0 | K12: 27922889 | L12: 0 | M12: 50523767 | N12: 0 | O12: 12252269 | P12: 0 | Q12: 60700150 | R12: 0 | S12: 29377522 | T12: 0 | U12: 236820780 | V12: 0 | W12: 51308106 | X12: 0 | Y12: =+W12+S12+O12+K12 -> 120860786 | Z12: =+X12+T12+P12+L12 -> 0 | AC12: =+'Aging Analysis'!C12 -> 3084481917
B13: из них необеспеченные | C13: =E13+I13+M13+Q13+U13 -> 0 | D13: =F13+J13+N13+R13+V13 -> 0 | Y13: =+W13+S13+O13+K13 -> 0 | Z13: =+X13+T13+P13+L13 -> 0
A14: 5 | B14: Государственные предприятия | C14: =E14+I14+M14+Q14+U14 -> 237969866 | D14: =F14+J14+N14+R14+V14 -> 54188322 | E14: 171352995 | F14: 54188322 | G14: 0 | H14: 0 | I14: 60111156 | J14: 0 | K14: 6011116 | L14: 0 | M14: 6051420 | N14: 0 | O14: 630142 | P14: 0 | Q14: 0 | R14: 0 | S14: 0 | T14: 0 | U14: 454295 | V14: 0 | W14: 0 | X14: 0 | Y14: =+W14+S14+O14+K14 -> 6641258 | Z14: =+X14+T14+P14+L14 -> 0 | AC14: =+'Aging Analysis'!C13 -> 237969866
B15: из них необеспеченные | C15: =E15+I15+M15+Q15+U15 -> 0 | D15: =F15+J15+N15+R15+V15 -> 0 | Y15: =+W15+S15+O15+K15 -> 0 | Z15: =+X15+T15+P15+L15 -> 0
A16: 6 | B16: Совместные и иностранные предприятия | C16: =E16+I16+M16+Q16+U16 -> 455620953 | D16: =F16+J16+N16+R16+V16 -> 288547784 | E16: 388512721 | F16: 241016272 | G16: 0 | H16: 0 | I16: 60958145 | J16: 47531512 | K16: 5965799 | L16: 4753151 | M16: 1011514 | N16: 0 | O16: 252879 | P16: 0 | Q16: 900280 | R16: 0 | S16: 433465 | T16: 0 | U16: 4238293 | V16: 0 | W16: 197308 | X16: 0 | Y16: =+W16+S16+O16+K16 -> 6849451 | Z16: =+X16+T16+P16+L16 -> 4753151 | AC16: =+'Aging Analysis'!C14 -> 455620953
B17: из них необеспеченные | C17: =E17+I17+M17+Q17+U17 -> 0 | D17: =F17+J17+N17+R17+V17 -> 0 | Y17: =+W17+S17+O17+K17 -> 0 | Z17: =+X17+T17+P17+L17 -> 0
A18: 7 | B18: Частные товарищества и корпорации | C18: =E18+I18+M18+Q18+U18 -> 6772953254 | D18: =F18+J18+N18+R18+V18 -> 3190462147 | E18: 5927930415 | F18: 2888927032 | G18: 0 | H18: 38811 | I18: 569159880 | J18: 181288795 | K18: 54493731 | L18: 17300828 | M18: 176884326 | N18: 119725254 | O18: 15050150 | P18: 7674629 | Q18: 18143746 | R18: 0 | S18: 8416131 | T18: 0 | U18: 80834887 | V18: 521066 | W18: 6575278 | X18: 0 | Y18: =+W18+S18+O18+K18 -> 84535290 | Z18: =+X18+T18+P18+L18 -> 24975457 | AC18: =+'Aging Analysis'!C15 -> 6772953254
B19: из них необеспеченные | C19: =E19+I19+M19+Q19+U19 -> 0 | D19: =F19+J19+N19+R19+V19 -> 0 | Y19: =+W19+S19+O19+K19 -> 0 | Z19: =+X19+T19+P19+L19 -> 0
A20: 8 | B20: Фермерское хозяйство | C20: =E20+I20+M20+Q20+U20 -> 261233028 | D20: =F20+J20+N20+R20+V20 -> 77585862 | E20: 238375501 | F20: 76152219 | G20: 0 | H20: 0 | I20: 17170732 | J20: 1433643 | K20: 1672411 | L20: 143364 | M20: 3574759 | N20: 0 | O20: 393690 | P20: 0 | Q20: 80407 | R20: 0 | S20: 40204 | T20: 0 | U20: 2031629 | V20: 0 | W20: 77223 | X20: 0 | Y20: =+W20+S20+O20+K20 -> 2183528 | Z20: =+X20+T20+P20+L20 -> 143364 | AC20: =+'Aging Analysis'!C16 -> 261233028
B21: из них необеспеченные | C21: =E21+I21+M21+Q21+U21 -> 0 | D21: =F21+J21+N21+R21+V21 -> 0 | Y21: =+W21+S21+O21+K21 -> 0 | Z21: =+X21+T21+P21+L21 -> 0
A22: 9 | B22: Небанковские финансовые институты | C22: =E22+I22+M22+Q22+U22 -> 0 | D22: =F22+J22+N22+R22+V22 -> 0 | E22: 0 | F22: 0 | G22: 0 | H22: 0 | I22: 0 | J22: 0 | K22: 0 | L22: 0 | M22: 0 | N22: 0 | O22: 0 | P22: 0 | Q22: 0 | R22: 0 | S22: 0 | T22: 0 | U22: 0 | V22: 0 | W22: 0 | X22: 0 | Y22: =+W22+S22+O22+K22 -> 0 | Z22: =+X22+T22+P22+L22 -> 0 | AC22: =+'Aging Analysis'!C17 -> 0
B23: из них необеспеченные | C23: =E23+I23+M23+Q23+U23 -> 0 | D23: =F23+J23+N23+R23+V23 -> 0 | Y23: =+W23+S23+O23+K23 -> 0 | Z23: =+X23+T23+P23+L23 -> 0
A24: 10 | B24: Негосударственные некоммерческие организации | C24: =E24+I24+M24+Q24+U24 -> 3603902 | D24: =F24+J24+N24+R24+V24 -> 810574 | E24: 3224033 | F24: 810574 | G24: 0 | H24: 0 | I24: 379869 | J24: 0 | K24: 37987 | L24: 0 | M24: 0 | N24: 0 | O24: 0 | P24: 0 | Q24: 0 | R24: 0 | S24: 0 | T24: 0 | U24: 0 | V24: 0 | W24: 0 | X24: 0 | Y24: =+W24+S24+O24+K24 -> 37987 | Z24: =+X24+T24+P24+L24 -> 0 | AC24: =+'Aging Analysis'!C18 -> 3603902
B25: из них необеспеченные | C25: =E25+I25+M25+Q25+U25 -> 0 | D25: =F25+J25+N25+R25+V25 -> 0 | Y25: =+W25+S25+O25+K25 -> 0 | Z25: =+X25+T25+P25+L25 -> 0
A26: 11 | B26: Бюджетные организации | C26: =E26+I26+M26+Q26+U26 -> 0 | D26: =F26+J26+N26+R26+V26 -> 0 | E26: 0 | F26: 0 | G26: 0 | H26: 0 | I26: 0 | J26: 0 | K26: 0 | L26: 0 | M26: 0 | N26: 0 | O26: 0 | P26: 0 | Q26: 0 | R26: 0 | S26: 0 | T26: 0 | U26: 0 | V26: 0 | W26: 0 | X26: 0 | Y26: =+W26+S26+O26+K26 -> 0 | Z26: =+X26+T26+P26+L26 -> 0 | AC26: =+'Aging Analysis'!C19 -> 0
B27: из них необеспеченные | C27: =E27+I27+M27+Q27+U27 -> 0 | D27: =F27+J27+N27+R27+V27 -> 0 | Y27: =+W27+S27+O27+K27 -> 0 | Z27: =+X27+T27+P27+L27 -> 0
A28: 12 | B28: Прочие | C28: =E28+I28+M28+Q28+U28 -> 21091 | D28: =F28+J28+N28+R28+V28 -> 0 | E28: 21091 | F28: 0 | G28: 0 | H28: 0 | I28: 0 | J28: 0 | K28: 0 | L28: 0 | M28: 0 | N28: 0 | O28: 0 | P28: 0 | Q28: 0 | R28: 0 | S28: 0 | T28: 0 | U28: 0 | V28: 0 | W28: 0 | X28: 0 | Y28: =+W28+S28+O28+K28 -> 0 | Z28: =+X28+T28+P28+L28 -> 0 | AC28: =+'Aging Analysis'!C20 -> 21091
B29: из них необеспеченные | C29: =E29+I29+M29+Q29+U29 -> 0 | D29: =F29+J29+N29+R29+V29 -> 0 | Y29: =+W29+S29+O29+K29 -> 0 | Z29: =+X29+T29+P29+L29 -> 0
A30: 13 | B30: Итого кредита и лизинга | C30: =+C6+C8+C10+C12+C14+C16+C18+C20+C22+C24+C26+C28 -> 10815884011 | D30: =+D6+D8+D10+D12+D14+D16+D18+D20+D22+D24+D26+D28 -> 3611594689 | E30: =+E6+E8+E10+E12+E14+E16+E18+E20+E22+E24+E26+E28 -> 9186521324 | F30: =+F6+F8+F10+F12+F14+F16+F18+F20+F22+F24+F26+F28 -> 3261094419 | G30: =+G6+G8+G10+G12+G14+G16+G18+G20+G22+G24+G26+G28 -> 0 | H30: =+H6+H8+H10+H12+H14+H16+H18+H20+H22+H24+H26+H28 -> 38811 | I30: =+I6+I8+I10+I12+I14+I16+I18+I20+I22+I24+I26+I28 -> 987112434 | J30: =+J6+J8+J10+J12+J14+J16+J18+J20+J22+J24+J26+J28 -> 230253950 | ... AB30: =+AB6+AB8+AB10+AB12+AB14+AB16+AB18+AB20+AB22+AB24+AB26+AB28 -> 0
B31: из них необеспеченные | C31: =+C7+C9+C11+C13+C15+C17+C19+C21+C23+C25+C27+C29 -> 0 | D31: =+D7+D9+D11+D13+D15+D17+D19+D21+D23+D25+D27+D29 -> 0 | E31: =+E7+E9+E11+E13+E15+E17+E19+E21+E23+E25+E27+E29 -> 0 | F31: =+F7+F9+F11+F13+F15+F17+F19+F21+F23+F25+F27+F29 -> 0 | G31: =+G7+G9+G11+G13+G15+G17+G19+G21+G23+G25+G27+G29 -> 0 | H31: =+H7+H9+H11+H13+H15+H17+H19+H21+H23+H25+H27+H29 -> 0 | I31: =+I7+I9+I11+I13+I15+I17+I19+I21+I23+I25+I27+I29 -> 0 | J31: =+J7+J9+J11+J13+J15+J17+J19+J21+J23+J25+J27+J29 -> 0 | ... Z31: =+Z7+Z9+Z11+Z13+Z15+Z17+Z19+Z21+Z23+Z25+Z27+Z29 -> 0
B32: По сектору экономики
A34: 14 | B34: Промышленность | C34: =E34+I34+M34+Q34+U34 -> 1938850959 | D34: =F34+J34+N34+R34+V34 -> 1287218675 | E34: 1636572171 | F34: 1125442854 | H34: 0 | I34: 193126203 | J34: 115657283 | K34: 18363338 | L34: 11171082 | M34: 53481866 | N34: 46118538 | O34: 1765442 | P34: 21340 | Q34: 8424291 | R34: 0 | S34: 4091953 | T34: 0 | U34: 47246428 | V34: 0 | W34: 3941714 | X34: 0 | Y34: =+W34+S34+O34+K34 -> 28162447 | Z34: =+X34+T34+P34+L34 -> 11192422 | AC34: =+'Aging Analysis'!C25 -> 1938850959
B35: из них необеспеченные | C35: =E35+I35+M35+Q35+U35 -> 0 | D35: =F35+J35+N35+R35+V35 -> 0 | Y35: =+W35+S35+O35+K35 -> 0 | Z35: =+X35+T35+P35+L35 -> 0
A36: 15 | B36: Сельское хозяйство | C36: =E36+I36+M36+Q36+U36 -> 2467702573 | D36: =F36+J36+N36+R36+V36 -> 703690946 | E36: 1926908101 | F36: 626566883 | H36: 38811 | I36: 240229065 | J36: 12098103 | K36: 23081064 | L36: 1209810 | M36: 103752467 | N36: 65025960 | O36: 14066613 | P36: 6502596 | Q36: 43652661 | R36: 0 | S36: 21398402 | T36: 0 | U36: 153160279 | V36: 0 | W36: 22895718 | X36: 0 | Y36: =+W36+S36+O36+K36 -> 81441797 | Z36: =+X36+T36+P36+L36 -> 7712406 | AC36: =+'Aging Analysis'!C26 -> 2467702573
B37: из них необеспеченные | C37: =E37+I37+M37+Q37+U37 -> 0 | D37: =F37+J37+N37+R37+V37 -> 0 | Y37: =+W37+S37+O37+K37 -> 0 | Z37: =+X37+T37+P37+L37 -> 0
A38: 16 | B38: Транспорт и коммуникации | C38: =E38+I38+M38+Q38+U38 -> 350494739 | D38: =F38+J38+N38+R38+V38 -> 153734143 | E38: 253658047 | F38: 92194055 | H38: 0 | I38: 88039198 | J38: 61019022 | K38: 8373065 | L38: 5668496 | M38: 3977748 | N38: 0 | O38: 539029 | P38: 0 | Q38: 887324 | R38: 0 | S38: 443760 | T38: 0 | U38: 3932422 | V38: 521066 | W38: 243352 | X38: 0 | Y38: =+W38+S38+O38+K38 -> 9599206 | Z38: =+X38+T38+P38+L38 -> 5668496 | AC38: =+'Aging Analysis'!C27 -> 350494739
B39: из них необеспеченные | C39: =E39+I39+M39+Q39+U39 -> 0 | D39: =F39+J39+N39+R39+V39 -> 0 | Y39: =+W39+S39+O39+K39 -> 0 | Z39: =+X39+T39+P39+L39 -> 0
A40: 17 | B40: Строительство | C40: =E40+I40+M40+Q40+U40 -> 340066175 | D40: =F40+J40+N40+R40+V40 -> 18341012 | E40: 247611897 | F40: 3251298 | H40: 0 | I40: 85154264 | J40: 15089714 | K40: 8304225 | L40: 1508971 | M40: 5319433 | N40: 0 | O40: 84132 | P40: 0 | Q40: 36986 | R40: 0 | S40: 4493 | T40: 0 | U40: 1943595 | V40: 0 | W40: 0 | X40: 0 | Y40: =+W40+S40+O40+K40 -> 8392850 | Z40: =+X40+T40+P40+L40 -> 1508971 | AC40: =+'Aging Analysis'!C28 -> 340066175
B41: из них необеспеченные | C41: =E41+I41+M41+Q41+U41 -> 0 | D41: =F41+J41+N41+R41+V41 -> 0 | Y41: =+W41+S41+O41+K41 -> 0 | Z41: =+X41+T41+P41+L41 -> 0
...

Sheet loans type
Z1: Таблица-20 А
A2: Информация о структуре кредитного портфеля
B3: =+'Asset quality'!B3 -> "Микрокредитбанк" | V3: =+'Asset quality'!P3 -> 44560 | Z3: тыс. сум
A4: № | B4: Виды кредитования | C4: всего | I4: Сроки | N4: Категория качества | S4: Резерв на возможные потери | Y4: Списанные на внебаланс | Z4: Реструктуризи-рованные кредиты
I5: до 1 года | J5: От 1 до 5 лет | K5: От 5 до 10 лет | L5: От 10 до 15 лет | M5: Свыше 15 лет | S5: итого | T5: по категориям качества
C6: Остаток | D6: средневзвешенные % ставки | E6: в нацвалюте | F6: средневзвешенные % ставки | G6: в инвалюте | H6: средневзвешенные % ставки | N6: I | O6: II | P6: III | Q6: IV | R6: V | T6: I | U6: II | V6: III | W6: IV | X6: V | AB6: I | AC6: II | AD6: III | AE6: IV | AF6: V
B7: А | C7: Б | D7: В | E7: Г | F7: Д | G7: Е | H7: Ж | I7: З | J7: И | K7: К | L7: Л | M7: М | N7: Н | O7: О | P7: П | Q7: Р | R7: С | S7: Т | T7: У | U7: Ф | V7: Х | W7: Ц | X7: Ч | Y7: Ш | Z7: Щ
B8: ВСЕГО | C8: =+C9+C25 -> 10815884011 | D8: =IFERROR(((C9*D9)/C8)+((C25*D25)/C8),0) -> 0.12849568 | E8: =+E9+E25 -> 7204289323 | F8: =IFERROR(((E9*F9)/E8)+((E25*F25)/E8),0) -> 0.14999923 | G8: =+G9+G25 -> 3611594688 | H8: =IFERROR(((G9*H9)/G8)+((G25*H25)/G8),0) -> 0.085601115 | I8: =+I9+I25 -> 1882781339 | J8: =+J9+J25 -> 7196391815 | K8: =+K9+K25 -> 1127745122 | L8: =+L9+L25 -> 320076399 | M8: =+M9+M25 -> 288889336 | N8: =+N9+N25 -> 9186521324 | O8: =+O9+O25 -> 987112434 | P8: =+P9+P25 -> 238045786 | ... Z8: =+Z9+Z25 -> 0 | AA8: =+'Loans Receivable'!C92 -> 10815884011 | AB8: =+'Asset Classification'!G30 -> 0 | AC8: =+'Asset Classification'!K30 -> 96103933 | AD8: =+'Asset Classification'!O50 -> 28579130 | AE8: =+'Asset Classification'!S50 -> 38267322 | AF8: =+'Asset Classification'!W50 -> 58157915
A9: I | B9: Физические лица | C9: =+C11+C16+C21+C22+C24 -> 3084481917 | D9: =IFERROR(((C11*D11)/C9)+((C16*D16)/C9)+((C21*D21)/C9)+((C22*D22)/C9)+((C24*D24)/C9),0) -> 0.13213654 | E9: =+E11+E16+E21+E22+E24 -> 3084481917 | F9: =IFERROR(((E11*F11)/E9)+((E16*F16)/E9)+((E21*F21)/E9)+((E22*F22)/E9)+((E24*F24)/E9),0) -> 0.13213654 | G9: =+G11+G16+G21+G22+G24 -> 0 | H9: =IFERROR(((G11*H11)/G9)+((G16*H16)/G9)+((G21*H21)/G9)+((G22*H22)/G9)+((G24*H24)/G9),0) -> 0 | I9: =+I11+I16+I21+I22+I24 -> 316489565 | J9: =+J11+J16+J21+J22+J24 -> 2257635694 | K9: =+K11+K16+K21+K22+K24 -> 52246904 | L9: =+L11+L16+L21+L22+L24 -> 169220418 | M9: =+M11+M16+M21+M22+M24 -> 288889336 | N9: =+N11+N16+N21+N22+N24 -> 2457104567 | O9: =+O11+O16+O21+O22+O24 -> 279332652 | P9: =+P11+P16+P21+P22+P24 -> 50523766 | ... Z9: =+Z11+Z16+Z21+Z22+Z24 -> 0 | AA9: =+'Loans Receivable'!C80 -> 3084481917 | AB9: =+'Asset Classification'!E30 -> 9186521324 | AC9: =+'Asset Classification'!I30 -> 987112434 | AD9: =+'Asset Classification'!M30 -> 238045786 | AE9: =+'Asset Classification'!Q30 -> 79824583 | AF9: =+'Asset Classification'!U30 -> 324379884
B10: в том числе | AB10: =+N8-AB9 -> 0 | AC10: =+O8-AC9 -> 0 | AD10: =+P8-AD9 -> 0 | AE10: =+Q8-AE9 -> 0 | AF10: =+R8-AF9 -> 0
A11: 1 | B11: Ипотечные кредиты (льготные) в том числе: | C11: =SUM(C12:C15) -> 22828512 | D11: =IFERROR(((C12*D12)/C11)+((C13*D13)/C11)+((C14*D14)/C11)+((C15*D15)/C11),0) -> 0.095631003 | E11: =SUM(E12:E15) -> 22828512 | F11: =IFERROR(((E12*F12)/E11)+((E13*F13)/E11)+((E14*F14)/E11)+((E15*F15)/E11),0) -> 0.095631003 | G11: =SUM(G12:G15) -> 0 | H11: =IFERROR(((G12*H12)/G11)+((G13*H13)/G11)+((G14*H14)/G11)+((G15*H15)/G11),0) -> 0 | I11: =SUM(I12:I15) -> 6351 | J11: =SUM(J12:J15) -> 2016883 | K11: =SUM(K12:K15) -> 4883052 | L11: =SUM(L12:L15) -> 4061818 | M11: =SUM(M12:M15) -> 11860408 | N11: =SUM(N12:N15) -> 20971970 | O11: =SUM(O12:O15) -> 1526660 | P11: =SUM(P12:P15) -> 141194 | ... Z11: =SUM(Z12:Z15) -> 0 | AA11: =+'loans_av rate'!C10 -> 22828512 | AB11: =+'loans_av rate'!E10 -> 22828512 | AC11: =+'loans_av rate'!G10 -> 0
A12: 1.1. | B12: на приобретение недвижимого имущества | C12: =+E12+G12 -> 22828512 | D12: 0.095631003 | E12: 22828512 | F12: 0.095631003 | I12: 6351 | J12: 2016883 | K12: 4883052 | L12: 4061818 | M12: 11860408 | N12: 20971970 | O12: 1526660 | P12: 141194 | Q12: 18 | R12: 188670 | S12: =SUM(T12:X12) -> 209689 | T12: 0 | U12: 152666 | V12: 35299 | W12: 9 | X12: 21715
A13: 1.2. | B13: на ремонт недвижимого имущества | C13: =+E13+G13 -> 0 | D13: 0.17191684 | E13: 0 | F13: 0.17191684 | S13: =SUM(T13:X13) -> 8533422 | T13: 0 | U13: 3789693 | V13: 1696712 | W13: 0 | X13: 3047017
A14: 1.3. | B14: на реконструкцию недвижимого имущества | C14: =+E14+G14 -> 0 | S14: =SUM(T14:X14) -> 0
A15: 1.4. | B15: на строительство недвижимого имущества | C15: =+E15+G15 -> 0 | S15: =SUM(T15:X15) -> 0
