Workbook
Name jop: #REF!
Name kol: #REF!
Name RISKTOTASS: SUM('[6]Calculation of Risk Weighted As'!$C$38:$F$38)
Name RISKTOTASS: SUM('[7]Calculation of Risk Weighted As'!$C$41:$G$41)
Name TwentyLargestData: #REF!
Name Е: #REF!

Sheet Asset quality
A1: АКТИВЛАР ТАСНИФИ ВА УЛАР БЎЙИЧА ЯРАТИЛГАН ЭҲТИМОЛИЙ ЙЎҚОТИШЛАРНИ ҚОПЛАШ ЗАХИРАЛАРИ ТЎҒРИСИДА ҲИСОБОТ | S1: 2-жадвал | V1: №2
B3: "Ўзсаноатқурилишбанк" АТБ | Q3: 46021 | T3: минг. сўмда
A4: № | B4: Активлар таркиби* | C4: Қолдиқ | D4: Сифат тоифаси | I4: Муддати ўтган қарздорлик (брутто) | O4: Зарарларни қоплаш захираси
I5: Жами | J5: 30 кунгача | K5: 31дан 90 кунгача | L5: 91дан 180 кунгача | M5: 181 дан 365 кунгача | N5: 366 кун ва ундан ортиқ | O5: ҳақиқатдан яратилган захиралар
O6: Жами | P6: сифат тоифаси бўйича
D7: I | E7: II | F7: III | G7: IV | H7: V | P7: I | Q7: II | R7: III | S7: IV | T7: V
A8: А | B8: Б | C8: В | D8: Г | E8: Д | F8: Е | G8: Ж | H8: З | I8: И | J8: К | K8: Л | L8: М | M8: Н | N8: О | O8: П | P8: Р | Q8: С | R8: Т | S8: У | T8: Ф
B9: Жами активлар | C9: =SUM(C10:C58)+C60-C59 -> 102438659711 | D9: =SUM(D10:D58)-D59+D60 -> 90101210261 | E9: =SUM(E10:E58)-E59+E60 -> 13119177802 | F9: =SUM(F10:F58)-F59+F60 -> 219279699 | G9: =SUM(G10:G58)-G59+G60 -> 605533577 | H9: =SUM(H10:H58)-H59+H60 -> 1791089731 | I9: =SUM(I10:I60) -> 5462182165 | J9: =SUM(J10:J60) -> 1857643039 | K9: =SUM(K10:K60) -> 2636236689 | L9: =SUM(L10:L60) -> 209905190 | M9: =SUM(M10:M60) -> 363261057 | N9: =SUM(N10:N60) -> 395136190 | O9: =SUM(O10:O60) -> 4092811566 | P9: =SUM(P10:P60) -> 695180207 | ... T9: =SUM(T10:T60) -> 1524578442
A10: 1 | B10: Кассадаги нақд пул ва бошқа тўлов ҳужжатлари | C10: =SUM(D10:H10)-O10+P10 -> 2006706908 | D10: 2006706908 | E10: 0 | F10: 0 | G10: 0 | H10: 0 | I10: =SUM(J10:N10) -> 0 | J10: 0 | K10: 0 | L10: 0 | M10: 0 | N10: 0 | O10: =SUM(P10:T10) -> 0 | P10: 0 | Q10: 0 | R10: 0 | S10: 0 | T10: 0 | U10: 10100
A11: 2 | B11: Банкнинг Марказий банкдаги маблағлар | C11: =SUM(D11:H11)-O11+P11 -> 4172748921 | D11: 4172748921 | E11: 0 | F11: 0 | G11: 0 | H11: 0 | I11: =SUM(J11:N11) -> 0 | J11: 0 | K11: 0 | L11: 0 | M11: 0 | N11: 0 | O11: =SUM(P11:T11) -> 0 | P11: 0 | Q11: 0 | R11: 0 | S11: 0 | T11: 0 | U11: 10300
A12: 3 | B12: Бошқа банклар ва молиявий ташкилотлардан олиниши лозим бўлган маблағлар | C12: =SUM(D12:H12)-O12+P12 -> 12590856955 | D12: 12590856955 | E12: 0 | F12: 0 | G12: 0 | H12: 0 | I12: =SUM(J12:N12) -> 0 | J12: 0 | K12: 0 | L12: 0 | M12: 0 | N12: 0 | O12: =SUM(P12:T12) -> 96908570 | P12: 96908570 | Q12: 0 | R12: 0 | S12: 0 | T12: 0 | U12: 10500
A13: 4 | B13: Фойда ёки зарар орқали ҳаққоний қийматда баҳоланадиган қимматли қоғозлар | C13: =SUM(D13:H13)-O13+P13 -> 6949463201 | D13: 6949463201 | E13: 0 | F13: 0 | G13: 0 | H13: 0 | I13: =SUM(J13:N13) -> 0 | J13: 0 | K13: 0 | L13: 0 | M13: 0 | N13: 0 | O13: =SUM(P13:T13) -> 0 | P13: 0 | Q13: 0 | R13: 0 | S13: 0 | T13: 0 | U13: 10700
A14: 5 | B14: Бошқа умумлашган даромад орқали ҳаққоний қийматда баҳоланадиган қимматли қоғозларга қилинган инвестициялар | C14: =SUM(D14:H14)-O14+P14 -> 65000000 | D14: 65000000 | E14: 0 | F14: 0 | G14: 0 | H14: 0 | I14: =SUM(J14:N14) -> 0 | J14: 0 | K14: 0 | L14: 0 | M14: 0 | N14: 0 | O14: =SUM(P14:T14) -> 0 | P14: 0 | Q14: 0 | R14: 0 | S14: 0 | T14: 0 | U14: 10800
A15: 6 | B15: Олди-сотдига мўлжалланган қимматбаҳо металлар, тошлар ва тангалар | C15: =SUM(D15:H15)-O15+P15 -> 657455 | D15: 657455 | E15: 0 | F15: 0 | G15: 0 | H15: 0 | I15: =SUM(J15:N15) -> 0 | J15: 0 | K15: 0 | L15: 0 | M15: 0 | N15: 0 | O15: =SUM(P15:T15) -> 6575 | P15: 6575 | Q15: 0 | R15: 0 | S15: 0 | T15: 0 | U15: 10900
A16: 7 | B16: Сотиб олинган дебиторлик қарзлари — Факторинг | C16: =SUM(D16:H16)-O16+P16 -> 218323686 | D16: 57590330 | E16: 165791505 | F16: 16203587 | G16: 2856809 | H16: 0 | I16: =SUM(J16:N16) -> 237467050 | J16: 74261151 | K16: 142968769 | L16: 16873070 | M16: 3364060 | N16: 0 | O16: =SUM(P16:T16) -> 24694448 | P16: 575903 | Q16: 17968248 | R16: 4468267 | S16: 1682030 | T16: 0 | U16: 11100
A17: 8 | B17: Мижозларнинг аккредитив ва/ёки траст ҳужжатлари билан кафолатланган тратталари бўйича мажбуриятлари | C17: =SUM(D17:H17)-O17+P17 -> 228458304 | D17: 0 | E17: 0 | F17: 0 | G17: 0 | H17: 228458304 | I17: =SUM(J17:N17) -> 0 | J17: 0 | K17: 0 | L17: 0 | M17: 0 | N17: 0 | O17: =SUM(P17:T17) -> 0 | P17: 0 | Q17: 0 | R17: 0 | S17: 0 | T17: 0 | U17: 11500
A18: 9 | B18: Банкнинг тўланмаган акцептлари бўйича мижозларнинг мажбуриятлари | C18: =SUM(D18:H18)-O18+P18 -> 0 | D18: 0 | E18: 0 | F18: 0 | G18: 0 | H18: 0 | I18: =SUM(J18:N18) -> 0 | J18: 0 | K18: 0 | L18: 0 | M18: 0 | N18: 0 | O18: =SUM(P18:T18) -> 0 | P18: 0 | Q18: 0 | R18: 0 | S18: 0 | T18: 0 | U18: 11700
A19: 10 | B19: РЕПО битимлари бўйича сотиб олинган қимматли қоғозлар | C19: =SUM(D19:H19)-O19+P19 -> 0 | D19: 0 | E19: 0 | F19: 0 | G19: 0 | H19: 0 | I19: =SUM(J19:N19) -> 0 | J19: 0 | K19: 0 | L19: 0 | M19: 0 | N19: 0 | O19: =SUM(P19:T19) -> 0 | P19: 0 | Q19: 0 | R19: 0 | S19: 0 | T19: 0 | U19: 11800
A20: 11 | B20: Марказий банкка берилган қисқа муддатли кредитлар | C20: =SUM(D20:H20)-O20+P20 -> 0 | D20: 0 | E20: 0 | F20: 0 | G20: 0 | H20: 0 | I20: =SUM(J20:N20) -> 0 | J20: 0 | K20: 0 | L20: 0 | M20: 0 | N20: 0 | O20: =SUM(P20:T20) -> 0 | P20: 0 | Q20: 0 | R20: 0 | S20: 0 | T20: 0 | U20: 11900
A21: 12 | B21: Бошқа банкларга берилган қисқа муддатли кредитлар | C21: =SUM(D21:H21)-O21+P21 -> 0 | D21: 0 | E21: 0 | F21: 0 | G21: 0 | H21: 0 | I21: =SUM(J21:N21) -> 0 | J21: 0 | K21: 0 | L21: 0 | M21: 0 | N21: 0 | O21: =SUM(P21:T21) -> 0 | P21: 0 | Q21: 0 | R21: 0 | S21: 0 | T21: 0 | U21: 12100
A22: 13 | B22: Ҳукуматга берилган қисқа муддатли кредитлар | C22: =SUM(D22:H22)-O22+P22 -> 0 | D22: 0 | E22: 0 | F22: 0 | G22: 0 | H22: 0 | I22: =SUM(J22:N22) -> 0 | J22: 0 | K22: 0 | L22: 0 | M22: 0 | N22: 0 | O22: =SUM(P22:T22) -> 0 | P22: 0 | Q22: 0 | R22: 0 | S22: 0 | T22: 0 | U22: 12300
A23: 14 | B23: Бюджет ташкилотларига берилган қисқа муддатли кредитлар | C23: =SUM(D23:H23)-O23+P23 -> 123299477 | D23: 123299477 | E23: 0 | F23: 0 | G23: 0 | H23: 0 | I23: =SUM(J23:N23) -> 0 | J23: 0 | K23: 0 | L23: 0 | M23: 0 | N23: 0 | O23: =SUM(P23:T23) -> 1232995 | P23: 1232995 | Q23: 0 | R23: 0 | S23: 0 | T23: 0 | U23: 12400
A24: 15 | B24: Жисмоний шахсларга берилган қисқа муддатли кредитлар | C24: =SUM(D24:H24)-O24+P24 -> 125142101 | D24: 122550190 | E24: 957593 | F24: 763551 | G24: 2514992 | H24: 369179 | I24: =SUM(J24:N24) -> 3864840 | J24: 123488 | K24: 313960 | L24: 675202 | M24: 2357562 | N24: 394628 | O24: =SUM(P24:T24) -> 3238906 | P24: 1225502 | Q24: 188499 | R24: 192230 | S24: 1263496 | T24: 369179 | U24: 12500
A25: 16 | B25: Якка тартибдаги тадбиркорларга берилган қисқа муддатли кредитлар | C25: =SUM(D25:H25)-O25+P25 -> 47761159 | D25: 47009180 | E25: 493813 | F25: 278594 | G25: 434859 | H25: 52522 | I25: =SUM(J25:N25) -> 702328 | J25: 10000 | K25: 120431 | L25: 163303 | M25: 356072 | N25: 52522 | O25: =SUM(P25:T25) -> 977901 | P25: 470092 | Q25: 168210 | R25: 69648 | S25: 217429 | T25: 52522 | U25: 12600
A26: 17 | B26: Давлат корхоналари, ташкилотлари ва муассасаларига берилган қисқа муддатли кредитлар | C26: =SUM(D26:H26)-O26+P26 -> 3875795556 | D26: 1925928992 | E26: 2166518404 | F26: 0 | G26: 0 | H26: 0 | I26: =SUM(J26:N26) -> 281709195 | J26: 0 | K26: 281709195 | L26: 0 | M26: 0 | N26: 0 | O26: =SUM(P26:T26) -> 234603428 | P26: 17951588 | Q26: 216651840 | R26: 0 | S26: 0 | T26: 0 | U26: 12700
A27: 18 | B27: Тадбиркорлик фаолиятини қўллаб-қувватлаш давлат жамғармаси кўмагида берилган қисқа муддатли кредитлар | C27: =SUM(D27:H27)-O27+P27 -> 140478777 | D27: 133876871 | E27: 7335451 | F27: 0 | G27: 0 | H27: 0 | I27: =SUM(J27:N27) -> 0 | J27: 0 | K27: 0 | L27: 0 | M27: 0 | N27: 0 | O27: =SUM(P27:T27) -> 2072314 | P27: 1338769 | Q27: 733545 | R27: 0 | S27: 0 | T27: 0 | U27: 12800
A28: 19 | B28: Чет эл капитали иштирокидаги корхоналарга берилган қисқа муддатли кредитлар | C28: =SUM(D28:H28)-O28+P28 -> 1984666940 | D28: 1997028673 | E28: 2833736 | F28: 0 | G28: 0 | H28: 0 | I28: =SUM(J28:N28) -> 141660613 | J28: 141622300 | K28: 38313 | L28: 0 | M28: 0 | N28: 0 | O28: =SUM(P28:T28) -> 35165756 | P28: 19970287 | Q28: 15195469 | R28: 0 | S28: 0 | T28: 0 | U28: 12900
... A48: 39 | B48: Амортизацияланган қиймати бўйича баҳоланадиган қарз қимматли қоғозларга қилинган инвестициялар | C48: =SUM(D48:H48)-O48+P48 -> 310050000 | D48: 310050000 | E48: 0 | F48: 0 | G48: 0 | H48: 0 | I48: =SUM(J48:N48) -> 0 | J48: 0 | K48: 0 | L48: 0 | M48: 0 | N48: 0 | O48: =SUM(P48:T48) -> 3100500 | P48: 3100500 | Q48: 0 | R48: 0 | S48: 0 | T48: 0 | U48: 15900
A49: 40 | B49: Олиниши лозим бўлган ҳисобланган фоизлар | C49: =SUM(D49:H49)-O49+P49 -> 5975826954 | D49: 5284514053 | E49: 897597659 | F49: 7403607 | G49: 62444000 | H49: 459856333 | I49: =SUM(J49:N49) -> 2148690840 | J49: ='Aging Analysis'!M22 -> 1049071107 | K49: ='Aging Analysis'!O22+'Aging Analysis'!Q22 -> 838312288 | L49: ='Aging Analysis'!S22 -> 68368048 | M49: ='Aging Analysis'!U22 -> 95371174 | N49: ='Aging Analysis'!W22+'Aging Analysis'!Y22 -> 97568223 | O49: =SUM(P49:T49) -> 788833839 | P49: 52845141 | Q49: 257270650 | R49: 6582694 | S49: 57948744 | T49: 414186610 | U49: 16300
A50: 41 | B50: Олиниши лозим бўлган ҳисобланган фоизсиз даромадлар | C50: =SUM(D50:H50)-O50+P50 -> 412599235 | D50: 206690337 | E50: 219985743 | F50: 1937594 | G50: 17562446 | H50: 12662029 | I50: =SUM(J50:N50) -> 0 | J50: 0 | K50: 0 | L50: 0 | M50: 0 | N50: 0 | O50: =SUM(P50:T50) -> 48305817 | P50: 2066903 | Q50: 20363203 | R50: 506097 | S50: 12707585 | T50: 12662029 | U50: 16400
A51: 42 | B51: Асосий воситалар | C51: =SUM(D51:H51)-O51+P51 -> 3694759110 | D51: 3694759110 | E51: 0 | F51: 0 | G51: 0 | H51: 0 | I51: =SUM(J51:N51) -> 0 | J51: 0 | K51: 0 | L51: 0 | M51: 0 | N51: 0 | O51: =SUM(P51:T51) -> 0 | P51: 0 | Q51: 0 | R51: 0 | S51: 0 | T51: 0 | U51: 16500
A52: 43 | B52: Номоддий активлар | C52: =SUM(D52:H52)-O52+P52 -> 72964375 | D52: 72964375 | E52: 0 | F52: 0 | G52: 0 | H52: 0 | I52: =SUM(J52:N52) -> 0 | J52: 0 | K52: 0 | L52: 0 | M52: 0 | N52: 0 | O52: =SUM(P52:T52) -> 0 | P52: 0 | Q52: 0 | R52: 0 | S52: 0 | T52: 0 | U52: 16600
A53: 44 | B53: Банкнинг бошқа хусусий мулклари | C53: =SUM(D53:H53)-O53+P53 -> 712257850 | D53: 718757850 | E53: 0 | F53: 0 | G53: 0 | H53: 131678722 | I53: =SUM(J53:N53) -> 0 | J53: 0 | K53: 0 | L53: 0 | M53: 0 | N53: 0 | O53: =SUM(P53:T53) -> 145366301 | P53: 7187579 | Q53: 0 | R53: 0 | S53: 0 | T53: 138178722 | U53: 16700
A54: 45 | B54: Муддати узайтирилган дебитор қарздорлик | C54: =SUM(D54:H54)-O54+P54 -> 321868635 | D54: 293160739 | E54: 24786564 | F54: 3713675 | G54: 9729159 | H54: 24780382 | I54: =SUM(J54:N54) -> 0 | J54: 0 | K54: 0 | L54: 0 | M54: 0 | N54: 0 | O54: =SUM(P54:T54) -> 37233491 | P54: 2931607 | Q54: 2603889 | R54: 928419 | S54: 4864579 | T54: 25904997 | U54: 16800
A55: 46 | B55: Ҳосилавий инструментларнинг ревальвацияси натижасида ўзлаштирилмаган фойда | C55: =SUM(D55:H55)-O55+P55 -> 0 | D55: 0 | E55: 0 | F55: 0 | G55: 0 | H55: 0 | I55: =SUM(J55:N55) -> 0 | J55: 0 | K55: 0 | L55: 0 | M55: 0 | N55: 0 | O55: =SUM(P55:T55) -> 0 | P55: 0 | Q55: 0 | R55: 0 | S55: 0 | T55: 0 | U55: 16900
A56: 47 | B56: Валюталар савдоси ва валюта позициялари | C56: =SUM(D56:H56)-O56+P56 -> 0 | D56: 0 | E56: 0 | F56: 0 | G56: 0 | H56: 0 | I56: =SUM(J56:N56) -> 0 | J56: 0 | K56: 0 | L56: 0 | M56: 0 | N56: 0 | O56: =SUM(P56:T56) -> 0 | P56: 0 | Q56: 0 | R56: 0 | S56: 0 | T56: 0 | U56: 17100
A57: 48 | B57: Транзит ҳисобварақлари | C57: =SUM(D57:H57)-O57+P57 -> 0 | D57: 0 | E57: 0 | F57: 0 | G57: 0 | H57: 0 | I57: =SUM(J57:N57) -> 0 | J57: 0 | K57: 0 | L57: 0 | M57: 0 | N57: 0 | O57: =SUM(P57:T57) -> 0 | P57: 0 | Q57: 0 | R57: 0 | S57: 0 | T57: 0 | U57: 17300
A58: 49 | B58: Мижозларнинг банк карталаридан ҳисобдан чиқарилиши лозим бўлган маблағлар бўйича транзит ҳисобварақлари | C58: =SUM(D58:H58)-O58+P58 -> 432932007 | D58: 432932007 | E58: 0 | F58: 0 | G58: 0 | H58: 0 | I58: =SUM(J58:N58) -> 0 | J58: 0 | K58: 0 | L58: 0 | M58: 0 | N58: 0 | O58: =SUM(P58:T58) -> 4329320 | P58: 4329320 | Q58: 0 | R58: 0 | S58: 0 | T58: 0 | U58: 17400
A59: 50 | B59: Стандарт активлар бўйича яратилган захирлар | C59: =SUM(D59:H59)-O59 -> 695180207 | D59: 695180207 | E59: 0 | F59: 0 | G59: 0 | H59: 0 | I59: =SUM(J59:N59) -> 0 | J59: 0 | K59: 0 | L59: 0 | M59: 0 | N59: 0 | O59: =SUM(P59:T59) -> 0 | P59: 0 | Q59: 0 | R59: 0 | S59: 0 | T59: 0 | U59: 17700 | W59: =+[8]Balance!$C$39 -> 695180207
A60: 51 | B60: Бошқа активлар | C60: =SUM(D60:H60)-O60+P60 -> 1482663662 | D60: 1473382146 | E60: 3302881 | F60: 8273120 | G60: 80459 | H60: 1720143 | I60: =SUM(J60:N60) -> 0 | J60: 0 | K60: 0 | L60: 0 | M60: 0 | N60: 0 | O60: =SUM(P60:T60) -> 5969336 | P60: 1874249 | Q60: 266435 | R60: 2068280 | S60: 40229 | T60: 1720143 | U60: 19900
...

Sheet Income 
A1: МОЛИЯВИЙ НАТИЖАЛАР ТЎҒРИСИДА ҲИСОБОТ | E1: 3-жадвал
B3: =+'Asset quality'!B3 -> "Ўзсаноатқурилишбанк" АТБ | D3: =+'Asset quality'!Q3 -> 46021 | E3: =+'Asset quality'!T3 -> минг. сўмда
A4: № | B4: Кўрсаткичлар | C4: Жами | D4: миллий валютада | E4: хорижий валютада (экв. сўмда)
A5: 1. | B5: ФОИЗЛИ ДАРОМАДЛАР
A6: a. | B6: Марказий банкдаги ҳисобварақлар бўйича фоизли даромадлар | C6: =+D6+E6 -> 5956850 | D6: 5956850 | E6: 0 | G6: =+'Analysis of Interest'!C17 -> 5956850
A7: б. | B7: Бошқа банклардаги ҳисобварақлар бўйича фоизли даромадлар | C7: =+D7+E7 -> 540479128 | D7: 86080352 | E7: 454398776 | G7: =+'Analysis of Interest'!C18 -> 540479128
A8: в. | B8: Амортизацияланган қиймати бўйича баҳоланадиган қарз қимматли қоғозларга қилинган инвестициялар бўйича фоизли даромадлар | C8: =+D8+E8 -> 19968826 | D8: 19968826 | E8: 0
A9: г. | B9: Қимматли қоғозлар ва уларга қилинган инвестициялар бўйича фоизли даромадлар | C9: =+D9+E9 -> 972492922 | D9: 871536966 | E9: 100955956 | G9: =+'Analysis of Interest'!C28 -> 972492922
A10: д. | B10: Мижозларнинг мажбуриятлари бўйича ҳисобланган фоизлар | C10: =+D10+E10 -> 0 | D10: 0 | E10: 0
A11: е. | B11: Банкнинг тўланмаган акцептлари юзасидан мижозлар мажбуриятлари бўйича фоизли даромадлар | C11: =+D11+E11 -> 0 | D11: 0 | E11: 0
A12: ж. | B12: Кредит ва лизинг операциялари бўйича фоизлар, дисконтлар (чегирмалар) ва бадаллар | C12: =+D12+E12 -> 9213565209 | D12: 5440404855 | E12: 3773160354 | G12: =+'Analysis of Interest'!C14 -> 9213565209
A13: з. | B13: Қимматли қоғозлар билан амалга оширилган РЕПО битимлари бўйича фоизли даромадлар | C13: =+D13+E13 -> 17311219 | D13: 17311219 | E13: 0 | G13: =+'Analysis of Interest'!C39 -> 17311219
A14: и. | B14: Бошқа фоизли даромадлар | C14: =+D14+E14 -> 28373976 | D14: 28373976 | E14: 0 | G14: =+'Analysis of Interest'!C40 -> 28373976
A15: к. | B15: Жами фоизли даромадлар | C15: =SUM(C6:C14) -> 10798148130 | D15: =SUM(D6:D14) -> 6469633044 | E15: =SUM(E6:E14) -> 4328515086 | G15: =+'Analysis of Interest'!C42 -> 10798148130
A17: 2. | B17: ФОИЗЛИ ХAРAЖAТЛAР
A18: а. | B18: Талаб қилиб олингунча сақланадиган депозитлар бўйича фоизли харажатлар | C18: =+D18+E18 -> 192446073 | D18: 160672455 | E18: 31773618 | G18: =+'Analysis of Interest'!C52 -> 192446073
A19: б. | B19: Муддатли депозитлар бўйича фоизли харажатлар | C19: =+D19+E19 -> 2935629121 | D19: 2803790307 | E19: 131838814 | G19: =+'Analysis of Interest'!C61 -> 2935629121
A20: в. | B20: Марказий банкнинг ҳисобварақлари бўйича фоизли харажатлар | C20: =+D20+E20 -> 0 | D20: 0 | E20: 0
A21: г. | B21: Бошқа банкларнинг ҳисобварақлари бўйича фоизли харажатлар | C21: =+D21+E21 -> 389880608 | D21: 235163973 | E21: 154716635
A22: д. | B22: Жами депозитлар бўйича фоизли харажатлар | C22: =SUM(C18:C21) -> 3517955802 | D22: =SUM(D18:D21) -> 3199626735 | E22: =SUM(E18:E21) -> 318329067
A23: е. | B23: Кредитлар бўйича фоизли харажатлар | C23: =+D23+E23 -> 2305541410 | D23: 391140924 | E23: 1914400486 | G23: =+'Analysis of Interest'!C67 -> 2305541410
A24: ж. | B24: Қимматли қоғозлар билан амалга оширилган РЕПО битимлари бўйича фоизли харажатлар | C24: =+D24+E24 -> 148206712 | D24: 148206712 | E24: 0 | G24: =+'Analysis of Interest'!C68 -> 148206712
A25: з. | B25: Бошқа фоизли харажатлар | C25: =+D25+E25 -> 1437841583 | D25: 723893883 | E25: 713947700
A26: и. | B26: Жами кредит ва бошқа қарздорликлар бўйича фоизли харажатлар | C26: =SUM(C23:C25) -> 3891589705 | D26: =SUM(D23:D25) -> 1263241519 | E26: =SUM(E23:E25) -> 2628348186
A27: к. | B27: Жами фоизли харажатлар | C27: =C26+C22 -> 7409545507 | D27: =D26+D22 -> 4462868254 | E27: =E26+E22 -> 2946677253 | G27: =+'Analysis of Interest'!C72 -> 7409545507
A29: 3. | B29: Активлар бўйича эҳтимолий йўқотишларга қарши яратилган захираларни баҳолашдан олдинги соф даромад | C29: =C15-C27 -> 3388602623 | D29: =D15-D27 -> 2006764790 | E29: =E15-E27 -> 1381837833
A30: а. | B30: Минус: Кредит ва лизинглар бўйича кўрилиши мумкин бўлган зарарларни баҳолаш | C30: =+D30+E30 -> 2466678392 | D30: 1216635160 | E30: 1250043232
A31: б. | B31: Минус: Қимматли қоғозлар бўйича кўрилиши мумкин бўлган зарарларни баҳолаш | C31: =+D31+E31 -> 0 | D31: 0 | E31: 0
A32: в. | B32: Минус: Инвестициялар бўйича кўрилиши мумкин бўлган зарарларни баҳолаш | C32: =+D32+E32 -> 0 | D32: 0 | E32: 0
A33: г. | B33: Минус: Бошқа активлар бўйича кўрилиши мумкин бўлган зарарларни баҳолаш | C33: =+D33+E33 -> 1463458178 | D33: 1186933686 | E33: 276524492
A34: д. | B34: Активлар бўйича эҳтимолий зарарларни баҳолашдан кейинги соф даромад | C34: =C29-C30-C31-C32-C33 -> -541533947 | D34: =D29-D30-D31-D32-D33 -> -396804056 | E34: =E29-E30-E31-E32-E33 -> -144729891
A36: 4. | B36: ФОИЗСИЗ ДАРОМАДЛАР
A37: а. | B37: Кўрсатилган хизматлар ва воситачилик учун олинган даромадлар | C37: =+D37+E37 -> 704393857 | D37: 540193841 | E37: 164200016
A38: б. | B38: Хорижий валюталардаги фойда | C38: =+D38+E38 -> 3084670386 | D38: 1183408393 | E38: 1901261993
A39: в. | B39: Тижорат операцияларидан олинган фойда | C39: =+D39+E39 -> 1316598 | D39: -14089098 | E39: 15405696
A40: г. | B40: Инвестициядан олинган фойда ва дивидендлар | C40: =+D40+E40 -> 68373696 | D40: 67875673 | E40: 498023
A41: д. | B41: Активлар бўйича эҳтимолий йўқотишларга қарши яратилган захираларнинг қайтарилиши | C41: =+D41+E41 -> 2607850054 | D41: 1172133085 | E41: 1435716969
A42: е. | B42: Ҳисобдан чиқарилган кредитлар қайтарилиши билан боғлиқ даромадлар | C42: =+D42+E42 -> 403454 | D42: 393168 | E42: 10286
A43: ж. | B43: Бошқа фоизсиз даромадлар | C43: =+D43+E43 -> 563145794 | D43: 345918445 | E43: 217227349
A44: з. | B44: Жами фоизсиз даромадлар | C44: =SUM(C37:C43) -> 7030153839 | D44: =SUM(D37:D43) -> 3295833507 | E44: =SUM(E37:E43) -> 3734320332
...

Sheet Analysis of Interest
B1: ФОИЗЛИ ДАРОМАД ВА ХАРАЖАТЛАР ТАҲЛИЛИ | C1: 4-жадвал
B3: =+'Asset quality'!B3 -> "Ўзсаноатқурилишбанк" АТБ | C3: =+'Asset quality'!Q3 -> 46021
A4: № | B4: Кўрсаткичлар | C4: =+'Asset quality'!T3 -> минг. сўмда
A5: 1. | B5: КРЕДИТ ВА ЛИЗИНГ ОПЕРАЦИЯЛАРИ БЎЙИЧА ФОИЗЛИ ДАРОМАДЛАР
A6: a. | B6: Марказий банкка берилган қисқа муддатли кредитлар | C6: 0
A7: б. | B7: Бошқа банкларга берилган кредитлар | C7: 0
A8: в. | B8: Ҳукуматга берилган кредитлар | C8: 0
A9: г. | B9: Жисмоний шахсларга берилган кредит ва лизинглар | C9: 2212569400
A10: д. | B10: Давлат корхоналарига берилган кредит ва лизинглар | C10: 1627491445
A11: е. | B11: Қўшма ва чет эл капитали иштирокидаги корхоналарга берилган кредит ва лизинглар | C11: 1265227810
A12: ж. | B12: Хусусий корхоналар, хўжалик ширкатлари ва жамиятларга берилган кредит ва лизинглар | C12: 3938465840
A13: з. | B13: Бошқа кредит ва лизинглар | C13: 169810714
A14: и. | B14: Жами кредит ва лизинг операциялари бўйича фоизли даромад | C14: =SUM(C6:C13) -> 9213565209 | E14: =+'Income '!C12 -> 9213565209
A16: 2. | B16: ВАКИЛЛИК ҲИСОБВАРАҚЛАРИ БЎЙИЧА ФОИЗЛИ ДАРОМАДЛАР
A17: a. | B17: Марказий банкдаги ҳисобварақлар бўйича фоизли даромадлар | C17: 5956850 | E17: =+'Income '!C6 -> 5956850
A18: б. | B18: Бошқа банклардаги ҳисобварақлар бўйича фоизли даромадлар | C18: 540479128 | E18: =+'Income '!C7 -> 540479128
B19: Жами вакиллик ҳисобварағи бўйича фоизли даромадлар | C19: =SUM(C17:C18) -> 546435978
A21: 3. | B21: ҚИММАТЛИ ҚОҒОЗЛАР ВА УЛАРГА ҚИЛИНГАН ИНВЕСТИЦИЯЛАР БЎЙИЧА ФОИЗЛИ ДАРОМАДЛАР
A22: a. | B22: Давлат қимматли қоғозлари | C22: 879600306
A23: б. | B23: Марказий банкнинг облигациялари ва бошқа қимматли қоғозлари | C23: 51555973
A24: в. | B24: Давлат корхоналарининг қарз қимматли қоғозлари бўйича фоизли даромадлар | C24: 12350000
A25: г. | B25: Еврооблигациялар бўйича фоизли даромадлар | C25: 26970967
A26: д. | B26: Хусусий корхоналарнинг қимматли қоғозлари | C26: 0
A27: е. | B27: Бошқа қимматли қоғозлар | C27: 2015676
A28: ж. | B28: Жами олди-сотди қимматли қоғозлар бўйича фоизли даромадлар | C28: =SUM(C22:C27) -> 972492922 | E28: =+'Income '!C9 -> 972492922
A30: 4. | B30: ИНВЕСТИЦИЯЛАР БЎЙИЧА ФОИЗЛИ ДАРОМАДЛАР
A31: a. | B31: Давлат қимматли қоғозлари | C31: 0
A32: б. | B32: Марказий банкнинг облигациялари ва бошқа қарз қимматли қоғозларига қилинган инвестициялар бўйича фоизли даромадлар | C32: 0
A33: в. | B33: Корхоналарнинг қарз қимматли қоғозларига қилинган инвестициялар бўйича фоизли даромадлар | C33: 2379785
A34: г. | B34: Еврооблигациялар | C34: 0
A35: д. | B35: Бошқа қимматли қоғозлар | C35: 17589041
A36: е. | B36: Жами инвестициялар бўйича фоизли даромадлар | C36: =SUM(C31:C35) -> 19968826
A38: 5. | B38: БОШҚА ФОИЗЛИ ДАРОМАДЛАР
A39: a. | B39: Қимматли қоғозлар билан амалга оширилган репо битимлари бўйича фоизли даромадлар | C39: 17311219
A40: б. | B40: Бошқа фоизли даромадлар | C40: 28373976 | E40: =+'Income '!C14 -> 28373976
A42: 6. | B42: ЖАМИ ФОИЗЛИ ДАРОМАДЛАР | C42: =C14+C19+C28+C36+C39+C40 -> 10798148130 | E42: =+'Income '!C15 -> 10798148130
A44: 7. | B44: ДЕПОЗИТЛАР БЎЙИЧА ФОИЗЛИ ХАРАЖАТЛАР
A45: A. | B45: Талаб қилиб олингунча сақланадиган депозитлар
A46: a. | B46: Ҳукумат | C46: 65266745
A47: б. | B47: Жисмоний шахслар | C47: 0
...

Sheet Changes in Equity
A1: ХУСУСИЙ КАПИТАЛДАГИ ЎЗГАРИШЛАР | C1: 7-жадвал
B3: =+'Asset quality'!B3 -> "Ўзсаноатқурилишбанк" АТБ | C3: =+'Asset quality'!Q3 -> 46021
A4: № | B4: Кўрсаткичлар | C4: =+'Asset quality'!T3 -> минг. сўмда
A5: 1. | B5: Ўтган йил учун дастлабки ҳисобланган умумий капитал | C5: 10025446358
A6: 2. | B6: Хусусий капиталдаги ўтган йил учун ҳисоботларда кўрсатилмаган тузатишлар, (соф) | C6: 0
A7: 3. | B7: Ўтган календар йили якуни бўйича балансдаги тузатишлар (3=1-2 ) | C7: =SUM(C5:C6) -> 10025446358
A8: 4. | B8: Йил бошидан соф фойда (зарар) | C8: =+'Income '!C77 -> 1880069362 | D8: =+[8]Balance!$C$76 -> 1880069362 | E8: =+C8-D8 -> 0
A9: 5. | B9: Жорий йилда сотиш, айирбошлаш, сотиб олиш ёки қайтиб сотиб олиш (соф кирим)
A10: 6. | B10: Жорий йил учун бошланғич қийматига нисбатан баҳолаш қийматининг ошган суммаси | C10: -2697058
A11: 7. | B11: МИНУС: Имтиёзли акциялар бўйича эълон қилинган пул дивидендлари | C11: 1616900
A12: 8. | B12: МИНУС: Оддий акциялар бўйича эълон қилинган пуллик дивидендлар
A13: 9. | B13: Жорий йилнинг соф хусусий капиталига таъсир этувчи бошқа моддалар | C13: -26035954
A14: 10. | B14: Жорий давр якуни бўйича жами хусусий капитал | C14: =C7+SUM(C8:C10)-SUM(C11:C12)+C13 -> 11875165808 | D14: =+[8]Balance!$C$77 -> 11875165808 | E14: =+C14-D14 -> 0
B16: Бошқарув Раис имзоси:
B18: Бош бухгалтер имзоси:

Sheet Loans Receivable
A1: ИҚТИСОДИЁТ ТАРМОҚЛАРИ, МИЖОЗЛАР ТУРЛАРИ, ВА ТАЪМИНОТ ТУРЛАРИ БЎЙИЧА АЖРАТИЛГАН КРЕДИТЛАР ВА ЛИЗИНГЛАР ҲИСОБОТИ | W1: 8-жадвал
B3: =+'Asset quality'!B3 -> "Ўзсаноатқурилишбанк" АТБ | T3: =+'Asset quality'!Q3 -> 46021 | X3: =+'Asset quality'!T3 -> минг. сўмда
A4: № | B4: Иқтисодиёт тармоқлари бўйича | C4: Кредит суммаси | D4: шундан | F4: шундан муаммоли кредитлар | J4: шундан
D5: миллий валютада | E5: хорижий валютада (экв. сўмда) | F5: NPL | G5: шундан | J5: Депозитлар | K5: Ўзбекистон Республикаси Ҳукумати тамонидан кафолатланган кредитлар | L5: шундан | M5: Транспорт воситалари | N5: Инвентарлар | O5: Кўчмас мулк | P5: шундан | R5: Асбоб ускуналар | S5: Векселлар (облигациялар) | T5: Акциялар | U5: Учинчи шахс кафолати | V5: Учинчи шахс кафиллиги | W5: Суғурта полиси | X5: Таъминотсиз | Y5: Бошқа кафолатлар
G6: Қониқарсиз | H6: Шубҳали | I6: Умидсиз | L6: Ўзбекистон Республикаси Ҳукумати томонидан кафолатланган хорижий валютадаги (эквивалент сўмда) кредитлар | P6: турар жой (хонадон) | Q6: тижорат кўчмас мулки
A7: Код | B7: (А) | C7: (Б) | D7: (Б1) | E7: (Б3) | F7: (В) | G7: (В1) | H7: (В2) | I7: (В3) | J7: (Г) | K7: (Д) | L7: (Д1) | M7: (Е) | N7: (Ж) | O7: (З) | P7: (З1) | Q7: (З2) | R7: (И) | S7: (К) | T7: (Л) | U7: (М) | V7: (Н) | W7: (О) | X7: (П) | Y7: (Р)
B8: Саноат
A9: 10 | B9: Давлат корхоналари | C9: =SUM(J9:Y9)-L9-P9-Q9 -> 7376109185 | D9: 1211274277 | E9: 6164834908 | F9: =+G9+H9+I9 -> 0 | G9: 0 | H9: 0 | I9: 0 | J9: 0 | K9: 4039268436 | L9: 3876628750 | M9: 0 | N9: 146995764 | O9: =+P9+Q9 -> 183970813 | P9: 0 | Q9: 183970813 | R9: 0 | S9: 0 | T9: 82926813 | U9: 0 | V9: 1600360527 | W9: 0 | X9: 0 | Y9: 1322586832
A10: =A9+10 -> 20 | B10: Қўшма ва чет эл капитали иштирокидаги корхоналар | C10: =SUM(J10:Y10)-L10-P10-Q10 -> 6852809674 | D10: 950657958 | E10: 5902151716 | F10: =+G10+H10+I10 -> 9432816 | G10: 9405114 | H10: 27702 | I10: 0 | J10: 69220 | K10: 0 | L10: 0 | M10: 2857151 | N10: 97604664 | O10: =+P10+Q10 -> 2134683941 | P10: 0 | Q10: 2134683941 | R10: 2517665217 | S10: 0 | T10: 0 | U10: 0 | V10: 1356468240 | W10: 260904454 | X10: 0 | Y10: 482556787
A11: =A10+10 -> 30 | B11: Хусусий корхоналар | C11: =SUM(J11:Y11)-L11-P11-Q11 -> 18298845076 | D11: 3694426854 | E11: 14604418222 | F11: =+G11+H11+I11 -> 340994107 | G11: 12336856 | H11: 71764707 | I11: 256892544 | J11: 12267690 | K11: 0 | L11: 0 | M11: 37599179 | N11: 13909269 | O11: =+P11+Q11 -> 4866645989 | P11: 95459848 | Q11: 4771186141 | R11: 3117571090 | S11: 0 | T11: 0 | U11: 1101356 | V11: 6323210796 | W11: 3348667284 | X11: 26136642 | Y11: 551735781
A12: =A11+10 -> 40 | B12: Ҳукумат | C12: =SUM(J12:Y12)-L12-P12-Q12 -> 0 | D12: 0 | E12: 0 | F12: =+G12+H12+I12 -> 0 | G12: 0 | H12: 0 | I12: 0 | J12: 0 | K12: 0 | L12: 0 | M12: 0 | N12: 0 | O12: =+P12+Q12 -> 0 | P12: 0 | Q12: 0 | R12: 0 | S12: 0 | T12: 0 | U12: 0 | V12: 0 | W12: 0 | X12: 0 | Y12: 0
A13: =A12+10 -> 50 | B13: Бошқалар | C13: =SUM(J13:Y13)-L13-P13-Q13 -> 0 | D13: 0 | E13: 0 | F13: =+G13+H13+I13 -> 0 | G13: 0 | H13: 0 | I13: 0 | J13: 0 | K13: 0 | L13: 0 | M13: 0 | N13: 0 | O13: =+P13+Q13 -> 0 | P13: 0 | Q13: 0 | R13: 0 | S13: 0 | T13: 0 | U13: 0 | V13: 0 | W13: 0 | X13: 0 | Y13: 0
A14: =A13+10 -> 60 | B14: Жами | C14: =SUM(J14:Y14)-L14-P14-Q14 -> 32527763935 | D14: =SUM(D9:D13) -> 5856359089 | E14: =SUM(E9:E13) -> 26671404846 | F14: =+G14+H14+I14 -> 350426923 | G14: =SUM(G9:G13) -> 21741970 | H14: =SUM(H9:H13) -> 71792409 | I14: =SUM(I9:I13) -> 256892544 | J14: =SUM(J9:J13) -> 12336910 | K14: =SUM(K9:K13) -> 4039268436 | L14: =SUM(L9:L13) -> 3876628750 | M14: =SUM(M9:M13) -> 40456330 | N14: =SUM(N9:N13) -> 258509697 | ... Y14: =SUM(Y9:Y13) -> 2356879400
B15: Қишлоқ хўжалиги
A16: 70 | B16: Давлат корхоналари | C16: =SUM(J16:Y16)-L16-P16-Q16 -> 0 | D16: 0 | E16: 0 | F16: =+G16+H16+I16 -> 0 | G16: 0 | H16: 0 | I16: 0 | J16: 0 | K16: 0 | L16: 0 | M16: 0 | N16: 0 | O16: =+P16+Q16 -> 0 | P16: 0 | Q16: 0 | R16: 0 | S16: 0 | T16: 0 | U16: 0 | V16: 0 | W16: 0 | X16: 0 | Y16: 0
A17: =A16+10 -> 80 | B17: Қўшма ва чет эл капитали иштирокидаги корхоналар | C17: =SUM(J17:Y17)-L17-P17-Q17 -> 681636361 | D17: 142893708 | E17: 538742653 | F17: =+G17+H17+I17 -> 0 | G17: 0 | H17: 0 | I17: 0 | J17: 0 | K17: 0 | L17: 0 | M17: 8402439 | N17: 2094028 | O17: =+P17+Q17 -> 332471102 | P17: 0 | Q17: 332471102 | R17: 159897865 | S17: 0 | T17: 0 | U17: 0 | V17: 87689095 | W17: 91081832 | X17: 0 | Y17: 0
A18: =A17+10 -> 90 | B18: Хусусий корхоналар | C18: =SUM(J18:Y18)-L18-P18-Q18 -> 3081519889 | D18: 1788659741 | E18: 1292860148 | F18: =+G18+H18+I18 -> 286601439 | G18: 3053383 | H18: 14906906 | I18: 268641150 | J18: 7873466 | K18: 0 | L18: 0 | M18: 25595839 | N18: 0 | O18: =+P18+Q18 -> 502708329 | P18: 30883752 | Q18: 471824577 | R18: 104119618 | S18: 0 | T18: 0 | U18: 0 | V18: 1724743055 | W18: 699355558 | X18: 0 | Y18: 17124024
A19: =A18+10 -> 100 | B19: Фермер хўжалиги | C19: =SUM(J19:Y19)-L19-P19-Q19 -> 88243247 | D19: 15854960 | E19: 72388287 | F19: =+G19+H19+I19 -> 5009857 | G19: 0 | H19: 620043 | I19: 4389814 | J19: 261460 | K19: 0 | L19: 0 | M19: 921535 | N19: 0 | O19: =+P19+Q19 -> 27921057 | P19: 1257301 | Q19: 26663756 | R19: 25839863 | S19: 0 | T19: 0 | U19: 0 | V19: 30638071 | W19: 2661261 | X19: 0 | Y19: 0
A20: =A19+10 -> 110 | B20: Ҳукумат | C20: =SUM(J20:Y20)-L20-P20-Q20 -> 0 | D20: 0 | E20: 0 | F20: =+G20+H20+I20 -> 0 | G20: 0 | H20: 0 | I20: 0 | J20: 0 | K20: 0 | L20: 0 | M20: 0 | N20: 0 | O20: =+P20+Q20 -> 0 | P20: 0 | Q20: 0 | R20: 0 | S20: 0 | T20: 0 | U20: 0 | V20: 0 | W20: 0 | X20: 0 | Y20: 0
A21: =A20+10 -> 120 | B21: Бошқалар | C21: =SUM(J21:Y21)-L21-P21-Q21 -> 0 | D21: 0 | E21: 0 | F21: =+G21+H21+I21 -> 0 | G21: 0 | H21: 0 | I21: 0 | J21: 0 | K21: 0 | L21: 0 | M21: 0 | N21: 0 | O21: =+P21+Q21 -> 0 | P21: 0 | Q21: 0 | R21: 0 | S21: 0 | T21: 0 | U21: 0 | V21: 0 | W21: 0 | X21: 0 | Y21: 0
A22: =A21+10 -> 130 | B22: Жами | C22: =SUM(J22:Y22)-L22-P22-Q22 -> 3851399497 | D22: =SUM(D16:D21) -> 1947408409 | E22: =SUM(E16:E21) -> 1903991088 | F22: =+G22+H22+I22 -> 291611296 | G22: =SUM(G17:G21) -> 3053383 | H22: =SUM(H17:H21) -> 15526949 | I22: =SUM(I17:I21) -> 273030964 | J22: =SUM(J16:J21) -> 8134926 | K22: =SUM(K16:K21) -> 0 | L22: =SUM(L16:L21) -> 0 | M22: =SUM(M16:M21) -> 34919813 | N22: =SUM(N16:N21) -> 2094028 | O22: =SUM(O16:O21) -> 863100488 | P22: =SUM(P16:P21) -> 32141053 | Q22: =SUM(Q16:Q21) -> 830959435 | ... Y22: =SUM(Y16:Y21) -> 17124024
B23: Транспорт ва коммуникация
A24: 140 | B24: Давлат корхоналари | C24: =SUM(J24:Y24)-L24-P24-Q24 -> 1379892532 | D24: 163103919 | E24: 1216788613 | F24: =+G24+H24+I24 -> 0 | G24: 0 | H24: 0 | I24: 0 | J24: 1200000 | K24: 568195595 | L24: 521388245 | M24: 0 | N24: 0 | O24: =+P24+Q24 -> 73063237 | P24: 0 | Q24: 73063237 | R24: 0 | S24: 0 | T24: 0 | U24: 0 | V24: 427996319 | W24: 309437381 | X24: 0 | Y24: 0
A25: =A24+10 -> 150 | B25: Қўшма ва чет эл капитали иштирокидаги корхоналар | C25: =SUM(J25:Y25)-L25-P25-Q25 -> 563209579 | D25: 0 | E25: 563209579 | F25: =+G25+H25+I25 -> 0 | G25: 0 | H25: 0 | I25: 0 | J25: 0 | K25: 0 | L25: 0 | M25: 0 | N25: 0 | O25: =+P25+Q25 -> 187863438 | P25: 0 | Q25: 187863438 | R25: 0 | S25: 0 | T25: 0 | U25: 0 | V25: 375346141 | W25: 0 | X25: 0 | Y25: 0
A26: =A25+10 -> 160 | B26: Хусусий корхоналар | C26: =SUM(J26:Y26)-L26-P26-Q26 -> 937248651 | D26: 136444450 | E26: 800804201 | F26: =+G26+H26+I26 -> 12655935 | G26: 3240237 | H26: 3958673 | I26: 5457025 | J26: 1386921 | K26: 0 | L26: 0 | M26: 19549512 | N26: 0 | O26: =+P26+Q26 -> 514734268 | P26: 0 | Q26: 514734268 | R26: 48530925 | S26: 0 | T26: 0 | U26: 229726 | V26: 102162742 | W26: 249964819 | X26: 689738 | Y26: 0
A27: =A26+10 -> 170 | B27: Ҳукумат | C27: =SUM(J27:Y27)-L27-P27-Q27 -> 0 | D27: 0 | E27: 0 | F27: =+G27+H27+I27 -> 0 | G27: 0 | H27: 0 | I27: 0 | J27: 0 | K27: 0 | L27: 0 | M27: 0 | N27: 0 | O27: =+P27+Q27 -> 0 | P27: 0 | Q27: 0 | R27: 0 | S27: 0 | T27: 0 | U27: 0 | V27: 0 | W27: 0 | X27: 0 | Y27: 0
A28: =A27+10 -> 180 | B28: Бошқалар | C28: =SUM(J28:Y28)-L28-P28-Q28 -> 0 | D28: 0 | E28: 0 | F28: =+G28+H28+I28 -> 0 | G28: 0 | H28: 0 | I28: 0 | J28: 0 | K28: 0 | L28: 0 | M28: 0 | N28: 0 | O28: =+P28+Q28 -> 0 | P28: 0 | Q28: 0 | R28: 0 | S28: 0 | T28: 0 | U28: 0 | V28: 0 | W28: 0 | X28: 0 | Y28: 0
A29: =A28+10 -> 190 | B29: Жами | C29: =SUM(J29:Y29)-L29-P29-Q29 -> 2880350762 | D29: =SUM(D24:D28) -> 299548369 | E29: =SUM(E24:E28) -> 2580802393 | F29: =+G29+H29+I29 -> 12655935 | G29: =SUM(G24:G28) -> 3240237 | H29: =SUM(H24:H28) -> 3958673 | I29: =SUM(I24:I28) -> 5457025 | J29: =SUM(J24:J28) -> 2586921 | K29: =SUM(K24:K28) -> 568195595 | L29: =SUM(L24:L28) -> 521388245 | M29: =SUM(M24:M28) -> 19549512 | N29: =SUM(N24:N28) -> 0 | ... Y29: =SUM(Y24:Y28) -> 0
B30: Қурилиш соҳаси
A31: 200 | B31: Давлат корхоналари | C31: =SUM(J31:Y31)-L31-P31-Q31 -> 123299477 | D31: 123299477 | E31: 0 | F31: =+G31+H31+I31 -> 0 | G31: 0 | H31: 0 | I31: 0 | J31: 0 | K31: 0 | L31: 0 | M31: 0 | N31: 0 | O31: =+P31+Q31 -> 123299477 | P31: 0 | Q31: 123299477 | R31: 0 | S31: 0 | T31: 0 | U31: 0 | V31: 0 | W31: 0 | X31: 0 | Y31: 0
A32: =A31+10 -> 210 | B32: Қўшма ва чет эл капитали иштирокидаги корхоналар | C32: =SUM(J32:Y32)-L32-P32-Q32 -> 334812 | D32: 260268 | E32: 74544 | F32: =+G32+H32+I32 -> 146802 | G32: 0 | H32: 0 | I32: 146802 | J32: 0 | K32: 0 | L32: 0 | M32: 95252 | N32: 0 | O32: =+P32+Q32 -> 56733 | P32: 0 | Q32: 56733 | R32: 0 | S32: 0 | T32: 0 | U32: 0 | V32: 92979 | W32: 89848 | X32: 0 | Y32: 0
A33: =A32+10 -> 220 | B33: Хусусий корхоналар | C33: =SUM(J33:Y33)-L33-P33-Q33 -> 2625340231 | D33: 790913039 | E33: 1834427192 | F33: =+G33+H33+I33 -> 215087014 | G33: 10053338 | H33: 9809195 | I33: 195224481 | J33: 2481120 | K33: 0 | L33: 0 | M33: 25053533 | N33: 0 | O33: =+P33+Q33 -> 1379498500 | P33: 1871142 | Q33: 1377627358 | R33: 30023437 | S33: 0 | T33: 0 | U33: 11852172 | V33: 403432859 | W33: 768901418 | X33: 0 | Y33: 4097192
A34: =A33+10 -> 230 | B34: Ҳукумат | C34: =SUM(J34:Y34)-L34-P34-Q34 -> 0 | D34: 0 | E34: 0 | F34: =+G34+H34+I34 -> 0 | G34: 0 | H34: 0 | I34: 0 | J34: 0 | K34: 0 | L34: 0 | M34: 0 | N34: 0 | O34: =+P34+Q34 -> 0 | P34: 0 | Q34: 0 | R34: 0 | S34: 0 | T34: 0 | U34: 0 | V34: 0 | W34: 0 | X34: 0 | Y34: 0
A35: =A34+10 -> 240 | B35: Бошқалар | C35: =SUM(J35:Y35)-L35-P35-Q35 -> 0 | D35: 0 | E35: 0 | F35: =+G35+H35+I35 -> 0 | G35: 0 | H35: 0 | I35: 0 | J35: 0 | K35: 0 | L35: 0 | M35: 0 | N35: 0 | O35: =+P35+Q35 -> 0 | P35: 0 | Q35: 0 | R35: 0 | S35: 0 | T35: 0 | U35: 0 | V35: 0 | W35: 0 | X35: 0 | Y35: 0
A36: =A35+10 -> 250 | B36: Жами | C36: =SUM(J36:Y36)-L36-P36-Q36 -> 2748974520 | D36: =SUM(D31:D35) -> 914472784 | E36: =SUM(E31:E35) -> 1834501736 | F36: =+G36+H36+I36 -> 215233816 | G36: =SUM(G31:G35) -> 10053338 | H36: =SUM(H31:H35) -> 9809195 | I36: =SUM(I31:I35) -> 195371283 | J36: =SUM(J31:J35) -> 2481120 | K36: =SUM(K31:K35) -> 0 | L36: =SUM(L31:L35) -> 0 | M36: =SUM(M31:M35) -> 25148785 | N36: =SUM(N31:N35) -> 0 | ... Y36: =SUM(Y31:Y35) -> 4097192
B37: Савдо ва умумий хизмат
A38: 260 | B38: Давлат корхоналари | C38: =SUM(J38:Y38)-L38-P38-Q38 -> 0 | D38: 0 | E38: 0 | F38: =+G38+H38+I38 -> 0 | G38: 0 | H38: 0 | I38: 0 | J38: 0 | K38: 0 | L38: 0 | M38: 0 | N38: 0 | O38: =+P38+Q38 -> 0 | P38: 0 | Q38: 0 | R38: 0 | S38: 0 | T38: 0 | U38: 0 | V38: 0 | W38: 0 | X38: 0 | Y38: 0
A39: =A38+10 -> 270 | B39: Қўшма ва чет эл капитали иштирокидаги корхоналар | C39: =SUM(J39:Y39)-L39-P39-Q39 -> 220650469 | D39: 5364781 | E39: 215285688 | F39: =+G39+H39+I39 -> 0 | G39: 0 | H39: 0 | I39: 0 | J39: 175294 | K39: 0 | L39: 0 | M39: 5720102 | N39: 0 | O39: =+P39+Q39 -> 50744108 | P39: 0 | Q39: 50744108 | R39: 12352922 | S39: 0 | T39: 0 | U39: 2035891 | V39: 136098170 | W39: 12617887 | X39: 0 | Y39: 906095
A40: =A39+10 -> 280 | B40: Хусусий корхоналар | C40: =SUM(J40:Y40)-L40-P40-Q40 -> 3790891657 | D40: 943979659 | E40: 2846911998 | F40: =+G40+H40+I40 -> 393468578 | G40: 47877975 | H40: 224581757 | I40: 121008846 | J40: 26469780 | K40: 0 | L40: 0 | M40: 91525448 | N40: 20493537 | O40: =+P40+Q40 -> 1642272928 | P40: 5523454 | Q40: 1636749474 | R40: 92952200 | S40: 0 | T40: 0 | U40: 0 | V40: 524897993 | W40: 1132964917 | X40: 92604751 | Y40: 166710103
A41: =A40+10 -> 290 | B41: Ҳукумат | C41: =SUM(J41:Y41)-L41-P41-Q41 -> 0 | D41: 0 | E41: 0 | F41: =+G41+H41+I41 -> 0 | G41: 0 | H41: 0 | I41: 0 | J41: 0 | K41: 0 | L41: 0 | M41: 0 | N41: 0 | O41: =+P41+Q41 -> 0 | P41: 0 | Q41: 0 | R41: 0 | S41: 0 | T41: 0 | U41: 0 | V41: 0 | W41: 0 | X41: 0 | Y41: 0
...

Sheet Aging Analysis
A1: ОЛИНИШИ ЛОЗИМ БЎЛГАН МУДДАТИ ЎТГАН КРЕДИТ ВА МОЛИЯВИЙ ЛИЗИНГ ТАҲЛИЛИ | X1: 9-жадвал
B3: =+'Asset quality'!B3 -> "Ўзсаноатқурилишбанк" АТБ | T3: =+'Asset quality'!Q3 -> 46021 | X3: =+'Asset quality'!T3 -> минг. сўмда
A4: № | B4: Кўрсаткичлар | C4: Жами кредит суммаси | D4: % | E4: Шартлари қайта кўрилган кредит ва лизинглар | F4: % | G4: Суд жараёнидаги қарздорликлар | H4: % | I4: Муддати ўтган | K4: % | L4: шу жумладан, кечиктирилган муддати бўйича
L5: 1-30 кун | N5: 31-60 кун | P5: 61-90 кун | R5: 91-180 кун | T5: 181-365 кун | V5: 366-730 кун | X5: 2 йилдан ортиқ
I6: асосий қарздорлик | J6: фоиз тўловлари | L6: асосий қарздорлик | M6: фоиз тўловлари | N6: асосий қарздорлик | O6: фоиз тўловлари | P6: асосий қарздорлик | Q6: фоиз тўловлари | R6: асосий қарздорлик | S6: фоиз тўловлари | T6: асосий қарздорлик | U6: фоиз тўловлари | V6: асосий қарздорлик | W6: фоиз тўловлари | X6: асосий қарздорлик | Y6: фоиз тўловлари
B7: (А) | C7: (Б) | D7: (В) | E7: (Г) | F7: (Д) | G7: (Е) | H7: (Ж) | I7: (З) | J7: (З1) | K7: (И) | L7: (К) | M7: (К1) | N7: (Л) | O7: (Л1) | P7: (М) | Q7: (М1) | R7: (Н) | S7: (Н1) | T7: (О) | U7: (О1) | V7: (П) | W7: (П1) | X7: (Р) | Y7: (Р1)
B8: Мижозлар тури бўйича
A9: 1 | B9: Марказий банк | C9: =+'Loans Receivable'!C79 -> 0 | D9: =IF(C$22=0,"",C9/C$22) -> 0 | E9: 0 | F9: =IF(E$22=0,"",E9/E$22) -> 0 | G9: 0 | H9: =IF($G$22=0,"",G9/$G$22) -> 0 | I9: =+L9+N9+P9+R9+T9+V9+X9 -> 0 | J9: =+M9+O9+T9+S9+U9+W9+Y9 -> 0 | K9: =IF($Z$22=0,"",Z9/$Z$22) -> 0 | L9: 0 | M9: 0 | N9: 0 | O9: 0 | P9: 0 | Q9: 0 | R9: 0 | S9: 0 | T9: 0 | U9: 0 | V9: 0 | W9: 0 | X9: 0 | Y9: 0 | Z9: =+I9+J9 -> 0 | AA9: =+C9-Z9 -> 0
A10: 2 | B10: Бошқа банклар | C10: =+'Loans Receivable'!C78 -> 0 | D10: =IF(C$22=0,"",C10/C$22) -> 0 | E10: 0 | F10: =IF(E$22=0,"",E10/E$22) -> 0 | G10: 0 | H10: =IF($G$22=0,"",G10/$G$22) -> 0 | I10: =+L10+N10+P10+R10+T10+V10+X10 -> 0 | J10: =+M10+O10+Q10+S10+U10+W10+Y10 -> 0 | K10: =IF($Z$22=0,"",Z10/$Z$22) -> 0 | L10: 0 | M10: 0 | N10: 0 | O10: 0 | P10: 0 | Q10: 0 | R10: 0 | S10: 0 | T10: 0 | U10: 0 | V10: 0 | W10: 0 | X10: 0 | Y10: 0 | Z10: =+I10+J10 -> 0
A11: 3 | B11: Ҳукумат | C11: =+'Loans Receivable'!C80 -> 0 | D11: =IF(C$22=0,"",C11/C$22) -> 0 | E11: 0 | F11: =IF(E$22=0,"",E11/E$22) -> 0 | G11: 0 | H11: =IF($G$22=0,"",G11/$G$22) -> 0 | I11: =+L11+N11+P11+R11+T11+V11+X11 -> 0 | J11: =+M11+O11+Q11+S11+U11+W11+Y11 -> 0 | K11: =IF($Z$22=0,"",Z11/$Z$22) -> 0 | L11: 0 | M11: 0 | N11: 0 | O11: 0 | P11: 0 | Q11: 0 | R11: 0 | S11: 0 | T11: 0 | U11: 0 | V11: 0 | W11: 0 | X11: 0 | Y11: 0 | Z11: =+I11+J11 -> 0
A12: 4 | B12: Жисмоний шахслар | C12: =+'Loans Receivable'!C73 -> 9706748229 | D12: =IF(C$22=0,"",C12/C$22) -> 0.14948276 | E12: 4368029 | F12: =IF(E$22=0,"",E12/E$22) -> 0.6074495 | G12: 3021754 | H12: =IF($G$22=0,"",G12/$G$22) -> 0.0079618522 | I12: =+L12+N12+P12+R12+T12+V12+X12 -> 65737735 | J12: =+M12+O12+Q12+S12+U12+W12+Y12 -> 63709585 | K12: =IF($Z$22=0,"",Z12/$Z$22) -> 0.023698825 | L12: 2904500 | M12: 6443818 | N12: 5102080 | O12: 7357441 | P12: 6667427 | Q12: 7887930 | R12: 13996893 | S12: 11543084 | T12: 28982833 | U12: 21431635 | V12: 8002034 | W12: 9037185 | X12: 81968 | Y12: 8492 | Z12: =+I12+J12 -> 129447320
A13: 5 | B13: Давлат корхоналари | C13: =+'Loans Receivable'!C74 -> 12813996196 | D13: =IF(C$22=0,"",C13/C$22) -> 0.19733401 | E13: 0 | F13: =IF(E$22=0,"",E13/E$22) -> 0 | G13: 10984853 | H13: =IF($G$22=0,"",G13/$G$22) -> 0.028943381 | I13: =+L13+N13+P13+R13+T13+V13+X13 -> 466857467 | J13: =+M13+O13+Q13+S13+U13+W13+Y13 -> 327767309 | K13: =IF($Z$22=0,"",Z13/$Z$22) -> 0.14547751 | L13: 68888273 | M13: 257263435 | N13: 198375861 | O13: 24335703 | P13: 199593333 | Q13: 46168171 | R13: 0 | S13: 0 | T13: 0 | U13: 0 | V13: 0 | W13: 0 | X13: 0 | Y13: 0 | Z13: =+I13+J13 -> 794624776
A14: 6 | B14: Қўшма ва чет эл капитали иштирокидаги корхоналар | C14: =+'Loans Receivable'!C75 -> 9759069887 | D14: =IF(C$22=0,"",C14/C$22) -> 0.15028851 | E14: 0 | F14: =IF(E$22=0,"",E14/E$22) -> 0 | G14: 0 | H14: =IF($G$22=0,"",G14/$G$22) -> 0 | I14: =+L14+N14+P14+R14+T14+V14+X14 -> 227185965 | J14: =+M14+O14+Q14+S14+U14+W14+Y14 -> 231501720 | K14: =IF($Z$22=0,"",Z14/$Z$22) -> 0.083975158 | L14: 150963275 | M14: 198854628 | N14: 13516821 | O14: 4841718 | P14: 62536507 | Q14: 27773527 | R14: 50347 | S14: 17486 | T14: 119015 | U14: 14361 | V14: 0 | W14: 0 | X14: 0 | Y14: 0 | Z14: =+I14+J14 -> 458687685
A15: 7 | B15: Хусусий корхоналар | C15: =+'Loans Receivable'!C76 -> 32532347335 | D15: =IF(C$22=0,"",C15/C$22) -> 0.50099425 | E15: 1856181 | F15: =IF(E$22=0,"",E15/E$22) -> 0.25813387 | G15: 361142484 | H15: =IF($G$22=0,"",G15/$G$22) -> 0.95155433 | I15: =+L15+N15+P15+R15+T15+V15+X15 -> 2542808207 | J15: =+M15+O15+Q15+S15+U15+W15+Y15 -> 1518814500 | K15: =IF($Z$22=0,"",Z15/$Z$22) -> 0.74358963 | L15: =584884013+900 -> 584884913 | M15: 583514568 | N15: 492053275 | O15: 136496654 | P15: 810513549 | Q15: 579728327 | R15: 127362917 | S15: 56773523 | T15: 238567932 | U15: 73798136 | V15: 287971086 | W15: 88010327 | X15: 1454535 | Y15: 492965 | Z15: =+I15+J15 -> 4061622707
A16: 8 | B16: Фермер хўжаликлари | C16: =+'Loans Receivable'!C77 -> 88243247 | D16: =IF(C$22=0,"",C16/C$22) -> 0.0013589354 | E16: 966559 | F16: =IF(E$22=0,"",E16/E$22) -> 0.13441664 | G16: 4379932 | H16: =IF($G$22=0,"",G16/$G$22) -> 0.01154044 | I16: =+L16+N16+P16+R16+T16+V16+X16 -> 10805277 | J16: =+M16+O16+Q16+S16+U16+W16+Y16 -> 6870137 | K16: =IF($Z$22=0,"",Z16/$Z$22) -> 0.0032359615 | L16: 929330 | M16: 2991516 | N16: 107279 | O16: 23293 | P16: 9421579 | Q16: 3694331 | R16: 126985 | S16: 33955 | T16: 220104 | U16: 127042 | V16: 0 | W16: 0 | X16: 0 | Y16: 0 | Z16: =+I16+J16 -> 17675414
A17: 9 | B17: Нобанк молиявий институтлар | C17: =+'Loans Receivable'!C81 -> 33541698 | D17: =IF(C$22=0,"",C17/C$22) -> 0.00051653813 | E17: 0 | F17: =IF(E$22=0,"",E17/E$22) -> 0 | G17: 0 | H17: =IF($G$22=0,"",G17/$G$22) -> 0 | I17: =+L17+N17+P17+R17+T17+V17+X17 -> 0 | J17: =+M17+O17+Q17+S17+U17+W17+Y17 -> 0 | K17: =IF($Z$22=0,"",Z17/$Z$22) -> 0 | L17: 0 | M17: 0 | N17: 0 | O17: 0 | P17: 0 | Q17: 0 | R17: 0 | S17: 0 | T17: 0 | U17: 0 | V17: 0 | W17: 0 | X17: 0 | Y17: 0 | Z17: =+I17+J17 -> 0
A18: 10 | B18: Нодавлат нотижорат ташкилотлар | C18: =+'Loans Receivable'!C82 -> 1623241 | D18: =IF(C$22=0,"",C18/C$22) -> 2.4997717e-05 | E18: 0 | F18: =IF(E$22=0,"",E18/E$22) -> 0 | G18: 0 | H18: =IF($G$22=0,"",G18/$G$22) -> 0 | I18: =+L18+N18+P18+R18+T18+V18+X18 -> 97577 | J18: =+M18+O18+Q18+S18+U18+W18+Y18 -> 27589 | K18: =IF($Z$22=0,"",Z18/$Z$22) -> 2.2915014e-05 | L18: 2543 | M18: 3142 | N18: 0 | O18: 0 | P18: 36690 | Q18: 5193 | R18: 0 | S18: 0 | T18: 0 | U18: 0 | V18: 58344 | W18: 19254 | X18: 0 | Y18: 0 | Z18: =+I18+J18 -> 125166
A19: 11 | B19: Бюджет ташкилотлари | C19: =+'Loans Receivable'!C83 -> 0 | D19: =IF(C$22=0,"",C19/C$22) -> 0 | E19: 0 | F19: =IF(E$22=0,"",E19/E$22) -> 0 | G19: 0 | H19: =IF($G$22=0,"",G19/$G$22) -> 0 | I19: =+L19+N19+P19+R19+T19+V19+X19 -> 0 | J19: =+M19+O19+Q19+S19+U19+W19+Y19 -> 0 | K19: =IF($Z$22=0,"",Z19/$Z$22) -> 0 | L19: 0 | M19: 0 | N19: 0 | O19: 0 | P19: 0 | Q19: 0 | R19: 0 | S19: 0 | T19: 0 | U19: 0 | V19: 0 | W19: 0 | X19: 0 | Y19: 0 | Z19: =+I19+J19 -> 0
A20: 12 | B20: Бошқалар | C20: =+'Loans Receivable'!C84 -> 0 | D20: =IF(C$22=0,"",C20/C$22) -> 0 | E20: 0 | F20: =IF(E$22=0,"",E20/E$22) -> 0 | G20: 0 | H20: =IF($G$22=0,"",G20/$G$22) -> 0 | I20: =+L20+N20+P20+R20+T20+V20+X20 -> 0 | J20: =+M20+O20+Q20+S20+U20+W20+Y20 -> 0 | K20: =IF($Z$22=0,"",Z20/$Z$22) -> 0 | L20: 0 | M20: 0 | N20: 0 | O20: 0 | P20: 0 | Q20: 0 | R20: 0 | S20: 0 | T20: 0 | U20: 0 | V20: 0 | W20: 0 | X20: 0 | Y20: 0 | Z20: =+I20+J20 -> 0
Z21: =+I21+J21 -> 0
A22: 13 | B22: Жами кредит ва лизинг суммаси | C22: =SUM(C9:C20) -> 64935569833 | D22: =IF(C$22=0,"",C22/C$22) -> 1 | E22: =SUM(E9:E20) -> 7190769 | F22: =IF(E$22=0,"",E22/E$22) -> 1 | G22: =SUM(G9:G20) -> 379529023 | H22: =IF($G$22=0,"",G22/$G$22) -> 1 | I22: =SUM(I9:I20) -> 3313492228 | J22: =SUM(J9:J20) -> 2148690840 | K22: =IF($Z$22=0,"",Z22/$Z$22) -> 1 | L22: =SUM(L9:L20) -> 808572834 | M22: =SUM(M9:M20) -> 1049071107 | N22: =SUM(N9:N20) -> 709155316 | O22: =SUM(O9:O20) -> 173054809 | P22: =SUM(P9:P20) -> 1088769085 | Q22: =SUM(Q9:Q20) -> 665257479 | R22: =SUM(R9:R20) -> 141537142 | S22: =SUM(S9:S20) -> 68368048 | ... Y22: =SUM(Y9:Y20) -> 501457 | Z22: =+I22+J22 -> 5462183068
Z23: =+I23+J23 -> 0
B24: Иқтисодиёт соҳалари бўйича | Z24: =+I24+J24 -> 0
A25: 14 | B25: Саноат | C25: =+'Loans Receivable'!C14 -> 32527763935 | D25: =IF(C$35=0,"",C25/C$35) -> 0.50092367 | E25: 0 | F25: =IF($E$35=0,"",E25/$E$35) -> 0 | G25: 172460938 | H25: =IF($G$35=0,"",G25/$G$35) -> 0.45440777 | I25: =+L25+N25+P25+R25+T25+V25+X25 -> 1581681421 | J25: =+M25+O25+Q25+S25+U25+W25+Y25 -> 1273813986 | K25: =IF($Z$35=0,"",Z25/$Z$35) -> 0.52277549 | L25: 658264393 | M25: 652655127 | N25: 344926023 | O25: 102555763 | P25: 459262625 | Q25: 456681329 | R25: 25775149 | S25: 29666509 | T25: 35921392 | U25: 11066003 | V25: 57229489 | W25: 21039789 | X25: 302350 | Y25: 149466 | Z25: =+I25+J25 -> 2855495407
A26: 15 | B26: Қишлоқ хўжалиги | C26: =+'Loans Receivable'!C22 -> 3851399497 | D26: =IF(C$35=0,"",C26/C$35) -> 0.059311091 | E26: 1377812 | F26: =IF($E$35=0,"",E26/$E$35) -> 0.19160844 | G26: 99866751 | H26: =IF($G$35=0,"",G26/$G$35) -> 0.26313337 | I26: =+L26+N26+P26+R26+T26+V26+X26 -> 404860479 | J26: =+M26+O26+Q26+S26+U26+W26+Y26 -> 241506901 | K26: =IF($Z$35=0,"",Z26/$Z$35) -> 0.11833499 | L26: 38555789 | M26: 137476799 | N26: 19291085 | O26: 10551770 | P26: 126128436 | Q26: 35975936 | R26: 41863238 | S26: 12145872 | T26: 8400479 | U26: 2770591 | V26: 170621452 | W26: 42585933 | X26: 0 | Y26: 0 | Z26: =+I26+J26 -> 646367380
A27: 16 | B27: Транспорт ва коммуникация | C27: =+'Loans Receivable'!C29 -> 2880350762 | D27: =IF(C$35=0,"",C27/C$35) -> 0.044357057 | E27: 0 | F27: =IF($E$35=0,"",E27/$E$35) -> 0 | G27: 565000 | H27: =IF($G$35=0,"",G27/$G$35) -> 0.0014886872 | I27: =+L27+N27+P27+R27+T27+V27+X27 -> 12183966 | J27: =+M27+O27+Q27+S27+U27+W27+Y27 -> 24209860 | K27: =IF($Z$35=0,"",Z27/$Z$35) -> 0.0066628719 | L27: 2271739 | M27: 7253881 | N27: 3751872 | O27: 2648863 | P27: 2234034 | Q27: 12694079 | R27: 1727666 | S27: 577324 | T27: 385517 | U27: 554771 | V27: 1813138 | W27: 480942 | X27: 0 | Y27: 0 | Z27: =+I27+J27 -> 36393826
A28: 17 | B28: Қурилиш соҳаси | C28: =+'Loans Receivable'!C36 -> 2748974520 | D28: =IF(C$35=0,"",C28/C$35) -> 0.042333878 | E28: 0 | F28: =IF($E$35=0,"",E28/$E$35) -> 0 | G28: 15411869 | H28: =IF($G$35=0,"",G28/$G$35) -> 0.04060788 | I28: =+L28+N28+P28+R28+T28+V28+X28 -> 121522332 | J28: =+M28+O28+Q28+S28+U28+W28+Y28 -> 104062230 | K28: =IF($Z$35=0,"",Z28/$Z$35) -> 0.041299341 | L28: 12939839 | M28: 28314400 | N28: 52322005 | O28: 1642770 | P28: 13273708 | Q28: 48921669 | R28: 5683150 | S28: 1255704 | T28: 26237146 | U28: 19713569 | V28: 10669467 | W28: 4058682 | X28: 397017 | Y28: 155436 | Z28: =+I28+J28 -> 225584562
A29: 18 | B29: Савдо ва умумий овқатланиш | C29: =+'Loans Receivable'!C43 -> 4011542126 | D29: =IF(C$35=0,"",C29/C$35) -> 0.061777268 | E29: 0 | F29: =IF($E$35=0,"",E29/$E$35) -> 0 | G29: 68001586 | H29: =IF($G$35=0,"",G29/$G$35) -> 0.17917361 | I29: =+L29+N29+P29+R29+T29+V29+X29 -> 518527549 | J29: =+M29+O29+Q29+S29+U29+W29+Y29 -> 134503302 | K29: =IF($Z$35=0,"",Z29/$Z$35) -> 0.11955492 | L29: 71074413 | M29: 66991112 | N29: 109046807 | O29: 7132723 | P29: 107804838 | Q29: 7394133 | R29: 46250745 | S29: 9771350 | T29: 152090107 | U29: 30460136 | V29: 31505471 | W29: 12565785 | X29: 755168 | Y29: 188063 | Z29: =+I29+J29 -> 653030851
A30: 19 | B30: Моддий ва техник таъминотни ривожлантириш | C30: =+'Loans Receivable'!C50 -> 1793348888 | D30: =IF(C$35=0,"",C30/C$35) -> 0.027617358 | E30: 0 | F30: =IF($E$35=0,"",E30/$E$35) -> 0 | G30: 73479 | H30: =IF($G$35=0,"",G30/$G$35) -> 0.00019360575 | I30: =+L30+N30+P30+R30+T30+V30+X30 -> 109657965 | J30: =+M30+O30+Q30+S30+U30+W30+Y30 -> 66395490 | K30: =IF($Z$35=0,"",Z30/$Z$35) -> 0.032231335 | L30: 10366787 | M30: 36896474 | N30: 1891809 | O30: 1703280 | P30: 85429079 | Q30: 21158790 | R30: 245558 | S30: 110083 | T30: 4250660 | U30: 2506610 | V30: 7474072 | W30: 4020253 | X30: 0 | Y30: 0 | Z30: =+I30+J30 -> 176053455
A31: 20 | B31: Уй-жой коммунал хизмати | C31: =+'Loans Receivable'!C58 -> 23337550 | D31: =IF(C$35=0,"",C31/C$35) -> 0.00035939548 | E31: 0 | F31: =IF($E$35=0,"",E31/$E$35) -> 0 | G31: 299444 | H31: =IF($G$35=0,"",G31/$G$35) -> 0.00078898841 | I31: =+L31+N31+P31+R31+T31+V31+X31 -> 12702604 | J31: =+M31+O31+Q31+S31+U31+W31+Y31 -> 3372861 | K31: =IF($Z$35=0,"",Z31/$Z$35) -> 0.0029430476 | L31: 8376 | M31: 136103 | N31: 12610017 | O31: 3201973 | P31: 0 | Q31: 0 | R31: 25867 | S31: 15531 | T31: 0 | U31: 0 | V31: 58344 | W31: 19254 | X31: 0 | Y31: 0 | Z31: =+I31+J31 -> 16075465
A32: 21 | B32: Бошқа соҳалар | C32: =+'Loans Receivable'!C70 -> 7392104326 | D32: =IF(C$35=0,"",C32/C$35) -> 0.11383752 | E32: 1444928 | F32: =IF($E$35=0,"",E32/$E$35) -> 0.20094207 | G32: 19828202 | H32: =IF($G$35=0,"",G32/$G$35) -> 0.052244231 | I32: =+L32+N32+P32+R32+T32+V32+X32 -> 486618177 | J32: =+M32+O32+Q32+S32+U32+W32+Y32 -> 237116625 | K32: =IF($Z$35=0,"",Z32/$Z$35) -> 0.13249918 | L32: =12186098+900 -> 12186998 | M32: 112903393 | N32: 160213618 | O32: 36260226 | P32: 287968938 | Q32: 74543613 | R32: 5968876 | S32: 3282591 | T32: 11621750 | U32: 6867859 | V32: 8657997 | W32: 3258943 | X32: 0 | Y32: 0 | Z32: =+I32+J32 -> 723734802
A33: 22 | B33: Жисмоний шахслар | C33: =+'Loans Receivable'!C71 -> 9706748229 | D33: =IF(C$35=0,"",C33/C$35) -> 0.14948276 | E33: 4368029 | F33: =IF($E$35=0,"",E33/$E$35) -> 0.6074495 | G33: 3021754 | H33: =IF($G$35=0,"",G33/$G$35) -> 0.0079618522 | I33: =+L33+N33+P33+R33+T33+V33+X33 -> 65737735 | J33: =+M33+O33+Q33+S33+U33+W33+Y33 -> 63709585 | K33: =IF($Z$35=0,"",Z33/$Z$35) -> 0.023698825 | L33: 2904500 | M33: 6443818 | N33: 5102080 | O33: 7357441 | P33: 6667427 | Q33: 7887930 | R33: 13996893 | S33: 11543084 | T33: 28982833 | U33: 21431635 | V33: 8002034 | W33: 9037185 | X33: 81968 | Y33: 8492 | Z33: =+I33+J33 -> 129447320
Z34: =+I34+J34 -> 0
A35: 23 | B35: Жами кредит ва лизинг суммаси | C35: =SUM(C25:C33) -> 64935569833 | D35: =IF(C$35=0,"",C35/C$35) -> 1 | E35: =SUM(E25:E33) -> 7190769 | F35: =IF($E$35=0,"",E35/$E$35) -> 1 | G35: =SUM(G25:G33) -> 379529023 | H35: =IF($G$35=0,"",G35/$G$35) -> 1 | I35: =SUM(I25:I33) -> 3313492228 | J35: =SUM(J25:J33) -> 2148690840 | K35: =IF($Z$35=0,"",Z35/$Z$35) -> 1 | L35: =SUM(L25:L33) -> 808572834 | M35: =SUM(M25:M33) -> 1049071107 | N35: =SUM(N25:N33) -> 709155316 | O35: =SUM(O25:O33) -> 173054809 | P35: =SUM(P25:P33) -> 1088769085 | Q35: =SUM(Q25:Q33) -> 665257479 | R35: =SUM(R25:R33) -> 141537142 | S35: =SUM(S25:S33) -> 68368048 | ... Y35: =SUM(Y25:Y33) -> 501457 | Z35: =+I35+J35 -> 5462183068
B37: Бошқарув Раис имзоси:
B39: Бош бухгалтер имзоси:
G42: =+'[8]Bank Assets Analysis'!$S$32 -> 30353847

Sheet Asset Classification
A1: АКТИВЛАР СИФАТИ БЎЙИЧА ТАСНИФЛАНИШИ ТЎҒРИСИДА ҲИСОБОТ | Z1: 10-жадвал
B3: =+'Asset quality'!B3 -> "Ўзсаноатқурилишбанк" АТБ | U3: =+'Asset quality'!Q3 -> 46021 | AB3: =+'Asset quality'!T3 -> минг. сўмда
A4: № | B4: Кўрсаткичлар | C4: Жами суммаси | D4: шундан, хорижий валютада (экв. сўмда) | E4: Стандарт | F4: шундан, хорижий валютада (экв. сўмда) | G4: Стандарт активлар бўйича яратилган захиралар (1%) | H4: шундан, хорижий валютада (экв. сўмда) | I4: Субстандарт | J4: шундан, хорижий валютада (экв. сўмда) | K4: Махсус захиралар (мин 10%) | L4: шундан, хорижий валютада (экв. сўмда) | M4: Қониқарсиз | N4: шундан, хорижий валютада (экв. сўмда) | O4: Махсус захиралар (мин 25%) | P4: шундан, хорижий валютада (экв. сўмда) | Q4: Шубҳали | R4: шундан, хорижий валютада (экв. сўмда) | S4: Махсус захиралар (мин 50%) | T4: шундан, хорижий валютада (экв. сўмда) | U4: Умидсиз | V4: шундан, хорижий валютада (экв. сўмда) | W4: Махсус захиралар (мин 100%) | X4: шундан, хорижий валютада (экв. сўмда) | Y4: Жами махсус захиралар суммаси | Z4: шундан, хорижий валютада (экв. сўмда) | AA4: ҳисобот ойида балансдан ташқари ҳисобдан чиқарилган кредитлар | AB4: ҳисобот ойида балансдан ташқари қайтган кредитлар суммаси
A5: (А) | B5: (Б) | C5: (В) | D5: (В1) | E5: (Г) | F5: (Г1) | G5: (Д) | H5: (Д1) | I5: (Е) | J5: (Е1) | K5: (Ж) | L5: (Ж1) | M5: (З) | N5: (З1) | O5: (И) | P5: (И1) | Q5: (К) | R5: (К1) | S5: (Л) | T5: (Л1) | U5: (М) | V5: (М1) | W5: (Н) | X5: (Н1) | Y5: О=Ж+И+Л+Н | Z5: (О1)=(Ж1)+(И1)+(Л1)+(Н1) | AA5: П | AB5: Р
B6: Мижозлар тури бўйича
A7: 1 | B7: Марказий банк | C7: =E7+I7+M7+Q7+U7 -> 0 | D7: =F7+J7+N7+R7+V7 -> 0 | Y7: =+W7+S7+O7+K7 -> 0 | Z7: =+X7+T7+P7+L7 -> 0 | AC7: =+'Aging Analysis'!C9 -> 0 | AD7: =+C7-AC7 -> 0
B8: шундан, таъминланмаган қисми | C8: =E8+I8+M8+Q8+U8 -> 0 | D8: =F8+J8+N8+R8+V8 -> 0 | Y8: =+W8+S8+O8+K8 -> 0 | Z8: =+X8+T8+P8+L8 -> 0
A9: 2 | B9: Бошқа банклар | C9: =E9+I9+M9+Q9+U9 -> 0 | D9: =F9+J9+N9+R9+V9 -> 0 | Y9: =+W9+S9+O9+K9 -> 0 | Z9: =+X9+T9+P9+L9 -> 0 | AC9: =+'Aging Analysis'!C10 -> 0 | AD9: =+C9-AC9 -> 0
B10: шундан, таъминланмаган қисми | C10: =E10+I10+M10+Q10+U10 -> 0 | D10: =F10+J10+N10+R10+V10 -> 0 | Y10: =+W10+S10+O10+K10 -> 0 | Z10: =+X10+T10+P10+L10 -> 0
A11: 3 | B11: Ҳукумат | C11: =E11+I11+M11+Q11+U11 -> 0 | D11: =F11+J11+N11+R11+V11 -> 0 | Y11: =+W11+S11+O11+K11 -> 0 | Z11: =+X11+T11+P11+L11 -> 0 | AC11: =+'Aging Analysis'!C11 -> 0 | AD11: =+C11-AC11 -> 0
B12: шундан, таъминланмаган қисми | C12: =E12+I12+M12+Q12+U12 -> 0 | D12: =F12+J12+N12+R12+V12 -> 0 | Y12: =+W12+S12+O12+K12 -> 0 | Z12: =+X12+T12+P12+L12 -> 0
A13: 4 | B13: Жисмоний шахслар | C13: =E13+I13+M13+Q13+U13 -> 9706748229 | D13: =F13+J13+N13+R13+V13 -> 0 | E13: 8900894853 | F13: 0 | G13: 89008949 | H13: 0 | I13: 534089561 | J13: 0 | K13: 53411263 | L13: 0 | M13: 94140521 | N13: 0 | O13: 23536472 | P13: 0 | Q13: 146207436 | R13: 0 | S13: 73109718 | T13: 0 | U13: 31415858 | V13: 0 | W13: 31407981 | X13: 0 | Y13: =+W13+S13+O13+K13 -> 181465434 | Z13: =+X13+T13+P13+L13 -> 0 | AA13: 100373685 | AB13: 2719295 | AC13: =+'Aging Analysis'!C12 -> 9706748229 | AD13: =+C13-AC13 -> 0
B14: шундан, таъминланмаган қисми | C14: =E14+I14+M14+Q14+U14 -> 0 | D14: =F14+J14+N14+R14+V14 -> 0 | E14: 0 | F14: 0 | G14: 0 | H14: 0 | I14: 0 | J14: 0 | K14: 0 | L14: 0 | M14: 0 | N14: 0 | O14: 0 | P14: 0 | Q14: 0 | R14: 0 | S14: 0 | T14: 0 | U14: 0 | V14: 0 | W14: 0 | X14: 0 | Y14: =+W14+S14+O14+K14 -> 0 | Z14: =+X14+T14+P14+L14 -> 0
A15: 5 | B15: Давлат корхоналари | C15: =E15+I15+M15+Q15+U15 -> 12813996196 | D15: =F15+J15+N15+R15+V15 -> 8020986178 | E15: 10096267167 | F15: 7541171165 | G15: 98421975 | H15: 0 | I15: 2706744176 | J15: 479815013 | K15: 270674418 | L15: 47981501 | M15: 0 | N15: 0 | O15: 0 | P15: 0 | Q15: 0 | R15: 0 | S15: 0 | T15: 0 | U15: 10984853 | V15: 0 | W15: 10984853 | X15: 0 | Y15: =+W15+S15+O15+K15 -> 281659271 | Z15: =+X15+T15+P15+L15 -> 47981501 | AA15: 0 | AB15: 0 | AC15: =+'Aging Analysis'!C13 -> 12813996196 | AD15: =+C15-AC15 -> 0
B16: шундан, таъминланмаган қисми | C16: =E16+I16+M16+Q16+U16 -> 0 | D16: =F16+J16+N16+R16+V16 -> 0 | E16: 0 | F16: 0 | G16: 0 | H16: 0 | I16: 0 | J16: 0 | K16: 0 | L16: 0 | M16: 0 | N16: 0 | O16: 0 | P16: 0 | Q16: 0 | R16: 0 | S16: 0 | T16: 0 | U16: 0 | V16: 0 | W16: 0 | X16: 0 | Y16: =+W16+S16+O16+K16 -> 0 | Z16: =+X16+T16+P16+L16 -> 0
A17: 6 | B17: Қўшма ва чет эл капитали иштирокидаги корхоналар | C17: =E17+I17+M17+Q17+U17 -> 9759069887 | D17: =F17+J17+N17+R17+V17 -> 7349678047 | E17: 8810965778 | F17: 6510874630 | G17: 88109295 | H17: 0 | I17: 938524491 | J17: 838803417 | K17: 93852449 | L17: 83880342 | M17: 9405114 | N17: 0 | O17: 2351279 | P17: 0 | Q17: 27702 | R17: 0 | S17: 13851 | T17: 0 | U17: 146802 | V17: 0 | W17: 146802 | X17: 0 | Y17: =+W17+S17+O17+K17 -> 96364381 | Z17: =+X17+T17+P17+L17 -> 83880342 | AA17: 0 | AB17: 0 | AC17: =+'Aging Analysis'!C14 -> 9759069887 | AD17: =+C17-AC17 -> 0
B18: шундан, таъминланмаган қисми | C18: =E18+I18+M18+Q18+U18 -> 0 | D18: =F18+J18+N18+R18+V18 -> 0 | E18: 0 | F18: 0 | G18: 0 | H18: 0 | I18: 0 | J18: 0 | K18: 0 | L18: 0 | M18: 0 | N18: 0 | O18: 0 | P18: 0 | Q18: 0 | R18: 0 | S18: 0 | T18: 0 | U18: 0 | V18: 0 | W18: 0 | X18: 0 | Y18: =+W18+S18+O18+K18 -> 0 | Z18: =+X18+T18+P18+L18 -> 0
A19: 7 | B19: Хусусий корхоналар | C19: =E19+I19+M19+Q19+U19 -> 32532347335 | D19: =F19+J19+N19+R19+V19 -> 23580570578 | E19: 23440218775 | F19: 17979954570 | G19: 235636455 | H19: 0 | I19: 7747200513 | J19: 5179376376 | K19: 776244341 | L19: 517937639 | M19: 94406068 | N19: 21411043 | O19: 24018887 | P19: 5352762 | Q19: 368862332 | R19: 180999960 | S19: 184684793 | T19: 90499980 | U19: 881659647 | V19: 218828629 | W19: 881659647 | X19: 218828629 | Y19: =+W19+S19+O19+K19 -> 1866607668 | Z19: =+X19+T19+P19+L19 -> 832619010 | AA19: 153800183 | AB19: 105768265 | AC19: =+'Aging Analysis'!C15 -> 32532347335 | AD19: =+C19-AC19 -> 0
B20: шундан, таъминланмаган қисми | C20: =E20+I20+M20+Q20+U20 -> 0 | D20: =F20+J20+N20+R20+V20 -> 0 | E20: 0 | F20: 0 | G20: 0 | H20: 0 | I20: 0 | J20: 0 | K20: 0 | L20: 0 | M20: 0 | N20: 0 | O20: 0 | P20: 0 | Q20: 0 | R20: 0 | S20: 0 | T20: 0 | U20: 0 | V20: 0 | W20: 0 | X20: 0 | Y20: =+W20+S20+O20+K20 -> 0 | Z20: =+X20+T20+P20+L20 -> 0 | AB20: 0
A21: 8 | B21: Фермер хўжалиги | C21: =E21+I21+M21+Q21+U21 -> 88243247 | D21: =F21+J21+N21+R21+V21 -> 72388287 | E21: 36717456 | F21: 29360157 | G21: 366265 | H21: 0 | I21: 46515934 | J21: 43028130 | K21: 4651593 | L21: 4302813 | M21: 0 | N21: 0 | O21: 0 | P21: 0 | Q21: 620043 | R21: 0 | S21: 310021 | T21: 0 | U21: 4389814 | V21: 0 | W21: 4389814 | X21: 0 | Y21: =+W21+S21+O21+K21 -> 9351428 | Z21: =+X21+T21+P21+L21 -> 4302813 | AA21: 0 | AB21: 0 | AC21: =+'Aging Analysis'!C16 -> 88243247 | AD21: =+C21-AC21 -> 0
B22: шундан, таъминланмаган қисми | C22: =E22+I22+M22+Q22+U22 -> 0 | D22: =F22+J22+N22+R22+V22 -> 0 | E22: 0 | F22: 0 | G22: 0 | H22: 0 | I22: 0 | J22: 0 | K22: 0 | L22: 0 | M22: 0 | N22: 0 | O22: 0 | P22: 0 | Q22: 0 | R22: 0 | S22: 0 | T22: 0 | U22: 0 | V22: 0 | W22: 0 | X22: 0 | Y22: =+W22+S22+O22+K22 -> 0 | Z22: =+X22+T22+P22+L22 -> 0
A23: 9 | B23: Нобанк молиявий институтлар | C23: =E23+I23+M23+Q23+U23 -> 33541698 | D23: =F23+J23+N23+R23+V23 -> 0 | E23: 33541698 | F23: 0 | G23: 335417 | H23: 0 | I23: 0 | J23: 0 | K23: 0 | L23: 0 | M23: 0 | N23: 0 | O23: 0 | P23: 0 | Q23: 0 | R23: 0 | S23: 0 | T23: 0 | U23: 0 | V23: 0 | W23: 0 | X23: 0 | Y23: =+W23+S23+O23+K23 -> 0 | Z23: =+X23+T23+P23+L23 -> 0 | AA23: 0 | AB23: 0 | AC23: =+'Aging Analysis'!C17 -> 33541698 | AD23: =+C23-AC23 -> 0
B24: шундан, таъминланмаган қисми | C24: =E24+I24+M24+Q24+U24 -> 0 | D24: =F24+J24+N24+R24+V24 -> 0 | E24: 0 | F24: 0 | G24: 0 | H24: 0 | I24: 0 | J24: 0 | K24: 0 | L24: 0 | M24: 0 | N24: 0 | O24: 0 | P24: 0 | Q24: 0 | R24: 0 | S24: 0 | T24: 0 | U24: 0 | V24: 0 | W24: 0 | X24: 0 | Y24: =+W24+S24+O24+K24 -> 0 | Z24: =+X24+T24+P24+L24 -> 0
A25: 10 | B25: Нодавлат нотижорат ташкилотлар | C25: =E25+I25+M25+Q25+U25 -> 1623241 | D25: =F25+J25+N25+R25+V25 -> 430280 | E25: 1061761 | F25: 0 | G25: 10618 | H25: 0 | I25: 430280 | J25: 430280 | K25: 43028 | L25: 43028 | M25: 0 | N25: 0 | O25: 0 | P25: 0 | Q25: 0 | R25: 0 | S25: 0 | T25: 0 | U25: 131200 | V25: 0 | W25: 131200 | X25: 0 | Y25: =+W25+S25+O25+K25 -> 174228 | Z25: =+X25+T25+P25+L25 -> 43028 | AA25: 0 | AB25: 0 | AC25: =+'Aging Analysis'!C18 -> 1623241 | AD25: =+C25-AC25 -> 0
B26: шундан, таъминланмаган қисми | C26: =E26+I26+M26+Q26+U26 -> 0 | D26: =F26+J26+N26+R26+V26 -> 0 | Y26: =+W26+S26+O26+K26 -> 0 | Z26: =+X26+T26+P26+L26 -> 0
A27: 11 | B27: Бюджет ташкилотлари | C27: =E27+I27+M27+Q27+U27 -> 0 | D27: =F27+J27+N27+R27+V27 -> 0 | Y27: =+W27+S27+O27+K27 -> 0 | Z27: =+X27+T27+P27+L27 -> 0 | AA27: 0 | AB27: 0 | AC27: =+'Aging Analysis'!C19 -> 0 | AD27: =+C27-AC27 -> 0
B28: шундан, таъминланмаган қисми | C28: =E28+I28+M28+Q28+U28 -> 0 | D28: =F28+J28+N28+R28+V28 -> 0 | Y28: =+W28+S28+O28+K28 -> 0 | Z28: =+X28+T28+P28+L28 -> 0
A29: 12 | B29: Бошқалар | C29: =E29+I29+M29+Q29+U29 -> 0 | D29: =F29+J29+N29+R29+V29 -> 0 | Y29: =+W29+S29+O29+K29 -> 0 | Z29: =+X29+T29+P29+L29 -> 0 | AA29: 0 | AB29: 0 | AC29: =+'Aging Analysis'!C20 -> 0 | AD29: =+C29-AC29 -> 0
B30: шундан, таъминланмаган қисми | C30: =E30+I30+M30+Q30+U30 -> 0 | D30: =F30+J30+N30+R30+V30 -> 0 | Y30: =+W30+S30+O30+K30 -> 0 | Z30: =+X30+T30+P30+L30 -> 0
