Workbook
Name jop: #REF!
Name kol: #REF!
Name TwentyLargestData: #REF!
Name Е: #REF!

Sheet Bank Capital Calc
A1: БАНКНИНГ РЕГУЛЯТИВ КАПИТАЛИ ҲИСОБ-КИТОБИ | C1: 5-жадвал | E1: №2
B3: MKBANK | C3: 46021
A4: № | B4: Кўрсаткичлар | C4: минг сўмда
A5: I. | B5: I ДАРАЖАЛИ КАПИТАЛ
A6: 1 | B6: I ДАРАЖАЛИ АСОСИЙ КАПИТАЛ
A7: 1.1. | B7: Оддий акциялар, нетто | C7: =+C8-C9 -> 7145161149
A8: a | B8: Тўлиқ тўланган оддий акциялар | C8: 7145161149
A9: б | B9: Минус: Қайта сотиб олинган оддий акциялар | C9: 0
A10: 1.2. | B10: Қўшимча капитал (оддий)
A11: 1.3. | B11: Тақсимланмаган фойда (зарар), шу жумладан капитал захиралар | C11: =+C12+C13-C14-C15 -> -1571600175
A12: а | B12: Капитал ва бошқа захиралар | C12: 27827555
A13: б | B13: Тақсимланмаган фойда | C13: 0
A14: в | B14: Ўтган даврлар (йиллар) учун зарарлар | C14: 1599427730
A15: г | B15: Жорий йил учун зарар | C15: 0
A16: 1.4. | B16: Озчилик улуш эгаларининг банк йиғма балансига бирлашадиган корхоналардаги улушлари | C16: 0
A17: 1.5. | B17: Девальвация захираси | C17: 0
A18: 1.6. | B18: Чегирмалар ҳисоблангунга қадар жами I даражали асосий капитал | C18: =+C7+C10+C11+C16+C17 -> 5573560974
A19: 1.7. | B19: I даражали асосий капиталдан чегирмалар | C19: =C20+C21+C22+C23+C24 -> 6889119
A20: а | B20: Номоддий активлар (бундан банкнинг дастурий таъминотлари мустасно) | C20: 6889119 | H20: бирлашмаган молиявий бўлмаган битта ташкилот устав фондидаги (устав капиталидаги) улушлар ва (ёки) акцияларга инвестицияларнинг банк I даражали асосий капиталининг 15 фоизидан ошган қисми
A21: б | B21: Бирлашмаган молиявий бўлмаган ташкилотлар капиталига қилинган инвестициялар | C21: =+G20+G21 -> 0 | G21: 0 | H21: бирлашмаган молиявий бўлмаган барча ташкилотлар устав фондидаги (устав капиталидаги) улушлар ва (ёки) акцияларга инвестициялар йиғиндисининг (бунда инвестициянинг мазкур банднинг «д»- кичик банди иккинчи хатбошисига кўра чегирилган қисми ҳисобга олинмайди) банк I даражали асосий капиталининг 50 фоизидан ошган қисми
A22: в | B22: Бирлашмаган молиявий бўлган ташкилотлар капиталига қилинган инвестициялар | C22: =+G22+G23 -> 0 | H22: бирлашмаган молиявий ташкилот устав фондидаги (устав капиталидаги) улушлар ва (ёки) акцияларга инвестициялар натижасида банкнинг ушбу ташкилотдаги улуши 10 фоиздан ошмаган бўлса, бундай ташкилотларга жами инвестициялар йиғиндисининг банк I даражали асосий капиталининг 10 фоизидан ошган қисми
A23: г | B23: Банк томонидан муаммоли активлар бўйича қўшимча шакллантирилиши лозим бўлган захиралар | C23: 0 | H23: бирлашмаган молиявий ташкилот устав фондидаги (устав капиталидаги) улушлар ва (ёки) акцияларга инвестициялар натижасида банкнинг ушбу ташкилотдаги улуши 10 фоиздан ошган бўлса, бундай ташкилотларга жами инвестициялар йиғиндисининг банк I даражали асосий капиталининг 10 фоизидан ошган қисми
A24: д | B24: Банкка алоқадор бир ёки барча шахслар учун таваккалчиликнинг белгиланган энг кўп миқдоридан ортиқ қиймати | C24: =+IF(MAX('[6]Transactions of related parties'!$Z$90-E25*25%,'[6]Transactions of related parties'!$Z$89-E25*50%)<0,0,MAX('[6]Transactions of related parties'!$Z$90-E25*25%,'[6]Transactions of related parties'!$Z$89-E25*50%)) -> 0 | E24: =+'[6]Transactions of related parties'!$Z$89 -> 2179274
A25: I | B25: I ДАРАЖАЛИ АСОСИЙ КАПИТАЛ | C25: =+C18-C19 -> 5566671855 | E25: =C18-C20-C21-C22-C23 -> 5566671855
A26: 2 | B26: I ДАРАЖАЛИ ҚЎШИМЧА КАПИТАЛ
A27: 2.1. | B27: Нокумулятив муддатсиз имтиёзли акциялар | C27: =+C28-C29 -> 175651
A28: а | B28: Тўлиқ тўланган имтиёзли акциялар | C28: 175651
A29: б | B29: Минус: Қайтиб сотиб олинган имтиёзли акциялар | C29: 0
A30: 2.2. | B30: Қўшилган капитал (имтиёзли) | C30: 0
A31: 2.3. | B31: Озчилик улуш эгаларининг банк йиғма балансига бирлашадиган корхоналардаги улушлари | C31: 0
A32: 2.4. | B32: Шўъба корхоналарнинг улушлари (шўъба корхоналар томонидан чиқарилган ва капиталга тенглаштирилган учинчи шахслар эгалик қиладиган воситалар) | C32: 0
A33: II | B33: ЖАМИ I ДАРАЖАЛИ ҚЎШИМЧА КАПИТАЛ | C33: =+C27+C30+C31+C32 -> 175651
A34: III | B34: ЖАМИ ТЎҒРИЛАНГАН I ДАРАЖАЛИ КАПИТАЛ | C34: =+C25+C33 -> 5566847506 | E34: =+C44/2 -> 3.1348333e+09
B35: II ДАРАЖАЛИ КАПИТАЛ
A36: 3.1. | B36: Жорий йил соф фойдаси | C36: 160802633
A37: 3.2. | B37: Стандарт активларга яратилган захиралар | C37: =IF(F37<(C45*1.25%),F37,(C45*1.25%)) -> 123374035 | E37: Резервы созданные по стандартным активам | F37: 123374035
A38: 3.3. | B38: Чегирмалардан сўнг I даражали капиталнинг учдан бир қисмидан ошмаган миқдорда аралаш турдаги мажбуриятлар | C38: 0 | F38: =+[7]Balance!$C$39+[7]Balance!$C$61 -> 123374035
A39: 3.4. | B39: Субординар қарз | C39: 416540075 | F39: =+F37-F38 -> 0
A40: 3.5. | B40: Активларнинг бошланғич қийматига нисбатан баҳолаш қийматининг ошган суммасининг 45 фоизи миқдори | C40: 2102260
A41: 3.6. | B41: II даражали капиталнинг I даражали капиталдан ортиқча қисми (чегирмаси) | C41: =IF($C$34>=SUM($C$36:$C$40),0,(SUM($C$36:$C$40)-$C$34))*-1 -> 0
...

Sheet Bank Capital Calc (2)
A1: РАСЧЕТ РЕГУЛЯТИВНОГО КАПИТАЛА БАНКА | C1: Таблица-5
B3: =#REF! -> #REF! | C3: =+#REF! -> #REF!
A4: № | B4: Характеристики | C4: Итого капитала
A5: I. | B5: КАПИТАЛ УРОВНЯ 1
A6: 1 | B6: ОСНОВНОЙ КАПИТАЛ УРОВНЯ 1
A7: 1.1. | B7: Обыкновенные Акции, чистые | C7: Формула
A8: a | B8: Полностью оплаченные обыкновенные акции
A9: б | B9: Минус: Обратно Выкупленные обыкновенные акции
A10: 1.2. | B10: Добавленный капитал - Обыкновенные | C10: 0
A11: 1.3. | B11: Нераспределенная прибыль (убыток), в том числе капитальные резервы | C11: Формула
A12: а | B12: Капитальные резервы
A13: б | B13: Нераспределенная прибыль
A14: в | B14: Убыток за предыдущие периоды
A15: г | B15: Убыток за текущий год
A16: 1.4. | B16: Интерес меньшинства в консолидированных дочерних компаниях (согласно МБС)
A17: 1.5. | B17: Резерв на девальвацию
B18: Итого основного капитала уровня I до вычетов | C18: Формула
A19: 1.6. | B19: Вычеты из суммы основного капитала уровня I | C19: Формула
A20: а | B20: Нематериальные активы
A21: б | B21: Все инвестиции в капитал неконсолидированных хозяйствующих субъектов, в том числе в долговые обязательства, которые образуют капитал хозяйствующих субъектов
A22: в | B22: Инвестиции в капитал других банков
A23: I | B23: ВСЕГО СКОРРЕКТИРОВАННЫЙ ОСНОВНОЙ КАПИТАЛ УРОВНЯ I | C23: Формула
A24: 2 | B24: ДОБАВЛЕННЫЙ КАПИТАЛ УРОВНЯ 1
A25: 2.1. | B25: Некумулятивные бессрочные привилегированные акции | C25: =+C26+C27 -> 0
A26: а | B26: Полностью оплаченные привилегированные акции
A27: б | B27: Минус: Обратно Выкупленные привилегированные акции
A28: 2.2. | B28: Добавленный капитал - Привилегированные | C28: 0
A29: 2.3. | B29: Интерес меньшинства в консолидированных дочерних компаниях | C29: 0
A30: 2.4. | B30: Доля участия дочерних предприятий (выпущенные дочерними предприятиями и находящиеся во владении третьих лиц инструменты, приравненные к капиталу) | C30: 0
A31: II | B31: ВСЕГО ДОБАВЛЕННЫЙ КАПИТАЛ УРОВНЯ I | C31: =+C25+C28+C29+C30 -> 0
A32: III | B32: ВСЕГО СКОРРЕКТИРОВАННЫЙ КАПИТАЛ УРОВНЯ I | C32: Формула
B33: КАПИТАЛ УРОВНЯ II
A34: 3.1. | B34: Прибыль за текущий год
A35: 3.2. | B35: Резервы, создаваемые на стандартные кредиты (активы), в размере не более 1.25% от общей суммы активов, взвешенных с учетом риска | C35: =IF(#REF!<(C43*1.25%),#REF!,(C43*1.25%)) -> #REF!
A36: 3.3. | B36: Излишки оценочной стоимости прироста над первоначальной стоимостью
A37: 3.4. | B37: Другие инструменты капитала (не более 1/3 части капитала 1 уровня после вычетов)
A38: 3.5. | B38: Субординированный долг
A39: 3.6. | B39: Вычеты превышения Капитала Уровня II над Капиталом Уровня I | C39: Формула
B40: Итого капитала Уровня II | C40: =SUM(C34:C38) -> #REF!
A41: IV | B41: СКОРРЕКТИРОВАННЫЙ КАПИТАЛ УРОВНЯ II | C41: Формула
...

Sheet Calculation of Risk Weighted As
A1: ТАВАККАЛЧИЛИКНИ ҲИСОБГА ОЛГАН ҲОЛДАГИ АКТИВЛАР | L1: 6-жадвал | M1: №2
B2: =+'Bank Capital Calc'!B3 -> MKBANK | J2: =+'Bank Capital Calc'!C3 -> 46021 | L2: минг сўмда
A3: № | B3: Кўрсаткичлар | D3: 0 | E3: 0.2 | F3: 0.35 | G3: 0.5 | H3: 0.75 | I3: 1 | J3: 1.5 | K3: 2 | L3: 2.5
D4: Таваккалчилик | E4: Таваккалчилик | F4: Таваккалчилик | G4: Таваккалчилик | H4: Таваккалчилик | I4: Таваккалчилик | J4: Таваккалчилик | K4: Таваккалчилик | L4: Таваккалчилик
D5: I гуруҳ | E5: II гуруҳ | F5: III гуруҳ | G5: IV гуруҳ | H5: V гуруҳ | I5: VI гуруҳ | J5: VII гуруҳ | K5: VIII гуруҳ | L5: IX гуруҳ
B6: (A) | D6: (Б) | E6: (В) | F6: (Г) | G6: (Д) | H6: (Е) | I6: (Ж) | J6: (З) | K6: (И) | L6: (K)
B7: I. БАЛАНС АКТИВЛАРИ
A8: 1. | B8: Кассадаги нақд пул ва бошқа тўлов ҳужжатлари ва қимматбаҳо металлар | D8: 416486264
A9: 2. | B9: Йўлдаги нақд пуллар ва бошқа тўлов ҳужжатлари | E9: 287064457
A10: 3. | B10: Банкнинг Марказий банкдаги маблағлар | D10: 584034134 | E10: 0
A11: 4. | B11: Бошқа банкларга жойлаштирилган пул маблағлари, жумладан вакиллик ҳисобварақлари, депозитлар ва кредитлар | E11: 2002567177 | G11: 709223347 | I11: 50382898 | J11: 704707635
A12: 5. | B12: Қимматли қоғозлар (соф)
A13: а | B13: Ўзбекистон Республикаси Ҳукумати ва Марказий банки томонидан чиқарилган қимматли қоғозлар | D13: 508169320 | E13: 0
A14: б | B14: Ипотекани қайта молиялаштириш ташкилотлари томонидан чиқарилган қимматли қоғозлар | D14: 0 | E14: 10000000
A15: в | B15: Хорижий давлатларининг ҳукуматлари ва марказий банклари томонидан чиқарилган қимматли қоғозлар, шунингдек ушбу мамлакатларнинг марказий банклари ва ҳукуматларига нисбатан бошқа талаблар | D15: 0 | E15: 0
A16: г | B16: Ўзбекистон Республикаси ҳудудида чиқарилган бошқа қимматли қоғозлар | D16: 0 | E16: 0
A17: д | B17: Ўзбекистон Республикаси ҳудудидан ташқарида чиқарилган бошқа қимматли қоғозлар | D17: 0 | E17: 0
A18: е | B18: РЕПО битимлари бўйича сотиб олинган қимматли қоғозлар | D18: 0 | E18: 0
A19: 6. | B19: Миллий валютага деноминация қилинмаган ва миллий валютада молиялаштириш суммасидан ошиб кетган активлар
A20: 7. | B20: Хорижий давлатларнинг давлат секторлари (ҳукуматлар ва марказий банклар бундан мустасно) ва хорижий компаниялар бўйича банк талаблари, шунингдек уларнинг қимматли қоғозлари билан таъминланган ёки кафолатланган активлар (кредитлар ва қимматли қоғозлар бундан мустасно) | D20: 0 | E20: 0
A21: 8. | B21: Кредит ва лизинглар, соф
A22: 8.1. | B22: Юридик шахсларга ажратилган кредит ва лизинглар, соф
A23: а | B23: Ўзбекистон Республикаси ҳукумати ва Марказий банкига тўғридан-тўғри берилган кредитлар | D23: 0
A24: б | B24: Халқаро молия институтларига берилган кредитлар, халқаро молия ташкилотларининг қимматли қоғозлари билан таъминланган ёки улар томонидан кафолатланган кредитлар | D24: 0
A25: в | B25: Кредитларнинг депозит билан таъминланган қисми | D25: 0 | E25: 0
A26: г | B26: Жорий бозор қийматида баҳоланган ва ЎзР Ҳукумати, ЎзР Марказий банки томонидан эмиссия қилинган ёки кафолатланган қимматли қоғозлар кўринишидаги гаров билан таъминланган ёки кафолатланган кредитлар, уларнинг қисмлари | D26: 0
A27: д | B27: Дастлабки гаров ҳуқуқи банкка тегишли бўлмаган кредитлар | I27: 0
A28: е | B28: Қайта тикланадиган энергия манбалари учун ажратилган кредитлар | D28: 25146470 | I28: 13589939 | J28: 0 | K28: 0
A29: ж | B29: 2024 йил 1 апрелдан бошлаб 2025 йил 1 июнга қадар доимий даромадга эга бўлган, шунингдек камида олти ой давомида банк ҳисобварағида, шу жумладан банк картасида маблағлар айланмасига эга бўлган кичик тадбиркорлик субъектларига микромолиялаштириш фаолияти доирасида кўрсатилган хизматлар (оилавий тадбиркорликни ривожлантириш дастурлари доирасида ажратилган кредитлар мустасно) | H29: 0
A30: з | B30: 2024 йил 1 апрелдан бошлаб 2025 йил 1 июнга қадар мазкур жадвалнинг 8.1.ж-қаторида қайд этилган хизматларни кўрсатиш мақсадида микромолия ташкилотларига ажратилган кредитлар | H30: 0
A31: и | B31: 2025 йил 1 июндан бошлаб кичик тадбиркорлик субъектларига ажратилган жами қолдиқ суммаси банк регулятив капиталининг 0,2 фоизидан ошмаган, бироқ энг кўпи билан 15 млрд. сўмгача кредитлар (оилавий тадбиркорликни ривожлантириш дастурлари доирасида ажратилган кредитлар мустасно) | H31: 882500809
A32: к | B32: Юридик шахсларга ажратилган бошқа барча кредит, лизинг ва кўрсатилган факторинг хизматлари | I32: 8986784184 | J32: 906804172 | K32: 541134414
A33: л | B33: Юридик шахсларнинг муаммоли кредит ва лизинглари, соф | K33: 384144464
A34: 8.2. | B34: Жисмоний шахсларга ажратилган кредитлар, соф
A35: а | B35: Дастлабки гаров ҳуқуқи банкка тегишли бўлмаган кредитлар
A36: б | B36: Кредитларнинг (микроқарзларнинг) депозит билан таъминланган қисми
A37: в | B37: 2024 йил 1 июлга қадар ажратилган ипотека кредитлари | F37: 41905153 | G37: 194137077 | I37: 505205459 | J37: 10438662
A38: г | B38: 2024 йил 1 июлдан бошлаб ажратилган ипотека кредитлари | F38: 4046099 | G38: 21718576 | I38: 276640869 | J38: 417098745
A39: д | B39: 2023 йил 20 августга қадар автомобиль сотиб олиш учун ажратилган кредитлар | I39: 20449913 | J39: 26624915 | K39: 3883155
A40: е | B40: 2023 йил 20 августдан бошлаб 2024 йил 1 июлга қадар жисмоний шахсларга автомобиль сотиб олиш учун ажратилган кредитлар | I40: 146576121 | J40: 139324014 | K40: 11962343
...

Sheet Calculation of Risk Weighte нац
A1: МИЛЛИЙ ВАЛЮТАДА ТАВАККАЛЧИЛИКНИ ҲИСОБГА ОЛГАН ҲОЛДАГИ АКТИВЛАР | L1: 6.1-жадвал
B2: =+'Bank Capital Calc'!B3 -> MKBANK | J2: =+'Bank Capital Calc'!C3 -> 46021 | L2: минг сўмда
A3: № | B3: Кўрсаткичлар | D3: 0 | E3: 0.2 | F3: 0.35 | G3: 0.5 | H3: 0.75 | I3: 1 | J3: 1.5 | K3: 2 | L3: 2.5
D4: Таваккалчилик | E4: Таваккалчилик | F4: Таваккалчилик | G4: Таваккалчилик | H4: Таваккалчилик | I4: Таваккалчилик | J4: Таваккалчилик | K4: Таваккалчилик | L4: Таваккалчилик
D5: I гуруҳ | E5: II гуруҳ | F5: III гуруҳ | G5: IV гуруҳ | H5: V гуруҳ | I5: VI гуруҳ | J5: VII гуруҳ | K5: VIII гуруҳ | L5: IX гуруҳ
B6: (A) | D6: (Б) | E6: (В) | F6: (Г) | G6: (Д) | H6: (Е) | I6: (Ж) | J6: (З) | K6: (И) | L6: (K)
B7: I. БАЛАНС АКТИВЛАРИ
A8: 1. | B8: Кассадаги нақд пул ва бошқа тўлов ҳужжатлари ва қимматбаҳо металлар | D8: 350206926
A9: 2. | B9: Йўлдаги нақд пуллар ва бошқа тўлов ҳужжатлари | E9: 188784749
A10: 3. | B10: Банкнинг Марказий банкдаги маблағлар | D10: 584034134 | E10: 0
A11: 4. | B11: Бошқа банкларга жойлаштирилган пул маблағлари, жумладан вакиллик ҳисобварақлари, депозитлар ва кредитлар | E11: 0 | G11: 11133345 | I11: 50382898 | J11: 0
A12: 5. | B12: Қимматли қоғозлар (соф)
A13: а | B13: Ўзбекистон Республикаси Ҳукумати ва Марказий банки томонидан чиқарилган қимматли қоғозлар | D13: 508169320 | E13: 0
A14: б | B14: Ипотекани қайта молиялаштириш ташкилотлари томонидан чиқарилган қимматли қоғозлар | D14: 0 | E14: 10000000
A15: в | B15: Хорижий давлатларининг ҳукуматлари ва марказий банклари томонидан чиқарилган қимматли қоғозлар, шунингдек ушбу мамлакатларнинг марказий банклари ва ҳукуматларига нисбатан бошқа талаблар | D15: 0 | E15: 0 | G15: 0 | I15: 0 | J15: 0
A16: г | B16: Ўзбекистон Республикаси ҳудудида чиқарилган бошқа қимматли қоғозлар | D16: 0 | E16: 0 | G16: 0 | I16: 0 | J16: 0
A17: д | B17: Ўзбекистон Республикаси ҳудудидан ташқарида чиқарилган бошқа қимматли қоғозлар | D17: 0 | E17: 0 | G17: 0 | I17: 0 | J17: 0
A18: е | B18: РЕПО битимлари бўйича сотиб олинган қимматли қоғозлар | D18: 0 | E18: 0 | G18: 0 | I18: 0 | J18: 0
A19: 6. | B19: Миллий валютага деноминация қилинмаган ва миллий валютада молиялаштириш суммасидан ошиб кетган активлар | I19: 0
A20: 7. | B20: Хорижий давлатларнинг давлат секторлари (ҳукуматлар ва марказий банклар бундан мустасно) ва хорижий компаниялар бўйича банк талаблари, шунингдек уларнинг қимматли қоғозлари билан таъминланган ёки кафолатланган активлар (кредитлар ва қимматли қоғозлар бундан мустасно) | D20: 0 | E20: 0 | G20: 0 | I20: 0 | J20: 0
A21: 8. | B21: Кредит ва лизинглар, соф
A22: 8.1. | B22: Юридик шахсларга ажратилган кредит ва лизинглар, соф
A23: а | B23: Ўзбекистон Республикаси ҳукумати ва Марказий банкига тўғридан-тўғри берилган кредитлар | D23: 0
A24: б | B24: Халқаро молия институтларига берилган кредитлар, халқаро молия ташкилотларининг қимматли қоғозлари билан таъминланган ёки улар томонидан кафолатланган кредитлар | D24: 0
A25: в | B25: Кредитларнинг депозит билан таъминланган қисми | D25: 0 | E25: 0
A26: г | B26: Жорий бозор қийматида баҳоланган ва ЎзР Ҳукумати, ЎзР Марказий банки томонидан эмиссия қилинган ёки кафолатланган қимматли қоғозлар кўринишидаги гаров билан таъминланган ёки кафолатланган кредитлар, уларнинг қисмлари | D26: 0
A27: д | B27: Дастлабки гаров ҳуқуқи банкка тегишли бўлмаган кредитлар | I27: 0
A28: е | B28: Қайта тикланадиган энергия манбалари учун ажратилган кредитлар | D28: 25146470 | I28: 13589939 | J28: 0 | K28: 0
A29: ж | B29: 2024 йил 1 апрелдан бошлаб 2025 йил 1 июнга қадар доимий даромадга эга бўлган, шунингдек камида олти ой давомида банк ҳисобварағида, шу жумладан банк картасида маблағлар айланмасига эга бўлган кичик тадбиркорлик субъектларига микромолиялаштириш фаолияти доирасида кўрсатилган хизматлар (оилавий тадбиркорликни ривожлантириш дастурлари доирасида ажратилган кредитлар мустасно) | H29: 0
A30: з | B30: 2024 йил 1 апрелдан бошлаб 2025 йил 1 июнга қадар мазкур жадвалнинг 8.1.ж-қаторида қайд этилган хизматларни кўрсатиш мақсадида микромолия ташкилотларига ажратилган кредитлар | H30: 0
A31: и | B31: 2025 йил 1 июндан бошлаб кичик тадбиркорлик субъектларига ажратилган жами қолдиқ суммаси банк регулятив капиталининг 0,2 фоизидан ошмаган, бироқ энг кўпи билан 15 млрд. сўмгача кредитлар (оилавий тадбиркорликни ривожлантириш дастурлари доирасида ажратилган кредитлар мустасно) | H31: 870639551
A32: к | B32: Юридик шахсларга ажратилган бошқа барча кредит, лизинг ва кўрсатилган факторинг хизматлари | I32: 6061797156 | J32: 466859789 | K32: 287232270
A33: л | B33: Юридик шахсларнинг муаммоли кредит ва лизинглари, соф | K33: 300550490
A34: 8.2. | B34: Жисмоний шахсларга ажратилган кредитлар, соф
A35: а | B35: Дастлабки гаров ҳуқуқи банкка тегишли бўлмаган кредитлар | I35: 0
A36: б | B36: Кредитларнинг (микроқарзларнинг) депозит билан таъминланган қисми | D36: 0 | E36: 0
A37: в | B37: 2024 йил 1 июлга қадар ажратилган ипотека кредитлари | F37: 41905153 | G37: 194137077 | I37: 505205459 | J37: 10438662
A38: г | B38: 2024 йил 1 июлдан бошлаб ажратилган ипотека кредитлари | F38: 4046099 | G38: 21718576 | I38: 276640869 | J38: 417098745
A39: д | B39: 2023 йил 20 августга қадар автомобиль сотиб олиш учун ажратилган кредитлар | I39: 20449913 | J39: 26624915 | K39: 3883155
A40: е | B40: 2023 йил 20 августдан бошлаб 2024 йил 1 июлга қадар жисмоний шахсларга автомобиль сотиб олиш учун ажратилган кредитлар | I40: 146576121 | J40: 139324014 | K40: 11962343
...

Sheet Calculation of Risk Weighte ин
A1: ХОРИЖИЙ ВАЛЮТАДА ТАВАККАЛЧИЛИКНИ ҲИСОБГА ОЛГАН ҲОЛДАГИ АКТИВЛАР | L1: 6.2-жадвал
B2: =+'Bank Capital Calc'!B3 -> MKBANK | J2: =+'Bank Capital Calc'!C3 -> 46021 | L2: минг сўмда
A3: № | B3: Кўрсаткичлар | D3: 0 | E3: 0.2 | F3: 0.35 | G3: 0.5 | H3: 0.75 | I3: 1 | J3: 1.5 | K3: 2 | L3: 2.5
D4: Таваккалчилик | E4: Таваккалчилик | F4: Таваккалчилик | G4: Таваккалчилик | H4: Таваккалчилик | I4: Таваккалчилик | J4: Таваккалчилик | K4: Таваккалчилик | L4: Таваккалчилик
D5: I гуруҳ | E5: II гуруҳ | F5: III гуруҳ | G5: IV гуруҳ | H5: V гуруҳ | I5: VI гуруҳ | J5: VII гуруҳ | K5: VIII гуруҳ | L5: IX гуруҳ
B6: (A) | D6: (Б) | E6: (В) | F6: (Г) | G6: (Д) | H6: (Е) | I6: (Ж) | J6: (З) | K6: (И) | L6: (K)
B7: I. БАЛАНС АКТИВЛАРИ
A8: 1. | B8: Кассадаги нақд пул ва бошқа тўлов ҳужжатлари ва қимматбаҳо металлар | D8: =+'Calculation of Risk Weighted As'!D8-'Calculation of Risk Weighte нац'!D8 -> 66279338
A9: 2. | B9: Йўлдаги нақд пуллар ва бошқа тўлов ҳужжатлари | E9: =+'Calculation of Risk Weighted As'!E9-'Calculation of Risk Weighte нац'!E9 -> 98279708
A10: 3. | B10: Банкнинг Марказий банкдаги маблағлар | D10: =+'Calculation of Risk Weighted As'!D10-'Calculation of Risk Weighte нац'!D10 -> 0 | E10: =+'Calculation of Risk Weighted As'!E10-'Calculation of Risk Weighte нац'!E10 -> 0
A11: 4. | B11: Бошқа банкларга жойлаштирилган пул маблағлари, жумладан вакиллик ҳисобварақлари, депозитлар ва кредитлар | E11: =+'Calculation of Risk Weighted As'!E11-'Calculation of Risk Weighte нац'!E11 -> 2002567177 | G11: =+'Calculation of Risk Weighted As'!G11-'Calculation of Risk Weighte нац'!G11 -> 698090002 | I11: =+'Calculation of Risk Weighted As'!I11-'Calculation of Risk Weighte нац'!I11 -> 0 | J11: =+'Calculation of Risk Weighted As'!J11-'Calculation of Risk Weighte нац'!J11 -> 704707635
A12: 5. | B12: Қимматли қоғозлар (соф)
A13: а | B13: Ўзбекистон Республикаси Ҳукумати ва Марказий банки томонидан чиқарилган қимматли қоғозлар | D13: =+'Calculation of Risk Weighted As'!D13-'Calculation of Risk Weighte нац'!D13 -> 0 | E13: =+'Calculation of Risk Weighted As'!E13-'Calculation of Risk Weighte нац'!E13 -> 0
A14: б | B14: Ипотекани қайта молиялаштириш ташкилотлари томонидан чиқарилган қимматли қоғозлар | D14: =+'Calculation of Risk Weighted As'!D14-'Calculation of Risk Weighte нац'!D14 -> 0 | E14: =+'Calculation of Risk Weighted As'!E14-'Calculation of Risk Weighte нац'!E14 -> 0
A15: в | B15: Хорижий давлатларининг ҳукуматлари ва марказий банклари томонидан чиқарилган қимматли қоғозлар, шунингдек ушбу мамлакатларнинг марказий банклари ва ҳукуматларига нисбатан бошқа талаблар | D15: =+'Calculation of Risk Weighted As'!D15-'Calculation of Risk Weighte нац'!D15 -> 0 | E15: =+'Calculation of Risk Weighted As'!E15-'Calculation of Risk Weighte нац'!E15 -> 0 | G15: =+'Calculation of Risk Weighted As'!G15-'Calculation of Risk Weighte нац'!G15 -> 0 | I15: =+'Calculation of Risk Weighted As'!I15-'Calculation of Risk Weighte нац'!I15 -> 0 | J15: =+'Calculation of Risk Weighted As'!J15-'Calculation of Risk Weighte нац'!J15 -> 0
A16: г | B16: Ўзбекистон Республикаси ҳудудида чиқарилган бошқа қимматли қоғозлар | D16: =+'Calculation of Risk Weighted As'!D16-'Calculation of Risk Weighte нац'!D16 -> 0 | E16: =+'Calculation of Risk Weighted As'!E16-'Calculation of Risk Weighte нац'!E16 -> 0 | G16: =+'Calculation of Risk Weighted As'!G16-'Calculation of Risk Weighte нац'!G16 -> 0 | I16: =+'Calculation of Risk Weighted As'!I16-'Calculation of Risk Weighte нац'!I16 -> 0 | J16: =+'Calculation of Risk Weighted As'!J16-'Calculation of Risk Weighte нац'!J16 -> 0
A17: д | B17: Ўзбекистон Республикаси ҳудудидан ташқарида чиқарилган бошқа қимматли қоғозлар | D17: =+'Calculation of Risk Weighted As'!D17-'Calculation of Risk Weighte нац'!D17 -> 0 | E17: =+'Calculation of Risk Weighted As'!E17-'Calculation of Risk Weighte нац'!E17 -> 0 | G17: =+'Calculation of Risk Weighted As'!G17-'Calculation of Risk Weighte нац'!G17 -> 0 | I17: =+'Calculation of Risk Weighted As'!I17-'Calculation of Risk Weighte нац'!I17 -> 0 | J17: =+'Calculation of Risk Weighted As'!J17-'Calculation of Risk Weighte нац'!J17 -> 0
A18: е | B18: РЕПО битимлари бўйича сотиб олинган қимматли қоғозлар | D18: =+'Calculation of Risk Weighted As'!D18-'Calculation of Risk Weighte нац'!D18 -> 0 | E18: =+'Calculation of Risk Weighted As'!E18-'Calculation of Risk Weighte нац'!E18 -> 0 | G18: =+'Calculation of Risk Weighted As'!G18-'Calculation of Risk Weighte нац'!G18 -> 0 | I18: =+'Calculation of Risk Weighted As'!I18-'Calculation of Risk Weighte нац'!I18 -> 0 | J18: =+'Calculation of Risk Weighted As'!J18-'Calculation of Risk Weighte нац'!J18 -> 0
A19: 6. | B19: Миллий валютага деноминация қилинмаган ва миллий валютада молиялаштириш суммасидан ошиб кетган активлар | I19: =+'Calculation of Risk Weighted As'!I19-'Calculation of Risk Weighte нац'!I19 -> 0
A20: 7. | B20: Хорижий давлатларнинг давлат секторлари (ҳукуматлар ва марказий банклар бундан мустасно) ва хорижий компаниялар бўйича банк талаблари, шунингдек уларнинг қимматли қоғозлари билан таъминланган ёки кафолатланган активлар (кредитлар ва қимматли қоғозлар бундан мустасно) | D20: =+'Calculation of Risk Weighted As'!D20-'Calculation of Risk Weighte нац'!D20 -> 0 | E20: =+'Calculation of Risk Weighted As'!E20-'Calculation of Risk Weighte нац'!E20 -> 0 | G20: =+'Calculation of Risk Weighted As'!G20-'Calculation of Risk Weighte нац'!G20 -> 0 | I20: =+'Calculation of Risk Weighted As'!I20-'Calculation of Risk Weighte нац'!I20 -> 0 | J20: =+'Calculation of Risk Weighted As'!J20-'Calculation of Risk Weighte нац'!J20 -> 0
A21: 8. | B21: Кредит ва лизинглар, соф
A22: 8.1. | B22: Юридик шахсларга ажратилган кредит ва лизинглар, соф
A23: а | B23: Ўзбекистон Республикаси ҳукумати ва Марказий банкига тўғридан-тўғри берилган кредитлар | D23: =+'Calculation of Risk Weighted As'!D23-'Calculation of Risk Weighte нац'!D23 -> 0
A24: б | B24: Халқаро молия институтларига берилган кредитлар, халқаро молия ташкилотларининг қимматли қоғозлари билан таъминланган ёки улар томонидан кафолатланган кредитлар | D24: =+'Calculation of Risk Weighted As'!D24-'Calculation of Risk Weighte нац'!D24 -> 0
A25: в | B25: Кредитларнинг депозит билан таъминланган қисми | D25: =+'Calculation of Risk Weighted As'!D25-'Calculation of Risk Weighte нац'!D25 -> 0 | E25: =+'Calculation of Risk Weighted As'!E25-'Calculation of Risk Weighte нац'!E25 -> 0
A26: г | B26: Жорий бозор қийматида баҳоланган ва ЎзР Ҳукумати, ЎзР Марказий банки томонидан эмиссия қилинган ёки кафолатланган қимматли қоғозлар кўринишидаги гаров билан таъминланган ёки кафолатланган кредитлар, уларнинг қисмлари | D26: =+'Calculation of Risk Weighted As'!D26-'Calculation of Risk Weighte нац'!D26 -> 0
A27: д | B27: Дастлабки гаров ҳуқуқи банкка тегишли бўлмаган кредитлар | I27: =+'Calculation of Risk Weighted As'!I27-'Calculation of Risk Weighte нац'!I27 -> 0
A28: е | B28: Қайта тикланадиган энергия манбалари учун ажратилган кредитлар | D28: =+'Calculation of Risk Weighted As'!D28-'Calculation of Risk Weighte нац'!D28 -> 0 | I28: =+'Calculation of Risk Weighted As'!I28-'Calculation of Risk Weighte нац'!I28 -> 0 | J28: =+'Calculation of Risk Weighted As'!J28-'Calculation of Risk Weighte нац'!J28 -> 0 | K28: =+'Calculation of Risk Weighted As'!K28-'Calculation of Risk Weighte нац'!K28 -> 0
A29: ж | B29: 2024 йил 1 апрелдан бошлаб 2025 йил 1 июнга қадар доимий даромадга эга бўлган, шунингдек камида олти ой давомида банк ҳисобварағида, шу жумладан банк картасида маблағлар айланмасига эга бўлган кичик тадбиркорлик субъектларига микромолиялаштириш фаолияти доирасида кўрсатилган хизматлар (оилавий тадбиркорликни ривожлантириш дастурлари доирасида ажратилган кредитлар мустасно) | H29: =+'Calculation of Risk Weighted As'!H29-'Calculation of Risk Weighte нац'!H29 -> 0
A30: з | B30: 2024 йил 1 апрелдан бошлаб 2025 йил 1 июнга қадар мазкур жадвалнинг 8.1.ж-қаторида қайд этилган хизматларни кўрсатиш мақсадида микромолия ташкилотларига ажратилган кредитлар | H30: =+'Calculation of Risk Weighted As'!H30-'Calculation of Risk Weighte нац'!H30 -> 0
A31: и | B31: 2025 йил 1 июндан бошлаб кичик тадбиркорлик субъектларига ажратилган жами қолдиқ суммаси банк регулятив капиталининг 0,2 фоизидан ошмаган, бироқ энг кўпи билан 15 млрд. сўмгача кредитлар (оилавий тадбиркорликни ривожлантириш дастурлари доирасида ажратилган кредитлар мустасно) | H31: =+'Calculation of Risk Weighted As'!H31-'Calculation of Risk Weighte нац'!H31 -> 11861258
A32: к | B32: Юридик шахсларга ажратилган бошқа барча кредит, лизинг ва кўрсатилган факторинг хизматлари | I32: =+'Calculation of Risk Weighted As'!I32-'Calculation of Risk Weighte нац'!I32 -> 2924987028 | J32: =+'Calculation of Risk Weighted As'!J32-'Calculation of Risk Weighte нац'!J32 -> 439944383 | K32: =+'Calculation of Risk Weighted As'!K32-'Calculation of Risk Weighte нац'!K32 -> 253902144
A33: л | B33: Юридик шахсларнинг муаммоли кредит ва лизинглари, соф | K33: =+'Calculation of Risk Weighted As'!K33-'Calculation of Risk Weighte нац'!K33 -> 83593974
A34: 8.2. | B34: Жисмоний шахсларга ажратилган кредитлар, соф
A35: а | B35: Дастлабки гаров ҳуқуқи банкка тегишли бўлмаган кредитлар | I35: =+'Calculation of Risk Weighted As'!I35-'Calculation of Risk Weighte нац'!I35 -> 0
A36: б | B36: Кредитларнинг (микроқарзларнинг) депозит билан таъминланган қисми | D36: =+'Calculation of Risk Weighted As'!D36-'Calculation of Risk Weighte нац'!D36 -> 0 | E36: =+'Calculation of Risk Weighted As'!E36-'Calculation of Risk Weighte нац'!E36 -> 0
A37: в | B37: 2024 йил 1 июлга қадар ажратилган ипотека кредитлари | F37: =+'Calculation of Risk Weighted As'!F37-'Calculation of Risk Weighte нац'!F37 -> 0 | G37: =+'Calculation of Risk Weighted As'!G37-'Calculation of Risk Weighte нац'!G37 -> 0 | I37: =+'Calculation of Risk Weighted As'!I37-'Calculation of Risk Weighte нац'!I37 -> 0 | J37: =+'Calculation of Risk Weighted As'!J37-'Calculation of Risk Weighte нац'!J37 -> 0
A38: г | B38: 2024 йил 1 июлдан бошлаб ажратилган ипотека кредитлари | F38: =+'Calculation of Risk Weighted As'!F38-'Calculation of Risk Weighte нац'!F38 -> 0 | G38: =+'Calculation of Risk Weighted As'!G38-'Calculation of Risk Weighte нац'!G38 -> 0 | I38: =+'Calculation of Risk Weighted As'!I38-'Calculation of Risk Weighte нац'!I38 -> 0 | J38: =+'Calculation of Risk Weighted As'!J38-'Calculation of Risk Weighte нац'!J38 -> 0
A39: д | B39: 2023 йил 20 августга қадар автомобиль сотиб олиш учун ажратилган кредитлар | I39: =+'Calculation of Risk Weighted As'!I39-'Calculation of Risk Weighte нац'!I39 -> 0 | J39: =+'Calculation of Risk Weighted As'!J39-'Calculation of Risk Weighte нац'!J39 -> 0 | K39: =+'Calculation of Risk Weighted As'!K39-'Calculation of Risk Weighte нац'!K39 -> 0
A40: е | B40: 2023 йил 20 августдан бошлаб 2024 йил 1 июлга қадар жисмоний шахсларга автомобиль сотиб олиш учун ажратилган кредитлар | I40: =+'Calculation of Risk Weighted As'!I40-'Calculation of Risk Weighte нац'!I40 -> 0 | J40: =+'Calculation of Risk Weighted As'!J40-'Calculation of Risk Weighte нац'!J40 -> 0 | K40: =+'Calculation of Risk Weighted As'!K40-'Calculation of Risk Weighte нац'!K40 -> 0
...

Sheet Calculation of Risk
A1: ОПЕРАЦИОН ВА БОЗОР ТАВАККАЛЧИЛИКЛАРИ ҲИСОБ-КИТОБИ | C1: 6а-жадвал
B2: =IF(C3>0," "&TEXT(C3,"гггг"),"Число,Месяц,Год") -> 2025
B3: =+'Bank Capital Calc'!B3 -> MKBANK | C3: =+'Bank Capital Calc'!C3 -> 46021
A4: № | B4: Кўрсаткичлар номи | C4: минг сўмда
A5: 1. | B5: =+""&(D$6-3)&" йилдаги банкнинг ялпи даромади" -> 2022 йилдаги банкнинг ялпи даромади | C5: =+C6+C8-C7-C9 -> 1287894464
A6: а. | B6: фоизли даромад | C6: 2589031954 | D6: =+B2 -> 2025 | E6: 13
A7: б. | B7: фоизли харажат | C7: 1758289358
A8: в. | B8: фоизсиз даромад | C8: 886968966
A9: г. | B9: фоизсиз харажат | C9: 429817098
A10: 2. | B10: =+""&(D$6-2)&" йилдаги банкнинг ялпи даромади" -> 2023 йилдаги банкнинг ялпи даромади | C10: =+C11+C13-C12-C14 -> 1322545992
A11: а. | B11: фоизли даромад | C11: 3219716484
A12: б. | B12: фоизли харажат | C12: 2475830862
A13: в. | B13: фоизсиз даромад | C13: 1479529469
A14: г. | B14: фоизсиз харажат | C14: 900869099
A15: 3. | B15: =+""&(D$6-1)&" йилдаги банкнинг ялпи даромади" -> 2024 йилдаги банкнинг ялпи даромади | C15: =+C16+C18-C17-C19 -> 1265205603
A16: а. | B16: фоизли даромад | C16: 4027791395
A17: б. | B17: фоизли харажат | C17: 3239799931
A18: в. | B18: фоизсиз даромад | C18: 1228713951
A19: г. | B19: фоизсиз харажат | C19: 751499812
A20: 4. | B20: Банкнинг ўртача ялпи даромади (оҳирги уч йил давомида) | C20: =(C5+C10+C15)/3 -> 1.291882e+09
A21: 5. | B21: Операцион таваккалчиликлар қиймати | C21: =+(100/C28)*C20*15% -> 1.4906331e+09
A23: 6. | B23: Валюта позицияси ҳисобварақлари | C23: 9167292 | E23: сўм қисми
A24: 7. | B24: Кўзда тутилмаган ҳолатлар бўйича талаблар | C24: 0 | D24: 92503, 92705, 92716, 92717, 92728, 92732 | E24: чет эл валютасидаги қолдиқларининг эквиваленти
A25: 8. | B25: Кўзда тутилмаган ҳолатлар бўйича мажбуриятлар | C25: 0 | D25: 92501, 92701, 92709, 92710, 92724, 92736 | E25: чет эл валютасидаги қолдиқларининг эквиваленти
A26: 9. | B26: Очиқ валюта позицияси, жами | C26: =ABS(C23+(C24-C25)) -> 9167292 | D26: =+C26*0.1 -> 916729.2
A27: 10. | B27: Бозор таваккалчилиги суммаси | C27: =+(100/C28)*(C26*10%) -> 7051763.1
A28: 11. | B28: Капитал монандлигига бўлган амалдаги минимал талаб | C28: =VLOOKUP($D$6,$D$6:$E$6,2,0) -> 13
B30: Бошқарув Раис имзоси:
B32: Бош бухгалтер имзоси:
