Workbook
Name RISKTOTASS: SUM('[6]Calculation of Risk Weighted As'!$C$38:$F$38)
Name RISKTOTASS: SUM('[7]Calculation of Risk Weighted As'!$C$41:$G$41)

Sheet Asset quality
A1: АКТИВЛАР ТАСНИФИ ВА УЛАР БЎЙИЧА ЯРАТИЛГАН ЭҲТИМОЛИЙ ЙЎҚОТИШЛАРНИ ҚОПЛАШ ЗАХИРАЛАРИ ТЎҒРИСИДА ҲИСОБОТ | S1: 2-жадвал | V1: №2
B3: MKBANK | Q3: 46021 | T3: минг. сўмда
A4: № | B4: Активлар таркиби* | C4: Қолдиқ | D4: Сифат тоифаси | I4: Муддати ўтган қарздорлик (брутто) | O4: Зарарларни қоплаш захираси
I5: Жами | J5: 30 кунгача | K5: 31дан 90 кунгача | L5: 91дан 180 кунгача | M5: 181 дан 365 кунгача | N5: 366 кун ва ундан ортиқ | O5: ҳақиқатдан яратилган захиралар
O6: Жами | P6: сифат тоифаси бўйича
D7: I | E7: II | F7: III | G7: IV | H7: V | P7: I | Q7: II | R7: III | S7: IV | T7: V
A8: А | B8: Б | C8: В | D8: Г | E8: Д | F8: Е | G8: Ж | H8: З | I8: И | J8: К | K8: Л | L8: М | M8: Н | N8: О | O8: П | P8: Р | Q8: С | R8: Т | S8: У | T8: Ф
B9: Жами активлар | C9: =SUM(C10:C58)+C60-C59 -> 30728787180 | D9: =SUM(D10:D58)-D59+D60 -> 26949179754 | E9: =SUM(E10:E58)-E59+E60 -> 2058382184 | F9: =SUM(F10:F58)-F59+F60 -> 338634441 | G9: =SUM(G10:G58)-G59+G60 -> 768752525 | H9: =SUM(H10:H58)-H59+H60 -> 802744728 | I9: =SUM(I10:I60) -> 798938437 | J9: =SUM(J10:J60) -> 57876232 | K9: =SUM(K10:K60) -> 175356163 | L9: =SUM(L10:L60) -> 67914859 | M9: =SUM(M10:M60) -> 102226018 | N9: =SUM(N10:N60) -> 395565165 | O9: =SUM(O10:O60) -> 312280487 | P9: =SUM(P10:P60) -> 123374035 | ... T9: =SUM(T10:T60) -> 96528964
A10: 1 | B10: Кассадаги нақд пул ва бошқа тўлов ҳужжатлари | C10: =SUM(D10:H10)-O10+P10 -> 703550546 | D10: 703550546 | E10: 0 | F10: 0 | G10: 0 | H10: 0 | I10: =SUM(J10:N10) -> 0 | O10: =SUM(P10:T10) -> 0 | P10: 0 | Q10: 0 | R10: 0 | S10: 0 | T10: 0 | U10: 10100
A11: 2 | B11: Банкнинг Марказий банкдаги маблағлар | C11: =SUM(D11:H11)-O11+P11 -> 584034134 | D11: 584034134 | E11: 0 | F11: 0 | G11: 0 | H11: 0 | I11: =SUM(J11:N11) -> 0 | O11: =SUM(P11:T11) -> 0 | P11: 0 | Q11: 0 | R11: 0 | S11: 0 | T11: 0 | U11: 10300
A12: 3 | B12: Бошқа банклар ва молиявий ташкилотлардан олиниши лозим бўлган маблағлар | C12: =SUM(D12:H12)-O12+P12 -> 3466881057 | D12: 3466881057 | E12: 0 | F12: 0 | G12: 0 | H12: 0 | I12: =SUM(J12:N12) -> 0 | O12: =SUM(P12:T12) -> 0 | P12: 0 | Q12: 0 | R12: 0 | S12: 0 | T12: 0 | U12: 10500
A13: 4 | B13: Фойда ёки зарар орқали ҳаққоний қийматда баҳоланадиган қимматли қоғозлар | C13: =SUM(D13:H13)-O13+P13 -> 508169320 | D13: 508169320 | E13: 0 | F13: 0 | G13: 0 | H13: 0 | I13: =SUM(J13:N13) -> 0 | O13: =SUM(P13:T13) -> 0 | P13: 0 | Q13: 0 | R13: 0 | S13: 0 | T13: 0 | U13: 10700
A14: 5 | B14: Бошқа умумлашган даромад орқали ҳаққоний қийматда баҳоланадиган қимматли қоғозларга қилинган инвестициялар | C14: =SUM(D14:H14)-O14+P14 -> 10000000 | D14: 10000000 | E14: 0 | F14: 0 | G14: 0 | H14: 0 | I14: =SUM(J14:N14) -> 0 | O14: =SUM(P14:T14) -> 0 | P14: 0 | Q14: 0 | R14: 0 | S14: 0 | T14: 0 | U14: 10800
A15: 6 | B15: Олди-сотдига мўлжалланган қимматбаҳо металлар, тошлар ва тангалар | C15: =SUM(D15:H15)-O15+P15 -> 175 | D15: 175 | E15: 0 | F15: 0 | G15: 0 | H15: 0 | I15: =SUM(J15:N15) -> 0 | O15: =SUM(P15:T15) -> 0 | P15: 0 | Q15: 0 | R15: 0 | S15: 0 | T15: 0 | U15: 10900
A16: 7 | B16: Сотиб олинган дебиторлик қарзлари — Факторинг | C16: =SUM(D16:H16)-O16+P16 -> 316939901 | D16: 313277456 | E16: 3662445 | F16: 0 | G16: 0 | H16: 0 | I16: =SUM(J16:N16) -> 17295876 | J16: 2836334 | K16: 10207771 | L16: 3291628 | M16: 960143 | N16: 0 | O16: =SUM(P16:T16) -> 739490 | P16: 739490 | Q16: 0 | R16: 0 | S16: 0 | T16: 0 | U16: 11100
A17: 8 | B17: Мижозларнинг аккредитив ва/ёки траст ҳужжатлари билан кафолатланган тратталари бўйича мажбуриятлари | C17: =SUM(D17:H17)-O17+P17 -> 38191497 | D17: 38191497 | E17: 0 | F17: 0 | G17: 0 | H17: 0 | I17: =SUM(J17:N17) -> 0 | J17: 0 | K17: 0 | L17: 0 | M17: 0 | N17: 0 | O17: =SUM(P17:T17) -> 0 | U17: 11500
A18: 9 | B18: Банкнинг тўланмаган акцептлари бўйича мижозларнинг мажбуриятлари | C18: =SUM(D18:H18)-O18+P18 -> 0 | D18: 0 | E18: 0 | F18: 0 | G18: 0 | H18: 0 | I18: =SUM(J18:N18) -> 0 | J18: 0 | K18: 0 | L18: 0 | M18: 0 | N18: 0 | O18: =SUM(P18:T18) -> 0 | U18: 11700
A19: 10 | B19: РЕПО битимлари бўйича сотиб олинган қимматли қоғозлар | C19: =SUM(D19:H19)-O19+P19 -> 0 | D19: 0 | E19: 0 | F19: 0 | G19: 0 | H19: 0 | I19: =SUM(J19:N19) -> 0 | J19: 0 | K19: 0 | L19: 0 | M19: 0 | N19: 0 | O19: =SUM(P19:T19) -> 0 | U19: 11800
A20: 11 | B20: Марказий банкка берилган қисқа муддатли кредитлар | C20: =SUM(D20:H20)-O20+P20 -> 0 | D20: 0 | E20: 0 | F20: 0 | G20: 0 | H20: 0 | I20: =SUM(J20:N20) -> 0 | J20: 0 | K20: 0 | L20: 0 | M20: 0 | N20: 0 | O20: =SUM(P20:T20) -> 0 | U20: 11900
A21: 12 | B21: Бошқа банкларга берилган қисқа муддатли кредитлар | C21: =SUM(D21:H21)-O21+P21 -> 0 | D21: 0 | E21: 0 | F21: 0 | G21: 0 | H21: 0 | I21: =SUM(J21:N21) -> 0 | J21: 0 | K21: 0 | L21: 0 | M21: 0 | N21: 0 | O21: =SUM(P21:T21) -> 0 | U21: 12100
A22: 13 | B22: Ҳукуматга берилган қисқа муддатли кредитлар | C22: =SUM(D22:H22)-O22+P22 -> 0 | D22: 0 | E22: 0 | F22: 0 | G22: 0 | H22: 0 | I22: =SUM(J22:N22) -> 0 | J22: 0 | K22: 0 | L22: 0 | M22: 0 | N22: 0 | O22: =SUM(P22:T22) -> 0 | U22: 12300
A23: 14 | B23: Бюджет ташкилотларига берилган қисқа муддатли кредитлар | C23: =SUM(D23:H23)-O23+P23 -> 0 | D23: 0 | E23: 0 | F23: 0 | G23: 0 | H23: 0 | I23: =SUM(J23:N23) -> 0 | J23: 0 | K23: 0 | L23: 0 | M23: 0 | N23: 0 | O23: =SUM(P23:T23) -> 0 | U23: 12400
A24: 15 | B24: Жисмоний шахсларга берилган қисқа муддатли кредитлар | C24: =SUM(D24:H24)-O24+P24 -> 288868264 | D24: 46959486 | E24: 54118027 | F24: 55773811 | G24: 59803354 | H24: 72300689 | I24: =SUM(J24:N24) -> 6344634 | J24: 173866 | K24: 844828 | L24: 441327 | M24: 736406 | N24: 4148207 | O24: =SUM(P24:T24) -> 470082 | P24: 382979 | Q24: 42102 | R24: 28991 | S24: 10900 | T24: 5110 | U24: 12500
A25: 16 | B25: Якка тартибдаги тадбиркорларга берилган қисқа муддатли кредитлар | C25: =SUM(D25:H25)-O25+P25 -> 23250199 | D25: 13803502 | E25: 4261147 | F25: 670535 | G25: 1273145 | H25: 3401166 | I25: =SUM(J25:N25) -> 727333 | J25: 11278 | K25: 66344 | L25: 13017 | M25: 43089 | N25: 593605 | O25: =SUM(P25:T25) -> 300461 | P25: 141165 | Q25: 5256 | R25: 0 | S25: 0 | T25: 154040 | U25: 12600
A26: 17 | B26: Давлат корхоналари, ташкилотлари ва муассасаларига берилган қисқа муддатли кредитлар | C26: =SUM(D26:H26)-O26+P26 -> 28334386 | D26: 19676174 | E26: 0 | F26: 8658212 | G26: 0 | H26: 0 | I26: =SUM(J26:N26) -> 0 | J26: 0 | K26: 0 | L26: 0 | M26: 0 | N26: 0 | O26: =SUM(P26:T26) -> 3853 | P26: 3853 | Q26: 0 | R26: 0 | S26: 0 | T26: 0 | U26: 12700
A27: 18 | B27: Тадбиркорлик фаолиятини қўллаб-қувватлаш давлат жамғармаси кўмагида берилган қисқа муддатли кредитлар | C27: =SUM(D27:H27)-O27+P27 -> 0 | D27: 0 | E27: 0 | F27: 0 | G27: 0 | H27: 0 | I27: =SUM(J27:N27) -> 0 | O27: =SUM(P27:T27) -> 0 | P27: 0 | Q27: 0 | R27: 0 | S27: 0 | T27: 0 | U27: 12800
A28: 19 | B28: Чет эл капитали иштирокидаги корхоналарга берилган қисқа муддатли кредитлар | C28: =SUM(D28:H28)-O28+P28 -> 13707566 | D28: 8016879 | E28: 5013058 | F28: 0 | G28: 74778 | H28: 602851 | I28: =SUM(J28:N28) -> 0 | J28: 0 | K28: 0 | L28: 0 | M28: 0 | N28: 0 | O28: =SUM(P28:T28) -> 0 | P28: 0 | Q28: 0 | R28: 0 | S28: 0 | T28: 0 | U28: 12900
A29: 20 | B29: Нодавлат нотижорат ташкилотларига берилган қисқа муддатли кредитлар | C29: =SUM(D29:H29)-O29+P29 -> 63030 | D29: 63030 | E29: 0 | F29: 0 | G29: 0 | H29: 0 | I29: =SUM(J29:N29) -> 0 | J29: 0 | K29: 0 | L29: 0 | M29: 0 | N29: 0 | O29: =SUM(P29:T29) -> 364 | P29: 364 | Q29: 0 | R29: 0 | S29: 0 | T29: 0 | U29: 13000
A30: 21 | B30: Хусусий корхоналар, хўжалик ширкатлари ва жамиятларга берилган қисқа муддатли кредитлар | C30: =SUM(D30:H30)-O30+P30 -> 974736697 | D30: 610647453 | E30: 113823681 | F30: 12320480 | G30: 153127608 | H30: 90064314 | I30: =SUM(J30:N30) -> 20700370 | J30: 519010 | K30: 2648771 | L30: 305637 | M30: 4225954 | N30: 13000998 | O30: =SUM(P30:T30) -> 6198235 | P30: 951396 | Q30: 110814 | R30: 0 | S30: 2483632 | T30: 2652393 | U30: 13100
A31: 22 | B31: Банк бўлмаган молиявий муассасаларга берилган қисқа муддатли кредитлар | C31: =SUM(D31:H31)-O31+P31 -> 5000000 | D31: 5000000 | E31: 0 | F31: 0 | G31: 0 | H31: 0 | I31: =SUM(J31:N31) -> 0 | J31: 0 | K31: 0 | L31: 0 | M31: 0 | N31: 0 | O31: =SUM(P31:T31) -> 20000 | P31: 20000 | Q31: 0 | R31: 0 | S31: 0 | T31: 0 | U31: 13200
A32: 23 | B32: Давлат эҳтиёжлари учун харид қилинадиган қишлоқ хўжалиги маҳсулотларини етиштириш учун берилган қисқа муддатли кредитлар | C32: =SUM(D32:H32)-O32+P32 -> 35367443 | D32: 28454671 | E32: 6029304 | F32: 350946 | G32: 532522 | H32: 0 | I32: =SUM(J32:N32) -> 1672764 | J32: 121656 | K32: 998498 | L32: 489166 | M32: 0 | N32: 63444 | O32: =SUM(P32:T32) -> 296110 | P32: 296110 | Q32: 0 | R32: 0 | S32: 0 | T32: 0 | U32: 13300
A33: 24 | B33: Давлат эҳтиёжлари учун харид қилинадиган қишлоқ хўжалиги маҳсулотларини етиштириш учун берилган узоқ муддатли кредитлар | C33: =SUM(D33:H33)-O33+P33 -> 13446162 | D33: 13732792 | E33: 327166 | F33: 0 | G33: 0 | H33: 0 | I33: =SUM(J33:N33) -> 5755944 | J33: 0 | K33: 0 | L33: 3104992 | M33: 2650952 | N33: 0 | O33: =SUM(P33:T33) -> 811955 | P33: 198159 | Q33: 613796 | R33: 0 | S33: 0 | T33: 0 | U33: 14300
A34: 25 | B34: Тадбиркорлик фаолиятини қўллаб-қувватлаш давлат жамғармаси кўмагида берилган узоқ муддатли кредитлар | C34: =SUM(D34:H34)-O34+P34 -> 66976461 | D34: 63180329 | E34: 938508 | F34: 0 | G34: 4222222 | H34: 0 | I34: =SUM(J34:N34) -> 3765742 | J34: 56225 | K34: 911912 | L34: 264559 | M34: 209356 | N34: 2323690 | O34: =SUM(P34:T34) -> 1498952 | P34: 134354 | Q34: 0 | R34: 0 | S34: 829566 | T34: 535032 | U34: 14400
A35: 26 | B35: Бошқа банкларга берилган узоқ муддатли кредитлар | C35: =SUM(D35:H35)-O35+P35 -> 0 | D35: 0 | E35: 0 | F35: 0 | G35: 0 | H35: 0 | I35: =SUM(J35:N35) -> 0 | O35: =SUM(P35:T35) -> 0 | P35: 0 | Q35: 0 | R35: 0 | S35: 0 | T35: 0 | U35: 14500
A36: 27 | B36: Ҳукуматга берилган узоқ муддатли кредитлар | C36: =SUM(D36:H36)-O36+P36 -> 0 | D36: 0 | E36: 0 | F36: 0 | G36: 0 | H36: 0 | I36: =SUM(J36:N36) -> 0 | O36: =SUM(P36:T36) -> 0 | P36: 0 | Q36: 0 | R36: 0 | S36: 0 | T36: 0 | U36: 14700
A37: 28 | B37: Бюджет ташкилотларига берилган узоқ муддатли кредитлар | C37: =SUM(D37:H37)-O37+P37 -> 0 | D37: 0 | E37: 0 | F37: 0 | G37: 0 | H37: 0 | I37: =SUM(J37:N37) -> 0 | O37: =SUM(P37:T37) -> 0 | P37: 0 | Q37: 0 | R37: 0 | S37: 0 | T37: 0 | U37: 14800
A38: 29 | B38: Жисмоний шахсларга берилган узоқ муддатли кредитлар | C38: =SUM(D38:H38)-O38+P38 -> 8117618124 | D38: 7019070951 | E38: 891855355 | F38: 116902770 | G38: 49497828 | H38: 49218249 | I38: =SUM(J38:N38) -> 252593173 | J38: 11416967 | K38: 59536088 | L38: 16477746 | M38: 47560275 | N38: 117602097 | O38: =SUM(P38:T38) -> 92735728 | P38: 83808699 | Q38: 5646748 | R38: 2111145 | S38: 822978 | T38: 346158 | U38: 14900
A39: 30 | B39: Якка тартибдаги тадбиркорларга берилган узоқ муддатли кредитлар | C39: =SUM(D39:H39)-O39+P39 -> 766807801 | D39: 572177119 | E39: 188722113 | F39: 1678739 | G39: 2554602 | H39: 3430650 | I39: =SUM(J39:N39) -> 9341336 | J39: 381635 | K39: 3455537 | L39: 612214 | M39: 1083013 | N39: 3808937 | O39: =SUM(P39:T39) -> 9536337 | P39: 7780915 | Q39: 615101 | R39: 3453 | S39: 433 | T39: 1136435 | U39: 15000
A40: 31 | B40: Давлат корхоналари, ташкилотлари ва муассасаларига берилган узоқ муддатли кредитлар | C40: =SUM(D40:H40)-O40+P40 -> 239866103 | D40: 239866103 | E40: 0 | F40: 0 | G40: 0 | H40: 0 | I40: =SUM(J40:N40) -> 28109740 | J40: 19112125 | K40: 339403 | L40: 0 | M40: 8658212 | N40: 0 | O40: =SUM(P40:T40) -> 78666 | P40: 78666 | Q40: 0 | R40: 0 | S40: 0 | T40: 0 | U40: 15100
A41: 32 | B41: Нодавлат нотижорат ташкилотларига берилган узоқ муддатли кредитлар | C41: =SUM(D41:H41)-O41+P41 -> 3772042 | D41: 3772042 | E41: 0 | F41: 0 | G41: 0 | H41: 0 | I41: =SUM(J41:N41) -> 26667 | J41: 26667 | K41: 0 | L41: 0 | M41: 0 | N41: 0 | O41: =SUM(P41:T41) -> 37987 | P41: 37987 | Q41: 0 | R41: 0 | S41: 0 | T41: 0 | U41: 15200
...

Sheet Income 
A1: МОЛИЯВИЙ НАТИЖАЛАР ТЎҒРИСИДА ҲИСОБОТ | E1: 3-жадвал
B3: =+'Asset quality'!B3 -> MKBANK | D3: =+'Asset quality'!Q3 -> 46021 | E3: =+'Asset quality'!T3 -> минг. сўмда
A4: № | B4: Кўрсаткичлар | C4: Жами | D4: миллий валютада | E4: хорижий валютада (экв. сўмда)
A5: 1. | B5: ФОИЗЛИ ДАРОМАДЛАР
A6: a. | B6: Марказий банкдаги ҳисобварақлар бўйича фоизли даромадлар | C6: =+D6+E6 -> 23192521 | D6: 23192521 | E6: 0 | G6: =+'Analysis of Interest'!C17 -> 23192521
A7: б. | B7: Бошқа банклардаги ҳисобварақлар бўйича фоизли даромадлар | C7: =+D7+E7 -> 73993010 | D7: 9263965 | E7: 64729045 | G7: =+'Analysis of Interest'!C18 -> 73993010
A8: в. | B8: Амортизацияланган қиймати бўйича баҳоланадиган қарз қимматли қоғозларга қилинган инвестициялар бўйича фоизли даромадлар | C8: =+D8+E8 -> 0 | D8: 0 | E8: 0
A9: г. | B9: Қимматли қоғозлар ва уларга қилинган инвестициялар бўйича фоизли даромадлар | C9: =+D9+E9 -> 40706058 | D9: 40706058 | E9: 0 | G9: =+'Analysis of Interest'!C28 -> 40706058
A10: д. | B10: Мижозларнинг мажбуриятлари бўйича ҳисобланган фоизлар | C10: =+D10+E10 -> 0 | D10: 0 | E10: 0
A11: е. | B11: Банкнинг тўланмаган акцептлари юзасидан мижозлар мажбуриятлари бўйича фоизли даромадлар | C11: =+D11+E11 -> 0 | D11: 0 | E11: 0
A12: ж. | B12: Кредит ва лизинг операциялари бўйича фоизлар, дисконтлар (чегирмалар) ва бадаллар | C12: =+D12+E12 -> 3389629534 | D12: 2963318225 | E12: 426311309 | G12: =+'Analysis of Interest'!C14 -> 3389629534
A13: з. | B13: Қимматли қоғозлар билан амалга оширилган РЕПО битимлари бўйича фоизли даромадлар | C13: =+D13+E13 -> 0 | D13: 0 | E13: 0 | G13: =+'Analysis of Interest'!C39 -> 0
A14: и. | B14: Бошқа фоизли даромадлар | C14: =+D14+E14 -> 1773738283 | D14: 1605058975 | E14: 168679308 | G14: =+'Analysis of Interest'!C40 -> 1773738283
A15: к. | B15: Жами фоизли даромадлар | C15: =SUM(C6:C14) -> 5301259406 | D15: =SUM(D6:D14) -> 4641539744 | E15: =SUM(E6:E14) -> 659719662 | G15: =+'Analysis of Interest'!C42 -> 5301259406
A17: 2. | B17: ФОИЗЛИ ХAРAЖAТЛAР
A18: а. | B18: Талаб қилиб олингунча сақланадиган депозитлар бўйича фоизли харажатлар | C18: =+D18+E18 -> 14389513 | D18: 14389513 | E18: 0 | G18: =+'Analysis of Interest'!C52 -> 14389513
A19: б. | B19: Муддатли депозитлар бўйича фоизли харажатлар | C19: =+D19+E19 -> 1370099872 | D19: 1325792304 | E19: 44307568 | G19: =+'Analysis of Interest'!C61 -> 1370099872
A20: в. | B20: Марказий банкнинг ҳисобварақлари бўйича фоизли харажатлар | C20: =+D20+E20 -> 0 | D20: 0 | E20: 0
A21: г. | B21: Бошқа банкларнинг ҳисобварақлари бўйича фоизли харажатлар | C21: =+D21+E21 -> 157366850 | D21: 144714807 | E21: 12652043
A22: д. | B22: Жами депозитлар бўйича фоизли харажатлар | C22: =SUM(C18:C21) -> 1541856235 | D22: =SUM(D18:D21) -> 1484896624 | E22: =SUM(E18:E21) -> 56959611
A23: е. | B23: Кредитлар бўйича фоизли харажатлар | C23: =+D23+E23 -> 1155174509 | D23: 710518517 | E23: 444655992 | G23: =+'Analysis of Interest'!C67 -> 1155174509
A24: ж. | B24: Қимматли қоғозлар билан амалга оширилган РЕПО битимлари бўйича фоизли харажатлар | C24: =+D24+E24 -> 0 | D24: 0 | E24: 0 | G24: =+'Analysis of Interest'!C68 -> 0
A25: з. | B25: Бошқа фоизли харажатлар | C25: =+D25+E25 -> 1843001988 | D25: 1700157973 | E25: 142844015
A26: и. | B26: Жами кредит ва бошқа қарздорликлар бўйича фоизли харажатлар | C26: =SUM(C23:C25) -> 2998176497 | D26: =SUM(D23:D25) -> 2410676490 | E26: =SUM(E23:E25) -> 587500007
A27: к. | B27: Жами фоизли харажатлар | C27: =C26+C22 -> 4540032732 | D27: =D26+D22 -> 3895573114 | E27: =E26+E22 -> 644459618 | G27: =+'Analysis of Interest'!C72 -> 4540032732
A29: 3. | B29: Активлар бўйича эҳтимолий йўқотишларга қарши яратилган захираларни баҳолашдан олдинги соф даромад | C29: =C15-C27 -> 761226674 | D29: =D15-D27 -> 745966630 | E29: =E15-E27 -> 15260044
A30: а. | B30: Минус: Кредит ва лизинглар бўйича кўрилиши мумкин бўлган зарарларни баҳолаш | C30: =+D30+E30 -> 400806350 | D30: 301565942 | E30: 99240408
A31: б. | B31: Минус: Қимматли қоғозлар бўйича кўрилиши мумкин бўлган зарарларни баҳолаш | C31: =+D31+E31 -> 0 | D31: 0 | E31: 0
A32: в. | B32: Минус: Инвестициялар бўйича кўрилиши мумкин бўлган зарарларни баҳолаш | C32: =+D32+E32 -> 0 | D32: 0 | E32: 0
A33: г. | B33: Минус: Бошқа активлар бўйича кўрилиши мумкин бўлган зарарларни баҳолаш | C33: =+D33+E33 -> 23688414 | D33: 23688414
A34: д. | B34: Активлар бўйича эҳтимолий зарарларни баҳолашдан кейинги соф даромад | C34: =C29-C30-C31-C32-C33 -> 336731910 | D34: =D29-D30-D31-D32-D33 -> 420712274 | E34: =E29-E30-E31-E32-E33 -> -83980364
A36: 4. | B36: ФОИЗСИЗ ДАРОМАДЛАР
A37: а. | B37: Кўрсатилган хизматлар ва воситачилик учун олинган даромадлар | C37: =+D37+E37 -> 337123005 | D37: 302049173 | E37: 35073832
A38: б. | B38: Хорижий валюталардаги фойда | C38: =+D38+E38 -> 372949273 | D38: 319454996 | E38: 53494277
A39: в. | B39: Тижорат операцияларидан олинган фойда | C39: =+D39+E39 -> 0 | D39: 0 | E39: 0
A40: г. | B40: Инвестициядан олинган фойда ва дивидендлар | C40: =+D40+E40 -> 6577763 | D40: 6577763 | E40: 0
A41: д. | B41: Активлар бўйича эҳтимолий йўқотишларга қарши яратилган захираларнинг қайтарилиши | C41: =+D41+E41 -> 4246910 | D41: 4246910 | E41: 0
A42: е. | B42: Ҳисобдан чиқарилган кредитлар қайтарилиши билан боғлиқ даромадлар | C42: =+D42+E42 -> 606560308 | D42: 420298731 | E42: 186261577
A43: ж. | B43: Бошқа фоизсиз даромадлар | C43: =+D43+E43 -> 98963266 | D43: 98963266 | E43: 0
A44: з. | B44: Жами фоизсиз даромадлар | C44: =SUM(C37:C43) -> 1426420525 | D44: =SUM(D37:D43) -> 1151590839 | E44: =SUM(E37:E43) -> 274829686
...

Sheet Analysis of Interest
B1: ФОИЗЛИ ДАРОМАД ВА ХАРАЖАТЛАР ТАҲЛИЛИ | C1: 4-жадвал
B3: =+'Asset quality'!B3 -> MKBANK | C3: =+'Asset quality'!Q3 -> 46021
A4: № | B4: Кўрсаткичлар | C4: =+'Asset quality'!T3 -> минг. сўмда
A5: 1. | B5: КРЕДИТ ВА ЛИЗИНГ ОПЕРАЦИЯЛАРИ БЎЙИЧА ФОИЗЛИ ДАРОМАДЛАР
A6: a. | B6: Марказий банкка берилган қисқа муддатли кредитлар | C6: 0
A7: б. | B7: Бошқа банкларга берилган кредитлар | C7: 47664
A8: в. | B8: Ҳукуматга берилган кредитлар | C8: 0
A9: г. | B9: Жисмоний шахсларга берилган кредит ва лизинглар | C9: 1598177879
A10: д. | B10: Давлат корхоналарига берилган кредит ва лизинглар | C10: 3839867
A11: е. | B11: Қўшма ва чет эл капитали иштирокидаги корхоналарга берилган кредит ва лизинглар | C11: 11246925
A12: ж. | B12: Хусусий корхоналар, хўжалик ширкатлари ва жамиятларга берилган кредит ва лизинглар | C12: 1636726704
A13: з. | B13: Бошқа кредит ва лизинглар | C13: 139590495
A14: и. | B14: Жами кредит ва лизинг операциялари бўйича фоизли даромад | C14: =SUM(C6:C13) -> 3389629534 | E14: =+'Income '!C12 -> 3389629534
A16: 2. | B16: ВАКИЛЛИК ҲИСОБВАРАҚЛАРИ БЎЙИЧА ФОИЗЛИ ДАРОМАДЛАР
A17: a. | B17: Марказий банкдаги ҳисобварақлар бўйича фоизли даромадлар | C17: 23192521 | E17: =+'Income '!C6 -> 23192521
A18: б. | B18: Бошқа банклардаги ҳисобварақлар бўйича фоизли даромадлар | C18: 73993010 | E18: =+'Income '!C7 -> 73993010
B19: Жами вакиллик ҳисобварағи бўйича фоизли даромадлар | C19: =SUM(C17:C18) -> 97185531
A21: 3. | B21: ҚИММАТЛИ ҚОҒОЗЛАР ВА УЛАРГА ҚИЛИНГАН ИНВЕСТИЦИЯЛАР БЎЙИЧА ФОИЗЛИ ДАРОМАДЛАР
A22: a. | B22: Давлат қимматли қоғозлари | C22: 12725429
A23: б. | B23: Марказий банкнинг облигациялари ва бошқа қимматли қоғозлари | C23: 26080629
A24: в. | B24: Давлат корхоналарининг қарз қимматли қоғозлари бўйича фоизли даромадлар | C24: 1900000
A25: г. | B25: Еврооблигациялар бўйича фоизли даромадлар | C25: 0
A26: д. | B26: Хусусий корхоналарнинг қимматли қоғозлари | C26: 0
A27: е. | B27: Бошқа қимматли қоғозлар | C27: 0
A28: ж. | B28: Жами олди-сотди қимматли қоғозлар бўйича фоизли даромадлар | C28: =SUM(C22:C27) -> 40706058 | E28: =+'Income '!C9 -> 40706058
A30: 4. | B30: ИНВЕСТИЦИЯЛАР БЎЙИЧА ФОИЗЛИ ДАРОМАДЛАР
A31: a. | B31: Давлат қимматли қоғозлари | C31: 0
A32: б. | B32: Марказий банкнинг облигациялари ва бошқа қарз қимматли қоғозларига қилинган инвестициялар бўйича фоизли даромадлар | C32: 0
A33: в. | B33: Корхоналарнинг қарз қимматли қоғозларига қилинган инвестициялар бўйича фоизли даромадлар | C33: 0
A34: г. | B34: Еврооблигациялар | C34: 0
A35: д. | B35: Бошқа қимматли қоғозлар | C35: 0
A36: е. | B36: Жами инвестициялар бўйича фоизли даромадлар | C36: =SUM(C31:C35) -> 0
A38: 5. | B38: БОШҚА ФОИЗЛИ ДАРОМАДЛАР
A39: a. | B39: Қимматли қоғозлар билан амалга оширилган репо битимлари бўйича фоизли даромадлар | C39: 0
A40: б. | B40: Бошқа фоизли даромадлар | C40: 1773738283 | E40: =+'Income '!C14 -> 1773738283
A42: 6. | B42: ЖАМИ ФОИЗЛИ ДАРОМАДЛАР | C42: =C14+C19+C28+C36+C39+C40 -> 5301259406 | E42: =+'Income '!C15 -> 5301259406
A44: 7. | B44: ДЕПОЗИТЛАР БЎЙИЧА ФОИЗЛИ ХАРАЖАТЛАР
A45: A. | B45: Талаб қилиб олингунча сақланадиган депозитлар
A46: a. | B46: Ҳукумат | C46: 0
A47: б. | B47: Жисмоний шахслар | C47: 0
...

Sheet Changes in Equity
A1: ХУСУСИЙ КАПИТАЛДАГИ ЎЗГАРИШЛАР | C1: 7-жадвал
B3: =+'Asset quality'!B3 -> MKBANK | C3: =+'Asset quality'!Q3 -> 46021
A4: № | B4: Кўрсаткичлар | C4: =+'Asset quality'!T3 -> минг. сўмда
A5: 1. | B5: Ўтган йил учун дастлабки ҳисобланган умумий капитал | C5: 3550613724
A6: 2. | B6: Хусусий капиталдаги ўтган йил учун ҳисоботларда кўрсатилмаган тузатишлар, (соф) | C6: 0
A7: 3. | B7: Ўтган календар йили якуни бўйича балансдаги тузатишлар (3=1-2 ) | C7: =SUM(C5:C6) -> 3550613724
A8: 4. | B8: Йил бошидан соф фойда (зарар) | C8: =+'Income '!C77 -> 160802633 | D8: =+[8]Balance!$C$76 -> 160802633 | E8: =+C8-D8 -> 0
A9: 5. | B9: Жорий йилда сотиш, айирбошлаш, сотиб олиш ёки қайтиб сотиб олиш (соф кирим) | C9: 2027852065
A10: 6. | B10: Жорий йил учун бошланғич қийматига нисбатан баҳолаш қийматининг ошган суммаси | C10: -546609
A11: 7. | B11: МИНУС: Имтиёзли акциялар бўйича эълон қилинган пул дивидендлари | C11: 0
A12: 8. | B12: МИНУС: Оддий акциялар бўйича эълон қилинган пуллик дивидендлар | C12: 0
A13: 9. | B13: Жорий йилнинг соф хусусий капиталига таъсир этувчи бошқа моддалар | C13: 489133
A14: 10. | B14: Жорий давр якуни бўйича жами хусусий капитал | C14: =C7+SUM(C8:C10)-SUM(C11:C12)+C13 -> 5739210946 | D14: =+[8]Balance!$C$77 -> 5739210946 | E14: =+C14-D14 -> 0
B16: Бошқарув Раис имзоси:
B18: Бош бухгалтер имзоси:

Sheet Loans Receivable
A1: ИҚТИСОДИЁТ ТАРМОҚЛАРИ, МИЖОЗЛАР ТУРЛАРИ, ВА ТАЪМИНОТ ТУРЛАРИ БЎЙИЧА АЖРАТИЛГАН КРЕДИТЛАР ВА ЛИЗИНГЛАР ҲИСОБОТИ | W1: 8-жадвал
B3: =+'Asset quality'!B3 -> MKBANK | T3: =+'Asset quality'!Q3 -> 46021 | X3: =+'Asset quality'!T3 -> минг. сўмда
A4: № | B4: Иқтисодиёт тармоқлари бўйича | C4: Кредит суммаси | D4: шундан | F4: шундан муаммоли кредитлар | J4: шундан
D5: миллий валютада | E5: хорижий валютада (экв. сўмда) | F5: NPL | G5: шундан | J5: Депозитлар | K5: Ўзбекистон Республикаси Ҳукумати тамонидан кафолатланган кредитлар | L5: шундан | M5: Транспорт воситалари | N5: Инвентарлар | O5: Кўчмас мулк | P5: шундан | R5: Асбоб ускуналар | S5: Векселлар (облигациялар) | T5: Акциялар | U5: Учинчи шахс кафолати | V5: Учинчи шахс кафиллиги | W5: Суғурта полиси | X5: Таъминотсиз | Y5: Бошқа кафолатлар
G6: Қониқарсиз | H6: Шубҳали | I6: Умидсиз | L6: Ўзбекистон Республикаси Ҳукумати томонидан кафолатланган хорижий валютадаги (эквивалент сўмда) кредитлар | P6: турар жой (хонадон) | Q6: тижорат кўчмас мулки
A7: Код | B7: (А) | C7: (Б) | D7: (Б1) | E7: (Б3) | F7: (В) | G7: (В1) | H7: (В2) | I7: (В3) | J7: (Г) | K7: (Д) | L7: (Д1) | M7: (Е) | N7: (Ж) | O7: (З) | P7: (З1) | Q7: (З2) | R7: (И) | S7: (К) | T7: (Л) | U7: (М) | V7: (Н) | W7: (О) | X7: (П) | Y7: (Р)
B8: Саноат
A9: 10 | B9: Давлат корхоналари | C9: =SUM(J9:Y9)-L9-P9-Q9 -> 224140522 | D9: 3964904 | E9: 220175618 | F9: =+G9+H9+I9 -> 8818842 | G9: 8658212 | H9: 160630 | I9: 0 | J9: 0 | K9: 0 | L9: 0 | M9: 1250688 | N9: 0 | O9: =+P9+Q9 -> 220336247 | P9: 160630 | Q9: 220175617 | R9: 0 | S9: 0 | T9: 0 | U9: 0 | V9: 0 | W9: 0 | X9: 0 | Y9: 2553587
A10: =A9+10 -> 20 | B10: Қўшма ва чет эл капитали иштирокидаги корхоналар | C10: =SUM(J10:Y10)-L10-P10-Q10 -> 94705062 | D10: 0 | E10: 94705062 | F10: =+G10+H10+I10 -> 602851 | G10: 0 | H10: 0 | I10: 602851 | J10: 0 | K10: 0 | L10: 0 | M10: 0 | N10: 0 | O10: =+P10+Q10 -> 94705062 | P10: 26736313 | Q10: 67968749 | R10: 0 | S10: 0 | T10: 0 | U10: 0 | V10: 0 | W10: 0 | X10: 0 | Y10: 0
A11: =A10+10 -> 30 | B11: Хусусий корхоналар | C11: =SUM(J11:Y11)-L11-P11-Q11 -> 3611022653 | D11: 2071216518 | E11: 1539806135 | F11: =+G11+H11+I11 -> 144589453 | G11: 17854792 | H11: 92498264 | I11: 34236397 | J11: 0 | K11: 0 | L11: 0 | M11: 63038769 | N11: 0 | O11: =+P11+Q11 -> 1881427097 | P11: 275934216 | Q11: 1605492881 | R11: 0 | S11: 0 | T11: 0 | U11: 0 | V11: 140660096 | W11: 1088319177 | X11: 257946137 | Y11: 179631377
A12: =A11+10 -> 40 | B12: Ҳукумат | C12: =SUM(J12:Y12)-L12-P12-Q12 -> 0 | D12: 0 | E12: 0 | F12: =+G12+H12+I12 -> 0 | G12: 0 | H12: 0 | I12: 0 | J12: 0 | K12: 0 | L12: 0 | M12: 0 | N12: 0 | O12: =+P12+Q12 -> 0 | P12: 0 | Q12: 0 | R12: 0 | S12: 0 | T12: 0 | U12: 0 | V12: 0 | W12: 0 | X12: 0 | Y12: 0
A13: =A12+10 -> 50 | B13: Бошқалар | C13: =SUM(J13:Y13)-L13-P13-Q13 -> 0 | D13: 0 | E13: 0 | F13: =+G13+H13+I13 -> 0 | G13: 0 | H13: 0 | I13: 0 | J13: 0 | K13: 0 | L13: 0 | M13: 0 | N13: 0 | O13: =+P13+Q13 -> 0 | P13: 0 | Q13: 0 | R13: 0 | S13: 0 | T13: 0 | U13: 0 | V13: 0 | W13: 0 | X13: 0 | Y13: 0
A14: =A13+10 -> 60 | B14: Жами | C14: =SUM(J14:Y14)-L14-P14-Q14 -> 3929868237 | D14: =SUM(D9:D13) -> 2075181422 | E14: =SUM(E9:E13) -> 1854686815 | F14: =+G14+H14+I14 -> 154011146 | G14: =SUM(G9:G13) -> 26513004 | H14: =SUM(H9:H13) -> 92658894 | I14: =SUM(I9:I13) -> 34839248 | J14: =SUM(J9:J13) -> 0 | K14: =SUM(K9:K13) -> 0 | L14: =SUM(L9:L13) -> 0 | M14: =SUM(M9:M13) -> 64289457 | N14: =SUM(N9:N13) -> 0 | ... Y14: =SUM(Y9:Y13) -> 182184964
B15: Қишлоқ хўжалиги
A16: 70 | B16: Давлат корхоналари | C16: =SUM(J16:Y16)-L16-P16-Q16 -> 6784810 | D16: 6784810 | E16: 0 | F16: =+G16+H16+I16 -> 0 | G16: 0 | H16: 0 | I16: 0 | J16: 0 | K16: 0 | L16: 0 | M16: 0 | N16: 0 | O16: =+P16+Q16 -> 6784810 | P16: 0 | Q16: 6784810 | R16: 0 | S16: 0 | T16: 0 | U16: 0 | V16: 0 | W16: 0 | X16: 0 | Y16: 0
A17: =A16+10 -> 80 | B17: Қўшма ва чет эл капитали иштирокидаги корхоналар | C17: =SUM(J17:Y17)-L17-P17-Q17 -> 101145756 | D17: 61413116 | E17: 39732640 | F17: =+G17+H17+I17 -> 0 | G17: 0 | H17: 0 | I17: 0 | J17: 0 | K17: 0 | L17: 0 | M17: 0 | N17: 0 | O17: =+P17+Q17 -> 101145756 | P17: 10552370 | Q17: 90593386 | R17: 0 | S17: 0 | T17: 0 | U17: 0 | V17: 0 | W17: 0 | X17: 0 | Y17: 0
A18: =A17+10 -> 90 | B18: Хусусий корхоналар | C18: =SUM(J18:Y18)-L18-P18-Q18 -> 3686671166 | D18: 2744499321 | E18: 942171845 | F18: =+G18+H18+I18 -> 134825507 | G18: 13026886 | H18: 69911550 | I18: 51887071 | J18: 0 | K18: 0 | L18: 0 | M18: 45085291 | N18: 0 | O18: =+P18+Q18 -> 3073924663 | P18: 556452619 | Q18: 2517472044 | R18: 0 | S18: 0 | T18: 0 | U18: 0 | V18: 281280181 | W18: 123907345 | X18: 98122413 | Y18: 64351273
A19: =A18+10 -> 100 | B19: Фермер хўжалиги | C19: =SUM(J19:Y19)-L19-P19-Q19 -> 339848885 | D19: 319019450 | E19: 20829435 | F19: =+G19+H19+I19 -> 24759951 | G19: 4150709 | H19: 13619621 | I19: 6989621 | J19: 0 | K19: 0 | L19: 0 | M19: 6464007 | N19: 0 | O19: =+P19+Q19 -> 260314790 | P19: 57301660 | Q19: 203013130 | R19: 0 | S19: 0 | T19: 0 | U19: 0 | V19: 5224395 | W19: 48231354 | X19: 9414658 | Y19: 10199681
A20: =A19+10 -> 110 | B20: Ҳукумат | C20: =SUM(J20:Y20)-L20-P20-Q20 -> 0 | D20: 0 | E20: 0 | F20: =+G20+H20+I20 -> 0 | G20: 0 | H20: 0 | I20: 0 | J20: 0 | K20: 0 | L20: 0 | M20: 0 | N20: 0 | O20: =+P20+Q20 -> 0 | P20: 0 | Q20: 0 | R20: 0 | S20: 0 | T20: 0 | U20: 0 | V20: 0 | W20: 0 | X20: 0 | Y20: 0
A21: =A20+10 -> 120 | B21: Бошқалар | C21: =SUM(J21:Y21)-L21-P21-Q21 -> 0 | D21: 0 | E21: 0 | F21: =+G21+H21+I21 -> 0 | G21: 0 | H21: 0 | I21: 0 | J21: 0 | K21: 0 | L21: 0 | M21: 0 | N21: 0 | O21: =+P21+Q21 -> 0 | P21: 0 | Q21: 0 | R21: 0 | S21: 0 | T21: 0 | U21: 0 | V21: 0 | W21: 0 | X21: 0 | Y21: 0
A22: =A21+10 -> 130 | B22: Жами | C22: =SUM(J22:Y22)-L22-P22-Q22 -> 4134450617 | D22: =SUM(D16:D21) -> 3131716697 | E22: =SUM(E16:E21) -> 1002733920 | F22: =+G22+H22+I22 -> 159585458 | G22: =SUM(G17:G21) -> 17177595 | H22: =SUM(H17:H21) -> 83531171 | I22: =SUM(I17:I21) -> 58876692 | J22: =SUM(J16:J21) -> 0 | K22: =SUM(K16:K21) -> 0 | L22: =SUM(L16:L21) -> 0 | M22: =SUM(M16:M21) -> 51549298 | N22: =SUM(N16:N21) -> 0 | O22: =SUM(O16:O21) -> 3442170019 | P22: =SUM(P16:P21) -> 624306649 | Q22: =SUM(Q16:Q21) -> 2817863370 | ... Y22: =SUM(Y16:Y21) -> 74550954
B23: Транспорт ва коммуникация
A24: 140 | B24: Давлат корхоналари | C24: =SUM(J24:Y24)-L24-P24-Q24 -> 0 | D24: 0 | E24: 0 | F24: =+G24+H24+I24 -> 0 | G24: 0 | H24: 0 | I24: 0 | J24: 0 | K24: 0 | L24: 0 | M24: 0 | N24: 0 | O24: =+P24+Q24 -> 0 | P24: 0 | Q24: 0 | R24: 0 | S24: 0 | T24: 0 | U24: 0 | V24: 0 | W24: 0 | X24: 0 | Y24: 0
A25: =A24+10 -> 150 | B25: Қўшма ва чет эл капитали иштирокидаги корхоналар | C25: =SUM(J25:Y25)-L25-P25-Q25 -> 3631752 | D25: 0 | E25: 3631752 | F25: =+G25+H25+I25 -> 0 | G25: 0 | H25: 0 | I25: 0 | J25: 0 | K25: 0 | L25: 0 | M25: 3631752 | N25: 0 | O25: =+P25+Q25 -> 0 | P25: 0 | Q25: 0 | R25: 0 | S25: 0 | T25: 0 | U25: 0 | V25: 0 | W25: 0 | X25: 0 | Y25: 0
A26: =A25+10 -> 160 | B26: Хусусий корхоналар | C26: =SUM(J26:Y26)-L26-P26-Q26 -> 252295118 | D26: 227387556 | E26: 24907562 | F26: =+G26+H26+I26 -> 6941489 | G26: 49614 | H26: 2419059 | I26: 4472816 | J26: 0 | K26: 0 | L26: 0 | M26: 31365097 | N26: 0 | O26: =+P26+Q26 -> 205195745 | P26: 48218029 | Q26: 156977716 | R26: 0 | S26: 0 | T26: 0 | U26: 0 | V26: 2993794 | W26: 659373 | X26: 7848056 | Y26: 4233053
A27: =A26+10 -> 170 | B27: Ҳукумат | C27: =SUM(J27:Y27)-L27-P27-Q27 -> 0 | D27: 0 | E27: 0 | F27: =+G27+H27+I27 -> 0 | G27: 0 | H27: 0 | I27: 0 | J27: 0 | K27: 0 | L27: 0 | M27: 0 | N27: 0 | O27: =+P27+Q27 -> 0 | P27: 0 | Q27: 0 | R27: 0 | S27: 0 | T27: 0 | U27: 0 | V27: 0 | W27: 0 | X27: 0 | Y27: 0
A28: =A27+10 -> 180 | B28: Бошқалар | C28: =SUM(J28:Y28)-L28-P28-Q28 -> 0 | D28: 0 | E28: 0 | F28: =+G28+H28+I28 -> 0 | G28: 0 | H28: 0 | I28: 0 | J28: 0 | K28: 0 | L28: 0 | M28: 0 | N28: 0 | O28: =+P28+Q28 -> 0 | P28: 0 | Q28: 0 | R28: 0 | S28: 0 | T28: 0 | U28: 0 | V28: 0 | W28: 0 | X28: 0 | Y28: 0
A29: =A28+10 -> 190 | B29: Жами | C29: =SUM(J29:Y29)-L29-P29-Q29 -> 255926870 | D29: =SUM(D24:D28) -> 227387556 | E29: =SUM(E24:E28) -> 28539314 | F29: =+G29+H29+I29 -> 6941489 | G29: =SUM(G24:G28) -> 49614 | H29: =SUM(H24:H28) -> 2419059 | I29: =SUM(I24:I28) -> 4472816 | J29: =SUM(J24:J28) -> 0 | K29: =SUM(K24:K28) -> 0 | L29: =SUM(L24:L28) -> 0 | M29: =SUM(M24:M28) -> 34996849 | N29: =SUM(N24:N28) -> 0 | ... Y29: =SUM(Y24:Y28) -> 4233053
B30: Қурилиш соҳаси
A31: 200 | B31: Давлат корхоналари | C31: =SUM(J31:Y31)-L31-P31-Q31 -> 2060681 | D31: 2060681 | E31: 0 | F31: =+G31+H31+I31 -> 0 | G31: 0 | H31: 0 | I31: 0 | J31: 0 | K31: 0 | L31: 0 | M31: 0 | N31: 0 | O31: =+P31+Q31 -> 1000000 | P31: 0 | Q31: 1000000 | R31: 0 | S31: 0 | T31: 0 | U31: 0 | V31: 0 | W31: 0 | X31: 0 | Y31: 1060681
A32: =A31+10 -> 210 | B32: Қўшма ва чет эл капитали иштирокидаги корхоналар | C32: =SUM(J32:Y32)-L32-P32-Q32 -> 0 | D32: 0 | E32: 0 | F32: =+G32+H32+I32 -> 0 | G32: 0 | H32: 0 | I32: 0 | J32: 0 | K32: 0 | L32: 0 | M32: 0 | N32: 0 | O32: =+P32+Q32 -> 0 | P32: 0 | Q32: 0 | R32: 0 | S32: 0 | T32: 0 | U32: 0 | V32: 0 | W32: 0 | X32: 0 | Y32: 0
A33: =A32+10 -> 220 | B33: Хусусий корхоналар | C33: =SUM(J33:Y33)-L33-P33-Q33 -> 1318906219 | D33: 787977240 | E33: 530928979 | F33: =+G33+H33+I33 -> 19809453 | G33: 1092783 | H33: 16569528 | I33: 2147142 | J33: 0 | K33: 0 | L33: 0 | M33: 5761102 | N33: 0 | O33: =+P33+Q33 -> 1277706359 | P33: 127837299 | Q33: 1149869060 | R33: 0 | S33: 0 | T33: 0 | U33: 0 | V33: 15214096 | W33: 702386 | X33: 5288561 | Y33: 14233715
A34: =A33+10 -> 230 | B34: Ҳукумат | C34: =SUM(J34:Y34)-L34-P34-Q34 -> 0 | D34: 0 | E34: 0 | F34: =+G34+H34+I34 -> 0 | G34: 0 | H34: 0 | I34: 0 | J34: 0 | K34: 0 | L34: 0 | M34: 0 | N34: 0 | O34: =+P34+Q34 -> 0 | P34: 0 | Q34: 0 | R34: 0 | S34: 0 | T34: 0 | U34: 0 | V34: 0 | W34: 0 | X34: 0 | Y34: 0
A35: =A34+10 -> 240 | B35: Бошқалар | C35: =SUM(J35:Y35)-L35-P35-Q35 -> 0 | D35: 0 | E35: 0 | F35: =+G35+H35+I35 -> 0 | G35: 0 | H35: 0 | I35: 0 | J35: 0 | K35: 0 | L35: 0 | M35: 0 | N35: 0 | O35: =+P35+Q35 -> 0 | P35: 0 | Q35: 0 | R35: 0 | S35: 0 | T35: 0 | U35: 0 | V35: 0 | W35: 0 | X35: 0 | Y35: 0
A36: =A35+10 -> 250 | B36: Жами | C36: =SUM(J36:Y36)-L36-P36-Q36 -> 1320966900 | D36: =SUM(D31:D35) -> 790037921 | E36: =SUM(E31:E35) -> 530928979 | F36: =+G36+H36+I36 -> 19809453 | G36: =SUM(G31:G35) -> 1092783 | H36: =SUM(H31:H35) -> 16569528 | I36: =SUM(I31:I35) -> 2147142 | J36: =SUM(J31:J35) -> 0 | K36: =SUM(K31:K35) -> 0 | L36: =SUM(L31:L35) -> 0 | M36: =SUM(M31:M35) -> 5761102 | N36: =SUM(N31:N35) -> 0 | ... Y36: =SUM(Y31:Y35) -> 15294396
B37: Савдо ва умумий хизмат
A38: 260 | B38: Давлат корхоналари | C38: =SUM(J38:Y38)-L38-P38-Q38 -> 272646 | D38: 272646 | E38: 0 | F38: =+G38+H38+I38 -> 0 | G38: 0 | H38: 0 | I38: 0 | J38: 0 | K38: 0 | L38: 0 | M38: 0 | N38: 0 | O38: =+P38+Q38 -> 224646 | P38: 224646 | Q38: 0 | R38: 0 | S38: 0 | T38: 0 | U38: 0 | V38: 0 | W38: 48000 | X38: 0 | Y38: 0
A39: =A38+10 -> 270 | B39: Қўшма ва чет эл капитали иштирокидаги корхоналар | C39: =SUM(J39:Y39)-L39-P39-Q39 -> 702135 | D39: 702135 | E39: 0 | F39: =+G39+H39+I39 -> 0 | G39: 0 | H39: 0 | I39: 0 | J39: 0 | K39: 0 | L39: 0 | M39: 702135 | N39: 0 | O39: =+P39+Q39 -> 0 | P39: 0 | Q39: 0 | R39: 0 | S39: 0 | T39: 0 | U39: 0 | V39: 0 | W39: 0 | X39: 0 | Y39: 0
A40: =A39+10 -> 280 | B40: Хусусий корхоналар | C40: =SUM(J40:Y40)-L40-P40-Q40 -> 1443890608 | D40: 1234041648 | E40: 209848960 | F40: =+G40+H40+I40 -> 96865938 | G40: 29782795 | H40: 39906082 | I40: 27177061 | J40: 0 | K40: 0 | L40: 0 | M40: 36317712 | N40: 0 | O40: =+P40+Q40 -> 890231782 | P40: 214885571 | Q40: 675346211 | R40: 0 | S40: 0 | T40: 0 | U40: 0 | V40: 83317059 | W40: 178752223 | X40: 115960437 | Y40: 139311395
A41: =A40+10 -> 290 | B41: Ҳукумат | C41: =SUM(J41:Y41)-L41-P41-Q41 -> 0 | D41: 0 | E41: 0 | F41: =+G41+H41+I41 -> 0 | G41: 0 | H41: 0 | I41: 0 | J41: 0 | K41: 0 | L41: 0 | M41: 0 | N41: 0 | O41: =+P41+Q41 -> 0 | P41: 0 | Q41: 0 | R41: 0 | S41: 0 | T41: 0 | U41: 0 | V41: 0 | W41: 0 | X41: 0 | Y41: 0
...

Sheet Aging Analysis
A1: ОЛИНИШИ ЛОЗИМ БЎЛГАН МУДДАТИ ЎТГАН КРЕДИТ ВА МОЛИЯВИЙ ЛИЗИНГ ТАҲЛИЛИ | X1: 9-жадвал
B3: =+'Asset quality'!B3 -> MKBANK | T3: =+'Asset quality'!Q3 -> 46021 | X3: =+'Asset quality'!T3 -> минг. сўмда
A4: № | B4: Кўрсаткичлар | C4: Жами кредит суммаси | D4: % | E4: Шартлари қайта кўрилган кредит ва лизинглар | F4: % | G4: Суд жараёнидаги қарздорликлар | H4: % | I4: Муддати ўтган | K4: % | L4: шу жумладан, кечиктирилган муддати бўйича
L5: 1-30 кун | N5: 31-60 кун | P5: 61-90 кун | R5: 91-180 кун | T5: 181-365 кун | V5: 366-730 кун | X5: 2 йилдан ортиқ
I6: асосий қарздорлик | J6: фоиз тўловлари | L6: асосий қарздорлик | M6: фоиз тўловлари | N6: асосий қарздорлик | O6: фоиз тўловлари | P6: асосий қарздорлик | Q6: фоиз тўловлари | R6: асосий қарздорлик | S6: фоиз тўловлари | T6: асосий қарздорлик | U6: фоиз тўловлари | V6: асосий қарздорлик | W6: фоиз тўловлари | X6: асосий қарздорлик | Y6: фоиз тўловлари
B7: (А) | C7: (Б) | D7: (В) | E7: (Г) | F7: (Д) | G7: (Е) | H7: (Ж) | I7: (З) | J7: (З1) | K7: (И) | L7: (К) | M7: (К1) | N7: (Л) | O7: (Л1) | P7: (М) | Q7: (М1) | R7: (Н) | S7: (Н1) | T7: (О) | U7: (О1) | V7: (П) | W7: (П1) | X7: (Р) | Y7: (Р1)
B8: Мижозлар тури бўйича
A9: 1 | B9: Марказий банк | C9: =+'Loans Receivable'!C79 -> 0 | D9: =IF(C$22=0,"",C9/C$22) -> 0 | E9: 0 | F9: =IF(E$22=0,"",E9/E$22) -> 0 | H9: =IF($G$22=0,"",G9/$G$22) -> 0 | I9: =+L9+N9+P9+R9+T9+V9+X9 -> 0 | J9: =+M9+O9+T9+S9+U9+W9+Y9 -> 0 | K9: =IF($Z$22=0,"",Z9/$Z$22) -> 0 | L9: 0 | M9: 0 | N9: 0 | O9: 0 | P9: 0 | Q9: 0 | R9: 0 | S9: 0 | T9: 0 | U9: 0 | V9: 0 | W9: 0 | X9: 0 | Y9: 0 | Z9: =+I9+J9 -> 0 | AA9: =+C9-Z9 -> 0
A10: 2 | B10: Бошқа банклар | C10: =+'Loans Receivable'!C78 -> 0 | D10: =IF(C$22=0,"",C10/C$22) -> 0 | E10: 0 | F10: =IF(E$22=0,"",E10/E$22) -> 0 | H10: =IF($G$22=0,"",G10/$G$22) -> 0 | I10: =+L10+N10+P10+R10+T10+V10+X10 -> 0 | J10: =+M10+O10+Q10+S10+U10+W10+Y10 -> 0 | K10: =IF($Z$22=0,"",Z10/$Z$22) -> 0 | L10: 0 | M10: 0 | N10: 0 | O10: 0 | P10: 0 | Q10: 0 | R10: 0 | S10: 0 | T10: 0 | U10: 0 | V10: 0 | W10: 0 | X10: 0 | Y10: 0 | Z10: =+I10+J10 -> 0
A11: 3 | B11: Ҳукумат | C11: =+'Loans Receivable'!C80 -> 0 | D11: =IF(C$22=0,"",C11/C$22) -> 0 | E11: 0 | F11: =IF(E$22=0,"",E11/E$22) -> 0 | H11: =IF($G$22=0,"",G11/$G$22) -> 0 | I11: =+L11+N11+P11+R11+T11+V11+X11 -> 0 | J11: =+M11+O11+Q11+S11+U11+W11+Y11 -> 0 | K11: =IF($Z$22=0,"",Z11/$Z$22) -> 0 | L11: 0 | M11: 0 | N11: 0 | O11: 0 | P11: 0 | Q11: 0 | R11: 0 | S11: 0 | T11: 0 | U11: 0 | V11: 0 | W11: 0 | X11: 0 | Y11: 0 | Z11: =+I11+J11 -> 0
A12: 4 | B12: Жисмоний шахслар | C12: =+'Loans Receivable'!C73 -> 8419167816 | D12: =IF(C$22=0,"",C12/C$22) -> 0.41518951 | E12: 0 | F12: =IF(E$22=0,"",E12/E$22) -> 0 | G12: 3667296 | H12: =IF($G$22=0,"",G12/$G$22) -> 0.019219644 | I12: =+L12+N12+P12+R12+T12+V12+X12 -> 258937806 | J12: =+M12+O12+Q12+S12+U12+W12+Y12 -> 147359454 | K12: =IF($Z$22=0,"",Z12/$Z$22) -> 0.29509308 | L12: 11590833 | M12: 10251684 | N12: 16212529 | O12: 10407699 | P12: 44168387 | Q12: 22151834 | R12: 16919073 | S12: 7254021 | T12: 48296680 | U12: 18515597 | V12: 92443432 | W12: 45230181 | X12: 29306872 | Y12: 33548438 | Z12: =+I12+J12 -> 406297260
A13: 5 | B13: Давлат корхоналари | C13: =+'Loans Receivable'!C74 -> 268361120 | D13: =IF(C$22=0,"",C13/C$22) -> 0.013234173 | E13: 0 | F13: =IF(E$22=0,"",E13/E$22) -> 0 | G13: 160630 | H13: =IF($G$22=0,"",G13/$G$22) -> 0.00084183319 | I13: =+L13+N13+P13+R13+T13+V13+X13 -> 28109740 | J13: =+M13+O13+Q13+S13+U13+W13+Y13 -> 2563488 | K13: =IF($Z$22=0,"",Z13/$Z$22) -> 0.022277919 | L13: 19112125 | M13: 518619 | N13: 339403 | O13: 131197 | P13: 0 | Q13: 0 | R13: 0 | S13: 0 | T13: 8658212 | U13: 1913672 | V13: 0 | W13: 0 | X13: 0 | Y13: 0 | Z13: =+I13+J13 -> 30673228
A14: 6 | B14: Қўшма ва чет эл капитали иштирокидаги корхоналар | C14: =+'Loans Receivable'!C75 -> 205430203 | D14: =IF(C$22=0,"",C14/C$22) -> 0.010130748 | E14: 34201632 | F14: =IF(E$22=0,"",E14/E$22) -> 0.030221896 | H14: =IF($G$22=0,"",G14/$G$22) -> 0 | I14: =+L14+N14+P14+R14+T14+V14+X14 -> 5690687 | J14: =+M14+O14+Q14+S14+U14+W14+Y14 -> 14022530 | K14: =IF($Z$22=0,"",Z14/$Z$22) -> 0.014317679 | L14: 74778 | M14: 1487075 | N14: 0 | O14: 0 | P14: 0 | Q14: 0 | R14: 5013058 | S14: 12310279 | T14: 0 | U14: 0 | V14: 0 | W14: 0 | X14: 602851 | Y14: 225176 | Z14: =+I14+J14 -> 19713217
A15: 7 | B15: Хусусий корхоналар | C15: =+'Loans Receivable'!C76 -> 11038064916 | D15: =IF(C$22=0,"",C15/C$22) -> 0.54433988 | E15: 1084523012 | F15: =IF(E$22=0,"",E15/E$22) -> 0.95832684 | G15: 185820766 | H15: =IF($G$22=0,"",G15/$G$22) -> 0.9738535 | I15: =+L15+N15+P15+R15+T15+V15+X15 -> 484725859 | J15: =+M15+O15+Q15+S15+U15+W15+Y15 -> 399232199 | K15: =IF($Z$22=0,"",Z15/$Z$22) -> 0.64201739 | L15: 26828042 | M15: 47933170 | N15: 56105988 | O15: 34657482 | P15: 55373433 | Q15: 43948140 | R15: 41691608 | S15: 26707920 | T15: 42182760 | U15: 32932582 | V15: 172425697 | W15: 120992747 | X15: 90118331 | Y15: 92060158 | Z15: =+I15+J15 -> 883958058
A16: 8 | B16: Фермер хўжаликлари | C16: =+'Loans Receivable'!C77 -> 339848885 | D16: =IF(C$22=0,"",C16/C$22) -> 0.016759577 | E16: 12959210 | F16: =IF(E$22=0,"",E16/E$22) -> 0.011451263 | G16: 1161081 | H16: =IF($G$22=0,"",G16/$G$22) -> 0.0060850185 | I16: =+L16+N16+P16+R16+T16+V16+X16 -> 21447678 | J16: =+M16+O16+Q16+S16+U16+W16+Y16 -> 14709334 | K16: =IF($Z$22=0,"",Z16/$Z$22) -> 0.026260783 | L16: 243787 | M16: 1232914 | N16: 691210 | O16: 415687 | P16: 2465213 | Q16: 1370846 | R16: 4291120 | S16: 1883338 | T16: 3088366 | U16: 670382 | V16: 4984817 | W16: 3527880 | X16: 5683165 | Y16: 5608287 | Z16: =+I16+J16 -> 36157012
A17: 9 | B17: Нобанк молиявий институтлар | C17: =+'Loans Receivable'!C81 -> 0 | D17: =IF(C$22=0,"",C17/C$22) -> 0 | E17: 0 | F17: =IF(E$22=0,"",E17/E$22) -> 0 | H17: =IF($G$22=0,"",G17/$G$22) -> 0 | I17: =+L17+N17+P17+R17+T17+V17+X17 -> 0 | J17: =+M17+O17+Q17+S17+U17+W17+Y17 -> 0 | K17: =IF($Z$22=0,"",Z17/$Z$22) -> 0 | L17: 0 | M17: 0 | N17: 0 | O17: 0 | P17: 0 | Q17: 0 | R17: 0 | S17: 0 | T17: 0 | U17: 0 | V17: 0 | W17: 0 | X17: 0 | Y17: 0 | Z17: =+I17+J17 -> 0
A18: 10 | B18: Нодавлат нотижорат ташкилотлар | C18: =+'Loans Receivable'!C82 -> 3835072 | D18: =IF(C$22=0,"",C18/C$22) -> 0.00018912578 | E18: 0 | F18: =IF(E$22=0,"",E18/E$22) -> 0 | H18: =IF($G$22=0,"",G18/$G$22) -> 0 | I18: =+L18+N18+P18+R18+T18+V18+X18 -> 26667 | J18: =+M18+O18+Q18+S18+U18+W18+Y18 -> 18982 | K18: =IF($Z$22=0,"",Z18/$Z$22) -> 3.3154799e-05 | L18: 26667 | M18: 18982 | N18: 0 | O18: 0 | P18: 0 | Q18: 0 | R18: 0 | S18: 0 | T18: 0 | U18: 0 | V18: 0 | W18: 0 | X18: 0 | Y18: 0 | Z18: =+I18+J18 -> 45649
A19: 11 | B19: Бюджет ташкилотлари | C19: =+'Loans Receivable'!C83 -> 0 | D19: =IF(C$22=0,"",C19/C$22) -> 0 | E19: 0 | F19: =IF(E$22=0,"",E19/E$22) -> 0 | H19: =IF($G$22=0,"",G19/$G$22) -> 0 | I19: =+L19+N19+P19+R19+T19+V19+X19 -> 0 | J19: =+M19+O19+Q19+S19+U19+W19+Y19 -> 0 | K19: =IF($Z$22=0,"",Z19/$Z$22) -> 0 | L19: 0 | M19: 0 | N19: 0 | O19: 0 | P19: 0 | Q19: 0 | R19: 0 | S19: 0 | T19: 0 | U19: 0 | V19: 0 | W19: 0 | X19: 0 | Y19: 0 | Z19: =+I19+J19 -> 0
A20: 12 | B20: Бошқалар | C20: =+'Loans Receivable'!C84 -> 3183333 | D20: =IF(C$22=0,"",C20/C$22) -> 0.00015698541 | E20: 0 | F20: =IF(E$22=0,"",E20/E$22) -> 0 | H20: =IF($G$22=0,"",G20/$G$22) -> 0 | I20: =+L20+N20+P20+R20+T20+V20+X20 -> 0 | J20: =+M20+O20+Q20+S20+U20+W20+Y20 -> 0 | K20: =IF($Z$22=0,"",Z20/$Z$22) -> 0 | L20: 0 | M20: 0 | N20: 0 | O20: 0 | P20: 0 | Q20: 0 | R20: 0 | S20: 0 | T20: 0 | U20: 0 | V20: 0 | W20: 0 | X20: 0 | Y20: 0 | Z20: =+I20+J20 -> 0
Z21: =+I21+J21 -> 0
A22: 13 | B22: Жами кредит ва лизинг суммаси | C22: =SUM(C9:C20) -> 20277891345 | D22: =IF(C$22=0,"",C22/C$22) -> 1 | E22: =SUM(E9:E20) -> 1131683854 | F22: =IF(E$22=0,"",E22/E$22) -> 1 | G22: =SUM(G9:G20) -> 190809773 | H22: =IF($G$22=0,"",G22/$G$22) -> 1 | I22: =SUM(I9:I20) -> 798938437 | J22: =SUM(J9:J20) -> 577905987 | K22: =IF($Z$22=0,"",Z22/$Z$22) -> 1 | L22: =SUM(L9:L20) -> 57876232 | M22: =SUM(M9:M20) -> 61442444 | N22: =SUM(N9:N20) -> 73349130 | O22: =SUM(O9:O20) -> 45612065 | P22: =SUM(P9:P20) -> 102007033 | Q22: =SUM(Q9:Q20) -> 67470820 | R22: =SUM(R9:R20) -> 67914859 | S22: =SUM(S9:S20) -> 48155558 | ... Y22: =SUM(Y9:Y20) -> 131442059 | Z22: =+I22+J22 -> 1376844424
Z23: =+I23+J23 -> 0
B24: Иқтисодиёт соҳалари бўйича | Z24: =+I24+J24 -> 0
A25: 14 | B25: Саноат | C25: =+'Loans Receivable'!C14 -> 3929868237 | D25: =IF(C$35=0,"",C25/C$35) -> 0.19380064 | E25: 850543605 | F25: =IF($E$35=0,"",E25/$E$35) -> 0.75157351 | G25: 103328007 | H25: =IF($G$35=0,"",G25/$G$35) -> 0.54152366 | I25: =+L25+N25+P25+R25+T25+V25+X25 -> 217421178 | J25: =+M25+O25+Q25+S25+U25+W25+Y25 -> 125354320 | K25: =IF($Z$35=0,"",Z25/$Z$35) -> 0.24895732 | L25: 22614613 | M25: 2130860 | N25: 10626320 | O25: 4285049 | P25: 21608851 | Q25: 17289480 | R25: 12676966 | S25: 15496773 | T25: 22488719 | U25: 9143325 | V25: 105289573 | W25: 52238110 | X25: 22116136 | Y25: 24770723 | Z25: =+I25+J25 -> 342775498
A26: 15 | B26: Қишлоқ хўжалиги | C26: =+'Loans Receivable'!C22 -> 4134450617 | D26: =IF(C$35=0,"",C26/C$35) -> 0.20388957 | E26: 105927233 | F26: =IF($E$35=0,"",E26/$E$35) -> 0.093601435 | G26: 41576060 | H26: =IF($G$35=0,"",G26/$G$35) -> 0.21789272 | I26: =+L26+N26+P26+R26+T26+V26+X26 -> 124856529 | J26: =+M26+O26+Q26+S26+U26+W26+Y26 -> 135083500 | K26: =IF($Z$35=0,"",Z26/$Z$35) -> 0.18879405 | L26: 8341146 | M26: 22026844 | N26: 5483928 | O26: 5882358 | P26: 14828962 | Q26: 13498484 | R26: 9112001 | S26: 7824318 | T26: 18358631 | U26: 15899998 | V26: 37379601 | W26: 37939485 | X26: 31352260 | Y26: 32012013 | Z26: =+I26+J26 -> 259940029
A27: 16 | B27: Транспорт ва коммуникация | C27: =+'Loans Receivable'!C29 -> 255926870 | D27: =IF(C$35=0,"",C27/C$35) -> 0.01262098 | E27: 8672875 | F27: =IF($E$35=0,"",E27/$E$35) -> 0.0076636907 | G27: 3379292 | H27: =IF($G$35=0,"",G27/$G$35) -> 0.017710267 | I27: =+L27+N27+P27+R27+T27+V27+X27 -> 10038042 | J27: =+M27+O27+Q27+S27+U27+W27+Y27 -> 7301289 | K27: =IF($Z$35=0,"",Z27/$Z$35) -> 0.01259353 | L27: 368761 | M27: 376253 | N27: 491181 | O27: 334901 | P27: 2393452 | Q27: 1372512 | R27: 1019209 | S27: 216732 | T27: 108731 | U27: 66874 | V27: 1393666 | W27: 963308 | X27: 4263042 | Y27: 3970709 | Z27: =+I27+J27 -> 17339331
A28: 17 | B28: Қурилиш соҳаси | C28: =+'Loans Receivable'!C36 -> 1320966900 | D28: =IF(C$35=0,"",C28/C$35) -> 0.065143208 | E28: 34793691 | F28: =IF($E$35=0,"",E28/$E$35) -> 0.030745063 | G28: 6272879 | H28: =IF($G$35=0,"",G28/$G$35) -> 0.03287504 | I28: =+L28+N28+P28+R28+T28+V28+X28 -> 80062835 | J28: =+M28+O28+Q28+S28+U28+W28+Y28 -> 53719889 | K28: =IF($Z$35=0,"",Z28/$Z$35) -> 0.097166188 | L28: 5950064 | M28: 2201293 | N28: 31366353 | O28: 20784978 | P28: 5913641 | Q28: 2467834 | R28: 24340496 | S28: 13091041 | T28: 1619276 | U28: 456244 | V28: 8128329 | W28: 10445653 | X28: 2744676 | Y28: 4272846 | Z28: =+I28+J28 -> 133782724
A29: 18 | B29: Савдо ва умумий овқатланиш | C29: =+'Loans Receivable'!C43 -> 1444865389 | D29: =IF(C$35=0,"",C29/C$35) -> 0.071253237 | E29: 68704797 | F29: =IF($E$35=0,"",E29/$E$35) -> 0.060710239 | G29: 31217538 | H29: =IF($G$35=0,"",G29/$G$35) -> 0.16360555 | I29: =+L29+N29+P29+R29+T29+V29+X29 -> 64519912 | J29: =+M29+O29+Q29+S29+U29+W29+Y29 -> 70575569 | K29: =IF($Z$35=0,"",Z29/$Z$35) -> 0.098119641 | L29: 8335693 | M29: 22254219 | N29: 6799573 | O29: 2411640 | P29: 6460426 | Q29: 7207643 | R29: 3002590 | S29: 3346948 | T29: 4652758 | U29: 3968152 | V29: 15110981 | W29: 10410899 | X29: 20157891 | Y29: 20976068 | Z29: =+I29+J29 -> 135095481
A30: 19 | B30: Моддий ва техник таъминотни ривожлантириш | C30: =+'Loans Receivable'!C50 -> 179982546 | D30: =IF(C$35=0,"",C30/C$35) -> 0.0088758019 | E30: 987043 | F30: =IF($E$35=0,"",E30/$E$35) -> 0.0008721897 | G30: 505122 | H30: =IF($G$35=0,"",G30/$G$35) -> 0.0026472543 | I30: =+L30+N30+P30+R30+T30+V30+X30 -> 9330175 | J30: =+M30+O30+Q30+S30+U30+W30+Y30 -> 9804753 | K30: =IF($Z$35=0,"",Z30/$Z$35) -> 0.013897669 | L30: 200275 | M30: 1558826 | N30: 1202945 | O30: 1089590 | P30: 2401082 | Q30: 889117 | R30: 72271 | S30: 35490 | T30: 2973470 | U30: 3622842 | V30: 1423200 | W30: 1210960 | X30: 1056932 | Y30: 1397928 | Z30: =+I30+J30 -> 19134928
A31: 20 | B31: Уй-жой коммунал хизмати | C31: =+'Loans Receivable'!C58 -> 592662970 | D31: =IF(C$35=0,"",C31/C$35) -> 0.029227051 | E31: 62054610 | F31: =IF($E$35=0,"",E31/$E$35) -> 0.054833874 | G31: 863579 | H31: =IF($G$35=0,"",G31/$G$35) -> 0.0045258636 | I31: =+L31+N31+P31+R31+T31+V31+X31 -> 33771960 | J31: =+M31+O31+Q31+S31+U31+W31+Y31 -> 28707213 | K31: =IF($Z$35=0,"",Z31/$Z$35) -> 0.045378528 | L31: 474847 | M31: 642465 | N31: 1166300 | O31: 415850 | P31: 4232233 | Q31: 2593917 | R31: 772253 | S31: 890235 | T31: 3727753 | U31: 2359201 | V31: 8685164 | W31: 11312211 | X31: 14713410 | Y31: 10493334 | Z31: =+I31+J31 -> 62479173
A32: 21 | B32: Бошқа соҳалар | C32: =+'Loans Receivable'!C70 -> 0 | D32: =IF(C$35=0,"",C32/C$35) -> 0 | E32: 0 | F32: =IF($E$35=0,"",E32/$E$35) -> 0 | G32: 0 | H32: =IF($G$35=0,"",G32/$G$35) -> 0 | I32: =+L32+N32+P32+R32+T32+V32+X32 -> 0 | J32: =+M32+O32+Q32+S32+U32+W32+Y32 -> 0 | K32: =IF($Z$35=0,"",Z32/$Z$35) -> 0 | L32: 0 | M32: 0 | N32: 0 | O32: 0 | P32: 0 | Q32: 0 | R32: 0 | S32: 0 | T32: 0 | U32: 0 | V32: 0 | W32: 0 | X32: 0 | Y32: 0 | Z32: =+I32+J32 -> 0
A33: 22 | B33: Жисмоний шахслар | C33: =+'Loans Receivable'!C71 -> 8419167816 | D33: =IF(C$35=0,"",C33/C$35) -> 0.41518951 | E33: 0 | F33: =IF($E$35=0,"",E33/$E$35) -> 0 | G33: 3667296 | H33: =IF($G$35=0,"",G33/$G$35) -> 0.019219644 | I33: =+L33+N33+P33+R33+T33+V33+X33 -> 258937806 | J33: =+M33+O33+Q33+S33+U33+W33+Y33 -> 147359454 | K33: =IF($Z$35=0,"",Z33/$Z$35) -> 0.29509308 | L33: 11590833 | M33: 10251684 | N33: 16212530 | O33: 10407699 | P33: 44168386 | Q33: 22151833 | R33: 16919073 | S33: 7254021 | T33: 48296680 | U33: 18515597 | V33: 92443432 | W33: 45230182 | X33: 29306872 | Y33: 33548438 | Z33: =+I33+J33 -> 406297260
Z34: =+I34+J34 -> 0
A35: 23 | B35: Жами кредит ва лизинг суммаси | C35: =SUM(C25:C33) -> 20277891345 | D35: =IF(C$35=0,"",C35/C$35) -> 1 | E35: =SUM(E25:E33) -> 1131683854 | F35: =IF($E$35=0,"",E35/$E$35) -> 1 | G35: =SUM(G25:G33) -> 190809773 | H35: =IF($G$35=0,"",G35/$G$35) -> 1 | I35: =SUM(I25:I33) -> 798938437 | J35: =SUM(J25:J33) -> 577905987 | K35: =IF($Z$35=0,"",Z35/$Z$35) -> 1 | L35: =SUM(L25:L33) -> 57876232 | M35: =SUM(M25:M33) -> 61442444 | N35: =SUM(N25:N33) -> 73349130 | O35: =SUM(O25:O33) -> 45612065 | P35: =SUM(P25:P33) -> 102007033 | Q35: =SUM(Q25:Q33) -> 67470820 | R35: =SUM(R25:R33) -> 67914859 | S35: =SUM(S25:S33) -> 48155558 | ... Y35: =SUM(Y25:Y33) -> 131442059 | Z35: =+I35+J35 -> 1376844424
B37: Бошқарув Раис имзоси:
B39: Бош бухгалтер имзоси:
G42: =+'[8]Bank Assets Analysis'!$S$32 -> 167963237

Sheet Asset Classification
A1: АКТИВЛАР СИФАТИ БЎЙИЧА ТАСНИФЛАНИШИ ТЎҒРИСИДА ҲИСОБОТ | Z1: 10-жадвал
B3: =+'Asset quality'!B3 -> MKBANK | U3: =+'Asset quality'!Q3 -> 46021 | AB3: =+'Asset quality'!T3 -> минг. сўмда
A4: № | B4: Кўрсаткичлар | C4: Жами суммаси | D4: шундан, хорижий валютада (экв. сўмда) | E4: Стандарт | F4: шундан, хорижий валютада (экв. сўмда) | G4: Стандарт активлар бўйича яратилган захиралар (1%) | H4: шундан, хорижий валютада (экв. сўмда) | I4: Субстандарт | J4: шундан, хорижий валютада (экв. сўмда) | K4: Махсус захиралар (мин 10%) | L4: шундан, хорижий валютада (экв. сўмда) | M4: Қониқарсиз | N4: шундан, хорижий валютада (экв. сўмда) | O4: Махсус захиралар (мин 25%) | P4: шундан, хорижий валютада (экв. сўмда) | Q4: Шубҳали | R4: шундан, хорижий валютада (экв. сўмда) | S4: Махсус захиралар (мин 50%) | T4: шундан, хорижий валютада (экв. сўмда) | U4: Умидсиз | V4: шундан, хорижий валютада (экв. сўмда) | W4: Махсус захиралар (мин 100%) | X4: шундан, хорижий валютада (экв. сўмда) | Y4: Жами махсус захиралар суммаси | Z4: шундан, хорижий валютада (экв. сўмда) | AA4: ҳисобот ойида балансдан ташқари ҳисобдан чиқарилган кредитлар | AB4: ҳисобот ойида балансдан ташқари қайтган кредитлар суммаси
A5: (А) | B5: (Б) | C5: (В) | D5: (В1) | E5: (Г) | F5: (Г1) | G5: (Д) | H5: (Д1) | I5: (Е) | J5: (Е1) | K5: (Ж) | L5: (Ж1) | M5: (З) | N5: (З1) | O5: (И) | P5: (И1) | Q5: (К) | R5: (К1) | S5: (Л) | T5: (Л1) | U5: (М) | V5: (М1) | W5: (Н) | X5: (Н1) | Y5: О=Ж+И+Л+Н | Z5: (О1)=(Ж1)+(И1)+(Л1)+(Н1) | AA5: П | AB5: Р
B6: Мижозлар тури бўйича
A7: 1 | B7: Марказий банк | C7: =E7+I7+M7+Q7+U7 -> 0 | D7: =F7+J7+N7+R7+V7 -> 0 | Y7: =+W7+S7+O7+K7 -> 0 | Z7: =+X7+T7+P7+L7 -> 0 | AC7: =+'Aging Analysis'!C9 -> 0 | AD7: =+C7-AC7 -> 0
B8: шундан, таъминланмаган қисми | C8: =E8+I8+M8+Q8+U8 -> 0 | D8: =F8+J8+N8+R8+V8 -> 0 | Y8: =+W8+S8+O8+K8 -> 0 | Z8: =+X8+T8+P8+L8 -> 0
A9: 2 | B9: Бошқа банклар | C9: =E9+I9+M9+Q9+U9 -> 0 | D9: =F9+J9+N9+R9+V9 -> 0 | Y9: =+W9+S9+O9+K9 -> 0 | Z9: =+X9+T9+P9+L9 -> 0 | AC9: =+'Aging Analysis'!C10 -> 0 | AD9: =+C9-AC9 -> 0
B10: шундан, таъминланмаган қисми | C10: =E10+I10+M10+Q10+U10 -> 0 | D10: =F10+J10+N10+R10+V10 -> 0 | Y10: =+W10+S10+O10+K10 -> 0 | Z10: =+X10+T10+P10+L10 -> 0
A11: 3 | B11: Ҳукумат | C11: =E11+I11+M11+Q11+U11 -> 0 | D11: =F11+J11+N11+R11+V11 -> 0 | Y11: =+W11+S11+O11+K11 -> 0 | Z11: =+X11+T11+P11+L11 -> 0 | AC11: =+'Aging Analysis'!C11 -> 0 | AD11: =+C11-AC11 -> 0
B12: шундан, таъминланмаган қисми | C12: =E12+I12+M12+Q12+U12 -> 0 | D12: =F12+J12+N12+R12+V12 -> 0 | Y12: =+W12+S12+O12+K12 -> 0 | Z12: =+X12+T12+P12+L12 -> 0
A13: 4 | B13: Жисмоний шахслар | C13: =E13+I13+M13+Q13+U13 -> 8419167816 | D13: =F13+J13+N13+R13+V13 -> 0 | E13: 7066030436 | F13: 0 | G13: 84191679 | H13: 0 | I13: 945973383 | J13: 0 | K13: 5688849 | L13: 0 | M13: 173943343 | N13: 0 | O13: 2184405 | P13: 0 | Q13: 110154468 | R13: 0 | S13: 853013 | T13: 0 | U13: 123066186 | V13: 0 | W13: 351268 | X13: 0 | Y13: =+W13+S13+O13+K13 -> 9077535 | Z13: =+X13+T13+P13+L13 -> 0 | AC13: =+'Aging Analysis'!C12 -> 8419167816 | AD13: =+C13-AC13 -> 0
B14: шундан, таъминланмаган қисми | C14: =E14+I14+M14+Q14+U14 -> 0 | D14: =F14+J14+N14+R14+V14 -> 0 | Y14: =+W14+S14+O14+K14 -> 0 | Z14: =+X14+T14+P14+L14 -> 0
A15: 5 | B15: Давлат корхоналари | C15: =E15+I15+M15+Q15+U15 -> 268361120 | D15: =F15+J15+N15+R15+V15 -> 220175617 | E15: 259542278 | F15: 211517405 | G15: 82518 | H15: 0 | I15: 0 | J15: 0 | K15: 0 | L15: 0 | M15: 8658212 | N15: 8658212 | O15: 0 | P15: 0 | Q15: 160630 | R15: 0 | S15: 160630 | T15: 0 | U15: 0 | V15: 0 | W15: 0 | X15: 0 | Y15: =+W15+S15+O15+K15 -> 160630 | Z15: =+X15+T15+P15+L15 -> 0 | AC15: =+'Aging Analysis'!C13 -> 268361120 | AD15: =+C15-AC15 -> 0
B16: шундан, таъминланмаган қисми | C16: =E16+I16+M16+Q16+U16 -> 0 | D16: =F16+J16+N16+R16+V16 -> 0 | Y16: =+W16+S16+O16+K16 -> 0 | Z16: =+X16+T16+P16+L16 -> 0
A17: 6 | B17: Қўшма ва чет эл капитали иштирокидаги корхоналар | C17: =E17+I17+M17+Q17+U17 -> 205430203 | D17: =F17+J17+N17+R17+V17 -> 142513572 | E17: 158461630 | F17: 95933880 | G17: 21064 | H17: 6029 | I17: 45976841 | J17: 45976841 | K17: 0 | L17: 0 | M17: 0 | N17: 0 | O17: 0 | P17: 0 | Q17: 388881 | R17: 0 | S17: 194440 | T17: 0 | U17: 602851 | V17: 602851 | W17: 301425 | X17: 301425 | Y17: =+W17+S17+O17+K17 -> 495865 | Z17: =+X17+T17+P17+L17 -> 301425 | AC17: =+'Aging Analysis'!C14 -> 205430203 | AD17: =+C17-AC17 -> 0
B18: шундан, таъминланмаган қисми | C18: =E18+I18+M18+Q18+U18 -> 0 | D18: =F18+J18+N18+R18+V18 -> 0 | Y18: =+W18+S18+O18+K18 -> 0 | Z18: =+X18+T18+P18+L18 -> 0
A19: 7 | B19: Хусусий корхоналар | C19: =E19+I19+M19+Q19+U19 -> 11038064916 | D19: =F19+J19+N19+R19+V19 -> 3354480324 | E19: 9761052004 | F19: 2979124077 | G19: 37281069 | H19: 1608888 | I19: 824743581 | J19: 281921405 | K19: 15076750 | L19: 4608229 | M19: 67399884 | N19: 7315986 | O19: 482494 | P19: 0 | Q19: 249641802 | R19: 73657201 | S19: 43186632 | T19: 14152805 | U19: 135227645 | V19: 12461655 | W19: 53430722 | X19: 4647701 | Y19: =+W19+S19+O19+K19 -> 112176598 | Z19: =+X19+T19+P19+L19 -> 23408735 | AC19: =+'Aging Analysis'!C15 -> 11038064916 | AD19: =+C19-AC19 -> 0
B20: шундан, таъминланмаган қисми | C20: =E20+I20+M20+Q20+U20 -> 0 | D20: =F20+J20+N20+R20+V20 -> 0 | Y20: =+W20+S20+O20+K20 -> 0 | Z20: =+X20+T20+P20+L20 -> 0
A21: 8 | B21: Фермер хўжалиги | C21: =E21+I21+M21+Q21+U21 -> 339848885 | D21: =F21+J21+N21+R21+V21 -> 20829434 | E21: 299554132 | F21: 20704256 | G21: 1727521 | H21: 50457 | I21: 15534802 | J21: 125178 | K21: 846934 | L21: 0 | M21: 4150709 | N21: 0 | O21: 0 | P21: 0 | Q21: 13619621 | R21: 0 | S21: 2770912 | T21: 0 | U21: 6989621 | V21: 0 | W21: 2168138 | X21: 0 | Y21: =+W21+S21+O21+K21 -> 5785984 | Z21: =+X21+T21+P21+L21 -> 0 | AC21: =+'Aging Analysis'!C16 -> 339848885 | AD21: =+C21-AC21 -> 0
B22: шундан, таъминланмаган қисми | C22: =E22+I22+M22+Q22+U22 -> 0 | D22: =F22+J22+N22+R22+V22 -> 0 | Y22: =+W22+S22+O22+K22 -> 0 | Z22: =+X22+T22+P22+L22 -> 0
A23: 9 | B23: Нобанк молиявий институтлар | C23: =E23+I23+M23+Q23+U23 -> 0 | D23: =F23+J23+N23+R23+V23 -> 0 | E23: 0 | F23: 0 | I23: 0 | J23: 0 | K23: 0 | L23: 0 | M23: 0 | N23: 0 | O23: 0 | P23: 0 | Q23: 0 | R23: 0 | S23: 0 | T23: 0 | U23: 0 | V23: 0 | W23: 0 | X23: 0 | Y23: =+W23+S23+O23+K23 -> 0 | Z23: =+X23+T23+P23+L23 -> 0 | AC23: =+'Aging Analysis'!C17 -> 0 | AD23: =+C23-AC23 -> 0
B24: шундан, таъминланмаган қисми | C24: =E24+I24+M24+Q24+U24 -> 0 | D24: =F24+J24+N24+R24+V24 -> 0 | Y24: =+W24+S24+O24+K24 -> 0 | Z24: =+X24+T24+P24+L24 -> 0
A25: 10 | B25: Нодавлат нотижорат ташкилотлар | C25: =E25+I25+M25+Q25+U25 -> 3835072 | D25: =F25+J25+N25+R25+V25 -> 0 | E25: 3835072 | F25: 0 | G25: 38351 | H25: 0 | I25: 0 | J25: 0 | K25: 0 | L25: 0 | M25: 0 | N25: 0 | O25: 0 | P25: 0 | Q25: 0 | R25: 0 | S25: 0 | T25: 0 | U25: 0 | V25: 0 | W25: 0 | X25: 0 | Y25: =+W25+S25+O25+K25 -> 0 | Z25: =+X25+T25+P25+L25 -> 0 | AC25: =+'Aging Analysis'!C18 -> 3835072 | AD25: =+C25-AC25 -> 0
B26: шундан, таъминланмаган қисми | C26: =E26+I26+M26+Q26+U26 -> 0 | D26: =F26+J26+N26+R26+V26 -> 0 | Y26: =+W26+S26+O26+K26 -> 0 | Z26: =+X26+T26+P26+L26 -> 0
A27: 11 | B27: Бюджет ташкилотлари | C27: =E27+I27+M27+Q27+U27 -> 0 | D27: =F27+J27+N27+R27+V27 -> 0 | E27: 0 | F27: 0 | I27: 0 | J27: 0 | K27: 0 | L27: 0 | M27: 0 | N27: 0 | O27: 0 | P27: 0 | Q27: 0 | R27: 0 | S27: 0 | T27: 0 | U27: 0 | V27: 0 | W27: 0 | X27: 0 | Y27: =+W27+S27+O27+K27 -> 0 | Z27: =+X27+T27+P27+L27 -> 0 | AC27: =+'Aging Analysis'!C19 -> 0 | AD27: =+C27-AC27 -> 0
B28: шундан, таъминланмаган қисми | C28: =E28+I28+M28+Q28+U28 -> 0 | D28: =F28+J28+N28+R28+V28 -> 0 | Y28: =+W28+S28+O28+K28 -> 0 | Z28: =+X28+T28+P28+L28 -> 0
A29: 12 | B29: Бошқалар | C29: =E29+I29+M29+Q29+U29 -> 3183333 | D29: =F29+J29+N29+R29+V29 -> 0 | E29: 3183333 | F29: 0 | G29: 31833 | H29: 0 | I29: 0 | J29: 0 | K29: 0 | L29: 0 | M29: 0 | N29: 0 | O29: 0 | P29: 0 | Q29: 0 | R29: 0 | S29: 0 | T29: 0 | U29: 0 | V29: 0 | W29: 0 | X29: 0 | Y29: =+W29+S29+O29+K29 -> 0 | Z29: =+X29+T29+P29+L29 -> 0 | AC29: =+'Aging Analysis'!C20 -> 3183333 | AD29: =+C29-AC29 -> 0
B30: шундан, таъминланмаган қисми | C30: =E30+I30+M30+Q30+U30 -> 0 | D30: =F30+J30+N30+R30+V30 -> 0 | Y30: =+W30+S30+O30+K30 -> 0 | Z30: =+X30+T30+P30+L30 -> 0
A31: 13 | B31: Жами кредит ва лизинг суммаси | C31: =+C7+C9+C11+C13+C15+C17+C19+C21+C23+C25+C27+C29 -> 20277891345 | D31: =+D7+D9+D11+D13+D15+D17+D19+D21+D23+D25+D27+D29 -> 3737998947 | E31: =+E7+E9+E11+E13+E15+E17+E19+E21+E23+E25+E27+E29 -> 17551658885 | F31: =+F7+F9+F11+F13+F15+F17+F19+F21+F23+F25+F27+F29 -> 3307279618 | G31: =+G7+G9+G11+G13+G15+G17+G19+G21+G23+G25+G27+G29 -> 123374035 | H31: =+H7+H9+H11+H13+H15+H17+H19+H21+H23+H25+H27+H29 -> 1665374 | I31: =+I7+I9+I11+I13+I15+I17+I19+I21+I23+I25+I27+I29 -> 1832228607 | J31: =+J7+J9+J11+J13+J15+J17+J19+J21+J23+J25+J27+J29 -> 328023424 | ... AB31: =+AB7+AB9+AB11+AB13+AB15+AB17+AB19+AB21+AB23+AB25+AB27+AB29 -> 0 | AC31: =+'Loans Receivable'!C85 -> 20277891345 | AD31: =+C31-AC31 -> 0
B32: шундан, таъминланмаган қисми | C32: =+C8+C10+C12+C14+C16+C18+C20+C22+C24+C26+C28+C30 -> 0 | D32: =+D8+D10+D12+D14+D16+D18+D20+D22+D24+D26+D28+D30 -> 0 | E32: =+E8+E10+E12+E14+E16+E18+E20+E22+E24+E26+E28+E30 -> 0 | F32: =+F8+F10+F12+F14+F16+F18+F20+F22+F24+F26+F28+F30 -> 0 | G32: =+G8+G10+G12+G14+G16+G18+G20+G22+G24+G26+G28+G30 -> 0 | H32: =+H8+H10+H12+H14+H16+H18+H20+H22+H24+H26+H28+H30 -> 0 | I32: =+I8+I10+I12+I14+I16+I18+I20+I22+I24+I26+I28+I30 -> 0 | J32: =+J8+J10+J12+J14+J16+J18+J20+J22+J24+J26+J28+J30 -> 0 | ... Z32: =+Z8+Z10+Z12+Z14+Z16+Z18+Z20+Z22+Z24+Z26+Z28+Z30 -> 0
B33: Иқтисодиёт соҳалари бўйича
A35: 14 | B35: Саноат | C35: =E35+I35+M35+Q35+U35 -> 3929868237 | D35: =F35+J35+N35+R35+V35 -> 1854686815 | E35: 3317232337 | F35: 1503865555 | G35: 12691345 | H35: 729789 | I35: 458624751 | J35: 279250351 | K35: 6022658 | L35: 4608229 | M35: 26513005 | N35: 15974198 | O35: 255125 | P35: 0 | Q35: 92658895 | R35: 48540411 | S35: 11833571 | T35: 6251331 | U35: 34839249 | V35: 7056300 | W35: 11935208 | X35: 1961823 | Y35: =+W35+S35+O35+K35 -> 30046562 | Z35: =+X35+T35+P35+L35 -> 12821383 | AC35: =+'Aging Analysis'!C25 -> 3929868237 | AD35: =+C35-AC35 -> 0
B36: шундан, таъминланмаган қисми | C36: =E36+I36+M36+Q36+U36 -> 0 | D36: =F36+J36+N36+R36+V36 -> 0 | Y36: =+W36+S36+O36+K36 -> 0 | Z36: =+X36+T36+P36+L36 -> 0
A37: 15 | B37: Қишлоқ хўжалиги | C37: =E37+I37+M37+Q37+U37 -> 4134450617 | D37: =F37+J37+N37+R37+V37 -> 1002733920 | E37: 3807842742 | F37: 987280796 | G37: 9555115 | H37: 365384 | I37: 167022420 | J37: 2168958 | K37: 7326218 | L37: 0 | M37: 17177594 | N37: 0 | O37: 155440 | P37: 0 | Q37: 83531170 | R37: 12246479 | S37: 17897521 | T37: 3731733 | U37: 58876691 | V37: 1037687 | W37: 23423125 | X37: 518844 | Y37: =+W37+S37+O37+K37 -> 48802304 | Z37: =+X37+T37+P37+L37 -> 4250577 | AC37: =+'Aging Analysis'!C26 -> 4134450617 | AD37: =+C37-AC37 -> 0
B38: шундан, таъминланмаган қисми | C38: =E38+I38+M38+Q38+U38 -> 0 | D38: =F38+J38+N38+R38+V38 -> 0 | Y38: =+W38+S38+O38+K38 -> 0 | Z38: =+X38+T38+P38+L38 -> 0
