Workbook
Name jop: #REF!
Name kol: #REF!
Name TwentyLargestData: #REF!
Name Е: #REF!

Sheet Bank Capital Calc
A1: БАНКНИНГ РЕГУЛЯТИВ КАПИТАЛИ ҲИСОБ-КИТОБИ | C1: 5-жадвал | E1: №1
B3: "Алоқабанк" | C3: 45291
A4: № | B4: Кўрсаткичлар | C4: минг сўмда
A5: I. | B5: I ДАРАЖАЛИ КАПИТАЛ
A6: 1 | B6: I ДАРАЖАЛИ АСОСИЙ КАПИТАЛ
A7: 1.1. | B7: Оддий акциялар, нетто | C7: =+C8-C9 -> 1189065847
A8: a | B8: Тўлиқ тўланган оддий акциялар | C8: 1189065847
A9: б | B9: Минус: Қайта сотиб олинган оддий акциялар | C9: 0
A10: 1.2. | B10: Қўшимча капитал (оддий) | C10: 3870139
A11: 1.3. | B11: Тақсимланмаган фойда (зарар), шу жумладан капитал захиралар | C11: =+C12+C13-C14-C15 -> 837083540
A12: а | B12: Капитал ва бошқа захиралар | C12: 524440207
A13: б | B13: Тақсимланмаган фойда | C13: 312643333
A14: в | B14: Ўтган даврлар (йиллар) учун зарарлар | C14: 0
A15: г | B15: Жорий йил учун зарар | C15: 0
A16: 1.4. | B16: Озчилик улуш эгаларининг банк йиғма балансига бирлашадиган корхоналардаги улушлари | C16: 0
A17: 1.5. | B17: Девальвация захираси | C17: 0
A18: 1.6. | B18: Чегирмалар ҳисоблангунга қадар жами I даражали асосий капитал | C18: =+C7+C10+C11+C16+C17 -> 2030019526
A19: 1.7. | B19: I даражали асосий капиталдан чегирмалар | C19: =C20+C21+C22+C23+C24 -> 1757673
A20: а | B20: Номоддий активлар (бундан банкнинг дастурий таъминотлари мустасно) | C20: 1757673
A21: б | B21: Бирлашмаган (консолидация қилинмаган) молиявий бўлган фаолият билан шуғулланувчи хўжалик юритувчи субъектларнинг капиталига қилинган барча инвестициялар суммаси | C21: 0
A22: в | B22: Бошқа банкларнинг капиталига қилинган инвестициялар | C22: 0
A23: г | B23: Банк томонидан муаммоли активлар бўйича қўшимча шакллантирилиши лозим бўлган захиралар | C23: 0
A24: д | B24: Банкка алоқадор бир ёки барча шахслар учун таваккалчиликнинг белгиланган энг кўп миқдоридан ортиқ қиймати | C24: 0 | E24: =+'[6]Transactions of related parties'!$Z$89 -> 6.8200842e+08
A25: I | B25: I ДАРАЖАЛИ АСОСИЙ КАПИТАЛ | C25: =+C18-C19 -> 2028261853 | E25: =C18-C20-C21-C22-C23 -> 2028261853
A26: 2 | B26: I ДАРАЖАЛИ ҚЎШИМЧА КАПИТАЛ
A27: 2.1. | B27: Нокумулятив муддатсиз имтиёзли акциялар | C27: =+C28-C29 -> 2178000
A28: а | B28: Тўлиқ тўланган имтиёзли акциялар | C28: 2178000
A29: б | B29: Минус: Қайтиб сотиб олинган имтиёзли акциялар | C29: 0
A30: 2.2. | B30: Қўшилган капитал (имтиёзли) | C30: 36000
A31: 2.3. | B31: Озчилик улуш эгаларининг банк йиғма балансига бирлашадиган корхоналардаги улушлари | C31: 0
A32: 2.4. | B32: Шўъба корхоналарнинг улушлари (шўъба корхоналар томонидан чиқарилган ва капиталга тенглаштирилган учинчи шахслар эгалик қиладиган воситалар) | C32: 0
A33: II | B33: ЖАМИ I ДАРАЖАЛИ ҚЎШИМЧА КАПИТАЛ | C33: =+C27+C30+C31+C32 -> 2214000
A34: III | B34: ЖАМИ ТЎҒРИЛАНГАН I ДАРАЖАЛИ КАПИТАЛ | C34: =+C25+C33 -> 2030475853
B35: II ДАРАЖАЛИ КАПИТАЛ
A36: 3.1. | B36: Жорий йил соф фойдаси | C36: 607650640
A37: 3.2. | B37: Стандарт активларга яратилган захиралар | C37: =IF(F37<(C45*1.25%),F37,(C45*1.25%)) -> 102677702 | E37: Резервы созданные по стандартным активам | F37: 102677702
A38: 3.3. | B38: Чегирмалардан сўнг I даражали капиталнинг учдан бир қисмидан ошмаган миқдорда аралаш турдаги мажбуриятлар | C38: 0 | F38: =+[7]Balance!$C$39+[7]Balance!$C$61 -> 102677702
A39: 3.4. | B39: Субординар қарз | C39: 160342316 | F39: =+F37-F38 -> 0
A40: 3.5. | B40: Активларнинг бошланғич қийматига нисбатан баҳолаш қийматининг ошган суммасининг 45 фоизи миқдори | C40: 1478316
A41: 3.6. | B41: II даражали капиталнинг I даражали капиталдан ортиқча қисми (чегирмаси) | C41: =IF($C$34>=SUM($C$36:$C$40),0,(SUM($C$36:$C$40)-$C$34))*-1 -> 0
...

Sheet Bank Capital Calc (2)
A1: РАСЧЕТ РЕГУЛЯТИВНОГО КАПИТАЛА БАНКА | C1: Таблица-5
B3: =#REF! -> #REF! | C3: =+#REF! -> #REF!
A4: № | B4: Характеристики | C4: Итого капитала
A5: I. | B5: КАПИТАЛ УРОВНЯ 1
A6: 1 | B6: ОСНОВНОЙ КАПИТАЛ УРОВНЯ 1
A7: 1.1. | B7: Обыкновенные Акции, чистые | C7: Формула
A8: a | B8: Полностью оплаченные обыкновенные акции
A9: б | B9: Минус: Обратно Выкупленные обыкновенные акции
A10: 1.2. | B10: Добавленный капитал - Обыкновенные | C10: 0
A11: 1.3. | B11: Нераспределенная прибыль (убыток), в том числе капитальные резервы | C11: Формула
A12: а | B12: Капитальные резервы
A13: б | B13: Нераспределенная прибыль
A14: в | B14: Убыток за предыдущие периоды
A15: г | B15: Убыток за текущий год
A16: 1.4. | B16: Интерес меньшинства в консолидированных дочерних компаниях (согласно МБС)
A17: 1.5. | B17: Резерв на девальвацию
B18: Итого основного капитала уровня I до вычетов | C18: Формула
A19: 1.6. | B19: Вычеты из суммы основного капитала уровня I | C19: Формула
A20: а | B20: Нематериальные активы
A21: б | B21: Все инвестиции в капитал неконсолидированных хозяйствующих субъектов, в том числе в долговые обязательства, которые образуют капитал хозяйствующих субъектов
A22: в | B22: Инвестиции в капитал других банков
A23: I | B23: ВСЕГО СКОРРЕКТИРОВАННЫЙ ОСНОВНОЙ КАПИТАЛ УРОВНЯ I | C23: Формула
A24: 2 | B24: ДОБАВЛЕННЫЙ КАПИТАЛ УРОВНЯ 1
A25: 2.1. | B25: Некумулятивные бессрочные привилегированные акции | C25: =+C26+C27 -> 0
A26: а | B26: Полностью оплаченные привилегированные акции
A27: б | B27: Минус: Обратно Выкупленные привилегированные акции
A28: 2.2. | B28: Добавленный капитал - Привилегированные | C28: 0
A29: 2.3. | B29: Интерес меньшинства в консолидированных дочерних компаниях | C29: 0
A30: 2.4. | B30: Доля участия дочерних предприятий (выпущенные дочерними предприятиями и находящиеся во владении третьих лиц инструменты, приравненные к капиталу) | C30: 0
A31: II | B31: ВСЕГО ДОБАВЛЕННЫЙ КАПИТАЛ УРОВНЯ I | C31: =+C25+C28+C29+C30 -> 0
A32: III | B32: ВСЕГО СКОРРЕКТИРОВАННЫЙ КАПИТАЛ УРОВНЯ I | C32: Формула
B33: КАПИТАЛ УРОВНЯ II
A34: 3.1. | B34: Прибыль за текущий год
A35: 3.2. | B35: Резервы, создаваемые на стандартные кредиты (активы), в размере не более 1.25% от общей суммы активов, взвешенных с учетом риска | C35: =IF(#REF!<(C43*1.25%),#REF!,(C43*1.25%)) -> #REF!
A36: 3.3. | B36: Излишки оценочной стоимости прироста над первоначальной стоимостью
A37: 3.4. | B37: Другие инструменты капитала (не более 1/3 части капитала 1 уровня после вычетов)
A38: 3.5. | B38: Субординированный долг
A39: 3.6. | B39: Вычеты превышения Капитала Уровня II над Капиталом Уровня I | C39: Формула
B40: Итого капитала Уровня II | C40: =SUM(C34:C38) -> #REF!
A41: IV | B41: СКОРРЕКТИРОВАННЫЙ КАПИТАЛ УРОВНЯ II | C41: Формула
...

Sheet Calculation of Risk Weighted As
A1: ТАВАККАЛЧИЛИКНИ ҲИСОБГА ОЛГАН ҲОЛДАГИ АКТИВЛАР | J1: 6-жадвал
B2: =+'Bank Capital Calc'!B3 -> "Алоқабанк" | H2: =+'Bank Capital Calc'!C3 -> 45291 | J2: минг сўмда
A3: № | B3: Кўрсаткичлар | D3: 0 | E3: 0.2 | F3: 0.35 | G3: 0.5 | H3: 1 | I3: 1.5 | J3: 2
D4: Таваккалчилик | E4: Таваккалчилик | F4: Таваккалчилик | G4: Таваккалчилик | H4: Таваккалчилик | I4: Таваккалчилик | J4: Таваккалчилик
D5: I гуруҳ | E5: II гуруҳ | F5: III гуруҳ | G5: IV гуруҳ | H5: V гуруҳ | I5: VI гуруҳ | J5: VII гуруҳ
B6: (A) | D6: (Б) | E6: (В) | F6: (Г) | G6: (Д) | H6: (Е) | I6: (Ж) | J6: (З)
B7: I. БАЛАНС АКТИВЛАРИ
A8: 1. | B8: Кассадаги нақд пул ва бошқа тўлов ҳужжатлари ва қимматбаҳо металлар | D8: 427565101
A9: 2. | B9: Йўлдаги нақд пуллар ва бошқа тўлов ҳужжатлари | E9: 20584524
A10: 3. | B10: Банкнинг Марказий банкдаги маблағлар | D10: 751379622 | E10: 61976744
A11: 4. | B11: Бошқа банкларга жойлаштирилган пул маблағлари, жумладан вакиллик ҳисобварақлари, депозитлар ва кредитлар | E11: 188043533 | G11: 118627879 | H11: 338942194 | I11: 59343095
A12: 5. | B12: Қимматли қоғозлар (соф)
A13: а | B13: Ўзбекистон Республикаси Ҳукумати ва Марказий банки томонидан чиқарилган қимматли қоғозлар | D13: 209969287 | E13: 0
A14: б | B14: Ипотекани қайта молиялаштириш ташкилотлари томонидан чиқарилган қимматли қоғозлар | D14: 0 | E14: 0
A15: в | B15: Хорижий давлатларининг ҳукуматлари ва марказий банклари томонидан чиқарилган қимматли қоғозлар, шунингдек ушбу мамлакатларнинг марказий банклари ва ҳукуматларига нисбатан бошқа талаблар | D15: 0 | E15: 0 | G15: 0 | H15: 0 | I15: 0
A16: г | B16: Ўзбекистон Республикаси ҳудудида чиқарилган бошқа қимматли қоғозлар | D16: 0 | E16: 0 | G16: 0 | H16: 0 | I16: 0
A17: д | B17: Чет давлатлар томонидан чиқарилган бошқа қимматли қоғозлар | D17: 0 | E17: 0 | G17: 0 | H17: 0 | I17: 0
A18: е | B18: РЕПО битимлари бўйича сотиб олинган қимматли қоғозлар | D18: 0 | E18: 0 | G18: 0 | H18: 0 | I18: 0
A19: 6. | B19: Миллий валютага деноминация қилинмаган ва миллий валютада молиялаштириш суммасидан ошиб кетган активлар | H19: 0
A20: 7. | B20: Хорижий давлатларнинг давлат секторлари (ҳукуматлар ва марказий банклар бундан мустасно) ва хорижий компаниялар бўйича банк талаблари, шунингдек уларнинг қимматли қоғозлари билан таъминланган ёки кафолатланган активлар (кредитлар ва қимматли қоғозлар бундан мустасно) | D20: 0 | E20: 0 | G20: 0 | H20: 0 | I20: 0
A21: 8. | B21: Кредит ва лизинглар, соф
A22: а | B22: Ўзбекистон Республикаси ҳукумати ва Марказий банкига тўғридан-тўғри берилган кредитлар | D22: 0
A23: б | B23: Халқаро молия институтларига берилган кредитлар, халқаро молия ташкилотларининг қимматли қоғозлари билан таъминланган ёки улар томонидан кафолатланган кредитлар қисми | D23: 0
A24: в | B24: Қисман ёки тўлиқ депозит билан таъминланган кредитлар | D24: 251740444
A25: г | B25: Жорий бозор қийматида баҳоланган ва ЎзР Ҳукумати, ЎзР Марказий банки томонидан эмиссия қилинган ёки кафолатланган қимматли қоғозлар кўринишидаги гаров билан таъминланган ёки кафолатланган кредитлар, уларнинг қисмлари. | D25: 0
A26: д | B26: Дастлабки гаров ҳуқуқи банкка тегишли бўлмаган кредитлар | H26: 0
A27: е | B27: Аҳолига кўчмас мулк сотиб олиш учун берилган ва сотиб олинган ёки қурилаётган уй (квартира) билан таъминланган кредитлар | F27: 59570238 | G27: 104498073 | H27: 222462363 | I27: 276946236
A28: ж | B28: Жисмоний шахсларга автомобиль сотиб олиш учун ажратилган кредитлар | H28: 862533732 | I28: 842352568 | J28: 6391156
A29: з | B29: Жисмоний шахсларга қайта тикланадиган энергия манбалари учун ажратилган кредитлар | D29: 9258449 | H29: 0 | I29: 0 | J29: 0
A30: и | B30: Аҳолига берилган бошқа кредитлар | H30: 252741759 | I30: 86317160 | J30: 324404810
A31: к | B31: Юридик шахсларга қайта тикланадиган энергия манбалари учун ажратилган кредитлар | D31: 26325247 | H31: 0 | I31: 0 | J31: 0
A32: л | B32: Бошқа барча кредит ва лизинглар | H32: 6198958199 | I32: 583435950 | J32: 16114825
A33: м | B33: Муаммоли кредит ва лизинглар, соф | J33: 135478535
A34: 9. | B34: Банкнинг асосий воситалари ва бошқа хусусий мол-мулклари
A35: а | B35: Банк фаолиятидаги фойдаланиладиган асосий воситалар (амортизацияни чегирган ҳолда) | H35: 2003170965
A36: б | B36: Банкнинг бошқа хусусий мулклари | H36: 0
A37: в | B37: Қарздорликни тўлиқ ёки қисман ундириш мақсадида банк балансига қабул қилинган кўчмас мулк | I37: 349433916 | J37: 46693523
A38: г | B38: Икки йилдан ортиқ вақт мобайнида банк фойдаланмаётган банкнинг кўчмас мулки | I38: 0 | J38: 0
A39: 10. | B39: Молиявий бўлган фаолият билан шуғулланувчи хўжалик юритувчи субъектларнинг капиталига қилинган барча инвестициялар, соф | D39: 0 | J39: 156083266
A40: 11. | B40: Молиявий бўлмаган фаолият билан шуғулланувчи хўжалик юритувчи субъектларнинг капиталига қилинган барча инвестициялар, соф | J40: 0
...

Sheet Calculation of Risk Weighte нац
A1: МИЛЛИЙ ВАЛЮТАДА ТАВАККАЛЧИЛИКНИ ҲИСОБГА ОЛГАН ҲОЛДАГИ АКТИВЛАР | J1: 6.1-жадвал
B2: =+'Bank Capital Calc'!B3 -> "Алоқабанк" | H2: =+'Bank Capital Calc'!C3 -> 45291 | J2: минг сўмда
A3: № | B3: Кўрсаткичлар | D3: 0 | E3: 0.2 | F3: 0.35 | G3: 0.5 | H3: 1 | I3: 1.5 | J3: 2
D4: Таваккалчилик | E4: Таваккалчилик | F4: Таваккалчилик | G4: Таваккалчилик | H4: Таваккалчилик | I4: Таваккалчилик | J4: Таваккалчилик
D5: I гуруҳ | E5: II гуруҳ | F5: III гуруҳ | G5: IV гуруҳ | H5: V гуруҳ | I5: VI гуруҳ | J5: VII гуруҳ
B6: (A) | D6: (Б) | E6: (В) | F6: (Г) | G6: (Д) | H6: (Е) | I6: (Ж) | J6: (З)
B7: I. БАЛАНС АКТИВЛАРИ
A8: 1. | B8: Кассадаги нақд пул ва бошқа тўлов ҳужжатлари ва қимматбаҳо металлар | D8: 218070289
A9: 2. | B9: Йўлдаги нақд пуллар ва бошқа тўлов ҳужжатлари | E9: 12930000
A10: 3. | B10: Банкнинг Марказий банкдаги маблағлар | D10: 751379622 | E10: 0
A11: 4. | B11: Бошқа банкларга жойлаштирилган пул маблағлари, жумладан вакиллик ҳисобварақлари, депозитлар ва кредитлар | E11: 0 | G11: 0 | H11: 153860643 | I11: 1643291
A12: 5. | B12: Қимматли қоғозлар (соф)
A13: а | B13: Ўзбекистон Республикаси Ҳукумати ва Марказий банки томонидан чиқарилган қимматли қоғозлар | D13: 209969287 | E13: 0
A14: б | B14: Ипотекани қайта молиялаштириш ташкилотлари томонидан чиқарилган қимматли қоғозлар | D14: 0 | E14: 0
A15: в | B15: Хорижий давлатларининг ҳукуматлари ва марказий банклари томонидан чиқарилган қимматли қоғозлар, шунингдек ушбу мамлакатларнинг марказий банклари ва ҳукуматларига нисбатан бошқа талаблар | D15: 0 | E15: 0 | G15: 0 | H15: 0 | I15: 0
A16: г | B16: Ўзбекистон Республикаси ҳудудида чиқарилган бошқа қимматли қоғозлар | D16: 0 | E16: 0 | G16: 0 | H16: 0 | I16: 0
A17: д | B17: Чет давлатлар томонидан чиқарилган бошқа қимматли қоғозлар | D17: 0 | E17: 0 | G17: 0 | H17: 0 | I17: 0
A18: е | B18: РЕПО битимлари бўйича сотиб олинган қимматли қоғозлар | D18: 0 | E18: 0 | G18: 0 | H18: 0 | I18: 0
A19: 6. | B19: Миллий валютага деноминация қилинмаган ва миллий валютада молиялаштириш суммасидан ошиб кетган активлар | H19: 0
A20: 7. | B20: Хорижий давлатларнинг давлат секторлари (ҳукуматлар ва марказий банклар бундан мустасно) ва хорижий компаниялар бўйича банк талаблари, шунингдек уларнинг қимматли қоғозлари билан таъминланган ёки кафолатланган активлар (кредитлар ва қимматли қоғозлар бундан мустасно) | D20: 0 | E20: 0 | G20: 0 | H20: 0 | I20: 0
A21: 8. | B21: Кредит ва лизинглар, соф
A22: а | B22: Ўзбекистон Республикаси ҳукумати ва Марказий банкига тўғридан-тўғри берилган кредитлар | D22: 0
A23: б | B23: Халқаро молия институтларига берилган кредитлар, халқаро молия ташкилотларининг қимматли қоғозлари билан таъминланган ёки улар томонидан кафолатланган кредитлар қисми | D23: 0
A24: в | B24: Қисман ёки тўлиқ депозит билан таъминланган кредитлар | D24: 250390965 | E24: 0
A25: г | B25: Кредитлар/уларнинг қисмлари жорий бозор баҳосидаги ҳукумат, Марказий банк томонидан чиқарилган ёки кафолатланган қимматли қоғозлар билан таъминланган кредитлар/уларнинг қисмлари, шунингдек ҳукумат ва Марказий банк томонидан кафолатланган кредитлар/уларнинг қисмлари | D25: 0
A26: д | B26: Дастлабки гаров ҳуқуқи банкка тегишли бўлмаган кредитлар | H26: 0
A27: е | B27: Аҳолига кўчмас мулк сотиб олиш учун берилган ва сотиб олинган ёки қурилаётган уй (квартира) билан таъминланган кредитлар | F27: 59570238 | G27: 104498073 | H27: 222462363 | I27: 276946236
A28: ж | B28: Жисмоний шахсларга автомобиль сотиб олиш учун ажратилган кредитлар | H28: 862533732 | I28: 842352568 | J28: 6391156
A29: з | B29: Жисмоний шахсларга қайта тикланадиган энергия манбалари учун ажратилган кредитлар | D29: 9258449 | H29: 0 | I29: 0 | J29: 0
A30: и | B30: Аҳолига берилган бошқа кредитлар | H30: 252741759 | I30: 86317160 | J30: 324404810
A31: к | B31: Юридик шахсларга қайта тикланадиган энергия манбалари учун ажратилган кредитлар | D31: 26325247 | H31: 0 | I31: 0 | J31: 0
A32: л | B32: Бошқа барча кредит ва лизинглар | H32: 2470580972 | I32: 572250793 | J32: 2428669
A33: м | B33: Муаммоли кредит ва лизинглар, соф | J33: 79509611
A34: 9. | B34: Банкнинг асосий воситалари ва бошқа хусусий мол-мулклари
A35: а | B35: Банк фаолиятидаги фойдаланиладиган асосий воситалар (амортизацияни чегирган ҳолда) | H35: 2003170965
A36: б | B36: Банкнинг бошқа хусусий мулклари | H36: 0
A37: в | B37: Қарздорликни тўлиқ ёки қисман ундириш мақсадида банк балансига қабул қилинган кўчмас мулк | I37: 349433916 | J37: 46693523
A38: г | B38: Икки йилдан ортиқ вақт мобайнида банк фойдаланмаётган банкнинг кўчмас мулки | I38: 0 | J38: 0
A39: 10. | B39: Молиявий бўлган фаолият билан шуғулланувчи хўжалик юритувчи субъектларнинг капиталига қилинган барча инвестициялар, соф | D39: 0 | J39: 156083266
A40: 11. | B40: Молиявий бўлмаган фаолият билан шуғулланувчи хўжалик юритувчи субъектларнинг капиталига қилинган барча инвестициялар, соф | J40: 0
...

Sheet Calculation of Risk Weighte ин
A1: ХОРИЖИЙ ВАЛЮТАДА ТАВАККАЛЧИЛИКНИ ҲИСОБГА ОЛГАН ҲОЛДАГИ АКТИВЛАР | J1: 6.2-жадвал
B2: =+'Bank Capital Calc'!B3 -> "Алоқабанк" | H2: =+'Bank Capital Calc'!C3 -> 45291 | J2: минг сўмда
A3: № | B3: Кўрсаткичлар | D3: 0 | E3: 0.2 | F3: 0.35 | G3: 0.5 | H3: 1 | I3: 1.5 | J3: 2
D4: Таваккалчилик | E4: Таваккалчилик | F4: Таваккалчилик | G4: Таваккалчилик | H4: Таваккалчилик | I4: Таваккалчилик | J4: Таваккалчилик
D5: I гуруҳ | E5: II гуруҳ | F5: III гуруҳ | G5: IV гуруҳ | H5: V гуруҳ | I5: VI гуруҳ | J5: VII гуруҳ
B6: (A) | D6: (Б) | E6: (В) | F6: (Г) | G6: (Д) | H6: (Е) | I6: (Ж) | J6: (З)
B7: I. БАЛАНС АКТИВЛАРИ
A8: 1. | B8: Кассадаги нақд пул ва бошқа тўлов ҳужжатлари ва қимматбаҳо металлар | D8: =+'Calculation of Risk Weighted As'!D8-'Calculation of Risk Weighte нац'!D8 -> 209494812
A9: 2. | B9: Йўлдаги нақд пуллар ва бошқа тўлов ҳужжатлари | E9: =+'Calculation of Risk Weighted As'!E9-'Calculation of Risk Weighte нац'!E9 -> 7654524
A10: 3. | B10: Банкнинг Марказий банкдаги маблағлар | D10: =+'Calculation of Risk Weighted As'!D10-'Calculation of Risk Weighte нац'!D10 -> 0 | E10: =+'Calculation of Risk Weighted As'!E10-'Calculation of Risk Weighte нац'!E10 -> 61976744
A11: 4. | B11: Бошқа банкларга жойлаштирилган пул маблағлари, жумладан вакиллик ҳисобварақлари, депозитлар ва кредитлар | E11: =+'Calculation of Risk Weighted As'!E11-'Calculation of Risk Weighte нац'!E11 -> 188043533 | G11: =+'Calculation of Risk Weighted As'!G11-'Calculation of Risk Weighte нац'!G11 -> 118627879 | H11: =+'Calculation of Risk Weighted As'!H11-'Calculation of Risk Weighte нац'!H11 -> 185081551 | I11: =+'Calculation of Risk Weighted As'!I11-'Calculation of Risk Weighte нац'!I11 -> 57699804
A12: 5. | B12: Қимматли қоғозлар (соф)
A13: а | B13: Ўзбекистон Республикаси Ҳукумати ва Марказий банки томонидан чиқарилган қимматли қоғозлар | D13: =+'Calculation of Risk Weighted As'!D13-'Calculation of Risk Weighte нац'!D13 -> 0 | E13: =+'Calculation of Risk Weighted As'!E13-'Calculation of Risk Weighte нац'!E13 -> 0
A14: б | B14: Ипотекани қайта молиялаштириш ташкилотлари томонидан чиқарилган қимматли қоғозлар | D14: =+'Calculation of Risk Weighted As'!D14-'Calculation of Risk Weighte нац'!D14 -> 0 | E14: =+'Calculation of Risk Weighted As'!E14-'Calculation of Risk Weighte нац'!E14 -> 0
A15: в | B15: Хорижий давлатларининг ҳукуматлари ва марказий банклари томонидан чиқарилган қимматли қоғозлар, шунингдек ушбу мамлакатларнинг марказий банклари ва ҳукуматларига нисбатан бошқа талаблар | D15: =+'Calculation of Risk Weighted As'!D15-'Calculation of Risk Weighte нац'!D15 -> 0 | E15: =+'Calculation of Risk Weighted As'!E15-'Calculation of Risk Weighte нац'!E15 -> 0 | G15: =+'Calculation of Risk Weighted As'!G15-'Calculation of Risk Weighte нац'!G15 -> 0 | H15: =+'Calculation of Risk Weighted As'!H15-'Calculation of Risk Weighte нац'!H15 -> 0 | I15: =+'Calculation of Risk Weighted As'!I15-'Calculation of Risk Weighte нац'!I15 -> 0
A16: г | B16: Ўзбекистон Республикаси ҳудудида чиқарилган бошқа қимматли қоғозлар | D16: =+'Calculation of Risk Weighted As'!D16-'Calculation of Risk Weighte нац'!D16 -> 0 | E16: =+'Calculation of Risk Weighted As'!E16-'Calculation of Risk Weighte нац'!E16 -> 0 | G16: =+'Calculation of Risk Weighted As'!G16-'Calculation of Risk Weighte нац'!G16 -> 0 | H16: =+'Calculation of Risk Weighted As'!H16-'Calculation of Risk Weighte нац'!H16 -> 0 | I16: =+'Calculation of Risk Weighted As'!I16-'Calculation of Risk Weighte нац'!I16 -> 0
A17: д | B17: Чет давлатлар томонидан чиқарилган бошқа қимматли қоғозлар | D17: =+'Calculation of Risk Weighted As'!D17-'Calculation of Risk Weighte нац'!D17 -> 0 | E17: =+'Calculation of Risk Weighted As'!E17-'Calculation of Risk Weighte нац'!E17 -> 0 | G17: =+'Calculation of Risk Weighted As'!G17-'Calculation of Risk Weighte нац'!G17 -> 0 | H17: =+'Calculation of Risk Weighted As'!H17-'Calculation of Risk Weighte нац'!H17 -> 0 | I17: =+'Calculation of Risk Weighted As'!I17-'Calculation of Risk Weighte нац'!I17 -> 0
A18: е | B18: РЕПО битимлари бўйича сотиб олинган қимматли қоғозлар | D18: =+'Calculation of Risk Weighted As'!D18-'Calculation of Risk Weighte нац'!D18 -> 0 | E18: =+'Calculation of Risk Weighted As'!E18-'Calculation of Risk Weighte нац'!E18 -> 0 | G18: =+'Calculation of Risk Weighted As'!G18-'Calculation of Risk Weighte нац'!G18 -> 0 | H18: =+'Calculation of Risk Weighted As'!H18-'Calculation of Risk Weighte нац'!H18 -> 0 | I18: =+'Calculation of Risk Weighted As'!I18-'Calculation of Risk Weighte нац'!I18 -> 0
A19: 6. | B19: Миллий валютага деноминация қилинмаган ва миллий валютада молиялаштириш суммасидан ошиб кетган активлар | H19: =+'Calculation of Risk Weighted As'!H19-'Calculation of Risk Weighte нац'!H19 -> 0
A20: 7. | B20: Хорижий давлатларнинг давлат секторлари (ҳукуматлар ва марказий банклар бундан мустасно) ва хорижий компаниялар бўйича банк талаблари, шунингдек уларнинг қимматли қоғозлари билан таъминланган ёки кафолатланган активлар (кредитлар ва қимматли қоғозлар бундан мустасно) | D20: =+'Calculation of Risk Weighted As'!D20-'Calculation of Risk Weighte нац'!D20 -> 0 | E20: =+'Calculation of Risk Weighted As'!E20-'Calculation of Risk Weighte нац'!E20 -> 0 | G20: =+'Calculation of Risk Weighted As'!G20-'Calculation of Risk Weighte нац'!G20 -> 0 | H20: =+'Calculation of Risk Weighted As'!H20-'Calculation of Risk Weighte нац'!H20 -> 0 | I20: =+'Calculation of Risk Weighted As'!I20-'Calculation of Risk Weighte нац'!I20 -> 0
A21: 8. | B21: Кредит ва лизинглар, соф
A22: а | B22: Ўзбекистон Республикаси ҳукумати ва Марказий банкига тўғридан-тўғри берилган кредитлар | D22: =+'Calculation of Risk Weighted As'!D22-'Calculation of Risk Weighte нац'!D22 -> 0
A23: б | B23: Халқаро молия институтларига берилган кредитлар, халқаро молия ташкилотларининг қимматли қоғозлари билан таъминланган ёки улар томонидан кафолатланган кредитлар қисми | D23: =+'Calculation of Risk Weighted As'!D23-'Calculation of Risk Weighte нац'!D23 -> 0
A24: в | B24: Қисман ёки тўлиқ депозит билан таъминланган кредитлар | D24: =+'Calculation of Risk Weighted As'!D24-'Calculation of Risk Weighte нац'!D24 -> 1349479 | E24: =+'Calculation of Risk Weighted As'!E24-'Calculation of Risk Weighte нац'!E24 -> 0
A25: г | B25: Кредитлар/уларнинг қисмлари жорий бозор баҳосидаги ҳукумат, Марказий банк томонидан чиқарилган ёки кафолатланган қимматли қоғозлар билан таъминланган кредитлар/уларнинг қисмлари, шунингдек ҳукумат ва Марказий банк томонидан кафолатланган кредитлар/уларнинг қисмлари | D25: =+'Calculation of Risk Weighted As'!D25-'Calculation of Risk Weighte нац'!D25 -> 0
A26: д | B26: Дастлабки гаров ҳуқуқи банкка тегишли бўлмаган кредитлар | H26: =+'Calculation of Risk Weighted As'!H26-'Calculation of Risk Weighte нац'!H26 -> 0
A27: е | B27: Аҳолига кўчмас мулк сотиб олиш учун берилган ва сотиб олинган ёки қурилаётган уй (квартира) билан таъминланган кредитлар | F27: =+'Calculation of Risk Weighted As'!F27-'Calculation of Risk Weighte нац'!F27 -> 0 | G27: =+'Calculation of Risk Weighted As'!G27-'Calculation of Risk Weighte нац'!G27 -> 0 | H27: =+'Calculation of Risk Weighted As'!H27-'Calculation of Risk Weighte нац'!H27 -> 0 | I27: =+'Calculation of Risk Weighted As'!I27-'Calculation of Risk Weighte нац'!I27 -> 0
A28: ж | B28: Жисмоний шахсларга автомобиль сотиб олиш учун ажратилган кредитлар | H28: =+'Calculation of Risk Weighted As'!H28-'Calculation of Risk Weighte нац'!H28 -> 0 | I28: =+'Calculation of Risk Weighted As'!I28-'Calculation of Risk Weighte нац'!I28 -> 0 | J28: =+'Calculation of Risk Weighted As'!J28-'Calculation of Risk Weighte нац'!J28 -> 0
A29: з | B29: Жисмоний шахсларга қайта тикланадиган энергия манбалари учун ажратилган кредитлар | D29: =+'Calculation of Risk Weighted As'!D29-'Calculation of Risk Weighte нац'!D29 -> 0 | H29: =+'Calculation of Risk Weighted As'!H29-'Calculation of Risk Weighte нац'!H29 -> 0 | I29: =+'Calculation of Risk Weighted As'!I29-'Calculation of Risk Weighte нац'!I29 -> 0 | J29: =+'Calculation of Risk Weighted As'!J29-'Calculation of Risk Weighte нац'!J29 -> 0
A30: и | B30: Аҳолига берилган бошқа кредитлар | H30: =+'Calculation of Risk Weighted As'!H30-'Calculation of Risk Weighte нац'!H30 -> 0 | I30: =+'Calculation of Risk Weighted As'!I30-'Calculation of Risk Weighte нац'!I30 -> 0 | J30: =+'Calculation of Risk Weighted As'!J30-'Calculation of Risk Weighte нац'!J30 -> 0
A31: к | B31: Юридик шахсларга қайта тикланадиган энергия манбалари учун ажратилган кредитлар | D31: =+'Calculation of Risk Weighted As'!D31-'Calculation of Risk Weighte нац'!D31 -> 0 | H31: =+'Calculation of Risk Weighted As'!H31-'Calculation of Risk Weighte нац'!H31 -> 0 | I31: =+'Calculation of Risk Weighted As'!I31-'Calculation of Risk Weighte нац'!I31 -> 0 | J31: =+'Calculation of Risk Weighted As'!J31-'Calculation of Risk Weighte нац'!J31 -> 0
A32: л | B32: Бошқа барча кредит ва лизинглар | H32: =+'Calculation of Risk Weighted As'!H32-'Calculation of Risk Weighte нац'!H32 -> 3728377227 | I32: =+'Calculation of Risk Weighted As'!I32-'Calculation of Risk Weighte нац'!I32 -> 11185157 | J32: =+'Calculation of Risk Weighted As'!J32-'Calculation of Risk Weighte нац'!J32 -> 13686156
A33: м | B33: Муаммоли кредит ва лизинглар, соф | J33: =+'Calculation of Risk Weighted As'!J33-'Calculation of Risk Weighte нац'!J33 -> 55968924
A34: 9. | B34: Банкнинг асосий воситалари ва бошқа хусусий мол-мулклари
A35: а | B35: Банк фаолиятидаги фойдаланиладиган асосий воситалар (амортизацияни чегирган ҳолда) | H35: =+'Calculation of Risk Weighted As'!H35-'Calculation of Risk Weighte нац'!H35 -> 0
A36: б | B36: Банкнинг бошқа хусусий мулклари | H36: =+'Calculation of Risk Weighted As'!H36-'Calculation of Risk Weighte нац'!H36 -> 0
A37: в | B37: Қарздорликни тўлиқ ёки қисман ундириш мақсадида банк балансига қабул қилинган кўчмас мулк | I37: =+'Calculation of Risk Weighted As'!I37-'Calculation of Risk Weighte нац'!I37 -> 0 | J37: =+'Calculation of Risk Weighted As'!J37-'Calculation of Risk Weighte нац'!J37 -> 0
A38: г | B38: Икки йилдан ортиқ вақт мобайнида банк фойдаланмаётган банкнинг кўчмас мулки | I38: =+'Calculation of Risk Weighted As'!I38-'Calculation of Risk Weighte нац'!I38 -> 0 | J38: =+'Calculation of Risk Weighted As'!J38-'Calculation of Risk Weighte нац'!J38 -> 0
A39: 10. | B39: Молиявий бўлган фаолият билан шуғулланувчи хўжалик юритувчи субъектларнинг капиталига қилинган барча инвестициялар, соф | D39: =+'Calculation of Risk Weighted As'!D39-'Calculation of Risk Weighte нац'!D39 -> 0 | J39: =+'Calculation of Risk Weighted As'!J39-'Calculation of Risk Weighte нац'!J39 -> 0
A40: 11. | B40: Молиявий бўлмаган фаолият билан шуғулланувчи хўжалик юритувчи субъектларнинг капиталига қилинган барча инвестициялар, соф | J40: =+'Calculation of Risk Weighted As'!J40-'Calculation of Risk Weighte нац'!J40 -> 0
...

Sheet Calculation of Risk
A1: ОПЕРАЦИОН ВА БОЗОР ТАВАККАЛЧИЛИКЛАРИ ҲИСОБ-КИТОБИ | C1: 6а-жадвал
B2: =IF(C3>0," "&TEXT(C3,"гггг"),"Число,Месяц,Год") -> 2023
B3: =+'Bank Capital Calc'!B3 -> "Алоқабанк" | C3: =+'Bank Capital Calc'!C3 -> 45291
A4: № | B4: Кўрсаткичлар номи | C4: минг сўмда
A5: 1. | B5: =+""&(D$6-3)&" йилдаги банкнинг ялпи даромади" -> 2020 йилдаги банкнинг ялпи даромади | C5: =+C6+C8-C7-C9 -> 490963020
A6: а. | B6: фоизли даромад | C6: 1185874258 | D6: =+B2 -> 2023 | E6: 13
A7: б. | B7: фоизли харажат | C7: 819338253
A8: в. | B8: фоизсиз даромад | C8: 294481740
A9: г. | B9: фоизсиз харажат | C9: 170054725
A10: 2. | B10: =+""&(D$6-2)&" йилдаги банкнинг ялпи даромади" -> 2021 йилдаги банкнинг ялпи даромади | C10: =+C11+C13-C12-C14 -> 623564273
A11: а. | B11: фоизли даромад | C11: 1206690017
A12: б. | B12: фоизли харажат | C12: 798308535
A13: в. | B13: фоизсиз даромад | C13: 427153372
A14: г. | B14: фоизсиз харажат | C14: 211970581
A15: 3. | B15: =+""&(D$6-1)&" йилдаги банкнинг ялпи даромади" -> 2022 йилдаги банкнинг ялпи даромади | C15: =+C16+C18-C17-C19 -> 942831511
A16: а. | B16: фоизли даромад | C16: 1499548960
A17: б. | B17: фоизли харажат | C17: 993836102
A18: в. | B18: фоизсиз даромад | C18: 836134469
A19: г. | B19: фоизсиз харажат | C19: 399015816
A20: 4. | B20: Банкнинг ўртача ялпи даромади (оҳирги уч йил давомида) | C20: =(C5+C10+C15)/3 -> 685786268
A21: 5. | B21: Операцион таваккалчиликлар қиймати | C21: =+(100/C28)*C20*15% -> 7.9129185e+08
A23: 6. | B23: Валюта позицияси ҳисобварақлари | C23: 1.9864212e+08 | E23: сўм қисми
A24: 7. | B24: Кўзда тутилмаган ҳолатлар бўйича талаблар | C24: 173600000 | D24: 92503, 92705, 92716, 92728, 92732 | E24: чет эл валютасидаги қолдиқларининг эквиваленти
A25: 8. | B25: Кўзда тутилмаган ҳолатлар бўйича мажбуриятлар | C25: 1.7702683e+08 | D25: 92501, 92701, 92709, 92724, 92736 | E25: чет эл валютасидаги қолдиқларининг эквиваленти
A26: 9. | B26: Очиқ валюта позицияси, жами | C26: =ABS(C23+(C24-C25)) -> 1.9521529e+08 | D26: =+C26*0.1 -> 19521529
A27: 10. | B27: Бозор таваккалчилиги суммаси | C27: =+(100/C28)*(C26*10%) -> 1.5016561e+08
A28: 11. | B28: Капитал монандлигига бўлган амалдаги минимал талаб | C28: =VLOOKUP($D$6,$D$6:$E$6,2,0) -> 13
B30: Бошқарув Раис имзоси:
B32: Бош бухгалтер имзоси:
