Workbook
Name jop: #REF!
Name kol: #REF!
Name RISKTOTASS: SUM('[6]Calculation of Risk Weighted As'!$C$38:$F$38)
Name RISKTOTASS: SUM('[7]Calculation of Risk Weighted As'!$C$41:$G$41)
Name TwentyLargestData: #REF!
Name Е: #REF!

Sheet Asset quality
A1: АКТИВЛАР ТАСНИФИ ВА УЛАР БЎЙИЧА ЯРАТИЛГАН ЭҲТИМОЛИЙ ЙЎҚОТИШЛАРНИ ҚОПЛАШ ЗАХИРАЛАРИ ТЎҒРИСИДА ҲИСОБОТ | S1: 2-жадвал | V1: №6
B3: "МКБАНК" | Q3: 44926 | T3: минг. сўмда
A4: № | B4: Активлар таркиби* | C4: Қолдиқ | D4: Сифат тоифаси | I4: Муддати ўтган қарздорлик (брутто) | O4: Зарарларни қоплаш захираси
I5: Жами | J5: 30 кунгача | K5: 31дан 90 кунгача | L5: 91дан 180 кунгача | M5: 181 дан 365 кунгача | N5: 366 кун ва ундан ортиқ | O5: ҳақиқатдан яратилган захиралар
O6: Жами | P6: сифат тоифаси бўйича
D7: I | E7: II | F7: III | G7: IV | H7: V | P7: I | Q7: II | R7: III | S7: IV | T7: V
A8: А | B8: Б | C8: В | D8: Г | E8: Д | F8: Е | G8: Ж | H8: З | I8: И | J8: К | K8: Л | L8: М | M8: Н | N8: О | O8: П | P8: Р | Q8: С | R8: Т | S8: У | T8: Ф
B9: Жами активлар | C9: =SUM(C10:C58)+C60-C59 -> 16782496965 | D9: =SUM(D10:D58)-D59+D60 -> 13938328217 | E9: =SUM(E10:E58)-E59+E60 -> 2572974084 | F9: =SUM(F10:F58)-F59+F60 -> 110817389 | G9: =SUM(G10:G58)-G59+G60 -> 331525438 | H9: =SUM(H10:H58)-H59+H60 -> 193107671 | I9: =SUM(I10:I60) -> 5.9209924e+08 | J9: =SUM(J10:J60) -> 28792695 | K9: =SUM(K10:K60) -> 1.5778571e+08 | L9: =SUM(L10:L60) -> 73643579 | M9: =SUM(M10:M60) -> 99094983 | N9: =SUM(N10:N60) -> 2.3278228e+08 | O9: =SUM(O10:O60) -> 412973993 | P9: =SUM(P10:P60) -> 48718159 | ... T9: =SUM(T10:T60) -> 155988148
A10: 1 | B10: Кассадаги нақд пул ва бошқа тўлов ҳужжатлари | C10: =SUM(D10:H10)-O10+P10 -> 550033332 | D10: 550033332 | I10: =SUM(J10:N10) -> 0 | O10: =SUM(P10:T10) -> 0 | Q10: 0 | U10: 10100
A11: 2 | B11: Банкнинг Марказий банкдаги маблағлар | C11: =SUM(D11:H11)-O11+P11 -> 425539396 | D11: 425539396 | I11: =SUM(J11:N11) -> 0 | O11: =SUM(P11:T11) -> 0 | Q11: 0 | U11: 10300
A12: 3 | B12: Бошқа банклар ва молиявий ташкилотлардан олиниши лозим бўлган маблағлар | C12: =SUM(D12:H12)-O12+P12 -> 700292075 | D12: 700406984 | I12: =SUM(J12:N12) -> 0 | O12: =SUM(P12:T12) -> 114909 | Q12: 114909 | U12: 10500
A13: 4 | B13: Фойда ёки зарар орқали ҳаққоний қийматда баҳоланадиган қимматли қоғозлар | C13: =SUM(D13:H13)-O13+P13 -> 454589171 | D13: 454589171 | I13: =SUM(J13:N13) -> 0 | O13: =SUM(P13:T13) -> 0 | Q13: 0 | U13: 10700
A14: 5 | B14: Бошқа умумлашган даромад орқали ҳаққоний қийматда баҳоланадиган қимматли қоғозларга қилинган инвестициялар | C14: =SUM(D14:H14)-O14+P14 -> 0 | D14: 0 | I14: =SUM(J14:N14) -> 0 | O14: =SUM(P14:T14) -> 0 | U14: 10800
A15: 6 | B15: Олди-сотдига мўлжалланган қимматбаҳо металлар, тошлар ва тангалар | C15: =SUM(D15:H15)-O15+P15 -> 175 | D15: 175 | I15: =SUM(J15:N15) -> 0 | O15: =SUM(P15:T15) -> 0 | Q15: 0 | U15: 10900
A16: 7 | B16: Сотиб олинган дебиторлик қарзлари — Факторинг | C16: =SUM(D16:H16)-O16+P16 -> 0 | D16: 0 | E16: 183563 | F16: 0 | G16: 0 | H16: 4750 | I16: =SUM(J16:N16) -> 188313.39 | J16: 0 | K16: 0 | L16: 0 | M16: 0 | N16: 188313.39 | O16: =SUM(P16:T16) -> 188313 | P16: 0 | Q16: 0 | R16: 0 | S16: 0 | T16: 188313 | U16: 11100
A17: 8 | B17: Мижозларнинг аккредитив ва/ёки траст ҳужжатлари билан кафолатланган тратталари бўйича мажбуриятлари | C17: =SUM(D17:H17)-O17+P17 -> 0 | I17: =SUM(J17:N17) -> 0 | O17: =SUM(P17:T17) -> 0 | U17: 11500
A18: 9 | B18: Банкнинг тўланмаган акцептлари бўйича мижозларнинг мажбуриятлари | C18: =SUM(D18:H18)-O18+P18 -> 0 | I18: =SUM(J18:N18) -> 0 | O18: =SUM(P18:T18) -> 0 | U18: 11700
A19: 10 | B19: РЕПО битимлари бўйича сотиб олинган қимматли қоғозлар | C19: =SUM(D19:H19)-O19+P19 -> 0 | I19: =SUM(J19:N19) -> 0 | O19: =SUM(P19:T19) -> 0 | U19: 11800
A20: 11 | B20: Марказий банкка берилган қисқа муддатли кредитлар | C20: =SUM(D20:H20)-O20+P20 -> 0 | I20: =SUM(J20:N20) -> 0 | O20: =SUM(P20:T20) -> 0 | U20: 11900
A21: 12 | B21: Бошқа банкларга берилган қисқа муддатли кредитлар | C21: =SUM(D21:H21)-O21+P21 -> 0 | I21: =SUM(J21:N21) -> 0 | O21: =SUM(P21:T21) -> 0 | U21: 12100
A22: 13 | B22: Ҳукуматга берилган қисқа муддатли кредитлар | C22: =SUM(D22:H22)-O22+P22 -> 0 | I22: =SUM(J22:N22) -> 0 | O22: =SUM(P22:T22) -> 0 | U22: 12300
A23: 14 | B23: Бюджет ташкилотларига берилган қисқа муддатли кредитлар | C23: =SUM(D23:H23)-O23+P23 -> 0 | I23: =SUM(J23:N23) -> 0 | O23: =SUM(P23:T23) -> 0 | U23: 12400
A24: 15 | B24: Жисмоний шахсларга берилган қисқа муддатли кредитлар | C24: =SUM(D24:H24)-O24+P24 -> 383237356 | D24: 378063913 | E24: 4823632 | F24: 821898 | G24: 1369300 | H24: 4282209 | I24: =SUM(J24:N24) -> 8112707.6 | J24: 526809.69 | K24: 990227.2 | L24: 640824.35 | M24: 857444.22 | N24: 5097402.1 | O24: =SUM(P24:T24) -> 6123596 | P24: 0 | Q24: 1076144 | R24: 337057 | S24: 437597 | T24: 4272798 | U24: 12500
A25: 16 | B25: Якка тартибдаги тадбиркорларга берилган қисқа муддатли кредитлар | C25: =SUM(D25:H25)-O25+P25 -> 65514141 | D25: 63519491 | E25: 2040261 | F25: 0 | G25: 329940 | H25: 395189 | I25: =SUM(J25:N25) -> 1699549.3 | J25: 14205.282 | K25: 237055.23 | L25: 449966.65 | M25: 252266.25 | N25: 746055.93 | O25: =SUM(P25:T25) -> 770740 | P25: 0 | Q25: 0 | R25: 0 | S25: 0 | T25: 770740 | U25: 12600
A26: 17 | B26: Давлат корхоналари, ташкилотлари ва муассасаларига берилган қисқа муддатли кредитлар | C26: =SUM(D26:H26)-O26+P26 -> 59374260 | D26: 58485371 | E26: 888889 | F26: 0 | G26: 0 | H26: 160630 | I26: =SUM(J26:N26) -> 7716185.3 | J26: 6666666.7 | K26: 0 | L26: 0 | M26: 0 | N26: 1049518.7 | O26: =SUM(P26:T26) -> 160630 | P26: 0 | Q26: 0 | R26: 0 | S26: 0 | T26: 160630 | U26: 12700
A27: 18 | B27: Тадбиркорлик фаолиятини қўллаб-қувватлаш давлат жамғармаси кўмагида берилган қисқа муддатли кредитлар | C27: =SUM(D27:H27)-O27+P27 -> 0 | I27: =SUM(J27:N27) -> 0 | O27: =SUM(P27:T27) -> 0 | U27: 12800
A28: 19 | B28: Чет эл капитали иштирокидаги корхоналарга берилган қисқа муддатли кредитлар | C28: =SUM(D28:H28)-O28+P28 -> 72927570 | D28: 72927570 | E28: 0 | F28: 0 | G28: 0 | H28: 0 | I28: =SUM(J28:N28) -> 0 | O28: =SUM(P28:T28) -> 0 | U28: 12900
A29: 20 | B29: Нодавлат нотижорат ташкилотларига берилган қисқа муддатли кредитлар | C29: =SUM(D29:H29)-O29+P29 -> 9281 | D29: 9281 | I29: =SUM(J29:N29) -> 0 | O29: =SUM(P29:T29) -> 0 | U29: 13000
A30: 21 | B30: Хусусий корхоналар, хўжалик ширкатлари ва жамиятларга берилган қисқа муддатли кредитлар | C30: =SUM(D30:H30)-O30+P30 -> 789333227 | D30: 690124253 | E30: 105508450 | F30: 4352 | G30: 8202915 | H30: 12504914 | I30: =SUM(J30:N30) -> 82572149 | J30: 4714828.2 | K30: 32388114 | L30: 15028124 | M30: 13255816 | N30: 17185267 | O30: =SUM(P30:T30) -> 27011657 | P30: 0 | Q30: 5633149 | R30: 178592 | S30: 354468 | T30: 20845448 | U30: 13100
A31: 22 | B31: Банк бўлмаган молиявий муассасаларга берилган қисқа муддатли кредитлар | C31: =SUM(D31:H31)-O31+P31 -> 0 | I31: =SUM(J31:N31) -> 0 | O31: =SUM(P31:T31) -> 0 | U31: 13200
A32: 23 | B32: Давлат эҳтиёжлари учун харид қилинадиган қишлоқ хўжалиги маҳсулотларини етиштириш учун берилган қисқа муддатли кредитлар | C32: =SUM(D32:H32)-O32+P32 -> 0 | I32: =SUM(J32:N32) -> 0 | O32: =SUM(P32:T32) -> 0 | U32: 13300
A33: 24 | B33: Давлат эҳтиёжлари учун харид қилинадиган қишлоқ хўжалиги маҳсулотларини етиштириш учун берилган узоқ муддатли кредитлар | C33: =SUM(D33:H33)-O33+P33 -> 0 | I33: =SUM(J33:N33) -> 0 | O33: =SUM(P33:T33) -> 0 | U33: 14300
A34: 25 | B34: Тадбиркорлик фаолиятини қўллаб-қувватлаш давлат жамғармаси кўмагида берилган узоқ муддатли кредитлар | C34: =SUM(D34:H34)-O34+P34 -> 162669466 | D34: 119077712 | E34: 45499543 | F34: 0 | G34: 0 | H34: 0 | I34: =SUM(J34:N34) -> 2179410.4 | J34: 49856.829 | K34: 785109.17 | L34: 0 | M34: 1344444.4 | N34: 0 | O34: =SUM(P34:T34) -> 1907789 | P34: 0 | Q34: 1907789 | R34: 0 | S34: 0 | T34: 0 | U34: 14400
A35: 26 | B35: Бошқа банкларга берилган узоқ муддатли кредитлар | C35: =SUM(D35:H35)-O35+P35 -> 0 | I35: =SUM(J35:N35) -> 0 | O35: =SUM(P35:T35) -> 0 | U35: 14500
A36: 27 | B36: Ҳукуматга берилган узоқ муддатли кредитлар | C36: =SUM(D36:H36)-O36+P36 -> 0 | I36: =SUM(J36:N36) -> 0 | O36: =SUM(P36:T36) -> 0 | U36: 14700
A37: 28 | B37: Бюджет ташкилотларига берилган узоқ муддатли кредитлар | C37: =SUM(D37:H37)-O37+P37 -> 0 | I37: =SUM(J37:N37) -> 0 | O37: =SUM(P37:T37) -> 0 | U37: 14800
A38: 29 | B38: Жисмоний шахсларга берилган узоқ муддатли кредитлар | C38: =SUM(D38:H38)-O38+P38 -> 4105373163 | D38: 3233013525 | E38: 586290005 | F38: 81600165 | G38: 200513239 | H38: 90607369 | I38: =SUM(J38:N38) -> 2.0274573e+08 | J38: 7579674.7 | K38: 26649808 | L38: 28741203 | M38: 37634267 | N38: 1.0214078e+08 | O38: =SUM(P38:T38) -> 106138404 | P38: 19487264 | Q38: 18853326 | R38: 7896707 | S38: 17763216 | T38: 42137891 | U38: 14900
A39: 30 | B39: Якка тартибдаги тадбиркорларга берилган узоқ муддатли кредитлар | C39: =SUM(D39:H39)-O39+P39 -> 167492533 | D39: 88474406 | E39: 47325847 | F39: 2502571 | G39: 25544894 | H39: 23012236 | I39: =SUM(J39:N39) -> 46055608 | J39: 577958.62 | K39: 3986770.2 | L39: 2158207.8 | M39: 4339938.1 | N39: 34992734 | O39: =SUM(P39:T39) -> 19367421 | P39: 0 | Q39: 1208102 | R39: 540345 | S39: 6549972 | T39: 11069002 | U39: 15000
A40: 31 | B40: Давлат корхоналари, ташкилотлари ва муассасаларига берилган узоқ муддатли кредитлар | C40: =SUM(D40:H40)-O40+P40 -> 218360021 | D40: 214884018 | E40: 3438109 | F40: 0 | G40: 75789 | H40: 0 | I40: =SUM(J40:N40) -> 665592.86 | J40: 0 | K40: 466184.34 | L40: 0 | M40: 0 | N40: 199408.52 | O40: =SUM(P40:T40) -> 37895 | P40: 0 | Q40: 0 | R40: 0 | S40: 37895 | T40: 0 | U40: 15100
A41: 32 | B41: Нодавлат нотижорат ташкилотларига берилган узоқ муддатли кредитлар | C41: =SUM(D41:H41)-O41+P41 -> 5116454 | D41: 2017159 | E41: 3099295 | F41: 0 | G41: 0 | H41: 0 | I41: =SUM(J41:N41) -> 9280.554 | J41: 9280.554 | K41: 0 | L41: 0 | M41: 0 | N41: 0 | O41: =SUM(P41:T41) -> 0 | P41: 0 | Q41: 0 | R41: 0 | S41: 0 | T41: 0 | U41: 15200
...

Sheet Income 
A1: МОЛИЯВИЙ НАТИЖАЛАР ТЎҒРИСИДА ҲИСОБОТ | E1: 3-жадвал
B3: =+'Asset quality'!B3 -> "МКБАНК" | D3: =+'Asset quality'!Q3 -> 44926 | E3: =+'Asset quality'!T3 -> минг. сўмда
A4: № | B4: Кўрсаткичлар | C4: Жами | D4: миллий валютада | E4: хорижий валютада (экв. сўмда)
A5: 1. | B5: ФОИЗЛИ ДАРОМАДЛАР
A6: a. | B6: Марказий банкдаги ҳисобварақлар бўйича фоизли даромадлар | C6: =+D6+E6 -> 31527277 | D6: 31527277
A7: б. | B7: Бошқа банклардаги ҳисобварақлар бўйича фоизли даромадлар | C7: =+D7+E7 -> 25430621 | D7: 25430621
A8: в. | B8: Амортизацияланган қиймати бўйича баҳоланадиган қарз қимматли қоғозларга қилинган инвестициялар бўйича фоизли даромадлар | C8: =+D8+E8 -> 0 | D8: 0
A9: г. | B9: Қимматли қоғозлар ва уларга қилинган инвестициялар бўйича фоизли даромадлар | C9: =+D9+E9 -> 71587753 | D9: 71587753
A10: д. | B10: Мижозларнинг мажбуриятлари бўйича ҳисобланган фоизлар | C10: =+D10+E10 -> 0 | D10: 0
A11: е. | B11: Банкнинг тўланмаган акцептлари юзасидан мижозлар мажбуриятлари бўйича фоизли даромадлар | C11: =+D11+E11 -> 0 | D11: 0
A12: ж. | B12: Кредит ва лизинг операциялари бўйича фоизлар, дисконтлар (чегирмалар) ва бадаллар | C12: =+D12+E12 -> 1753677130 | D12: 1753677130
A13: з. | B13: Қимматли қоғозлар билан амалга оширилган РЕПО битимлари бўйича фоизли даромадлар | C13: =+D13+E13 -> 0 | D13: 0
A14: и. | B14: Бошқа фоизли даромадлар | C14: =+D14+E14 -> 706809173 | D14: 706809173
A15: к. | B15: Жами фоизли даромадлар | C15: =SUM(C6:C14) -> 2589031954 | D15: =SUM(D6:D14) -> 2589031954 | E15: =SUM(E6:E14) -> 0 | G15: =+'Analysis of Interest'!C42 -> 2589031954
A17: 2. | B17: ФОИЗЛИ ХAРAЖAТЛAР
A18: а. | B18: Талаб қилиб олингунча сақланадиган депозитлар бўйича фоизли харажатлар | C18: =+D18+E18 -> 30667852 | D18: 30667852
A19: б. | B19: Муддатли депозитлар бўйича фоизли харажатлар | C19: =+D19+E19 -> 453954471 | D19: 453954471
A20: в. | B20: Марказий банкнинг ҳисобварақлари бўйича фоизли харажатлар | C20: =+D20+E20 -> 0 | D20: 0
A21: г. | B21: Бошқа банкларнинг ҳисобварақлари бўйича фоизли харажатлар | C21: =+D21+E21 -> 204078097 | D21: 204078097
A22: д. | B22: Жами депозитлар бўйича фоизли харажатлар | C22: =SUM(C18:C21) -> 688700420 | D22: =SUM(D18:D21) -> 688700420 | E22: =SUM(E18:E21) -> 0
A23: е. | B23: Кредитлар бўйича фоизли харажатлар | C23: =+D23+E23 -> 369289967 | D23: 369289967
A24: ж. | B24: Қимматли қоғозлар билан амалга оширилган РЕПО битимлари бўйича фоизли харажатлар | C24: =+D24+E24 -> 92658 | D24: 92658
A25: з. | B25: Бошқа фоизли харажатлар | C25: =+D25+E25 -> 700206313 | D25: 700206313
A26: и. | B26: Жами кредит ва бошқа қарздорликлар бўйича фоизли харажатлар | C26: =SUM(C23:C25) -> 1069588938 | D26: =SUM(D23:D25) -> 1069588938 | E26: =SUM(E23:E25) -> 0
A27: к. | B27: Жами фоизли харажатлар | C27: =C26+C22 -> 1758289358 | D27: =D26+D22 -> 1758289358 | E27: =E26+E22 -> 0 | G27: =+'Analysis of Interest'!C72 -> 1758289358
A29: 3. | B29: Активлар бўйича эҳтимолий йўқотишларга қарши яратилган захираларни баҳолашдан олдинги соф даромад | C29: =C15-C27 -> 830742596 | D29: =D15-D27 -> 830742596 | E29: =E15-E27 -> 0
A30: а. | B30: Минус: Кредит ва лизинглар бўйича кўрилиши мумкин бўлган зарарларни баҳолаш | C30: =+D30+E30 -> 525252371 | D30: 525252371
A31: б. | B31: Минус: Қимматли қоғозлар бўйича кўрилиши мумкин бўлган зарарларни баҳолаш | C31: =+D31+E31 -> 0 | D31: 0
A32: в. | B32: Минус: Инвестициялар бўйича кўрилиши мумкин бўлган зарарларни баҳолаш | C32: =+D32+E32 -> 0 | D32: 0
A33: г. | B33: Минус: Бошқа активлар бўйича кўрилиши мумкин бўлган зарарларни баҳолаш | C33: =+D33+E33 -> 5597996 | D33: 5597996
A34: д. | B34: Активлар бўйича эҳтимолий зарарларни баҳолашдан кейинги соф даромад | C34: =C29-C30-C31-C32-C33 -> 299892229 | D34: =D29-D30-D31-D32-D33 -> 299892229 | E34: =E29-E30-E31-E32-E33 -> 0
A36: 4. | B36: ФОИЗСИЗ ДАРОМАДЛАР
A37: а. | B37: Кўрсатилган хизматлар ва воситачилик учун олинган даромадлар | C37: =+D37+E37 -> 189651306 | D37: 189651306 | E37: 0
A38: б. | B38: Хорижий валюталардаги фойда | C38: =+D38+E38 -> 399827990 | D38: 0 | E38: 399827990
A39: в. | B39: Тижорат операцияларидан олинган фойда | C39: =+D39+E39 -> 0 | D39: 0 | E39: 0
A40: г. | B40: Инвестициядан олинган фойда ва дивидендлар | C40: =+D40+E40 -> 578356 | D40: 578356 | E40: 0
A41: д. | B41: Бошқа фоизсиз даромадлар | C41: =+D41+E41 -> 296911314 | D41: 296911314 | E41: 0
B42: шундан | D42: 0 | E42: 0
A43: д1. | B43: Активлар бўйича эҳтимолий йўқотишларга қарши яратилган захираларни қайтарилиши | C43: =+D43+E43 -> 288590517 | D43: 288590517 | E43: 0
A44: д2. | B44: Ҳисобдан чиқарилган кредитлар қайтарилиши билан боғлиқ даромадлар | C44: =+D44+E44 -> 0 | D44: 0 | E44: 0
...

Sheet Analysis of Interest
B1: ФОИЗЛИ ДАРОМАД ВА ХАРАЖАТЛАР ТАҲЛИЛИ | C1: 4-жадвал
B3: =+'Asset quality'!B3 -> "МКБАНК" | C3: =+'Asset quality'!Q3 -> 44926
A4: № | B4: Кўрсаткичлар | C4: =+'Asset quality'!T3 -> минг. сўмда
A5: 1. | B5: КРЕДИТ ВА ЛИЗИНГ ОПЕРАЦИЯЛАРИ БЎЙИЧА ФОИЗЛИ ДАРОМАДЛАР
A6: a. | B6: Марказий банкка берилган қисқа муддатли кредитлар | C6: 0
A7: б. | B7: Бошқа банкларга берилган кредитлар | C7: 14242
A8: в. | B8: Ҳукуматга берилган кредитлар | C8: 374
A9: г. | B9: Жисмоний шахсларга берилган кредит ва лизинглар | C9: 608248395
A10: д. | B10: Давлат корхоналарига берилган кредит ва лизинглар | C10: 13041010
A11: е. | B11: Қўшма ва чет эл капитали иштирокидаги корхоналарга берилган кредит ва лизинглар | C11: 11673505
A12: ж. | B12: Хусусий корхоналар, хўжалик ширкатлари ва жамиятларга берилган кредит ва лизинглар | C12: 1065990214
A13: з. | B13: Бошқа кредит ва лизинглар | C13: 54709389
A14: и. | B14: Жами кредит ва лизинг операциялари бўйича фоизли даромад | C14: =SUM(C6:C13) -> 1753677129
A16: 2. | B16: ВАКИЛЛИК ҲИСОБВАРАҚЛАРИ БЎЙИЧА ФОИЗЛИ ДАРОМАДЛАР
A17: a. | B17: Марказий банкдаги ҳисобварақлар бўйича фоизли даромадлар | C17: 31527277
A18: б. | B18: Бошқа банклардаги ҳисобварақлар бўйича фоизли даромадлар | C18: 25430621
B19: Жами вакиллик ҳисобварағи бўйича фоизли даромадлар | C19: =SUM(C17:C18) -> 56957898
A21: 3. | B21: ҚИММАТЛИ ҚОҒОЗЛАР ВА УЛАРГА ҚИЛИНГАН ИНВЕСТИЦИЯЛАР БЎЙИЧА ФОИЗЛИ ДАРОМАДЛАР
A22: a. | B22: Давлат қимматли қоғозлари | C22: 1547182
A23: б. | B23: Марказий банкнинг облигациялари ва бошқа қимматли қоғозлари | C23: 70040571
A24: в. | B24: Давлат корхоналарининг қарз қимматли қоғозлари бўйича фоизли даромадлар | C24: 0
A25: г. | B25: Еврооблигациялар бўйича фоизли даромадлар | C25: 0
A26: д. | B26: Хусусий корхоналарнинг қимматли қоғозлари | C26: 0
A27: е. | B27: Бошқа қимматли қоғозлар | C27: 0
A28: ж. | B28: Жами олди-сотди қимматли қоғозлар бўйича фоизли даромадлар | C28: =SUM(C22:C27) -> 71587753
A30: 4. | B30: ИНВЕСТИЦИЯЛАР БЎЙИЧА ФОИЗЛИ ДАРОМАДЛАР
A31: a. | B31: Давлат қимматли қоғозлари | C31: 0
A32: б. | B32: Марказий банкнинг облигациялари ва бошқа қарз қимматли қоғозларига қилинган инвестициялар бўйича фоизли даромадлар | C32: 0
A33: в. | B33: Корхоналарнинг қарз қимматли қоғозларига қилинган инвестициялар бўйича фоизли даромадлар | C33: 0
A34: г. | B34: Еврооблигациялар | C34: 0
A35: д. | B35: Бошқа қимматли қоғозлар | C35: 0
A36: е. | B36: Жами инвестициялар бўйича фоизли даромадлар | C36: =SUM(C31:C35) -> 0
A38: 5. | B38: БОШҚА ФОИЗЛИ ДАРОМАДЛАР
A39: a. | B39: Қимматли қоғозлар билан амалга оширилган репо битимлари бўйича фоизли даромадлар | C39: 0
A40: б. | B40: Бошқа фоизли даромадлар | C40: 706809174
A42: 6. | B42: ЖАМИ ФОИЗЛИ ДАРОМАДЛАР | C42: =C14+C19+C28+C36+C39+C40 -> 2589031954
A44: 7. | B44: ДЕПОЗИТЛАР БЎЙИЧА ФОИЗЛИ ХАРАЖАТЛАР
A45: A. | B45: Талаб қилиб олингунча сақланадиган депозитлар
A46: a. | B46: Ҳукумат | C46: 0
A47: б. | B47: Жисмоний шахслар | C47: 205
...

Sheet Changes in Equity
A1: ХУСУСИЙ КАПИТАЛДАГИ ЎЗГАРИШЛАР | C1: 7-жадвал
B3: =+'Asset quality'!B3 -> "МКБАНК" | C3: =+'Asset quality'!Q3 -> 44926
A4: № | B4: Кўрсаткичлар | C4: =+'Asset quality'!T3 -> минг. сўмда
A5: 1. | B5: Ўтган йил учун дастлабки ҳисобланган умумий капитал | C5: 2321096229
A6: 2. | B6: Хусусий капиталдаги ўтган йил учун ҳисоботларда кўрсатилмаган тузатишлар, (соф) | C6: 0
A7: 3. | B7: Ўтган календар йили якуни бўйича балансдаги тузатишлар (3=1-2 ) | C7: =SUM(C5:C6) -> 2321096229
A8: 4. | B8: Йил бошидан соф фойда (зарар) | C8: =+'Income '!C78 -> 21314665 | D8: =+[8]Balance!$C$77 -> 21314665 | E8: =+C8-D8 -> 0
A9: 5. | B9: Жорий йилда сотиш, айирбошлаш, сотиб олиш ёки қайтиб сотиб олиш (соф кирим) | C9: 1350190918
A10: 6. | B10: Жорий йил учун бошланғич қийматига нисбатан баҳолаш қийматининг ошган суммаси | C10: -1407510
A11: 7. | B11: МИНУС: Имтиёзли акциялар бўйича эълон қилинган пул дивидендлари | C11: 0
A12: 8. | B12: МИНУС: Оддий акциялар бўйича эълон қилинган пуллик дивидендлар
A13: 9. | B13: Жорий йилнинг соф хусусий капиталига таъсир этувчи бошқа моддалар | C13: -47283221
A14: 10. | B14: Жорий давр якуни бўйича жами хусусий капитал | C14: =C7+SUM(C8:C10)-SUM(C11:C12)+C13 -> 3643911081 | D14: =+[8]Balance!$C$78 -> 3643911081 | E14: =+C14-D14 -> 0
B16: Бошқарув Раис имзоси:
B18: Бош бухгалтер имзоси:

Sheet Loans Receivable
A1: ИҚТИСОДИЁТ ТАРМОҚЛАРИ, МИЖОЗЛАР ТУРЛАРИ, ВА ТАЪМИНОТ ТУРЛАРИ БЎЙИЧА АЖРАТИЛГАН КРЕДИТЛАР ВА ЛИЗИНГЛАР ҲИСОБОТИ | W1: 8-жадвал
B3: =+'Asset quality'!B3 -> "МКБАНК" | T3: =+'Asset quality'!Q3 -> 44926 | X3: =+'Asset quality'!T3 -> минг. сўмда
A4: № | B4: Иқтисодиёт тармоқлари бўйича | C4: Кредит суммаси | D4: шундан | F4: шундан муаммоли кредитлар | J4: шундан
D5: миллий валютада | E5: хорижий валютада (экв. сўмда) | F5: NPL | G5: шундан | J5: Депозитлар | K5: Ўзбекистон Республикаси Ҳукумати тамонидан кафолатланган кредитлар | L5: шундан | M5: Транспорт воситалари | N5: Инвентарлар | O5: Кўчмас мулк | P5: шундан | R5: Асбоб ускуналар | S5: Векселлар (облигациялар) | T5: Акциялар | U5: Учинчи шахс кафолати | V5: Учинчи шахс кафиллиги | W5: Суғурта полиси | X5: Таъминотсиз | Y5: Бошқа кафолатлар
G6: Қониқарсиз | H6: Шубҳали | I6: Умидсиз | L6: Ўзбекистон Республикаси Ҳукумати томонидан кафолатланган хорижий валютадаги (эквивалент сўмда) кредитлар | P6: турар жой (хонадон) | Q6: тижорат кўчмас мулки
A7: Код | B7: (А) | C7: (Б) | D7: (Б1) | E7: (Б3) | F7: (В) | G7: (В1) | H7: (В2) | I7: (В3) | J7: (Г) | K7: (Д) | L7: (Д1) | M7: (Е) | N7: (Ж) | O7: (З) | P7: (З1) | Q7: (З2) | R7: (И) | S7: (К) | T7: (Л) | U7: (М) | V7: (Н) | W7: (О) | X7: (П) | Y7: (Р)
B8: Саноат
A9: 10 | B9: Давлат корхоналари | C9: =SUM(J9:Y9)-L9-P9-Q9 -> 0 | D9: 0 | E9: 0 | F9: =+G9+H9+I9 -> 0 | G9: 0 | H9: 0 | I9: 0 | J9: 0 | K9: 0 | L9: 0 | M9: 0 | N9: 0 | O9: =+P9+Q9 -> 0 | P9: 0 | Q9: 0 | R9: 0 | S9: 0 | T9: 0 | U9: 0 | V9: 0 | W9: 0 | X9: 0 | Y9: 0
A10: =A9+10 -> 20 | B10: Қўшма ва чет эл капитали иштирокидаги корхоналар | C10: =SUM(J10:Y10)-L10-P10-Q10 -> 739146908 | D10: 434659629 | E10: 304487279 | F10: =+G10+H10+I10 -> 5592809 | G10: 394255 | H10: 2325827 | I10: 2872727 | J10: 0 | K10: 0 | L10: 0 | M10: 13362330 | N10: 0 | O10: =+P10+Q10 -> 553524732 | P10: 920000 | Q10: 552604732 | R10: 0 | S10: 0 | T10: 0 | U10: 0 | V10: 2753900 | W10: 18622606 | X10: 0 | Y10: 150883340
A11: =A10+10 -> 30 | B11: Хусусий корхоналар | C11: =SUM(J11:Y11)-L11-P11-Q11 -> 2890969465 | D11: 1361781789 | E11: 1529187676 | F11: =+G11+H11+I11 -> 81614189 | G11: 10755201 | H11: 37591348 | I11: 33267640 | J11: 475339 | K11: 0 | L11: 0 | M11: 142642986 | N11: 0 | O11: =+P11+Q11 -> 2367942755 | P11: 155983697 | Q11: 2211959058 | R11: 9660347 | S11: 0 | T11: 0 | U11: 0 | V11: 94693776 | W11: 270224760 | X11: 0 | Y11: 5329502
A12: =A11+10 -> 40 | B12: Ҳукумат | C12: =SUM(J12:Y12)-L12-P12-Q12 -> 0 | D12: 0 | E12: 0 | F12: =+G12+H12+I12 -> 0 | G12: 0 | H12: 0 | I12: 0 | J12: 0 | K12: 0 | L12: 0 | M12: 0 | N12: 0 | O12: =+P12+Q12 -> 0 | P12: 0 | Q12: 0 | R12: 0 | S12: 0 | T12: 0 | U12: 0 | V12: 0 | W12: 0 | X12: 0 | Y12: 0
A13: =A12+10 -> 50 | B13: Бошқалар | C13: =SUM(J13:Y13)-L13-P13-Q13 -> 0 | D13: 0 | E13: 0 | F13: =+G13+H13+I13 -> 0 | G13: 0 | H13: 0 | I13: 0 | J13: 0 | K13: 0 | L13: 0 | M13: 0 | N13: 0 | O13: =+P13+Q13 -> 0 | P13: 0 | Q13: 0 | R13: 0 | S13: 0 | T13: 0 | U13: 0 | V13: 0 | W13: 0 | X13: 0 | Y13: 0
A14: =A13+10 -> 60 | B14: Жами | C14: =SUM(J14:Y14)-L14-P14-Q14 -> 3630116373 | D14: =SUM(D9:D13) -> 1796441418 | E14: =SUM(E9:E13) -> 1833674955 | F14: =+G14+H14+I14 -> 87206998 | G14: =SUM(G9:G13) -> 11149456 | H14: =SUM(H9:H13) -> 39917175 | I14: =SUM(I9:I13) -> 36140367 | J14: =SUM(J9:J13) -> 475339 | K14: =SUM(K9:K13) -> 0 | L14: =SUM(L9:L13) -> 0 | M14: =SUM(M9:M13) -> 156005316 | N14: =SUM(N9:N13) -> 0 | ... Y14: =SUM(Y9:Y13) -> 156212842
B15: Қишлоқ хўжалиги
A16: 70 | B16: Давлат корхоналари | C16: =SUM(J16:Y16)-L16-P16-Q16 -> 50191388 | D16: 50191388 | E16: 0 | F16: =+G16+H16+I16 -> 572474 | G16: 572474 | H16: 0 | I16: 0 | J16: 0 | K16: 0 | L16: 0 | M16: 0 | N16: 0 | O16: =+P16+Q16 -> 0 | P16: 0 | Q16: 0 | R16: 0 | S16: 0 | T16: 0 | U16: 0 | V16: 48605580 | W16: 0 | X16: 1585808 | Y16: 0
A17: =A16+10 -> 80 | B17: Қўшма ва чет эл капитали иштирокидаги корхоналар | C17: =SUM(J17:Y17)-L17-P17-Q17 -> 346526466 | D17: 169339753 | E17: 177186713 | F17: =+G17+H17+I17 -> 1719054 | G17: 468806 | H17: 956826 | I17: 293422 | J17: 0 | K17: 0 | L17: 0 | M17: 1690081 | N17: 0 | O17: =+P17+Q17 -> 343059623 | P17: 0 | Q17: 343059623 | R17: 0 | S17: 0 | T17: 0 | U17: 0 | V17: 798687 | W17: 978075 | X17: 0 | Y17: 0
A18: =A17+10 -> 90 | B18: Хусусий корхоналар | C18: =SUM(J18:Y18)-L18-P18-Q18 -> 1221112377 | D18: 780190386 | E18: 440921991 | F18: =+G18+H18+I18 -> 49974130 | G18: 7623382 | H18: 20774441 | I18: 21576307 | J18: 0 | K18: 0 | L18: 0 | M18: 41698378 | N18: 0 | O18: =+P18+Q18 -> 1123848628 | P18: 51136508 | Q18: 1072712120 | R18: 1330897 | S18: 0 | T18: 0 | U18: 0 | V18: 10130994 | W18: 43637715 | X18: 300000 | Y18: 165765
A19: =A18+10 -> 100 | B19: Фермер хўжалиги | C19: =SUM(J19:Y19)-L19-P19-Q19 -> 229585211 | D19: 128315969 | E19: 101269242 | F19: =+G19+H19+I19 -> 10712460 | G19: 761592 | H19: 6869332 | I19: 3081536 | J19: 0 | K19: 0 | L19: 0 | M19: 8396232 | N19: 0 | O19: =+P19+Q19 -> 199166678 | P19: 0 | Q19: 199166678 | R19: 672474 | S19: 0 | T19: 0 | U19: 0 | V19: 1828798 | W19: 19521029 | X19: 0 | Y19: 0
A20: =A19+10 -> 110 | B20: Ҳукумат | C20: =SUM(J20:Y20)-L20-P20-Q20 -> 0 | D20: 0 | E20: 0 | F20: =+G20+H20+I20 -> 0 | G20: 0 | H20: 0 | I20: 0 | J20: 0 | K20: 0 | L20: 0 | M20: 0 | N20: 0 | O20: =+P20+Q20 -> 0 | P20: 0 | Q20: 0 | R20: 0 | S20: 0 | T20: 0 | U20: 0 | V20: 0 | W20: 0 | X20: 0 | Y20: 0
A21: =A20+10 -> 120 | B21: Бошқалар | C21: =SUM(J21:Y21)-L21-P21-Q21 -> 0 | D21: 0 | E21: 0 | F21: =+G21+H21+I21 -> 0 | G21: 0 | H21: 0 | I21: 0 | J21: 0 | K21: 0 | L21: 0 | M21: 0 | N21: 0 | O21: =+P21+Q21 -> 0 | P21: 0 | Q21: 0 | R21: 0 | S21: 0 | T21: 0 | U21: 0 | V21: 0 | W21: 0 | X21: 0 | Y21: 0
A22: =A21+10 -> 130 | B22: Жами | C22: =SUM(J22:Y22)-L22-P22-Q22 -> 1847415442 | D22: =SUM(D16:D21) -> 1128037496 | E22: =SUM(E16:E21) -> 719377946 | F22: =+G22+H22+I22 -> 62405644 | G22: =SUM(G17:G21) -> 8853780 | H22: =SUM(H17:H21) -> 28600599 | I22: =SUM(I17:I21) -> 24951265 | J22: =SUM(J16:J21) -> 0 | K22: =SUM(K16:K21) -> 0 | L22: =SUM(L16:L21) -> 0 | M22: =SUM(M16:M21) -> 51784691 | N22: =SUM(N16:N21) -> 0 | O22: =SUM(O16:O21) -> 1666074929 | P22: =SUM(P16:P21) -> 51136508 | Q22: =SUM(Q16:Q21) -> 1614938421 | ... Y22: =SUM(Y16:Y21) -> 165765
B23: Транспорт ва коммуникация
A24: 140 | B24: Давлат корхоналари | C24: =SUM(J24:Y24)-L24-P24-Q24 -> 9816 | D24: 9816 | E24: 0 | F24: =+G24+H24+I24 -> 0 | G24: 0 | H24: 0 | I24: 0 | J24: 0 | K24: 0 | L24: 0 | M24: 9816 | N24: 0 | O24: =+P24+Q24 -> 0 | P24: 0 | Q24: 0 | R24: 0 | S24: 0 | T24: 0 | U24: 0 | V24: 0 | W24: 0 | X24: 0 | Y24: 0
A25: =A24+10 -> 150 | B25: Қўшма ва чет эл капитали иштирокидаги корхоналар | C25: =SUM(J25:Y25)-L25-P25-Q25 -> 48053102 | D25: 3128811 | E25: 44924291 | F25: =+G25+H25+I25 -> 0 | G25: 0 | H25: 0 | I25: 0 | J25: 13195 | K25: 0 | L25: 0 | M25: 402627 | N25: 0 | O25: =+P25+Q25 -> 47637280 | P25: 0 | Q25: 47637280 | R25: 0 | S25: 0 | T25: 0 | U25: 0 | V25: 0 | W25: 0 | X25: 0 | Y25: 0
A26: =A25+10 -> 160 | B26: Хусусий корхоналар | C26: =SUM(J26:Y26)-L26-P26-Q26 -> 132725910 | D26: 77339149 | E26: 55386761 | F26: =+G26+H26+I26 -> 11697865 | G26: 129890 | H26: 9619736 | I26: 1948239 | J26: 617454 | K26: 0 | L26: 0 | M26: 41077353 | N26: 0 | O26: =+P26+Q26 -> 85122090 | P26: 0 | Q26: 85122090 | R26: 0 | S26: 0 | T26: 0 | U26: 0 | V26: 5024136 | W26: 884877 | X26: 0 | Y26: 0
A27: =A26+10 -> 170 | B27: Ҳукумат | C27: =SUM(J27:Y27)-L27-P27-Q27 -> 0 | D27: 0 | E27: 0 | F27: =+G27+H27+I27 -> 0 | G27: 0 | H27: 0 | I27: 0 | J27: 0 | K27: 0 | L27: 0 | M27: 0 | N27: 0 | O27: =+P27+Q27 -> 0 | P27: 0 | Q27: 0 | R27: 0 | S27: 0 | T27: 0 | U27: 0 | V27: 0 | W27: 0 | X27: 0 | Y27: 0
A28: =A27+10 -> 180 | B28: Бошқалар | C28: =SUM(J28:Y28)-L28-P28-Q28 -> 0 | D28: 0 | E28: 0 | F28: =+G28+H28+I28 -> 0 | G28: 0 | H28: 0 | I28: 0 | J28: 0 | K28: 0 | L28: 0 | M28: 0 | N28: 0 | O28: =+P28+Q28 -> 0 | P28: 0 | Q28: 0 | R28: 0 | S28: 0 | T28: 0 | U28: 0 | V28: 0 | W28: 0 | X28: 0 | Y28: 0
A29: =A28+10 -> 190 | B29: Жами | C29: =SUM(J29:Y29)-L29-P29-Q29 -> 180788828 | D29: =SUM(D24:D28) -> 80477776 | E29: =SUM(E24:E28) -> 100311052 | F29: =+G29+H29+I29 -> 11697865 | G29: =SUM(G24:G28) -> 129890 | H29: =SUM(H24:H28) -> 9619736 | I29: =SUM(I24:I28) -> 1948239 | J29: =SUM(J24:J28) -> 630649 | K29: =SUM(K24:K28) -> 0 | L29: =SUM(L24:L28) -> 0 | M29: =SUM(M24:M28) -> 41489796 | N29: =SUM(N24:N28) -> 0 | ... Y29: =SUM(Y24:Y28) -> 0
B30: Қурилиш соҳаси
A31: 200 | B31: Давлат корхоналари | C31: =SUM(J31:Y31)-L31-P31-Q31 -> 0 | D31: 0 | E31: 0 | F31: =+G31+H31+I31 -> 0 | G31: 0 | H31: 0 | I31: 0 | J31: 0 | K31: 0 | L31: 0 | M31: 0 | N31: 0 | O31: =+P31+Q31 -> 0 | P31: 0 | Q31: 0 | R31: 0 | S31: 0 | T31: 0 | U31: 0 | V31: 0 | W31: 0 | X31: 0 | Y31: 0
A32: =A31+10 -> 210 | B32: Қўшма ва чет эл капитали иштирокидаги корхоналар | C32: =SUM(J32:Y32)-L32-P32-Q32 -> 6101922 | D32: 6101922 | E32: 0 | F32: =+G32+H32+I32 -> 2000000 | G32: 0 | H32: 2000000 | I32: 0 | J32: 0 | K32: 0 | L32: 0 | M32: 0 | N32: 0 | O32: =+P32+Q32 -> 2268589 | P32: 0 | Q32: 2268589 | R32: 0 | S32: 0 | T32: 0 | U32: 0 | V32: 3833333 | W32: 0 | X32: 0 | Y32: 0
A33: =A32+10 -> 220 | B33: Хусусий корхоналар | C33: =SUM(J33:Y33)-L33-P33-Q33 -> 186083068 | D33: 182721043 | E33: 3362025 | F33: =+G33+H33+I33 -> 4751166 | G33: 2327364 | H33: 1046820 | I33: 1376982 | J33: 0 | K33: 0 | L33: 0 | M33: 2838682 | N33: 0 | O33: =+P33+Q33 -> 180332251 | P33: 0 | Q33: 180332251 | R33: 906271 | S33: 0 | T33: 0 | U33: 0 | V33: 185027 | W33: 1820837 | X33: 0 | Y33: 0
A34: =A33+10 -> 230 | B34: Ҳукумат | C34: =SUM(J34:Y34)-L34-P34-Q34 -> 0 | D34: 0 | E34: 0 | F34: =+G34+H34+I34 -> 0 | G34: 0 | H34: 0 | I34: 0 | J34: 0 | K34: 0 | L34: 0 | M34: 0 | N34: 0 | O34: =+P34+Q34 -> 0 | P34: 0 | Q34: 0 | R34: 0 | S34: 0 | T34: 0 | U34: 0 | V34: 0 | W34: 0 | X34: 0 | Y34: 0
A35: =A34+10 -> 240 | B35: Бошқалар | C35: =SUM(J35:Y35)-L35-P35-Q35 -> 0 | D35: 0 | E35: 0 | F35: =+G35+H35+I35 -> 0 | G35: 0 | H35: 0 | I35: 0 | J35: 0 | K35: 0 | L35: 0 | M35: 0 | N35: 0 | O35: =+P35+Q35 -> 0 | P35: 0 | Q35: 0 | R35: 0 | S35: 0 | T35: 0 | U35: 0 | V35: 0 | W35: 0 | X35: 0 | Y35: 0
A36: =A35+10 -> 250 | B36: Жами | C36: =SUM(J36:Y36)-L36-P36-Q36 -> 192184990 | D36: =SUM(D31:D35) -> 188822965 | E36: =SUM(E31:E35) -> 3362025 | F36: =+G36+H36+I36 -> 6751166 | G36: =SUM(G31:G35) -> 2327364 | H36: =SUM(H31:H35) -> 3046820 | I36: =SUM(I31:I35) -> 1376982 | J36: =SUM(J31:J35) -> 0 | K36: =SUM(K31:K35) -> 0 | L36: =SUM(L31:L35) -> 0 | M36: =SUM(M31:M35) -> 2838682 | N36: =SUM(N31:N35) -> 0 | ... Y36: =SUM(Y31:Y35) -> 0
B37: Савдо ва умумий хизмат
A38: 260 | B38: Давлат корхоналари | C38: =SUM(J38:Y38)-L38-P38-Q38 -> 26193826 | D38: 26193826 | E38: 0 | F38: =+G38+H38+I38 -> 331481 | G38: 0 | H38: 170851 | I38: 160630 | J38: 0 | K38: 0 | L38: 0 | M38: 5144726 | N38: 0 | O38: =+P38+Q38 -> 11933777 | P38: 0 | Q38: 11933777 | R38: 7631250 | S38: 0 | T38: 0 | U38: 0 | V38: 551119 | W38: 887652 | X38: 45302 | Y38: 0
A39: =A38+10 -> 270 | B39: Қўшма ва чет эл капитали иштирокидаги корхоналар | C39: =SUM(J39:Y39)-L39-P39-Q39 -> 136885937 | D39: 136418969 | E39: 466968 | F39: =+G39+H39+I39 -> 169027 | G39: 106390 | H39: 30000 | I39: 32637 | J39: 0 | K39: 0 | L39: 0 | M39: 2350795 | N39: 0 | O39: =+P39+Q39 -> 124966280 | P39: 120000 | Q39: 124846280 | R39: 0 | S39: 0 | T39: 0 | U39: 0 | V39: 214730 | W39: 9354132 | X39: 0 | Y39: 0
A40: =A39+10 -> 280 | B40: Хусусий корхоналар | C40: =SUM(J40:Y40)-L40-P40-Q40 -> 1272260302 | D40: 784323057 | E40: 487937245 | F40: =+G40+H40+I40 -> 30250097 | G40: 885051 | H40: 14561177 | I40: 14803869 | J40: 64853 | K40: 0 | L40: 0 | M40: 52271304 | N40: 0 | O40: =+P40+Q40 -> 882774665 | P40: 31636252 | Q40: 851138413 | R40: 1191007 | S40: 0 | T40: 0 | U40: 0 | V40: 34239341 | W40: 283114649 | X40: 564032 | Y40: 18040451
A41: =A40+10 -> 290 | B41: Ҳукумат | C41: =SUM(J41:Y41)-L41-P41-Q41 -> 0 | D41: 0 | E41: 0 | F41: =+G41+H41+I41 -> 0 | G41: 0 | H41: 0 | I41: 0 | J41: 0 | K41: 0 | L41: 0 | M41: 0 | N41: 0 | O41: =+P41+Q41 -> 0 | P41: 0 | Q41: 0 | R41: 0 | S41: 0 | T41: 0 | U41: 0 | V41: 0 | W41: 0 | X41: 0 | Y41: 0
...

Sheet Aging Analysis
A1: ОЛИНИШИ ЛОЗИМ БЎЛГАН МУДДАТИ ЎТГАН КРЕДИТ ВА МОЛИЯВИЙ ЛИЗИНГ ТАҲЛИЛИ | X1: 9-жадвал
B3: =+'Asset quality'!B3 -> "МКБАНК" | T3: =+'Asset quality'!Q3 -> 44926 | X3: =+'Asset quality'!T3 -> минг. сўмда
A4: № | B4: Кўрсаткичлар | C4: Жами кредит суммаси | D4: % | E4: Шартлари қайта кўрилган кредит ва лизинглар | F4: % | G4: Суд жараёнидаги қарздорликлар | H4: % | I4: Муддати ўтган | K4: % | L4: шу жумладан, кечиктирилган муддати бўйича
L5: 1-30 кун | N5: 31-60 кун | P5: 61-90 кун | R5: 91-180 кун | T5: 181-365 кун | V5: 366-730 кун | X5: 2 йилдан ортиқ
I6: асосий қарздорлик | J6: фоиз тўловлари | L6: асосий қарздорлик | M6: фоиз тўловлари | N6: асосий қарздорлик | O6: фоиз тўловлари | P6: асосий қарздорлик | Q6: фоиз тўловлари | R6: асосий қарздорлик | S6: фоиз тўловлари | T6: асосий қарздорлик | U6: фоиз тўловлари | V6: асосий қарздорлик | W6: фоиз тўловлари | X6: асосий қарздорлик | Y6: фоиз тўловлари
B7: (А) | C7: (Б) | D7: (В) | E7: (Г) | F7: (Д) | G7: (Е) | H7: (Ж) | I7: (З) | J7: (З1) | K7: (И) | L7: (К) | M7: (К1) | N7: (Л) | O7: (Л1) | P7: (М) | Q7: (М1) | R7: (Н) | S7: (Н1) | T7: (О) | U7: (О1) | V7: (П) | W7: (П1) | X7: (Р) | Y7: (Р1)
B8: Мижозлар тури бўйича
A9: 1 | B9: Марказий банк | C9: =+'Loans Receivable'!C79 -> 0 | D9: =IF(C$22=0,"",C9/C$22) -> 0 | F9: =IF(E$22=0,"",E9/E$22) -> 0 | H9: =IF($G$22=0,"",G9/$G$22) -> 0 | I9: =+L9+N9+P9+R9+T9+V9+X9 -> 0 | J9: =+M9+O9+T9+S9+U9+W9+Y9 -> 0 | K9: =IF($Z$22=0,"",Z9/$Z$22) -> 0 | Z9: =+I9+J9 -> 0
A10: 2 | B10: Бошқа банклар | C10: =+'Loans Receivable'!C78 -> 0 | D10: =IF(C$22=0,"",C10/C$22) -> 0 | F10: =IF(E$22=0,"",E10/E$22) -> 0 | H10: =IF($G$22=0,"",G10/$G$22) -> 0 | I10: =+L10+N10+P10+R10+T10+V10+X10 -> 0 | J10: =+M10+O10+Q10+S10+U10+W10+Y10 -> 0 | K10: =IF($Z$22=0,"",Z10/$Z$22) -> 0 | Z10: =+I10+J10 -> 0
A11: 3 | B11: Ҳукумат | C11: =+'Loans Receivable'!C80 -> 0 | D11: =IF(C$22=0,"",C11/C$22) -> 0 | F11: =IF(E$22=0,"",E11/E$22) -> 0 | H11: =IF($G$22=0,"",G11/$G$22) -> 0 | I11: =+L11+N11+P11+R11+T11+V11+X11 -> 0 | J11: =+M11+O11+Q11+S11+U11+W11+Y11 -> 0 | K11: =IF($Z$22=0,"",Z11/$Z$22) -> 0 | Z11: =+I11+J11 -> 0
A12: 4 | B12: Жисмоний шахслар | C12: =+'Loans Receivable'!C73 -> 4581385255 | D12: =IF(C$22=0,"",C12/C$22) -> 0.34398338 | F12: =IF(E$22=0,"",E12/E$22) -> 0 | H12: =IF($G$22=0,"",G12/$G$22) -> 0 | I12: =+L12+N12+P12+R12+T12+V12+X12 -> 2.1085844e+08 | J12: =+M12+O12+Q12+S12+U12+W12+Y12 -> 85048575 | K12: =IF($Z$22=0,"",Z12/$Z$22) -> 0.32688121 | L12: 10932587 | M12: 8560888 | N12: 11018434 | O12: 4386200 | P12: 12543620 | Q12: 5251065 | R12: 38240762 | S12: 14467723 | T12: 39156244 | U12: 23036470 | V12: 85180069 | W12: 22209213 | X12: 13786724 | Y12: 7137016 | Z12: =+I12+J12 -> 2.9590701e+08
A13: 5 | B13: Давлат корхоналари | C13: =+'Loans Receivable'!C74 -> 82687816 | D13: =IF(C$22=0,"",C13/C$22) -> 0.0062084354 | F13: =IF(E$22=0,"",E13/E$22) -> 0 | H13: =IF($G$22=0,"",G13/$G$22) -> 0 | I13: =+L13+N13+P13+R13+T13+V13+X13 -> 2066822.8 | J13: =+M13+O13+Q13+S13+U13+W13+Y13 -> 746862 | K13: =IF($Z$22=0,"",Z13/$Z$22) -> 0.0031082085 | L13: 463546.6 | M13: 16439 | N13: 125816.41 | O13: 31075 | P13: 113485.3 | Q13: 25161 | R13: 208582.53 | S13: 167429 | T13: 666867.44 | U13: 114079 | V13: 488524.51 | W13: 392679 | X13: 0 | Z13: =+I13+J13 -> 2813684.8
A14: 6 | B14: Қўшма ва чет эл капитали иштирокидаги корхоналар | C14: =+'Loans Receivable'!C75 -> 1377755770 | D14: =IF(C$22=0,"",C14/C$22) -> 0.10344581 | F14: =IF(E$22=0,"",E14/E$22) -> 0 | H14: =IF($G$22=0,"",G14/$G$22) -> 0 | I14: =+L14+N14+P14+R14+T14+V14+X14 -> 31590360 | J14: =+M14+O14+Q14+S14+U14+W14+Y14 -> 20841990 | K14: =IF($Z$22=0,"",Z14/$Z$22) -> 0.057920729 | L14: 2615925.8 | M14: 6006908 | N14: 14819837 | O14: 3487772 | P14: 1815789.8 | Q14: 3016039 | R14: 6533005.5 | S14: 3965534 | T14: 1754854.5 | U14: 1744428 | V14: 3210289.7 | W14: 1440066 | X14: 840657.55 | Y14: 1181243 | Z14: =+I14+J14 -> 52432350
A15: 7 | B15: Хусусий корхоналар | C15: =+'Loans Receivable'!C76 -> 6847944103 | D15: =IF(C$22=0,"",C15/C$22) -> 0.51416304 | E15: 22445529 | F15: =IF(E$22=0,"",E15/E$22) -> 1 | G15: 39846807 | H15: =IF($G$22=0,"",G15/$G$22) -> 1 | I15: =+L15+N15+P15+R15+T15+V15+X15 -> 3.3556512e+08 | J15: =+M15+O15+Q15+S15+U15+W15+Y15 -> 198979819 | K15: =IF($Z$22=0,"",Z15/$Z$22) -> 0.59049866 | L15: 28391193 | M15: 23981305 | N15: 40664913 | O15: 14994415 | P15: 51823479 | Q15: 50220051 | R15: 75555943 | S15: 22860008 | T15: 47406473 | U15: 21104543 | V15: 83439427 | W15: 55315598 | X15: 8283693.9 | Y15: 10503899 | Z15: =+I15+J15 -> 5.3454494e+08
A16: 8 | B16: Фермер хўжаликлари | C16: =+'Loans Receivable'!C77 -> 229585211 | D16: =IF(C$22=0,"",C16/C$22) -> 0.017237908 | F16: =IF(E$22=0,"",E16/E$22) -> 0 | H16: =IF($G$22=0,"",G16/$G$22) -> 0 | I16: =+L16+N16+P16+R16+T16+V16+X16 -> 10525054 | J16: =+M16+O16+Q16+S16+U16+W16+Y16 -> 6937340 | K16: =IF($Z$22=0,"",Z16/$Z$22) -> 0.019290278 | L16: 472594.91 | M16: 335051 | N16: 1580936.8 | O16: 629719 | P16: 1815401.5 | Q16: 2110473 | R16: 675221.4 | S16: 1171886 | T16: 4037586.8 | U16: 992023 | V16: 1894875.1 | W16: 1681743 | X16: 48437.942 | Y16: 16445 | Z16: =+I16+J16 -> 17462394
A17: 9 | B17: Нобанк молиявий институтлар | C17: =+'Loans Receivable'!C81 -> 0 | D17: =IF(C$22=0,"",C17/C$22) -> 0 | F17: =IF(E$22=0,"",E17/E$22) -> 0 | H17: =IF($G$22=0,"",G17/$G$22) -> 0 | I17: =+L17+N17+P17+R17+T17+V17+X17 -> 0 | J17: =+M17+O17+Q17+S17+U17+W17+Y17 -> 0 | K17: =IF($Z$22=0,"",Z17/$Z$22) -> 0 | L17: 0 | N17: 0 | P17: 0 | R17: 0 | T17: 0 | V17: 0 | X17: 0 | Z17: =+I17+J17 -> 0
A18: 10 | B18: Нодавлат нотижорат ташкилотлар | C18: =+'Loans Receivable'!C82 -> 199265686 | D18: =IF(C$22=0,"",C18/C$22) -> 0.014961432 | F18: =IF(E$22=0,"",E18/E$22) -> 0 | H18: =IF($G$22=0,"",G18/$G$22) -> 0 | I18: =+L18+N18+P18+R18+T18+V18+X18 -> 1493441.9 | J18: =+M18+O18+Q18+S18+U18+W18+Y18 -> 589444 | K18: =IF($Z$22=0,"",Z18/$Z$22) -> 0.0023009128 | L18: 138476.93 | M18: 132352 | N18: 380890.29 | O18: 328210 | P18: 76886.776 | Q18: 53869 | R18: 891457.88 | S18: 52210 | T18: 5729.9743 | U18: 22803 | V18: 0 | X18: 0 | Z18: =+I18+J18 -> 2082885.9
A19: 11 | B19: Бюджет ташкилотлари | C19: =+'Loans Receivable'!C83 -> 0 | D19: =IF(C$22=0,"",C19/C$22) -> 0 | F19: =IF(E$22=0,"",E19/E$22) -> 0 | H19: =IF($G$22=0,"",G19/$G$22) -> 0 | I19: =+L19+N19+P19+R19+T19+V19+X19 -> 0 | J19: =+M19+O19+Q19+S19+U19+W19+Y19 -> 0 | K19: =IF($Z$22=0,"",Z19/$Z$22) -> 0 | Z19: =+I19+J19 -> 0
A20: 12 | B20: Бошқалар | C20: =+'Loans Receivable'!C84 -> 0 | D20: =IF(C$22=0,"",C20/C$22) -> 0 | F20: =IF(E$22=0,"",E20/E$22) -> 0 | H20: =IF($G$22=0,"",G20/$G$22) -> 0 | I20: =+L20+N20+P20+R20+T20+V20+X20 -> 0 | J20: =+M20+O20+Q20+S20+U20+W20+Y20 -> 0 | K20: =IF($Z$22=0,"",Z20/$Z$22) -> 0 | Z20: =+I20+J20 -> 0
Z21: =+I21+J21 -> 0
A22: 13 | B22: Жами кредит ва лизинг суммаси | C22: =SUM(C9:C20) -> 13318623841 | D22: =IF(C$22=0,"",C22/C$22) -> 1 | E22: =SUM(E9:E20) -> 22445529 | F22: =IF(E$22=0,"",E22/E$22) -> 1 | G22: =SUM(G9:G20) -> 39846807 | H22: =IF($G$22=0,"",G22/$G$22) -> 1 | I22: =SUM(I9:I20) -> 592099241 | J22: =SUM(J9:J20) -> 313144030 | K22: =IF($Z$22=0,"",Z22/$Z$22) -> 1 | L22: =SUM(L9:L20) -> 43014325 | M22: =SUM(M9:M20) -> 39032943 | N22: =SUM(N9:N20) -> 68590827 | O22: =SUM(O9:O20) -> 23857391 | P22: =SUM(P9:P20) -> 68188663 | Q22: =SUM(Q9:Q20) -> 60676658 | R22: =SUM(R9:R20) -> 1.2210497e+08 | S22: =SUM(S9:S20) -> 42684790 | ... Y22: =SUM(Y9:Y20) -> 18838603 | Z22: =+I22+J22 -> 905243271
Z23: =+I23+J23 -> 0
B24: Иқтисодиёт соҳалари бўйича | Z24: =+I24+J24 -> 0
A25: 14 | B25: Саноат | C25: =+'Loans Receivable'!C14 -> 3630116373 | D25: =IF(C$35=0,"",C25/C$35) -> 0.27255942 | E25: 2572161 | F25: =IF($E$35=0,"",E25/$E$35) -> 0.1145957 | G25: 9150659 | H25: =IF($G$35=0,"",G25/$G$35) -> 0.22964598 | I25: =+L25+N25+P25+R25+T25+V25+X25 -> 1.3869188e+08 | J25: =+M25+O25+Q25+S25+U25+W25+Y25 -> 95293333 | K25: =IF($Z$35=0,"",Z25/$Z$35) -> 0.25847771 | L25: 8501843.2 | M25: 8905798.9 | N25: 25052517 | O25: 8081340.6 | P25: 21653231 | Q25: 29521374 | R25: 37780244 | S25: 11792556 | T25: 7450404.4 | U25: 7520315.9 | V25: 31929793 | W25: 22042893 | X25: 6323843.2 | Y25: 7429054.3 | Z25: =+I25+J25 -> 2.3398521e+08
A26: 15 | B26: Қишлоқ хўжалиги | C26: =+'Loans Receivable'!C22 -> 1847415442 | D26: =IF(C$35=0,"",C26/C$35) -> 0.13870918 | E26: 1045741 | F26: =IF($E$35=0,"",E26/$E$35) -> 0.046590169 | G26: 9138262 | H26: =IF($G$35=0,"",G26/$G$35) -> 0.22933486 | I26: =+L26+N26+P26+R26+T26+V26+X26 -> 55016872 | J26: =+M26+O26+Q26+S26+U26+W26+Y26 -> 43422471 | K26: =IF($Z$35=0,"",Z26/$Z$35) -> 0.10874352 | L26: 2211351.1 | M26: 4920314.7 | N26: 5774947.8 | O26: 2805291.8 | P26: 7265116.8 | Q26: 10143094 | R26: 8318064.1 | S26: 7149884.3 | T26: 12959420 | U26: 6594788.9 | V26: 17411742 | W26: 10737614 | X26: 1076230.6 | Y26: 1071483.8 | Z26: =+I26+J26 -> 98439343
A27: 16 | B27: Транспорт ва коммуникация | C27: =+'Loans Receivable'!C29 -> 180788828 | D27: =IF(C$35=0,"",C27/C$35) -> 0.013574137 | E27: 0 | F27: =IF($E$35=0,"",E27/$E$35) -> 0 | G27: 3642444 | H27: =IF($G$35=0,"",G27/$G$35) -> 0.091411189 | I27: =+L27+N27+P27+R27+T27+V27+X27 -> 14647043 | J27: =+M27+O27+Q27+S27+U27+W27+Y27 -> 7204394.5 | K27: =IF($Z$35=0,"",Z27/$Z$35) -> 0.024138746 | L27: 1521845.7 | M27: 355832.1 | N27: 711542.72 | O27: 376004.24 | P27: 1506384.8 | Q27: 625726.97 | R27: 490836.9 | S27: 52907.48 | T27: 3151968.7 | U27: 2488672.7 | V27: 6491973.6 | W27: 2713272.5 | X27: 772490.21 | Y27: 591978.51 | Z27: =+I27+J27 -> 21851437
A28: 17 | B28: Қурилиш соҳаси | C28: =+'Loans Receivable'!C36 -> 192184990 | D28: =IF(C$35=0,"",C28/C$35) -> 0.014429793 | E28: 1423986 | F28: =IF($E$35=0,"",E28/$E$35) -> 0.063441855 | G28: 2710259 | H28: =IF($G$35=0,"",G28/$G$35) -> 0.068016968 | I28: =+L28+N28+P28+R28+T28+V28+X28 -> 13507443 | J28: =+M28+O28+Q28+S28+U28+W28+Y28 -> 4591040.5 | K28: =IF($Z$35=0,"",Z28/$Z$35) -> 0.01999295 | L28: 221341.87 | M28: 305857.69 | N28: 520194.6 | O28: 41608.786 | P28: 8615285.4 | Q28: 1579489.8 | R28: 1533640.4 | S28: 494575.57 | T28: 1092330.8 | U28: 730864.55 | V28: 1393053.7 | W28: 584094.57 | X28: 131595.96 | Y28: 854549.57 | Z28: =+I28+J28 -> 18098483
A29: 18 | B29: Савдо ва умумий овқатланиш | C29: =+'Loans Receivable'!C43 -> 1435340065 | D29: =IF(C$35=0,"",C29/C$35) -> 0.1077694 | E29: 14416468 | F29: =IF($E$35=0,"",E29/$E$35) -> 0.64228684 | G29: 4804495 | H29: =IF($G$35=0,"",G29/$G$35) -> 0.12057415 | I29: =+L29+N29+P29+R29+T29+V29+X29 -> 91062704 | J29: =+M29+O29+Q29+S29+U29+W29+Y29 -> 34514035 | K29: =IF($Z$35=0,"",Z29/$Z$35) -> 0.13872154 | L29: 3393241.4 | M29: 4480349.7 | N29: 18162649 | O29: 4793921.8 | P29: 8883634 | Q29: 2279952.3 | R29: 24459580 | S29: 6453487.7 | T29: 19699065 | U29: 3735412 | V29: 15916851 | W29: 11522404 | X29: 547684.66 | Y29: 1248507.4 | Z29: =+I29+J29 -> 1.2557674e+08
A30: 19 | B30: Моддий ва техник таъминотни ривожлантириш | C30: =+'Loans Receivable'!C50 -> 999195681 | D30: =IF(C$35=0,"",C30/C$35) -> 0.075022442 | E30: 2987173 | F30: =IF($E$35=0,"",E30/$E$35) -> 0.13308544 | G30: 10400688 | H30: =IF($G$35=0,"",G30/$G$35) -> 0.26101685 | I30: =+L30+N30+P30+R30+T30+V30+X30 -> 49338696 | J30: =+M30+O30+Q30+S30+U30+W30+Y30 -> 37844280 | K30: =IF($Z$35=0,"",Z30/$Z$35) -> 0.096308891 | L30: 15144845 | M30: 11140632 | N30: 5974470 | O30: 2852965.8 | P30: 4204043.8 | Q30: 10556141 | R30: 8026791.6 | S30: 1691014 | T30: 4202624.9 | U30: 1714924.8 | V30: 11623830 | W30: 9382588.5 | X30: 162090.79 | Y30: 506013.45 | Z30: =+I30+J30 -> 87182975
A31: 20 | B31: Уй-жой коммунал хизмати | C31: =+'Loans Receivable'!C58 -> 104803073 | D31: =IF(C$35=0,"",C31/C$35) -> 0.0078689116 | F31: =IF($E$35=0,"",E31/$E$35) -> 0 | H31: =IF($G$35=0,"",G31/$G$35) -> 0 | I31: =+L31+N31+P31+R31+T31+V31+X31 -> 0 | J31: =+M31+O31+Q31+S31+U31+W31+Y31 -> 22664.873 | K31: =IF($Z$35=0,"",Z31/$Z$35) -> 2.5037328e-05 | L31: 0 | M31: 22664.873 | N31: 0 | O31: 0 | P31: 0 | Q31: 0 | R31: 0 | S31: 0 | T31: 0 | U31: 0 | V31: 0 | W31: 0 | X31: 0 | Y31: 0 | Z31: =+I31+J31 -> 22664.873
A32: 21 | B32: Бошқа соҳалар | C32: =+'Loans Receivable'!C70 -> 347394134 | D32: =IF(C$35=0,"",C32/C$35) -> 0.026083335 | F32: =IF($E$35=0,"",E32/$E$35) -> 0 | H32: =IF($G$35=0,"",G32/$G$35) -> 0 | I32: =+L32+N32+P32+R32+T32+V32+X32 -> 18976168 | J32: =+M32+O32+Q32+S32+U32+W32+Y32 -> 5203236.7 | K32: =IF($Z$35=0,"",Z32/$Z$35) -> 0.026710394 | L32: 1087269.4 | M32: 340604.93 | N32: 1376071.9 | O32: 520057.95 | P32: 3517347.4 | Q32: 719814.71 | R32: 3255053.9 | S32: 582641.95 | T32: 5315698.1 | U32: 1192897.1 | V32: 4265872.8 | W32: 1847220.1 | X32: 158854.04 | Y32: 0 | Z32: =+I32+J32 -> 24179404
A33: 22 | B33: Жисмоний шахслар | C33: =+'Loans Receivable'!C71 -> 4581385255 | D33: =IF(C$35=0,"",C33/C$35) -> 0.34398338 | F33: =IF($E$35=0,"",E33/$E$35) -> 0 | H33: =IF($G$35=0,"",G33/$G$35) -> 0 | I33: =+L33+N33+P33+R33+T33+V33+X33 -> 2.1085844e+08 | J33: =+M33+O33+Q33+S33+U33+W33+Y33 -> 85048575 | K33: =IF($Z$35=0,"",Z33/$Z$35) -> 0.32688121 | L33: 10932587 | M33: 8560888 | N33: 11018434 | O33: 4386200 | P33: 12543620 | Q33: 5251065 | R33: 38240762 | S33: 14467723 | T33: 39156244 | U33: 23036470 | V33: 85180069 | W33: 22209213 | X33: 13786724 | Y33: 7137016 | Z33: =+I33+J33 -> 2.9590701e+08
Z34: =+I34+J34 -> 0
A35: 23 | B35: Жами кредит ва лизинг суммаси | C35: =SUM(C25:C33) -> 13318623841 | D35: =IF(C$35=0,"",C35/C$35) -> 1 | E35: =SUM(E25:E33) -> 22445529 | F35: =IF($E$35=0,"",E35/$E$35) -> 1 | G35: =SUM(G25:G33) -> 39846807 | H35: =IF($G$35=0,"",G35/$G$35) -> 1 | I35: =SUM(I25:I33) -> 592099241 | J35: =SUM(J25:J33) -> 313144030 | K35: =IF($Z$35=0,"",Z35/$Z$35) -> 1 | L35: =SUM(L25:L33) -> 43014325 | M35: =SUM(M25:M33) -> 39032943 | N35: =SUM(N25:N33) -> 68590827 | O35: =SUM(O25:O33) -> 23857391 | P35: =SUM(P25:P33) -> 68188663 | Q35: =SUM(Q25:Q33) -> 60676658 | R35: =SUM(R25:R33) -> 1.2210497e+08 | S35: =SUM(S25:S33) -> 42684790 | ... Y35: =SUM(Y25:Y33) -> 18838603 | Z35: =+I35+J35 -> 905243271
B37: Бошқарув Раис имзоси:
B39: Бош бухгалтер имзоси:
G42: =+'[8]Bank Assets Analysis'!$S$31 -> 17337481

Sheet Asset Classification
A1: АКТИВЛАР СИФАТИ БЎЙИЧА ТАСНИФЛАНИШИ ТЎҒРИСИДА ҲИСОБОТ | Z1: 10-жадвал
B3: =+'Asset quality'!B3 -> "МКБАНК" | U3: =+'Asset quality'!Q3 -> 44926 | AB3: =+'Asset quality'!T3 -> минг. сўмда
A4: № | B4: Кўрсаткичлар | C4: Жами суммаси | D4: шундан, хорижий валютада (экв. сўмда) | E4: Стандарт | F4: шундан, хорижий валютада (экв. сўмда) | G4: Стандарт активлар бўйича яратилган захиралар (1%) | H4: шундан, хорижий валютада (экв. сўмда) | I4: Субстандарт | J4: шундан, хорижий валютада (экв. сўмда) | K4: Махсус захиралар (мин 10%) | L4: шундан, хорижий валютада (экв. сўмда) | M4: Қониқарсиз | N4: шундан, хорижий валютада (экв. сўмда) | O4: Махсус захиралар (мин 25%) | P4: шундан, хорижий валютада (экв. сўмда) | Q4: Шубҳали | R4: шундан, хорижий валютада (экв. сўмда) | S4: Махсус захиралар (мин 50%) | T4: шундан, хорижий валютада (экв. сўмда) | U4: Умидсиз | V4: шундан, хорижий валютада (экв. сўмда) | W4: Махсус захиралар (мин 100%) | X4: шундан, хорижий валютада (экв. сўмда) | Y4: Жами махсус захиралар суммаси | Z4: шундан, хорижий валютада (экв. сўмда) | AA4: ҳисобот ойида балансдан ташқари ҳисобдан чиқарилган кредитлар | AB4: ҳисобот ойида балансдан ташқари қайтган кредитлар суммаси
A5: (А) | B5: (Б) | C5: (В) | D5: (В1) | E5: (Г) | F5: (Г1) | G5: (Д) | H5: (Д1) | I5: (Е) | J5: (Е1) | K5: (Ж) | L5: (Ж1) | M5: (З) | N5: (З1) | O5: (И) | P5: (И1) | Q5: (К) | R5: (К1) | S5: (Л) | T5: (Л1) | U5: (М) | V5: (М1) | W5: (Н) | X5: (Н1) | Y5: О=Ж+И+Л+Н | Z5: (О1)=(Ж1)+(И1)+(Л1)+(Н1) | AA5: П | AB5: Р
B6: Мижозлар тури бўйича
A7: 1 | B7: Марказий банк | C7: =E7+I7+M7+Q7+U7 -> 0 | D7: =F7+J7+N7+R7+V7 -> 0 | Y7: =+W7+S7+O7+K7 -> 0 | Z7: =+X7+T7+P7+L7 -> 0 | AC7: =+'Aging Analysis'!C9 -> 0
B8: шундан, таъминланмаган қисми | C8: =E8+I8+M8+Q8+U8 -> 0 | D8: =F8+J8+N8+R8+V8 -> 0 | Y8: =+W8+S8+O8+K8 -> 0 | Z8: =+X8+T8+P8+L8 -> 0
A9: 2 | B9: Бошқа банклар | C9: =E9+I9+M9+Q9+U9 -> 0 | D9: =F9+J9+N9+R9+V9 -> 0 | Y9: =+W9+S9+O9+K9 -> 0 | Z9: =+X9+T9+P9+L9 -> 0 | AC9: =+'Aging Analysis'!C10 -> 0
B10: шундан, таъминланмаган қисми | C10: =E10+I10+M10+Q10+U10 -> 0 | D10: =F10+J10+N10+R10+V10 -> 0 | Y10: =+W10+S10+O10+K10 -> 0 | Z10: =+X10+T10+P10+L10 -> 0
A11: 3 | B11: Ҳукумат | C11: =E11+I11+M11+Q11+U11 -> 0 | D11: =F11+J11+N11+R11+V11 -> 0 | Y11: =+W11+S11+O11+K11 -> 0 | Z11: =+X11+T11+P11+L11 -> 0 | AC11: =+'Aging Analysis'!C11 -> 0
B12: шундан, таъминланмаган қисми | C12: =E12+I12+M12+Q12+U12 -> 0 | D12: =F12+J12+N12+R12+V12 -> 0 | Y12: =+W12+S12+O12+K12 -> 0 | Z12: =+X12+T12+P12+L12 -> 0
A13: 4 | B13: Жисмоний шахслар | C13: =E13+I13+M13+Q13+U13 -> 4581385255 | D13: =F13+J13+N13+R13+V13 -> 0 | E13: 3611077438 | F13: 0 | G13: 19487264 | H13: 0 | I13: 591113637 | J13: 0 | K13: 19725504 | L13: 0 | M13: 82422064 | N13: 0 | O13: 5604350 | P13: 0 | Q13: 201882538 | R13: 0 | S13: 20577296 | T13: 0 | U13: 94889578 | V13: 0 | W13: 46126485 | X13: 0 | Y13: =+W13+S13+O13+K13 -> 92033635 | Z13: =+X13+T13+P13+L13 -> 0 | AC13: =+'Aging Analysis'!C12 -> 4581385255
B14: шундан, таъминланмаган қисми | C14: =E14+I14+M14+Q14+U14 -> 0 | D14: =F14+J14+N14+R14+V14 -> 0 | Y14: =+W14+S14+O14+K14 -> 0 | Z14: =+X14+T14+P14+L14 -> 0
A15: 5 | B15: Давлат корхоналари | C15: =E15+I15+M15+Q15+U15 -> 82687815 | D15: =F15+J15+N15+R15+V15 -> 0 | E15: 72411648 | F15: 0 | G15: 0 | H15: 0 | I15: 9211160 | J15: 0 | K15: 869759 | L15: 0 | M15: 572474 | N15: 0 | O15: 57247 | P15: 0 | Q15: 331903 | R15: 0 | S15: 208978 | T15: 0 | U15: 160630 | V15: 0 | W15: 160630 | X15: 0 | Y15: =+W15+S15+O15+K15 -> 1296614 | Z15: =+X15+T15+P15+L15 -> 0 | AC15: =+'Aging Analysis'!C13 -> 82687816
B16: шундан, таъминланмаган қисми | C16: =E16+I16+M16+Q16+U16 -> 0 | D16: =F16+J16+N16+R16+V16 -> 0 | Y16: =+W16+S16+O16+K16 -> 0 | Z16: =+X16+T16+P16+L16 -> 0
A17: 6 | B17: Қўшма ва чет эл капитали иштирокидаги корхоналар | C17: =E17+I17+M17+Q17+U17 -> 1377755770 | D17: =F17+J17+N17+R17+V17 -> 527065251 | E17: 1223105546 | F17: 496515520 | G17: 0 | H17: 2170479 | I17: 143619938 | J17: 29957368 | K17: 6353725 | L17: 261722 | M17: 1163220 | N17: 0 | O17: 99386 | P17: 0 | Q17: 6577274 | R17: 0 | S17: 1586327 | T17: 0 | U17: 3289792 | V17: 592363 | W17: 1829070 | X17: 592364 | Y17: =+W17+S17+O17+K17 -> 9868508 | Z17: =+X17+T17+P17+L17 -> 854086 | AC17: =+'Aging Analysis'!C14 -> 1377755770
B18: шундан, таъминланмаган қисми | C18: =E18+I18+M18+Q18+U18 -> 0 | D18: =F18+J18+N18+R18+V18 -> 0 | Y18: =+W18+S18+O18+K18 -> 0 | Z18: =+X18+T18+P18+L18 -> 0
A19: 7 | B19: Хусусий корхоналар | C19: =E19+I19+M19+Q19+U19 -> 6847944102 | D19: =F19+J19+N19+R19+V19 -> 3109387449 | E19: 4862399861 | F19: 2271450246 | G19: 29230895 | H19: 11936336 | I19: 1752234657 | J19: 825783161 | K19: 89993078 | L19: 55830129 | M19: 25792059 | N19: 0 | O19: 40013972 | P19: 0 | Q19: 115831390 | R19: 4142609 | S19: 6627648 | T19: 1655738 | U19: 91686135 | V19: 8011433 | W19: 106083021 | X19: 8011432 | Y19: =+W19+S19+O19+K19 -> 242717719 | Z19: =+X19+T19+P19+L19 -> 65497299 | AC19: =+'Aging Analysis'!C15 -> 6847944103
B20: шундан, таъминланмаган қисми | C20: =E20+I20+M20+Q20+U20 -> 0 | D20: =F20+J20+N20+R20+V20 -> 0 | Y20: =+W20+S20+O20+K20 -> 0 | Z20: =+X20+T20+P20+L20 -> 0
A21: 8 | B21: Фермер хўжалиги | C21: =E21+I21+M21+Q21+U21 -> 229585212 | D21: =F21+J21+N21+R21+V21 -> 101269242 | E21: 160872982 | F21: 72744186 | G21: 0 | H21: 0 | I21: 57999770 | J21: 28525056 | K21: 3782400 | L21: 1807799 | M21: 761591 | N21: 0 | O21: 1293 | P21: 0 | Q21: 6869333 | R21: 0 | S21: 2237850 | T21: 0 | U21: 3081536 | V21: 0 | W21: 1788942 | X21: 0 | Y21: =+W21+S21+O21+K21 -> 7810485 | Z21: =+X21+T21+P21+L21 -> 1807799 | AC21: =+'Aging Analysis'!C16 -> 229585211
B22: шундан, таъминланмаган қисми | C22: =E22+I22+M22+Q22+U22 -> 0 | D22: =F22+J22+N22+R22+V22 -> 0 | Y22: =+W22+S22+O22+K22 -> 0 | Z22: =+X22+T22+P22+L22 -> 0
A23: 9 | B23: Нобанк молиявий институтлар | C23: =E23+I23+M23+Q23+U23 -> 0 | D23: =F23+J23+N23+R23+V23 -> 0 | E23: 0 | F23: 0 | G23: 0 | H23: 0 | I23: 0 | J23: 0 | K23: 0 | L23: 0 | M23: 0 | N23: 0 | O23: 0 | P23: 0 | Q23: 0 | R23: 0 | S23: 0 | T23: 0 | U23: 0 | V23: 0 | W23: 0 | X23: 0 | Y23: =+W23+S23+O23+K23 -> 0 | Z23: =+X23+T23+P23+L23 -> 0 | AC23: =+'Aging Analysis'!C17 -> 0
B24: шундан, таъминланмаган қисми | C24: =E24+I24+M24+Q24+U24 -> 0 | D24: =F24+J24+N24+R24+V24 -> 0 | Y24: =+W24+S24+O24+K24 -> 0 | Z24: =+X24+T24+P24+L24 -> 0
A25: 10 | B25: Нодавлат нотижорат ташкилотлар | C25: =E25+I25+M25+Q25+U25 -> 199265687 | D25: =F25+J25+N25+R25+V25 -> 785783 | E25: 180331784 | F25: 785783 | G25: 0 | H25: 0 | I25: 18794922 | J25: 0 | K25: 467846 | L25: 0 | M25: 105981 | N25: 0 | O25: 0 | P25: 0 | Q25: 33000 | R25: 0 | S25: 16500 | T25: 0 | U25: 0 | V25: 0 | W25: 0 | X25: 0 | Y25: =+W25+S25+O25+K25 -> 484346 | Z25: =+X25+T25+P25+L25 -> 0 | AC25: =+'Aging Analysis'!C18 -> 199265686
B26: шундан, таъминланмаган қисми | C26: =E26+I26+M26+Q26+U26 -> 0 | D26: =F26+J26+N26+R26+V26 -> 0 | Y26: =+W26+S26+O26+K26 -> 0 | Z26: =+X26+T26+P26+L26 -> 0
A27: 11 | B27: Бюджет ташкилотлари | C27: =E27+I27+M27+Q27+U27 -> 0 | D27: =F27+J27+N27+R27+V27 -> 0 | E27: 0 | F27: 0 | G27: 0 | H27: 0 | I27: 0 | J27: 0 | K27: 0 | L27: 0 | M27: 0 | N27: 0 | O27: 0 | P27: 0 | Q27: 0 | R27: 0 | S27: 0 | T27: 0 | U27: 0 | V27: 0 | W27: 0 | X27: 0 | Y27: =+W27+S27+O27+K27 -> 0 | Z27: =+X27+T27+P27+L27 -> 0 | AC27: =+'Aging Analysis'!C19 -> 0
B28: шундан, таъминланмаган қисми | C28: =E28+I28+M28+Q28+U28 -> 0 | D28: =F28+J28+N28+R28+V28 -> 0 | Y28: =+W28+S28+O28+K28 -> 0 | Z28: =+X28+T28+P28+L28 -> 0
A29: 12 | B29: Бошқалар | C29: =E29+I29+M29+Q29+U29 -> 0 | D29: =F29+J29+N29+R29+V29 -> 0 | E29: 0 | F29: 0 | G29: 0 | H29: 0 | I29: 0 | J29: 0 | K29: 0 | L29: 0 | M29: 0 | N29: 0 | O29: 0 | P29: 0 | Q29: 0 | R29: 0 | S29: 0 | T29: 0 | U29: 0 | V29: 0 | W29: 0 | X29: 0 | Y29: =+W29+S29+O29+K29 -> 0 | Z29: =+X29+T29+P29+L29 -> 0 | AC29: =+'Aging Analysis'!C20 -> 0
B30: шундан, таъминланмаган қисми | C30: =E30+I30+M30+Q30+U30 -> 0 | D30: =F30+J30+N30+R30+V30 -> 0 | Y30: =+W30+S30+O30+K30 -> 0 | Z30: =+X30+T30+P30+L30 -> 0
A31: 13 | B31: Жами кредит ва лизинг суммаси | C31: =+C7+C9+C11+C13+C15+C17+C19+C21+C23+C25+C27+C29 -> 13318623841 | D31: =+D7+D9+D11+D13+D15+D17+D19+D21+D23+D25+D27+D29 -> 3738507725 | E31: =+E7+E9+E11+E13+E15+E17+E19+E21+E23+E25+E27+E29 -> 10110199259 | F31: =+F7+F9+F11+F13+F15+F17+F19+F21+F23+F25+F27+F29 -> 2841495735 | G31: =+G7+G9+G11+G13+G15+G17+G19+G21+G23+G25+G27+G29 -> 48718159 | H31: =+H7+H9+H11+H13+H15+H17+H19+H21+H23+H25+H27+H29 -> 14106815 | I31: =+I7+I9+I11+I13+I15+I17+I19+I21+I23+I25+I27+I29 -> 2572974084 | J31: =+J7+J9+J11+J13+J15+J17+J19+J21+J23+J25+J27+J29 -> 884265585 | ... AB31: =+AB7+AB9+AB11+AB13+AB15+AB17+AB19+AB21+AB23+AB25+AB27+AB29 -> 0 | AC31: =+'Loans Receivable'!C85 -> 13318623841
B32: шундан, таъминланмаган қисми | C32: =+C8+C10+C12+C14+C16+C18+C20+C22+C24+C26+C28+C30 -> 0 | D32: =+D8+D10+D12+D14+D16+D18+D20+D22+D24+D26+D28+D30 -> 0 | E32: =+E8+E10+E12+E14+E16+E18+E20+E22+E24+E26+E28+E30 -> 0 | F32: =+F8+F10+F12+F14+F16+F18+F20+F22+F24+F26+F28+F30 -> 0 | G32: =+G8+G10+G12+G14+G16+G18+G20+G22+G24+G26+G28+G30 -> 0 | H32: =+H8+H10+H12+H14+H16+H18+H20+H22+H24+H26+H28+H30 -> 0 | I32: =+I8+I10+I12+I14+I16+I18+I20+I22+I24+I26+I28+I30 -> 0 | J32: =+J8+J10+J12+J14+J16+J18+J20+J22+J24+J26+J28+J30 -> 0 | ... Z32: =+Z8+Z10+Z12+Z14+Z16+Z18+Z20+Z22+Z24+Z26+Z28+Z30 -> 0
B33: Иқтисодиёт соҳалари бўйича
A35: 14 | B35: Саноат | C35: =E35+I35+M35+Q35+U35 -> 3630116370 | D35: =F35+J35+N35+R35+V35 -> 1833674955 | E35: 2589061577 | F35: 1173200612 | G35: 29230895 | H35: 6032016 | I35: 953847796 | J35: 656430591 | K35: 29758177 | L35: 39626166 | M35: 11149456 | N35: 0 | O35: 37068529 | P35: 0 | Q35: 39917175 | R35: 1417931 | S35: 6468351 | T35: 1417931 | U35: 36140366 | V35: 2625821 | W35: 66595013 | X35: 2625821 | Y35: =+W35+S35+O35+K35 -> 139890070 | Z35: =+X35+T35+P35+L35 -> 43669918 | AC35: =+'Aging Analysis'!C25 -> 3630116373
B36: шундан, таъминланмаган қисми | C36: =E36+I36+M36+Q36+U36 -> 0 | D36: =F36+J36+N36+R36+V36 -> 0 | Y36: =+W36+S36+O36+K36 -> 0 | Z36: =+X36+T36+P36+L36 -> 0
A37: 15 | B37: Қишлоқ хўжалиги | C37: =E37+I37+M37+Q37+U37 -> 1847415442 | D37: =F37+J37+N37+R37+V37 -> 719377947 | E37: 1295812299 | F37: 566095514 | G37: 0 | H37: 2170479 | I37: 488625025 | J37: 147317408 | K37: 29726446 | L37: 7452227 | M37: 9426254 | N37: 0 | O37: 1814654 | P37: 0 | Q37: 28600599 | R37: 821429 | S37: 4667665 | T37: 47351 | U37: 24951265 | V37: 5143596 | W37: 16154772 | X37: 5143596 | Y37: =+W37+S37+O37+K37 -> 52363537 | Z37: =+X37+T37+P37+L37 -> 12643174 | AC37: =+'Aging Analysis'!C26 -> 1847415442
B38: шундан, таъминланмаган қисми | C38: =E38+I38+M38+Q38+U38 -> 0 | D38: =F38+J38+N38+R38+V38 -> 0 | Y38: =+W38+S38+O38+K38 -> 0 | Z38: =+X38+T38+P38+L38 -> 0
A39: 16 | B39: Транспорт ва коммуникация | C39: =E39+I39+M39+Q39+U39 -> 180788828 | D39: =F39+J39+N39+R39+V39 -> 100311052 | E39: 126936248 | F39: 88010778 | G39: 0 | H39: 0 | I39: 42154715 | J39: 11084983 | K39: 3937727 | L39: 990851 | M39: 129890 | N39: 0 | O39: 27424 | P39: 0 | Q39: 9619736 | R39: 380912 | S39: 2106662 | T39: 190456 | U39: 1948239 | V39: 834379 | W39: 1948239 | X39: 834379 | Y39: =+W39+S39+O39+K39 -> 8020052 | Z39: =+X39+T39+P39+L39 -> 2015686 | AC39: =+'Aging Analysis'!C27 -> 180788828
B40: шундан, таъминланмаган қисми | C40: =E40+I40+M40+Q40+U40 -> 0 | D40: =F40+J40+N40+R40+V40 -> 0 | Y40: =+W40+S40+O40+K40 -> 0 | Z40: =+X40+T40+P40+L40 -> 0
A41: 17 | B41: Қурилиш соҳаси | C41: =E41+I41+M41+Q41+U41 -> 192184990 | D41: =F41+J41+N41+R41+V41 -> 3362025 | E41: 139909913 | F41: 0 | G41: 0 | H41: 0 | I41: 45523911 | J41: 3362025 | K41: 2756526 | L41: 0 | M41: 2327364 | N41: 0 | O41: 827364 | P41: 0 | Q41: 3046820 | R41: 0 | S41: 615181 | T41: 0 | U41: 1376982 | V41: 0 | W41: 1155982 | X41: 0 | Y41: =+W41+S41+O41+K41 -> 5355053 | Z41: =+X41+T41+P41+L41 -> 0 | AC41: =+'Aging Analysis'!C28 -> 192184990
B42: шундан, таъминланмаган қисми | C42: =E42+I42+M42+Q42+U42 -> 0 | D42: =F42+J42+N42+R42+V42 -> 0 | Y42: =+W42+S42+O42+K42 -> 0 | Z42: =+X42+T42+P42+L42 -> 0
...

Sheet Asset Provisioning
A1: АКТИВЛАР ВА УЛАРНИНГ ТАСНИФИ БЎЙИЧА ШАКЛЛАНТИРИЛГАН ЗАХИРАЛАР | AT1: 10 А-жадвал
B3: =+'Asset quality'!B3 -> "МКБАНК" | AH3: =+'Asset quality'!Q3 -> 44926 | AU3: =+'Asset quality'!T3 -> минг. сўмда
A4: № | B4: Кўрсаткичлар | C4: Жами суммаси | D4: шундан, хорижий валютада (экв. сўмда) | E4: Стандарт | F4: шундан, хорижий валютада (экв. сўмда) | G4: Стандарт активлар бўйича яратилган захиралар (мин 1%) | J4: Субстандарт | K4: шундан, хорижий валютада (экв. сўмда) | L4: Субстандарт активлар бўйича яратилган захиралар (мин 10%) | O4: шундан, хорижий валютада (экв. сўмда) | R4: Қониқарсиз | S4: шундан, хорижий валютада (экв. сўмда) | T4: Қониқарсиз активлар бўйича яратилган захиралар (мин 25%) | W4: шундан, хорижий валютада (экв. сўмда) | Z4: Шубҳали | AA4: шундан, хорижий валютада (экв. сўмда) | AB4: Шубҳали активлар бўйича яратилган захиралар (мин 50%) | AE4: шундан, хорижий валютада (экв. сўмда) | AH4: Умидсиз | AI4: шундан, хорижий валютада (экв. сўмда) | AJ4: Умидсиз активлар бўйича яратилган захиралар (мин 100%) | AM4: шундан, хорижий валютада (экв. сўмда) | AP4: Жами махсус захиралар суммаси | AS4: шундан, хорижий валютада (экв. сўмда)
G5: Ҳақиқатдан яратилган заҳира | H5: Яратилиши лозим бўлган заҳира | I5: Фарқи | L5: Ҳақиқатдан яратилган заҳира | M5: Яратилиши лозим бўлган заҳира | N5: Фарқи | O5: Ҳақиқатдан яратилган заҳира | P5: Яратилиши лозим бўлган заҳира | Q5: Фарқи | T5: Ҳақиқатдан яратилган заҳира | U5: Яратилиши лозим бўлган заҳира | V5: Фарқи | W5: Ҳақиқатдан яратилган заҳира | X5: Яратилиши лозим бўлган заҳира | Y5: Фарқи | AB5: Ҳақиқатдан яратилган заҳира | AC5: Яратилиши лозим бўлган заҳира | AD5: Фарқи | AE5: Ҳақиқатдан яратилган заҳира | AF5: Яратилиши лозим бўлган заҳира | AG5: Фарқи | AJ5: Ҳақиқатдан яратилган заҳира | AK5: Яратилиши лозим бўлган заҳира | AL5: Фарқи | AM5: Ҳақиқатдан яратилган заҳира | AN5: Яратилиши лозим бўлган заҳира | AO5: Фарқи | AP5: Ҳақиқатдан яратилган заҳира | AQ5: Яратилиши лозим бўлган заҳира | AR5: Фарқи | AS5: Ҳақиқатдан яратилган заҳира | AT5: Яратилиши лозим бўлган заҳира | AU5: Фарқи
B6: Мижозлар тури бўйича
