Workbook
Name jop: #REF!
Name kol: #REF!
Name OLE_LINK19: Balance!$D$32
Name TwentyLargestData: #REF!
Name Е: #REF!

Sheet Balance
A1: БАНК БАЛАНСИ ТАРКИБИ | E1: 1-жадвал | G1: №1
B2: =IF(D3>0," "&TEXT(D3,"д ММММ, гггг"),"Число,Месяц,Год") -> 31 Декабрь, 2024
B3: "MKBANK" | D3: 45657 | E3: минг сўмда
A4: № | B4: АКТИВЛАР | C4: Жами | D4: Миллий валютада | E4: Хорижий валютада (сўм экв.)
A5: 1 | B5: Кассадаги нақд пул ва бошқа тўлов ҳужжатлари | C5: =+D5+E5 -> 874095566 | D5: =+'Bank Assets Analysis'!T6 -> 661579127 | E5: =+'Bank Assets Analysis'!U6 -> 212516439 | J5: =+C5-D5-E5 -> 0
A6: 2 | B6: Банкнинг Марказий банкдаги маблағлари | C6: =+D6+E6 -> 496195792 | D6: =+'Bank Assets Analysis'!T7+'Bank Assets Analysis'!T8 -> 496195792 | E6: =+'Bank Assets Analysis'!U7+'Bank Assets Analysis'!U8 -> 0 | J6: =+C6-D6-E6 -> 0
A7: 3 | B7: Бошқа банклар ва молиявий ташкилотлардан олиниши лозим бўлган маблағлар, соф | C7: =+'Bank Assets Analysis'!S9 -> 1530859823 | D7: =+'Bank Assets Analysis'!T9 -> 75605011 | E7: =+'Bank Assets Analysis'!U9 -> 1455254812 | J7: =+C7-D7-E7 -> 0
A8: 3.1 | B8: Бошқа банклар ва молиявий ташкилотлардан олиниши лозим бўлган маблағлар, брутто | C8: =+D8+E8 -> 1530859823 | D8: 75605011 | E8: 1455254812 | J8: =+C8-D8-E8 -> 0
A9: 3.2 | B9: Минус: Кўрилиши мумкин бўлган зарарларни қоплаш захираси | C9: =+D9+E9 -> 0 | D9: 0 | E9: 0 | J9: =+C9-D9-E9 -> 0
A10: 4 | B10: Қимматли қоғозлар ва уларга қилинган инвестициялар, соф | C10: =+D10+E10 -> 211358447 | D10: =+'Investment Securities'!C29 -> 211358447 | E10: =+'Investment Securities'!D29 -> 0 | J10: =+C10-D10-E10 -> 0
A11: 4.1 | B11: Қимматли қоғозлар ва уларга қилинган инвестициялар, брутто | C11: =+D11+E11 -> 217000000 | D11: =+'Investment Securities'!C26 -> 217000000 | E11: =+'Investment Securities'!D26 -> 0 | J11: =+C11-D11-E11 -> 0
A12: 4.2 | B12: Қимматли қоғозлар бўйича харажатлар, дисконт, мукофот ва уларнинг ҳаққоний қийматининг ўзгариши | C12: =+D12+E12 -> -5641553 | D12: =+'Investment Securities'!C27 -> -5641553 | E12: =+'Investment Securities'!D27 -> 0 | J12: =+C12-D12-E12 -> 0
A13: 4.3 | B13: Минус: Кўрилиши мумкин бўлган зарарларни қоплаш захираси | C13: =+D13+E13 -> 0 | D13: =+'Investment Securities'!C28 -> 0 | E13: =+'Investment Securities'!D28 -> 0 | J13: =+C13-D13-E13 -> 0
A14: 5 | B14: Қимматбаҳо металлар, тошлар ва тангалар, соф | C14: =+C15-C16 -> 175 | D14: =+'Investment Securities'!C39 -> 175 | E14: =+'Investment Securities'!D39 -> 0 | J14: =+C14-D14-E14 -> 0
A15: 5.1 | B15: Қимматбаҳо металлар, тошлар ва тангалар, брутто | C15: =+D15+E15 -> 175 | D15: =+'Investment Securities'!C37 -> 175 | E15: =+'Investment Securities'!D37 -> 0 | J15: =+C15-D15-E15 -> 0
A16: 5.2 | B16: Минус: Кўрилиши мумкин бўлган зарарларни қоплаш захираси | C16: =+D16+E16 -> 0 | D16: =+'Investment Securities'!C38 -> 0 | E16: =+'Investment Securities'!D38 -> 0 | J16: =+C16-D16-E16 -> 0
A17: 6 | B17: Инвестициялар, соф | C17: =+'Investment Securities'!B15 -> 171402110 | D17: =+'Investment Securities'!C15 -> 171402110 | E17: =+'Investment Securities'!D15 -> 0 | J17: =+C17-D17-E17 -> 0
A18: 6.1 | B18: Инвестициялар, брутто | C18: =+D18+E18 -> 171417220 | D18: =+'Investment Securities'!C12 -> 171417220 | E18: =+'Investment Securities'!D12 -> 0 | J18: =+C18-D18-E18 -> 0
A19: 6.2 | B19: Инвестициялар бўйича харажатлар, дисконт ва мукофот | C19: =+D19+E19 -> 0 | D19: =+'Investment Securities'!C13 -> 0 | E19: =+'Investment Securities'!D13 -> 0 | J19: =+C19-D19-E19 -> 0
A20: 6.3 | B20: Минус: Кўрилиши мумкин бўлган зарарларни қоплаш захираси | C20: =+D20+E20 -> 15110 | D20: =+'Investment Securities'!C14 -> 15110 | E20: =+'Investment Securities'!D14 -> 0 | J20: =+C20-D20-E20 -> 0
A21: 7 | B21: РЕПО битимлари бўйича сотиб олинган қимматли қоғозлар, соф | C21: =+'Bank Assets Analysis'!S34 -> 0 | D21: =+'Bank Assets Analysis'!T34 -> 0 | E21: =+'Bank Assets Analysis'!U34 -> 0 | J21: =+C21-D21-E21 -> 0
A22: 7.1 | B22: РЕПО битимлари бўйича сотиб олинган қимматли қоғозлар, брутто | C22: =+D22+E22 -> 0 | D22: 0 | E22: 0 | J22: =+C22-D22-E22 -> 0
A23: 7.2 | B23: Минус: Кўрилиши мумкин бўлган зарарларни қоплаш захираси | C23: =+D23+E23 -> 0 | D23: 0 | E23: 0 | J23: =+C23-D23-E23 -> 0
A24: 8 | B24: Кредит ва лизинг операциялари, соф | C24: =+'Bank Assets Analysis'!S29+'Bank Assets Analysis'!S30+'Bank Assets Analysis'!S32 -> 16924606170 | D24: =+'Bank Assets Analysis'!T29+'Bank Assets Analysis'!T30+'Bank Assets Analysis'!T32 -> 13221996067 | E24: =+'Bank Assets Analysis'!U29+'Bank Assets Analysis'!U30+'Bank Assets Analysis'!U32 -> 3702610103 | J24: =+C24-D24-E24 -> 0
A25: 8.1 | B25: Кредит ва лизинг операциялари, брутто | C25: =+D25+E25 -> 17416357689 | D25: 13567075694 | E25: 3849281995 | J25: =+C25-D25-E25 -> 0
A26: 8.2 | B26: Минус: Кўрилиши мумкин бўлган зарарларни қоплаш захираси | C26: =+D26+E26 -> 491751519 | D26: 345079627 | E26: 146671892 | J26: =+C26-D26-E26 -> 0
A27: 9 | B27: Молиявий инструментлар бўйича мижозларнинг мажбуриятлари, соф | C27: =+'Bank Assets Analysis'!S26+'Bank Assets Analysis'!S27 -> 30025798 | D27: =+'Bank Assets Analysis'!T26+'Bank Assets Analysis'!T27 -> 1400024 | E27: =+'Bank Assets Analysis'!U26+'Bank Assets Analysis'!U27 -> 28625774 | J27: =+C27-D27-E27 -> 0
A28: 9.1 | B28: Молиявий инструментлар бўйича мижозларнинг мажбуриятлари, брутто | C28: =+D28+E28 -> 30025798 | D28: 1400024 | E28: 28625774 | J28: =+C28-D28-E28 -> 0
A29: 9.2 | B29: Минус: Кўрилиши мумкин бўлган зарарларни қоплаш захираси | C29: =+D29+E29 -> 0 | D29: 0 | E29: 0 | J29: =+C29-D29-E29 -> 0
A30: 10 | B30: Асосий воситалар, соф | C30: =+'Bank Assets Analysis'!S37 -> 929814271 | D30: =+'Bank Assets Analysis'!T37 -> 929814271 | E30: =+'Bank Assets Analysis'!U37 -> 0 | J30: =+C30-D30-E30 -> 0
A31: 11 | B31: Жами ҳисобланган фоизли ва фоизсиз даромадлар, соф | C31: =+C32+C33-C34 -> 1529592132 | D31: =+D32+D33-D34 -> 1121196872 | E31: =+E32+E33-E34 -> 408395260 | J31: =+C31-D31-E31 -> 0
A32: 11.1 | B32: Ҳисобланган фоизли даромадлар, брутто | C32: =+D32+E32 -> 1536769538 | D32: 1128374278 | E32: 408395260 | J32: =+C32-D32-E32 -> 0
A33: 11.2 | B33: Ҳисобланган фоизсиз даромадлар, брутто | C33: =+D33+E33 -> 9666 | D33: 9666 | E33: 0 | J33: =+C33-D33-E33 -> 0
A34: 11.2.1 | B34: Минус: Кўрилиши мумкин бўлган зарарларни қоплаш захираси | C34: =+D34+E34 -> 7187072 | D34: 7187072 | E34: 0 | J34: =+C34-D34-E34 -> 0
A35: 12 | B35: Банкнинг бошқа хусусий мулклари, соф | C35: =+'Bank Assets Analysis'!S38 -> 408190381 | D35: =+'Bank Assets Analysis'!T38 -> 408190381 | E35: =+'Bank Assets Analysis'!U38 -> 0 | J35: =+C35-D35-E35 -> 0
A36: 12.1 | B36: Кредит ва лизинг бўйича гаров ҳисобидан ундирилган бошқа мулклар, брутто | C36: =+D36+E36 -> 493820560 | D36: 493820560 | E36: 0 | J36: =+C36-D36-E36 -> 0
A37: 12.2 | B37: Банкнинг бошқа хусусий мулклари, брутто | C37: =+D37+E37 -> 0 | D37: 0 | E37: 0 | J37: =+C37-D37-E37 -> 0
A38: 12.3 | B38: Минус: Йиғилган эскириш суммаси ва кўрилиши мумкин бўлган зарарларни қоплаш захираси | C38: =+D38+E38 -> 85630179 | D38: 85630179 | E38: 0 | J38: =+C38-D38-E38 -> 0
A39: 13 | B39: Стандарт деб таснифланган активлар бўйича яратилган захиралар | C39: =+D39+E39 -> 123714035 | D39: =+D40+D41+D42 -> 123714035 | E39: =+E40+E41+E42 -> 0 | J39: =+C39-D39-E39 -> 0
A40: 13.1 | B40: Стандарт деб таснифланган кредитлар, лизинг ва факторинг бўйича захира | C40: =+D40+E40 -> 123714035 | D40: 123714035 | E40: 0 | J40: =+C40-D40-E40 -> 0
...

Sheet Bank Capital Calc (2)
A1: РАСЧЕТ РЕГУЛЯТИВНОГО КАПИТАЛА БАНКА | C1: Таблица-5
B3: =Balance!B3 -> "MKBANK" | C3: =+Balance!D3 -> 45657
A4: № | B4: Характеристики | C4: Итого капитала
A5: I. | B5: КАПИТАЛ УРОВНЯ 1
A6: 1 | B6: ОСНОВНОЙ КАПИТАЛ УРОВНЯ 1
A7: 1.1. | B7: Обыкновенные Акции, чистые | C7: Формула
A8: a | B8: Полностью оплаченные обыкновенные акции
A9: б | B9: Минус: Обратно Выкупленные обыкновенные акции
A10: 1.2. | B10: Добавленный капитал - Обыкновенные | C10: 0
A11: 1.3. | B11: Нераспределенная прибыль (убыток), в том числе капитальные резервы | C11: Формула
A12: а | B12: Капитальные резервы
A13: б | B13: Нераспределенная прибыль
A14: в | B14: Убыток за предыдущие периоды
A15: г | B15: Убыток за текущий год
A16: 1.4. | B16: Интерес меньшинства в консолидированных дочерних компаниях (согласно МБС)
A17: 1.5. | B17: Резерв на девальвацию
B18: Итого основного капитала уровня I до вычетов | C18: Формула
A19: 1.6. | B19: Вычеты из суммы основного капитала уровня I | C19: Формула
A20: а | B20: Нематериальные активы
A21: б | B21: Все инвестиции в капитал неконсолидированных хозяйствующих субъектов, в том числе в долговые обязательства, которые образуют капитал хозяйствующих субъектов
A22: в | B22: Инвестиции в капитал других банков
A23: I | B23: ВСЕГО СКОРРЕКТИРОВАННЫЙ ОСНОВНОЙ КАПИТАЛ УРОВНЯ I | C23: Формула
A24: 2 | B24: ДОБАВЛЕННЫЙ КАПИТАЛ УРОВНЯ 1
A25: 2.1. | B25: Некумулятивные бессрочные привилегированные акции | C25: =+C26+C27 -> 0
A26: а | B26: Полностью оплаченные привилегированные акции
A27: б | B27: Минус: Обратно Выкупленные привилегированные акции
A28: 2.2. | B28: Добавленный капитал - Привилегированные | C28: 0
A29: 2.3. | B29: Интерес меньшинства в консолидированных дочерних компаниях | C29: 0
A30: 2.4. | B30: Доля участия дочерних предприятий (выпущенные дочерними предприятиями и находящиеся во владении третьих лиц инструменты, приравненные к капиталу) | C30: 0
A31: II | B31: ВСЕГО ДОБАВЛЕННЫЙ КАПИТАЛ УРОВНЯ I | C31: =+C25+C28+C29+C30 -> 0
A32: III | B32: ВСЕГО СКОРРЕКТИРОВАННЫЙ КАПИТАЛ УРОВНЯ I | C32: Формула
B33: КАПИТАЛ УРОВНЯ II
A34: 3.1. | B34: Прибыль за текущий год
A35: 3.2. | B35: Резервы, создаваемые на стандартные кредиты (активы), в размере не более 1.25% от общей суммы активов, взвешенных с учетом риска | C35: =IF(Balance!#REF!<(C43*1.25%),Balance!#REF!,(C43*1.25%)) -> #REF!
A36: 3.3. | B36: Излишки оценочной стоимости прироста над первоначальной стоимостью
A37: 3.4. | B37: Другие инструменты капитала (не более 1/3 части капитала 1 уровня после вычетов)
A38: 3.5. | B38: Субординированный долг
A39: 3.6. | B39: Вычеты превышения Капитала Уровня II над Капиталом Уровня I | C39: Формула
B40: Итого капитала Уровня II | C40: =SUM(C34:C38) -> #REF!
A41: IV | B41: СКОРРЕКТИРОВАННЫЙ КАПИТАЛ УРОВНЯ II | C41: Формула
...

Sheet Liquidity Analysis
A1: ЛИКВИДЛИЛИК ТАҲЛИЛИ | E1: 16-жадвал
B2: =Balance!B3 -> "MKBANK" | D2: =+Balance!D3 -> 45657 | E2: минг сўмда
A3: № | B3: Ликвид активлар | C3: Жами | D3: Миллий валютада | E3: Хорижий валютада
B4: 1-қисм. Юқори ликвидли активлар | C4: фоизда
A5: 1.1 | B5: Кассадаги нақд пул ва бошқа тўлов ҳужжатлари | C5: =+'Bank Assets Analysis'!S6 -> 874095566 | D5: =+'Bank Assets Analysis'!T6 -> 661579127 | E5: =+'Bank Assets Analysis'!U6 -> 212516439
A6: 1.2 | B6: Банкнинг Марказий банкдаги маблағлар (мажбурий захираларсиз) | C6: =+'Bank Assets Analysis'!S7 -> 496195792 | D6: =+'Bank Assets Analysis'!T7 -> 496195792 | E6: =+'Bank Assets Analysis'!U7 -> 0
A7: 1.3 | B7: Ўзбекистон Республикаси Ҳукумати ва Марказий банки томонидан чиқарилган қимматли қоғозлар | C7: =+'Bank Assets Analysis'!S19 -> 201358446 | D7: =+'Bank Assets Analysis'!T19 -> 201358446 | E7: =+'Bank Assets Analysis'!U19 -> 0
A8: 1.4 | B8: Инвестиция даражасидан паст бўлмаган рейтингга эга хорижий банкларда ва кредит рейтингига эга маҳаллий банкларда очилган вакиллик ҳисобварақларидаги маблағлар | C8: =+E8 -> 1361192858 | E8: =+'Bank Assets Analysis'!D10+'Bank Assets Analysis'!D11 -> 1361192858
A9: 1.5 | B9: Инвестиция даражасидан паст бўлмаган рейтингга эга бўлган мамлакатлардаги банкларда чет-эл валютасида овернайт шарти асосида жойлаштирилган депозитлар | C9: =+E9 -> 0 | E9: =+'Bank Assets Analysis'!F13 -> 0
A10: 1.6 | B10: ХВФ, Жаҳон банки гуруҳи, Осиё тараққиёт банки, Осиё инфратузилма ва инвестиция банки, ЕТTБ, Европа инвестиция банки, Европа инвестиция жамғармаси, Ислом тараққиёт банки ва Европа Кенгашининг тараққиёт банки томонидан чиқарилган қимматли қоғозлар | C10: =+'Bank Assets Analysis'!S21 -> 0 | D10: =+'Bank Assets Analysis'!T21 -> 0 | E10: =+'Bank Assets Analysis'!U21 -> 0
A11: 1.7 | B11: Таваккалчилик даражаси паст бўлган мамлакатлар ҳукуматлари ва Марказий банклари томонидан чиқарилган қимматли қоғозлар | C11: =+'Bank Assets Analysis'!S20 -> 0 | D11: =+'Bank Assets Analysis'!T20 -> 0 | E11: =+'Bank Assets Analysis'!U20 -> 0
A12: 1.8 | B12: Қайтариб олинмайдиган кредит линиялари (ўзлаштирилмаган қисми) | C12: =+D12 -> 0 | D12: 0 | G12: Мазкур қатор ЎзР. Марказий банки билан тегишли кредит шартнома тузилганда тўлдириши керак. Ҳисобот даврига банкнинг нетто активларининг 2 % акс эттирилади.
A13: 1.9 | B13: Ипотекани қайта молиялаштириш ташкилотлари томонидан чиқарилган корпоратив облигациялар ва таъминланган қарз муносабатларини тасдиқловчи бошқа қимматли қоғозлар | C13: =+'Bank Assets Analysis'!S24+('Bank Assets Analysis'!S23*0.8) -> 8000000 | D13: =+'Bank Assets Analysis'!T24+('Bank Assets Analysis'!T23*0.8) -> 8000000 | E13: =+'Bank Assets Analysis'!U24+('Bank Assets Analysis'!U23*0.8) -> 0
A14: 1.10 | B14: РЕПО битимлари бўйича сотиб олинган юқори ликвидли қимматли қоғозлар | C14: =+'Bank Assets Analysis'!S35 -> 0 | D14: =+'Bank Assets Analysis'!T35 -> 0 | E14: =+'Bank Assets Analysis'!U35 -> 0
A15: 1.11 | B15: Гаровга қўйилган юқори ликвидли активлар | C15: =+'Bank Assets Analysis'!S18+'Bank Assets Analysis'!S46 -> 0 | D15: =+'Bank Assets Analysis'!T18+'Bank Assets Analysis'!T46 -> 0 | E15: =+'Bank Assets Analysis'!U18+'Bank Assets Analysis'!U46 -> 0
A16: 1.12 | B16: Жами юқори ликвидли активлар | C16: =SUM(C5:C14)-'Bank Liabilities Analysis'!S22-'Bank Liabilities Analysis'!T25-C15 -> 2940653516 | D16: =SUM(D5:D14)-'Bank Liabilities Analysis'!T22-'Bank Liabilities Analysis'!T25-D15 -> 1366944219 | E16: =SUM(E5:E14)-'Bank Liabilities Analysis'!U22-E15 -> 1573709297
B17: 2-қисм. Иқтисодий меъёрлар - Ликвидлилик
A18: 2.1 | B18: Юқори ликвидли активларнинг жами активларга нисбати | C18: =IFERROR((+C19/C20),0) -> 0.12490815 | D18: =IFERROR((+D19/D20),0) -> 0.077212944 | E18: =IFERROR((+E19/E20),0) -> 0.26951859
A19: 2.1.1 | B19: Юқори ликвидли активлар | C19: =+C16 -> 2940653516 | D19: =+D16 -> 1366944219 | E19: =+E16 -> 1573709297
A20: 2.1.2 | B20: Жами активлар (РЕПО битимлари айрилган ҳолда) | C20: =Balance!C47-'Bank Liabilities Analysis'!S34 -> 23542526924 | D20: =Balance!D47-'Bank Liabilities Analysis'!T34 -> 17703563116 | E20: =Balance!E47-'Bank Liabilities Analysis'!U34 -> 5838963808
A21: 2.2 | B21: Юқори ликвидли активларнинг қисқа муддатли мажбуриятларга нисбати | C21: =IFERROR((+C22/C23),0) -> 0.36160851 | D21: =IFERROR((+D22/D23),0) -> 0.22837124 | E21: =IFERROR((+E22/E23),0) -> 0.73314324
A22: 2.2.1 | B22: Юқори ликвидли активлар | C22: =+C16 -> 2940653516 | D22: =+D16 -> 1366944219 | E22: =+E16 -> 1573709297
A23: 2.2.2 | B23: Қисқа муддатли мажбуриятлар (РЕПО битимлари айрилган ҳолда) | C23: =+'Bank Liabilities Analysis'!C42+'Bank Liabilities Analysis'!E42+'Bank Liabilities Analysis'!G42+'Bank Liabilities Analysis'!I42+'Bank Liabilities Analysis'!K42+'Bank Liabilities Analysis'!M42-'Bank Liabilities Analysis'!C34-'Bank Liabilities Analysis'!E34-'Bank Liabilities Analysis'!G34-'Bank Liabilities Analysis'!I34-'Bank Liabilities Analysis'!K34-'Bank Liabilities Analysis'!M34 -> 8132146908 | D23: =+C23-E23 -> 5985623275 | E23: =+'Bank Liabilities Analysis'!D42+'Bank Liabilities Analysis'!F42+'Bank Liabilities Analysis'!H42+'Bank Liabilities Analysis'!J42+'Bank Liabilities Analysis'!L42+'Bank Liabilities Analysis'!N42-'Bank Liabilities Analysis'!D34-'Bank Liabilities Analysis'!F34-'Bank Liabilities Analysis'!H34-'Bank Liabilities Analysis'!J34-'Bank Liabilities Analysis'!L34-'Bank Liabilities Analysis'!N34 -> 2146523633
A24: 2.3 | B24: Ликвидлиликни қоплаш меъёри коэффициенти | C24: =IFERROR((+C25/C26),0) -> 1.6895584 | D24: =IFERROR((+D25/D26),0) -> 1.026971 | E24: =IFERROR((+E25/E26),0) -> 3.8435475
A25: 2.3.1 | B25: Юқори ликвидли активлар | C25: =+C16 -> 2940653516 | D25: =+D16 -> 1366944219 | E25: =+E16 -> 1573709297
A26: 2.3.2 | B26: Кейинги 30 кун ичида соф чиқим | C26: =+'Bank Assets Analysis'!X65 -> 1.7404865e+09 | D26: =+'Bank Assets Analysis (нац)'!P61 -> 1.3310446e+09 | E26: =+'Bank Assets Analysis'!Z65 -> 4.0944188e+08
B27: 30 кунлик чиқим суммаси | C27: =+'Bank Assets Analysis'!X67 -> 2.3657352e+09 | D27: =+'Bank Assets Analysis (нац)'!P63 -> 1.7276362e+09 | E27: =+'Bank Assets Analysis'!Z67 -> 6.3809907e+08
B28: 30 кунлик кирим суммаси | C28: =+'Bank Assets Analysis'!X70 -> 625248744 | D28: =+'Bank Assets Analysis (нац)'!P65 -> 3.9659156e+08 | E28: =+'Bank Assets Analysis'!Z70 -> 2.2865719e+08
A29: 2.4 | B29: Соф барқарор молиялаштириш меъёри | C29: =IFERROR((C30/C35),0) -> 1.1308614 | D29: =IFERROR((D30/D35),0) -> 1.0664487 | E29: =IFERROR((E30/E35),0) -> 1.3843182
A30: 2.5 | B30: Барқарор молиялаштиришнинг мавжуд суммаси | C30: =SUM(C31:C34) -> 1.7850024e+10 | D30: =SUM(D31:D34) -> 1.3331704e+10 | E30: =SUM(E31:E34) -> 4.5183197e+09
A31: 2.5.1 | B31: Хусусий капитал | C31: =Balance!C77 -> 3550613724 | D31: =Balance!D77 -> 3550613724 | E31: =Balance!E77 -> 0
A32: 2.5.2 | B32: Бир йилдан ортиқ муддатли мажбуриятлар | C32: ='Bank Liabilities Analysis'!O42+'Bank Liabilities Analysis'!Q42 -> 11859766292 | D32: =+'Bank Liabilities Analysis (нац)'!I43+'Bank Liabilities Analysis (нац)'!J43 -> 7985403704 | E32: ='Bank Liabilities Analysis'!P42+'Bank Liabilities Analysis'!R42 -> 3874362588
A33: 2.5.3 | B33: Бошқа муддатсиз мажбуриятларнинг 30 фоизи | C33: =+('Bank Liabilities Analysis'!C42)*0.3 -> 3.4932181e+08 | D33: =+('Bank Liabilities Analysis (нац)'!C43)*0.3 -> 3.0297539e+08 | E33: =+('Bank Liabilities Analysis'!D42)*0.3 -> 46346416
A34: 2.5.4 | B34: Бир йилдан кам муддатли жами мажбуриятларнинг 30 фоизи | C34: =+('Bank Liabilities Analysis'!E42+'Bank Liabilities Analysis'!G42+'Bank Liabilities Analysis'!I42+'Bank Liabilities Analysis'!K42+'Bank Liabilities Analysis'!M42)*0.3 -> 2.0903223e+09 | D34: =+('Bank Liabilities Analysis (нац)'!D43+'Bank Liabilities Analysis (нац)'!E43+'Bank Liabilities Analysis (нац)'!F43+'Bank Liabilities Analysis (нац)'!G43+'Bank Liabilities Analysis (нац)'!H43)*0.3 -> 1.4927116e+09 | E34: =+('Bank Liabilities Analysis'!F42+'Bank Liabilities Analysis'!H42+'Bank Liabilities Analysis'!J42+'Bank Liabilities Analysis'!L42+'Bank Liabilities Analysis'!N42)*0.3 -> 597610674
A35: 2.6 | B35: Барқарор молиялаштиришнинг зарур суммаси | C35: =SUM(C36:C41) -> 1.5784449e+10 | D35: =SUM(D36:D41) -> 1.2501028e+10 | E35: =SUM(E36:E41) -> 3.2639313e+09
A36: 2.6.1 | B36: Бир йилдан ортиқ муддатли активлар | C36: =+'Bank Assets Analysis'!O47-'Bank Assets Analysis'!O37+'Bank Assets Analysis'!Q47-'Bank Assets Analysis'!Q37-'Bank Assets Analysis'!O19-'Bank Assets Analysis'!Q19 -> 11334872669 | D36: =+C36-E36 -> 9214081795 | E36: =+'Bank Assets Analysis'!P47-'Bank Assets Analysis'!P40-'Bank Assets Analysis'!P37+'Bank Assets Analysis'!R47-'Bank Assets Analysis'!R40-'Bank Assets Analysis'!R37-'Bank Assets Analysis'!P19-'Bank Assets Analysis'!R19 -> 2120790874
A37: 2.6.2 | B37: Қайтариш муддати бир йилдан ортиқ бўлган номолиявий активлар (ер участкалари, бинолар, мебель, компьютерлар ва автомашиналар) | C37: =+'Bank Assets Analysis'!O37+'Bank Assets Analysis'!O38+'Bank Assets Analysis'!Q37+'Bank Assets Analysis'!Q38 -> 929814271 | D37: =+C37-E37 -> 929814271 | E37: =+'Bank Assets Analysis'!P37+'Bank Assets Analysis'!P38+'Bank Assets Analysis'!R37+'Bank Assets Analysis'!R38 -> 0
A38: 2.6.3 | B38: Суд жараёнида бўлган ёки белгиланган тартибда ундирилмаган кредит ва лизинглар, соф | C38: =+'Bank Assets Analysis'!C28+'Bank Assets Analysis'!C29+'Bank Assets Analysis'!C30+'Bank Assets Analysis'!C32 -> 809913491 | D38: =+'Bank Assets Analysis (нац)'!C28+'Bank Assets Analysis (нац)'!C29+'Bank Assets Analysis (нац)'!C30+'Bank Assets Analysis (нац)'!C32 -> 436377233 | E38: =+'Bank Assets Analysis'!D28+'Bank Assets Analysis'!D29+'Bank Assets Analysis'!D30+'Bank Assets Analysis'!D32 -> 373536258
A39: 2.6.4 | B39: Суд жараёнида бўлган ёки белгиланган тартибда ундирилмаган активлар, соф (2.6.3-қаторда кўрсатилмаган қисми) | C39: =+D39+E39 -> 0 | D39: 0 | E39: 0
A40: 2.6.5 | B40: Қайтариш муддати 1 йилдан кам бўлган бошқа активлар суммасининг 30 фоизи (қайтариш муддати 1 йилдан кам бўлган ёки муддатсиз ликвидли активлар бундан мустасно) | C40: =((+'Bank Assets Analysis'!S47-'Bank Assets Analysis'!O47-'Bank Assets Analysis'!Q47-('Liquidity Analysis'!C58-'Bank Assets Analysis'!O19-'Bank Assets Analysis'!Q19))*0.3) -> 2.4938998e+09 | D40: =('Bank Assets Analysis (нац)'!K47-'Bank Assets Analysis (нац)'!I47-'Bank Assets Analysis (нац)'!J47-('Liquidity Analysis'!D58-'Bank Assets Analysis (нац)'!I19-'Bank Assets Analysis (нац)'!J19))*0.3 -> 1.850779e+09 | E40: =(('Bank Assets Analysis'!U47-'Bank Assets Analysis'!P47-'Bank Assets Analysis'!R47-('Liquidity Analysis'!E58-'Bank Assets Analysis'!P19-'Bank Assets Analysis'!R19))*0.3) -> 6.2363104e+08
...

Sheet Bank Assets Analysis
A1: БАНК АКТИВЛАРИ ТАҲЛИЛИ | X1: 17-жадвал
B2: =Balance!B3 -> "MKBANK" | X2: =+Balance!D3 -> 45657 | Z2: минг сўмда
A3: № | B3: Кўрсаткичлар | C3: Сўндириш муддати (кунларда) | S3: Жами | T3: шундан, | V3: Ликвидлиликни қоплаш меёри ҳисоб китоби
C4: Муддатсиз | E4: 1 дан 7 гача | G4: 8 дан 30 гача | I4: 31 дан 90 гача | K4: 91 дан 180 гача | M4: 181 дан 365 гача | O4: 366 дан 730 гача | Q4: 2 йилдан ортиқ
C5: Сумма | D5: шундан, хорижий валютада (сўм экв.) | E5: Сумма | F5: шундан, хорижий валютада (сўм экв.) | G5: Сумма | H5: шундан, хорижий валютада (сўм экв.) | I5: Сумма | J5: шундан, хорижий валютада (сўм экв.) | K5: Сумма | L5: шундан, хорижий валютада (сўм экв.) | M5: Сумма | N5: шундан, хорижий валютада (сўм экв.) | O5: Сумма | P5: шундан, хорижий валютада (сўм экв.) | Q5: Сумма | R5: шундан, хорижий валютада (сўм экв.) | T5: миллий валютада | U5: хорижий валютада (сўм экв.) | V5: Коэффициент | W5: Активлар | X5: Юқори ликвидли активлар/кирим | Y5: Активлар (хорижий валютада) | Z5: Юқори ликвидли активлар/кирим (хорижий валютада)
A6: 1 | B6: Кассадаги нақд пул ва бошқа тўлов ҳужжатлари | C6: 874095566 | D6: 212516439 | E6: 0 | F6: 0 | G6: 0 | H6: 0 | I6: 0 | J6: 0 | K6: 0 | L6: 0 | M6: 0 | N6: 0 | O6: 0 | P6: 0 | Q6: 0 | R6: 0 | S6: =+C6+E6+G6+I6+K6+M6+O6+Q6 -> 874095566 | T6: =+S6-U6 -> 661579127 | U6: =+D6+F6+H6+J6+L6+N6+P6+R6 -> 212516439 | V6: 1 | W6: =+S6 -> 874095566 | X6: =+W6*V6 -> 874095566 | Y6: =+U6 -> 212516439 | Z6: =+Y6*V6 -> 212516439
A7: 2 | B7: Банкнинг Марказий банкдаги маблағлари (мажбурий захирасиз) | C7: 246195792 | D7: 0 | E7: 250000000 | F7: 0 | G7: 0 | H7: 0 | I7: 0 | J7: 0 | K7: 0 | L7: 0 | M7: 0 | N7: 0 | O7: 0 | P7: 0 | Q7: 0 | R7: 0 | S7: =+C7+E7+G7+I7+K7+M7+O7+Q7 -> 496195792 | T7: =+S7-U7 -> 496195792 | U7: =+D7+F7+H7+J7+L7+N7+P7+R7 -> 0 | V7: 1 | W7: =S7 -> 496195792 | X7: =+W7*V7 -> 496195792 | Y7: =+U7 -> 0 | Z7: =+Y7*V7 -> 0
A8: 2.1 | B8: Банкнинг Марказий банкдаги мажбурий захира ҳисобварағидаги маблағлар | C8: 0 | D8: 0 | E8: 0 | F8: 0 | G8: 0 | H8: 0 | I8: 0 | J8: 0 | K8: 0 | L8: 0 | M8: 0 | N8: 0 | O8: 0 | P8: 0 | Q8: 0 | R8: 0 | S8: =+C8+E8+G8+I8+K8+M8+O8+Q8 -> 0 | T8: =+S8-U8 -> 0 | U8: =+D8+F8+H8+J8+L8+N8+P8+R8 -> 0 | V8: 0
A9: 3 | B9: Бошқа банклар ва молиявий ташкилотлардан олиниши лозим бўлган маблағлар | C9: =SUM(C10:C16)-C13 -> 1378527034 | D9: =SUM(D10:D16)-D13 -> 1362283968 | E9: =SUM(E10:E16)-E13 -> 0 | F9: =SUM(F10:F16)-F13 -> 0 | G9: =SUM(G10:G16)-G13 -> 64602400 | H9: =SUM(H10:H16)-H13 -> 64602400 | I9: =SUM(I10:I16)-I13 -> 10465589 | J9: =SUM(J10:J16)-J13 -> 10465589 | ... R9: =SUM(R10:R16)-R13 -> 14666275 | S9: =+C9+E9+G9+I9+K9+M9+O9+Q9 -> 1530859823 | T9: =+S9-U9 -> 75605011 | U9: =+D9+F9+H9+J9+L9+N9+P9+R9 -> 1455254812
A10: 3.1 | B10: Таваккалчилик даражаси паст банклардаги вакиллик ҳисобварақлари (ностро) | C10: 586152820 | D10: 586152820 | E10: 0 | F10: 0 | G10: 0 | H10: 0 | I10: 0 | J10: 0 | K10: 0 | L10: 0 | M10: 0 | N10: 0 | O10: 0 | P10: 0 | Q10: 0 | R10: 0 | S10: =+C10+E10+G10+I10+K10+M10+O10+Q10 -> 586152820 | T10: =+S10-U10 -> 0 | U10: =+D10+F10+H10+J10+L10+N10+P10+R10 -> 586152820 | V10: 1 | W10: =+C10 -> 586152820 | X10: =+W10*V10 -> 586152820 | Y10: =+D10 -> 586152820 | Z10: =+Y10*V10 -> 586152820
A11: 3.2 | B11: Маҳаллий банклардаги вакиллик ҳисобварақлари (ностро) | C11: 775040043 | D11: 775040038 | S11: =+C11 -> 775040043 | T11: =+S11-U11 -> 5 | U11: =+D11 -> 775040038 | V11: 1 | W11: =+C11 -> 775040043 | X11: =+W11*V11 -> 775040043 | Y11: =+D11 -> 775040038 | Z11: =+Y11*V11 -> 775040038
A12: 3.3 | B12: Овернайт шарти билан жойлаштирилган депозитлар | E12: 0 | F12: 0 | S12: =+E12 -> 0 | T12: =+S12-U12 -> 0 | U12: =+F12 -> 0 | V12: 1 | W12: =+E12-E13 -> 0 | X12: =+W12*V12 -> 0 | Y12: =+F12-F13 -> 0 | Z12: =+Y12*V12 -> 0
A13: 3.3.1. | B13: шундан, инвестицион даражадан паст бўлмаган рейтингга эга банкларга овернайт шарти билан жойлаштирилган хорижий валютадаги депозитлар | E13: 0 | F13: 0 | S13: =+E13 -> 0 | T13: =+S13-U13 -> 0 | U13: =+F13 -> 0 | V13: 1 | W13: =+F13 -> 0 | X13: =+W13*V13 -> 0 | Y13: =+F13 -> 0 | Z13: =+Y13*V13 -> 0
A14: 3.4 | B14: Банкнинг бошқа банклар/молиявий ташкилотлардаги ҳисобварақлари | C14: 977851 | D14: 363398 | E14: 0 | F14: 0 | G14: 64602400 | H14: 64602400 | I14: 10465589 | J14: 10465589 | K14: 8116975 | L14: 3236580 | M14: 5505394 | N14: 0 | O14: 14342260 | P14: 0 | Q14: 49300171 | R14: 14666275 | S14: =+C14+E14+G14+I14+K14+M14+O14+Q14 -> 153310640 | T14: =+S14-U14 -> 59976398 | U14: =+D14+F14+H14+J14+L14+N14+P14+R14 -> 93334242 | V14: 1 | W14: =+C14+E14+G14+E10+G10+E11+G11 -> 65580251 | X14: =+W14*V14 -> 65580251 | Y14: =+D14+F14+H14+F10+H10+F11+H11 -> 64965798 | Z14: =+Y14*V14 -> 64965798
A15: 3.5 | B15: Пластик карталардан амалга оширилган тўловлар бўйича бошқа банклардан олиниши лозим бўлган маблағлар | C15: 16356320 | D15: 727712 | E15: 0 | F15: 0 | G15: 0 | H15: 0 | I15: 0 | J15: 0 | K15: 0 | L15: 0 | M15: 0 | N15: 0 | O15: 0 | P15: 0 | Q15: 0 | R15: 0 | S15: =+C15+E15+G15+I15+K15+M15+O15+Q15 -> 16356320 | T15: =+S15-U15 -> 15628608 | U15: =+D15+F15+H15+J15+L15+N15+P15+R15 -> 727712 | V15: 1 | W15: =+C15+E15+G15 -> 16356320 | X15: =+W15*V15 -> 16356320 | Y15: =+D15+F15+H15 -> 727712 | Z15: =+Y15*V15 -> 727712
A16: 3.6 | B16: Бошқа моддалар | S16: =+C16+E16+G16+I16+K16+M16+O16+Q16 -> 0 | T16: =+S16-U16 -> 0 | U16: =+D16+F16+H16+J16+L16+N16+P16+R16 -> 0 | V16: 1 | W16: =+C16+E16+G16 -> 0 | X16: =+W16*V16 -> 0 | Y16: =+D16+F16+H16 -> 0 | Z16: =+Y16*V16 -> 0
A17: 4 | B17: Қимматли қоғозлар ва уларга қилинган инвестициялар, соф | C17: =SUM(C19:C25) -> 175 | D17: =SUM(D19:D25) -> 0 | E17: =SUM(E19:E25) -> 0 | F17: =SUM(F19:F25) -> 0 | G17: =SUM(G19:G25) -> 103422526 | H17: =SUM(H19:H25) -> 0 | I17: =SUM(I19:I25) -> 52056510 | J17: =SUM(J19:J25) -> 0 | ... R17: =SUM(R19:R25) -> 0 | S17: =+C17+E17+G17+I17+K17+M17+O17+Q17 -> 211358621 | T17: =+S17-U17 -> 211358621 | U17: =+D17+F17+H17+J17+L17+N17+P17+R17 -> 0
A18: 4a | B18: шу жумладан, таъминот остидаги юқори ликвидли қимматли қоғозлар | C18: =+'Bank Liabilities Analysis'!C34 -> 0 | D18: =+'Bank Liabilities Analysis'!D34 -> 0 | E18: =+'Bank Liabilities Analysis'!E34 -> 0 | F18: =+'Bank Liabilities Analysis'!F34 -> 0 | G18: =+'Bank Liabilities Analysis'!G34 -> 0 | H18: =+'Bank Liabilities Analysis'!H34 -> 0 | I18: =+'Bank Liabilities Analysis'!I34 -> 0 | J18: =+'Bank Liabilities Analysis'!J34 -> 0 | ... R18: =+'Bank Liabilities Analysis'!R34 -> 0 | S18: =+C18+E18+G18+I18+K18+M18+O18+Q18 -> 0 | T18: =+S18-U18 -> 0 | U18: =+D18+F18+H18+J18+L18+N18+P18+R18 -> 0 | V18: 1 | W18: =+C18+E18+G18 -> 0 | X18: =+W18*V18 -> 0 | Y18: =+D18+F18+H18 -> 0 | Z18: =+Y18*V18 -> 0
A19: 4.1 | B19: Ўзбекистон Республикаси Ҳукумати ва Марказий банк томонидан чиқарилган қимматли қоғозлар (векселлар, облигациялар ва бошқа қарз қимматли қоғозлар) | C19: 0 | D19: 0 | E19: 0 | F19: 0 | G19: 103422526 | H19: 0 | I19: 52056510 | J19: 0 | K19: 0 | L19: 0 | M19: 45879410 | N19: 0 | O19: 0 | P19: 0 | Q19: 0 | R19: 0 | S19: =+C19+E19+G19+I19+K19+M19+O19+Q19 -> 201358446 | T19: =+S19-U19 -> 201358446 | U19: =+D19+F19+H19+J19+L19+N19+P19+R19 -> 0 | V19: 1 | W19: =+S19 -> 201358446 | X19: =+W19*V19 -> 201358446 | Y19: =+U19 -> 0 | Z19: =+Y19*V19 -> 0
A20: 4.2 | B20: Таваккалчилик даражаси паст бўлган мамлакатларнинг қимматли қоғозлари | C20: 0 | D20: 0 | E20: 0 | F20: 0 | G20: 0 | H20: 0 | I20: 0 | J20: 0 | K20: 0 | L20: 0 | M20: 0 | N20: 0 | O20: 0 | P20: 0 | Q20: 0 | R20: 0 | S20: =+C20+E20+G20+I20+K20+M20+O20+Q20 -> 0 | T20: =+S20-U20 -> 0 | U20: =+D20+F20+H20+J20+L20+N20+P20+R20 -> 0 | V20: 1 | W20: =+S20 -> 0 | X20: =+W20*V20 -> 0 | Y20: =+U20 -> 0 | Z20: =+Y20*V20 -> 0
A21: 4.3 | B21: ХВФ, Жаҳон банки гуруҳи, Осиё тараққиёт банки, Осиё инфраструктура инвестиция банки, ЕТТБ, Европа инвестиция банки, Европа инвестиция жамғармаси, Ислом тараққиёт банки ва Европа Кенгашининг тараққиёт банки томонидан чиқарилган қимматли қоғозлар | C21: 0 | D21: 0 | E21: 0 | F21: 0 | G21: 0 | H21: 0 | I21: 0 | J21: 0 | K21: 0 | L21: 0 | M21: 0 | N21: 0 | O21: 0 | P21: 0 | Q21: 0 | R21: 0 | S21: =+C21+E21+G21+I21+K21+M21+O21+Q21 -> 0 | T21: =+S21-U21 -> 0 | U21: =+D21+F21+H21+J21+L21+N21+P21+R21 -> 0 | V21: 1 | W21: =+S21 -> 0 | X21: =+W21*V21 -> 0 | Y21: =+U21 -> 0 | Z21: =+Y21*V21 -> 0
A22: 4.4 | B22: Таваккалчилик даражаси паст бўлган мамлакатларнинг етакчи компаниялари қимматли қоғозлари | C22: 0 | D22: 0 | E22: 0 | F22: 0 | G22: 0 | H22: 0 | I22: 0 | J22: 0 | K22: 0 | L22: 0 | M22: 0 | N22: 0 | O22: 0 | P22: 0 | Q22: 0 | R22: 0 | S22: =+C22+E22+G22+I22+K22+M22+O22+Q22 -> 0 | T22: =+S22-U22 -> 0 | U22: =+D22+F22+H22+J22+L22+N22+P22+R22 -> 0 | V22: 1 | W22: =+S22 -> 0 | X22: =+W22*V22 -> 0 | Y22: =+U22 -> 0 | Z22: =+Y22*V22 -> 0
A23: 4.5 | B23: Ипотекани қайта молиялаштириш ташкилотлари томонидан чиқарилган корпоратив облигациялар | C23: 0 | D23: 0 | E23: 0 | F23: 0 | G23: 0 | H23: 0 | I23: 0 | J23: 0 | K23: 0 | L23: 0 | M23: 0 | N23: 0 | O23: 10000000 | P23: 0 | Q23: 0 | R23: 0 | S23: =+C23+E23+G23+I23+K23+M23+O23+Q23 -> 10000000 | T23: =+S23-U23 -> 10000000 | U23: =+D23+F23+H23+J23+L23+N23+P23+R23 -> 0 | V23: 0.8 | W23: =+S23 -> 10000000 | X23: =+W23*V23 -> 8000000 | Y23: =+U23 -> 0 | Z23: =+Y23*V23 -> 0
A24: 4.6 | B24: Ипотекани қайта молиялаштириш ташкилотлари томонидан чиқарилган таъминланган қарз муносабатларини тасдиқловчи бошқа қимматли қоғозлар | C24: 0 | D24: 0 | E24: 0 | F24: 0 | G24: 0 | H24: 0 | I24: 0 | J24: 0 | K24: 0 | L24: 0 | M24: 0 | N24: 0 | O24: 0 | P24: 0 | Q24: 0 | R24: 0 | S24: =+C24+E24+G24+I24+K24+M24+O24+Q24 -> 0 | T24: =+S24-U24 -> 0 | U24: =+D24+F24+H24+J24+L24+N24+P24+R24 -> 0 | V24: 1 | W24: =+S24 -> 0 | X24: =+W24*V24 -> 0 | Y24: =+U24 -> 0 | Z24: =+Y24*V24 -> 0
A25: 4.7 | B25: Бошқалар | C25: 175 | D25: 0 | E25: 0 | F25: 0 | G25: 0 | H25: 0 | I25: 0 | J25: 0 | K25: 0 | L25: 0 | M25: 0 | N25: 0 | O25: 0 | P25: 0 | Q25: 0 | R25: 0 | S25: =+C25+E25+G25+I25+K25+M25+O25+Q25 -> 175 | T25: =+S25-U25 -> 175 | U25: =+D25+F25+H25+J25+L25+N25+P25+R25 -> 0 | V25: 1 | W25: =+C25+E25+G25 -> 175 | X25: =+W25*V25 -> 175 | Y25: =+D25+F25+H25 -> 0 | Z25: =+Y25*V25 -> 0
A26: 5 | B26: Мижозларнинг аккредитив ва траст ҳужжатлари билан кафолатланган тратталари бўйича мажбуриятлари, соф | C26: 30025798 | D26: 28625774 | E26: 0 | F26: 0 | G26: 0 | H26: 0 | I26: 0 | J26: 0 | K26: 0 | L26: 0 | M26: 0 | N26: 0 | O26: 0 | P26: 0 | Q26: 0 | R26: 0 | S26: =+C26+E26+G26+I26+K26+M26+O26+Q26 -> 30025798 | T26: =+S26-U26 -> 1400024 | U26: =+D26+F26+H26+J26+L26+N26+P26+R26 -> 28625774 | V26: 0.5 | W26: =+E26+G26 -> 0 | X26: =+W26*V26 -> 0 | Y26: =+F26+H26 -> 0 | Z26: =+Y26*V26 -> 0
A27: 6 | B27: Мижозларнинг банк олдидаги тўланмаган акцептлари бўйича мажбуриятлари, соф | C27: 0 | D27: 0 | E27: 0 | F27: 0 | G27: 0 | H27: 0 | I27: 0 | J27: 0 | K27: 0 | L27: 0 | M27: 0 | N27: 0 | O27: 0 | P27: 0 | Q27: 0 | R27: 0 | S27: =+C27+E27+G27+I27+K27+M27+O27+Q27 -> 0 | T27: =+S27-U27 -> 0 | U27: =+D27+F27+H27+J27+L27+N27+P27+R27 -> 0 | V27: 0.5 | W27: =+E27+G27 -> 0 | X27: =+W27*V27 -> 0 | Y27: =+F27+H27 -> 0 | Z27: =+Y27*V27 -> 0
A28: 7 | B28: Марказий банкка берилган кредит ва лизинглар, соф | C28: 0 | D28: 0 | E28: 0 | F28: 0 | G28: 0 | H28: 0 | I28: 0 | J28: 0 | K28: 0 | L28: 0 | M28: 0 | N28: 0 | O28: 0 | P28: 0 | Q28: 0 | R28: 0 | S28: =+C28+E28+G28+I28+K28+M28+O28+Q28 -> 0 | T28: =+S28-U28 -> 0 | U28: =+D28+F28+H28+J28+L28+N28+P28+R28 -> 0 | V28: 1 | W28: =+C28+E28+G28 -> 0 | X28: =+W28*V28 -> 0 | Y28: =+D28+F28+H28 -> 0 | Z28: =+Y28*V28 -> 0
A29: 8 | B29: Бошқа банкларга берилган кредит ва лизинглар, соф | C29: 0 | D29: 0 | E29: 0 | F29: 0 | G29: 0 | H29: 0 | I29: 0 | J29: 0 | K29: 0 | L29: 0 | M29: 0 | N29: 0 | O29: 0 | P29: 0 | Q29: 0 | R29: 0 | S29: =+C29+E29+G29+I29+K29+M29+O29+Q29 -> 0 | T29: =+S29-U29 -> 0 | U29: =+D29+F29+H29+J29+L29+N29+P29+R29 -> 0 | V29: 0.5 | W29: =+E29+G29 -> 0 | X29: =+W29*V29 -> 0 | Y29: =+F29+H29 -> 0 | Z29: =+Y29*V29 -> 0
A30: 9 | B30: Мижозларга берилган кредит ва лизинглар, соф | C30: 789012665 | D30: 373074797 | E30: 419150948 | F30: 185707333 | G30: 35459625 | H30: 15710599 | I30: 1008786882 | J30: 425881352 | K30: 1212869437 | L30: 233315051 | M30: 2177195549 | N30: 362334911 | O30: 3315476688 | P30: 653786610 | Q30: 7945753550 | R30: 1452337989 | S30: =+C30+E30+G30+I30+K30+M30+O30+Q30 -> 16903705344 | T30: =+S30-U30 -> 13201556702 | U30: =+D30+F30+H30+J30+L30+N30+P30+R30 -> 3702148642 | V30: 0.5 | W30: =+E30+G30 -> 454610573 | X30: =+W30*V30 -> 2.2730529e+08 | Y30: =+F30+H30 -> 201417932 | Z30: =+Y30*V30 -> 100708966
A31: 9.1 | B31: шу жумладан, жисмоний шахсларга берилган кредит ва лизинглар | C31: 217619303 | D31: 0 | E31: 152010825 | F31: 0 | G31: 6004586 | H31: 0 | I31: 338488547 | J31: 0 | K31: 512116570 | L31: 0 | M31: 972815556 | N31: 0 | O31: 1391014546 | P31: 0 | Q31: 3359108523 | R31: 0 | S31: =+C31+E31+G31+I31+K31+M31+O31+Q31 -> 6949178456 | T31: =+S31-U31 -> 6949178456 | U31: =+D31+F31+H31+J31+L31+N31+P31+R31 -> 0 | V31: 0 | W31: =+E31+G31 -> 158015411 | X31: =+W31*V31 -> 0 | Y31: =+F31+H31 -> 0 | Z31: =+Y31*V31 -> 0
A32: 10 | B32: Суд ёки ижро иши юритиш жараёнидаги кредитлар ва лизинг, соф | C32: 20900826 | D32: 461461 | S32: =+C32+E32+G32+I32+K32+M32+O32+Q32 -> 20900826 | T32: =+S32-U32 -> 20439365 | U32: =+D32+F32+H32+J32+L32+N32+P32+R32 -> 461461 | V32: 0 | W32: =+E32+G32 -> 0 | X32: =+W32*V32 -> 0 | Y32: =+F32+H32 -> 0 | Z32: =+Y32*V32 -> 0
A33: 11 | B33: Инвестициялар, соф | C33: 171402110 | D33: 0 | E33: 0 | F33: 0 | G33: 0 | H33: 0 | I33: 0 | J33: 0 | K33: 0 | L33: 0 | M33: 0 | N33: 0 | O33: 0 | P33: 0 | Q33: 0 | R33: 0 | S33: =+C33+E33+G33+I33+K33+M33+O33+Q33 -> 171402110 | T33: =+S33-U33 -> 171402110 | U33: =+D33+F33+H33+J33+L33+N33+P33+R33 -> 0 | V33: 0 | W33: =+E33+G33 -> 0 | X33: =+W33*V33 -> 0 | Y33: =+F33+H33 -> 0 | Z33: =+Y33*V33 -> 0
A34: 12 | B34: РЕПО битимлари бўйича сотиб олинган қимматли қоғозлар | C34: =+C35+C36 -> 0 | D34: =+D35+D36 -> 0 | E34: =+E35+E36 -> 0 | F34: =+F35+F36 -> 0 | G34: =+G35+G36 -> 0 | H34: =+H35+H36 -> 0 | I34: =+I35+I36 -> 0 | J34: =+J35+J36 -> 0 | ... R34: =+R35+R36 -> 0 | S34: =+C34+E34+G34+I34+K34+M34+O34+Q34 -> 0 | T34: =+S34-U34 -> 0 | U34: =+D34+F34+H34+J34+L34+N34+P34+R34 -> 0 | V34: 0 | W34: =+E34+G34 -> 0 | X34: =+W34*V34 -> 0 | Y34: =+F34+H34 -> 0 | Z34: =+Y34*V34 -> 0
A35: 12.1 | B35: РЕПО битимлари бўйича сотиб олинган юқори ликвидли қимматли қоғозлар | C35: 0 | D35: 0 | E35: 0 | F35: 0 | G35: 0 | H35: 0 | I35: 0 | J35: 0 | K35: 0 | L35: 0 | M35: 0 | N35: 0 | O35: 0 | P35: 0 | Q35: 0 | R35: 0 | S35: =+C35+E35+G35+I35+K35+M35+O35+Q35 -> 0 | T35: =+S35-U35 -> 0 | U35: =+D35+F35+H35+J35+L35+N35+P35+R35 -> 0 | V35: 1 | W35: =+S35 -> 0 | X35: =+W35*V35 -> 0 | Y35: =+U35 -> 0 | Z35: =+Y35*V35 -> 0
A36: 12.2 | B36: РЕПО битимлари бўйича сотиб олинган бошқа қимматли қоғозлар | C36: 0 | D36: 0 | E36: 0 | F36: 0 | G36: 0 | H36: 0 | I36: 0 | J36: 0 | K36: 0 | L36: 0 | M36: 0 | N36: 0 | O36: 0 | P36: 0 | Q36: 0 | R36: 0 | S36: =+C36+E36+G36+I36+K36+M36+O36+Q36 -> 0 | T36: =+S36-U36 -> 0 | U36: =+D36+F36+H36+J36+L36+N36+P36+R36 -> 0 | V36: 0
A37: 13 | B37: Aсосий воситалар, соф | C37: 0 | D37: 0 | E37: 0 | F37: 0 | G37: 0 | H37: 0 | I37: 0 | J37: 0 | K37: 0 | L37: 0 | M37: 0 | N37: 0 | O37: 0 | P37: 0 | Q37: 929814271 | R37: 0 | S37: =+C37+E37+G37+I37+K37+M37+O37+Q37 -> 929814271 | T37: =+S37-U37 -> 929814271 | U37: =+D37+F37+H37+J37+L37+N37+P37+R37 -> 0 | V37: 0
A38: 14 | B38: Банкнинг бошқа хусусий мулклари, соф | C38: 408190381 | D38: 0 | E38: 0 | F38: 0 | G38: 0 | H38: 0 | I38: 0 | J38: 0 | K38: 0 | L38: 0 | M38: 0 | N38: 0 | O38: 0 | P38: 0 | Q38: 0 | R38: 0 | S38: =+C38+E38+G38+I38+K38+M38+O38+Q38 -> 408190381 | T38: =+S38-U38 -> 408190381 | U38: =+D38+F38+H38+J38+L38+N38+P38+R38 -> 0 | V38: 0
A39: 15 | B39: Ҳосилавий инструментларнинг ревальвацияси натижасида ўзлаштирилмаган фойда | C39: 0 | D39: 0 | E39: 0 | F39: 0 | G39: 0 | H39: 0 | I39: 0 | J39: 0 | K39: 0 | L39: 0 | M39: 0 | N39: 0 | O39: 0 | P39: 0 | Q39: 0 | R39: 0 | S39: =+C39+E39+G39+I39+K39+M39+O39+Q39 -> 0 | T39: =+S39-U39 -> 0 | U39: =+D39+F39+H39+J39+L39+N39+P39+R39 -> 0 | V39: 0
A40: 16 | B40: Валюта савдоси ва валюта позициялари | C40: 0 | E40: 0 | G40: 0 | I40: 0 | K40: 0 | M40: 0 | O40: 0 | Q40: 0 | S40: =+C40+E40+G40+I40+K40+M40+O40+Q40 -> 0 | T40: =+S40-U40 -> 0 | U40: =+D40+F40+H40+J40+L40+N40+P40+R40 -> 0 | V40: 0
...

Sheet Bank Assets Analysis (нац)
A2: МИЛЛИЙ ВАЛЮТАДАГИ БАНК АКТИВЛАРИ ТАҲЛИЛИ | L2: 17 А-жадвал
B3: =Balance!B3 -> "MKBANK" | K3: =+Balance!D3 -> 45657 | N3: =+Balance!E3 -> минг сўмда
A4: № | B4: Кўрсаткичлар | C4: Сўндириш муддати (кунларда) | K4: Жами | L4: Ликвидлиликни қоплаш меёри ҳисоб китоби
C5: Муддатсиз | D5: 1 дан 7 гача | E5: 8 дан 30 гача | F5: 31 дан 90 гача | G5: 91 дан 180 гача | H5: 181 дан 365 гача | I5: 366 дан 730 гача | J5: 2 йилдан ортиқ | L5: Коэффициент | M5: Активлар | N5: Юқори ликвидли активлар/кирим
A6: 1 | B6: Кассадаги нақд пул ва бошқа тўлов ҳужжатлари | C6: =+'Bank Assets Analysis'!C6-'Bank Assets Analysis'!D6 -> 661579127 | D6: =+'Bank Assets Analysis'!E6-'Bank Assets Analysis'!F6 -> 0 | E6: =+'Bank Assets Analysis'!G6-'Bank Assets Analysis'!H6 -> 0 | F6: =+'Bank Assets Analysis'!I6-'Bank Assets Analysis'!J6 -> 0 | G6: =+'Bank Assets Analysis'!K6-'Bank Assets Analysis'!L6 -> 0 | H6: =+'Bank Assets Analysis'!M6-'Bank Assets Analysis'!N6 -> 0 | I6: =+'Bank Assets Analysis'!O6-'Bank Assets Analysis'!P6 -> 0 | J6: =+'Bank Assets Analysis'!Q6-'Bank Assets Analysis'!R6 -> 0 | K6: =+C6+D6+E6+F6+G6+H6+I6+J6 -> 661579127 | L6: 1 | M6: =+K6 -> 661579127 | N6: =+M6*L6 -> 661579127
A7: 2 | B7: Банкнинг Марказий банкдаги маблағлари (мажбурий захирасиз) | C7: =+'Bank Assets Analysis'!C7-'Bank Assets Analysis'!D7 -> 246195792 | D7: =+'Bank Assets Analysis'!E7-'Bank Assets Analysis'!F7 -> 250000000 | E7: =+'Bank Assets Analysis'!G7-'Bank Assets Analysis'!H7 -> 0 | F7: =+'Bank Assets Analysis'!I7-'Bank Assets Analysis'!J7 -> 0 | G7: =+'Bank Assets Analysis'!K7-'Bank Assets Analysis'!L7 -> 0 | H7: =+'Bank Assets Analysis'!M7-'Bank Assets Analysis'!N7 -> 0 | I7: =+'Bank Assets Analysis'!O7-'Bank Assets Analysis'!P7 -> 0 | J7: =+'Bank Assets Analysis'!Q7-'Bank Assets Analysis'!R7 -> 0 | K7: =+C7+D7+E7+F7+G7+H7+I7+J7 -> 496195792 | L7: 1 | M7: =+K7 -> 496195792 | N7: =+M7*L7 -> 496195792
A8: 2.1 | B8: Банкнинг Марказий банкдаги мажбурий захира ҳисобварағидаги маблағлар | C8: =+'Bank Assets Analysis'!C8-'Bank Assets Analysis'!D8 -> 0 | D8: =+'Bank Assets Analysis'!E8-'Bank Assets Analysis'!F8 -> 0 | E8: =+'Bank Assets Analysis'!G8-'Bank Assets Analysis'!H8 -> 0 | F8: =+'Bank Assets Analysis'!I8-'Bank Assets Analysis'!J8 -> 0 | G8: =+'Bank Assets Analysis'!K8-'Bank Assets Analysis'!L8 -> 0 | H8: =+'Bank Assets Analysis'!M8-'Bank Assets Analysis'!N8 -> 0 | I8: =+'Bank Assets Analysis'!O8-'Bank Assets Analysis'!P8 -> 0 | J8: =+'Bank Assets Analysis'!Q8-'Bank Assets Analysis'!R8 -> 0 | K8: =+C8+D8+E8+F8+G8+H8+I8+J8 -> 0 | L8: 0 | N8: =+M8*L8 -> 0
A9: 3 | B9: Бошқа банклар ва молиявий ташкилотлардан олиниши лозим бўлган маблағлар | C9: =SUM(C10:C16)-C13 -> 16243066 | D9: =SUM(D10:D16)-D13 -> 0 | E9: =SUM(E10:E16)-E13 -> 0 | F9: =SUM(F10:F16)-F13 -> 0 | G9: =SUM(G10:G16)-G13 -> 4880395 | H9: =SUM(H10:H16)-H13 -> 5505394 | I9: =SUM(I10:I16)-I13 -> 14342260 | J9: =SUM(J10:J16)-J13 -> 34633896 | K9: =+C9+D9+E9+F9+G9+H9+I9+J9 -> 75605011 | N9: =+M9*L9 -> 0
A10: 3.1 | B10: Таваккалчилик даражаси паст банклардаги вакиллик ҳисобварақлари (ностро) | C10: =+'Bank Assets Analysis'!C10-'Bank Assets Analysis'!D10 -> 0 | D10: =+'Bank Assets Analysis'!E10-'Bank Assets Analysis'!F10 -> 0 | E10: =+'Bank Assets Analysis'!G10-'Bank Assets Analysis'!H10 -> 0 | F10: =+'Bank Assets Analysis'!I10-'Bank Assets Analysis'!J10 -> 0 | G10: =+'Bank Assets Analysis'!K10-'Bank Assets Analysis'!L10 -> 0 | H10: =+'Bank Assets Analysis'!M10-'Bank Assets Analysis'!N10 -> 0 | I10: =+'Bank Assets Analysis'!O10-'Bank Assets Analysis'!P10 -> 0 | J10: =+'Bank Assets Analysis'!Q10-'Bank Assets Analysis'!R10 -> 0 | K10: =+C10+D10+E10+F10+G10+H10+I10+J10 -> 0 | L10: 1 | M10: =+C10 -> 0 | N10: =+M10*L10 -> 0
A11: 3.2 | B11: Маҳаллий банклардаги вакиллик ҳисобварақлари (ностро) | C11: =+'Bank Assets Analysis'!C11-'Bank Assets Analysis'!D11 -> 5 | D11: =+'Bank Assets Analysis'!E11-'Bank Assets Analysis'!F11 -> 0 | E11: =+'Bank Assets Analysis'!G11-'Bank Assets Analysis'!H11 -> 0 | F11: =+'Bank Assets Analysis'!I11-'Bank Assets Analysis'!J11 -> 0 | G11: =+'Bank Assets Analysis'!K11-'Bank Assets Analysis'!L11 -> 0 | H11: =+'Bank Assets Analysis'!M11-'Bank Assets Analysis'!N11 -> 0 | I11: =+'Bank Assets Analysis'!O11-'Bank Assets Analysis'!P11 -> 0 | J11: =+'Bank Assets Analysis'!Q11-'Bank Assets Analysis'!R11 -> 0 | K11: =+C11+D11+E11+F11+G11+H11+I11+J11 -> 5 | L11: 1 | M11: =+C11 -> 5 | N11: =+M11*L11 -> 5
A12: 3.3 | B12: Овернайт шарти билан жойлаштирилган депозитлар | C12: =+'Bank Assets Analysis'!C12-'Bank Assets Analysis'!D12 -> 0 | D12: =+'Bank Assets Analysis'!E12-'Bank Assets Analysis'!F12 -> 0 | E12: =+'Bank Assets Analysis'!G12-'Bank Assets Analysis'!H12 -> 0 | F12: =+'Bank Assets Analysis'!I12-'Bank Assets Analysis'!J12 -> 0 | G12: =+'Bank Assets Analysis'!K12-'Bank Assets Analysis'!L12 -> 0 | H12: =+'Bank Assets Analysis'!M12-'Bank Assets Analysis'!N12 -> 0 | I12: =+'Bank Assets Analysis'!O12-'Bank Assets Analysis'!P12 -> 0 | J12: =+'Bank Assets Analysis'!Q12-'Bank Assets Analysis'!R12 -> 0 | K12: =+C12+D12+E12+F12+G12+H12+I12+J12 -> 0 | L12: 1 | M12: =+D12-D13 -> 0 | N12: =+M12*L12 -> 0
A13: 3.3.1. | B13: шундан, инвестицион даражадан паст бўлмаган рейтингга эга банкларга овернайт шарти билан жойлаштирилган хорижий валютадаги депозитлар | C13: =+'Bank Assets Analysis'!C13-'Bank Assets Analysis'!D13 -> 0 | D13: =+'Bank Assets Analysis'!E13-'Bank Assets Analysis'!F13 -> 0 | E13: =+'Bank Assets Analysis'!G13-'Bank Assets Analysis'!H13 -> 0 | F13: =+'Bank Assets Analysis'!I13-'Bank Assets Analysis'!J13 -> 0 | G13: =+'Bank Assets Analysis'!K13-'Bank Assets Analysis'!L13 -> 0 | H13: =+'Bank Assets Analysis'!M13-'Bank Assets Analysis'!N13 -> 0 | I13: =+'Bank Assets Analysis'!O13-'Bank Assets Analysis'!P13 -> 0 | J13: =+'Bank Assets Analysis'!Q13-'Bank Assets Analysis'!R13 -> 0 | K13: =+C13+D13+E13+F13+G13+H13+I13+J13 -> 0 | L13: 1 | M13: =+D13 -> 0 | N13: =+M13*L13 -> 0
A14: 3.4 | B14: Банкнинг бошқа банклар/молиявий ташкилотлардаги ҳисобварақлари | C14: =+'Bank Assets Analysis'!C14-'Bank Assets Analysis'!D14 -> 614453 | D14: =+'Bank Assets Analysis'!E14-'Bank Assets Analysis'!F14 -> 0 | E14: =+'Bank Assets Analysis'!G14-'Bank Assets Analysis'!H14 -> 0 | F14: =+'Bank Assets Analysis'!I14-'Bank Assets Analysis'!J14 -> 0 | G14: =+'Bank Assets Analysis'!K14-'Bank Assets Analysis'!L14 -> 4880395 | H14: =+'Bank Assets Analysis'!M14-'Bank Assets Analysis'!N14 -> 5505394 | I14: =+'Bank Assets Analysis'!O14-'Bank Assets Analysis'!P14 -> 14342260 | J14: =+'Bank Assets Analysis'!Q14-'Bank Assets Analysis'!R14 -> 34633896 | K14: =+C14+D14+E14+F14+G14+H14+I14+J14 -> 59976398 | L14: 1 | M14: =+C14+D14+E14+D10+D11 -> 614453 | N14: =+M14*L14 -> 614453
A15: 3.5 | B15: Пластик карталардан амалга оширилган тўловлар бўйича бошқа банклардан олиниши лозим бўлган маблағлар | C15: =+'Bank Assets Analysis'!C15-'Bank Assets Analysis'!D15 -> 15628608 | D15: =+'Bank Assets Analysis'!E15-'Bank Assets Analysis'!F15 -> 0 | E15: =+'Bank Assets Analysis'!G15-'Bank Assets Analysis'!H15 -> 0 | F15: =+'Bank Assets Analysis'!I15-'Bank Assets Analysis'!J15 -> 0 | G15: =+'Bank Assets Analysis'!K15-'Bank Assets Analysis'!L15 -> 0 | H15: =+'Bank Assets Analysis'!M15-'Bank Assets Analysis'!N15 -> 0 | I15: =+'Bank Assets Analysis'!O15-'Bank Assets Analysis'!P15 -> 0 | J15: =+'Bank Assets Analysis'!Q15-'Bank Assets Analysis'!R15 -> 0 | K15: =+C15+D15+E15+F15+G15+H15+I15+J15 -> 15628608 | L15: 1 | M15: =+C15+D15+E15 -> 15628608 | N15: =+M15*L15 -> 15628608
A16: 3.6 | B16: Бошқа моддалар | C16: =+'Bank Assets Analysis'!C16-'Bank Assets Analysis'!D16 -> 0 | D16: =+'Bank Assets Analysis'!E16-'Bank Assets Analysis'!F16 -> 0 | E16: =+'Bank Assets Analysis'!G16-'Bank Assets Analysis'!H16 -> 0 | F16: =+'Bank Assets Analysis'!I16-'Bank Assets Analysis'!J16 -> 0 | G16: =+'Bank Assets Analysis'!K16-'Bank Assets Analysis'!L16 -> 0 | H16: =+'Bank Assets Analysis'!M16-'Bank Assets Analysis'!N16 -> 0 | I16: =+'Bank Assets Analysis'!O16-'Bank Assets Analysis'!P16 -> 0 | J16: =+'Bank Assets Analysis'!Q16-'Bank Assets Analysis'!R16 -> 0 | K16: =+C16+D16+E16+F16+G16+H16+I16+J16 -> 0 | L16: 1 | M16: =+C16+D16+E16 -> 0 | N16: =+M16*L16 -> 0
A17: 4 | B17: Қимматли қоғозлар ва уларга қилинган инвестициялар, соф | C17: =+'Bank Assets Analysis'!C17-'Bank Assets Analysis'!D17 -> 175 | D17: =+'Bank Assets Analysis'!E17-'Bank Assets Analysis'!F17 -> 0 | E17: =+'Bank Assets Analysis'!G17-'Bank Assets Analysis'!H17 -> 103422526 | F17: =+'Bank Assets Analysis'!I17-'Bank Assets Analysis'!J17 -> 52056510 | G17: =+'Bank Assets Analysis'!K17-'Bank Assets Analysis'!L17 -> 0 | H17: =+'Bank Assets Analysis'!M17-'Bank Assets Analysis'!N17 -> 45879410 | I17: =+'Bank Assets Analysis'!O17-'Bank Assets Analysis'!P17 -> 10000000 | J17: =+'Bank Assets Analysis'!Q17-'Bank Assets Analysis'!R17 -> 0 | K17: =+C17+D17+E17+F17+G17+H17+I17+J17 -> 211358621 | N17: =+M17*L17 -> 0
A18: 4a | B18: шу жумладан, таъминот остидаги юқори ликвидли қимматли қоғозлар | C18: =+'Bank Assets Analysis'!C18-'Bank Assets Analysis'!D18 -> 0 | D18: =+'Bank Assets Analysis'!E18-'Bank Assets Analysis'!F18 -> 0 | E18: =+'Bank Assets Analysis'!G18-'Bank Assets Analysis'!H18 -> 0 | F18: =+'Bank Assets Analysis'!I18-'Bank Assets Analysis'!J18 -> 0 | G18: =+'Bank Assets Analysis'!K18-'Bank Assets Analysis'!L18 -> 0 | H18: =+'Bank Assets Analysis'!M18-'Bank Assets Analysis'!N18 -> 0 | I18: =+'Bank Assets Analysis'!O18-'Bank Assets Analysis'!P18 -> 0 | J18: =+'Bank Assets Analysis'!Q18-'Bank Assets Analysis'!R18 -> 0 | K18: =+C18+D18+E18+F18+G18+H18+I18+J18 -> 0 | L18: 1 | M18: =SUM(C18:E18) -> 0 | N18: =+M18*L18 -> 0
A19: 4.1 | B19: Ўзбекистон Республикаси Ҳукумати ва Марказий банк томонидан чиқарилган қимматли қоғозлар (векселлар, облигациялар ва бошқа қарз қимматли қоғозлар) | C19: =+'Bank Assets Analysis'!C19-'Bank Assets Analysis'!D19 -> 0 | D19: =+'Bank Assets Analysis'!E19-'Bank Assets Analysis'!F19 -> 0 | E19: =+'Bank Assets Analysis'!G19-'Bank Assets Analysis'!H19 -> 103422526 | F19: =+'Bank Assets Analysis'!I19-'Bank Assets Analysis'!J19 -> 52056510 | G19: =+'Bank Assets Analysis'!K19-'Bank Assets Analysis'!L19 -> 0 | H19: =+'Bank Assets Analysis'!M19-'Bank Assets Analysis'!N19 -> 45879410 | I19: =+'Bank Assets Analysis'!O19-'Bank Assets Analysis'!P19 -> 0 | J19: =+'Bank Assets Analysis'!Q19-'Bank Assets Analysis'!R19 -> 0 | K19: =+C19+D19+E19+F19+G19+H19+I19+J19 -> 201358446 | L19: 1 | M19: =+K19 -> 201358446 | N19: =+M19*L19 -> 201358446
A20: 4.2 | B20: Таваккалчилик даражаси паст бўлган мамлакатларнинг қимматли қоғозлари | C20: =+'Bank Assets Analysis'!C20-'Bank Assets Analysis'!D20 -> 0 | D20: =+'Bank Assets Analysis'!E20-'Bank Assets Analysis'!F20 -> 0 | E20: =+'Bank Assets Analysis'!G20-'Bank Assets Analysis'!H20 -> 0 | F20: =+'Bank Assets Analysis'!I20-'Bank Assets Analysis'!J20 -> 0 | G20: =+'Bank Assets Analysis'!K20-'Bank Assets Analysis'!L20 -> 0 | H20: =+'Bank Assets Analysis'!M20-'Bank Assets Analysis'!N20 -> 0 | I20: =+'Bank Assets Analysis'!O20-'Bank Assets Analysis'!P20 -> 0 | J20: =+'Bank Assets Analysis'!Q20-'Bank Assets Analysis'!R20 -> 0 | K20: =+C20+D20+E20+F20+G20+H20+I20+J20 -> 0 | L20: 1 | M20: =+K20 -> 0 | N20: =+M20*L20 -> 0
A21: 4.3 | B21: ХВФ, Жаҳон банки гуруҳи, Осиё тараққиёт банки, Осиё инфраструктура инвестиция банки, ЕТТБ, Европа инвестиция банки, Европа инвестиция жамғармаси, Ислом тараққиёт банки ва Европа Кенгашининг тараққиёт банки томонидан чиқарилган қимматли қоғозлар | C21: =+'Bank Assets Analysis'!C21-'Bank Assets Analysis'!D21 -> 0 | D21: =+'Bank Assets Analysis'!E21-'Bank Assets Analysis'!F21 -> 0 | E21: =+'Bank Assets Analysis'!G21-'Bank Assets Analysis'!H21 -> 0 | F21: =+'Bank Assets Analysis'!I21-'Bank Assets Analysis'!J21 -> 0 | G21: =+'Bank Assets Analysis'!K21-'Bank Assets Analysis'!L21 -> 0 | H21: =+'Bank Assets Analysis'!M21-'Bank Assets Analysis'!N21 -> 0 | I21: =+'Bank Assets Analysis'!O21-'Bank Assets Analysis'!P21 -> 0 | J21: =+'Bank Assets Analysis'!Q21-'Bank Assets Analysis'!R21 -> 0 | K21: =+C21+D21+E21+F21+G21+H21+I21+J21 -> 0 | L21: 1 | M21: =+K21 -> 0 | N21: =+M21*L21 -> 0
A22: 4.4 | B22: Таваккалчилик даражаси паст бўлган мамлакатларнинг етакчи компаниялари қимматли қоғозлари | C22: =+'Bank Assets Analysis'!C22-'Bank Assets Analysis'!D22 -> 0 | D22: =+'Bank Assets Analysis'!E22-'Bank Assets Analysis'!F22 -> 0 | E22: =+'Bank Assets Analysis'!G22-'Bank Assets Analysis'!H22 -> 0 | F22: =+'Bank Assets Analysis'!I22-'Bank Assets Analysis'!J22 -> 0 | G22: =+'Bank Assets Analysis'!K22-'Bank Assets Analysis'!L22 -> 0 | H22: =+'Bank Assets Analysis'!M22-'Bank Assets Analysis'!N22 -> 0 | I22: =+'Bank Assets Analysis'!O22-'Bank Assets Analysis'!P22 -> 0 | J22: =+'Bank Assets Analysis'!Q22-'Bank Assets Analysis'!R22 -> 0 | K22: =+C22+D22+E22+F22+G22+H22+I22+J22 -> 0 | L22: 1 | M22: =+D22+E22 -> 0 | N22: =+M22*L22 -> 0
A23: 4.5 | B23: Ипотекани қайта молиялаштириш ташкилотлари томонидан чиқарилган корпоратив облигациялар | C23: =+'Bank Assets Analysis'!C23-'Bank Assets Analysis'!D23 -> 0 | D23: =+'Bank Assets Analysis'!E23-'Bank Assets Analysis'!F23 -> 0 | E23: =+'Bank Assets Analysis'!G23-'Bank Assets Analysis'!H23 -> 0 | F23: =+'Bank Assets Analysis'!I23-'Bank Assets Analysis'!J23 -> 0 | G23: =+'Bank Assets Analysis'!K23-'Bank Assets Analysis'!L23 -> 0 | H23: =+'Bank Assets Analysis'!M23-'Bank Assets Analysis'!N23 -> 0 | I23: =+'Bank Assets Analysis'!O23-'Bank Assets Analysis'!P23 -> 10000000 | J23: =+'Bank Assets Analysis'!Q23-'Bank Assets Analysis'!R23 -> 0 | K23: =+C23+D23+E23+F23+G23+H23+I23+J23 -> 10000000 | L23: 0.8 | M23: =+C23+D23+E23 -> 0 | N23: =+M23*L23 -> 0
A24: 4.6 | B24: Ипотекани қайта молиялаштириш ташкилотлари томонидан чиқарилган таъминланган қарз муносабатларини тасдиқловчи бошқа қимматли қоғозлар | C24: =+'Bank Assets Analysis'!C24-'Bank Assets Analysis'!D24 -> 0 | D24: =+'Bank Assets Analysis'!E24-'Bank Assets Analysis'!F24 -> 0 | E24: =+'Bank Assets Analysis'!G24-'Bank Assets Analysis'!H24 -> 0 | F24: =+'Bank Assets Analysis'!I24-'Bank Assets Analysis'!J24 -> 0 | G24: =+'Bank Assets Analysis'!K24-'Bank Assets Analysis'!L24 -> 0 | H24: =+'Bank Assets Analysis'!M24-'Bank Assets Analysis'!N24 -> 0 | I24: =+'Bank Assets Analysis'!O24-'Bank Assets Analysis'!P24 -> 0 | J24: =+'Bank Assets Analysis'!Q24-'Bank Assets Analysis'!R24 -> 0 | K24: =+C24+D24+E24+F24+G24+H24+I24+J24 -> 0 | L24: 1 | M24: =+D24+E24 -> 0 | N24: =+M24*L24 -> 0
A25: 4.7 | B25: Бошқалар | C25: =+'Bank Assets Analysis'!C25-'Bank Assets Analysis'!D25 -> 175 | D25: =+'Bank Assets Analysis'!E25-'Bank Assets Analysis'!F25 -> 0 | E25: =+'Bank Assets Analysis'!G25-'Bank Assets Analysis'!H25 -> 0 | F25: =+'Bank Assets Analysis'!I25-'Bank Assets Analysis'!J25 -> 0 | G25: =+'Bank Assets Analysis'!K25-'Bank Assets Analysis'!L25 -> 0 | H25: =+'Bank Assets Analysis'!M25-'Bank Assets Analysis'!N25 -> 0 | I25: =+'Bank Assets Analysis'!O25-'Bank Assets Analysis'!P25 -> 0 | J25: =+'Bank Assets Analysis'!Q25-'Bank Assets Analysis'!R25 -> 0 | K25: =+C25+D25+E25+F25+G25+H25+I25+J25 -> 175 | L25: 1 | M25: =+C25+D25+E25 -> 175 | N25: =+M25*L25 -> 175
A26: 5 | B26: Мижозларнинг аккредитив ва траст ҳужжатлари билан кафолатланган тратталари бўйича мажбуриятлари, соф | C26: =+'Bank Assets Analysis'!C26-'Bank Assets Analysis'!D26 -> 1400024 | D26: =+'Bank Assets Analysis'!E26-'Bank Assets Analysis'!F26 -> 0 | E26: =+'Bank Assets Analysis'!G26-'Bank Assets Analysis'!H26 -> 0 | F26: =+'Bank Assets Analysis'!I26-'Bank Assets Analysis'!J26 -> 0 | G26: =+'Bank Assets Analysis'!K26-'Bank Assets Analysis'!L26 -> 0 | H26: =+'Bank Assets Analysis'!M26-'Bank Assets Analysis'!N26 -> 0 | I26: =+'Bank Assets Analysis'!O26-'Bank Assets Analysis'!P26 -> 0 | J26: =+'Bank Assets Analysis'!Q26-'Bank Assets Analysis'!R26 -> 0 | K26: =+C26+D26+E26+F26+G26+H26+I26+J26 -> 1400024 | L26: 0.5 | M26: =+D26+E26 -> 0 | N26: =+M26*L26 -> 0
A27: 6 | B27: Мижозларнинг банк олдидаги тўланмаган акцептлари бўйича мажбуриятлари, соф | C27: =+'Bank Assets Analysis'!C27-'Bank Assets Analysis'!D27 -> 0 | D27: =+'Bank Assets Analysis'!E27-'Bank Assets Analysis'!F27 -> 0 | E27: =+'Bank Assets Analysis'!G27-'Bank Assets Analysis'!H27 -> 0 | F27: =+'Bank Assets Analysis'!I27-'Bank Assets Analysis'!J27 -> 0 | G27: =+'Bank Assets Analysis'!K27-'Bank Assets Analysis'!L27 -> 0 | H27: =+'Bank Assets Analysis'!M27-'Bank Assets Analysis'!N27 -> 0 | I27: =+'Bank Assets Analysis'!O27-'Bank Assets Analysis'!P27 -> 0 | J27: =+'Bank Assets Analysis'!Q27-'Bank Assets Analysis'!R27 -> 0 | K27: =+C27+D27+E27+F27+G27+H27+I27+J27 -> 0 | L27: 0.5 | M27: =+D27+E27 -> 0 | N27: =+M27*L27 -> 0
A28: 7 | B28: Марказий банкка берилган кредит ва лизинглар, соф | C28: =+'Bank Assets Analysis'!C28-'Bank Assets Analysis'!D28 -> 0 | D28: =+'Bank Assets Analysis'!E28-'Bank Assets Analysis'!F28 -> 0 | E28: =+'Bank Assets Analysis'!G28-'Bank Assets Analysis'!H28 -> 0 | F28: =+'Bank Assets Analysis'!I28-'Bank Assets Analysis'!J28 -> 0 | G28: =+'Bank Assets Analysis'!K28-'Bank Assets Analysis'!L28 -> 0 | H28: =+'Bank Assets Analysis'!M28-'Bank Assets Analysis'!N28 -> 0 | I28: =+'Bank Assets Analysis'!O28-'Bank Assets Analysis'!P28 -> 0 | J28: =+'Bank Assets Analysis'!Q28-'Bank Assets Analysis'!R28 -> 0 | K28: =+C28+D28+E28+F28+G28+H28+I28+J28 -> 0 | L28: 1 | M28: =C28+D28+E28 -> 0 | N28: =+M28*L28 -> 0
A29: 8 | B29: Бошқа банкларга берилган кредит ва лизинглар, соф | C29: =+'Bank Assets Analysis'!C29-'Bank Assets Analysis'!D29 -> 0 | D29: =+'Bank Assets Analysis'!E29-'Bank Assets Analysis'!F29 -> 0 | E29: =+'Bank Assets Analysis'!G29-'Bank Assets Analysis'!H29 -> 0 | F29: =+'Bank Assets Analysis'!I29-'Bank Assets Analysis'!J29 -> 0 | G29: =+'Bank Assets Analysis'!K29-'Bank Assets Analysis'!L29 -> 0 | H29: =+'Bank Assets Analysis'!M29-'Bank Assets Analysis'!N29 -> 0 | I29: =+'Bank Assets Analysis'!O29-'Bank Assets Analysis'!P29 -> 0 | J29: =+'Bank Assets Analysis'!Q29-'Bank Assets Analysis'!R29 -> 0 | K29: =+C29+D29+E29+F29+G29+H29+I29+J29 -> 0 | L29: 0.5 | M29: =+D29+E29 -> 0 | N29: =+M29*L29 -> 0
A30: 9 | B30: Мижозларга берилган кредит ва лизинглар, соф | C30: =+'Bank Assets Analysis'!C30-'Bank Assets Analysis'!D30 -> 415937868 | D30: =+'Bank Assets Analysis'!E30-'Bank Assets Analysis'!F30 -> 233443615 | E30: =+'Bank Assets Analysis'!G30-'Bank Assets Analysis'!H30 -> 19749026 | F30: =+'Bank Assets Analysis'!I30-'Bank Assets Analysis'!J30 -> 582905530 | G30: =+'Bank Assets Analysis'!K30-'Bank Assets Analysis'!L30 -> 979554386 | H30: =+'Bank Assets Analysis'!M30-'Bank Assets Analysis'!N30 -> 1814860638 | I30: =+'Bank Assets Analysis'!O30-'Bank Assets Analysis'!P30 -> 2661690078 | J30: =+'Bank Assets Analysis'!Q30-'Bank Assets Analysis'!R30 -> 6493415561 | K30: =+C30+D30+E30+F30+G30+H30+I30+J30 -> 13201556702 | L30: 0.5 | M30: =+D30+E30 -> 253192641 | N30: =+M30*L30 -> 1.2659632e+08
A31: 9.1 | B31: шу жумладан, жисмоний шахсларга берилган кредит ва лизинглар | C31: =+'Bank Assets Analysis'!C31-'Bank Assets Analysis'!D31 -> 217619303 | D31: =+'Bank Assets Analysis'!E31-'Bank Assets Analysis'!F31 -> 152010825 | E31: =+'Bank Assets Analysis'!G31-'Bank Assets Analysis'!H31 -> 6004586 | F31: =+'Bank Assets Analysis'!I31-'Bank Assets Analysis'!J31 -> 338488547 | G31: =+'Bank Assets Analysis'!K31-'Bank Assets Analysis'!L31 -> 512116570 | H31: =+'Bank Assets Analysis'!M31-'Bank Assets Analysis'!N31 -> 972815556 | I31: =+'Bank Assets Analysis'!O31-'Bank Assets Analysis'!P31 -> 1391014546 | J31: =+'Bank Assets Analysis'!Q31-'Bank Assets Analysis'!R31 -> 3359108523 | K31: =+C31+D31+E31+F31+G31+H31+I31+J31 -> 6949178456 | L31: 0 | M31: =+D31+E31 -> 158015411 | N31: =+M31*L31 -> 0
A32: 10 | B32: Суд ёки ижро иши юритиш жараёнидаги кредитлар ва лизинг, соф | C32: =+'Bank Assets Analysis'!C32-'Bank Assets Analysis'!D32 -> 20439365 | D32: =+'Bank Assets Analysis'!E32-'Bank Assets Analysis'!F32 -> 0 | E32: =+'Bank Assets Analysis'!G32-'Bank Assets Analysis'!H32 -> 0 | F32: =+'Bank Assets Analysis'!I32-'Bank Assets Analysis'!J32 -> 0 | G32: =+'Bank Assets Analysis'!K32-'Bank Assets Analysis'!L32 -> 0 | H32: =+'Bank Assets Analysis'!M32-'Bank Assets Analysis'!N32 -> 0 | I32: =+'Bank Assets Analysis'!O32-'Bank Assets Analysis'!P32 -> 0 | J32: =+'Bank Assets Analysis'!Q32-'Bank Assets Analysis'!R32 -> 0 | K32: =+C32+D32+E32+F32+G32+H32+I32+J32 -> 20439365 | L32: 0 | M32: =+D32+E32 -> 0 | N32: =+M32*L32 -> 0
A33: 11 | B33: Инвестициялар, соф | C33: =+'Bank Assets Analysis'!C33-'Bank Assets Analysis'!D33 -> 171402110 | D33: =+'Bank Assets Analysis'!E33-'Bank Assets Analysis'!F33 -> 0 | E33: =+'Bank Assets Analysis'!G33-'Bank Assets Analysis'!H33 -> 0 | F33: =+'Bank Assets Analysis'!I33-'Bank Assets Analysis'!J33 -> 0 | G33: =+'Bank Assets Analysis'!K33-'Bank Assets Analysis'!L33 -> 0 | H33: =+'Bank Assets Analysis'!M33-'Bank Assets Analysis'!N33 -> 0 | I33: =+'Bank Assets Analysis'!O33-'Bank Assets Analysis'!P33 -> 0 | J33: =+'Bank Assets Analysis'!Q33-'Bank Assets Analysis'!R33 -> 0 | K33: =+C33+D33+E33+F33+G33+H33+I33+J33 -> 171402110 | L33: 0 | M33: =+D33+E33 -> 0 | N33: =+M33*L33 -> 0
A34: 12 | B34: РЕПО битимлари бўйича сотиб олинган қимматли қоғозлар | C34: =+C35+C36 -> 0 | D34: =+D35+D36 -> 0 | E34: =+E35+E36 -> 0 | F34: =+F35+F36 -> 0 | G34: =+G35+G36 -> 0 | H34: =+H35+H36 -> 0 | I34: =+I35+I36 -> 0 | J34: =+J35+J36 -> 0 | K34: =+C34+D34+E34+F34+G34+H34+I34+J34 -> 0 | L34: 0 | M34: =+D34+E34 -> 0 | N34: =+M34*L34 -> 0
A35: 12.1 | B35: РЕПО битимлари бўйича сотиб олинган юқори ликвидли қимматли қоғозлар | C35: =+'Bank Assets Analysis'!C35-'Bank Assets Analysis'!D35 -> 0 | D35: =+'Bank Assets Analysis'!E35-'Bank Assets Analysis'!F35 -> 0 | E35: =+'Bank Assets Analysis'!G35-'Bank Assets Analysis'!H35 -> 0 | F35: =+'Bank Assets Analysis'!I35-'Bank Assets Analysis'!J35 -> 0 | G35: =+'Bank Assets Analysis'!K35-'Bank Assets Analysis'!L35 -> 0 | H35: =+'Bank Assets Analysis'!M35-'Bank Assets Analysis'!N35 -> 0 | I35: =+'Bank Assets Analysis'!O35-'Bank Assets Analysis'!P35 -> 0 | J35: =+'Bank Assets Analysis'!Q35-'Bank Assets Analysis'!R35 -> 0 | K35: =+C35+D35+E35+F35+G35+H35+I35+J35 -> 0 | L35: 1 | M35: =+K35 -> 0 | N35: =+M35*L35 -> 0
