Workbook

Sheet Ko‘rsatma
A1: FOND BOZORI RISKLARINI BOSHQARISH — amaliy hisob-kitoblar ish kitobi
A3: Ma’lumotlar haqida
A4: “Narxlar” va “Hajmlar” varaqlaridagi kunlik ma’lumotlar O‘QUV MAQSADIDA MODELLASHTIRILGAN (sintetik). Ular real kompaniyalarga tegishli emas.
A5: Ma’lumotlar GARCH(1,1) jarayoni va bir omilli (bozor) model asosida yaratilgan; 2025-yil fevral–mart oylarida sun’iy stress davri bor.
A6: Real ma’lumot bilan ishlash uchun: “Narxlar” varag‘idagi B:F ustunlarga Toshkent RFB (uzse.uz) yoki boshqa manbadan olingan yopilish narxlarini qo‘ying — barcha formulalar avtomatik qayta hisoblanadi.
A8: Rang belgilari
A9: Ko‘k matn — qo‘lda kiritiladigan boshlang‘ich qiymat (o‘zgartirish mumkin).
A10: Sariq fon — asosiy faraz/parametr: talaba ssenariy tahlilida aynan shu kataklarni o‘zgartiradi.
A11: Yashil matn — boshqa varaqdan olingan havola.
A12: Qora matn — formula (o‘zgartirmang). Havorang fon — asosiy natija.
A14: Varaqlar va amaliy mashg‘ulotlar bog‘liqligi
A15: Parametrlar — umumiy faraz va parametrlar (risksiz stavka, portfel qiymati, ishonch darajasi, vaznlar).
... A28: Eslatma: “VaR” varag‘idagi Monte-Karlo ustuni RAND() funksiyasidan foydalanadi, shuning uchun har qayta hisoblashda biroz o‘zgaradi (F9 tugmasi).

Sheet Parametrlar
A1: Umumiy parametrlar
A2: Ko‘k/sariq kataklar — kiritiladigan qiymatlar. Qiymatlar o‘quv maqsadida faraz qilingan.
A3: Parametr | B3: Qiymat | C3: Izoh
A4: Risksiz stavka (yillik) | B4: 0.14 | C4: Faraz: davlat qisqa muddatli obligatsiyalari daromadliligi darajasida
A5: Bozorning kutilayotgan daromadliligi (yillik) | B5: 0.22 | C5: Faraz: CAPM uchun
A6: Yildagi savdo kunlari | B6: 252 | C6: Yillik ko‘rsatkichga o‘tkazish uchun
A7: Portfel qiymati, so‘m | B7: 10000000000 | C7: Faraz: 10 mlrd so‘m
A8: VaR ishonch darajasi (α) | B8: 0.99 | C8: 0,95 yoki 0,99
A9: VaR gorizonti, kun | B9: 10 | C9: √T qoidasi bilan masshtablanadi
A10: EWMA λ koeffitsienti | B10: 0.94 | C10: RiskMetrics: kunlik ma’lumot uchun 0,94
A11: Sirpanuvchi oyna, kun | B11: 20 | C11: Volatillik varag‘ida 20 kun uchun qurilgan
A13: Portfel vaznlari | B13: A_Sanoat | C13: B_Bank | D13: C_Telekom | E13: D_Energetika | F13: Jami
A14: Vazn (w) | B14: 0.3 | C14: 0.25 | D14: 0.25 | E14: 0.2 | F14: =SUM(B14:E14) -> 1
A15: Tekshiruv | B15: =IF(ABS(F14-1)<0.0001,"Vaznlar yig‘indisi 100%","XATO: vaznlar yig‘indisi 100% emas") -> Vaznlar yig‘indisi 100%

Sheet Narxlar
A1: Sana | B1: Indeks | C1: A_Sanoat | D1: B_Bank | E1: C_Telekom | F1: D_Energetika | H1: Narxlar — so‘m (indeks — punkt). O‘quv maqsadida modellashtirilgan ma’lumot.
A2: 45293 | B2: 1000 | C2: 12500 | D2: 18400 | E2: 7300 | F2: 25600
A3: 45294 | B3: 1005.74 | C3: 12525 | D3: 18569 | E3: 7609 | F3: 24892
A4: 45295 | B4: 992.3 | C4: 12561 | D4: 18382 | E4: 7494 | F4: 24601
A5: 45296 | B5: 998.81 | C5: 12672 | D5: 18501 | E5: 7528 | F5: 24607
A6: 45299 | B6: 1004.23 | C6: 12927 | D6: 18731 | E6: 7504 | F6: 24752
A7: 45300 | B7: 998.95 | C7: 12666 | D7: 18583 | E7: 7418 | F7: 24472
A8: 45301 | B8: 1010.31 | C8: 12914 | D8: 18714 | E8: 7386 | F8: 25369
A9: 45302 | B9: 997.1 | C9: 12703 | D9: 18477 | E9: 7326 | F9: 24994
A10: 45303 | B10: 982.92 | C10: 12432 | D10: 18332 | E10: 7177 | F10: 24119
A11: 45306 | B11: 978.34 | C11: 12341 | D11: 18310 | E11: 7171 | F11: 23977
A12: 45307 | B12: 976.53 | C12: 11807 | D12: 18493 | E12: 7217 | F12: 24313
A13: 45308 | B13: 973.87 | C13: 11859 | D13: 18377 | E13: 7253 | F13: 24447
... A506: 45999 | B506: 1217.03 | C506: 23452 | D506: 30761 | E506: 8227 | F506: 35456

Sheet Hajmlar
A1: Sana | B1: A_Sanoat | C1: B_Bank | D1: C_Telekom | E1: D_Energetika | G1: Kunlik savdo hajmi — dona aksiya. O‘quv maqsadida modellashtirilgan ma’lumot.
A2: 45293 | B2: 56300 | C2: 49300 | D2: 85600 | E2: 22700
A3: 45294 | B3: 84300 | C3: 20800 | D3: 167500 | E3: 50800
A4: 45295 | B4: 31100 | C4: 71500 | D4: 101600 | E4: 20700
A5: 45296 | B5: 89100 | C5: 42900 | D5: 76400 | E5: 13800
A6: 45299 | B6: 143100 | C6: 55900 | D6: 57500 | E6: 24800
A7: 45300 | B7: 77500 | C7: 31500 | D7: 85200 | E7: 26200
A8: 45301 | B8: 53600 | C8: 59600 | D8: 80400 | E8: 29900
A9: 45302 | B9: 175900 | C9: 96400 | D9: 146800 | E9: 27100
A10: 45303 | B10: 55900 | C10: 55100 | D10: 117600 | E10: 24000
A11: 45306 | B11: 42300 | C11: 68500 | D11: 152500 | E11: 11100
A12: 45307 | B12: 124400 | C12: 37900 | D12: 198000 | E12: 30500
A13: 45308 | B13: 78700 | C13: 38900 | D13: 121300 | E13: 21800
... A506: 45999 | B506: 138300 | C506: 40400 | D506: 183300 | E506: 18700

Sheet Daromadlilik
A1: Sana | B1: Indeks R | C1: A_Sanoat R | D1: B_Bank R | E1: C_Telekom R | F1: D_Energetika R | H1: Indeks r=ln | I1: A_Sanoat r | J1: B_Bank r | K1: C_Telekom r | L1: D_Energetika r | N1: Ko‘rsatkich (log daromadlilik) | O1: Indeks | P1: A_Sanoat | Q1: B_Bank | R1: C_Telekom | S1: D_Energetika
A2: =Narxlar!A3 -> 45294 | B2: =Narxlar!B3/Narxlar!B2-1 -> 0.00574 | C2: =Narxlar!C3/Narxlar!C2-1 -> 0.002 | D2: =Narxlar!D3/Narxlar!D2-1 -> 0.0091847826 | E2: =Narxlar!E3/Narxlar!E2-1 -> 0.042328767 | F2: =Narxlar!F3/Narxlar!F2-1 -> -0.02765625 | H2: =LN(Narxlar!B3/Narxlar!B2) -> 0.005723589 | I2: =LN(Narxlar!C3/Narxlar!C2) -> 0.0019980027 | J2: =LN(Narxlar!D3/Narxlar!D2) -> 0.009142859 | K2: =LN(Narxlar!E3/Narxlar!E2) -> 0.041457409 | L2: =LN(Narxlar!F3/Narxlar!F2) -> -0.028045885 | N2: Kuzatuvlar soni | O2: =COUNT(H2:H505) -> 504 | P2: =COUNT(I2:I505) -> 504 | Q2: =COUNT(J2:J505) -> 504 | R2: =COUNT(K2:K505) -> 504 | S2: =COUNT(L2:L505) -> 504
A3: =Narxlar!A4 -> 45295 | B3: =Narxlar!B4/Narxlar!B3-1 -> -0.013363295 | C3: =Narxlar!C4/Narxlar!C3-1 -> 0.0028742515 | D3: =Narxlar!D4/Narxlar!D3-1 -> -0.010070548 | E3: =Narxlar!E4/Narxlar!E3-1 -> -0.015113681 | F3: =Narxlar!F4/Narxlar!F3-1 -> -0.011690503 | H3: =LN(Narxlar!B4/Narxlar!B3) -> -0.013453387 | I3: =LN(Narxlar!C4/Narxlar!C3) -> 0.0028701287 | J3: =LN(Narxlar!D4/Narxlar!D3) -> -0.010121599 | K3: =LN(Narxlar!E4/Narxlar!E3) -> -0.015229057 | L3: =LN(Narxlar!F4/Narxlar!F3) -> -0.011759374 | N3: Kunlik o‘rtacha | O3: =AVERAGE(H2:H505) -> 0.00038970925 | P3: =AVERAGE(I2:I505) -> 0.0012484665 | Q3: =AVERAGE(J2:J505) -> 0.0010196369 | R3: =AVERAGE(K2:K505) -> 0.00023719659 | S3: =AVERAGE(L2:L505) -> 0.00064623044
A4: =Narxlar!A5 -> 45296 | B4: =Narxlar!B5/Narxlar!B4-1 -> 0.006560516 | C4: =Narxlar!C5/Narxlar!C4-1 -> 0.008836876 | D4: =Narxlar!D5/Narxlar!D4-1 -> 0.0064737243 | E4: =Narxlar!E5/Narxlar!E4-1 -> 0.0045369629 | F4: =Narxlar!F5/Narxlar!F4-1 -> 0.00024389252 | H4: =LN(Narxlar!B5/Narxlar!B4) -> 0.0065390894 | I4: =LN(Narxlar!C5/Narxlar!C4) -> 0.0087980594 | J4: =LN(Narxlar!D5/Narxlar!D4) -> 0.0064528597 | K4: =LN(Narxlar!E5/Narxlar!E4) -> 0.0045267019 | L4: =LN(Narxlar!F5/Narxlar!F4) -> 0.00024386279 | N4: Kunlik standart og‘ish (σ) | O4: =STDEV(H2:H505) -> 0.01197095 | P4: =STDEV(I2:I505) -> 0.017821622 | Q4: =STDEV(J2:J505) -> 0.014745122 | R4: =STDEV(K2:K505) -> 0.012135057 | S4: =STDEV(L2:L505) -> 0.02225816
A5: =Narxlar!A6 -> 45299 | B5: =Narxlar!B6/Narxlar!B5-1 -> 0.0054264575 | C5: =Narxlar!C6/Narxlar!C5-1 -> 0.020123106 | D5: =Narxlar!D6/Narxlar!D5-1 -> 0.01243176 | E5: =Narxlar!E6/Narxlar!E5-1 -> -0.0031880978 | F5: =Narxlar!F6/Narxlar!F5-1 -> 0.0058926322 | H5: =LN(Narxlar!B6/Narxlar!B5) -> 0.0054117873 | I5: =LN(Narxlar!C6/Narxlar!C5) -> 0.019923312 | J5: =LN(Narxlar!D6/Narxlar!D5) -> 0.012355121 | K5: =LN(Narxlar!E6/Narxlar!E5) -> -0.0031931906 | L5: =LN(Narxlar!F6/Narxlar!F5) -> 0.0058753385 | N5: Yillik o‘rtacha daromadlilik | O5: =AVERAGE(H2:H505)*Parametrlar!$B$6 -> 0.098206732 | P5: =AVERAGE(I2:I505)*Parametrlar!$B$6 -> 0.31461357 | Q5: =AVERAGE(J2:J505)*Parametrlar!$B$6 -> 0.25694849 | R5: =AVERAGE(K2:K505)*Parametrlar!$B$6 -> 0.05977354 | S5: =AVERAGE(L2:L505)*Parametrlar!$B$6 -> 0.16285007
A6: =Narxlar!A7 -> 45300 | B6: =Narxlar!B7/Narxlar!B6-1 -> -0.0052577597 | C6: =Narxlar!C7/Narxlar!C6-1 -> -0.020190299 | D6: =Narxlar!D7/Narxlar!D6-1 -> -0.00790134 | E6: =Narxlar!E7/Narxlar!E6-1 -> -0.011460554 | F6: =Narxlar!F7/Narxlar!F6-1 -> -0.011312217 | H6: =LN(Narxlar!B7/Narxlar!B6) -> -0.0052716303 | I6: =LN(Narxlar!C7/Narxlar!C6) -> -0.020396909 | J6: =LN(Narxlar!D7/Narxlar!D6) -> -0.007932721 | K6: =LN(Narxlar!E7/Narxlar!E6) -> -0.011526733 | L6: =LN(Narxlar!F7/Narxlar!F6) -> -0.011376687 | N6: Yillik volatillik (σ·√252) | O6: =STDEV(H2:H505)*SQRT(Parametrlar!$B$6) -> 0.19003295 | P6: =STDEV(I2:I505)*SQRT(Parametrlar!$B$6) -> 0.28290949 | Q6: =STDEV(J2:J505)*SQRT(Parametrlar!$B$6) -> 0.23407155 | R6: =STDEV(K2:K505)*SQRT(Parametrlar!$B$6) -> 0.19263806 | S6: =STDEV(L2:L505)*SQRT(Parametrlar!$B$6) -> 0.35333733
A7: =Narxlar!A8 -> 45301 | B7: =Narxlar!B8/Narxlar!B7-1 -> 0.011371941 | C7: =Narxlar!C8/Narxlar!C7-1 -> 0.019579978 | D7: =Narxlar!D8/Narxlar!D7-1 -> 0.0070494538 | E7: =Narxlar!E8/Narxlar!E7-1 -> -0.0043138312 | F7: =Narxlar!F8/Narxlar!F7-1 -> 0.036654135 | H7: =LN(Narxlar!B8/Narxlar!B7) -> 0.011307766 | I7: =LN(Narxlar!C8/Narxlar!C7) -> 0.019390756 | J7: =LN(Narxlar!D8/Narxlar!D7) -> 0.0070247226 | K7: =LN(Narxlar!E8/Narxlar!E7) -> -0.0043231626 | L7: =LN(Narxlar!F8/Narxlar!F7) -> 0.035998349 | N7: Variatsiya koeffitsienti (σ/μ) | O7: =IFERROR(STDEV(H2:H505)/AVERAGE(H2:H505),0) -> 30.717645 | P7: =IFERROR(STDEV(I2:I505)/AVERAGE(I2:I505),0) -> 14.27481 | Q7: =IFERROR(STDEV(J2:J505)/AVERAGE(J2:J505),0) -> 14.46115 | R7: =IFERROR(STDEV(K2:K505)/AVERAGE(K2:K505),0) -> 51.160337 | S7: =IFERROR(STDEV(L2:L505)/AVERAGE(L2:L505),0) -> 34.443069
A8: =Narxlar!A9 -> 45302 | B8: =Narxlar!B9/Narxlar!B8-1 -> -0.013075195 | C8: =Narxlar!C9/Narxlar!C8-1 -> -0.016338857 | D8: =Narxlar!D9/Narxlar!D8-1 -> -0.012664315 | E8: =Narxlar!E9/Narxlar!E8-1 -> -0.0081234768 | F8: =Narxlar!F9/Narxlar!F8-1 -> -0.01478182 | H8: =LN(Narxlar!B9/Narxlar!B8) -> -0.013161428 | I8: =LN(Narxlar!C9/Narxlar!C8) -> -0.016473808 | J8: =LN(Narxlar!D9/Narxlar!D8) -> -0.012745191 | K8: =LN(Narxlar!E9/Narxlar!E8) -> -0.0081566521 | L8: =LN(Narxlar!F9/Narxlar!F8) -> -0.01489216 | N8: Minimum (eng katta kunlik pasayish) | O8: =MIN(H2:H505) -> -0.040834424 | P8: =MIN(I2:I505) -> -0.051764515 | Q8: =MIN(J2:J505) -> -0.044207718 | R8: =MIN(K2:K505) -> -0.043068857 | S8: =MIN(L2:L505) -> -0.08696931
A9: =Narxlar!A10 -> 45303 | B9: =Narxlar!B10/Narxlar!B9-1 -> -0.014221242 | C9: =Narxlar!C10/Narxlar!C9-1 -> -0.021333543 | D9: =Narxlar!D10/Narxlar!D9-1 -> -0.0078475943 | E9: =Narxlar!E10/Narxlar!E9-1 -> -0.02033852 | F9: =Narxlar!F10/Narxlar!F9-1 -> -0.035008402 | H9: =LN(Narxlar!B10/Narxlar!B9) -> -0.014323333 | I9: =LN(Narxlar!C10/Narxlar!C9) -> -0.021564392 | J9: =LN(Narxlar!D10/Narxlar!D9) -> -0.0078785487 | K9: =LN(Narxlar!E10/Narxlar!E9) -> -0.020548196 | L9: =LN(Narxlar!F10/Narxlar!F9) -> -0.035635884 | N9: Maksimum | O9: =MAX(H2:H505) -> 0.061512562 | P9: =MAX(I2:I505) -> 0.074530871 | Q9: =MAX(J2:J505) -> 0.065935946 | R9: =MAX(K2:K505) -> 0.047278984 | S9: =MAX(L2:L505) -> 0.081117386
A10: =Narxlar!A11 -> 45306 | B10: =Narxlar!B11/Narxlar!B10-1 -> -0.0046595857 | C10: =Narxlar!C11/Narxlar!C10-1 -> -0.0073198198 | D10: =Narxlar!D11/Narxlar!D10-1 -> -0.0012000873 | E10: =Narxlar!E11/Narxlar!E10-1 -> -0.0008360039 | F10: =Narxlar!F11/Narxlar!F10-1 -> -0.0058874746 | H10: =LN(Narxlar!B11/Narxlar!B10) -> -0.0046704754 | I10: =LN(Narxlar!C11/Narxlar!C10) -> -0.0073467412 | J10: =LN(Narxlar!D11/Narxlar!D10) -> -0.001200808 | K10: =LN(Narxlar!E11/Narxlar!E10) -> -0.00083635355 | L10: =LN(Narxlar!F11/Narxlar!F10) -> -0.0059048741 | N10: Asimmetriya (skewness) | O10: =SKEW(H2:H505) -> 0.32956056 | P10: =SKEW(I2:I505) -> 0.22021415 | Q10: =SKEW(J2:J505) -> 0.18827231 | R10: =SKEW(K2:K505) -> 0.1850183 | S10: =SKEW(L2:L505) -> 0.20366668
A11: =Narxlar!A12 -> 45307 | B11: =Narxlar!B12/Narxlar!B11-1 -> -0.0018500726 | C11: =Narxlar!C12/Narxlar!C11-1 -> -0.043270399 | D11: =Narxlar!D12/Narxlar!D11-1 -> 0.0099945385 | E11: =Narxlar!E12/Narxlar!E11-1 -> 0.006414726 | F11: =Narxlar!F12/Narxlar!F11-1 -> 0.01401343 | H11: =LN(Narxlar!B12/Narxlar!B11) -> -0.0018517861 | I11: =LN(Narxlar!C12/Narxlar!C11) -> -0.044234477 | J11: =LN(Narxlar!D12/Narxlar!D11) -> 0.0099449234 | K11: =LN(Narxlar!E12/Narxlar!E11) -> 0.0063942392 | L11: =LN(Narxlar!F12/Narxlar!F11) -> 0.013916149 | N11: Ortiqcha ekstsess (kurtosis) | O11: =KURT(H2:H505) -> 2.9960798 | P11: =KURT(I2:I505) -> 1.3211769 | Q11: =KURT(J2:J505) -> 1.6172094 | R11: =KURT(K2:K505) -> 1.6350457 | S11: =KURT(L2:L505) -> 0.87637901
A12: =Narxlar!A13 -> 45308 | B12: =Narxlar!B13/Narxlar!B12-1 -> -0.0027239307 | C12: =Narxlar!C13/Narxlar!C12-1 -> 0.004404167 | D12: =Narxlar!D13/Narxlar!D12-1 -> -0.0062726437 | E12: =Narxlar!E13/Narxlar!E12-1 -> 0.0049882223 | F12: =Narxlar!F13/Narxlar!F12-1 -> 0.0055114548 | H12: =LN(Narxlar!B13/Narxlar!B12) -> -0.0027276473 | I12: =LN(Narxlar!C13/Narxlar!C12) -> 0.0043944971 | J12: =LN(Narxlar!D13/Narxlar!D12) -> -0.0062923994 | K12: =LN(Narxlar!E13/Narxlar!E12) -> 0.0049758223 | L12: =LN(Narxlar!F13/Narxlar!F12) -> 0.0054963223 | N12: Σ ln-daromadliliklar | O12: =SUM(H2:H505) -> 0.19641346 | P12: =SUM(I2:I505) -> 0.62922713 | Q12: =SUM(J2:J505) -> 0.51389699 | R12: =SUM(K2:K505) -> 0.11954708 | S12: =SUM(L2:L505) -> 0.32570014
A13: =Narxlar!A14 -> 45309 | B13: =Narxlar!B14/Narxlar!B13-1 -> 0.0033988109 | C13: =Narxlar!C14/Narxlar!C13-1 -> 0.012058352 | D13: =Narxlar!D14/Narxlar!D13-1 -> 0.0046797627 | E13: =Narxlar!E14/Narxlar!E13-1 -> 0.011443541 | F13: =Narxlar!F14/Narxlar!F13-1 -> 0.0031905755 | H13: =LN(Narxlar!B14/Narxlar!B13) -> 0.003393048 | I13: =LN(Narxlar!C14/Narxlar!C13) -> 0.01198623 | J13: =LN(Narxlar!D14/Narxlar!D13) -> 0.0046688467 | K13: =LN(Narxlar!E14/Narxlar!E13) -> 0.011378559 | L13: =LN(Narxlar!F14/Narxlar!F13) -> 0.0031854964 | N13: ln(P oxirgi / P birinchi) | O13: =LN(Narxlar!B506/Narxlar!B2) -> 0.19641346 | P13: =LN(Narxlar!C506/Narxlar!C2) -> 0.62922713 | Q13: =LN(Narxlar!D506/Narxlar!D2) -> 0.51389699 | R13: =LN(Narxlar!E506/Narxlar!E2) -> 0.11954708 | S13: =LN(Narxlar!F506/Narxlar!F2) -> 0.32570014
A14: =Narxlar!A15 -> 45310 | B14: =Narxlar!B15/Narxlar!B14-1 -> -0.002977957 | C14: =Narxlar!C15/Narxlar!C14-1 -> -0.0082486252 | D14: =Narxlar!D15/Narxlar!D14-1 -> 0.0076910578 | E14: =Narxlar!E15/Narxlar!E14-1 -> -0.0070883315 | F14: =Narxlar!F15/Narxlar!F14-1 -> 0.0081141692 | H14: =LN(Narxlar!B15/Narxlar!B14) -> -0.0029823999 | I14: =LN(Narxlar!C15/Narxlar!C14) -> -0.0082828334 | J14: =LN(Narxlar!D15/Narxlar!D14) -> 0.0076616324 | K14: =LN(Narxlar!E15/Narxlar!E14) -> -0.0071135731 | L14: =LN(Narxlar!F15/Narxlar!F14) -> 0.0080814263 | N14: Qo‘shiluvchanlik tekshiruvi | O14: =IF(ABS(O12-O13)<0.0000001,"Teng ✓","Teng emas") -> Teng ✓ | P14: =IF(ABS(P12-P13)<0.0000001,"Teng ✓","Teng emas") -> Teng ✓ | Q14: =IF(ABS(Q12-Q13)<0.0000001,"Teng ✓","Teng emas") -> Teng ✓ | R14: =IF(ABS(R12-R13)<0.0000001,"Teng ✓","Teng emas") -> Teng ✓ | S14: =IF(ABS(S12-S13)<0.0000001,"Teng ✓","Teng emas") -> Teng ✓
A15: =Narxlar!A16 -> 45313 | B15: =Narxlar!B16/Narxlar!B15-1 -> -0.0042698636 | C15: =Narxlar!C16/Narxlar!C15-1 -> 0.0041166093 | D15: =Narxlar!D16/Narxlar!D15-1 -> -0.016178447 | E15: =Narxlar!E16/Narxlar!E15-1 -> -0.0057660626 | F15: =Narxlar!F16/Narxlar!F15-1 -> -0.013792267 | H15: =LN(Narxlar!B16/Narxlar!B15) -> -0.0042790055 | I15: =LN(Narxlar!C16/Narxlar!C15) -> 0.0041081592 | J15: =LN(Narxlar!D16/Narxlar!D15) -> -0.016310747 | K15: =LN(Narxlar!E16/Narxlar!E15) -> -0.0057827505 | L15: =LN(Narxlar!F16/Narxlar!F15) -> -0.013888264 | N15: Davr uchun oddiy daromadlilik | O15: =Narxlar!B506/Narxlar!B2-1 -> 0.21703 | P15: =Narxlar!C506/Narxlar!C2-1 -> 0.87616 | Q15: =Narxlar!D506/Narxlar!D2-1 -> 0.67179348 | R15: =Narxlar!E506/Narxlar!E2-1 -> 0.1269863 | S15: =Narxlar!F506/Narxlar!F2-1 -> 0.385
A16: =Narxlar!A17 -> 45314 | B16: =Narxlar!B17/Narxlar!B16-1 -> -0.0042469411 | C16: =Narxlar!C17/Narxlar!C16-1 -> -0.0054384203 | D16: =Narxlar!D17/Narxlar!D16-1 -> 0.013057255 | E16: =Narxlar!E17/Narxlar!E16-1 -> -0.0056614195 | F16: =Narxlar!F17/Narxlar!F16-1 -> -0.014395275 | H16: =LN(Narxlar!B17/Narxlar!B16) -> -0.0042559849 | I16: =LN(Narxlar!C17/Narxlar!C16) -> -0.0054532624 | J16: =LN(Narxlar!D17/Narxlar!D16) -> 0.012972744 | K16: =LN(Narxlar!E17/Narxlar!E16) -> -0.0056775061 | L16: =LN(Narxlar!F17/Narxlar!F16) -> -0.014499893 | N16: Σ oddiy daromadliliklar (noto‘g‘ri usul) | O16: =SUM(B2:B505) -> 0.23255645 | P16: =SUM(C2:C505) -> 0.70971217 | Q16: =SUM(D2:D505) -> 0.56895065 | R16: =SUM(E2:E505) -> 0.15663555 | S16: =SUM(F2:F505) -> 0.45069301
A17: =Narxlar!A18 -> 45315 | B17: =Narxlar!B18/Narxlar!B17-1 -> 0.0070808186 | C17: =Narxlar!C18/Narxlar!C17-1 -> 0.0031967696 | D17: =Narxlar!D18/Narxlar!D17-1 -> 0.0070646605 | E17: =Narxlar!E18/Narxlar!E17-1 -> 0.018191918 | F17: =Narxlar!F18/Narxlar!F17-1 -> 0.0017476698 | H17: =LN(Narxlar!B18/Narxlar!B17) -> 0.0070558674 | I17: =LN(Narxlar!C18/Narxlar!C17) -> 0.0031916708 | J17: =LN(Narxlar!D18/Narxlar!D17) -> 0.0070398227 | K17: =LN(Narxlar!E18/Narxlar!E17) -> 0.018028425 | L17: =LN(Narxlar!F18/Narxlar!F17) -> 0.0017461444
A18: =Narxlar!A19 -> 45316 | B18: =Narxlar!B19/Narxlar!B18-1 -> 0.013167768 | C18: =Narxlar!C19/Narxlar!C18-1 -> 0.013081761 | D18: =Narxlar!D19/Narxlar!D18-1 -> 0.035289708 | E18: =Narxlar!E19/Narxlar!E18-1 -> 0.015139116 | F18: =Narxlar!F19/Narxlar!F18-1 -> 0.024964692 | H18: =LN(Narxlar!B19/Narxlar!B18) -> 0.013081827 | I18: =LN(Narxlar!C19/Narxlar!C18) -> 0.012996934 | J18: =LN(Narxlar!D19/Narxlar!D18) -> 0.034681298 | K18: =LN(Narxlar!E19/Narxlar!E18) -> 0.015025663 | L18: =LN(Narxlar!F19/Narxlar!F18) -> 0.024658165 | N18: Izoh: logarifmik daromadliliklar yig‘indisi butun davr daromadliligiga aniq teng (qo‘shiluvchanlik); oddiy daromadliliklar yig‘indisi esa teng emas.
A19: =Narxlar!A20 -> 45317 | B19: =Narxlar!B20/Narxlar!B19-1 -> 0.0026175886 | C19: =Narxlar!C20/Narxlar!C19-1 -> 0.0058769969 | D19: =Narxlar!D20/Narxlar!D19-1 -> 0.0098277557 | E19: =Narxlar!E20/Narxlar!E19-1 -> 0.0080612656 | F19: =Narxlar!F20/Narxlar!F19-1 -> 0.0065653495 | H19: =LN(Narxlar!B20/Narxlar!B19) -> 0.0026141687 | I19: =LN(Narxlar!C20/Narxlar!C19) -> 0.0058597948 | J19: =LN(Narxlar!D20/Narxlar!D19) -> 0.0097797774 | K19: =LN(Narxlar!E20/Narxlar!E19) -> 0.0080289472 | L19: =LN(Narxlar!F20/Narxlar!F19) -> 0.0065438915
A20: =Narxlar!A21 -> 45320 | B20: =Narxlar!B21/Narxlar!B20-1 -> 0.0004857218 | C20: =Narxlar!C21/Narxlar!C20-1 -> -0.0013166557 | D20: =Narxlar!D21/Narxlar!D20-1 -> -0.011729755 | E20: =Narxlar!E21/Narxlar!E20-1 -> 0.014527522 | F20: =Narxlar!F21/Narxlar!F20-1 -> -0.0060393767 | H20: =LN(Narxlar!B21/Narxlar!B20) -> 0.00048560388 | I20: =LN(Narxlar!C21/Narxlar!C20) -> -0.0013175232 | J20: =LN(Narxlar!D21/Narxlar!D20) -> -0.011799091 | K20: =LN(Narxlar!E21/Narxlar!E20) -> 0.014423009 | L20: =LN(Narxlar!F21/Narxlar!F20) -> -0.0060576875
A21: =Narxlar!A22 -> 45321 | B21: =Narxlar!B22/Narxlar!B21-1 -> 0.0069080611 | C21: =Narxlar!C22/Narxlar!C21-1 -> -0.0097231378 | D21: =Narxlar!D22/Narxlar!D21-1 -> -0.0088628589 | E21: =Narxlar!E22/Narxlar!E21-1 -> 0.015370468 | F21: =Narxlar!F22/Narxlar!F21-1 -> 0.02317009 | H21: =LN(Narxlar!B22/Narxlar!B21) -> 0.0068843098 | I21: =LN(Narxlar!C22/Narxlar!C21) -> -0.0097707161 | J21: =LN(Narxlar!D22/Narxlar!D21) -> -0.0089023677 | K21: =LN(Narxlar!E22/Narxlar!E21) -> 0.015253539 | L21: =LN(Narxlar!F22/Narxlar!F21) -> 0.022905739
A22: =Narxlar!A23 -> 45322 | B22: =Narxlar!B23/Narxlar!B22-1 -> 0.004650789 | C22: =Narxlar!C23/Narxlar!C22-1 -> 0.0064902646 | D22: =Narxlar!D23/Narxlar!D22-1 -> 0.011347592 | E22: =Narxlar!E23/Narxlar!E22-1 -> -0.0012938284 | F22: =Narxlar!F23/Narxlar!F22-1 -> 0.001583594 | H22: =LN(Narxlar!B23/Narxlar!B22) -> 0.0046400075 | I22: =LN(Narxlar!C23/Narxlar!C22) -> 0.0064692935 | J22: =LN(Narxlar!D23/Narxlar!D22) -> 0.011283691 | K22: =LN(Narxlar!E23/Narxlar!E22) -> -0.0012946662 | L22: =LN(Narxlar!F23/Narxlar!F22) -> 0.0015823414
A23: =Narxlar!A24 -> 45323 | B23: =Narxlar!B24/Narxlar!B23-1 -> -0.0057490801 | C23: =Narxlar!C24/Narxlar!C23-1 -> 0.0085978836 | D23: =Narxlar!D24/Narxlar!D23-1 -> -0.0013960703 | E23: =Narxlar!E24/Narxlar!E23-1 -> -0.0025910092 | F23: =Narxlar!F24/Narxlar!F23-1 -> 0.00031621803 | H23: =LN(Narxlar!B24/Narxlar!B23) -> -0.0057656697 | I23: =LN(Narxlar!C24/Narxlar!C23) -> 0.0085611323 | J23: =LN(Narxlar!D24/Narxlar!D23) -> -0.0013970457 | K23: =LN(Narxlar!E24/Narxlar!E23) -> -0.0025943717 | L23: =LN(Narxlar!F24/Narxlar!F23) -> 0.00031616805
A24: =Narxlar!A25 -> 45324 | B24: =Narxlar!B25/Narxlar!B24-1 -> -0.0016089943 | C24: =Narxlar!C25/Narxlar!C24-1 -> 0.0037704918 | D24: =Narxlar!D25/Narxlar!D24-1 -> 0.0058509812 | E24: =Narxlar!E25/Narxlar!E24-1 -> -0.012209378 | F24: =Narxlar!F25/Narxlar!F24-1 -> 0.0082585846 | H24: =LN(Narxlar!B25/Narxlar!B24) -> -0.0016102901 | I24: =LN(Narxlar!C25/Narxlar!C24) -> 0.0037634013 | J24: =LN(Narxlar!D25/Narxlar!D24) -> 0.0058339307 | K24: =LN(Narxlar!E25/Narxlar!E24) -> -0.012284525 | L24: =LN(Narxlar!F25/Narxlar!F24) -> 0.0082246691
A25: =Narxlar!A26 -> 45327 | B25: =Narxlar!B26/Narxlar!B25-1 -> 0.0051167897 | C25: =Narxlar!C26/Narxlar!C25-1 -> 0.00016331863 | D25: =Narxlar!D26/Narxlar!D25-1 -> -0.017244929 | E25: =Narxlar!E26/Narxlar!E25-1 -> 0.0095989481 | F25: =Narxlar!F26/Narxlar!F25-1 -> 0.0083085123 | H25: =LN(Narxlar!B26/Narxlar!B25) -> 0.0051037434 | I25: =LN(Narxlar!C26/Narxlar!C25) -> 0.0001633053 | J25: =LN(Narxlar!D26/Narxlar!D25) -> -0.017395355 | K25: =LN(Narxlar!E26/Narxlar!E25) -> 0.0095531709 | L25: =LN(Narxlar!F26/Narxlar!F25) -> 0.0082741866
A26: =Narxlar!A27 -> 45328 | B26: =Narxlar!B27/Narxlar!B26-1 -> -0.0054214392 | C26: =Narxlar!C27/Narxlar!C26-1 -> -0.012083605 | D26: =Narxlar!D27/Narxlar!D26-1 -> -0.0048190247 | E26: =Narxlar!E27/Narxlar!E26-1 -> -0.027741599 | F26: =Narxlar!F27/Narxlar!F26-1 -> -0.019356343 | H26: =LN(Narxlar!B27/Narxlar!B26) -> -0.0054361886 | I26: =LN(Narxlar!C27/Narxlar!C26) -> -0.012157206 | J26: =LN(Narxlar!D27/Narxlar!D26) -> -0.0048306736 | K26: =LN(Narxlar!E27/Narxlar!E26) -> -0.028133666 | L26: =LN(Narxlar!F27/Narxlar!F26) -> -0.01954613
A27: =Narxlar!A28 -> 45329 | B27: =Narxlar!B28/Narxlar!B27-1 -> 0.00089674351 | C27: =Narxlar!C28/Narxlar!C27-1 -> 0.007107438 | D27: =Narxlar!D28/Narxlar!D27-1 -> 0.0031054266 | E27: =Narxlar!E28/Narxlar!E27-1 -> -0.00093770931 | F27: =Narxlar!F28/Narxlar!F27-1 -> 0.0015061435 | H27: =LN(Narxlar!B28/Narxlar!B27) -> 0.00089634168 | I27: =LN(Narxlar!C28/Narxlar!C27) -> 0.0070822992 | J27: =LN(Narxlar!D28/Narxlar!D27) -> 0.0031006147 | K27: =LN(Narxlar!E28/Narxlar!E27) -> -0.00093814923 | L27: =LN(Narxlar!F28/Narxlar!F27) -> 0.0015050104
A28: =Narxlar!A29 -> 45330 | B28: =Narxlar!B29/Narxlar!B28-1 -> 0.0069863193 | C28: =Narxlar!C29/Narxlar!C28-1 -> 0.0077137699 | D28: =Narxlar!D29/Narxlar!D28-1 -> 0.0023612131 | E28: =Narxlar!E29/Narxlar!E28-1 -> 0 | F28: =Narxlar!F29/Narxlar!F28-1 -> 0.0036805446 | H28: =LN(Narxlar!B29/Narxlar!B28) -> 0.006962028 | I28: =LN(Narxlar!C29/Narxlar!C28) -> 0.0076841709 | J28: =LN(Narxlar!D29/Narxlar!D28) -> 0.0023584299 | K28: =LN(Narxlar!E29/Narxlar!E28) -> 0 | L28: =LN(Narxlar!F29/Narxlar!F28) -> 0.0036737879
A29: =Narxlar!A30 -> 45331 | B29: =Narxlar!B30/Narxlar!B29-1 -> 1.9993802e-05 | C29: =Narxlar!C30/Narxlar!C29-1 -> -0.0026058632 | D29: =Narxlar!D30/Narxlar!D29-1 -> 0.009370256 | E29: =Narxlar!E30/Narxlar!E29-1 -> -0.0096540628 | F29: =Narxlar!F30/Narxlar!F29-1 -> -0.0076495406 | H29: =LN(Narxlar!B30/Narxlar!B29) -> 1.9993602e-05 | I29: =LN(Narxlar!C30/Narxlar!C29) -> -0.0026092644 | J29: =LN(Narxlar!D30/Narxlar!D29) -> 0.0093266275 | K29: =LN(Narxlar!E30/Narxlar!E29) -> -0.0097009653 | L29: =LN(Narxlar!F30/Narxlar!F29) -> -0.0076789484
A30: =Narxlar!A31 -> 45334 | B30: =Narxlar!B31/Narxlar!B30-1 -> 0.0013795448 | C30: =Narxlar!C31/Narxlar!C30-1 -> -0.0017145656 | D30: =Narxlar!D31/Narxlar!D30-1 -> 0.00093351312 | E30: =Narxlar!E31/Narxlar!E30-1 -> 0.00027078256 | F30: =Narxlar!F31/Narxlar!F30-1 -> 0.0036953153 | H30: =LN(Narxlar!B31/Narxlar!B30) -> 0.0013785941 | I30: =LN(Narxlar!C31/Narxlar!C30) -> -0.0017160372 | J30: =LN(Narxlar!D31/Narxlar!D30) -> 0.00093307767 | K30: =LN(Narxlar!E31/Narxlar!E30) -> 0.00027074591 | L30: =LN(Narxlar!F31/Narxlar!F30) -> 0.0036885044
... A505: =Narxlar!A506 -> 45999 | B505: =Narxlar!B506/Narxlar!B505-1 -> -0.018389618 | C505: =Narxlar!C506/Narxlar!C505-1 -> -0.019032083 | D505: =Narxlar!D506/Narxlar!D505-1 -> -0.017942087 | E505: =Narxlar!E506/Narxlar!E505-1 -> -0.034729555 | F505: =Narxlar!F506/Narxlar!F505-1 -> -0.029134721 | H505: =LN(Narxlar!B506/Narxlar!B505) -> -0.018560809 | I505: =LN(Narxlar!C506/Narxlar!C505) -> -0.019215524 | J505: =LN(Narxlar!D506/Narxlar!D505) -> -0.018104998 | K505: =LN(Narxlar!E506/Narxlar!E505) -> -0.035346963 | L505: =LN(Narxlar!F506/Narxlar!F505) -> -0.029567565

Sheet Volatillik
A1: Volatillikni baholash: sirpanuvchi oyna va EWMA (Indeks)
A2: σ²(t) = λ·σ²(t−1) + (1−λ)·r²(t−1). Boshlang‘ich dispersiya — dastlabki 20 kunlik tanlanma dispersiyasi.
A4: λ (Parametrlar) | B4: =Parametrlar!$B$10 -> 0.94
A6: Sana | B6: r (ln) | C6: r² | D6: EWMA σ² (prognoz) | E6: EWMA σ kunlik | F6: EWMA σ yillik | G6: 20 kunlik σ yillik | I6: Xulosa | J6: Qiymat
A7: =Daromadlilik!A2 -> 45294 | B7: =Daromadlilik!H2 -> 0.005723589 | C7: =B7^2 -> 3.2759471e-05 | D7: =VAR(B7:B26) -> 6.2301555e-05 | E7: =SQRT(D7) -> 0.0078931334 | F7: =E7*SQRT(Parametrlar!$B$6) -> 0.12529961 | I7: Butun davr yillik volatilligi | J7: =STDEV(B7:B510)*SQRT(Parametrlar!$B$6) -> 0.19003295
A8: =Daromadlilik!A3 -> 45295 | B8: =Daromadlilik!H3 -> -0.013453387 | C8: =B8^2 -> 0.00018099362 | D8: =$B$4*D7+(1-$B$4)*C7 -> 6.052903e-05 | E8: =SQRT(D8) -> 0.0077800405 | F8: =E8*SQRT(Parametrlar!$B$6) -> 0.12350431 | I8: EWMA: oxirgi yillik prognoz | J8: =SQRT($B$4*D510+(1-$B$4)*C510)*SQRT(Parametrlar!$B$6) -> 0.16433054
A9: =Daromadlilik!A4 -> 45296 | B9: =Daromadlilik!H4 -> 0.0065390894 | C9: =B9^2 -> 4.2759691e-05 | D9: =$B$4*D8+(1-$B$4)*C8 -> 6.7756906e-05 | E9: =SQRT(D9) -> 0.0082314583 | F9: =E9*SQRT(Parametrlar!$B$6) -> 0.13067035 | I9: EWMA: davrdagi maksimum | J9: =MAX(F7:F510) -> 0.35765525
A10: =Daromadlilik!A5 -> 45299 | B10: =Daromadlilik!H5 -> 0.0054117873 | C10: =B10^2 -> 2.9287442e-05 | D10: =$B$4*D9+(1-$B$4)*C9 -> 6.6257073e-05 | E10: =SQRT(D10) -> 0.0081398448 | F10: =E10*SQRT(Parametrlar!$B$6) -> 0.12921603 | I10: EWMA: davrdagi minimum | J10: =MIN(F7:F510) -> 0.057177751
A11: =Daromadlilik!A6 -> 45300 | B11: =Daromadlilik!H6 -> -0.0052716303 | C11: =B11^2 -> 2.7790086e-05 | D11: =$B$4*D10+(1-$B$4)*C10 -> 6.4038895e-05 | E11: =SQRT(D11) -> 0.0080024306 | F11: =E11*SQRT(Parametrlar!$B$6) -> 0.12703465 | I11: 20 kunlik: maksimum | J11: =MAX(G26:G510) -> 0.38519459
A12: =Daromadlilik!A7 -> 45301 | B12: =Daromadlilik!H7 -> 0.011307766 | C12: =B12^2 -> 0.00012786557 | D12: =$B$4*D11+(1-$B$4)*C11 -> 6.1863966e-05 | E12: =SQRT(D12) -> 0.007865365 | F12: =E12*SQRT(Parametrlar!$B$6) -> 0.1248588 | I12: 20 kunlik: minimum | J12: =MIN(G26:G510) -> 0.048072829
A13: =Daromadlilik!A8 -> 45302 | B13: =Daromadlilik!H8 -> -0.013161428 | C13: =B13^2 -> 0.00017322318 | D13: =$B$4*D12+(1-$B$4)*C12 -> 6.5824063e-05 | E13: =SQRT(D13) -> 0.008113203 | F13: =E13*SQRT(Parametrlar!$B$6) -> 0.1287931
A14: =Daromadlilik!A9 -> 45303 | B14: =Daromadlilik!H9 -> -0.014323333 | C14: =B14^2 -> 0.00020515785 | D14: =$B$4*D13+(1-$B$4)*C13 -> 7.226801e-05 | E14: =SQRT(D14) -> 0.0085010593 | F14: =E14*SQRT(Parametrlar!$B$6) -> 0.13495013
A15: =Daromadlilik!A10 -> 45306 | B15: =Daromadlilik!H10 -> -0.0046704754 | C15: =B15^2 -> 2.1813341e-05 | D15: =$B$4*D14+(1-$B$4)*C14 -> 8.02414e-05 | E15: =SQRT(D15) -> 0.0089577564 | F15: =E15*SQRT(Parametrlar!$B$6) -> 0.14219997
A16: =Daromadlilik!A11 -> 45307 | B16: =Daromadlilik!H11 -> -0.0018517861 | C16: =B16^2 -> 3.4291116e-06 | D16: =$B$4*D15+(1-$B$4)*C15 -> 7.6735717e-05 | E16: =SQRT(D16) -> 0.0087598925 | F16: =E16*SQRT(Parametrlar!$B$6) -> 0.13905898
A17: =Daromadlilik!A12 -> 45308 | B17: =Daromadlilik!H12 -> -0.0027276473 | C17: =B17^2 -> 7.4400598e-06 | D17: =$B$4*D16+(1-$B$4)*C16 -> 7.233732e-05 | E17: =SQRT(D17) -> 0.0085051349 | F17: =E17*SQRT(Parametrlar!$B$6) -> 0.13501483
A18: =Daromadlilik!A13 -> 45309 | B18: =Daromadlilik!H13 -> 0.003393048 | C18: =B18^2 -> 1.1512775e-05 | D18: =$B$4*D17+(1-$B$4)*C17 -> 6.8443485e-05 | E18: =SQRT(D18) -> 0.0082730578 | F18: =E18*SQRT(Parametrlar!$B$6) -> 0.13133072
A19: =Daromadlilik!A14 -> 45310 | B19: =Daromadlilik!H14 -> -0.0029823999 | C19: =B19^2 -> 8.8947093e-06 | D19: =$B$4*D18+(1-$B$4)*C18 -> 6.5027642e-05 | E19: =SQRT(D19) -> 0.0080639719 | F19: =E19*SQRT(Parametrlar!$B$6) -> 0.12801158
A20: =Daromadlilik!A15 -> 45313 | B20: =Daromadlilik!H15 -> -0.0042790055 | C20: =B20^2 -> 1.8309888e-05 | D20: =$B$4*D19+(1-$B$4)*C19 -> 6.1659666e-05 | E20: =SQRT(D20) -> 0.0078523669 | F20: =E20*SQRT(Parametrlar!$B$6) -> 0.12465246
A21: =Daromadlilik!A16 -> 45314 | B21: =Daromadlilik!H16 -> -0.0042559849 | C21: =B21^2 -> 1.8113408e-05 | D21: =$B$4*D20+(1-$B$4)*C20 -> 5.905868e-05 | E21: =SQRT(D21) -> 0.0076849645 | F21: =E21*SQRT(Parametrlar!$B$6) -> 0.12199503
A22: =Daromadlilik!A17 -> 45315 | B22: =Daromadlilik!H17 -> 0.0070558674 | C22: =B22^2 -> 4.9785264e-05 | D22: =$B$4*D21+(1-$B$4)*C21 -> 5.6601963e-05 | E22: =SQRT(D22) -> 0.0075234276 | F22: =E22*SQRT(Parametrlar!$B$6) -> 0.11943071
A23: =Daromadlilik!A18 -> 45316 | B23: =Daromadlilik!H18 -> 0.013081827 | C23: =B23^2 -> 0.00017113419 | D23: =$B$4*D22+(1-$B$4)*C22 -> 5.6192961e-05 | E23: =SQRT(D23) -> 0.0074961965 | F23: =E23*SQRT(Parametrlar!$B$6) -> 0.11899843
A24: =Daromadlilik!A19 -> 45317 | B24: =Daromadlilik!H19 -> 0.0026141687 | C24: =B24^2 -> 6.8338777e-06 | D24: =$B$4*D23+(1-$B$4)*C23 -> 6.3089435e-05 | E24: =SQRT(D24) -> 0.0079428858 | F24: =E24*SQRT(Parametrlar!$B$6) -> 0.1260894
A25: =Daromadlilik!A20 -> 45320 | B25: =Daromadlilik!H20 -> 0.00048560388 | C25: =B25^2 -> 2.3581113e-07 | D25: =$B$4*D24+(1-$B$4)*C24 -> 5.9714102e-05 | E25: =SQRT(D25) -> 0.00772749 | F25: =E25*SQRT(Parametrlar!$B$6) -> 0.1226701
A26: =Daromadlilik!A21 -> 45321 | B26: =Daromadlilik!H21 -> 0.0068843098 | C26: =B26^2 -> 4.7393721e-05 | D26: =$B$4*D25+(1-$B$4)*C25 -> 5.6145404e-05 | E26: =SQRT(D26) -> 0.0074930237 | F26: =E26*SQRT(Parametrlar!$B$6) -> 0.11894806 | G26: =STDEV(B7:B26)*SQRT(Parametrlar!$B$6) -> 0.12529961
A27: =Daromadlilik!A22 -> 45322 | B27: =Daromadlilik!H22 -> 0.0046400075 | C27: =B27^2 -> 2.152967e-05 | D27: =$B$4*D26+(1-$B$4)*C26 -> 5.5620303e-05 | E27: =SQRT(D27) -> 0.0074579021 | F27: =E27*SQRT(Parametrlar!$B$6) -> 0.11839053 | G27: =STDEV(B8:B27)*SQRT(Parametrlar!$B$6) -> 0.12467491
A28: =Daromadlilik!A23 -> 45323 | B28: =Daromadlilik!H23 -> -0.0057656697 | C28: =B28^2 -> 3.3242947e-05 | D28: =$B$4*D27+(1-$B$4)*C27 -> 5.3574865e-05 | E28: =SQRT(D28) -> 0.0073194853 | F28: =E28*SQRT(Parametrlar!$B$6) -> 0.11619323 | G28: =STDEV(B9:B28)*SQRT(Parametrlar!$B$6) -> 0.11662644
A29: =Daromadlilik!A24 -> 45324 | B29: =Daromadlilik!H24 -> -0.0016102901 | C29: =B29^2 -> 2.5930342e-06 | D29: =$B$4*D28+(1-$B$4)*C28 -> 5.235495e-05 | E29: =SQRT(D29) -> 0.0072356721 | F29: =E29*SQRT(Parametrlar!$B$6) -> 0.11486273 | G29: =STDEV(B10:B29)*SQRT(Parametrlar!$B$6) -> 0.11422743
A30: =Daromadlilik!A25 -> 45327 | B30: =Daromadlilik!H25 -> 0.0051037434 | C30: =B30^2 -> 2.6048197e-05 | D30: =$B$4*D29+(1-$B$4)*C29 -> 4.9369235e-05 | E30: =SQRT(D30) -> 0.0070263244 | F30: =E30*SQRT(Parametrlar!$B$6) -> 0.11153944 | G30: =STDEV(B11:B30)*SQRT(Parametrlar!$B$6) -> 0.11402815
A31: =Daromadlilik!A26 -> 45328 | B31: =Daromadlilik!H26 -> -0.0054361886 | C31: =B31^2 -> 2.9552146e-05 | D31: =$B$4*D30+(1-$B$4)*C30 -> 4.7969973e-05 | E31: =SQRT(D31) -> 0.0069260359 | F31: =E31*SQRT(Parametrlar!$B$6) -> 0.10994741 | G31: =STDEV(B12:B31)*SQRT(Parametrlar!$B$6) -> 0.11412445
A32: =Daromadlilik!A27 -> 45329 | B32: =Daromadlilik!H27 -> 0.00089634168 | C32: =B32^2 -> 8.034284e-07 | D32: =$B$4*D31+(1-$B$4)*C31 -> 4.6864903e-05 | E32: =SQRT(D32) -> 0.0068457946 | F32: =E32*SQRT(Parametrlar!$B$6) -> 0.10867362 | G32: =STDEV(B13:B32)*SQRT(Parametrlar!$B$6) -> 0.10572385
A33: =Daromadlilik!A28 -> 45330 | B33: =Daromadlilik!H28 -> 0.006962028 | C33: =B33^2 -> 4.8469834e-05 | D33: =$B$4*D32+(1-$B$4)*C32 -> 4.4101215e-05 | E33: =SQRT(D33) -> 0.0066408746 | F33: =E33*SQRT(Parametrlar!$B$6) -> 0.10542062 | G33: =STDEV(B14:B33)*SQRT(Parametrlar!$B$6) -> 0.09851736
A34: =Daromadlilik!A29 -> 45331 | B34: =Daromadlilik!H29 -> 1.9993602e-05 | C34: =B34^2 -> 3.9974412e-10 | D34: =$B$4*D33+(1-$B$4)*C33 -> 4.4363332e-05 | E34: =SQRT(D34) -> 0.0066605805 | F34: =E34*SQRT(Parametrlar!$B$6) -> 0.10573344 | G34: =STDEV(B15:B34)*SQRT(Parametrlar!$B$6) -> 0.082383596
A35: =Daromadlilik!A30 -> 45334 | B35: =Daromadlilik!H30 -> 0.0013785941 | C35: =B35^2 -> 1.9005216e-06 | D35: =$B$4*D34+(1-$B$4)*C34 -> 4.1701556e-05 | E35: =SQRT(D35) -> 0.0064576742 | F35: =E35*SQRT(Parametrlar!$B$6) -> 0.1025124 | G35: =STDEV(B16:B35)*SQRT(Parametrlar!$B$6) -> 0.079735945
A36: =Daromadlilik!A31 -> 45335 | B36: =Daromadlilik!H31 -> 0.0084991839 | C36: =B36^2 -> 7.2236126e-05 | D36: =$B$4*D35+(1-$B$4)*C35 -> 3.9313494e-05 | E36: =SQRT(D36) -> 0.0062700474 | F36: =E36*SQRT(Parametrlar!$B$6) -> 0.099533916 | G36: =STDEV(B17:B36)*SQRT(Parametrlar!$B$6) -> 0.082917311
A37: =Daromadlilik!A32 -> 45336 | B37: =Daromadlilik!H32 -> 0.0055967257 | C37: =B37^2 -> 3.1323338e-05 | D37: =$B$4*D36+(1-$B$4)*C36 -> 4.1288852e-05 | E37: =SQRT(D37) -> 0.0064256402 | F37: =E37*SQRT(Parametrlar!$B$6) -> 0.10200388 | G37: =STDEV(B18:B37)*SQRT(Parametrlar!$B$6) -> 0.082287168
... A510: =Daromadlilik!A505 -> 45999 | B510: =Daromadlilik!H505 -> -0.018560809 | C510: =B510^2 -> 0.00034450363 | D510: =$B$4*D509+(1-$B$4)*C509 -> 9.2011283e-05 | E510: =SQRT(D510) -> 0.0095922512 | F510: =E510*SQRT(Parametrlar!$B$6) -> 0.15227227 | G510: =STDEV(B491:B510)*SQRT(Parametrlar!$B$6) -> 0.13112844

Sheet Beta_CAPM
A1: Beta koeffitsienti, tizimli/notizimli risk va CAPM
A2: Kunlik log daromadlilik asosida: r(i) = α + β·r(m) + ε. Bozor portfeli sifatida Indeks olingan.
A4: Ko‘rsatkich | B4: A_Sanoat | C4: B_Bank | D4: C_Telekom | E4: D_Energetika
A5: Beta (β) = SLOPE | B5: =SLOPE(Daromadlilik!$I$2:$I$505,Daromadlilik!$H$2:$H$505) -> 1.1920325 | C5: =SLOPE(Daromadlilik!$J$2:$J$505,Daromadlilik!$H$2:$H$505) -> 0.92772073 | D5: =SLOPE(Daromadlilik!$K$2:$K$505,Daromadlilik!$H$2:$H$505) -> 0.72873103 | E5: =SLOPE(Daromadlilik!$L$2:$L$505,Daromadlilik!$H$2:$H$505) -> 1.327378
A6: Alfa (kunlik) = INTERCEPT | B6: =INTERCEPT(Daromadlilik!$I$2:$I$505,Daromadlilik!$H$2:$H$505) -> 0.00078392045 | C6: =INTERCEPT(Daromadlilik!$J$2:$J$505,Daromadlilik!$H$2:$H$505) -> 0.00065809553 | D6: =INTERCEPT(Daromadlilik!$K$2:$K$505,Daromadlilik!$H$2:$H$505) -> -4.6796639e-05 | E6: =INTERCEPT(Daromadlilik!$L$2:$L$505,Daromadlilik!$H$2:$H$505) -> 0.00012893894
A7: Korrelyatsiya (ρ) indeks bilan | B7: =CORREL(Daromadlilik!$I$2:$I$505,Daromadlilik!$H$2:$H$505) -> 0.80069934 | C7: =CORREL(Daromadlilik!$J$2:$J$505,Daromadlilik!$H$2:$H$505) -> 0.75317782 | D7: =CORREL(Daromadlilik!$K$2:$K$505,Daromadlilik!$H$2:$H$505) -> 0.71887612 | E7: =CORREL(Daromadlilik!$L$2:$L$505,Daromadlilik!$H$2:$H$505) -> 0.71389444
A8: Determinatsiya koeff. R² | B8: =RSQ(Daromadlilik!$I$2:$I$505,Daromadlilik!$H$2:$H$505) -> 0.64111944 | C8: =RSQ(Daromadlilik!$J$2:$J$505,Daromadlilik!$H$2:$H$505) -> 0.56727683 | D8: =RSQ(Daromadlilik!$K$2:$K$505,Daromadlilik!$H$2:$H$505) -> 0.51678288 | E8: =RSQ(Daromadlilik!$L$2:$L$505,Daromadlilik!$H$2:$H$505) -> 0.50964527
A9: Umumiy dispersiya (yillik) | B9: =VAR(Daromadlilik!$I$2:$I$505)*Parametrlar!$B$6 -> 0.080037778 | C9: =VAR(Daromadlilik!$J$2:$J$505)*Parametrlar!$B$6 -> 0.054789493 | D9: =VAR(Daromadlilik!$K$2:$K$505)*Parametrlar!$B$6 -> 0.037109423 | E9: =VAR(Daromadlilik!$L$2:$L$505)*Parametrlar!$B$6 -> 0.12484727
A10: Tizimli dispersiya β²·σ²m (yillik) | B10: =B5^2*VAR(Daromadlilik!$H$2:$H$505)*Parametrlar!$B$6 -> 0.051313775 | C10: =C5^2*VAR(Daromadlilik!$H$2:$H$505)*Parametrlar!$B$6 -> 0.03108081 | D10: =D5^2*VAR(Daromadlilik!$H$2:$H$505)*Parametrlar!$B$6 -> 0.019177515 | E10: =E5^2*VAR(Daromadlilik!$H$2:$H$505)*Parametrlar!$B$6 -> 0.06362782
A11: Notizimli dispersiya (yillik) | B11: =B9-B10 -> 0.028724002 | C11: =C9-C10 -> 0.023708683 | D11: =D9-D10 -> 0.017931909 | E11: =E9-E10 -> 0.06121945
A12: Tizimli risk ulushi | B12: =B10/B9 -> 0.64111944 | C12: =C10/C9 -> 0.56727683 | D12: =D10/D9 -> 0.51678288 | E12: =E10/E9 -> 0.50964527
A13: Notizimli risk ulushi | B13: =B11/B9 -> 0.35888056 | C13: =C11/C9 -> 0.43272317 | D13: =D11/D9 -> 0.48321712 | E13: =E11/E9 -> 0.49035473
A14: Umumiy risk σ (yillik) | B14: =SQRT(B9) -> 0.28290949 | C14: =SQRT(C9) -> 0.23407155 | D14: =SQRT(D9) -> 0.19263806 | E14: =SQRT(E9) -> 0.35333733
A15: Tizimli risk β·σm (yillik) | B15: =B5*SQRT(VAR(Daromadlilik!$H$2:$H$505)*Parametrlar!$B$6) -> 0.22652544 | C15: =C5*SQRT(VAR(Daromadlilik!$H$2:$H$505)*Parametrlar!$B$6) -> 0.1762975 | D15: =D5*SQRT(VAR(Daromadlilik!$H$2:$H$505)*Parametrlar!$B$6) -> 0.1384829 | E15: =E5*SQRT(VAR(Daromadlilik!$H$2:$H$505)*Parametrlar!$B$6) -> 0.25224556
A16: CAPM bo‘yicha talab qilinadigan daromadlilik | B16: =Parametrlar!$B$4+B5*(Parametrlar!$B$5-Parametrlar!$B$4) -> 0.2353626 | C16: =Parametrlar!$B$4+C5*(Parametrlar!$B$5-Parametrlar!$B$4) -> 0.21421766 | D16: =Parametrlar!$B$4+D5*(Parametrlar!$B$5-Parametrlar!$B$4) -> 0.19829848 | E16: =Parametrlar!$B$4+E5*(Parametrlar!$B$5-Parametrlar!$B$4) -> 0.24619024
A17: Haqiqiy yillik o‘rtacha daromadlilik | B17: =AVERAGE(Daromadlilik!$I$2:$I$505)*Parametrlar!$B$6 -> 0.31461357 | C17: =AVERAGE(Daromadlilik!$J$2:$J$505)*Parametrlar!$B$6 -> 0.25694849 | D17: =AVERAGE(Daromadlilik!$K$2:$K$505)*Parametrlar!$B$6 -> 0.05977354 | E17: =AVERAGE(Daromadlilik!$L$2:$L$505)*Parametrlar!$B$6 -> 0.16285007
A18: Farq (haqiqiy − CAPM) | B18: =B17-B16 -> 0.07925097 | C18: =C17-C16 -> 0.042730836 | D18: =D17-D16 -> -0.13852494 | E18: =E17-E16 -> -0.083340172
A20: Portfel betasi (vaznlangan) | B20: =SUMPRODUCT(Parametrlar!$B$14:$E$14,B5:E5) -> 1.0371983
A21: Risksiz stavka / bozor daromadliligi (Parametrlar) | B21: =Parametrlar!$B$4 -> 0.14 | C21: =Parametrlar!$B$5 -> 0.22
A23: Izoh: R² — aksiya riskining bozor bilan izohlanadigan (tizimli) qismi. Diversifikatsiya faqat notizimli qismni kamaytiradi.

Sheet Portfel
A1: Portfel riski va diversifikatsiya (Markovits)
A2: Oddiy kunlik daromadlilik asosida; yillik ko‘rsatkichlar. Vaznlar — Parametrlar varag‘ida.
K3: Ikki aktivli portfel: korrelyatsiya ta’siri va samarali chegara
A4: Aktiv | B4: Vazn w | C4: Yillik μ | D4: Yillik σ | F4: Riskka hissa | G4: Marginal (cov(i,p)/σp) | H4: Komponent w·MCR | I4: Ulush, % | K4: Parametr | L4: Qiymat
A5: A_Sanoat | B5: =Parametrlar!$B$14 -> 0.3 | C5: =AVERAGE(Daromadlilik!$C$2:$C$505)*Parametrlar!$B$6 -> 0.35485608 | D5: =STDEV(Daromadlilik!$C$2:$C$505)*SQRT(Parametrlar!$B$6) -> 0.28391806 | F5: A_Sanoat | G5: =SUMPRODUCT(Parametrlar!$B$14:$E$14,B17:E17)/$B$31 -> 0.24893452 | H5: =B5*G5 -> 0.074680356 | I5: =H5/$B$31 -> 0.34440793 | K5: μ1 (aktiv 1) | L5: 0.18
A6: B_Bank | B6: =Parametrlar!$C$14 -> 0.25 | C6: =AVERAGE(Daromadlilik!$D$2:$D$505)*Parametrlar!$B$6 -> 0.28447532 | D6: =STDEV(Daromadlilik!$D$2:$D$505)*SQRT(Parametrlar!$B$6) -> 0.23469613 | F6: B_Bank | G6: =SUMPRODUCT(Parametrlar!$B$14:$E$14,B18:E18)/$B$31 -> 0.18985074 | H6: =B6*G6 -> 0.047462686 | I6: =H6/$B$31 -> 0.21888655 | K6: σ1 | L6: 0.3
A7: C_Telekom | B7: =Parametrlar!$D$14 -> 0.25 | C7: =AVERAGE(Daromadlilik!$E$2:$E$505)*Parametrlar!$B$6 -> 0.078317773 | D7: =STDEV(Daromadlilik!$E$2:$E$505)*SQRT(Parametrlar!$B$6) -> 0.1929337 | F7: C_Telekom | G7: =SUMPRODUCT(Parametrlar!$B$14:$E$14,B19:E19)/$B$31 -> 0.14756847 | H7: =B7*G7 -> 0.036892116 | I7: =H7/$B$31 -> 0.17013761 | K7: μ2 (aktiv 2) | L7: 0.12
A8: D_Energetika | B8: =Parametrlar!$E$14 -> 0.2 | C8: =AVERAGE(Daromadlilik!$F$2:$F$505)*Parametrlar!$B$6 -> 0.22534651 | D8: =STDEV(Daromadlilik!$F$2:$F$505)*SQRT(Parametrlar!$B$6) -> 0.3545383 | F8: D_Energetika | G8: =SUMPRODUCT(Parametrlar!$B$14:$E$14,B20:E20)/$B$31 -> 0.28900884 | H8: =B8*G8 -> 0.057801768 | I8: =H8/$B$31 -> 0.26656792 | K8: σ2 | L8: 0.18
F9: Jami | H9: =SUM(H5:H8) -> 0.21683693 | I9: =SUM(I5:I8) -> 1 | K9: ρ12 | L9: 0.3
A10: Korrelyatsiya | B10: A_Sanoat | C10: B_Bank | D10: C_Telekom | E10: D_Energetika | K10: Minimal dispersiyali w1* | L10: =(L8^2-L9*L6*L8)/(L6^2+L8^2-2*L9*L6*L8) -> 0.18
A11: A_Sanoat | B11: =CORREL(Daromadlilik!$C$2:$C$505,Daromadlilik!$C$2:$C$505) -> 1 | C11: =CORREL(Daromadlilik!$C$2:$C$505,Daromadlilik!$D$2:$D$505) -> 0.60231895 | D11: =CORREL(Daromadlilik!$C$2:$C$505,Daromadlilik!$E$2:$E$505) -> 0.5801481 | E11: =CORREL(Daromadlilik!$C$2:$C$505,Daromadlilik!$F$2:$F$505) -> 0.58696761 | K11: σp min | L11: =SQRT(L10^2*L6^2+(1-L10)^2*L8^2+2*L10*(1-L10)*L9*L6*L8) -> 0.17170906
A12: B_Bank | B12: =CORREL(Daromadlilik!$D$2:$D$505,Daromadlilik!$C$2:$C$505) -> 0.60231895 | C12: =CORREL(Daromadlilik!$D$2:$D$505,Daromadlilik!$D$2:$D$505) -> 1 | D12: =CORREL(Daromadlilik!$D$2:$D$505,Daromadlilik!$E$2:$E$505) -> 0.55969846 | E12: =CORREL(Daromadlilik!$D$2:$D$505,Daromadlilik!$F$2:$F$505) -> 0.54198771 | K12: μp min | L12: =L10*L5+(1-L10)*L7 -> 0.1308
A13: C_Telekom | B13: =CORREL(Daromadlilik!$E$2:$E$505,Daromadlilik!$C$2:$C$505) -> 0.5801481 | C13: =CORREL(Daromadlilik!$E$2:$E$505,Daromadlilik!$D$2:$D$505) -> 0.55969846 | D13: =CORREL(Daromadlilik!$E$2:$E$505,Daromadlilik!$E$2:$E$505) -> 1 | E13: =CORREL(Daromadlilik!$E$2:$E$505,Daromadlilik!$F$2:$F$505) -> 0.49872875
A14: D_Energetika | B14: =CORREL(Daromadlilik!$F$2:$F$505,Daromadlilik!$C$2:$C$505) -> 0.58696761 | C14: =CORREL(Daromadlilik!$F$2:$F$505,Daromadlilik!$D$2:$D$505) -> 0.54198771 | D14: =CORREL(Daromadlilik!$F$2:$F$505,Daromadlilik!$E$2:$E$505) -> 0.49872875 | E14: =CORREL(Daromadlilik!$F$2:$F$505,Daromadlilik!$F$2:$F$505) -> 1 | K14: w1 | L14: μp | M14: σp | N14: σp (ρ=−1) | O14: σp (ρ=0) | P14: σp (ρ=+1)
K15: 0 | L15: =K15*$L$5+(1-K15)*$L$7 -> 0.12 | M15: =SQRT(MAX(0,K15^2*$L$6^2+(1-K15)^2*$L$8^2+2*K15*(1-K15)*$L$9*$L$6*$L$8)) -> 0.18 | N15: =SQRT(MAX(0,K15^2*$L$6^2+(1-K15)^2*$L$8^2+2*K15*(1-K15)*-1*$L$6*$L$8)) -> 0.18 | O15: =SQRT(MAX(0,K15^2*$L$6^2+(1-K15)^2*$L$8^2+2*K15*(1-K15)*0*$L$6*$L$8)) -> 0.18 | P15: =SQRT(MAX(0,K15^2*$L$6^2+(1-K15)^2*$L$8^2+2*K15*(1-K15)*1*$L$6*$L$8)) -> 0.18
A16: Kovariatsiya (yillik) | B16: A_Sanoat | C16: B_Bank | D16: C_Telekom | E16: D_Energetika | K16: 0.1 | L16: =K16*$L$5+(1-K16)*$L$7 -> 0.126 | M16: =SQRT(MAX(0,K16^2*$L$6^2+(1-K16)^2*$L$8^2+2*K16*(1-K16)*$L$9*$L$6*$L$8)) -> 0.1733782 | N16: =SQRT(MAX(0,K16^2*$L$6^2+(1-K16)^2*$L$8^2+2*K16*(1-K16)*-1*$L$6*$L$8)) -> 0.132 | O16: =SQRT(MAX(0,K16^2*$L$6^2+(1-K16)^2*$L$8^2+2*K16*(1-K16)*0*$L$6*$L$8)) -> 0.16475436 | P16: =SQRT(MAX(0,K16^2*$L$6^2+(1-K16)^2*$L$8^2+2*K16*(1-K16)*1*$L$6*$L$8)) -> 0.192
A17: A_Sanoat | B17: =B11*$D$5*INDEX($D$5:$D$8,1) -> 0.080609463 | C17: =C11*$D$5*INDEX($D$5:$D$8,2) -> 0.040135202 | D17: =D11*$D$5*INDEX($D$5:$D$8,3) -> 0.031778982 | E17: =E11*$D$5*INDEX($D$5:$D$8,4) -> 0.059084056 | K17: 0.2 | L17: =K17*$L$5+(1-K17)*$L$7 -> 0.132 | M17: =SQRT(MAX(0,K17^2*$L$6^2+(1-K17)^2*$L$8^2+2*K17*(1-K17)*$L$9*$L$6*$L$8)) -> 0.17181385 | N17: =SQRT(MAX(0,K17^2*$L$6^2+(1-K17)^2*$L$8^2+2*K17*(1-K17)*-1*$L$6*$L$8)) -> 0.084 | O17: =SQRT(MAX(0,K17^2*$L$6^2+(1-K17)^2*$L$8^2+2*K17*(1-K17)*0*$L$6*$L$8)) -> 0.156 | P17: =SQRT(MAX(0,K17^2*$L$6^2+(1-K17)^2*$L$8^2+2*K17*(1-K17)*1*$L$6*$L$8)) -> 0.204
A18: B_Bank | B18: =B12*$D$6*INDEX($D$5:$D$8,1) -> 0.040135202 | C18: =C12*$D$6*INDEX($D$5:$D$8,2) -> 0.055082271 | D18: =D12*$D$6*INDEX($D$5:$D$8,3) -> 0.02534359 | E18: =E12*$D$6*INDEX($D$5:$D$8,4) -> 0.045098128 | K18: 0.3 | L18: =K18*$L$5+(1-K18)*$L$7 -> 0.138 | M18: =SQRT(MAX(0,K18^2*$L$6^2+(1-K18)^2*$L$8^2+2*K18*(1-K18)*$L$9*$L$6*$L$8)) -> 0.1754423 | N18: =SQRT(MAX(0,K18^2*$L$6^2+(1-K18)^2*$L$8^2+2*K18*(1-K18)*-1*$L$6*$L$8)) -> 0.036 | O18: =SQRT(MAX(0,K18^2*$L$6^2+(1-K18)^2*$L$8^2+2*K18*(1-K18)*0*$L$6*$L$8)) -> 0.15484185 | P18: =SQRT(MAX(0,K18^2*$L$6^2+(1-K18)^2*$L$8^2+2*K18*(1-K18)*1*$L$6*$L$8)) -> 0.216
A19: C_Telekom | B19: =B13*$D$7*INDEX($D$5:$D$8,1) -> 0.031778982 | C19: =C13*$D$7*INDEX($D$5:$D$8,2) -> 0.02534359 | D19: =D13*$D$7*INDEX($D$5:$D$8,3) -> 0.037223413 | E19: =E13*$D$7*INDEX($D$5:$D$8,4) -> 0.034114236 | K19: 0.4 | L19: =K19*$L$5+(1-K19)*$L$7 -> 0.144 | M19: =SQRT(MAX(0,K19^2*$L$6^2+(1-K19)^2*$L$8^2+2*K19*(1-K19)*$L$9*$L$6*$L$8)) -> 0.18395652 | N19: =SQRT(MAX(0,K19^2*$L$6^2+(1-K19)^2*$L$8^2+2*K19*(1-K19)*-1*$L$6*$L$8)) -> 0.012 | O19: =SQRT(MAX(0,K19^2*$L$6^2+(1-K19)^2*$L$8^2+2*K19*(1-K19)*0*$L$6*$L$8)) -> 0.16144349 | P19: =SQRT(MAX(0,K19^2*$L$6^2+(1-K19)^2*$L$8^2+2*K19*(1-K19)*1*$L$6*$L$8)) -> 0.228
A20: D_Energetika | B20: =B14*$D$8*INDEX($D$5:$D$8,1) -> 0.059084056 | C20: =C14*$D$8*INDEX($D$5:$D$8,2) -> 0.045098128 | D20: =D14*$D$8*INDEX($D$5:$D$8,3) -> 0.034114236 | E20: =E14*$D$8*INDEX($D$5:$D$8,4) -> 0.1256974 | K20: 0.5 | L20: =K20*$L$5+(1-K20)*$L$7 -> 0.15 | M20: =SQRT(MAX(0,K20^2*$L$6^2+(1-K20)^2*$L$8^2+2*K20*(1-K20)*$L$9*$L$6*$L$8)) -> 0.19672316 | N20: =SQRT(MAX(0,K20^2*$L$6^2+(1-K20)^2*$L$8^2+2*K20*(1-K20)*-1*$L$6*$L$8)) -> 0.06 | O20: =SQRT(MAX(0,K20^2*$L$6^2+(1-K20)^2*$L$8^2+2*K20*(1-K20)*0*$L$6*$L$8)) -> 0.17492856 | P20: =SQRT(MAX(0,K20^2*$L$6^2+(1-K20)^2*$L$8^2+2*K20*(1-K20)*1*$L$6*$L$8)) -> 0.24
K21: 0.6 | L21: =K21*$L$5+(1-K21)*$L$7 -> 0.156 | M21: =SQRT(MAX(0,K21^2*$L$6^2+(1-K21)^2*$L$8^2+2*K21*(1-K21)*$L$9*$L$6*$L$8)) -> 0.21297887 | N21: =SQRT(MAX(0,K21^2*$L$6^2+(1-K21)^2*$L$8^2+2*K21*(1-K21)*-1*$L$6*$L$8)) -> 0.108 | O21: =SQRT(MAX(0,K21^2*$L$6^2+(1-K21)^2*$L$8^2+2*K21*(1-K21)*0*$L$6*$L$8)) -> 0.19386593 | P21: =SQRT(MAX(0,K21^2*$L$6^2+(1-K21)^2*$L$8^2+2*K21*(1-K21)*1*$L$6*$L$8)) -> 0.252
A22: w(i)·w(j)·cov(i,j) | B22: A_Sanoat | C22: B_Bank | D22: C_Telekom | E22: D_Energetika | K22: 0.7 | L22: =K22*$L$5+(1-K22)*$L$7 -> 0.162 | M22: =SQRT(MAX(0,K22^2*$L$6^2+(1-K22)^2*$L$8^2+2*K22*(1-K22)*$L$9*$L$6*$L$8)) -> 0.23199138 | N22: =SQRT(MAX(0,K22^2*$L$6^2+(1-K22)^2*$L$8^2+2*K22*(1-K22)*-1*$L$6*$L$8)) -> 0.156 | O22: =SQRT(MAX(0,K22^2*$L$6^2+(1-K22)^2*$L$8^2+2*K22*(1-K22)*0*$L$6*$L$8)) -> 0.21683173 | P22: =SQRT(MAX(0,K22^2*$L$6^2+(1-K22)^2*$L$8^2+2*K22*(1-K22)*1*$L$6*$L$8)) -> 0.264
A23: A_Sanoat | B23: =$B$5*INDEX($B$5:$B$8,1)*B17 -> 0.0072548516 | C23: =$B$5*INDEX($B$5:$B$8,2)*C17 -> 0.0030101402 | D23: =$B$5*INDEX($B$5:$B$8,3)*D17 -> 0.0023834237 | E23: =$B$5*INDEX($B$5:$B$8,4)*E17 -> 0.0035450434 | K23: 0.8 | L23: =K23*$L$5+(1-K23)*$L$7 -> 0.168 | M23: =SQRT(MAX(0,K23^2*$L$6^2+(1-K23)^2*$L$8^2+2*K23*(1-K23)*$L$9*$L$6*$L$8)) -> 0.25314028 | N23: =SQRT(MAX(0,K23^2*$L$6^2+(1-K23)^2*$L$8^2+2*K23*(1-K23)*-1*$L$6*$L$8)) -> 0.204 | O23: =SQRT(MAX(0,K23^2*$L$6^2+(1-K23)^2*$L$8^2+2*K23*(1-K23)*0*$L$6*$L$8)) -> 0.24268498 | P23: =SQRT(MAX(0,K23^2*$L$6^2+(1-K23)^2*$L$8^2+2*K23*(1-K23)*1*$L$6*$L$8)) -> 0.276
A24: B_Bank | B24: =$B$6*INDEX($B$5:$B$8,1)*B18 -> 0.0030101402 | C24: =$B$6*INDEX($B$5:$B$8,2)*C18 -> 0.003442642 | D24: =$B$6*INDEX($B$5:$B$8,3)*D18 -> 0.0015839744 | E24: =$B$6*INDEX($B$5:$B$8,4)*E18 -> 0.0022549064 | K24: 0.9 | L24: =K24*$L$5+(1-K24)*$L$7 -> 0.174 | M24: =SQRT(MAX(0,K24^2*$L$6^2+(1-K24)^2*$L$8^2+2*K24*(1-K24)*$L$9*$L$6*$L$8)) -> 0.27593477 | N24: =SQRT(MAX(0,K24^2*$L$6^2+(1-K24)^2*$L$8^2+2*K24*(1-K24)*-1*$L$6*$L$8)) -> 0.252 | O24: =SQRT(MAX(0,K24^2*$L$6^2+(1-K24)^2*$L$8^2+2*K24*(1-K24)*0*$L$6*$L$8)) -> 0.27059933 | P24: =SQRT(MAX(0,K24^2*$L$6^2+(1-K24)^2*$L$8^2+2*K24*(1-K24)*1*$L$6*$L$8)) -> 0.288
A25: C_Telekom | B25: =$B$7*INDEX($B$5:$B$8,1)*B19 -> 0.0023834237 | C25: =$B$7*INDEX($B$5:$B$8,2)*C19 -> 0.0015839744 | D25: =$B$7*INDEX($B$5:$B$8,3)*D19 -> 0.0023264633 | E25: =$B$7*INDEX($B$5:$B$8,4)*E19 -> 0.0017057118 | K25: 1 | L25: =K25*$L$5+(1-K25)*$L$7 -> 0.18 | M25: =SQRT(MAX(0,K25^2*$L$6^2+(1-K25)^2*$L$8^2+2*K25*(1-K25)*$L$9*$L$6*$L$8)) -> 0.3 | N25: =SQRT(MAX(0,K25^2*$L$6^2+(1-K25)^2*$L$8^2+2*K25*(1-K25)*-1*$L$6*$L$8)) -> 0.3 | O25: =SQRT(MAX(0,K25^2*$L$6^2+(1-K25)^2*$L$8^2+2*K25*(1-K25)*0*$L$6*$L$8)) -> 0.3 | P25: =SQRT(MAX(0,K25^2*$L$6^2+(1-K25)^2*$L$8^2+2*K25*(1-K25)*1*$L$6*$L$8)) -> 0.3
A26: D_Energetika | B26: =$B$8*INDEX($B$5:$B$8,1)*B20 -> 0.0035450434 | C26: =$B$8*INDEX($B$5:$B$8,2)*C20 -> 0.0022549064 | D26: =$B$8*INDEX($B$5:$B$8,3)*D20 -> 0.0017057118 | E26: =$B$8*INDEX($B$5:$B$8,4)*E20 -> 0.0050278962
A28: Natijalar | B28: Qiymat
A29: Portfel kutilayotgan daromadliligi μp | B29: =SUMPRODUCT(B5:B8,C5:C8) -> 0.2422244
A30: Portfel dispersiyasi σp² | B30: =SUM(B23:E26) -> 0.047018253
A31: Portfel riski σp (yillik) | B31: =SQRT(B30) -> 0.21683693
A32: Vaznlangan o‘rtacha σ (Σ w·σ) | B32: =SUMPRODUCT(B5:B8,D5:D8) -> 0.26299053
A33: Diversifikatsiya samarasi (riskning kamayishi) | B33: =B32-B31 -> 0.046153606
A34: Diversifikatsiya koeffitsienti Σw·σ / σp | B34: =B32/B31 -> 1.2128494
A35: Sharp koeffitsienti (μp − rf)/σp | B35: =(B29-Parametrlar!$B$4)/B31 -> 0.47143447

Sheet VaR
A1: Value at Risk va Expected Shortfall (portfel)
A2: Portfelning kunlik oddiy daromadliligi: Rp = Σ w(i)·R(i). VaR musbat son — yo‘qotish miqdori (so‘m).
A4: Sana | B4: Rp (kunlik) | C4: ln(1+Rp) | D4: 10 kunlik ln-yig‘indi | F4: Kiritilgan parametrlar | L4: MK simulyatsiya Rp
A5: =Daromadlilik!A2 -> 45294 | B5: =SUMPRODUCT(Parametrlar!$B$14:$E$14,Daromadlilik!C2:F2) -> 0.0079471374 | C5: =LN(1+B5) -> 0.0079157253 | F5: Portfel qiymati V, so‘m | G5: =Parametrlar!$B$7 -> 10000000000 | L5: =NORMSINV(RAND())*$G$7+$G$6 -> 0.002974312
A6: =Daromadlilik!A3 -> 45295 | B6: =SUMPRODUCT(Parametrlar!$B$14:$E$14,Daromadlilik!C3:F3) -> -0.0077718824 | C6: =LN(1+B6) -> -0.0078022408 | F6: Kunlik μ | G6: =AVERAGE($B$5:$B$508) -> 0.00096120794 | L6: =NORMSINV(RAND())*$G$7+$G$6 -> -0.0026924248
A7: =Daromadlilik!A4 -> 45296 | B7: =SUMPRODUCT(Parametrlar!$B$14:$E$14,Daromadlilik!C4:F4) -> 0.0054525131 | C7: =LN(1+B7) -> 0.005437702 | F7: Kunlik σ | G7: =STDEV($B$5:$B$508) -> 0.013659442 | L7: =NORMSINV(RAND())*$G$7+$G$6 -> 0.010426114
A8: =Daromadlilik!A5 -> 45299 | B8: =SUMPRODUCT(Parametrlar!$B$14:$E$14,Daromadlilik!C5:F5) -> 0.0095263739 | C8: =LN(1+B8) -> 0.0094812842 | F8: Gorizont h, kun | G8: =Parametrlar!$B$9 -> 10 | L8: =NORMSINV(RAND())*$G$7+$G$6 -> 0.027283246
A9: =Daromadlilik!A6 -> 45300 | B9: =SUMPRODUCT(Parametrlar!$B$14:$E$14,Daromadlilik!C6:F6) -> -0.013160007 | C9: =LN(1+B9) -> -0.013247367 | L9: =NORMSINV(RAND())*$G$7+$G$6 -> 0.010630295
A10: =Daromadlilik!A7 -> 45301 | B10: =SUMPRODUCT(Parametrlar!$B$14:$E$14,Daromadlilik!C7:F7) -> 0.013888726 | C10: =LN(1+B10) -> 0.013793162 | F10: Usul / ishonch darajasi α | G10: 95% | H10: 97,5% | I10: 99% | L10: =NORMSINV(RAND())*$G$7+$G$6 -> -0.0045218185
A11: =Daromadlilik!A8 -> 45302 | B11: =SUMPRODUCT(Parametrlar!$B$14:$E$14,Daromadlilik!C8:F8) -> -0.013054969 | C11: =LN(1+B11) -> -0.013140934 | F11: α (o‘zgartirish mumkin) | G11: 0.95 | H11: 0.975 | I11: 0.99 | L11: =NORMSINV(RAND())*$G$7+$G$6 -> 0.0080348326
A12: =Daromadlilik!A9 -> 45303 | B12: =SUMPRODUCT(Parametrlar!$B$14:$E$14,Daromadlilik!C9:F9) -> -0.020448272 | C12: =LN(1+B12) -> -0.020660232 | F12: z(α) = NORMSINV(α) | G12: =NORMSINV(G$11) -> 1.6448536 | H12: =NORMSINV(H$11) -> 1.959964 | I12: =NORMSINV(I$11) -> 2.3263479 | L12: =NORMSINV(RAND())*$G$7+$G$6 -> -0.020096137
A13: =Daromadlilik!A10 -> 45306 | B13: =SUMPRODUCT(Parametrlar!$B$14:$E$14,Daromadlilik!C10:F10) -> -0.0038824637 | C13: =LN(1+B13) -> -0.00389002 | F13: Parametrik VaR, 1 kun | G13: =(G$12*$G$7-$G$6)*$G$5 -> 2.1506575e+08 | H13: =(H$12*$G$7-$G$6)*$G$5 -> 2.5810807e+08 | I13: =(I$12*$G$7-$G$6)*$G$5 -> 3.0815407e+08 | L13: =NORMSINV(RAND())*$G$7+$G$6 -> -0.007333163
A14: =Daromadlilik!A11 -> 45307 | B14: =SUMPRODUCT(Parametrlar!$B$14:$E$14,Daromadlilik!C11:F11) -> -0.0060761178 | C14: =LN(1+B14) -> -0.0060946525 | D14: =SUM(C5:C14) -> -0.028207574 | F14: Parametrik VaR, h kun (√h qoidasi) | G14: =G13*SQRT($G$8) -> 6.8009763e+08 | H14: =H13*SQRT($G$8) -> 8.1620939e+08 | I14: =I13*SQRT($G$8) -> 9.7446873e+08 | L14: =NORMSINV(RAND())*$G$7+$G$6 -> 0.0053693858
A15: =Daromadlilik!A12 -> 45308 | B15: =SUMPRODUCT(Parametrlar!$B$14:$E$14,Daromadlilik!C12:F12) -> 0.0021024357 | C15: =LN(1+B15) -> 0.0021002287 | D15: =SUM(C6:C15) -> -0.034023071 | F15: Tarixiy VaR, 1 kun | G15: =-PERCENTILE($B$5:$B$508,1-G$11)*$G$5 -> 2.1088248e+08 | H15: =-PERCENTILE($B$5:$B$508,1-H$11)*$G$5 -> 2.7122642e+08 | I15: =-PERCENTILE($B$5:$B$508,1-I$11)*$G$5 -> 3.4237628e+08 | L15: =NORMSINV(RAND())*$G$7+$G$6 -> 0.023631383
A16: =Daromadlilik!A13 -> 45309 | B16: =SUMPRODUCT(Parametrlar!$B$14:$E$14,Daromadlilik!C13:F13) -> 0.0082864466 | C16: =LN(1+B16) -> 0.0082523025 | D16: =SUM(C7:C16) -> -0.017968527 | F16: Tarixiy VaR, h kun (√h qoidasi) | G16: =G15*SQRT($G$8) -> 6.6686897e+08 | H16: =H15*SQRT($G$8) -> 8.5769326e+08 | I16: =I15*SQRT($G$8) -> 1.0826889e+09 | L16: =NORMSINV(RAND())*$G$7+$G$6 -> 0.018198094
A17: =Daromadlilik!A14 -> 45310 | B17: =SUMPRODUCT(Parametrlar!$B$14:$E$14,Daromadlilik!C14:F14) -> -0.00070107216 | C17: =LN(1+B17) -> -0.00070131802 | D17: =SUM(C8:C17) -> -0.024107547 | F17: Parametrik ES, 1 kun | G17: =($G$7*NORMDIST(G$12,0,1,FALSE())/(1-G$11)-$G$6)*$G$5 -> 2.7214299e+08 | H17: =($G$7*NORMDIST(H$12,0,1,FALSE())/(1-H$11)-$G$6)*$G$5 -> 3.0971875e+08 | I17: =($G$7*NORMDIST(I$12,0,1,FALSE())/(1-I$11)-$G$6)*$G$5 -> 3.5444132e+08 | L17: =NORMSINV(RAND())*$G$7+$G$6 -> -0.0083298878
A18: =Daromadlilik!A15 -> 45313 | B18: =SUMPRODUCT(Parametrlar!$B$14:$E$14,Daromadlilik!C15:F15) -> -0.0070095979 | C18: =LN(1+B18) -> -0.0070342805 | D18: =SUM(C9:C18) -> -0.040623112 | F18: Tarixiy ES, 1 kun | G18: =-AVERAGEIF($B$5:$B$508,"<="&PERCENTILE($B$5:$B$508,1-G$11))*$G$5 -> 2.8604427e+08 | H18: =-AVERAGEIF($B$5:$B$508,"<="&PERCENTILE($B$5:$B$508,1-H$11))*$G$5 -> 3.2876465e+08 | I18: =-AVERAGEIF($B$5:$B$508,"<="&PERCENTILE($B$5:$B$508,1-I$11))*$G$5 -> 3.5615249e+08 | L18: =NORMSINV(RAND())*$G$7+$G$6 -> 0.0058338203
A19: =Daromadlilik!A16 -> 45314 | B19: =SUMPRODUCT(Parametrlar!$B$14:$E$14,Daromadlilik!C16:F16) -> -0.0026616222 | C19: =LN(1+B19) -> -0.0026651707 | D19: =SUM(C10:C19) -> -0.030040916 | F19: Monte-Karlo VaR, 1 kun | G19: =-PERCENTILE($L$5:$L$5004,1-G$11)*$G$5 -> 2.1304579e+08 | H19: =-PERCENTILE($L$5:$L$5004,1-H$11)*$G$5 -> 2.5620862e+08 | I19: =-PERCENTILE($L$5:$L$5004,1-I$11)*$G$5 -> 3.0892972e+08 | L19: =NORMSINV(RAND())*$G$7+$G$6 -> 0.010889282
A20: =Daromadlilik!A17 -> 45315 | B20: =SUMPRODUCT(Parametrlar!$B$14:$E$14,Daromadlilik!C17:F17) -> 0.0076227094 | C20: =LN(1+B20) -> 0.0075938034 | D20: =SUM(C11:C20) -> -0.036240274 | F20: ES / VaR (tarixiy) | G20: =G18/G15 -> 1.3564155 | H20: =H18/H15 -> 1.2121409 | I20: =I18/I15 -> 1.040237 | L20: =NORMSINV(RAND())*$G$7+$G$6 -> 0.010805004
A21: =Daromadlilik!A18 -> 45316 | B21: =SUMPRODUCT(Parametrlar!$B$14:$E$14,Daromadlilik!C18:F18) -> 0.021524673 | C21: =LN(1+B21) -> 0.021296288 | D21: =SUM(C12:C21) -> -0.0018030512 | F21: VaR chegarasidan oshgan kunlar soni | G21: =COUNTIF($B$5:$B$508,"<"&-G15/$G$5) -> 26 | H21: =COUNTIF($B$5:$B$508,"<"&-H15/$G$5) -> 13 | I21: =COUNTIF($B$5:$B$508,"<"&-I15/$G$5) -> 6 | L21: =NORMSINV(RAND())*$G$7+$G$6 -> 0.0063608427
A22: =Daromadlilik!A19 -> 45317 | B22: =SUMPRODUCT(Parametrlar!$B$14:$E$14,Daromadlilik!C19:F19) -> 0.0075484243 | C22: =LN(1+B22) -> 0.0075200775 | D22: =SUM(C13:C22) -> 0.026377259 | L22: =NORMSINV(RAND())*$G$7+$G$6 -> -0.0075843699
A23: =Daromadlilik!A20 -> 45320 | B23: =SUMPRODUCT(Parametrlar!$B$14:$E$14,Daromadlilik!C20:F20) -> -0.00090343014 | C23: =LN(1+B23) -> -0.00090383848 | D23: =SUM(C14:C23) -> 0.02936344 | F23: Diversifikatsiyalanmagan va diversifikatsiyalangan VaR (parametrik, 1 kun, α — Parametrlar) | L23: =NORMSINV(RAND())*$G$7+$G$6 -> 0.0015499386
A24: =Daromadlilik!A21 -> 45321 | B24: =SUMPRODUCT(Parametrlar!$B$14:$E$14,Daromadlilik!C21:F21) -> 0.0033439788 | C24: =LN(1+B24) -> 0.0033384001 | D24: =SUM(C15:C24) -> 0.038796493 | F24: Aktiv | G24: Pozitsiya, so‘m | H24: Kunlik σ | I24: Alohida VaR | L24: =NORMSINV(RAND())*$G$7+$G$6 -> 0.003184194
A25: =Daromadlilik!A22 -> 45322 | B25: =SUMPRODUCT(Parametrlar!$B$14:$E$14,Daromadlilik!C22:F22) -> 0.004777239 | C25: =LN(1+B25) -> 0.0047658642 | D25: =SUM(C16:C25) -> 0.041462128 | F25: A_Sanoat | G25: =Parametrlar!$B$14*Parametrlar!$B$7 -> 3000000000 | H25: =STDEV(Daromadlilik!$C$2:$C$505) -> 0.017885156 | I25: =NORMSINV(Parametrlar!$B$8)*H25*G25 -> 1.2482129e+08 | L25: =NORMSINV(RAND())*$G$7+$G$6 -> 0.025810318
A26: =Daromadlilik!A23 -> 45323 | B26: =SUMPRODUCT(Parametrlar!$B$14:$E$14,Daromadlilik!C23:F23) -> 0.0016458388 | C26: =LN(1+B26) -> 0.0016444859 | D26: =SUM(C17:C26) -> 0.034854312 | F26: B_Bank | G26: =Parametrlar!$C$14*Parametrlar!$B$7 -> 2500000000 | H26: =STDEV(Daromadlilik!$D$2:$D$505) -> 0.014784466 | I26: =NORMSINV(Parametrlar!$B$8)*H26*G26 -> 85984529 | L26: =NORMSINV(RAND())*$G$7+$G$6 -> 0.01686576
A27: =Daromadlilik!A24 -> 45324 | B27: =SUMPRODUCT(Parametrlar!$B$14:$E$14,Daromadlilik!C24:F24) -> 0.0011932653 | C27: =LN(1+B27) -> 0.0011925539 | D27: =SUM(C18:C27) -> 0.036748184 | F27: C_Telekom | G27: =Parametrlar!$D$14*Parametrlar!$B$7 -> 2500000000 | H27: =STDEV(Daromadlilik!$E$2:$E$505) -> 0.012153681 | I27: =NORMSINV(Parametrlar!$B$8)*H27*G27 -> 70684223 | L27: =NORMSINV(RAND())*$G$7+$G$6 -> 0.018218426
A28: =Daromadlilik!A25 -> 45327 | B28: =SUMPRODUCT(Parametrlar!$B$14:$E$14,Daromadlilik!C25:F25) -> -0.0002007973 | C28: =LN(1+B28) -> -0.00020081746 | D28: =SUM(C19:C28) -> 0.043581647 | F28: D_Energetika | G28: =Parametrlar!$E$14*Parametrlar!$B$7 -> 2000000000 | H28: =STDEV(Daromadlilik!$F$2:$F$505) -> 0.022333813 | I28: =NORMSINV(Parametrlar!$B$8)*H28*G28 -> 1.0391244e+08 | L28: =NORMSINV(RAND())*$G$7+$G$6 -> 0.0017280649
A29: =Daromadlilik!A26 -> 45328 | B29: =SUMPRODUCT(Parametrlar!$B$14:$E$14,Daromadlilik!C26:F26) -> -0.015636506 | C29: =LN(1+B29) -> -0.015760046 | D29: =SUM(C20:C29) -> 0.030486771 | F29: Alohida VaR’lar yig‘indisi | I29: =SUM(I25:I28) -> 3.8540248e+08 | L29: =NORMSINV(RAND())*$G$7+$G$6 -> 0.0062679727
A30: =Daromadlilik!A27 -> 45329 | B30: =SUMPRODUCT(Parametrlar!$B$14:$E$14,Daromadlilik!C27:F27) -> 0.0029753894 | C30: =LN(1+B30) -> 0.0029709717 | D30: =SUM(C21:C30) -> 0.02586394 | F30: Portfel VaR (diversifikatsiyalangan) | I30: =NORMSINV(Parametrlar!$B$8)*G7*G5 -> 3.1776615e+08 | L30: =NORMSINV(RAND())*$G$7+$G$6 -> 0.027748844
A31: =Daromadlilik!A28 -> 45330 | B31: =SUMPRODUCT(Parametrlar!$B$14:$E$14,Daromadlilik!C28:F28) -> 0.0036405432 | C31: =LN(1+B31) -> 0.0036339324 | D31: =SUM(C22:C31) -> 0.0082015839 | F31: Diversifikatsiya samarasi, so‘m | I31: =I29-I30 -> 67636329 | L31: =NORMSINV(RAND())*$G$7+$G$6 -> 0.0010114542
A32: =Daromadlilik!A29 -> 45331 | B32: =SUMPRODUCT(Parametrlar!$B$14:$E$14,Daromadlilik!C29:F29) -> -0.0023826188 | C32: =LN(1+B32) -> -0.0023854617 | D32: =SUM(C23:C32) -> -0.0017039554 | L32: =NORMSINV(RAND())*$G$7+$G$6 -> 0.011824742
A33: =Daromadlilik!A30 -> 45334 | B33: =SUMPRODUCT(Parametrlar!$B$14:$E$14,Daromadlilik!C30:F30) -> 0.00052576729 | C33: =LN(1+B33) -> 0.00052562912 | D33: =SUM(C24:C33) -> -0.00027448776 | F33: Eng yomon 10 kunlik davr (tarixiy, ln-yig‘indi) | I33: =EXP(MIN(D14:D508))-1 -> -0.13374648 | L33: =NORMSINV(RAND())*$G$7+$G$6 -> 0.0045107173
A34: =Daromadlilik!A31 -> 45335 | B34: =SUMPRODUCT(Parametrlar!$B$14:$E$14,Daromadlilik!C31:F31) -> 0.0033579976 | C34: =LN(1+B34) -> 0.0033523721 | D34: =SUM(C25:C34) -> -0.00026051578 | F34: Eng yomon 10 kunlik yo‘qotish, so‘m | I34: =-I33*G5 -> 1.3374648e+09 | L34: =NORMSINV(RAND())*$G$7+$G$6 -> -0.0013954359
A35: =Daromadlilik!A32 -> 45336 | B35: =SUMPRODUCT(Parametrlar!$B$14:$E$14,Daromadlilik!C32:F32) -> 0.0059271109 | C35: =LN(1+B35) -> 0.0059096146 | D35: =SUM(C26:C35) -> 0.00088323463 | L35: =NORMSINV(RAND())*$G$7+$G$6 -> 0.0063844269
A36: =Daromadlilik!A33 -> 45337 | B36: =SUMPRODUCT(Parametrlar!$B$14:$E$14,Daromadlilik!C33:F33) -> -0.00081285273 | C36: =LN(1+B36) -> -0.00081318328 | D36: =SUM(C27:C36) -> -0.0015744345 | F36: Monte-Karlo: L ustunida N(μ, σ) taqsimotidan 5000 ta tasodifiy kunlik daromadlilik (F9 — qayta generatsiya). | L36: =NORMSINV(RAND())*$G$7+$G$6 -> -0.022643274
