Workbook
Name jop: #REF!
Name kol: #REF!
Name OLE_LINK19: Balance!$D$33
Name RISKTOTASS: SUM('[1]Calculation of Risk Weighted As'!$C$38:$F$38)
Name TwentyLargestData: #REF!
Name Е: #REF!

Sheet Balance
A1: СТРУКТУРА БАЛАНСА БАНКА | E1: Таблица-1 | F1: 1133
B2: =IF(C3>0," "&TEXT(C3,"д ММММ, гггг"),"Число,Месяц,Год") -> 30 Декабрь, 2019
B3: АКБ "Микрокредитбанк" | C3: 43829 | E3: тыс. сум
A4: № | B4: АКТИВЫ | C4: Итого | D4: в национальной валюте | E4: в иностранной валюте (в экв. в сумах)
A5: 1 | B5: Кассовая наличность и другие платежные документы | C5: =+D5+E5 -> 173211577 | D5: =+'Bank Assets Analysis'!T7 -> 69805132 | E5: =+'Bank Assets Analysis'!U7 -> 103406445 | L5: =+C5-D5-E5 -> 0
A6: 2 | B6: К получению из ЦБРУ | C6: =+D6+E6 -> 140577780 | D6: =+'Bank Assets Analysis'!T8+'Bank Assets Analysis'!T9 -> 119493320 | E6: =+'Bank Assets Analysis'!U8+'Bank Assets Analysis'!U9 -> 21084460 | L6: =+C6-D6-E6 -> 0
A7: 3 | B7: К получению из других банков, чистые | C7: =+'Bank Assets Analysis'!S10 -> 453538332 | D7: =+'Bank Assets Analysis'!T10 -> 266889175 | E7: =+'Bank Assets Analysis'!U10 -> 186649157 | L7: =+C7-D7-E7 -> 0
A8: 3.1. | B8: К получению из других банков, брутто | C8: =+D8+E8 -> 453538332 | D8: 266889175 | E8: 186649157 | L8: =+C8-D8-E8 -> 0
A9: 3.2. | B9: Минус: Резерв возможных убытков | C9: =+D9+E9 -> 0 | L9: =+C9-D9-E9 -> 0
A10: 4 | B10: Счета купли и продажи, чистые | C10: =+C11-C12 -> 119576827 | D10: =+'Investment Securities'!C28 -> 119576827 | E10: =+'Investment Securities'!D28 -> 0 | L10: =+C10-D10-E10 -> 0
A11: 4.1. | B11: Ценные бумаги для купли продажи, брутто | C11: =+D11+E11 -> 119576827 | D11: =+'Investment Securities'!C26 -> 119576827 | E11: =+'Investment Securities'!D26 -> 0 | L11: =+C11-D11-E11 -> 0
A12: 4.2. | B12: Минус: Резерв возможных убытков | C12: =+D12+E12 -> 0 | D12: =+'Investment Securities'!C27 -> 0 | E12: =+'Investment Securities'!D27 -> 0 | L12: =+C12-D12-E12 -> 0
A13: 5 | B13: Драгоценные металлы, монеты, камни, чистые | C13: =+C14-C15 -> 175 | D13: =+'Investment Securities'!C39 -> 175 | E13: =+'Investment Securities'!D39 -> 0 | L13: =+C13-D13-E13 -> 0
A14: 5.1. | B14: Драгоценные металлы, монеты, камни, брутто | C14: =+D14+E14 -> 175 | D14: =+'Investment Securities'!C37 -> 175 | E14: =+'Investment Securities'!D37 -> 0 | L14: =+C14-D14-E14 -> 0
A15: 5.2. | B15: Минус: Резерв возможных убытков | C15: =+D15+E15 -> 0 | D15: =+'Investment Securities'!C38 -> 0 | E15: =+'Investment Securities'!D38 -> 0 | L15: =+C15-D15-E15 -> 0
A16: 6 | B16: Инвестиции, чистые | C16: =+'Investment Securities'!B15 -> 6670220 | D16: =+'Investment Securities'!C15 -> 6670220 | E16: =+'Investment Securities'!D15 -> 0 | L16: =+C16-D16-E16 -> 0
A17: 6.1. | B17: Инвестиции, брутто | C17: =+D17+E17 -> 6941924 | D17: =+'Investment Securities'!C13 -> 6941924 | E17: =+'Investment Securities'!D13 -> 0 | L17: =+C17-D17-E17 -> 0
A18: 6.2. | B18: Минус: Резерв возможных убытков | C18: =+D18+E18 -> 271704 | D18: =+'Investment Securities'!C14 -> 271704 | E18: =+'Investment Securities'!D14 -> 0 | L18: =+C18-D18-E18 -> 0
A19: 7 | B19: Ценные бумаги купленные по соглашению c обратным выкупом, чистые | C19: =+'Bank Assets Analysis'!S28 -> 0 | D19: =+'Bank Assets Analysis'!T28 -> 0 | E19: =+'Bank Assets Analysis'!U28 -> 0 | L19: =+C19-D19-E19 -> 0
A20: 7.1. | B20: Ценные бумаги, купленные по соглашению с обратным выкупом, брутто | C20: =+D20+E20 -> 0 | D20: 0 | E20: 0 | L20: =+C20-D20-E20 -> 0
A21: 7.2. | B21: Резерв возможных убытков | C21: =+D21+E21 -> 0 | D21: 0 | E21: 0 | L21: =+C21-D21-E21 -> 0
A22: 8 | B22: Кредиты и лизинговые операции, чистые | C22: =+'Bank Assets Analysis'!S24+'Bank Assets Analysis'!S25+'Bank Assets Analysis'!S26 -> 4652448980 | D22: =+'Bank Assets Analysis'!T24+'Bank Assets Analysis'!T25+'Bank Assets Analysis'!T26 -> 3092790433 | E22: =+'Bank Assets Analysis'!U24+'Bank Assets Analysis'!U25+'Bank Assets Analysis'!U26 -> 1559658547 | L22: =+C22-D22-E22 -> 0
A23: 8.1. | B23: Кредиты и лизинговые операции, брутто | C23: =+D23+E23 -> 4772374677 | D23: 3194072351 | E23: 1578302326 | L23: =+C23-D23-E23 -> 0
A24: 8.2. | B24: Минус: Резерв возможных убытков | C24: =+'Charge-offs and Recoveries'!C25 -> 119925697 | D24: 101281918 | E24: 18643779 | F24: =+'Asset Classification'!Y50 -> 119925697 | L24: =+C24-D24-E24 -> 0
A25: 9 | B25: Купленные векселя, чистые | C25: =+'Bank Assets Analysis'!S20 -> 0 | D25: =+'Bank Assets Analysis'!T20 -> 0 | E25: =+'Bank Assets Analysis'!U20 -> 0 | L25: =+C25-D25-E25 -> 0
A26: 9.1. | B26: Купленные векселя, брутто | C26: =+D26+E26 -> 0 | D26: 0 | E26: 0 | L26: =+C26-D26-E26 -> 0
A27: 9.2. | B27: Минус: Резерв возможных убытков | C27: =+D27+E27 -> 0 | D27: 0 | E27: 0 | L27: =+C27-D27-E27 -> 0
A28: 10 | B28: Обязательства клиентов по финансовым инструментам, чистые | C28: =+D28+E28 -> 0 | D28: =+'Bank Assets Analysis'!T21+'Bank Assets Analysis'!T22 -> 0 | E28: =+'Bank Assets Analysis'!U21+'Bank Assets Analysis'!U22 -> 0 | L28: =+C28-D28-E28 -> 0
A29: 10.1. | B29: Обязательства клиентов по финансовым инструментам, брутто | C29: =+D29+E29 -> 0 | D29: 0 | E29: 0 | L29: =+C29-D29-E29 -> 0
A30: 10.2. | B30: Минус: Резерв возможных убытков | C30: =+D30+E30 -> 0 | L30: =+C30-D30-E30 -> 0
A31: 11 | B31: Основные средства, чистые | C31: =+'Bank Assets Analysis'!S31 -> 149099836 | D31: =+'Bank Assets Analysis'!T31 -> 149099836 | E31: =+'Bank Assets Analysis'!U31 -> 0 | L31: =+C31-D31-E31 -> 0
A32: 12 | B32: Начисленные процентные и беспроцентные доходы всего, чистые | C32: =+C33+C34-C35 -> 35355520 | D32: =+D33+D34-D35 -> 27389456 | E32: =+E33+E34-E35 -> 7966064 | L32: =+C32-D32-E32 -> 0
A33: 12.1. | B33: Начисленные проценты к получению, брутто | C33: =+'Bank Assets Analysis'!S36 -> 35343476 | D33: =+'Bank Assets Analysis'!T36 -> 27377412 | E33: =+'Bank Assets Analysis'!U36 -> 7966064 | L33: =+C33-D33-E33 -> 0
A34: 12.2. | B34: Начисленные беспроцентные доходы к получению, брутто | C34: =+D34+E34 -> 12044 | D34: 12044 | E34: 0 | L34: =+C34-D34-E34 -> 0
A35: 12.2.1. | B35: Минус: Резерв возможных убытков | C35: =+D35+E35 -> 0 | D35: 0 | E35: 0 | L35: =+C35-D35-E35 -> 0
A36: 13 | B36: Другое собственное имущество банка, чистые | C36: =+'Bank Assets Analysis'!S32 -> 0 | D36: =+'Bank Assets Analysis'!T32 -> 0 | E36: =+'Bank Assets Analysis'!U32 -> 0 | L36: =+C36-D36-E36 -> 0
A37: 13.1. | B37: Другие собственное имущество, взысканное по кредитам и лизингу, брутто | C37: =+D37+E37 -> 0 | L37: =+C37-D37-E37 -> 0
A38: 13.2. | B38: Другое собственное имущество банка, брутто | C38: =+D38+E38 -> 0 | L38: =+C38-D38-E38 -> 0
A39: 13.3. | B39: Минус:Накопленный износ и резервы на возможные убытки | C39: =+D39+E39 -> 0 | D39: 0 | L39: =+C39-D39-E39 -> 0
A40: 14 | B40: Другие активы, чистые | C40: =+C41-C42+C43 -> 159793158 | D40: =+D41-D42+D43 -> 87417391 | E40: =+E41-E42+E43 -> 72375767 | L40: =+C40-D40-E40 -> 0
...

Sheet Asset quality
A1: ИНФОРМАЦИЯ О КАЧЕСТВЕ АКТИВОВ, ОЦЕНИВАЕМЫХ В ЦЕЛЯХ СОЗДАНИЯ РЕЗЕРВА НА ВОЗМОЖНЫЕ ПОТЕРИ | R1: Таблица-2
B3: =+Balance!B3 -> АКБ "Микрокредитбанк" | P3: =+Balance!C3 -> 43829 | S3: =+Balance!E3 -> тыс. сум
A4: № | B4: Состав активов* | C4: Остаток | D4: Категория качества | I4: Просроченная задолженность (брутто) | N4: Резерв на возможные потери
I5: итого | J5: до 30 дней | K5: от 31 до 90 дней | L5: от 91 до 180 дней | M5: свыше 180 дней | N5: фактически сформированный
N6: итого | O6: по категориям качества
D7: I | E7: II | F7: III | G7: IV | H7: V | O7: I | P7: II | Q7: III | R7: IV | S7: V
A8: А | B8: Б | C8: В | D8: Г | E8: Д | F8: Е | G8: Ж | H8: З | I8: И | J8: К | K8: Л | L8: М | M8: Н | N8: О | O8: П | P8: Р | Q8: С | R8: Т | S8: У
B9: ВСЕГО АКТИВОВ | C9: =SUM(C10:C60) -> 5890272405 | D9: =SUM(D10:D60) -> 5245683982 | E9: =SUM(E10:E60) -> 741964846 | F9: =SUM(F10:F60) -> 9977568 | G9: =SUM(G10:G60) -> 3530535 | H9: =SUM(H10:H60) -> 14101127 | I9: =SUM(I10:I60) -> 35636673 | J9: =SUM(J10:J60) -> 9434194 | ... S9: =SUM(S10:S60) -> 10600586
A10: 1 | B10: Кассовая наличность и другие платежные документы | C10: =SUM(D10:H10)-N10+O10 -> 173211577 | D10: 173211577 | I10: =SUM(J10:M10) -> 0 | N10: =SUM(O10:S10) -> 0 | T10: 10100
A11: 2 | B11: К получению из ЦБРУ | C11: =SUM(D11:H11)-N11+O11 -> 140577780 | D11: 140577780 | I11: =SUM(J11:M11) -> 0 | N11: =SUM(O11:S11) -> 0 | T11: 10300
A12: 3 | B12: К получению из других банков | C12: =SUM(D12:H12)-N12+O12 -> 453538332 | D12: 453538332 | I12: =SUM(J12:M12) -> 0 | N12: =SUM(O12:S12) -> 0 | T12: 10500
A13: 4 | B13: Ценные бумаги для купли и продажи | C13: =SUM(D13:H13)-N13+O13 -> 119576827 | D13: 119576827 | I13: =SUM(J13:M13) -> 0 | N13: =SUM(O13:S13) -> 0 | T13: 10700
A14: 5 | B14: Инвестиции в ценные бумаги, имеющиеся в наличии для продажи | C14: =SUM(D14:H14)-N14+O14 -> 0 | I14: =SUM(J14:M14) -> 0 | N14: =SUM(O14:S14) -> 0 | T14: 10800
A15: 6 | B15: Драгоценные металлы, камни и монеты для купли и продажи | C15: =SUM(D15:H15)-N15+O15 -> 175 | D15: 175 | I15: =SUM(J15:M15) -> 0 | N15: =SUM(O15:S15) -> 0 | T15: 10900
A16: 7 | B16: Купленные дебиторские задолженности - Факторинг | C16: =SUM(D16:H16)-N16+O16 -> 6311020 | D16: 6311020 | E16: 0 | F16: 0 | G16: 0 | H16: 0 | I16: =SUM(J16:M16) -> 279848 | J16: 0 | K16: 279848 | L16: 0 | M16: 0 | N16: =SUM(O16:S16) -> 0 | O16: 0 | P16: 0 | Q16: 0 | R16: 0 | S16: 0 | T16: 11100
A17: 8 | B17: Купленные векселя | C17: =SUM(D17:H17)-N17+O17 -> 0 | I17: =SUM(J17:M17) -> 0 | N17: =SUM(O17:S17) -> 0 | T17: 11300
A18: 9 | B18: Обязательства клиентов по траттам под аккредитив и/или трастовые документы | C18: =SUM(D18:H18)-N18+O18 -> 0 | I18: =SUM(J18:M18) -> 0 | N18: =SUM(O18:S18) -> 0 | T18: 11500
A19: 10 | B19: Обязательства лиентов по непогашенным акцептам банка | C19: =SUM(D19:H19)-N19+O19 -> 0 | I19: =SUM(J19:M19) -> 0 | N19: =SUM(O19:S19) -> 0 | T19: 11700
A20: 11 | B20: Купленные по сделкам РЕПО ценные бумаги | C20: =SUM(D20:H20)-N20+O20 -> 0 | I20: =SUM(J20:M20) -> 0 | N20: =SUM(O20:S20) -> 0 | T20: 11800
A21: 12 | B21: Краткосрочные кредиты, предоставленные ЦБРУ | C21: =SUM(D21:H21)-N21+O21 -> 0 | I21: =SUM(J21:M21) -> 0 | N21: =SUM(O21:S21) -> 0 | T21: 11900
A22: 13 | B22: Краткосрочные кредиты, предоставленные другим банкам | C22: =SUM(D22:H22)-N22+O22 -> 0 | I22: =SUM(J22:M22) -> 0 | N22: =SUM(O22:S22) -> 0 | T22: 12100
A23: 14 | B23: Краткосрочные кредиты, предоставленные правительству | C23: =SUM(D23:H23)-N23+O23 -> 0 | I23: =SUM(J23:M23) -> 0 | N23: =SUM(O23:S23) -> 0 | T23: 12300
A24: 15 | B24: Краткосрочные кредиты, предоставленные бюджетным организациям | C24: =SUM(D24:H24)-N24+O24 -> 0 | I24: =SUM(J24:M24) -> 0 | N24: =SUM(O24:S24) -> 0 | T24: 12400
A25: 16 | B25: Краткосрочные кредиты, предоставленные физическим лицам | C25: =SUM(D25:H25)-N25+O25 -> 81825947 | D25: 80249045 | E25: 1523268 | F25: 109598 | G25: 24327 | H25: 0 | I25: =SUM(J25:M25) -> 290686 | J25: 173539 | K25: 91690 | L25: 20347 | M25: 5110 | N25: =SUM(O25:S25) -> 80291 | O25: 0 | P25: 74471 | Q25: 5820 | R25: 0 | S25: 0 | T25: 12500
A26: 17 | B26: Краткосрочные кредиты, предоставленные индивидуальным предпринимателям | C26: =SUM(D26:H26)-N26+O26 -> 22125242 | D26: 20767187 | E26: 1132465 | F26: 384651 | G26: 4892 | H26: 0 | I26: =SUM(J26:M26) -> 370054 | J26: 113112 | K26: 160846 | L26: 93854 | M26: 2242 | N26: =SUM(O26:S26) -> 163953 | O26: 0 | P26: 62226 | Q26: 101727 | R26: 0 | S26: 0 | T26: 12600
A27: 18 | B27: Краткосрочные кредиты, предоставленные государственным предприятиям, организациям и учреждениям | C27: =SUM(D27:H27)-N27+O27 -> 4087343 | D27: 2328615 | E27: 2153839 | F27: 0 | G27: 5040 | H27: 0 | I27: =SUM(J27:M27) -> 0 | J27: 0 | K27: 0 | L27: 0 | M27: 0 | N27: =SUM(O27:S27) -> 400151 | O27: 0 | P27: 400151 | Q27: 0 | R27: 0 | S27: 0 | T27: 12700
A28: 19 | B28: Краткосрочные кредиты, предоставленные при содействии Государственного фонда поддержки развития предпринимательской деятельности | C28: =SUM(D28:H28)-N28+O28 -> 0 | I28: =SUM(J28:M28) -> 0 | N28: =SUM(O28:S28) -> 0 | T28: 12800
A29: 20 | B29: Краткосрочные кредиты, предоставленные предприятиям с участием иностранного капитала | C29: =SUM(D29:H29)-N29+O29 -> 28920287 | D29: 13333 | E29: 30315361 | F29: 0 | G29: 46684 | H29: 0 | I29: =SUM(J29:M29) -> 237330 | J29: 237330 | K29: 0 | L29: 0 | M29: 0 | N29: =SUM(O29:S29) -> 1455091 | O29: 0 | P29: 1455091 | Q29: 0 | R29: 0 | S29: 0 | T29: 12900
A30: 21 | B30: Краткосрочные кредиты, предоставленные негосударственным некоммерческим организациям | C30: =SUM(D30:H30)-N30+O30 -> 492867 | D30: 207415 | E30: 285452 | F30: 0 | G30: 0 | H30: 0 | I30: =SUM(J30:M30) -> 0 | J30: 0 | K30: 0 | L30: 0 | M30: 0 | N30: =SUM(O30:S30) -> 0 | O30: 0 | P30: 0 | Q30: 0 | R30: 0 | S30: 0 | T30: 13000
A31: 22 | B31: Краткосрочные кредиты, предоставленные частным предприятиям, хозяйственным товариществам и обществам | C31: =SUM(D31:H31)-N31+O31 -> 135706442 | D31: 118406210 | E31: 17108437 | F31: 0 | G31: 1547179 | H31: 0 | I31: =SUM(J31:M31) -> 1253341 | J31: 735495 | K31: 395749 | L31: 122097 | M31: 0 | N31: =SUM(O31:S31) -> 1355384 | O31: 0 | P31: 1355384 | Q31: 0 | R31: 0 | S31: 0 | T31: 13100
A32: 23 | B32: Краткосрочные кредиты, предоставленные небанковским финансовым институтам | C32: =SUM(D32:H32)-N32+O32 -> 10228 | D32: 10228 | I32: =SUM(J32:M32) -> 0 | N32: =SUM(O32:S32) -> 0 | T32: 13200
A33: 24 | B33: Краткосрочные кредиты, предоставленные для производства сельскохозяйственной продукции, закупаемой для государственных нужд | C33: =SUM(D33:H33)-N33+O33 -> 0 | I33: =SUM(J33:M33) -> 0 | N33: =SUM(O33:S33) -> 0 | T33: 13300
A34: 25 | B34: Долгосрочные кредиты, предоставленные для производства сельскохозяйственной продукции, закупаемой для государственных нужд | C34: =SUM(D34:H34)-N34+O34 -> 0 | I34: =SUM(J34:M34) -> 0 | N34: =SUM(O34:S34) -> 0 | T34: 14300
A35: 26 | B35: Долгосрочные кредиты, предоставленные при содействии Государственного фонда поддержки развития предпринимательской деятельности | C35: =SUM(D35:H35)-N35+O35 -> 2362100 | D35: 1996666 | E35: 413333 | F35: 0 | G35: 0 | H35: 0 | I35: =SUM(J35:M35) -> 21252 | J35: 16667 | K35: 4585 | L35: 0 | M35: 0 | N35: =SUM(O35:S35) -> 47899 | O35: 0 | P35: 47899 | Q35: 0 | R35: 0 | S35: 0 | T35: 14400
A36: 27 | B36: Долгосрочные кредиты, предоставленные другим банкам | C36: =SUM(D36:H36)-N36+O36 -> 0 | I36: =SUM(J36:M36) -> 0 | N36: =SUM(O36:S36) -> 0 | T36: 14500
A37: 28 | B37: Долгосрочные кредиты, предоставленные правительству | C37: =SUM(D37:H37)-N37+O37 -> 0 | I37: =SUM(J37:M37) -> 0 | N37: =SUM(O37:S37) -> 0 | T37: 14700
A38: 29 | B38: Долгосрочные кредиты, предоставленные бюджетным организациям | C38: =SUM(D38:H38)-N38+O38 -> 0 | I38: =SUM(J38:M38) -> 0 | N38: =SUM(O38:S38) -> 0 | T38: 14800
A39: 30 | B39: Долгосрочные кредиты, предоставленные физическим лицам | C39: =SUM(D39:H39)-N39+O39 -> 1374647662 | D39: 1360175424 | E39: 12442314 | F39: 4226282 | G39: 183301 | H39: 0 | I39: =SUM(J39:M39) -> 1921749 | J39: 660432 | K39: 580241 | L39: 401746 | M39: 279330 | N39: =SUM(O39:S39) -> 2379659 | P39: 1598673 | Q39: 627772 | R39: 153214 | S39: 0 | T39: 14900
A40: 31 | B40: Долгосрочные кредиты, предоставленные индивидуальным предпринимателям | C40: =SUM(D40:H40)-N40+O40 -> 127710513 | D40: 125749499 | E40: 2052405 | F40: 221484 | G40: 197968 | H40: 0 | I40: =SUM(J40:M40) -> 837202 | J40: 308051 | K40: 265750 | L40: 156359 | M40: 107042 | N40: =SUM(O40:S40) -> 510843 | O40: 0 | P40: 339850 | Q40: 62970 | R40: 108023 | S40: 0 | T40: 15000
A41: 32 | B41: Долгосрочные кредиты, предоставленные государственным предприятиям, организациям и учреждениям | C41: =SUM(D41:H41)-N41+O41 -> 90333574 | D41: 18109752 | E41: 76644921 | F41: 3534667 | G41: 579444 | H41: 0 | I41: =SUM(J41:M41) -> 243778 | J41: 40203 | K41: 65177 | L41: 95341 | M41: 43057 | N41: =SUM(O41:S41) -> 8535210 | O41: 0 | P41: 7024810 | Q41: 1210400 | R41: 300000 | S41: 0 | T41: 15100
...

Sheet Income 
B1: ОТЧЕТ О ФИНАНСОВЫХ РЕЗУЛЬТАТАХ | D1: Таблица-3
B3: =Balance!B3 -> АКБ "Микрокредитбанк" | C3: =+'Asset quality'!P3 -> 43829 | E3: в тыс. сум
A4: № | B4: Категории | C4: Итого | D4: в национальной валюте | E4: в иностранной валюте (в экв. в сумах)
A5: 1. | B5: 1. ПРОЦЕНТНЫЕ ДОХОДЫ
A6: a. | B6: Процентные доходы по счетам в ЦБРУ | C6: =+D6+E6 -> 81594 | D6: 81594
A7: б. | B7: Процентные доходы по счетам в других банках | C7: =+D7+E7 -> 12489567 | D7: 12489567
A8: в. | B8: Процентные доходы по купленным векселям | C8: =+D8+E8 -> 0 | D8: 0
A9: г. | B9: Процентные доходы по инвестициям | C9: =+D9+E9 -> 792723 | D9: 792723
A10: д. | B10: Процентные доходы по счетам купли-продажи ценных бумаг | C10: =+D10+E10 -> 9722584 | D10: 9722584
A11: е. | B11: Процентные доходы по обязательствам клиентов | C11: =+D11+E11 -> 0 | D11: 0
A12: ж. | B12: Процентные доходы по обяз-вам клиентов по непогашенным акцептам этого банка | C12: =+D12+E12 -> 0 | D12: 0
A13: з. | B13: Процент, Дисконт (Скидки) и взносы по кредитным и лизинговым операциям | C13: =+D13+E13 -> 509814535 | D13: 509814535
A14: и. | B14: Процентные доходы по соглашениям о покупке ценных бумаг с обратным выкупом | C14: =+D14+E14 -> 0 | D14: 0
A15: к. | B15: Другие процентные доходы | C15: =+D15+E15 -> 188576046 | D15: 188576046
A16: л. | B16: Итого процентных доходов | C16: =SUM(C6:C15) -> 721477049 | D16: =SUM(D6:D15) -> 721477049 | E16: =SUM(E6:E15) -> 0 | G16: =+'Analysis of Interest'!C42 -> 721477049
A18: 2. | B18: ПРОЦЕНТНЫЕ РАСХОДЫ
A19: а. | B19: Процентные расходы по депозитам до востребования | C19: =+D19+E19 -> 1370451 | D19: 1370451
A20: б. | B20: Процентные расходы по срочным депозитам | C20: =+D20+E20 -> 125270257 | D20: 125270257
A21: в. | B21: Процентные расходы по счетам к оплате в ЦБРУ | C21: =+D21+E21 -> 0
A22: г. | B22: Процентные расходы по счетам к оплате в другие банки | C22: =+D22+E22 -> 52377347 | D22: 52377347
A23: д. | B23: Итого процентных расходов по депозитам | C23: =SUM(C19:C22) -> 179018055 | D23: =SUM(D19:D22) -> 179018055 | E23: =SUM(E19:E22) -> 0
A24: е. | B24: Процентные расходы по кредитам к оплате | C24: =+D24+E24 -> 36723237 | D24: 36723237
A25: ж. | B25: Процентные расходы по соглашениям о продаже ц/б с последующим выкупом | C25: =+D25+E25 -> 0
A26: з. | B26: Другие процентные расходы | C26: =+D26+E26 -> 187555672 | D26: 187555672
A27: и. | B27: Итого процентных расходов по займам | C27: =SUM(C24:C26) -> 224278909 | D27: =SUM(D24:D26) -> 224278909 | E27: =SUM(E24:E26) -> 0
A28: л. | B28: Итого процентных расходов | C28: =C27+C23 -> 403296964 | D28: =D27+D23 -> 403296964 | E28: =E27+E23 -> 0 | G28: =+'Analysis of Interest'!C72 -> 403296964
A30: 3. | B30: ЧИСТЫЕ ПРОЦЕНТНЫЕ ДОХОДЫ ДО ОЦЕНКИ ВОЗМОЖНЫХ УБЫТКОВ ПО АКТИВАМ | C30: =C16-C28 -> 318180085 | D30: =D16-D28 -> 318180085 | E30: =E16-E28 -> 0
A31: а. | B31: Минус: Оценка возможных убытков по кредитам и лизингу | C31: =+D31+E31 -> 139622948 | D31: 139622948
A32: б. | B32: Минус: Оценка возможных убытков по в ценным бумагам | C32: =+D32+E32 -> 0 | D32: 0
A33: в. | B33: Минус: Оценка возможных убытков по инвестициям | C33: =+D33+E33 -> 271704 | D33: 271704
A34: г. | B34: Минус: Оценка возможных убытков по другим активам | C34: =+D34+E34 -> 4727042 | D34: 4727042
A35: д. | B35: Чистые процентные доходы после оценки возможных убытков по кредитам и лизингу | C35: =C30-C31-C32-C33-C34 -> 173558391 | D35: =D30-D31-D32-D33-D34 -> 173558391 | E35: =E30-E31-E32-E33-E34 -> 0
A37: 4. | B37: БЕСПРОЦЕНТНЫЕ ДОХОДЫ
A38: а. | B38: Доходы от комиссий и платы за услуги | C38: =+D38+E38 -> 77887497 | D38: 77887497
A39: б. | B39: Прибыль в иностранной валюте | C39: =+D39+E39 -> 40924909 | D39: 40924909
A40: в. | B40: Прибыль от коммерческих операций | C40: =+D40+E40 -> 21699 | D40: 21699
A41: г. | B41: Прибыль и дивиденды от инвестиций | C41: =+D41+E41 -> 23246 | D41: 23246
A42: д. | B42: Другие беспроцентные доходы | C42: =+D42+E42 -> 97933027 | D42: 97933027
A43: е. | B43: Итого беспроцентных доходов | C43: =SUM(C38:C42) -> 216790378 | D43: =SUM(D38:D42) -> 216790378 | E43: =SUM(E38:E42) -> 0
A45: 5. | B45: БЕСПРОЦЕНТНЫЕ РАСХОДЫ
...

Sheet Analysis of Interest
B1: АНАЛИЗ ПРОЦЕНТНЫХ ДОХОДОВ И РАСХОДОВ | C1: Таблица-4
B3: =Balance!B3 -> АКБ "Микрокредитбанк" | C3: =+Balance!C3 -> 43829
A4: № | B4: Категория | C4: в тыс. сум
A5: 1 . | B5: ПРОЦЕНТНЫЕ ДОХОДЫ ПО КРЕДИТНЫМ И ЛИЗИНГОВЫМ ОПЕРАЦИЯМ
A6: a. | B6: Кредиты и лизинговые операции ЦБРУ
A7: б. | B7: Кредиты и лизинговые операции другим банкам | C7: 31454
A8: в. | B8: Кредиты и лизинговые операции Правительству
A9: г. | B9: Кредиты и лизинговые операции физическим лицам | C9: 254188323
A10: д. | B10: Кредиты и лизинговые операции государственным предприятиям | C10: 8243902
A11: е. | B11: Кредиты и лизинговые операции совместным и иностранным предприятиям | C11: 26345385
A12: ж. | B12: Кредиты и лизинговые операции частным товариществам и корпорациям | C12: 218415663
A13: з. | B13: Другие кредиты и лизинговые операции | C13: 2589808
A14: и. | B14: ИТОГО ПРОЦЕНТНЫХ ДОХОДОВ ПО КРЕДИТНЫМ И ЛИЗИНГОВЫМ ОПЕРАЦИЯМ | C14: =SUM(C6:C13) -> 509814535
A16: 2. | B16: ПРОЦЕНТНЫЕ ДОХОДЫ ПО КОРРЕСПОНДЕНТСКИМ СЧЕТАМ
A17: a. | B17: К получению из ЦБРУ | C17: 81594
A18: б. | B18: К получению из других банков | C18: 12489567
B19: ИТОГО ПРОЦЕНТНЫХ ДОХОДОВ ПО КОРРЕСПОНДЕНТСКИМ СЧЕТАМ | C19: =SUM(C17:C18) -> 12571161
A21: 3. | B21: ПРОЦЕНТНЫЕ ДОХОДЫ ПО СЧЕТАМ КУПЛИ-ПРОДАЖИ Ц/Б
A22: a. | B22: Государственные казначейские ценные бумаги | C22: 9722584
A23: б. | B23: Облигации и ценные бумаги ЦБРУ | C23: 0
A24: в. | B24: Ценные бумаги государственных корпораций | C24: 0
A25: г. | B25: Еврооблигации | C25: 0
A26: д. | B26: Частные ценные бумаги | C26: 0
A27: е. | B27: Другие ценные бумаги | C27: 0
A28: ж. | B28: ИТОГО ПРОЦЕНТНЫХ ДОХОДОВ ПО СЧЕТАМ КУПЛИ-ПРОДАЖИ Ц/Б | C28: =SUM(C22:C27) -> 9722584
A30: 4. | B30: ПРОЦЕНТНЫЕ ДОХОДЫ ПО ИНВЕСТИЦИЯМ
A31: a. | B31: Государственные облигации | C31: 0
A32: б. | B32: Облигации и ценные бумаги ЦБРУ | C32: 0
A33: в. | B33: Частные облигации | C33: 0
A34: г. | B34: Еврооблигации | C34: 0
A35: д. | B35: Другие ценные бумаги | C35: 792723
A36: е. | B36: ИТОГО ПРОЦЕНТНЫХ ДОХОДОВ ПО ИНВЕСТИЦИЯМ | C36: =SUM(C31:C35) -> 792723
A38: 5. | B38: ДРУГИЕ ПРОЦЕНТНЫЕ ДОХОДЫ
A39: a. | B39: Процентные доходы по соглашениям о покупке ц/б c обратным выкупом | C39: 0
A40: б. | B40: Другие процентные доходы | C40: 188576046
A42: 6. | B42: ИТОГО ПРОЦЕНТНЫХ ДОХОДОВ | C42: =C14+C19+C28+C36+C39+C40 -> 721477049
A44: 7. | B44: ПРОЦЕНТНЫЕ РАСХОДЫ ПО ДЕПОЗИТАМ
A45: A. | B45: Депозиты до востребования
A46: a. | B46: Правительство | C46: 1364336
A47: б. | B47: Физические лица | C47: 6115
...

Sheet Bank Capital Calc
A1: РАСЧЕТ РЕГУЛЯТИВНОГО КАПИТАЛА БАНКА | C1: Таблица-5
B3: =Balance!B3 -> АКБ "Микрокредитбанк" | C3: =+Balance!C3 -> 43829
A4: № | B4: Характеристики | C4: Итого капитала
A5: I. | B5: КАПИТАЛ УРОВНЯ 1
A6: 1 | B6: ОСНОВНОЙ КАПИТАЛ УРОВНЯ 1
A7: 1.1. | B7: Обыкновенные Акции, чистые | C7: =+C8+C9 -> 1641584276
A8: a | B8: Полностью оплаченные обыкновенные акции | C8: 1641584276
A9: б | B9: Минус: Обратно Выкупленные обыкновенные акции
A10: 1.2. | B10: Добавленный капитал - Обыкновенные | C10: 0
A11: 1.3. | B11: Нераспределенная прибыль (убыток), в том числе капитальные резервы | C11: =+C12+C13-C14-C15 -> -28839355
A12: а | B12: Капитальные резервы | C12: 49010340
A13: б | B13: Нераспределенная прибыль | C13: 0
A14: в | B14: Убыток за предыдущие периоды | C14: 77849695
A15: г | B15: Убыток за текущий год | C15: 0
A16: 1.4. | B16: Интерес меньшинства в консолидированных дочерних компаниях (согласно МБС) | C16: 0
A17: 1.5. | B17: Резерв на девальвацию | C17: 0
B18: Итого основного капитала уровня I до вычетов | C18: =+C7+C10+C11+C16+C17 -> 1612744921
A19: 1.6. | B19: Вычеты из суммы основного капитала уровня I | C19: =C21+C22 -> 6941923
A20: а | B20: Нематериальные активы | C20: 1679916
A21: б | B21: Все инвестиции в капитал неконсолидированных хозяйствующих субъектов, в том числе в долговые обязательства, которые образуют капитал хозяйствующих субъектов | C21: 6941923
A22: в | B22: Инвестиции в капитал других банков | C22: 0
A23: I | B23: ВСЕГО СКОРРЕКТИРОВАННЫЙ ОСНОВНОЙ КАПИТАЛ УРОВНЯ I | C23: =+C18-C19 -> 1605802998
A24: 2 | B24: ДОБАВЛЕННЫЙ КАПИТАЛ УРОВНЯ 1
A25: 2.1. | B25: Некумулятивные бессрочные привилегированные акции | C25: =+C26+C27 -> 144180
A26: а | B26: Полностью оплаченные привилегированные акции | C26: 144180
A27: б | B27: Минус: Обратно Выкупленные привилегированные акции | C27: 0
A28: 2.2. | B28: Добавленный капитал - Привилегированные | C28: 0
A29: 2.3. | B29: Интерес меньшинства в консолидированных дочерних компаниях | C29: 0
A30: 2.4. | B30: Доля участия дочерних предприятий (выпущенные дочерними предприятиями и находящиеся во владении третьих лиц инструменты, приравненные к капиталу) | C30: 0
A31: II | B31: ВСЕГО ДОБАВЛЕННЫЙ КАПИТАЛ УРОВНЯ I | C31: =+C25+C28+C29+C30 -> 144180
A32: III | B32: ВСЕГО СКОРРЕКТИРОВАННЫЙ КАПИТАЛ УРОВНЯ I | C32: =+C23+C31 -> 1605947178
B33: КАПИТАЛ УРОВНЯ II
A34: 3.1. | B34: Прибыль за текущий год | C34: 6838822
A35: 3.2. | B35: Резервы, создаваемые на стандартные кредиты (активы), в размере не более 1.25% от общей суммы активов, взвешенных с учетом риска | C35: =IF(Balance!C71<(C43*1.25%),Balance!C71,(C43*1.25%)) -> 0
A36: 3.3. | B36: Излишки оценочной стоимости прироста над первоначальной стоимостью | C36: 2419898
A37: 3.4. | B37: Другие инструменты капитала (не более 1/3 части капитала 1 уровня после вычетов) | C37: 0
A38: 3.5. | B38: Субординированный долг | C38: 0
A39: 3.6. | B39: Вычеты превышения Капитала Уровня II над Капиталом Уровня I | C39: =IF(C40<(C32/3),0,(C40-C32/3)*-1) -> 0
B40: Итого капитала Уровня II | C40: =SUM(C34:C38) -> 9258720
A41: IV | B41: СКОРРЕКТИРОВАННЫЙ КАПИТАЛ УРОВНЯ II | C41: =+C39+C40 -> 9258720
...

Sheet Bank Capital Calc (2)
A1: РАСЧЕТ РЕГУЛЯТИВНОГО КАПИТАЛА БАНКА | C1: Таблица-5
B3: =Balance!B3 -> АКБ "Микрокредитбанк" | C3: =+Balance!C3 -> 43829
A4: № | B4: Характеристики | C4: Итого капитала
A5: I. | B5: КАПИТАЛ УРОВНЯ 1
A6: 1 | B6: ОСНОВНОЙ КАПИТАЛ УРОВНЯ 1
A7: 1.1. | B7: Обыкновенные Акции, чистые | C7: Формула
A8: a | B8: Полностью оплаченные обыкновенные акции
A9: б | B9: Минус: Обратно Выкупленные обыкновенные акции
A10: 1.2. | B10: Добавленный капитал - Обыкновенные | C10: 0
A11: 1.3. | B11: Нераспределенная прибыль (убыток), в том числе капитальные резервы | C11: Формула
A12: а | B12: Капитальные резервы
A13: б | B13: Нераспределенная прибыль
A14: в | B14: Убыток за предыдущие периоды
A15: г | B15: Убыток за текущий год
A16: 1.4. | B16: Интерес меньшинства в консолидированных дочерних компаниях (согласно МБС)
A17: 1.5. | B17: Резерв на девальвацию
B18: Итого основного капитала уровня I до вычетов | C18: Формула
A19: 1.6. | B19: Вычеты из суммы основного капитала уровня I | C19: Формула
A20: а | B20: Нематериальные активы
A21: б | B21: Все инвестиции в капитал неконсолидированных хозяйствующих субъектов, в том числе в долговые обязательства, которые образуют капитал хозяйствующих субъектов
A22: в | B22: Инвестиции в капитал других банков
A23: I | B23: ВСЕГО СКОРРЕКТИРОВАННЫЙ ОСНОВНОЙ КАПИТАЛ УРОВНЯ I | C23: Формула
A24: 2 | B24: ДОБАВЛЕННЫЙ КАПИТАЛ УРОВНЯ 1
A25: 2.1. | B25: Некумулятивные бессрочные привилегированные акции | C25: =+C26+C27 -> 0
A26: а | B26: Полностью оплаченные привилегированные акции
A27: б | B27: Минус: Обратно Выкупленные привилегированные акции
A28: 2.2. | B28: Добавленный капитал - Привилегированные | C28: 0
A29: 2.3. | B29: Интерес меньшинства в консолидированных дочерних компаниях | C29: 0
A30: 2.4. | B30: Доля участия дочерних предприятий (выпущенные дочерними предприятиями и находящиеся во владении третьих лиц инструменты, приравненные к капиталу) | C30: 0
A31: II | B31: ВСЕГО ДОБАВЛЕННЫЙ КАПИТАЛ УРОВНЯ I | C31: =+C25+C28+C29+C30 -> 0
A32: III | B32: ВСЕГО СКОРРЕКТИРОВАННЫЙ КАПИТАЛ УРОВНЯ I | C32: Формула
B33: КАПИТАЛ УРОВНЯ II
A34: 3.1. | B34: Прибыль за текущий год
A35: 3.2. | B35: Резервы, создаваемые на стандартные кредиты (активы), в размере не более 1.25% от общей суммы активов, взвешенных с учетом риска | C35: =IF(Balance!C71<(C43*1.25%),Balance!C71,(C43*1.25%)) -> 0
A36: 3.3. | B36: Излишки оценочной стоимости прироста над первоначальной стоимостью
A37: 3.4. | B37: Другие инструменты капитала (не более 1/3 части капитала 1 уровня после вычетов)
A38: 3.5. | B38: Субординированный долг
A39: 3.6. | B39: Вычеты превышения Капитала Уровня II над Капиталом Уровня I | C39: Формула
B40: Итого капитала Уровня II | C40: =SUM(C34:C38) -> 0
A41: IV | B41: СКОРРЕКТИРОВАННЫЙ КАПИТАЛ УРОВНЯ II | C41: Формула
...

Sheet Calculation of Risk Weighted As
A1: РАСЧЕТ АКТИВОВ ВЗВЕШЕННЫХ С УЧЕТОМ РИСКА | I1: Таблица-6
B3: =Balance!B3 -> АКБ "Микрокредитбанк" | G3: =+Balance!C3 -> 43829 | J3: =+Balance!E3 -> тыс. сум
A4: № | B4: Характеристики | C4: 0 | D4: 0.2 | E4: 0.3 | F4: 0.5 | G4: 1 | H4: 1.5 | I4: 2 | J4: 3
C5: Риск | D5: Риск | E5: Риск | F5: Риск | G5: Риск | H5: Риск | I5: Риск | J5: Риск
B6: (A) | C6: (Б) | D6: (В) | E6: (Г) | F6: (Д) | G6: (Е) | H6: (Ж) | I6: (З) | J6: (И)
B7: Балансовые Активы
A8: 1. | B8: Касса (наличность и монеты) и Драгоценные металлы | C8: 159937550
A9: 2. | B9: Денежная наличность и другие платежные документы в пути | D9: 13274201
A10: 3. | B10: Корреспондентские и резервные счета в ЦБРУ | C10: =+Balance!D6 -> 119493320 | D10: =+Balance!E6 -> 21084460
A11: 4. | B11: Корр. счета, кредиты и другие требования к банкам | G11: 309855 | H11: 453228477
A12: 5. | B12: Рыночные ценные бумаги, чистые
A13: а) | B13: Ценные бумаги, выпущенные Правительством Республики Узбекистан и ЦБРУ | C13: 109174000
A14: б) | B14: Ценные бумаги, выпущенные правительствами и центральными банками стран, с низким уровня риска, а также другие требования к центральным банкам и правительствам этих стран
A15: в) | B15: Ценные бумаги, выпущенные банками стран, с низким уровнем риска
A16: г) | B16: Другие ценные бумаги | G16: 10402827
A17: 6. | B17: Кредиты и другие активы или их части, обеспеченные наличными деньгами, хранящимися на отдельном блокированном депозитном счете.
A18: 7. | B18: Все требования банка, деноминированные в местную валюту стран не входящих в группу стран с низким уровнем риска, к Центральным банкам и центральным правительствам этих стран
A19: 8. | B19: Активы, обеспеченные ценными бумагами выпущенными банками зарегистрированными в странах с низким уровнем риска
A20: 9. | B20: Требования банка к международным финансовым организациям, а также активы, гарантированные этими организациями
A21: 10. | B21: Активы или их части, обеспеченные залогом в виде ценных бумаг, оцененных по текущей рыночной стоимости и эмитированных международными финансовыми институтами
A22: 11. | B22: Кредиты и лизинги, чистые
A23: а) | B23: прямые требования к Правительству и Центральному банку Республики Узбекистан | C23: 0 | D23: 0
A24: б) | B24: Гарантированные кредиты международными кредитными организациями | C24: 0
A25: в) | B25: Активы или их части, обеспеченные ценными бумагами, которые оцененные по текущей рыночной стоимости и выпущенными или гарантированными Правительством Республики Узбекистан, Центральным банком Республики Узбекистан или Правительствами стран с низким уровнем риска. | D25: 0
A26: г) | B26: Кредиты на недвижимость обеспеченные приобретаемым или строящимся домом (квартирой) | F26: 66552554
A27: д) | B27: Реструктуризированные кредиты и кредиты в статусе "ненаращивания" | G27: 129827087
A28: е) | B28: Кредиты, по которым банк не имеет приоритетного права на залог | G28: 0
A29: ж) | B29: Пересмотренные или пролонгированные кредиты и лизинги более одного раза | H29: 0
A30: з) | B30: Кредиты, выданные населению для приобретения автомобилей | G30: 2152157 | H30: 91403487 | I30: 56603467 | J30: 16031679
A31: и) | B31: Кредиты, выданные юридическим лицам на покупку автомобиля | J31: 65055525
A32: к) | B32: Микрозаймы (все нецелевые кредиты) | G32: 4227795 | H32: 43981306 | I32: 32208912 | J32: 138898
A33: л) | B33: Все другие кредиты (кроме лизинга) | G33: 4105828351
A34: 12. | B34: Кредиты и лизинги в судебном разбирательстве, чистые | H34: 8560497 | K34: =+'Bank Assets Analysis'!S26 -> 8560497
A35: 13. | B35: Просроченные кредиты и лизинги, чистые | H35: 25522506 | K35: =+'Bank Assets Analysis'!C25+'Bank Assets Analysis'!C24 -> 25522506
A36: 14. | B36: Финансовый лизинг, чистые | G36: 4354759
A37: 15. | B37: Основные средств и другое собственное имущество банка
A38: а | B38: Основные средства, используемые в банковской деятельности (минус амортизация) | G38: 147419920
A39: б | B39: Другое банковское собственное имущество | G39: 0
A40: в | B40: Недвижимое имущество принятое на баланс банка в целях полного или частичного погащения задолженности | H40: 0
A41: г | B41: Недвижимое имущество банка, которым банк не пользуется более двух лет | H41: 0
...

Sheet Calculation of Risk Weighte нац
A1: РАСЧЕТ АКТИВОВ ВЗВЕШЕННЫХ С УЧЕТОМ РИСКА В НАЦИОНАЛЬНОЙ ВАЛЮТЕ | I1: Таблица-6.1
B3: =Balance!B3 -> АКБ "Микрокредитбанк" | G3: =+Balance!C3 -> 43829 | J3: =+Balance!E3 -> тыс. сум
A4: № | B4: Характеристики | C4: 0 | D4: 0.2 | E4: 0.3 | F4: 0.5 | G4: 1 | H4: 1.5 | I4: 2 | J4: 3
C5: Риск | D5: Риск | E5: Риск | F5: Риск | G5: Риск | H5: Риск | I5: Риск | J5: Риск
B6: (A) | C6: (Б) | D6: (В) | E6: (Г) | F6: (Д) | G6: (Е) | H6: (Ж) | I6: (З) | J6: (И)
B7: Балансовые Активы
A8: 1. | B8: Касса (наличность и монеты) и Драгоценные металлы | C8: 60859707
A9: 2. | B9: Денежная наличность и другие платежные документы в пути | D9: 8945599
A10: 3. | B10: Корреспондентские и резервные счета в ЦБРУ | C10: =+Balance!D6 -> 119493320
A11: 4. | B11: Корр. счета, кредиты и другие требования к банкам | H11: 266889175
A12: 5. | B12: Рыночные ценные бумаги, чистые
A13: а) | B13: Ценные бумаги, выпущенные Правительством Республики Узбекистан и ЦБРУ | C13: 109174000
A14: б) | B14: Ценные бумаги, выпущенные правительствами и центральными банками стран, с низким уровня риска, а также другие требования к центральным банкам и правительствам этих стран
A15: в) | B15: Ценные бумаги, выпущенные банками стран, с низким уровнем риска
A16: г) | B16: Другие ценные бумаги | G16: 10402827
A17: 6. | B17: Кредиты и другие активы или их части, обеспеченные наличными деньгами, хранящимися на отдельном блокированном депозитном счете.
A18: 7. | B18: Все требования банка, деноминированные в местную валюту стран не входящих в группу стран с низким уровнем риска, к Центральным банкам и центральным правительствам этих стран
A19: 8. | B19: Активы, обеспеченные ценными бумагами выпущенными банками зарегистрированными в странах с низким уровнем риска
A20: 9. | B20: Требования банка к международным финансовым организациям, а также активы, гарантированные этими организациями
A21: 10. | B21: Активы или их части, обеспеченные залогом в виде ценных бумаг, оцененных по текущей рыночной стоимости и эмитированных международными финансовыми институтами
A22: 11. | B22: Кредиты и лизинги, чистые
A23: а) | B23: прямые требования к Правительству и Центральному банку Республики Узбекистан | C23: 0 | D23: 0
A24: б) | B24: Гарантированные кредиты международными кредитными организациями | C24: 0
A25: в) | B25: Активы или их части, обеспеченные ценными бумагами, которые оцененные по текущей рыночной стоимости и выпущенными или гарантированными Правительством Республики Узбекистан, Центральным банком Республики Узбекистан или Правительствами стран с низким уровнем риска. | D25: 0
A26: г) | B26: Кредиты на недвижимость обеспеченные приобретаемым или строящимся домом (квартирой) | F26: 66552554
A27: д) | B27: Реструктуризированные кредиты и кредиты в статусе "ненаращивания" | G27: 129827087
A28: е) | B28: Кредиты, по которым банк не имеет приоритетного права на залог
A29: ж) | B29: Пересмотренные или пролонгированные кредиты и лизинги более одного раза | H29: 0
A30: з) | B30: Кредиты, выданные населению для приобретения автомобилей | G30: 2152157 | H30: 91403487 | I30: 56603467 | J30: 16031679
A31: и) | B31: Кредиты, выданные юридическим лицам на покупку автомобиля | J31: 65055525
A32: к) | B32: Микрозаймы (все нецелевые кредиты) | G32: 4227795 | H32: 43981306 | I32: 32208912 | J32: 138898
A33: л) | B33: Все другие кредиты (кроме лизинга) | G33: 2550363615
A34: 12. | B34: Кредиты и лизинги в судебном разбирательстве, чистые | H34: 8560497 | K34: =+'Bank Assets Analysis (нац)'!K25 -> 8560497
A35: 13. | B35: Просроченные кредиты и лизинги, чистые | H35: 23225577 | K35: =+'Bank Assets Analysis (нац)'!C23+'Bank Assets Analysis (нац)'!C24 -> 23225577
A36: 14. | B36: Финансовый лизинг, чистые | G36: 2107924
A37: 15. | B37: Основные средств и другое собственное имущество банка
A38: а | B38: Основные средства, используемые в банковской деятельности (минус амортизация) | G38: 147419920
A39: б | B39: Другое банковское собственное имущество | G39: 0
A40: в | B40: Недвижимое имущество принятое на баланс банка в целях полного или частичного погащения задолженности | H40: 0
A41: г | B41: Недвижимое имущество банка, которым банк не пользуется более двух лет | H41: 0
...

Sheet Calculation of Risk Weighte ин
A1: РАСЧЕТ АКТИВОВ ВЗВЕШЕННЫХ С УЧЕТОМ РИСКА В ИНОСТРАННОЙ ВАЛЮТЕ | I1: Таблица-6.2
B3: =Balance!B3 -> АКБ "Микрокредитбанк" | G3: =+Balance!C3 -> 43829 | J3: =+Balance!E3 -> тыс. сум
A4: № | B4: Характеристики | C4: 0 | D4: 0.2 | E4: 0.3 | F4: 0.5 | G4: 1 | H4: 1.5 | I4: 2 | J4: 3
C5: Риск | D5: Риск | E5: Риск | F5: Риск | G5: Риск | H5: Риск | I5: Риск | J5: Риск
B6: (A) | C6: (Б) | D6: (В) | E6: (Г) | F6: (Д) | G6: (Е) | H6: (Ж) | I6: (З) | J6: (И)
B7: Балансовые Активы
A8: 1. | B8: Касса (наличность и монеты) и Драгоценные металлы | C8: =+'Calculation of Risk Weighted As'!C8-'Calculation of Risk Weighte нац'!C8 -> 99077843
A9: 2. | B9: Денежная наличность и другие платежные документы в пути | D9: =+'Calculation of Risk Weighted As'!D9-'Calculation of Risk Weighte нац'!D9 -> 4328602
A10: 3. | B10: Корреспондентские и резервные счета в ЦБРУ | D10: =+Balance!E6 -> 21084460
A11: 4. | B11: Корр. счета, кредиты и другие требования к банкам | D11: =+'Calculation of Risk Weighted As'!D11-'Calculation of Risk Weighte нац'!D11 -> 0 | E11: =+'Calculation of Risk Weighted As'!E11-'Calculation of Risk Weighte нац'!E11 -> 0 | F11: =+'Calculation of Risk Weighted As'!F11-'Calculation of Risk Weighte нац'!F11 -> 0 | G11: =+'Calculation of Risk Weighted As'!G11-'Calculation of Risk Weighte нац'!G11 -> 309855 | H11: =+'Calculation of Risk Weighted As'!H11-'Calculation of Risk Weighte нац'!H11 -> 186339302
A12: 5. | B12: Рыночные ценные бумаги, чистые
A13: а) | B13: Ценные бумаги, выпущенные Правительством Республики Узбекистан и ЦБРУ | C13: =+'Calculation of Risk Weighted As'!C13-'Calculation of Risk Weighte нац'!C13 -> 0
A14: б) | B14: Ценные бумаги, выпущенные правительствами и центральными банками стран, с низким уровня риска, а также другие требования к центральным банкам и правительствам этих стран | C14: =+'Calculation of Risk Weighted As'!C14-'Calculation of Risk Weighte нац'!C14 -> 0
A15: в) | B15: Ценные бумаги, выпущенные банками стран, с низким уровнем риска | D15: =+'Calculation of Risk Weighted As'!D15-'Calculation of Risk Weighte нац'!D15 -> 0 | F15: =+'Calculation of Risk Weighted As'!F15-'Calculation of Risk Weighte нац'!F15 -> 0
A16: г) | B16: Другие ценные бумаги | C16: =+'Calculation of Risk Weighted As'!C16-'Calculation of Risk Weighte нац'!C16 -> 0 | G16: =+'Calculation of Risk Weighted As'!G16-'Calculation of Risk Weighte нац'!G16 -> 0
A17: 6. | B17: Кредиты и другие активы или их части, обеспеченные наличными деньгами, хранящимися на отдельном блокированном депозитном счете. | C17: =+'Calculation of Risk Weighted As'!C17-'Calculation of Risk Weighte нац'!C17 -> 0
A18: 7. | B18: Все требования банка, деноминированные в местную валюту стран не входящих в группу стран с низким уровнем риска, к Центральным банкам и центральным правительствам этих стран | D18: =+'Calculation of Risk Weighted As'!D18-'Calculation of Risk Weighte нац'!D18 -> 0
A19: 8. | B19: Активы, обеспеченные ценными бумагами выпущенными банками зарегистрированными в странах с низким уровнем риска | D19: =+'Calculation of Risk Weighted As'!D19-'Calculation of Risk Weighte нац'!D19 -> 0 | F19: =+'Calculation of Risk Weighted As'!F19-'Calculation of Risk Weighte нац'!F19 -> 0
A20: 9. | B20: Требования банка к международным финансовым организациям, а также активы, гарантированные этими организациями | C20: =+'Calculation of Risk Weighted As'!C20-'Calculation of Risk Weighte нац'!C20 -> 0
A21: 10. | B21: Активы или их части, обеспеченные залогом в виде ценных бумаг, оцененных по текущей рыночной стоимости и эмитированных международными финансовыми институтами | D21: =+'Calculation of Risk Weighted As'!D21-'Calculation of Risk Weighte нац'!D21 -> 0
A22: 11. | B22: Кредиты и лизинги, чистые
A23: а) | B23: прямые требования к Правительству и Центральному банку Республики Узбекистан | C23: =+'Calculation of Risk Weighted As'!C23-'Calculation of Risk Weighte нац'!C23 -> 0 | D23: =+'Calculation of Risk Weighted As'!D23-'Calculation of Risk Weighte нац'!D23 -> 0
A24: б) | B24: Гарантированные кредиты международными кредитными организациями | C24: =+'Calculation of Risk Weighted As'!C24-'Calculation of Risk Weighte нац'!C24 -> 0
A25: в) | B25: Активы или их части, обеспеченные ценными бумагами, которые оцененные по текущей рыночной стоимости и выпущенными или гарантированными Правительством Республики Узбекистан, Центральным банком Республики Узбекистан или Правительствами стран с низким уровнем риска. | D25: =+'Calculation of Risk Weighted As'!D25-'Calculation of Risk Weighte нац'!D25 -> 0
A26: г) | B26: Кредиты на недвижимость обеспеченные приобретаемым или строящимся домом (квартирой) | F26: =+'Calculation of Risk Weighted As'!F26-'Calculation of Risk Weighte нац'!F26 -> 0
A27: д) | B27: Реструктуризированные кредиты и кредиты в статусе "ненаращивания" | G27: =+'Calculation of Risk Weighted As'!G27-'Calculation of Risk Weighte нац'!G27 -> 0
A28: е) | B28: Кредиты, по которым банк не имеет приоритетного права на залог | G28: =+'Calculation of Risk Weighted As'!G28-'Calculation of Risk Weighte нац'!G28 -> 0
A29: ж) | B29: Пересмотренные или пролонгированные кредиты и лизинги более одного раза | H29: =+'Calculation of Risk Weighted As'!H29-'Calculation of Risk Weighte нац'!H29 -> 0
A30: з) | B30: Кредиты, выданные населению для приобретения автомобилей | G30: =+'Calculation of Risk Weighted As'!G30-'Calculation of Risk Weighte нац'!G30 -> 0 | H30: =+'Calculation of Risk Weighted As'!H30-'Calculation of Risk Weighte нац'!H30 -> 0 | I30: =+'Calculation of Risk Weighted As'!I30-'Calculation of Risk Weighte нац'!I30 -> 0 | J30: =+'Calculation of Risk Weighted As'!J30-'Calculation of Risk Weighte нац'!J30 -> 0
A31: и) | B31: Кредиты, выданные юридическим лицам на покупку автомобиля | J31: =+'Calculation of Risk Weighted As'!J31-'Calculation of Risk Weighte нац'!J31 -> 0
A32: к) | B32: Микрозаймы (все нецелевые кредиты) | G32: =+'Calculation of Risk Weighted As'!G32-'Calculation of Risk Weighte нац'!G32 -> 0 | H32: =+'Calculation of Risk Weighted As'!H32-'Calculation of Risk Weighte нац'!H32 -> 0 | I32: =+'Calculation of Risk Weighted As'!I32-'Calculation of Risk Weighte нац'!I32 -> 0 | J32: =+'Calculation of Risk Weighted As'!J32-'Calculation of Risk Weighte нац'!J32 -> 0
A33: л) | B33: Все другие кредиты (кроме лизинга) | G33: =+'Calculation of Risk Weighted As'!G33-'Calculation of Risk Weighte нац'!G33 -> 1555464736
A34: 12. | B34: Кредиты и лизинги в судебном разбирательстве, чистые | H34: =+'Calculation of Risk Weighted As'!H34-'Calculation of Risk Weighte нац'!H34 -> 0 | K34: =+'Bank Assets Analysis'!U26 -> 0
A35: 13. | B35: Просроченные кредиты и лизинги, чистые | H35: =+'Calculation of Risk Weighted As'!H35-'Calculation of Risk Weighte нац'!H35 -> 2296929 | K35: =+'Bank Assets Analysis'!D24+'Bank Assets Analysis'!D25 -> 2296929
A36: 14. | B36: Финансовый лизинг, чистые | G36: =+'Calculation of Risk Weighted As'!G36-'Calculation of Risk Weighte нац'!G36 -> 2246835
A37: 15. | B37: Основные средств и другое собственное имущество банка
A38: а | B38: Основные средства, используемые в банковской деятельности (минус амортизация) | G38: =+'Calculation of Risk Weighted As'!G38-'Calculation of Risk Weighte нац'!G38 -> 0
A39: б | B39: Другое банковское собственное имущество | G39: =+'Calculation of Risk Weighted As'!G39-'Calculation of Risk Weighte нац'!G39 -> 0
A40: в | B40: Недвижимое имущество принятое на баланс банка в целях полного или частичного погащения задолженности | H40: =+'Calculation of Risk Weighted As'!H40-'Calculation of Risk Weighte нац'!H40 -> 0
A41: г | B41: Недвижимое имущество банка, которым банк не пользуется более двух лет | H41: =+'Calculation of Risk Weighted As'!H41-'Calculation of Risk Weighte нац'!H41 -> 0
...

Sheet Calculation of Risk
A1: РАСЧЕТ ПО ОПЕРАЦИОННЫМ И РЫНОЧНЫМ РИСКАМ | I1: Достаточность капитала - К1 | J1: Коэффициент достаточности капитала I уровня K2 | K1: Доля основного капитала I уровня к регулятивному капиталу | L1: Коэффициент нормы покрытия ликвидности | M1: Норма чистого стабильного финансирования (НЧСФ)
C2: Таблица-6А | H2: 2015 | I2: 10 | J2: 7.5 | K2: 6 | L2: 80
B3: =+Balance!B3 -> АКБ "Микрокредитбанк" | C3: =+Balance!C3 -> 43829 | H3: 2016 | I3: 11.5 | J3: 8.5 | K3: 7 | L3: 80
A4: № | B4: Наименование показателя | C4: в тыс. сум | H4: 2017 | I4: 12.5 | J4: 9.5 | K4: 7.5 | L4: 90
A5: 1. | B5: =+"Валовый доход банка за "&(E$9-3)&" год" -> Валовый доход банка за 2016 год | C5: =+C6+C8-C7-C9 -> 151405362 | H5: 2018 | I5: 12.5 | J5: 9.5 | K5: 7.5 | L5: 100 | M5: 100
A6: а. | B6: процентные доходы | C6: 204104096 | H6: 2019 | I6: 13 | J6: 10 | K6: 8 | L6: 100 | M6: 100
A7: б. | B7: процентные расходы | C7: 126300057 | E7: =RIGHT(Balance!B2,4) -> 2019
A8: в. | B8: беспроцентные доходы | C8: 94287758 | G8: =VLOOKUP(E9,H2:M6,2,0) -> 13
A9: г. | B9: беспроцентные расходы | C9: 20686435 | E9: =IF(E7>H6,H6,E7) -> 2019
A10: 2. | B10: =+"Валовый доход банка за "&(E$9-2)&" год" -> Валовый доход банка за 2017 год | C10: =+C11+C13-C12-C14 -> 215368224 | G10: =VLOOKUP($E$9,$H$2:$M$6,4,0) -> 8
A11: а. | B11: процентные доходы | C11: 222901466 | G11: =VLOOKUP($E$9,$H$2:$J$6,3,0) -> 10
A12: б. | B12: процентные расходы | C12: 146139315 | G12: =VLOOKUP($E$9,H2:M6,5,0) -> 100
A13: в. | B13: беспроцентные доходы | C13: 164180943 | G13: =VLOOKUP(E9,H2:M6,6,0) -> 100
A14: г. | B14: беспроцентные расходы | C14: 25574870
A15: 3. | B15: =+"Валовый доход банка за "&(E$9-1)&" год" -> Валовый доход банка за 2018 год | C15: =+C16+C18-C17-C19 -> 334481566
A16: а. | B16: процентные доходы | C16: 446360945
A17: б. | B17: процентные расходы | C17: 228795878
A18: в. | B18: беспроцентные доходы | C18: 158773389
A19: г. | B19: беспроцентные расходы | C19: 41856890
A20: 4. | B20: Средний валовый доход банка (за последние три года) | C20: =(C5+C10+C15)/3 -> 2.3375172e+08
A21: 5. | B21: Сумма операционных рисков | C21: =+(100/C28)*C20*15% -> 269713520
A23: 6. | B23: Счета валютной позиции (счет 17101 (сумавая часть)) | C23: 70081723
A24: 7. | B24: Продажа на условиях Своп и Форвард (счет 92709, 92732) | C24: 0
A25: 8. | B25: Покупка на условиях Своп и Форвард (счет 92716, 92736) | C25: 0
A26: 9. | B26: Открытая валютная позиция, всего | C26: =ABS(C23+(C24-C25)) -> 70081723 | D26: =+C26*0.1 -> 7008172.3
A27: 10. | B27: Сумма рыночных рисков | C27: =+(100/C28)*(C26*10%) -> 53909018
A28: 11. | B28: Действуюший минимальное требование к достаточности капитала | C28: =VLOOKUP($E$9,$H$2:$I$6,2,0) -> 13
A30: Подпись Председателя правления:
A32: Подпись Главного Бухгалтера:

Sheet Changes in Equity
B1: ИЗМЕНЕНИЯ В СОБСТВЕННОМ КАПИТАЛЕ | C1: Таблица-7
B3: =Balance!B3 -> АКБ "Микрокредитбанк" | C3: =+Balance!C3 -> 43829
A4: № | B4: Категория | C4: в тыс. сум
A5: 1. | B5: Итого собственного капитала первоначально определенного за прошлый год | C5: 665013964
A6: 2. | B6: Исправления в собственном капитале не показанные в отчете за прошлый год, чистые
A7: 3. | B7: Исправленный баланс на конец прошлого календарного года (сумма строк 1 и 2) | C7: =SUM(C5:C6) -> 665013964
A8: 4. | B8: Чистый прибыль (убыток) по состоянию на дату от начала года | C8: =+'Income '!C76 -> 6838822 | I8: =+Balance!C75 -> 6838822
A9: 5. | B9: Продажа, Обмен, Приобретение или выкуп акций, за текущий год (чистая выручка) | C9: 947543197
A10: 6. | B10: Изменения в оценочной стоимости прироста над первонач. стоимостью, за текущий год (чистые) | C10: 5377552
A11: 7. | B11: МИНУС: Денежные дивиденды объявленные по привилегированным акциям | C11: 0
A12: 8. | B12: МИНУС: Денежные дивиденды объявленные по обыкновенным акциям | C12: 0
A13: 9. | B13: Другие статьи влияющие на собственный капитал за текущий год (чистые) | C13: 331940
A14: 10. | B14: Итого собственного капитала на конец текущего периода (сумма строк с 3 по 10) | C14: =C7+SUM(C8:C10)-SUM(C11:C12)+C13 -> 1625105475 | D14: =+Balance!C76 -> 1625105475 | I14: =+Balance!C76 -> 1625105475
B16: Подпись Председателя правления:
B18: Подпись Главного Бухгалтера:

Sheet Loans Receivable
A1: КРЕДИТЫ И ЛИЗИНГИ К ПОЛУЧЕНИЮ ПО ОТРАСЛЯМ ЭКОНОМИКИ, ТИПАМ КЛИЕНТОВ И ПО ТИПУ ОБЕСПЕЧЕНИЯ | W1: Таблица-8
B3: =Balance!B3 -> АКБ "Микрокредитбанк" | T3: =+Balance!C3 -> 43829 | X3: =+Balance!E3 -> тыс. сум
A4: № | B4: Отрасль экономики | C4: Сумма кредита | D4: в национальной валюте | F4: в иностранной валюте (в экв. в сумах) | H4: из них | J4: из них
D5: Сумма | E5: средне-взвешенные процентные ставки | F5: Сумма | G5: средне-взвешенные процентные ставки | H5: Начисляемые кредиты | I5: Кредиты переведённые в статус ненаращивания процентов | J5: Депозиты | K5: Гарантированные Правительством Республики Узбекистан | L5: из них | M5: Транспортные средства | N5: Инвентарь | O5: Недвижимость | P5: из них | R5: Оборудование | S5: Векселя (облигации) | T5: Акции | U5: Гарантия третьей стороны | V5: Поручительства третьей стороны | W5: Страховой полис | X5: Необеспеченные | Y5: Другое обеспечение
L6: Гарантированные Правительством Республики Узбекистан в иностранной валюте (экв.сум) | P6: жилая недвижимость | Q6: коммерческая недвижимость
A7: Код | B7: (А) | C7: (Б) | D7: (Б1) | E7: (Б2) | F7: (Б3) | G7: (Б4) | H7: (В) | I7: (Г) | J7: (Д) | K7: (Е) | L7: (Е1) | M7: (Ж) | N7: (З) | O7: (И) | P7: (И1) | Q7: (И2) | R7: (К) | S7: (Л) | T7: (М) | U7: (Н) | V7: (О) | W7: (П) | X7: (Р) | Y7: (С)
B8: Промышленность
A9: 10 | B9: Физические лица | C9: =SUM(J9:Y9)-L9-P9-Q9 -> 100645482 | D9: 100645482 | E9: 0.077441266 | H9: 100645482 | J9: 0 | K9: 0 | L9: 0 | M9: 91464 | N9: 0 | O9: =+P9+Q9 -> 58001 | P9: 0 | Q9: 58001 | R9: 0 | S9: 0 | T9: 0 | U9: 0 | V9: 18608939 | W9: 81887078 | X9: 0 | Y9: 0
A10: =A9+10 -> 20 | B10: Государственные предприятия | C10: =SUM(J10:Y10)-L10-P10-Q10 -> 1060521 | D10: 1060521 | E10: 0.18592445 | H10: 1060521 | I10: 0 | J10: 0 | K10: 0 | L10: 0 | M10: 10000 | N10: 0 | O10: =+P10+Q10 -> 1050521 | P10: 0 | Q10: 1050521 | R10: 0 | S10: 0 | T10: 0 | U10: 0 | V10: 0 | W10: 0 | X10: 0 | Y10: 0
A11: =A10+10 -> 30 | B11: Совместные и иностранные предприятия | C11: =SUM(J11:Y11)-L11-P11-Q11 -> 81185906 | D11: 46882998 | E11: 0.21228218 | F11: 34302908 | G11: 0.11938421 | H11: 81185906 | I11: 0 | J11: 0 | K11: 0 | L11: 0 | M11: 443463 | N11: 0 | O11: =+P11+Q11 -> 50898620 | P11: 0 | Q11: 50898620 | R11: 0 | S11: 0 | T11: 0 | U11: 0 | V11: 0 | W11: 29606493 | X11: 0 | Y11: 237330
A12: =A11+10 -> 40 | B12: Частные товарищества и корпорации | C12: =SUM(J12:Y12)-L12-P12-Q12 -> 1044810736 | D12: 301931344 | E12: 0.12828057 | F12: 742879392 | G12: 0.10057936 | H12: 1039069231 | I12: 5741505 | J12: 0 | K12: 0 | L12: 0 | M12: 72364171 | N12: 0 | O12: =+P12+Q12 -> 667211899 | P12: 0 | Q12: 667211899 | R12: 5921945 | S12: 0 | T12: 0 | U12: 0 | V12: 34968502 | W12: 263835401 | X12: 0 | Y12: 508818
A13: =A12+10 -> 50 | B13: Правительство | C13: =SUM(J13:Y13)-L13-P13-Q13 -> 0 | O13: =+P13+Q13 -> 0
A14: =A13+10 -> 60 | B14: Прочие | C14: =SUM(J14:Y14)-L14-P14-Q14 -> 0 | O14: =+P14+Q14 -> 0
A15: =A14+10 -> 70 | B15: Итого по промышленности | C15: =SUM(J15:Y15)-L15-P15-Q15 -> 1227702645 | D15: =SUM(D9:D14) -> 450520345 | E15: =IFERROR(((D9*E9)/D15)+((D10*E10)/D15)+((D11*E11)/D15)+((D12*E12)/D15)+((D13*E13)/D15)+((D14*E14)/D15),0) -> 0.1258004 | F15: =SUM(F9:F14) -> 777182300 | G15: =IFERROR(((F9*G9)/F15)+((F10*G10)/F15)+((F11*G11)/F15)+((F12*G12)/F15)+((F13*G13)/F15)+((F14*G14)/F15),0) -> 0.10140936 | H15: =SUM(H9:H14) -> 1221961140 | I15: =SUM(I9:I14) -> 5741505 | J15: =SUM(J9:J14) -> 0 | K15: =SUM(K9:K14) -> 0 | L15: =SUM(L9:L14) -> 0 | M15: =SUM(M9:M14) -> 72909098 | N15: =SUM(N9:N14) -> 0 | O15: =SUM(O9:O14) -> 719219041 | ... Y15: =SUM(Y9:Y14) -> 746148
B16: Сельское хозяйство
A17: =A15+10 -> 80 | B17: Физические лица | C17: =SUM(J17:Y17)-L17-P17-Q17 -> 584765854 | D17: 584765854 | E17: 0.077723513 | H17: 584765854 | J17: 0 | K17: 0 | L17: 0 | M17: 1760837 | N17: 0 | O17: =+P17+Q17 -> 421378 | P17: 0 | Q17: 421378 | R17: 0 | S17: 0 | T17: 0 | U17: 0 | V17: 139930320 | W17: 442576277 | X17: 0 | Y17: 77042
A18: =A17+10 -> 90 | B18: Государственные предприятия | C18: =SUM(J18:Y18)-L18-P18-Q18 -> 71121613 | D18: 71121613 | E18: 0.066449218 | H18: 71121613 | J18: 0 | K18: 0 | L18: 0 | M18: 0 | N18: 0 | O18: =+P18+Q18 -> 2330000 | P18: 0 | Q18: 2330000 | R18: 0 | S18: 0 | T18: 0 | U18: 0 | V18: 68791613 | W18: 0 | X18: 0 | Y18: 0
A19: =A18+10 -> 100 | B19: Совместные и иностранные предприятия | C19: =SUM(J19:Y19)-L19-P19-Q19 -> 26499946 | D19: 26499946 | E19: 0.21056598 | H19: 26499946 | J19: 0 | K19: 0 | L19: 0 | M19: 0 | N19: 0 | O19: =+P19+Q19 -> 26499946 | P19: 0 | Q19: 26499946 | R19: 0 | S19: 0 | T19: 0 | U19: 0 | V19: 0 | W19: 0 | X19: 0 | Y19: 0
A20: =A19+10 -> 110 | B20: Частные товарищества и корпорации | C20: =SUM(J20:Y20)-L20-P20-Q20 -> 310022747 | D20: 215495555 | E20: 0.16510115 | F20: 94527192 | G20: 0.08852717 | H20: 301272419 | I20: 8750328 | J20: 0 | K20: 0 | L20: 0 | M20: 25591161 | N20: 0 | O20: =+P20+Q20 -> 209382778 | P20: 0 | Q20: 209382778 | R20: 4193068 | S20: 0 | T20: 0 | U20: 0 | V20: 10879376 | W20: 59976364 | X20: 0 | Y20: 0
A21: =A20+10 -> 120 | B21: Фермерское хозяйство | C21: =SUM(J21:Y21)-L21-P21-Q21 -> 60729562 | D21: 42011514 | E21: 0.17209202 | F21: 18718048 | G21: 0.054379883 | H21: 59150502 | I21: 1579060 | J21: 322400 | K21: 0 | L21: 0 | M21: 15614270 | N21: 0 | O21: =+P21+Q21 -> 43105805 | P21: 0 | Q21: 43105805 | R21: 40735 | S21: 0 | T21: 0 | U21: 0 | V21: 1053454 | W21: 592898 | X21: 0 | Y21: 0
A22: =A21+10 -> 130 | B22: Правительство | C22: =SUM(J22:Y22)-L22-P22-Q22 -> 0 | O22: =+P22+Q22 -> 0
A23: =A22+10 -> 140 | B23: Прочие | C23: =SUM(J23:Y23)-L23-P23-Q23 -> 0 | O23: =+P23+Q23 -> 0
A24: =A23+10 -> 150 | B24: Итого по сельскому хозяйству | C24: =SUM(J24:Y24)-L24-P24-Q24 -> 1053139722 | D24: =SUM(D17:D23) -> 939894482 | E24: =IFERROR(((D17*E17)/D24)+((D18*E18)/D24)+((D19*E19)/D24)+((D20*E20)/D24)+((D21*E21)/D24)+((D22*E22)/D24)+((D23*E23)/D24),0) -> 0.10486755 | F24: =SUM(F17:F23) -> 113245240 | G24: =IFERROR(((F17*G17)/F24)+((F18*G18)/F24)+((F19*G19)/F24)+((F20*G20)/F24)+((F21*G21)/F24)+((F22*G22)/F24)+((F23*G23)/F24),0) -> 0.082883043 | H24: =SUM(H17:H23) -> 1042810334 | I24: =SUM(I17:I23) -> 10329388 | J24: =SUM(J17:J23) -> 322400 | K24: =SUM(K17:K23) -> 0 | L24: =SUM(L17:L23) -> 0 | M24: =SUM(M17:M23) -> 42966268 | N24: =SUM(N17:N23) -> 0 | O24: =SUM(O17:O23) -> 281739907 | ... Y24: =SUM(Y17:Y23) -> 77042
B25: Транспорт и коммуникации
A26: =A24+10 -> 160 | B26: Физические лица | C26: =SUM(J26:Y26)-L26-P26-Q26 -> 169885131 | D26: 169885131 | E26: 0.27803906 | H26: 169885131 | J26: 0 | K26: 0 | L26: 0 | M26: 166183224 | N26: 0 | O26: =+P26+Q26 -> 0 | P26: 0 | Q26: 0 | R26: 0 | S26: 0 | T26: 0 | U26: 0 | V26: 7952 | W26: 3693955 | X26: 0 | Y26: 0
A27: =A26+10 -> 170 | B27: Государственные предприятия | C27: =SUM(J27:Y27)-L27-P27-Q27 -> 928138 | D27: 928138 | E27: 0.23207596 | H27: 928138 | J27: 0 | K27: 0 | L27: 0 | M27: 661138 | N27: 0 | O27: =+P27+Q27 -> 267000 | P27: 0 | Q27: 267000 | R27: 0 | S27: 0 | T27: 0 | U27: 0 | V27: 0 | W27: 0 | X27: 0 | Y27: 0
A28: =A27+10 -> 180 | B28: Совместные и иностранные предприятия | C28: =SUM(J28:Y28)-L28-P28-Q28 -> 47581850 | F28: 47581850 | G28: 0.09 | H28: 47581850 | J28: 0 | K28: 0 | L28: 0 | M28: 0 | N28: 0 | O28: =+P28+Q28 -> 47581850 | P28: 0 | Q28: 47581850 | R28: 0 | S28: 0 | T28: 0 | U28: 0 | V28: 0 | W28: 0 | X28: 0 | Y28: 0
A29: =A28+10 -> 190 | B29: Частные товарищества и корпорации | C29: =SUM(J29:Y29)-L29-P29-Q29 -> 237862697 | D29: 161511964 | E29: 0.23810183 | F29: 76350733 | G29: 0.11976033 | H29: 228920662 | I29: 8942035 | J29: 1625936 | K29: 0 | L29: 0 | M29: 116093385 | N29: 0 | O29: =+P29+Q29 -> 116013320 | P29: 0 | Q29: 116013320 | R29: 0 | S29: 0 | T29: 0 | U29: 0 | V29: 1372122 | W29: 2757934 | X29: 0 | Y29: 0
A30: =A29+10 -> 200 | B30: Правительство | C30: =SUM(J30:Y30)-L30-P30-Q30 -> 0 | O30: =+P30+Q30 -> 0
A31: =A30+10 -> 210 | B31: Прочие | C31: =SUM(J31:Y31)-L31-P31-Q31 -> 0 | O31: =+P31+Q31 -> 0
A32: =A31+10 -> 220 | B32: Итого по транспорту и коммуникациям | C32: =SUM(J32:Y32)-L32-P32-Q32 -> 456257816 | D32: =SUM(D26:D31) -> 332325233 | E32: =IFERROR(((D26*E26)/D32)+((D27*E27)/D32)+((D28*E28)/D32)+((D29*E29)/D32)+((D30*E30)/D32)+((D31*E31)/D32),0) -> 0.25850097 | F32: =SUM(F26:F31) -> 123932583 | G32: =IFERROR(((F26*G26)/F32)+((F27*G27)/F32)+((F28*G28)/F32)+((F29*G29)/F32)+((F30*G30)/F32)+((F31*G31)/F32),0) -> 0.10833434 | H32: =SUM(H26:H31) -> 447315781 | I32: =SUM(I26:I31) -> 8942035 | J32: =SUM(J26:J31) -> 1625936 | K32: =SUM(K26:K31) -> 0 | L32: =SUM(L26:L31) -> 0 | M32: =SUM(M26:M31) -> 282937747 | N32: =SUM(N26:N31) -> 0 | O32: =SUM(O26:O31) -> 163862170 | ... Y32: =SUM(Y26:Y31) -> 0
B33: Строительство
A34: =A32+10 -> 230 | B34: Физические лица | C34: =SUM(J34:Y34)-L34-P34-Q34 -> 0 | O34: =+P34+Q34 -> 0
A35: =A34+10 -> 240 | B35: Государственные предприятия | C35: =SUM(J35:Y35)-L35-P35-Q35 -> 1049953 | D35: 1049953 | E35: 0.28 | H35: 1049953 | J35: 0 | K35: 0 | L35: 0 | M35: 0 | N35: 0 | O35: =+P35+Q35 -> 350000 | P35: 0 | Q35: 350000 | R35: 0 | S35: 0 | T35: 0 | U35: 0 | V35: 699953 | W35: 0 | X35: 0 | Y35: 0
A36: =A35+10 -> 250 | B36: Совместные и иностранные предприятия | C36: =SUM(J36:Y36)-L36-P36-Q36 -> 490239 | D36: 490239 | E36: 0.24 | H36: 490239 | J36: 0 | K36: 0 | L36: 0 | M36: 0 | N36: 0 | O36: =+P36+Q36 -> 490239 | P36: 0 | Q36: 490239 | R36: 0 | S36: 0 | T36: 0 | U36: 0 | V36: 0 | W36: 0 | X36: 0 | Y36: 0
A37: =A36+10 -> 260 | B37: Частные товарищества и корпорации | C37: =SUM(J37:Y37)-L37-P37-Q37 -> 276471671 | D37: 276471671 | E37: 0.13227021 | H37: 233094178 | I37: 43377493 | J37: 0 | K37: 0 | L37: 0 | M37: 3947713 | N37: 0 | O37: =+P37+Q37 -> 259600031 | P37: 0 | Q37: 259600031 | R37: 1547619 | S37: 0 | T37: 0 | U37: 0 | V37: 7963862 | W37: 3412446 | X37: 0 | Y37: 0
A38: =A37+10 -> 270 | B38: Правительство | C38: =SUM(J38:Y38)-L38-P38-Q38 -> 0 | O38: =+P38+Q38 -> 0
A39: =A38+10 -> 280 | B39: Прочие | C39: =SUM(J39:Y39)-L39-P39-Q39 -> 0 | O39: =+P39+Q39 -> 0
A40: =A39+10 -> 290 | B40: Итого по строительству | C40: =SUM(J40:Y40)-L40-P40-Q40 -> 278011863 | D40: =SUM(D34:D39) -> 278011863 | E40: =IFERROR(((D34*E34)/D40)+((D35*E35)/D40)+((D36*E36)/D40)+((D37*E37)/D40)+((D38*E38)/D40)+((D39*E39)/D40),0) -> 0.1330181 | F40: =SUM(F34:F39) -> 0 | G40: =IFERROR(((F34*G34)/F40)+((F35*G35)/F40)+((F36*G36)/F40)+((F37*G37)/F40)+((F38*G38)/F40)+((F39*G39)/F40),0) -> 0 | H40: =SUM(H34:H39) -> 234634370 | I40: =SUM(I34:I39) -> 43377493 | J40: =SUM(J34:J39) -> 0 | K40: =SUM(K34:K39) -> 0 | L40: =SUM(L34:L39) -> 0 | M40: =SUM(M34:M39) -> 3947713 | N40: =SUM(N34:N39) -> 0 | O40: =SUM(O34:O39) -> 260440270 | ... Y40: =SUM(Y34:Y39) -> 0
B41: Торговля и общественное питание
...

Sheet Aging Analysis
A1: АНАЛИЗ ПРОСРОЧЕННЫХ КРЕДИТОВ И ФИНАНСОВОГО ЛИЗИНГА К ПОЛУЧЕНИЮ | X1: Таблица-9
B3: =Balance!B3 -> АКБ "Микрокредитбанк" | T3: =+Balance!C3 -> 43829 | X3: =+Balance!E3 -> тыс. сум
