Workbook
Name bal: [1]balance!$A:$IV
Name OLE_LINK19: Balance!$B$33

Sheet Balance
B1: Приложение №1 к Рекомендациям по заполнению отчетности коммерческих банков по банковскому надзору представляемых Центральному банку Республики Узбекистан
A2: БАЛАНСОВЫЙ ОТЧЕТ КОММЕРЧЕСКОГО БАНКА | B2: Таблица-1(Форма-0110BS)
A3: =IF(B4>0," "&TEXT(B4,"д ММММ, гггг"),"Число,Месяц,Год") -> 31 Декабрь, 2017 | B3: АКБ "Микрокредитбанк"
A4: =IF(B4>0,B4,"Число,Месяц,Год") -> 43100 | B4: 43100
A5: АКТИВЫ | B5: в тыс.сум
A7: 1. Кассовая наличность и другие платежные документы | C7: ='Bank Assets Analysis'!H9 -> 76954182
A8: 2. К получению из ЦБРУ | C8: ='Bank Assets Analysis'!H10+'Bank Assets Analysis'!H11 -> 213192148
A9: 3. К получению из других банков | C9: ='Bank Assets Analysis'!H12 -> 78542844
A10: 4. Счета купли и продажи
A11: а. Ценные бумаги | B11: ='Investment Securities'!B26 -> 349524
A12: б. Драгоценные металлы, монеты, камни | B12: ='Investment Securities'!B37 -> 175
A13: в. Минус: Резерв возможных убытков по счетам купли-продажи | B13: ='Investment Securities'!B27+'Investment Securities'!B38 -> 0
A14: г. Счета купли-продажи, чистые | C14: ='Bank Assets Analysis'!H16 -> 349699
A15: 5 а. Инвестиции | B15: ='Investment Securities'!B13 -> 2750000
A16: б. Минус: Резерв возможных убытков по инвестициям | B16: ='Investment Securities'!B14 -> 1
A17: в. Инвестиции, чистые | C17: ='Bank Assets Analysis'!H28 -> 2749999
A18: 6. Ценные бумаги купленные по соглашению c обратным выкупом | C18: ='Bank Assets Analysis'!H29 -> 0
A19: 7. Кредиты и лизинговые операции
A20: а. Брутто кредиты | B20: 1280369363
A21: б. Лизинговые операции, Брутто | B21: 5753150
A22: в. Минус: Резерв возможных убытков по кредитам и лизингу | B22: ='Charge-offs and Recoveries'!C26 -> 33716097 | E22: =+'Loan Classification'!N14 -> 33716097
A23: г. Кредиты и лизинговые операции, чистые | C23: =('Bank Assets Analysis'!H25+'Bank Assets Analysis'!H26+'Bank Assets Analysis'!H27) -> 1252406416
A24: 8 а. Купленные векселя
A25: б. Минус: Резерв возможных убытков по купленным векселям
A26: в. Купленные векселя, чистые | C26: ='Bank Assets Analysis'!H21 -> 0
A27: 9. Обязательства клиентов по финансовым инструментам | C27: ='Bank Assets Analysis'!H22 -> 0
A28: 10. Основные средства, чистые | C28: ='Bank Assets Analysis'!H32 -> 100870267
A29: 11. Начисленные проценты к получению | C29: ='Bank Assets Analysis'!H37 -> 7348132
A30: 12. Другое собственное имущество банка
A31: а. Инвестиции в недвижимость
A32: б. Другие активы, приобретенные при кредитных расчетах | B32: 3341276
A33: в. Минус:Резервы на возможные убытки по другому собственному имуществу банка | B33: 1728161
A34: г. Чистые, другое собственное имущество банка | C34: ='Bank Assets Analysis'!H33 -> 1613115
A35: 13. Другие активы | C35: 8966247
A36: 14. Итого активов | C36: =C7+C8+C9+C14+C17+C18+C23+C26+C27+C28+C29+C34+C35 -> 1742993049
A38: ОБЯЗАТЕЛЬСТВА И СОБСТВЕННЫЙ КАПИТАЛ
A40: ОБЯЗАТЕЛЬСТВА
A41: 15. Депозиты до востребования | C41: ='Deposits by Client'!B12 -> 357875870
A42: 16.Сберегательные депозиты | C42: ='Deposits by Client'!B21 -> 21367374
A43: 17. Срочные депозиты | C43: ='Deposits by Client'!B30 -> 642761240
...

Sheet Income 
B1: Приложение №1 к Рекомендациям по заполнению отчетности коммерческих банков по банковскому надзору представляемых Центральному банку Республики Узбекистан
A2: ОТЧЕТ О ПРИБЫЛЯХ И УБЫТКАХ | B2: Таблица-2 (Форма-0204IS)
A3: =+Balance!A4 -> 43100 | B3: =Balance!B3 -> АКБ "Микрокредитбанк"
A4: Категории | B4: в тыс. сум
A5: 1. ПРОЦЕНТНЫЕ ДОХОДЫ
A6: a. Процентные доходы по счетам в ЦБРУ | B6: 62
A7: б. Процентные доходы по счетам в других банках | B7: 58525
A8: в. Процентные доходы по купленным векселям | B8: 0
A9: г. Процентные доходы по инвестициям | B9: 0
A10: д. Процентные доходы по счетам купли-продажи ценных бумаг | B10: 222750
A11: е. Процентные доходы по обязательствам клиентов | B11: 0
A12: ж. Процентные доходы по обяз-вам клиентов по непогашенным акцептам этого банка | B12: 0
A13: з. Процент, Дисконт (Скидки) и взносы по кредитным и лизинговым операциям | B13: 142882099
A14: и. Процентные доходы по соглашениям о покупке ценных бумаг с обратным выкупом | B14: 0
A15: к. Другие процентные доходы | B15: 79738030
A16: л. Итого процентных доходов | B16: =SUM(B6:B15) -> 222901466 | D16: =+'Analysis of Interest'!B42 -> 222901466
A18: 2. ПРОЦЕНТНЫЕ РАСХОДЫ
A19: а. Процентные расходы по депозитам до востребования | B19: 374026
A20: б. Процентные расходы по сберегательным депозитам | B20: 9509331
A21: в. Процентные расходы по срочным депозитам | B21: 58283006
A22: г. Процентные расходы по счетам к оплате в ЦБРУ | B22: 0
A23: д. Процентные расходы по счетам к оплате в другие банки | B23: 9974483
A24: е. Итого процентных расходов по депозитам | B24: =SUM(B19:B23) -> 78140846
A25: ж. Процентные расходы по кредитам к оплате | B25: 2088909
A26: з. Процентные расходы по соглашениям о продаже ц/б с последующим выкупом | B26: 0
A27: и. Другие процентные расходы | B27: 65909560
A28: к. Итого процентных расходов по займам | B28: =SUM(B25:B27) -> 67998469
A29: л. Итого процентных расходов | B29: =B28+B24 -> 146139315 | C29: =+'Analysis of Interest'!B81 -> 146139315
A31: 3. ЧИСТЫЕ ПРОЦЕНТНЫЕ ДОХОДЫ ДО ОЦЕНКИ ВОЗМОЖНЫХ УБЫТКОВ ПО КРЕДИТАМ И ЛИЗИНГУ | B31: =B16-B29 -> 76762151
A32: а. Минус: Оценка возможных убытков по кредитам и лизингу | B32: 86761235
A33: б. Чистые процентные доходы после оценки возможных убытков по кредитам и лизингу | B33: =B31-B32 -> -9999084
A35: 4. БЕСПРОЦЕНТНЫЕ ДОХОДЫ
A36: а. Доходы от комиссий и платы за услуги | B36: 75291341
A37: б. Прибыль в иностранной валюте | B37: 53897168
A38: в. Прибыль от коммерческих операций | B38: 0
A39: г. Прибыль и дивиденды от инвестиций | B39: 69286
A40: д. Другие беспроцентные доходы | B40: 34923148
A41: е. Итого беспроцентных доходов | B41: =SUM(B36:B40) -> 164180943
A43: 5. БЕСПРОЦЕНТНЫЕ РАСХОДЫ
A44: а. Комиссионные расходы и расходы за услуги | B44: 20979604
...

Sheet Analysis of Interest
B1: Приложение №1 к Рекомендациям по заполнению отчетности коммерческих банков по банковскому надзору представляемых Центральному банку Республики Узбекистан
A2: АНАЛИЗ ПРОЦЕНТНЫХ ДОХОДОВ И РАСХОДОВ | B2: Таблица-3 (Форма-0206IS)
A3: =+Balance!A4 -> 43100 | B3: =Balance!B3 -> АКБ "Микрокредитбанк"
A4: Категория | B4: в тыс. сум
A5: 1 . ПРОЦЕНТНЫЕ ДОХОДЫ ПО КРЕДИТНЫМ И ЛИЗИНГОВЫМ ОПЕРАЦИЯМ
A6: a. Кредиты и лизинговые операции ЦБРУ | B6: 0
A7: б. Кредиты и лизинговые операции другим банкам | B7: 27
A8: в. Кредиты и лизинговые операции Правительству | B8: 1355
A9: г. Кредиты и лизинговые операции физическим лицам | B9: 54031630
A10: д. Кредиты и лизинговые операции государственным предприятиям | B10: 9124556
A11: е. Кредиты и лизинговые операции совместным и иностранным предприятиям | B11: 294487
A12: ж. Кредиты и лизинговые операции частным товариществам и корпорациям | B12: 78087747
A13: з. Другие кредиты и лизинговые операции | B13: 1342297
A14: и. ИТОГО ПРОЦЕНТНЫХ ДОХОДОВ ПО КРЕДИТНЫМ И ЛИЗИНГОВЫМ ОПЕРАЦИЯМ | B14: =SUM(B6:B13) -> 142882099
A16: 2. ПРОЦЕНТНЫЕ ДОХОДЫ ПО КОРРЕСПОНДЕНТСКИМ СЧЕТАМ
A17: a. К получению из ЦБРУ | B17: 62
A18: б. К получению из других банков | B18: 58525
A19: в. ИТОГО ПРОЦЕНТНЫХ ДОХОДОВ ПО КОРРЕСПОНДЕНТСКИМ СЧЕТАМ | B19: =SUM(B17:B18) -> 58587
A21: 3. ПРОЦЕНТНЫЕ ДОХОДЫ ПО СЧЕТАМ КУПЛИ-ПРОДАЖИ Ц/Б
A22: a. Государственные казначейские ценные бумаги | B22: 0
A23: б. Облигации и ценные бумаги ЦБРУ | B23: 0
A24: в. Ценные бумаги государственных корпораций | B24: 0
A25: г. Еврооблигации | B25: 0
A26: д. Частные ценные бумаги | B26: 222750
A27: е. Другие ценные бумаги | B27: 0
A28: ж. ИТОГО ПРОЦЕНТНЫХ ДОХОДОВ ПО СЧЕТАМ КУПЛИ-ПРОДАЖИ Ц/Б | B28: =SUM(B22:B27) -> 222750
A30: 4. ПРОЦЕНТНЫЕ ДОХОДЫ ПО ИНВЕСТИЦИЯМ
A31: а. Государственные облигации | B31: 0
A32: б. Облигации и ценные бумаги ЦБРУ | B32: 0
A33: в. Частные облигации | B33: 0
A34: г. Еврооблигации | B34: 0
A35: д. Другие ценные бумаги | B35: 0
A36: е. ИТОГО ПРОЦЕНТНЫХ ДОХОДОВ ПО ИНВЕСТИЦИЯМ | B36: =SUM(B31:B35) -> 0
A38: 5. ДРУГИЕ ПРОЦЕНТНЫЕ ДОХОДЫ
A39: а. Процентные доходы по соглашениям о покупке ц/б c обратным выкупом | B39: 0
A40: б. Другие процентные доходы | B40: 79738030
A42: 6. ИТОГО ПРОЦЕНТНЫХ ДОХОДОВ | B42: =B14+B19+B28+B36+B39+B40 -> 222901466
A44: 7. ПРОЦЕНТНЫЕ РАСХОДЫ ПО ДЕПОЗИТАМ
A45: A. Депозиты до востребования
A46: а. Правительство | B46: 269131
...

Sheet Bank Capital Calc.
D1: Приложение №1 к Рекомендациям по заполнению отчетности коммерческих банков по банковскому надзору представляемых Центральному банку Республики Узбекистан
A2: РАСЧЕТ КАПИТАЛА БАНКА | E2: Таблица-4 (Форма-3004CAR)
A3: =+Balance!A4 -> 43100
D4: =Balance!B3 -> АКБ "Микрокредитбанк"
A5: No. | B5: Характеристики | C5: Капитал
C6: Основной | D6: Дополнительный | E6: Итого капитала
B7: (A) | C7: (Б) | D7: (В) | E7: (Г)
A8: I. | B8: КАПИТАЛ УРОВНЯ 1 (до вычетов)
A9: 1 | B9: Обыкновенные Акции
A10: a | B10: Полностью оплаченные обыкновенные акции | C10: 592608108
A11: б | B11: Минус: Обратно Выкупленные обыкновенные акции | C11: 0
A12: в | B12: Выпущенные, полностью оплаченные обыкновенные акции | E12: =+C10-C11 -> 592608108
A13: 2 | B13: Некумулятивные бессрочные привилегированные акции
A14: а | B14: Полностью оплаченные привилегированные акции | D14: 144180
A15: б | B15: Минус: Обратно Выкупленные привилегированные акции
A16: в | B16: Выпущенные, полностью оплаченные привилегированные акции | E16: =+D14-D15 -> 144180
A17: 3 | B17: Добавленный капитал | E17: =+C17+D17 -> 0
A18: 4 | B18: Нераспределенная прибыль
A19: а | B19: Капитальные резервы | C19: 28021551
A20: б | B20: Нераспределенная прибыль | C20: 12847445
A21: в | B21: Минус: Убыток за текущий год | C21: -88223343
A22: г | B22: Итого нераспределенная прибыль | E22: =+C19+C20+C21 -> -47354347
A23: 5 | B23: Интерес меньшинства в консолидированных дочерних компаниях (согласно МБС) | E23: =+C23 -> 0
A24: 6 | B24: Доля участия дочерних предприятий (выпущенные дочерними предприятиями и находящиеся во владении третьих лиц инструменты, приравненные к капиталу) | E24: =+D24 -> 0
A25: 7 | B25: Резерв на девальвацию | E25: =+C25 -> 0
A26: 8 | B26: Итого капитал уровня 1 до вычетов | C26: =SUM(C10:C25) -> 5.4525376e+08 | D26: =SUM(D10:D25) -> 144180 | E26: =SUM(C26+D26) -> 5.4539794e+08
A27: II | B27: ВЫЧЕТЫ ИЗ СУММЫ КАПИТАЛА УРОВНЯ I
A28: 1 | B28: Нематериальные активы | C28: 1980258 | E28: =-C28 -> -1980258
A29: 2 | B29: Все инвестиции в капитал неконсолидированных хозяйствующих субъектов, в том числе в долговые обязательства, которые образуют капитал хозяйствующих субъектов | C29: 3099523 | E29: =-C29 -> -3099523
A30: 3 | B30: Инвестиции в капитал других банков | E30: =-C30 -> 0
A31: 4 | B31: Итого вычетов из суммы капитала Уровня 1 | C31: =SUM(C28:C30) -> 5079781 | E31: =-C31 -> -5079781
A32: III | B32: СКОРРЕКТИРОВАННЫЙ КАПИТАЛ УРОВНЯ I | E32: =SUM(E12+E16+E17+E22+E23+E25+E31) -> 5.4031816e+08
A34: IV | B34: КАПИТАЛ УРОВНЯ II
A36: 1 | B36: Прибыль за текущий год (при подтверждении аудиторами - 100%, в противном случае 50% от суммы) | C36: 0 | E36: =+C36 -> 0
A37: 2 | B37: Резервы, создаваемые на стандартные кредиты (активы), в размере не более 1.25% от общей суммы активов, взвешенных с учетом риска | C37: 0 | E37: =+C37 -> 0
A38: 3 | B38: Субординированный долг | C38: 0 | E38: =+C38 -> 0
A39: 4 | B39: Излишки оценочной стоимости прироста над первоначальной стоимостью | C39: 169615.96 | E39: =+C39 -> 169615.96
A40: 5 | B40: Другие инструменты капитала, в том числе обязательства смешанного типа (не более 1/3 части капитала 1 уровня после вычетов) | C40: 0 | E40: =+C40 -> 0
A41: 6 | B41: Вычеты превышения Капитала Уровня II над Капиталом Уровня I | E41: =IF(C42<(E32/3),0,(C42-E32/3)*-1) -> 0
A42: 7 | B42: Итого капитала Уровня II | C42: =SUM(C36:C40) -> 169615.96 | E42: =+C42 -> 169615.96
...

Sheet Calculation of Risk Weighted As
F1: Приложение №1 к Рекомендациям по заполнению отчетности коммерческих банков по банковскому надзору представляемых Центральному банку Республики Узбекистан
A2: РАСЧЕТ АКТИВОВ ВЗВЕШЕННЫХ С УЧЕТОМ РИСКА | G2: Таблица-5 (Форма-3006CAR)
B3: =+Balance!A4 -> 43100 | D3: =Balance!B3 -> АКБ "Микрокредитбанк"
A5: № | B5: Характеристики | C5: 0 | D5: 0.2 | E5: 0.5 | F5: 1 | G5: 1.5
C6: Риск | D6: Риск | E6: Риск | F6: Риск | G6: Риск
B7: (A) | C7: (Б) | D7: (В) | E7: (Г) | F7: (Д) | G7: (Е)
B8: Балансовые Активы
A9: 1. | B9: Касса (наличность и монеты) и Драгоценные металлы | C9: 75966635
A10: 2. | B10: Денежная наличность и другие платежные документы в пути | D10: 987722
A11: 3. | B11: Корреспондентские и резервные счета в ЦБРУ | C11: 213192148
A12: 4. | B12: Корр. счета, кредиты и другие требования к банкам и депозитарным институтам
A13: а | B13: требования к банкам стран с низким уровнем риска
A14: б | B14: требования к другим банкам | F14: 78542844
A15: 5. | B15: Рыночные ценные бумаги, чистые
A16: а) | B16: Ценные бумаги, выпущенные Правительством Республики Узбекистан и ЦБРУ | C16: 0
A17: б) | B17: Ценные бумаги, выпущенные правительствами и центральными банками стран, с низким уровня риска, а также другие требования к центральным банкам и правительствам этих стран | C17: 0
A18: в) | B18: Другие ценные бумаги | F18: 349524
A19: 6. | B19: Кредиты и другие активы или их части, обеспеченные наличными деньгами, хранящимися на отдельном блокированном депозитном счете. | C19: 0
A20: 7. | B20: Все требования банка, деноминированные в местную валюту стран не входящих в группу стран с низким уровнем риска, к Центральным банкам и центральным правительствам этих стран | D20: 0
A21: 8. | B21: Активы, обеспеченные ценными бумагами выпущенными банками зарегистрированными в странах с низким уровнем риска | D21: 0
A22: 9. | B22: Требования банка к международным кредитным организациям, а также активы, гарантированные этими организациями | D22: 0
A23: 10. | B23: Активы или их части, обеспеченные залогом в виде ценных бумаг, оцененных по текущей рыночной стоимости и эмитированных международными финансовыми институтами | D23: 0
A24: 11. | B24: Кредиты и лизинги, чистые
A25: а) | B25: прямые требования к Правительству и Центральному банку Республики Узбекистан | C25: 0
A26: б) | B26: Активы или их части, обеспеченные ценными бумагами, которые оцененные по текущей рыночной стоимости и выпущенными или гарантированными Правительством Республики Узбекистан, Центральным банком Республики Узбекистан или Правительствами стран с низким уровнем риска. | D26: 0
A27: в) | B27: Кредиты на недвижимость обеспеченные приобретаемым или строящимся домом (квартирой) | E27: 0
A28: г) | B28: Реструктуризированные кредиты и кредиты в статусе "ненаращивания" | F28: 0
A29: д) | B29: Кредиты, по которым банк не имеет приоритетного права на залог | F29: 0
A30: е) | B30: Пересмотренные или пролонгированные кредиты и лизинги более одного раза | G30: 0
A31: ж) | B31: все другие кредиты (кроме лизинга) | F31: 1236844076
A32: 12. | B32: Кредиты и лизинги в судебном разбирательстве, чистые
A33: 13. | B33: Просроченные кредиты и лизинги, чистые | G33: 10299194
A34: 14. | B34: Финансовый лизинг | F34: 5263146
A35: 15. | B35: Основные средств и другое собственное имущество банка
A36: а | B36: Основные средства, используемые в банковской деятельности (минус амортизация) | F36: 98890009
A37: б | B37: Недвижимое имущество принятое на баланс банка в целях полного или частичного погащения задолженности | G37: 1613115
A38: в | B38: Недвижимое имущество банка, которым банк не пользуется более двух лет | G38: 0
A39: 16. | B39: Инвестиции в капитал неконсолидированных банковских и небанковских финансовых дочерних компаний и всех нефинансовых предприятий
A40: 17. | B40: Все другие инвестиции, чистые | F40: 2749999
A41: 18. | B41: Нематериальные активы, включая гудвилл | C41: 1980258
...

Sheet Calculation of Risk
C1: Приложение №1 к Рекомендациям по заполнению отчетности коммерческих банков по банковскому надзору представляемых Центральному банку Республики Узбекистан | I1: Достаточность капитала - К1 | J1: Коэффициент достаточности капитала I уровня K2 | K1: Доля основного капитала I уровня к регулятивному капиталу | L1: Коэффициент нормы покрытия ликвидности | M1: Норма чистого стабильного финансирования (НЧСФ)
A2: РАСЧЕТ ПО ОПЕРАЦИОННЫМ И РЫНОЧНЫМ РИСКАМ | H2: 2015 | I2: 10 | J2: 7.5 | K2: 6 | L2: 80
C3: Таблица-5А (Форма-3006CAR) | H3: 2016 | I3: 11.5 | J3: 8.5 | K3: 7 | L3: 80
B4: =+Balance!A4 -> 43100 | C4: =+Balance!B3 -> АКБ "Микрокредитбанк" | H4: 2017 | I4: 12.5 | J4: 9.5 | K4: 7.5 | L4: 90
A5: № | B5: Наименование показателя | C5: в тыс. сум | H5: 2018 | I5: 13.5 | J5: 10.5 | K5: 8.5 | L5: 100 | M5: 100
A6: 1. | B6: =+"Валовый доход банка за "&(E$9-3)&" год" -> Валовый доход банка за 2014 год | C6: =+C7-C8+C9 -> 117166860 | H6: 2019 | I6: 14.5 | J6: 11 | K6: 9.5 | L6: 100 | M6: 100
A7: а. | B7: процентные доходы | C7: 112378436
A8: б. | B8: процентные расходы | C8: 61062136 | E8: =RIGHT(Balance!A3,4) -> 2017 | G8: =VLOOKUP(E9,H2:M6,2,0) -> 12.5
A9: в. | B9: другие доходы | C9: 65850560 | E9: =IF(E8>H6,H6,E8) -> 2017
A10: 2. | B10: =+"Валовый доход банка за "&(E$9-2)&" год" -> Валовый доход банка за 2015 год | C10: =+C11-C12+C13 -> 150836429 | G10: =VLOOKUP($E$9,$H$2:$J$6,3,0) -> 9.5
A11: а. | B11: процентные доходы | C11: 154719438 | G11: =VLOOKUP($E$9,H2:M6,5,0) -> 90
A12: б. | B12: процентные расходы | C12: 96585301 | G12: =VLOOKUP(E9,H2:M6,6,0) -> 0
A13: в. | B13: другие доходы | C13: 92702292
A14: 3. | B14: =+"Валовый доход банка за "&(E$9-1)&" год" -> Валовый доход банка за 2016 год | C14: =+C15-C16+C17 -> 172091797
A15: а. | B15: процентные доходы | C15: 204104096
A16: б. | B16: процентные расходы | C16: 126300057
A17: в. | B17: другие доходы | C17: 94287758
A18: 4. | B18: Средний валовый доход банка (за последние три года) | C18: =(C6+C10+C14)/3 -> 146698362
A19: 5. | B19: Сумма операционных рисков | C19: =+(100/C26)*C18*15% -> 1.7603803e+08
A21: 6. | B21: Счета валютной позиции (счет 17101 (сумавая часть)) | C21: 124002463
A22: 7. | B22: Продажа на условиях Своп и Форвард (счет 92709, 92732) | C22: 0
A23: 8. | B23: Покупка на условиях Своп и Форвард (счет 92716, 92736) | C23: 0
A24: 9. | B24: Открытая валютная позиция, всего | C24: =C21+(C23-C22) -> 124002463 | D24: =+C24*0.1 -> 12400246
A25: 10. | B25: Сумма рыночных рисков | C25: =+(100/C26)*(C24*10%) -> 99201970
A26: 11. | B26: Действуюший минимальное требование к достаточности капитала | C26: =VLOOKUP($E$9,$H$2:$I$6,2,0) -> 12.5
A28: Подпись Председателя правления:
A30: Подпись Главного Бухгалтера:

Sheet Changes in Equity
B1: Приложение №1 к Рекомендациям по заполнению отчетности коммерческих банков по банковскому надзору представляемых Центральному банку Республики Узбекистан
A2: ИЗМЕНЕНИЯ В СОБСТВЕННОМ КАПИТАЛЕ | B2: Таблица-6 (Форма-3106CSA)
A3: =+Balance!A4 -> 43100 | B3: =Balance!B3 -> АКБ "Микрокредитбанк"
A4: Категория | B4: в тыс. сум
A5: 1. Итого собственного капитала первоначально определенного за прошлый год | B5: 282646747
A6: 2. Исправления в собственном капитале не показанные в отчете за прошлый год, чистые | B6: 0
A7: 3. Исправленный баланс на конец прошлого календарного года (сумма строк 1 и 2) | B7: =SUM(B5:B6) -> 282646747
A8: 4. Чистый прибыль (убыток) по состоянию на дату от начала года | B8: -88223343
A9: 5. Продажа, Обмен, Приобретение или выкуп акций, за текущий год (чистая выручка) | B9: 342586323
A10: 6. Изменения в оценочной стоимости прироста над первонач. стоимостью, за текущий год (чистые) | B10: -9709947
A11: 7. МИНУС: Денежные дивиденды объявленные по привилегированным акциям
A12: 8. МИНУС: Денежные дивиденды объявленные по обыкновенным акциям
A13: 9. Другие статьи влияющие на собственный капитал за текущий год (чистые) | B13: 18475086
A14: 10. Итого собственного капитала на конец текущего периода (сумма строк с 3 по 10) | B14: =B7+SUM(B8:B10)-SUM(B11:B12)+B13 -> 545774866
A16: Подпись Председателя правления:
A18: Подпись Главного Бухгалтера:

Sheet Recociliation 
B1: Приложение №1 к Рекомендациям по заполнению отчетности коммерческих банков по банковскому надзору представляемых Центральному банку Республики Узбекистан
A2: ВЫВЕРКА НЕРАСПРЕДЕЛЕННОЙ ПРИБЫЛИ | B2: Таблица-7 (Форма-0208IS)
A3: =+Balance!A4 -> 43100
A4: =Balance!B3 -> АКБ "Микрокредитбанк" | B4: в тыс. сум
A5: 1. Нераспределенная прибыль, указанная в отчете за предыдущий календарный год | B5: 40126023
A6: 2. Плюс или Минус: Предварит. корректировки не указанные в отчете к концу года
A7: 3. Равно: Откорректированная нераспределенная прибыль | B7: =B5+B6 -> 40126023
A8: 4. Плюс или Минус: Кумулятивная чистая прибыль (Убытки) в текущем году | B8: -88223343
A9: 5. Минус: Денежные дивиденды объявленные по обыкновенным акциям
A10: 6. Минус: Денежные дивиденды объявленные по привилегированным акциям
A11: 7. Минус: Дивиденды в виде акций объявленные по обыкновенным акциям
A12: 8. Минус: Дивиденды в виде акций объявленные по привилегированным акциям
A13: 9. Другие статьи, влияющие на нераспределенную прибыль,Чистые | B13: 18475086
A14: 10. Равно: Текущий Баланс, Нераспределенная прибыль | B14: =B7+B8-SUM(B9:B12)+B13 -> -29622234
A16: Подпись Председателя правления:
A18: Подпись Главного Бухгалтера:

Sheet Loans Receivable
Q1: Приложение №1 к Рекомендациям по заполнению отчетности коммерческих банков по банковскому надзору представляемых Центральному банку Республики Узбекистан
A2: Кредиты к получению по отраслям экономики, типам клиентов и по типу обеспечения | R2: Таблица-8 (Форма-1516LES)
B3: =+Balance!A4 -> 43100 | P3: =Balance!B3 -> АКБ "Микрокредитбанк"
B4: Отрасль экономики | C4: Сумма кредита | D4: из них | G4: из них
D5: Начисляемые кредиты | E5: Неначисляемые кредиты | F5: Средняя процентная ставка | G5: Депозиты | H5: Гарантированные Правительством Республики Узбекистан | I5: из них | J5: Транспортные средства | K5: Инвентарь | L5: Недвижимость | M5: Оборудование | N5: Векселя (облигации) | O5: Акции | P5: Гарантия третьей стороны | Q5: Поручительства третьей стороны | R5: Страховой полис | S5: Необеспеченные | T5: Другое обеспечение
I6: Гарантированные Правительством Республики Узбекистан в иностранной валюте (экв.сум)
A7: Код | B7: (А) | C7: (Б) | D7: (В) | E7: (Г) | F7: (Д) | G7: (Е) | H7: (Ж) | I7: (Ж1) | J7: (З) | K7: (И) | L7: (К) | M7: (Л) | N7: (М) | O7: (Н) | P7: (О) | Q7: (П) | R7: (Р) | S7: (С) | T7: (Т)
B8: Промышленность
A9: 10 | B9: Физические лица | C9: =SUM(G9:T9)-I9 -> 14276766 | D9: =+SUM(G9:T9) -> 14276766 | F9: 0.16 | J9: 4960453 | L9: 3609587 | P9: 5706726
A10: =A9+10 -> 20 | B10: Государственные предприятия | C10: =SUM(G10:T10)-I10 -> 55895043 | D10: =+SUM(G10:T10) -> 55895043 | F10: 0.16 | J10: 1728447 | L10: 3647876 | P10: 50518720
A11: =A10+10 -> 30 | B11: Совместные и иностранные предприятия | C11: =SUM(G11:T11)-I11 -> 6560620 | D11: =+SUM(G11:T11) -> 6560620 | F11: 0.16 | J11: 2045376 | L11: 4515244
A12: =A11+10 -> 40 | B12: Частные товарищества и корпорации | C12: =SUM(G12:T12)-I12 -> 139693563 | D12: =+SUM(G12:T12) -> 139693563 | F12: 0.14 | J12: 52584227 | L12: 74035305 | M12: 1796900 | P12: 6033776 | T12: 5243355
A13: =A12+10 -> 50 | B13: Правительство | C13: =SUM(G13:T13)-I13 -> 0 | D13: 0
A14: =A13+10 -> 60 | B14: Прочие | C14: =SUM(G14:T14)-I14 -> 0 | D14: 0
A15: =A14+10 -> 70 | B15: Итого по промышленности | C15: =SUM(G15:T15)-I15 -> 216425992 | D15: =SUM(D9:D14) -> 216425992 | E15: =SUM(E9:E14) -> 0 | F15: =IF(C15=0,"",(F9*(C9/C15))+(F10*(C10/C15))+(F11*(C11/C15))+(F12*(C12/C15))+(F13*(C13/C15))+(F14*(C14/C15))) -> 0.14709087 | G15: =SUM(G9:G14) -> 0 | H15: =SUM(H9:H14) -> 0 | I15: =SUM(I9:I14) -> 0 | J15: =SUM(J9:J14) -> 61318503 | K15: =SUM(K9:K14) -> 0 | L15: =SUM(L9:L14) -> 85808012 | M15: =SUM(M9:M14) -> 1796900 | N15: =SUM(N9:N14) -> 0 | ... T15: =SUM(T9:T14) -> 5243355
B16: Сельское хозяйство
A17: =A15+10 -> 80 | B17: Физические лица | C17: =SUM(G17:T17)-I17 -> 137890348 | D17: =+SUM(G17:T17) -> 137890348 | F17: 0.13 | J17: 9473254 | L17: 12901203 | P17: 110089436 | T17: 5426455
A18: =A17+10 -> 90 | B18: Государственные предприятия | C18: =SUM(G18:T18)-I18 -> 56823460 | D18: =+SUM(G18:T18) -> 56823460 | F18: 0.14 | J18: 22095034 | L18: 22460581 | P18: 12267845
A19: =A18+10 -> 100 | B19: Совместные и иностранные предприятия | C19: =SUM(G19:T19)-I19 -> 0 | D19: =+SUM(G19:T19) -> 0
A20: =A19+10 -> 110 | B20: Частные товарищества и корпорации | C20: =SUM(G20:T20)-I20 -> 105931280 | D20: =+SUM(G20:T20) -> 105931280 | F20: 0.14 | J20: 37468720 | L20: 58021690 | P20: 10440870 | T20: 0
A21: =A20+10 -> 120 | B21: Фермерское хозяйство | C21: =SUM(G21:T21)-I21 -> 0 | D21: =+SUM(G21:T21) -> 0
A22: =A21+10 -> 130 | B22: Правительство | C22: =SUM(G22:T22)-I22 -> 0 | D22: =+SUM(G22:T22) -> 0
A23: =A22+10 -> 140 | B23: Прочие | C23: =SUM(G23:T23)-I23 -> 0 | D23: =+SUM(G23:T23) -> 0
A24: =A23+10 -> 150 | B24: Итого по сельскому хозяйству | C24: =SUM(G24:T24)-I24 -> 300645088 | D24: =SUM(D17:D23) -> 300645088 | E24: =SUM(E17:E23) -> 0 | F24: =IF(C24=0,"",(F17*(C17/C24))+(F18*(C18/C24))+(F19*(C19/C24))+(F20*(C20/C24))+(F21*(C21/C24))+(F22*(C22/C24))+(F23*(C23/C24))) -> 0.13541352 | G24: =SUM(G17:G23) -> 0 | H24: =SUM(H17:H23) -> 0 | I24: =SUM(I17:I23) -> 0 | J24: =SUM(J17:J23) -> 69037008 | K24: =SUM(K17:K23) -> 0 | L24: =SUM(L17:L23) -> 93383474 | M24: =SUM(M17:M23) -> 0 | N24: =SUM(N17:N23) -> 0 | ... T24: =SUM(T17:T23) -> 5426455
B25: Транспорт и коммуникации
A26: =A24+10 -> 160 | B26: Физические лица | C26: =SUM(G26:T26)-I26 -> 25275397 | D26: =+SUM(G26:T26) -> 25275397 | F26: 0.14 | G26: 502345 | J26: 19303796 | L26: 4373750 | P26: 743361 | T26: 352145
A27: =A26+10 -> 170 | B27: Государственные предприятия | C27: =SUM(G27:T27)-I27 -> 6469866 | D27: =+SUM(G27:T27) -> 6469866 | F27: 0.16 | J27: 5959815 | L27: 510051
A28: =A27+10 -> 180 | B28: Совместные и иностранные предприятия | C28: =SUM(G28:T28)-I28 -> 0 | D28: =+SUM(G28:T28) -> 0
A29: =A28+10 -> 190 | B29: Частные товарищества и корпорации | C29: =SUM(G29:T29)-I29 -> 138791421 | D29: =+SUM(G29:T29) -> 138791421 | F29: 0.14 | G29: 2297231 | J29: 120331781 | L29: 16162409
A30: =A29+10 -> 200 | B30: Правительство | C30: =SUM(G30:T30)-I30 -> 0 | D30: =+SUM(G30:T30) -> 0
A31: =A30+10 -> 210 | B31: Прочие | C31: =SUM(G31:T31)-I31 -> 0 | D31: =+SUM(G31:T31) -> 0
A32: =A31+10 -> 220 | B32: Итого по транспорту и коммуникациям | C32: =SUM(G32:T32)-I32 -> 170536684 | D32: =SUM(D26:D31) -> 170536684 | E32: =SUM(E26:E31) -> 0 | F32: =IF(C32=0,"",(F26*(C26/C32))+(F27*(C27/C32))+(F28*(C28/C32))+(F29*(C29/C32))+(F30*(C30/C32))+(F31*(C31/C32))) -> 0.14075877 | G32: =SUM(G26:G31) -> 2799576 | H32: =SUM(H26:H31) -> 0 | I32: =SUM(I26:I31) -> 0 | J32: =SUM(J26:J31) -> 145595392 | K32: =SUM(K26:K31) -> 0 | L32: =SUM(L26:L31) -> 21046210 | M32: =SUM(M26:M31) -> 0 | N32: =SUM(N26:N31) -> 0 | ... T32: =SUM(T26:T31) -> 352145
B33: Строительство
A34: =A32+10 -> 230 | B34: Физические лица | C34: =SUM(G34:T34)-I34 -> 51518565 | D34: =+SUM(G34:T34) -> 51518565 | F34: 0.15 | J34: 8046631 | L34: 16814400 | P34: 26514988 | T34: 142546
A35: =A34+10 -> 240 | B35: Государственные предприятия | C35: =SUM(G35:T35)-I35 -> 6926416 | D35: =+SUM(G35:T35) -> 6926416 | F35: 0.14 | J35: 2957132 | L35: 3648123 | P35: 321161
A36: =A35+10 -> 250 | B36: Совместные и иностранные предприятия | C36: =SUM(G36:T36)-I36 -> 0 | D36: =+SUM(G36:T36) -> 0
A37: =A36+10 -> 260 | B37: Частные товарищества и корпорации | C37: =SUM(G37:T37)-I37 -> 120243894 | D37: =+SUM(G37:T37) -> 120243894 | F37: 0.14 | J37: 41263190 | L37: 70055647 | M37: 1264299 | P37: 5715489 | T37: 1945269
A38: =A37+10 -> 270 | B38: Правительство | C38: =SUM(G38:T38)-I38 -> 0 | D38: =+SUM(G38:T38) -> 0
A39: =A38+10 -> 280 | B39: Прочие | C39: =SUM(G39:T39)-I39 -> 0 | D39: =+SUM(G39:T39) -> 0
A40: =A39+10 -> 290 | B40: Итого по строительству | C40: =SUM(G40:T40)-I40 -> 178688875 | D40: =SUM(D34:D39) -> 178688875 | E40: =SUM(E34:E39) -> 0 | F40: =IF(C40=0,"",(F34*(C34/C40))+(F35*(C35/C40))+(F36*(C36/C40))+(F37*(C37/C40))+(F38*(C38/C40))+(F39*(C39/C40))) -> 0.14288314 | G40: =SUM(G34:G39) -> 0 | H40: =SUM(H34:H39) -> 0 | I40: =SUM(I34:I39) -> 0 | J40: =SUM(J34:J39) -> 52266953 | K40: =SUM(K34:K39) -> 0 | L40: =SUM(L34:L39) -> 90518170 | M40: =SUM(M34:M39) -> 1264299 | N40: =SUM(N34:N39) -> 0 | ... T40: =SUM(T34:T39) -> 2087815
...

Sheet Aging Analysis
O1: Приложение №1 к Рекомендациям по заполнению отчетности коммерческих банков по банковскому надзору представляемых Центральному банку Республики Узбекистан
A2: Анализ просроченных кредитов и финансового лизинга к получению | P2: Таблица-9 (Форма-1604LOA)
A3: =Balance!A4 -> 43100 | O3: =Balance!B3 -> АКБ "Микрокредитбанк"
A5: № | B5: Характеристики | C5: Всего задолжность по кредитам | D5: % | E5: Реструктуризированные кредиты | F5: % | G5: Просроченная задолжность | K5: Анализ временной задолженности
G6: Всего | H6: % | I6: из них | K6: 1-30 дней | L6: 31-60 дней | M6: 61-90 дней | N6: 91-180 дней | O6: 181-365 дней | P6: 366 дней-2лет | Q6: Свыше 2 лет
I7: Просроченная задолжность | J7: В ходе судебного разбирательства
B9: (А) | C9: (Б) | D9: (В) | E9: (Г) | F9: (Д) | G9: (Е) | H9: (Ж) | I9: (З) | J9: (И) | K9: (К) | L9: (Л) | M9: (М) | N9: (Н) | O9: (О) | P9: (П) | Q9: (Р)
B10: По типу клиента
A11: 1 | B11: Центральный банк | C11: ='Loans Receivable'!C85 -> 0 | D11: =IF(C$24=0,"",C11/C$24) -> 0 | F11: =IF(E$24=0,"",E11/E$24) | G11: =SUM(K11:Q11) -> 0 | H11: =IF($G$24=0,"",G11/$G$24) -> 0
A12: 2 | B12: Другие банки | C12: ='Loans Receivable'!C84 -> 0 | D12: =IF(C$24=0,"",C12/C$24) -> 0 | F12: =IF(E$24=0,"",E12/E$24) | G12: =SUM(K12:Q12) -> 0 | H12: =IF($G$24=0,"",G12/$G$24) -> 0
A13: 3 | B13: Правительство | C13: ='Loans Receivable'!C86 -> 0 | D13: =IF(C$24=0,"",C13/C$24) -> 0 | F13: =IF(E$24=0,"",E13/E$24) | G13: =SUM(K13:Q13) -> 0 | H13: =IF($G$24=0,"",G13/$G$24) -> 0
A14: 4 | B14: Физические лица | C14: ='Loans Receivable'!C79 -> 468263196 | D14: =IF(C$24=0,"",C14/C$24) -> 0.36408911 | F14: =IF(E$24=0,"",E14/E$24) | G14: =SUM(K14:Q14) -> 2323519 | H14: =IF($G$24=0,"",G14/$G$24) -> 0.22564214 | I14: 2323519 | K14: 2323519
A15: 5 | B15: Государственные предприятия | C15: ='Loans Receivable'!C80 -> 141933618 | D15: =IF(C$24=0,"",C15/C$24) -> 0.11035777 | F15: =IF(E$24=0,"",E15/E$24) | G15: =SUM(K15:Q15) -> 13511 | H15: =IF($G$24=0,"",G15/$G$24) -> 0.0013120835 | I15: 13511 | K15: 13511
A16: 6 | B16: Совместные и иностранные предприятия | C16: ='Loans Receivable'!C81 -> 8044041 | D16: =IF(C$24=0,"",C16/C$24) -> 0.0062544905 | F16: =IF(E$24=0,"",E16/E$24) | G16: =SUM(K16:Q16) -> 3884 | H16: =IF($G$24=0,"",G16/$G$24) -> 0.00037718395 | I16: 3884 | K16: 3884
A17: 7 | B17: Частные товарищества и корпорации | C17: ='Loans Receivable'!C82 -> 667881660 | D17: =IF(C$24=0,"",C17/C$24) -> 0.51929863 | F17: =IF(E$24=0,"",E17/E$24) | G17: =SUM(K17:Q17) -> 7695228 | H17: =IF($G$24=0,"",G17/$G$24) -> 0.74730084 | I17: 7695228 | K17: 7695228
A18: 8 | B18: Фермерское хозяйство | C18: ='Loans Receivable'!C83 -> 0 | D18: =IF(C$24=0,"",C18/C$24) -> 0 | F18: =IF(E$24=0,"",E18/E$24) | G18: =SUM(K18:Q18) -> 0 | H18: =IF($G$24=0,"",G18/$G$24) -> 0
A19: 9 | B19: Небанковские финансовые институты | C19: ='Loans Receivable'!C87 -> 0 | D19: =IF(C$24=0,"",C19/C$24) -> 0 | F19: =IF(E$24=0,"",E19/E$24) | G19: =SUM(K19:Q19) -> 0 | H19: =IF($G$24=0,"",G19/$G$24) -> 0
A20: 10 | B20: Негосударственные некоммерческие организации | C20: ='Loans Receivable'!C88 -> 0 | D20: =IF(C$24=0,"",C20/C$24) -> 0 | F20: =IF(E$24=0,"",E20/E$24) | G20: =SUM(K20:Q20) -> 261221 | H20: =IF($G$24=0,"",G20/$G$24) -> 0.025367757 | I20: 261221 | K20: 261221
A21: 11 | B21: Бюджетные организации | C21: ='Loans Receivable'!C89 -> 0 | D21: =IF(C$24=0,"",C21/C$24) -> 0 | F21: =IF(E$24=0,"",E21/E$24) | G21: =SUM(K21:Q21) -> 0 | H21: =IF($G$24=0,"",G21/$G$24) -> 0
A22: 12 | B22: Прочие | C22: ='Loans Receivable'!C90 -> 0 | D22: =IF(C$24=0,"",C22/C$24) -> 0 | F22: =IF(E$24=0,"",E22/E$24) | G22: =SUM(K22:Q22) -> 0 | H22: =IF($G$24=0,"",G22/$G$24) -> 0
A24: 13 | B24: Итого кредита и лизинга | C24: =SUM(C11:C22) -> 1286122515 | D24: =IF(C$24=0,"",C24/C$24) -> 1 | E24: =SUM(E11:E22) -> 0 | F24: =IF(E$24=0,"",E24/E$24) | G24: =SUM(G11:G22) -> 10297363 | H24: =IF($G$24=0,"",G24/$G$24) -> 1 | I24: =SUM(I11:I22) -> 10297363 | J24: =SUM(J11:J22) -> 0 | K24: =SUM(K11:K22) -> 10297363 | L24: =SUM(L11:L22) -> 0 | M24: =SUM(M11:M22) -> 0 | N24: =SUM(N11:N22) -> 0 | O24: =SUM(O11:O22) -> 0 | P24: =SUM(P11:P22) -> 0 | Q24: =SUM(Q11:Q22) -> 0
F25: =IF(E$24=0,"",E25/E$24)
B26: По сектору экономики | F26: =IF(E$24=0,"",E26/E$24)
A27: 14 | B27: Промышленность | C27: ='Loans Receivable'!C15 -> 216425992 | D27: =IF(C$36=0,"",C27/C$36) -> 0.1682779 | F27: =IF(E$24=0,"",E27/E$24) | G27: =SUM(K27:Q27) -> 0 | H27: =IF($G$36=0,"",G27/$G$36) -> 0
A28: 15 | B28: Сельское хозяйство | C28: ='Loans Receivable'!C24 -> 300645088 | D28: =IF(C$36=0,"",C28/C$36) -> 0.23376085 | F28: =IF(E$24=0,"",E28/E$24) | G28: =SUM(K28:Q28) -> 0 | H28: =IF($G$36=0,"",G28/$G$36) -> 0
A29: 16 | B29: Транспорт и коммуникации | C29: ='Loans Receivable'!C32 -> 170536684 | D29: =IF(C$36=0,"",C29/C$36) -> 0.13259754 | F29: =IF(E$24=0,"",E29/E$24) | G29: =SUM(K29:Q29) -> 0 | H29: =IF($G$36=0,"",G29/$G$36) -> 0
A30: 17 | B30: Строительство | C30: ='Loans Receivable'!C40 -> 178688875 | D30: =IF(C$36=0,"",C30/C$36) -> 0.13893612 | F30: =IF(E$24=0,"",E30/E$24) | G30: =SUM(K30:Q30) -> 0 | H30: =IF($G$36=0,"",G30/$G$36) -> 0
A31: 18 | B31: Торговля и общественное питание | C31: ='Loans Receivable'!C48 -> 140213949 | D31: =IF(C$36=0,"",C31/C$36) -> 0.10902068 | F31: =IF(E$24=0,"",E31/E$24) | G31: =SUM(K31:Q31) -> 0 | H31: =IF($G$36=0,"",G31/$G$36) -> 0
A32: 19 | B32: Материально-техническое снабжение и сбыт | C32: ='Loans Receivable'!C56 -> 127634911 | D32: =IF(C$36=0,"",C32/C$36) -> 0.099240088 | F32: =IF(E$24=0,"",E32/E$24) | G32: =SUM(K32:Q32) -> 0 | H32: =IF($G$36=0,"",G32/$G$36) -> 0
A33: 20 | B33: Жилищно-коммунальные услуги | C33: ='Loans Receivable'!C64 -> 0 | D33: =IF(C$36=0,"",C33/C$36) -> 0 | F33: =IF(E$24=0,"",E33/E$24) | G33: =SUM(K33:Q33) -> 0 | H33: =IF($G$36=0,"",G33/$G$36) -> 0
A34: 21 | B34: Другие сектора | C34: ='Loans Receivable'!C77 -> 151977016 | D34: =IF(C$36=0,"",C34/C$36) -> 0.11816683 | F34: =IF(E$24=0,"",E34/E$24) | G34: =SUM(K34:Q34) -> 10297363 | H34: =IF($G$36=0,"",G34/$G$36) -> 1 | I34: 10297363 | K34: 10297363
F35: =IF(E$24=0,"",E35/E$24)
A36: 22 | B36: Итого кредита и лизинга | C36: =SUM(C27:C34) -> 1286122515 | D36: =IF(C$36=0,"",C36/C$36) -> 1 | E36: =SUM(E27:E34) -> 0 | F36: =IF(E$24=0,"",E36/E$24) | G36: =SUM(G27:G34) -> 10297363 | H36: =IF($G$36=0,"",G36/$G$36) -> 1 | I36: =SUM(I27:I34) -> 10297363 | J36: =SUM(J27:J34) -> 0 | K36: =SUM(K27:K34) -> 10297363 | L36: =SUM(L27:L34) -> 0 | M36: =SUM(M27:M34) -> 0 | N36: =SUM(N27:N34) -> 0 | O36: =SUM(O27:O34) -> 0 | P36: =SUM(P27:P34) -> 0 | Q36: =SUM(Q27:Q34) -> 0
B38: Подпись Председателя правления:
B40: Подпись Главного Бухгалтера:

Sheet Loan Classification
L1: Приложение №1 к Рекомендациям по заполнению отчетности коммерческих банков по банковскому надзору представляемых Центральному банку Республики Узбекистан
A2: Отчет о классификации активов по степени риска | M2: Таблица-10 (Форма-1596LKA)
B3: =Balance!A4 -> 43100 | L3: =Balance!B3 -> АКБ "Микрокредитбанк"
A4: № | B4: Статьи баланса | C4: Общая сумма | D4: Стандартные | E4: Общие резервы (1%) | F4: Субстандартные | G4: Специальные резервы (мин 10%) | H4: Неудовлетворительные | I4: Специальные резервы (мин 25%) | J4: Сомнительные | K4: Специальные резервы (мин 50%) | L4: Безнадежные | M4: Специальные резервы (100%) | N4: Совокупная сумма специальных резервов
A5: А | B5: Б | C5: В | D5: Г | E5: Д | F5: Е | G5: Ж | H5: З | I5: И | J5: К | K5: Л | L5: М | M5: Н | N5: О=Ж+И+Л+Н
A6: 1 | B6: Промышленность | C6: =D6+F6+H6+J6+L6 -> 216425992 | D6: 182709895 | F6: 33716097 | G6: 3371610 | N6: =+M6+K6+I6+G6 -> 3371610 | BX6: ='Aging Analysis'!C27 -> 216425992
A7: 2 | B7: Сельское хозяйство | C7: =D7+F7+H7+J7+L7 -> 300645088 | D7: 233212894 | F7: 67432194 | G7: 6743219 | N7: =+M7+K7+I7+G7 -> 6743219 | BX7: ='Aging Analysis'!C28 -> 300645088
A8: 3 | B8: Транспорт и коммуникации | C8: =D8+F8+H8+J8+L8 -> 170536684 | D8: 119962539 | F8: 50574145 | G8: 5057415 | N8: =+M8+K8+I8+G8 -> 5057415 | BX8: ='Aging Analysis'!C29 -> 170536684
A9: 4 | B9: Строительство | C9: =D9+F9+H9+J9+L9 -> 178688875 | D9: 134857949 | F9: 43830926 | G9: 4383093 | N9: =+M9+K9+I9+G9 -> 4383093 | BX9: ='Aging Analysis'!C30 -> 178688875
A10: 5 | B10: Торговля и сфера общественных услуг | C10: =D10+F10+H10+J10+L10 -> 140213949 | D10: 79524975 | F10: 60688974 | G10: 6068897 | N10: =+M10+K10+I10+G10 -> 6068897 | BX10: ='Aging Analysis'!C31 -> 140213949
A11: 6 | B11: Материально-техническое снабжение и сбыт | C11: =D11+F11+H11+J11+L11 -> 127634911 | D11: 90547204 | F11: 37087707 | G11: 3708771 | N11: =+M11+K11+I11+G11 -> 3708771 | BX11: ='Aging Analysis'!C32 -> 127634911
A12: 7 | B12: Жилищно-коммунальные услуги | C12: =D12+F12+H12+J12+L12 -> 0 | D12: 0 | F12: 0 | N12: =+M12+K12+I12+G12 -> 0 | BX12: ='Aging Analysis'!C33 -> 0
A13: 8 | B13: Другие сектора | C13: =D13+F13+H13+J13+L13 -> 151977016 | D13: 108146090 | F13: 43830926 | G13: 4383092 | N13: =+M13+K13+I13+G13 -> 4383092 | BX13: ='Aging Analysis'!C34 -> 151977016
A14: 9 | B14: Итого кредита и лизинга | C14: =SUM(C6:C13) -> 1286122515 | D14: =SUM(D6:D13) -> 948961546 | E14: =SUM(E6:E13) -> 0 | F14: =SUM(F6:F13) -> 337160969 | G14: =SUM(G6:G13) -> 33716097 | H14: =SUM(H6:H13) -> 0 | I14: =SUM(I6:I13) -> 0 | J14: =SUM(J6:J13) -> 0 | ... M14: =SUM(M6:M13) -> 0 | N14: =+M14+K14+I14+G14 -> 33716097 | BX14: ='Aging Analysis'!C36 -> 1286122515
A15: 10 | B15: Другие классифицированные активы | C15: =D15+F15+H15+J15+L15 -> 0 | N15: =+M15+K15+I15+G15 -> 0
A16: 11 | B16: Всего классифицированных активов | C16: =SUM(C14:C15) -> 1286122515 | D16: =SUM(D14:D15) -> 948961546 | E16: =SUM(E14:E15) -> 0 | F16: =SUM(F14:F15) -> 337160969 | G16: =SUM(G14:G15) -> 33716097 | H16: =SUM(H14:H15) -> 0 | I16: =SUM(I14:I15) -> 0 | J16: =SUM(J14:J15) -> 0 | ... M16: =SUM(M14:M15) -> 0 | N16: =+M16+K16+I16+G16 -> 33716097
B18: Подпись Председателя правления:
B20: Подпись Главного Бухгалтера:

Sheet Loans to Affiliated P.
I1: Приложение №1 к Рекомендациям по заполнению отчетности коммерческих банков по банковскому надзору представляемых Центральному банку Республики Узбекистан
A2: Отчет о кредитах и лизинге, выданным связанным лицам | J2: Таблица-11 (Форма-1624LCO)
A3: =Balance!A4 -> 43100 | I3: =Balance!B3 -> АКБ "Микрокредитбанк"
A5: № | B5: Наименования клиента | C5: Номер группы | D5: Дата выдачи | E5: Дата погашения | F5: Основная сумма кредита | G5: Текущая кредитная задолженность | H5: Пересмотрения | I5: Цель кредита | J5: Тип залога | K5: Классификация | L5: Источник кредита
B6: А | C6: Б | D6: В | E6: Г | F6: Д | G6: Е | H6: Ж | I6: З | J6: И | K6: К | L6: Л
A7: 1 | B7: Хасанов М. | C7: 1 | D7: 39961 | E7: 45448 | F7: 55500 | G7: 28003 | I7: 60011-Кредиты, выданные населению на приобретение квартиры в многоквартирных домах | J7: 22-Недвижимость (ипотека) | K7: 1-Хороший | L7: собственный
A8: =A7+1 -> 2 | B8: Раджаметов М. | C8: 1 | D8: 40157 | E8: 43809 | F8: 50000 | G8: 17361 | I8: 60011-Кредиты, выданные населению на приобретение квартиры в многоквартирных домах | J8: 22-Недвижимость (ипотека) | K8: 1-Хороший | L8: собственный
A9: =A8+1 -> 3 | B9: Пулатова М. | C9: 1 | D9: 41533 | E9: 45160 | F9: 100000 | G9: 84337 | I9: 60011-Кредиты, выданные населению на приобретение квартиры в многоквартирных домах | J9: 22-Недвижимость (ипотека) | K9: 1-Хороший | L9: собственный
A10: =A9+1 -> 4 | B10: Якубова Н. | C10: 1 | D10: 40017 | E10: 45498 | F10: 37500 | G10: 20833 | I10: 60011-Кредиты, выданные населению на приобретение квартиры в многоквартирных домах | J10: 22-Недвижимость (ипотека) | K10: 1-Хороший | L10: собственный
A11: =A10+1 -> 5 | B11: Саксонов А. | C11: 1 | D11: 40540 | E11: 46019 | F11: 52500 | G11: 14900 | I11: 60011-Кредиты, выданные населению на приобретение квартиры в многоквартирных домах | J11: 22-Недвижимость (ипотека) | K11: 1-Хороший | L11: собственный
A12: =A11+1 -> 6 | B12: ISMATULLOYEV AKRAM AKMALOVICH | C12: 1 | D12: 42611 | E12: 48088 | F12: 260000 | G12: 260000 | I12: 60011-Кредиты, выданные населению на приобретение квартиры в многоквартирных домах | J12: 22-Недвижимость (ипотека) | K12: 1-Хороший | L12: собственный
A13: =A12+1 -> 7
A14: =A13+1 -> 8
A15: =A14+1 -> 9
A16: =A15+1 -> 10
A17: =A16+1 -> 11
A18: =A17+1 -> 12
A19: =A18+1 -> 13
A20: =A19+1 -> 14
A21: =A20+1 -> 15
A22: =A21+1 -> 16
A23: =A22+1 -> 17
A24: =A23+1 -> 18
... A36: =A35+1 -> 30
A37: =A36+1 -> 31 | B37: ИТОГО СУММА КРЕДИТОВ/ ЛИЗИНГА СВЯЗАННЫМ ЛИЦАМ | F37: =SUM(G7:G36) -> 425434
A38: =A37+1 -> 32 | B38: САМЫЙ КРУПНЫЙ КРЕДИТ/ ЛИЗИНГ ОДНОМУ ИНСАЙДЕРУ | F38: =MAX(G7:G36) -> 260000
B40: Подпись Председателя правления:
B42: Подпись Главного Бухгалтера:

Sheet Twenty Largest
I1: Приложение №1 к Рекомендациям по заполнению отчетности коммерческих банков по банковскому надзору представляемых Центральному банку Республики Узбекистан
A2: Кредиты и лизинги к получению - двадцать крупнейших заёмщиков | J2: Таблица-12 (Форма-1574LBB)
A3: =Balance!A4 -> 43100 | I3: =Balance!B3 -> АКБ "Микрокредитбанк"
A5: № | B5: Наименования клиента | C5: Номер группы | D5: Дата выдачи | E5: Дата погашения | F5: Основная сумма кредиты | G5: Текущая кредитная задолженность | H5: Пересмотрения | I5: Цель кредита | J5: Тип залога | K5: Классификация | L5: Источник кредита
B6: А | C6: Б | D6: В | E6: Г | F6: Д | G6: Е | H6: Ж | I6: З | J6: И | K6: К | L6: Л
A7: 1 | P7: 0
A8: 2
A9: 3
A10: 4
A11: 5
A12: 6
A13: 7
A14: 8
A15: 9
A16: 10
A17: 11
A18: 12
A19: 13
... A36: 30
A37: 31 | B37: ИТОГО КРУПНЫХ КРЕДИТОВ/ ЛИЗИНГА | F37: =SUM(G7:G36) -> 0
A38: 32 | B38: САМЫЙ КРУПНЫЙ КРЕДИТ/ ЛИЗИНГ, ВЫДАННЫЙ БАНКОМ | F38: =MAX(G7:G36) -> 0
B40: Подпись Председателя правления:
B42: Подпись Главного Бухгалтера:
M45: Классификация
M46: К

Sheet Charge-offs and Recoveries
D1: Приложение №1 к Рекомендациям по заполнению отчетности коммерческих банков по банковскому надзору представляемых Центральному банку Республики Узбекистан
A2: ОТЧЕТ О CПИСАННЫХ И ВОЗВРАЩЕННЫХ ПЛАТЕЖАХ ИЗ РЕЗЕРВА ВОЗМОЖНЫХ ПОТЕРЬ ПО КРЕДИТАМ И ЛИЗИНГУ | E2: Таблица-13 (Форма-1598LKA)
B3: =Balance!A4 -> 43100 | D3: =Balance!B3 -> АКБ "Микрокредитбанк"
A4: Часть 1 Списания и возврат
B5: Списание - А | D5: Возврат - Б
B6: Всего | C6: в иностранной валюте | D6: Всего | E6: в иностранной валюте
A7: А | B7: Б | C7: В | D7: Г | E7: Д
A8: 1. Промышленность | B8: 3916716 | D8: 695049
A9: 2. Сельское хозяйство | B9: 77336760 | D9: 5530423
A10: 3. Транспорт и коммуникации | B10: 6390713 | D10: 720777
A11: 4. Строительство | B11: 5882656 | D11: 1555242
A12: 5. Торговля и общественное питание | B12: 7868824 | D12: 1284975
A13: 6. Материально-техническое снабжение и сбыт | B13: 897061 | D13: 0
A14: 7. Жилищно-коммунальные услуги | B14: 0 | D14: 0
A15: 8. Другие сектора | B15: 11566269 | D15: 644772
A16: 9. Итого | B16: =SUM(B8:B15) -> 113858999 | C16: =SUM(C8:C15) -> 0 | D16: =SUM(D8:D15) -> 10431238 | E16: =SUM(E8:E15) -> 0
A19: Часть 2
A20: Изменения в резерве возможных убытков по кредитам и лизингу
A21: 1. Остаток на начало текущего года | C21: 1173488
A22: 2. Плюс: Возвращенные платежи | C22: =D16 -> 10431238
A23: 3. Минус: Списанные кредиты и лизинги | C23: =B16 -> 113858999
A24: 4. Отчисления в резерв по состоянию на дату от начала года | C24: 86761235
A25: 5. Поправки | C25: 49209135
A26: 6. Текущий баланс | C26: =SUM(C21:C22)-C23+SUM(C24:C25) -> 33716097 | D26: =Balance!B22 -> 33716097 | E26: ='Loan Classification'!N14 -> 33716097
A28: Подпись Председателя правления:
A30: Подпись Главного Бухгалтера:

Sheet Deposits by Client
B1: Приложение №1 к Рекомендациям по заполнению отчетности коммерческих банков по банковскому надзору представляемых Центральному банку Республики Узбекистан
A2: ОТЧЕТ О ДЕПОЗИТАХ ПО ТИПАМ КЛИЕНТОВ Таблица-14 (Форма-2106DMC)
A3: =Balance!A4 -> 43100 | B3: =Balance!B3 -> АКБ "Микрокредитбанк" | C3: в тыс. сум
A4: Категории | B4: Всего | C4: в том числе в иностранной валюте
A5: 1. Депозиты до востребования
A6: а. Правительство | B6: 4533100 | C6: 0
A7: б. Физические лица | B7: 89954541 | C7: 11187202
A8: в. Государственные предприятия | B8: 108650817 | C8: 222607
A9: г. Совместные и иностранные предприятия | B9: 5121972 | C9: 4340017
A10: д. Частные товарищества и корпорации | B10: 81567352 | C10: 1858764
A11: е. Другие депозиты до востребования | B11: 68048088 | C11: 18443567
A12: ж. Итого депозитов до востребования | B12: =SUM(B6:B11) -> 357875870 | C12: =SUM(C6:C11) -> 36052157
A14: 2. Сберегательные депозиты
A15: а. Правительство | B15: 0 | C15: 0
A16: б. Физические лица | B16: 17605402 | C16: 374396
A17: в. Государственные предприятия | B17: 0 | C17: 0
A18: г. Совместные и иностранные предприятия | B18: 0 | C18: 0
A19: д. Частные товарищества и корпорации | B19: 3711173 | C19: 0
A20: е. Другие сберегательные депозиты | B20: 50799 | C20: 0
A21: ж. Итого сберегательных депозитов | B21: =SUM(B15:B20) -> 21367374 | C21: =SUM(C15:C20) -> 374396
A23: 3. Срочные депозиты
A24: а. Правительство | B24: 319400000 | C24: 0
A25: б. Физические лица | B25: 112319624 | C25: 0
A26: в. Государственные предприятия | B26: 94295850 | C26: 81255850
A27: г. Совместные и иностранные предприятия | B27: 34975000 | C27: 0
A28: д. Частные товарищества и корпорации | B28: 8275372 | C28: 0
A29: е. Другие срочные депозиты | B29: 73495394 | C29: 0
A30: ж. Итого срочных депозитов | B30: =SUM(B24:B29) -> 642761240 | C30: =SUM(C24:C29) -> 81255850
A32: 4. Итого депозитов | B32: =B12+B21+B30 -> 1022004484 | C32: =C12+C21+C30 -> 117682403
A34: Примечание:
A35: Были ли случаи, что банк не смог выплатить вкладчику основную сумму вклада или же процент в течение квартала?
A37: Подпись Председателя правления:
A39: Подпись Главного Бухгалтера:

Sheet Investment Securities
B1: Приложение №1 к Рекомендациям по заполнению отчетности коммерческих банков по банковскому надзору представляемых Центральному банку Республики Узбекистан
A2: ОТЧЕТ ОБ ИНВЕСТИЦИЯХ В ЦЕННЫЕ БУМАГИ И СЧЕТА КУПЛИ-ПРОДАЖИ АКТИВОВ | C2: Таблица-15 (Форма-1726SEC )
A3: =+Balance!A4 -> 43100 | C3: =Balance!B3 -> АКБ "Микрокредитбанк"
A4: Часть 1 - Инвестиции в ценные бумаги | B4: Балансовая стоимость | C4: Рыночная стоимость
A6: 1. Инвестиции в государственные облигации | B6: 0
A7: 2. Инвестиции в ценные бумаги и облигации ЦБРУ | B7: 0
A8: 3. Инвестиции в частные облигации | B8: 0
A9: 4. Инвестиции в еврооблигации | B9: 0
A10: 5. Инвестиции в акции гос предприятий | B10: 0
A11: 6. Инвестиции в акции частных предприятий | B11: 0
A12: 7. Инвестиции в другие ценные бумаги | B12: 2750000
A13: 8. Итого инвестиций | B13: =SUM(B6:B12) -> 2750000 | C13: =SUM(C6:C12) -> 0
A14: 9. Минус: Резерв возможных убытков | B14: 1
A15: 10. Чистая балансовая стоимость инвестиций | B15: =B13-B14 -> 2749999
A17: Часть 2 - Счета купли-продажи ценных бумаг | B17: Балансовая стоимость | C17: Рыночная стоимость
A19: 1. Государственные казначейские векселя | B19: 0
A20: 2. Государственные облигации | B20: 0
A21: 3. Ценные бумаги и облигации ЦБРУ | B21: 0
A22: 4. Ценные бумаги гос корпораций | B22: 0
A23: 5. Еврооблигации | B23: 0
A24: 6. Частные ценные бумаги | B24: 349524
A25: 7. Другие ценные бумаги | B25: 0
A26: 8. Итого по счетам купли-продажи ценных бумаг | B26: =SUM(B19:B25) -> 349524 | C26: =SUM(C19:C25) -> 0
A27: 9. Минус: Резерв возможных убытков
A28: 10. Чистая балансовая стоимость по счетам купли-продажи ц/б | B28: =B26-B27 -> 349524
A32: Часть 3 - Счета купли и продажи драгоценных металлов | B32: Первоначальная стоимость | C32: Рыночная стоимость
A34: 1. Драгоценные металлы | B34: 0
A35: 2. Драгоценные камни | B35: 0
A36: 3. Драгоценные монеты | B36: 175
A37: 5. Итого драгоценных металлов | B37: =SUM(B34:B36) -> 175 | C37: =SUM(C34:C36) -> 0
A38: 6. Минус: Резерв возможных убытков | B38: 0
A39: 7. Чистая балансовая стоимость по счетам купли и продажи д/м | B39: =B37-B38 -> 175
A41: Примечание:
A42: Итого ценных бумаг заложенных для общественных депозитов
A43: Портфель инвестиций в ценные бумаги
A44: Увеличение (Снижение) стоимости | B44: =C13-B13 -> -2750000
A45: Счета купли-продажи ценных бумаг
A46: Увеличение (Снижение) стоимости | B46: =C26-B26 -> -349524
A47: Счета купли-продажи драгоценных предметов
A48: Увеличение (Снижение) стоимости | B48: =C37-B37 -> -175
...

Sheet Liquidity Analysis
B1: Приложение №1 к Рекомендациям по заполнению отчетности коммерческих банков по банковскому надзору представляемых Центральному банку Республики Узбекистан
A2: АНАЛИЗ ЛИКВИДНОСТИ | B2: Таблица-16 (Форма-0022AAL)
A3: =Balance!A4 -> 43100 | B3: =Balance!B3 -> АКБ "Микрокредитбанк"
A4: Часть 1. Ликвидные активы | B4: в тыс. сум
A6: 1. Касса (наличность и монеты) и Драгоценные металлы | B6: 76954356
A7: 2. К получению из ЦБРУ | B7: 213192148
A8: 3. К получению из других банков | B8: 78170286
A9: 4. Ценные бумаги, выпущенные Правительством Республики Узбекистан и ЦБРУ (векселя, облигации и другие долговые ценные бумаги) | B9: 0
A10: 5. Ценные бумаги, выпущенные странами с низким уровня риска | B10: 0
A11: 6. Другие легко реализуемые ценные бумаги | B11: 0
A12: 7. Итого ликвидных активов | B12: =SUM(B6:B11) -> 368316790
A13: 8. Плюс: Кредиты и лизинги со сроком погашения 30 дней или менее | B13: 63112110
A14: 9. Минус: Просроченные, неблагоприятно классифицированные, неначисляемые, пролонгированные, или реструктуризированные кредиты и лизинги, включенные в строку 8. | B14: 10196060
A15: 10. Текущие Активы | B15: =SUM(B12:B13)-B14 -> 421232840
A17: Часть 2. Коэфициенты наличности и ликвидности | B17: в процентах
A19: 1. Коэффициент наличности
A20: а. Итого кассы разделить на
A21: среднее активов за текущий квартал | B21: =IF(B36=0,0,(B6/B36)) -> 0
A22: 2. Коэффициент ликвидности
A23: а. Итого ликвидных активов разделить на
A24: среднее активов за текущий квартал | B24: =IF(B36=0,0,(B7/B36)) -> 0
A25: 3. Непостоянные обязательства/ среднее активов за текущий квартал | B25: 0
A26: 4. Ликвидные активы/ Непостоянные обязательства | B26: 0
A27: 5. Кредиты (чистые)/ Депозиты | B27: =IF('Deposits by Client'!B32=0,"",Balance!C23/'Deposits by Client'!B32) -> 1.2254412
A28: 6 Заложенные ценные бумаги/ Общая сумма ценных бумаг
A30: Часть 3. Экономические нормативы - Ликвидность
A32: 1. Расчет коэффициента текущей ликвидности (Н4) | B32: =B15/('Bank Liabilities Analysis'!C33+'Bank Liabilities Analysis'!D33) -> 0.93350739
A35: Примечание:
A36: Укажите среднедневную сумму активов за текущий период, рассчитанную компьютерной системой действующей в банке.
A37: Часть 4.
A38: 1. Коэффициент покрытия ликвидности | B38: ='Bank Assets Analysis'!K41/'Bank Assets Analysis'!K42 -> 2.3779889
A39: а) Высоколиквидные активы | B39: =+'Bank Assets Analysis'!K41 -> 368659820
A40: б) Чистый отток в последующие 30 дней | B40: =+'Bank Assets Analysis'!K42 -> 1.5503009e+08
A41: 2. Норма чистого стабильного финансирования | B41: =+B42/B47 -> 1.0145831
A42: 3. Доступная сумма стабильного финансирования | B42: =SUM(B43:B46) -> 1.1029413e+09
A43: а) Регулятивный капитал | B43: =+'Bank Capital Calc.'!E44 -> 5.4048778e+08
A44: б) Обязательства свыше 1 года | B44: =+'Bank Liabilities Analysis'!G33 -> 290411542
A45: в) 30% других бессрочных обязательств | B45: =+('Bank Liabilities Analysis'!C33)*0.3 -> 1.1463425e+08
A46: г) 30% других обязательств менее 1 года | B46: =+('Bank Liabilities Analysis'!D33+'Bank Liabilities Analysis'!E33+'Bank Liabilities Analysis'!F33)*0.3 -> 1.5740774e+08
A47: 4. Необходимая сумма стабильного финансирования | B47: =SUM(B48:B53) -> 1087088150
...

Sheet Bank Assets Analysis
I1: Приложение №1 к Рекомендациям по заполнению отчетности коммерческих банков по банковскому надзору представляемых Центральному банку Республики Узбекистан
A2: АНАЛИЗ АКТИВОВ БАНКА | I2: Таблица-17 (Форма-0024AAL)
A3: =Balance!A4 -> 43100 | I3: =Balance!B3 -> АКБ "Микрокредитбанк"
A5: № | B5: Характеристики | C5: Дата погашения (в днях) | H5: ВСЕГО | I5: Коэффициент | J5: Сумма активов | K5: Высоко-ликвидные активы
C6: Бессрочные | D6: от 1 до 30 | E6: от 31 до180 | F6: от 181до 365 | G6: Свыше 365
B7: (А) | C7: (Б) | D7: (В) | E7: (Г) | F7: (Д) | G7: (Е) | H7: (Ж) | I7: (З) | J7: (И) | K7: (К=З*И)
B8: АКТИВЫ
A9: 1. | B9: Наличность и другие кассовые документы | C9: 76954182 | H9: =SUM(C9:G9) -> 76954182 | I9: 1 | J9: =+C9 -> 76954182 | K9: =+J9*I9 -> 76954182
A10: 2. | B10: К получению из ЦБРУ не учитывая сумму "Резервов на покрытие возможных убытков" (без ДОР) | C10: 129692339 | D10: 83499809 | H10: =SUM(C10:G10) -> 213192148 | I10: 1 | J10: =+C10+D10 -> 213192148 | K10: =+J10*I10 -> 213192148
A11: 2.1 | B11: К получению из ЦБРУ (сумма созданных резервов на покрытие возможных убытков по активам банка (ДОР)) | H11: =SUM(C11:G11) -> 0 | I11: 0 | J11: =+C11 -> 0 | K11: =+J11*I11 -> 0
A12: 3. | B12: К получению из других банков | C12: =+C13+C14+C15 -> 78174640 | D12: =+D13+D14+D15 -> 368204 | E12: =+E13+E14+E15 -> 0 | F12: =+F13+F14+F15 -> 0 | G12: =+G13+G14+G15 -> 0 | H12: =SUM(C12:G12) -> 78542844 | K12: =+J12*I12 -> 0
A13: 3.1 | B13: К получению со счетов в банках стран с низким уровнем риска (ностро, депозиты), но размещенные не в качестве обеспечения | C13: 78145286 | D13: 368204 | H13: =SUM(C13:G13) -> 78513490 | I13: 1 | J13: =+H13 -> 78513490 | K13: =+J13*I13 -> 78513490
A14: 3.2 | B14: К получению из других банков по расчетам пластиковых карт | C14: 4354 | H14: =SUM(C14:G14) -> 4354 | I14: 0.5 | J14: =+H14 -> 4354 | K14: =+J14*I14 -> 2177
A15: 3.3 | B15: Другие статьи | C15: 25000 | H15: =SUM(C15:G15) -> 25000 | I15: 0 | J15: =+H15 -> 25000 | K15: =+J15*I15 -> 0
A16: 4. | B16: Счета купли и продажи, чистые | C16: =+C17+C18+C19+C20 -> 349699 | D16: =+D17+D18+D19+D20 -> 0 | E16: =+E17+E18+E19+E20 -> 0 | F16: =+F17+F18+F19+F20 -> 0 | G16: =+G17+G18+G19+G20 -> 0 | H16: =SUM(C16:G16) -> 349699 | K16: =+J16*I16 -> 0
A17: 4.1 | B17: Ценные бумаги, выпущенные Правительством Республики Узбекистан и ЦБРУ (векселя, облигации и другие долговые ценные бумаги) | H17: =SUM(C17:G17) -> 0 | I17: 1 | J17: =+C17+D17 -> 0 | K17: =+J17*I17 -> 0
A18: 4.2 | B18: Правительственные ценные бумаги стран с низкой степенью странового риска | H18: =SUM(C18:G18) -> 0 | I18: 1 | J18: =+C18+D18 -> 0 | K18: =+J18*I18 -> 0
A19: 4.3 | B19: Ценные бумаги ведущих транснациональных компаний с низким уровнем странового риска | H19: =SUM(C19:G19) -> 0 | I19: 1 | J19: =+C19+D19 -> 0 | K19: =+J19*I19 -> 0
A20: 4.4 | B20: Другие | C20: 349699 | H20: =SUM(C20:G20) -> 349699 | I20: 0 | J20: =+C20+D20 -> 349699 | K20: =+J20*I20 -> 0
A21: 5. | B21: Купленные векселя, чистые | H21: =SUM(C21:G21) -> 0 | I21: 0.3 | J21: =+C21+D21 -> 0 | K21: =+J21*I21 -> 0
A22: 6. | B22: Обязательства клиентов по траттам под аккредитивы или трастовые документы | H22: =SUM(C22:G22) -> 0 | I22: 0.3 | J22: =+C22+D22 -> 0 | K22: =+J22*I22 -> 0
A23: 7. | B23: Обязательства клиентов по непогашенным акцептам этого банка | H23: =SUM(C23:G23) -> 0 | I23: 0.3 | J23: =+C23+D23 -> 0 | K23: =+J23*I23 -> 0
A24: 8. | B24: Кредиты и лизинги, предоставленные ЦБРУ, чистые | H24: =SUM(C24:G24) -> 0 | I24: 1 | J24: =+C24+D24 -> 0 | K24: =+J24*I24 -> 0
A25: 9. | B25: Кредиты и лизинги, предоставленные другим банкам, чистые | H25: =SUM(C25:G25) -> 0 | I25: 0.5 | J25: =+D25 -> 0 | K25: =+J25*I25 -> 0
A26: 10 | B26: Кредиты и лизинги, предоставленные другим клиентам, чистые | C26: 10299194 | D26: 52916050 | E26: 90771118 | F26: 277145504 | G26: 821377684 | H26: =SUM(C26:G26) -> 1252509550 | I26: 0.3 | J26: =+D26 -> 52916050 | K26: =+J26*I26 -> 15874815
A27: 11 | B27: Кредиты и лизинги и авансы в процессе судебного разбирательства, чистые | C27: -103134 | H27: =SUM(C27:G27) -> -103134 | I27: 0 | J27: =+C27+D27 -> -103134 | K27: =+J27*I27 -> 0
A28: 12. | B28: Инвестиции, чистые | G28: 2749999 | H28: =SUM(C28:G28) -> 2749999 | I28: 0 | J28: =+C28+D28 -> 0 | K28: =+J28*I28 -> 0
A29: 13. | B29: Ценные бумаги купленные по соглашению с обратным выкупом | C29: =+C30+C31 -> 0 | D29: =+D30+D31 -> 0 | E29: =+E30+E31 -> 0 | F29: =+F30+F31 -> 0 | G29: =+G30+G31 -> 0 | H29: =SUM(C29:G29) -> 0 | K29: =+J29*I29 -> 0
A30: 13.1 | B30: Правительственные ценные бумаги купленные по соглашению с обратным выкупом (РЕПО) | H30: =SUM(C30:G30) -> 0 | I30: 0.3 | J30: =+C30+D30 -> 0 | K30: =+J30*I30 -> 0
A31: 13,2 | B31: Другие ценные бумаги купленные по соглашению с обратным выкупом (РЕПО) | H31: =SUM(C31:G31) -> 0 | I31: 0 | J31: =+C31+D31 -> 0 | K31: =+J31*I31 -> 0
A32: 14. | B32: Банковские помещения, мебель и оборудование, чистые | G32: 100870267 | H32: =SUM(C32:G32) -> 100870267 | I32: 0 | J32: =+C32+D32 -> 0 | K32: =+J32*I32 -> 0
A33: 15. | B33: Недвижимость и другое собственное имущество, чистые | D33: 1613115 | H33: =SUM(C33:G33) -> 1613115 | I33: 0 | J33: =+C33+D33 -> 1613115 | K33: =+J33*I33 -> 0
A34: 16. | B34: Нереализованная прибыль при ревальвации по сделкам "форвард" | H34: =SUM(C34:G34) -> 0 | I34: 0 | J34: =+C34+D34 -> 0 | K34: =+J34*I34 -> 0
A35: 17. | B35: Счета купли-продажи валюты и валютные позиции | H35: =SUM(C35:G35) -> 0 | I35: 0 | J35: =+C35+D35 -> 0 | K35: =+J35*I35 -> 0
A36: 18. | B36: Клиринговые счета | H36: =SUM(C36:G36) -> 0 | I36: 0 | J36: =+C36+D36 -> 0 | K36: =+J36*I36 -> 0
A37: 19. | B37: Начисленные проценты | C37: 7348132 | H37: =SUM(C37:G37) -> 7348132 | I37: 0.3 | J37: =+D37 -> 0 | K37: =+J37*I37 -> 0
A38: 20. | B38: Другие активы | C38: 8966247 | H38: =SUM(C38:G38) -> 8966247 | I38: 0 | J38: =+C38+D38 -> 8966247 | K38: =+J38*I38 -> 0
A39: 21. | B39: ИТОГО АКТИВОВ | C39: =SUM(C9:C38)-C12-C16-C29 -> 311681299 | D39: =SUM(D9:D38)-D12-D16-D29 -> 138397178 | E39: =SUM(E9:E38)-E12-E16-E29 -> 90771118 | F39: =SUM(F9:F38)-F12-F16-F29 -> 277145504 | G39: =SUM(G9:G38)-G12-G16-G29 -> 924997950 | H39: =SUM(H9:H38)-H12-H16-H29 -> 1742993049 | K39: =SUM(K9:K38)-K12-K29 -> 384536812
C40: =+C39-C27-C9-C10-C12-C16-C25 -> 26613573 | D40: =+D39-D27-D9-D10-D12-D16-D25 -> 54529165 | E40: =+E39-E27-E9-E10-E12-E16-E25 -> 90771118 | F40: =+F39-F27-F9-F10-F12-F16-F25 -> 277145504 | I40: Ликвидные активы | K40: =+K39-K41 -> 15876992
B41: * Примечание: Показать раздельно суммы | C41: =+C40+D40+E40+F40 -> 449059360 | D41: =+C41*0.3 -> 134717808 | I41: Активы с риском 0% | K41: =+K9+K10+K13+K17+K18 -> 368659820
...

Sheet Bank Liabilities Analysis
I1: Приложение №1 к Рекомендациям по заполнению отчетности коммерческих банков по банковскому надзору представляемых Центральному банку Республики Узбекистан
A2: АНАЛИЗ ОБЯЗАТЕЛЬСТВ БАНКА | I2: Таблица-18 (Форма-0026AAL)
A3: =Balance!A4:A4 -> 43100 | I3: =Balance!B3 -> АКБ "Микрокредитбанк"
A5: № | B5: Характеристики | D5: Срок погашения (в днях) | H5: ВСЕГО | I5: Коэффициент | J5: Сумма расхода за 30 дней | K5: Сумма чистого расхода за 30 дней
C6: Бессрочные | D6: от 1 до 30 | E6: от 31 до180 | F6: от 181до 365 | G6: Свыше 1 года
B7: (А) | C7: (Б) | D7: (В) | E7: (Г) | F7: (Д) | G7: (Е) | H7: (Ж) | I7: (З) | J7: (И) | K7: (К=З*И)
B8: ОБЯЗАТЕЛЬСТВА
A9: 1. | B9: ДЕПОЗИТЫ
A10: 1.1 | B10: Депозиты до востребования | C10: =SUM(C11:C15) -> 235562823 | D10: =SUM(D11:D15) -> 0 | E10: =SUM(E11:E15) -> 0 | F10: =SUM(F11:F15) -> 0 | G10: =SUM(G11:G15) -> 582695 | H10: =SUM(C10:G10) -> 236145518
A11: а) | B11: Вклады населения до востребования (гарантированные) | C11: 14481346 | H11: =SUM(C11:G11) -> 14481346 | I11: 0.1 | J11: =+C11+D11 -> 14481346 | K11: =+J11*I11 -> 1448134.6
A12: б) | B12: Вклады населения до востребования (не гарантированные) | H12: =SUM(C12:G12) -> 0 | I12: 0.15 | J12: =+C12+D12 -> 0 | K12: =+J12*I12 -> 0
A13: в) | B13: Вклады населения до востребования (под залогом по выданным кредитам) | G13: 582695 | H13: =SUM(C13:G13) -> 582695 | I13: 0 | J13: =+C13+D13 -> 0 | K13: =+J13*I13 -> 0
A14: г) | B14: Другие депозиты до востребования (под залогом по выданным кредитам) | H14: =SUM(C14:G14) -> 0 | I14: 0 | J14: =+C14+D14 -> 0 | K14: =+J14*I14 -> 0
A15: д) | B15: Другие депозиты до востребования | C15: 221081477 | H15: =SUM(C15:G15) -> 221081477 | I15: 0.3 | J15: =+C15+D15 -> 221081477 | K15: =+J15*I15 -> 66324443
