Workbook
Name jop: #REF!
Name kol: #REF!
Name RISKTOTASS: SUM('[6]Calculation of Risk Weighted As'!$C$38:$F$38)
Name RISKTOTASS: SUM('[7]Calculation of Risk Weighted As'!$C$41:$G$41)
Name TwentyLargestData: #REF!
Name Е: #REF!

Sheet Asset quality
A1: АКТИВЛАР ТАСНИФИ ВА УЛАР БЎЙИЧА ЯРАТИЛГАН ЭҲТИМОЛИЙ ЙЎҚОТИШЛАРНИ ҚОПЛАШ ЗАХИРАЛАРИ ТЎҒРИСИДА ҲИСОБОТ | S1: 2-жадвал | V1: №6
B3: "Ўзсаноатқурилишбанк" АТБ | Q3: 44925 | T3: минг. сўмда
A4: № | B4: Активлар таркиби* | C4: Қолдиқ | D4: Сифат тоифаси | I4: Муддати ўтган қарздорлик (брутто) | O4: Зарарларни қоплаш захираси
I5: Жами | J5: 30 кунгача | K5: 31дан 90 кунгача | L5: 91дан 180 кунгача | M5: 181 дан 365 кунгача | N5: 366 кун ва ундан ортиқ | O5: ҳақиқатдан яратилган захиралар
O6: Жами | P6: сифат тоифаси бўйича
D7: I | E7: II | F7: III | G7: IV | H7: V | P7: I | Q7: II | R7: III | S7: IV | T7: V
A8: А | B8: Б | C8: В | D8: Г | E8: Д | F8: Е | G8: Ж | H8: З | I8: И | J8: К | K8: Л | L8: М | M8: Н | N8: О | O8: П | P8: Р | Q8: С | R8: Т | S8: У | T8: Ф
B9: Жами активлар | C9: =SUM(C10:C58)+C60-C59 -> 64263771349 | D9: =SUM(D10:D58)-D59+D60 -> 60944572016 | E9: =SUM(E10:E58)-E59+E60 -> 2691462008 | F9: =SUM(F10:F58)-F59+F60 -> 507333345 | G9: =SUM(G10:G58)-G59+G60 -> 1000162337 | H9: =SUM(H10:H58)-H59+H60 -> 257499868 | I9: =SUM(I10:I60) -> 988593441 | J9: =SUM(J10:J60) -> 96264988 | K9: =SUM(K10:K60) -> 283830528 | L9: =SUM(L10:L60) -> 264621199 | M9: =SUM(M10:M60) -> 314624827 | N9: =SUM(N10:N60) -> 29251899 | O9: =SUM(O10:O60) -> 1659124432 | P9: =SUM(P10:P60) -> 521866207 | ... T9: =SUM(T10:T60) -> 222940564
A10: 1 | B10: Кассадаги нақд пул ва бошқа тўлов ҳужжатлари | C10: =SUM(D10:H10)-O10+P10 -> 1558319960 | D10: 1558319960 | E10: 0 | F10: 0 | G10: 0 | H10: 0 | I10: =SUM(J10:N10) -> 0 | O10: =SUM(P10:T10) -> 0 | P10: 0 | Q10: 0 | R10: 0 | S10: 0 | T10: 0 | U10: 10100
A11: 2 | B11: Банкнинг Марказий банкдаги маблағлар | C11: =SUM(D11:H11)-O11+P11 -> 1510578445 | D11: 1510578445 | E11: 0 | F11: 0 | G11: 0 | H11: 0 | I11: =SUM(J11:N11) -> 0 | O11: =SUM(P11:T11) -> 0 | P11: 0 | Q11: 0 | R11: 0 | S11: 0 | T11: 0 | U11: 10300
A12: 3 | B12: Бошқа банклар ва молиявий ташкилотлардан олиниши лозим бўлган маблағлар | C12: =SUM(D12:H12)-O12+P12 -> 6508984468 | D12: 6508984468 | E12: 0 | F12: 0 | G12: 0 | H12: 33976380 | I12: =SUM(J12:N12) -> 0 | O12: =SUM(P12:T12) -> 99066225 | P12: 65089845 | Q12: 0 | R12: 0 | S12: 0 | T12: 33976380 | U12: 10500
A13: 4 | B13: Фойда ёки зарар орқали ҳаққоний қийматда баҳоланадиган қимматли қоғозлар | C13: =SUM(D13:H13)-O13+P13 -> 2655203447 | D13: 2655203447 | E13: 0 | F13: 0 | G13: 0 | H13: 0 | I13: =SUM(J13:N13) -> 0 | O13: =SUM(P13:T13) -> 0 | P13: 0 | Q13: 0 | R13: 0 | S13: 0 | T13: 0 | U13: 10700
A14: 5 | B14: Бошқа умумлашган даромад орқали ҳаққоний қийматда баҳоланадиган қимматли қоғозларга қилинган инвестициялар | C14: =SUM(D14:H14)-O14+P14 -> 0 | D14: 0 | E14: 0 | F14: 0 | G14: 0 | H14: 0 | I14: =SUM(J14:N14) -> 0 | O14: =SUM(P14:T14) -> 0 | P14: 0 | Q14: 0 | R14: 0 | S14: 0 | T14: 0 | U14: 10800
A15: 6 | B15: Олди-сотдига мўлжалланган қимматбаҳо металлар, тошлар ва тангалар | C15: =SUM(D15:H15)-O15+P15 -> 875 | D15: 875 | E15: 0 | F15: 0 | G15: 0 | H15: 0 | I15: =SUM(J15:N15) -> 0 | O15: =SUM(P15:T15) -> 9 | P15: 9 | Q15: 0 | R15: 0 | S15: 0 | T15: 0 | U15: 10900
A16: 7 | B16: Сотиб олинган дебиторлик қарзлари — Факторинг | C16: =SUM(D16:H16)-O16+P16 -> 283941159 | D16: 283941159 | E16: 0 | F16: 0 | G16: 0 | H16: 0 | I16: =SUM(J16:N16) -> 0 | O16: =SUM(P16:T16) -> 2839412 | P16: 2839412 | Q16: 0 | R16: 0 | S16: 0 | T16: 0 | U16: 11100
A17: 8 | B17: Мижозларнинг аккредитив ва/ёки траст ҳужжатлари билан кафолатланган тратталари бўйича мажбуриятлари | C17: =SUM(D17:H17)-O17+P17 -> 47694399 | D17: 47694399 | E17: 0 | F17: 0 | G17: 0 | H17: 0 | I17: =SUM(J17:N17) -> 0 | O17: =SUM(P17:T17) -> 476944 | P17: 476944 | Q17: 0 | R17: 0 | S17: 0 | T17: 0 | U17: 11500
A18: 9 | B18: Банкнинг тўланмаган акцептлари бўйича мижозларнинг мажбуриятлари | C18: =SUM(D18:H18)-O18+P18 -> 0 | D18: 0 | E18: 0 | F18: 0 | G18: 0 | H18: 0 | I18: =SUM(J18:N18) -> 0 | O18: =SUM(P18:T18) -> 0 | P18: 0 | Q18: 0 | R18: 0 | S18: 0 | T18: 0 | U18: 11700
A19: 10 | B19: РЕПО битимлари бўйича сотиб олинган қимматли қоғозлар | C19: =SUM(D19:H19)-O19+P19 -> 0 | D19: 0 | E19: 0 | F19: 0 | G19: 0 | H19: 0 | I19: =SUM(J19:N19) -> 0 | O19: =SUM(P19:T19) -> 0 | P19: 0 | Q19: 0 | R19: 0 | S19: 0 | T19: 0 | U19: 11800
A20: 11 | B20: Марказий банкка берилган қисқа муддатли кредитлар | C20: =SUM(D20:H20)-O20+P20 -> 0 | D20: 0 | E20: 0 | F20: 0 | G20: 0 | H20: 0 | I20: =SUM(J20:N20) -> 0 | O20: =SUM(P20:T20) -> 0 | P20: 0 | Q20: 0 | R20: 0 | S20: 0 | T20: 0 | U20: 11900
A21: 12 | B21: Бошқа банкларга берилган қисқа муддатли кредитлар | C21: =SUM(D21:H21)-O21+P21 -> 0 | D21: 0 | E21: 0 | F21: 0 | G21: 0 | H21: 0 | I21: =SUM(J21:N21) -> 0 | O21: =SUM(P21:T21) -> 0 | P21: 0 | Q21: 0 | R21: 0 | S21: 0 | T21: 0 | U21: 12100
A22: 13 | B22: Ҳукуматга берилган қисқа муддатли кредитлар | C22: =SUM(D22:H22)-O22+P22 -> 0 | D22: 0 | E22: 0 | F22: 0 | G22: 0 | H22: 0 | I22: =SUM(J22:N22) -> 0 | O22: =SUM(P22:T22) -> 0 | P22: 0 | Q22: 0 | R22: 0 | S22: 0 | T22: 0 | U22: 12300
A23: 14 | B23: Бюджет ташкилотларига берилган қисқа муддатли кредитлар | C23: =SUM(D23:H23)-O23+P23 -> 0 | D23: 0 | E23: 0 | F23: 0 | G23: 0 | H23: 0 | I23: =SUM(J23:N23) -> 0 | O23: =SUM(P23:T23) -> 0 | P23: 0 | Q23: 0 | R23: 0 | S23: 0 | T23: 0 | U23: 12400
A24: 15 | B24: Жисмоний шахсларга берилган қисқа муддатли кредитлар | C24: =SUM(D24:H24)-O24+P24 -> 192018693 | D24: 190619423 | E24: 824220 | F24: 492025 | G24: 571217 | H24: 23941 | I24: =SUM(J24:N24) -> 1330970 | J24: 184668 | K24: 261812 | L24: 365976 | M24: 494755 | N24: 23759 | O24: =SUM(P24:T24) -> 2418327 | P24: 1906194 | Q24: 80437 | R24: 122147 | S24: 285608 | T24: 23941 | U24: 12500
A25: 16 | B25: Якка тартибдаги тадбиркорларга берилган қисқа муддатли кредитлар | C25: =SUM(D25:H25)-O25+P25 -> 46132525 | D25: 45113153 | E25: 1132636 | F25: 0 | G25: 0 | H25: 0 | I25: =SUM(J25:N25) -> 124747 | J25: 116565 | K25: 8182 | L25: 0 | M25: 0 | N25: 0 | O25: =SUM(P25:T25) -> 564396 | P25: 451132 | Q25: 113264 | R25: 0 | S25: 0 | T25: 0 | U25: 12600
A26: 17 | B26: Давлат корхоналари, ташкилотлари ва муассасаларига берилган қисқа муддатли кредитлар | C26: =SUM(D26:H26)-O26+P26 -> 2644342581 | D26: 2627395347 | E26: 18830260 | F26: 0 | G26: 0 | H26: 0 | I26: =SUM(J26:N26) -> 1754549 | J26: 0 | K26: 1754549 | L26: 0 | M26: 0 | N26: 0 | O26: =SUM(P26:T26) -> 28156979 | P26: 26273953 | Q26: 1883026 | R26: 0 | S26: 0 | T26: 0 | U26: 12700
A27: 18 | B27: Тадбиркорлик фаолиятини қўллаб-қувватлаш давлат жамғармаси кўмагида берилган қисқа муддатли кредитлар | C27: =SUM(D27:H27)-O27+P27 -> 154873173 | D27: 107408832 | E27: 24050379 | F27: 12924812 | G27: 26417752 | H27: 335987 | I27: =SUM(J27:N27) -> 48886846 | J27: 762434 | K27: 14684729 | L27: 14954366 | M27: 18149330 | N27: 335987 | O27: =SUM(P27:T27) -> 17338677 | P27: 1074088 | Q27: -511477 | R27: 3231203 | S27: 13208876 | T27: 335987 | U27: 12800
A28: 19 | B28: Чет эл капитали иштирокидаги корхоналарга берилган қисқа муддатли кредитлар | C28: =SUM(D28:H28)-O28+P28 -> 2071605949 | D28: 2067731539 | E28: 0 | F28: 0 | G28: 7748821 | H28: 0 | I28: =SUM(J28:N28) -> 7748821 | J28: 0 | K28: 0 | L28: 0 | M28: 7748821 | N28: 0 | O28: =SUM(P28:T28) -> 24551726 | P28: 20677315 | Q28: 0 | R28: 0 | S28: 3874411 | T28: 0 | U28: 12900
A29: 20 | B29: Нодавлат нотижорат ташкилотларига берилган қисқа муддатли кредитлар | C29: =SUM(D29:H29)-O29+P29 -> 888692 | D29: 888692 | E29: 0 | F29: 0 | G29: 0 | H29: 0 | I29: =SUM(J29:N29) -> 0 | J29: 0 | K29: 0 | L29: 0 | M29: 0 | N29: 0 | O29: =SUM(P29:T29) -> 8887 | P29: 8887 | Q29: 0 | R29: 0 | S29: 0 | T29: 0 | U29: 13000
A30: 21 | B30: Хусусий корхоналар, хўжалик ширкатлари ва жамиятларга берилган қисқа муддатли кредитлар | C30: =SUM(D30:H30)-O30+P30 -> 2389804204 | D30: 2167565789 | E30: 179961956 | F30: 56340014 | G30: 43128739 | H30: 3118638 | I30: =SUM(J30:N30) -> 114308313 | J30: 8172378 | K30: 14726247 | L30: 61560581 | M30: 28751052 | N30: 1098055 | O30: =SUM(P30:T30) -> 81986590 | P30: 21675658 | Q30: 19961421 | R30: 15666503 | S30: 21564370 | T30: 3118638 | U30: 13100
A31: 22 | B31: Банк бўлмаган молиявий муассасаларга берилган қисқа муддатли кредитлар | C31: =SUM(D31:H31)-O31+P31 -> 3441000 | D31: 3441000 | E31: 0 | F31: 0 | G31: 0 | H31: 0 | I31: =SUM(J31:N31) -> 0 | J31: 0 | K31: 0 | L31: 0 | M31: 0 | N31: 0 | O31: =SUM(P31:T31) -> 34410 | P31: 34410 | Q31: 0 | R31: 0 | S31: 0 | T31: 0 | U31: 13200
A32: 23 | B32: Давлат эҳтиёжлари учун харид қилинадиган қишлоқ хўжалиги маҳсулотларини етиштириш учун берилган қисқа муддатли кредитлар | C32: =SUM(D32:H32)-O32+P32 -> 0 | D32: 0 | E32: 0 | F32: 0 | G32: 0 | H32: 0 | I32: =SUM(J32:N32) -> 0 | J32: 0 | K32: 0 | L32: 0 | M32: 0 | N32: 0 | O32: =SUM(P32:T32) -> 0 | P32: 0 | Q32: 0 | R32: 0 | S32: 0 | T32: 0 | U32: 13300
A33: 24 | B33: Давлат эҳтиёжлари учун харид қилинадиган қишлоқ хўжалиги маҳсулотларини етиштириш учун берилган узоқ муддатли кредитлар | C33: =SUM(D33:H33)-O33+P33 -> 1652275495 | D33: 1652275495 | E33: 0 | F33: 0 | G33: 0 | H33: 0 | I33: =SUM(J33:N33) -> 2104992 | J33: 2104992 | K33: 0 | L33: 0 | M33: 0 | N33: 0 | O33: =SUM(P33:T33) -> 16522755 | P33: 16522755 | Q33: 0 | R33: 0 | S33: 0 | T33: 0 | U33: 14300
A34: 25 | B34: Тадбиркорлик фаолиятини қўллаб-қувватлаш давлат жамғармаси кўмагида берилган узоқ муддатли кредитлар | C34: =SUM(D34:H34)-O34+P34 -> 3482004636 | D34: 2691959341 | E34: 632888609 | F34: 154748726 | G34: 195717001 | H34: 39238546 | I34: =SUM(J34:N34) -> 130907677 | J34: 22955573 | K34: 30860755 | L34: 20959439 | M34: 44440642 | N34: 11691268 | O34: =SUM(P34:T34) -> 259467180 | P34: 26919593 | Q34: 57829778 | R34: 37620763 | S34: 97858500 | T34: 39238546 | U34: 14400
A35: 26 | B35: Бошқа банкларга берилган узоқ муддатли кредитлар | C35: =SUM(D35:H35)-O35+P35 -> 0 | D35: 0 | E35: 0 | F35: 0 | G35: 0 | H35: 0 | I35: =SUM(J35:N35) -> 0 | J35: 0 | K35: 0 | L35: 0 | M35: 0 | N35: 0 | O35: =SUM(P35:T35) -> 0 | P35: 0 | Q35: 0 | R35: 0 | S35: 0 | T35: 0 | U35: 14500
... A44: 35 | B44: Хусусий корхоналар, хўжалик ширкатлари ва жамиятларга берилган узоқ муддатли кредитлар | C44: =SUM(D44:H44)-O44+P44 -> 12071110691 | D44: 10879925723 | E44: 1107278492 | F44: 122981634 | G44: 201183364 | H44: 7654167 | I44: =SUM(J44:N44) -> 161508676 | J44: 9367918 | K44: 63342905 | L44: 33308775 | M44: 55343245 | N44: 145833 | O44: =SUM(P44:T44) -> 356711946 | P44: 108799257 | Q44: 108859695 | R44: 30811112 | S44: 100587715 | T44: 7654167 | U44: 15500
A45: 36 | B45: Лизинг (молиявий ижара) | C45: =SUM(D45:H45)-O45+P45 -> 335566010 | D45: 335566010 | E45: 0 | F45: 0 | G45: 0 | H45: 0 | I45: =SUM(J45:N45) -> 0 | O45: =SUM(P45:T45) -> 3355660 | P45: 3355660 | Q45: 0 | R45: 0 | S45: 0 | T45: 0 | U45: 15600
A46: 37 | B46: Суд ёки ижро иши юритиш жараёнидаги кредитлар ва лизинг | C46: =SUM(D46:H46)-O46+P46 -> 71465006 | D46: 0 | E46: 0 | F46: 63874260 | G46: 60205586 | H46: 32313429 | I46: =SUM(J46:N46) -> 0 | O46: =SUM(P46:T46) -> 84928269 | P46: 0 | Q46: 8301596 | R46: 14217481 | S46: 30095766 | T46: 32313426 | U46: 15700
A47: 38 | B47: Қарам хўжалик жамиятларига, биргаликдаги корхоналарга ва шўъба хўжалик жамиятларига қилинган инвестициялар | C47: =SUM(D47:H47)-O47+P47 -> 233090515 | D47: 227467057 | E47: 0 | F47: 7499992 | G47: 0 | H47: 3205644 | I47: =SUM(J47:N47) -> 0 | O47: =SUM(P47:T47) -> 7356849 | P47: 2274671 | Q47: 0 | R47: 1876534 | S47: 0 | T47: 3205644 | U47: 15800
A48: 39 | B48: Амортизацияланган қиймати бўйича баҳоланадиган қарз қимматли қоғозларга қилинган инвестициялар | C48: =SUM(D48:H48)-O48+P48 -> 5805445 | D48: 5805445 | E48: 0 | F48: 0 | G48: 0 | H48: 0 | I48: =SUM(J48:N48) -> 0 | O48: =SUM(P48:T48) -> 58054 | P48: 58054 | Q48: 0 | R48: 0 | S48: 0 | T48: 0 | U48: 15900
A49: 40 | B49: Олиниши лозим бўлган ҳисобланган фоизлар | C49: =SUM(D49:H49)-O49+P49 -> 1805164470 | D49: 1581537458 | E49: 121751748 | F49: 54841935 | G49: 156571796 | H49: 18261861 | I49: =SUM(J49:N49) -> 494296721 | J49: ='Aging Analysis'!L22 -> 48132494 | K49: ='Aging Analysis'!N22+'Aging Analysis'!P22 -> 141915264 | L49: ='Aging Analysis'!R22 -> 132310600 | M49: ='Aging Analysis'!T22 -> 157312413 | N49: ='Aging Analysis'!V22+'Aging Analysis'!X22 -> 14625950 | O49: =SUM(P49:T49) -> 143615659 | P49: 15815331 | Q49: 127800328 | R49: 0 | S49: 0 | T49: 0 | U49: 16300
...

Sheet Income 
A1: МОЛИЯВИЙ НАТИЖАЛАР ТЎҒРИСИДА ҲИСОБОТ | E1: 3-жадвал
B3: =+'Asset quality'!B3 -> "Ўзсаноатқурилишбанк" АТБ | D3: =+'Asset quality'!Q3 -> 44925 | E3: =+'Asset quality'!T3 -> минг. сўмда
A4: № | B4: Кўрсаткичлар | C4: Жами | D4: миллий валютада | E4: хорижий валютада (экв. сўмда)
A5: 1. | B5: ФОИЗЛИ ДАРОМАДЛАР
A6: a. | B6: Марказий банкдаги ҳисобварақлар бўйича фоизли даромадлар | C6: =+D6+E6 -> 35844465 | D6: 35844465 | E6: 0
A7: б. | B7: Бошқа банклардаги ҳисобварақлар бўйича фоизли даромадлар | C7: =+D7+E7 -> 268881890 | D7: 62413635 | E7: 206468255
A8: в. | B8: Амортизацияланган қиймати бўйича баҳоланадиган қарз қимматли қоғозларга қилинган инвестициялар бўйича фоизли даромадлар | C8: =+D8+E8 -> 1289908 | D8: 1289908 | E8: 0
A9: г. | B9: Қимматли қоғозлар ва уларга қилинган инвестициялар бўйича фоизли даромадлар | C9: =+D9+E9 -> 269037836 | D9: 267075910 | E9: 1961926
A10: д. | B10: Мижозларнинг мажбуриятлари бўйича ҳисобланган фоизлар | C10: =+D10+E10 -> 0 | D10: 0 | E10: 0
A11: е. | B11: Банкнинг тўланмаган акцептлари юзасидан мижозлар мажбуриятлари бўйича фоизли даромадлар | C11: =+D11+E11 -> 0 | D11: 0 | E11: 0
A12: ж. | B12: Кредит ва лизинг операциялари бўйича фоизлар, дисконтлар (чегирмалар) ва бадаллар | C12: =+D12+E12 -> 4591911242 | D12: 2769776100 | E12: 1822135142
A13: з. | B13: Қимматли қоғозлар билан амалга оширилган РЕПО битимлари бўйича фоизли даромадлар | C13: =+D13+E13 -> 0 | D13: 0 | E13: 0
A14: и. | B14: Бошқа фоизли даромадлар | C14: =+D14+E14 -> 218264480 | D14: 95915323 | E14: 122349157
A15: к. | B15: Жами фоизли даромадлар | C15: =SUM(C6:C14) -> 5385229821 | D15: =SUM(D6:D14) -> 3232315341 | E15: =SUM(E6:E14) -> 2152914480 | G15: =+'Analysis of Interest'!C42 -> 5385229821
A17: 2. | B17: ФОИЗЛИ ХAРAЖAТЛAР
A18: а. | B18: Талаб қилиб олингунча сақланадиган депозитлар бўйича фоизли харажатлар | C18: =+D18+E18 -> 6423638 | D18: 5582656 | E18: 840982
A19: б. | B19: Муддатли депозитлар бўйича фоизли харажатлар | C19: =+D19+E19 -> 783151094 | D19: 611953664 | E19: 171197430
A20: в. | B20: Марказий банкнинг ҳисобварақлари бўйича фоизли харажатлар | C20: =+D20+E20 -> 0 | D20: 0 | E20: 0
A21: г. | B21: Бошқа банкларнинг ҳисобварақлари бўйича фоизли харажатлар | C21: =+D21+E21 -> 114525305 | D21: 76606694 | E21: 37918611
A22: д. | B22: Жами депозитлар бўйича фоизли харажатлар | C22: =SUM(C18:C21) -> 904100037 | D22: =SUM(D18:D21) -> 694143014 | E22: =SUM(E18:E21) -> 209957023
A23: е. | B23: Кредитлар бўйича фоизли харажатлар | C23: =+D23+E23 -> 1446893800 | D23: 676650337 | E23: 770243463
A24: ж. | B24: Қимматли қоғозлар билан амалга оширилган РЕПО битимлари бўйича фоизли харажатлар | C24: =+D24+E24 -> 1443836 | D24: 1443836 | E24: 0
A25: з. | B25: Бошқа фоизли харажатлар | C25: =+D25+E25 -> 437549437 | D25: 111482420 | E25: 326067017
A26: и. | B26: Жами кредит ва бошқа қарздорликлар бўйича фоизли харажатлар | C26: =SUM(C23:C25) -> 1885887073 | D26: =SUM(D23:D25) -> 789576593 | E26: =SUM(E23:E25) -> 1096310480
A27: к. | B27: Жами фоизли харажатлар | C27: =C26+C22 -> 2789987110 | D27: =D26+D22 -> 1483719607 | E27: =E26+E22 -> 1306267503 | G27: =+'Analysis of Interest'!C72 -> 2789987110
A29: 3. | B29: Активлар бўйича эҳтимолий йўқотишларга қарши яратилган захираларни баҳолашдан олдинги соф даромад | C29: =C15-C27 -> 2595242711 | D29: =D15-D27 -> 1748595734 | E29: =E15-E27 -> 846646977
A30: а. | B30: Минус: Кредит ва лизинглар бўйича кўрилиши мумкин бўлган зарарларни баҳолаш | C30: =+D30+E30 -> 2008948377 | D30: 425674834 | E30: 1583273543
A31: б. | B31: Минус: Қимматли қоғозлар бўйича кўрилиши мумкин бўлган зарарларни баҳолаш | C31: =+D31+E31 -> 0 | D31: 0 | E31: 0
A32: в. | B32: Минус: Инвестициялар бўйича кўрилиши мумкин бўлган зарарларни баҳолаш | C32: =+D32+E32 -> 1874998 | D32: 1581228 | E32: 293770
A33: г. | B33: Минус: Бошқа активлар бўйича кўрилиши мумкин бўлган зарарларни баҳолаш | C33: =+D33+E33 -> 456006888 | D33: 252820973 | E33: 203185915
A34: д. | B34: Активлар бўйича эҳтимолий зарарларни баҳолашдан кейинги соф даромад | C34: =C29-C30-C31-C32-C33 -> 128412448 | D34: =D29-D30-D31-D32-D33 -> 1068518699 | E34: =E29-E30-E31-E32-E33 -> -940106251
A36: 4. | B36: ФОИЗСИЗ ДАРОМАДЛАР
A37: а. | B37: Кўрсатилган хизматлар ва воситачилик учун олинган даромадлар | C37: =+D37+E37 -> 474409860 | D37: 363862280 | E37: 110547580
A38: б. | B38: Хорижий валюталардаги фойда | C38: =+D38+E38 -> 1042504795 | D38: 189142622 | E38: 853362173
A39: в. | B39: Тижорат операцияларидан олинган фойда | C39: =+D39+E39 -> 0 | D39: 0 | E39: 0
A40: г. | B40: Инвестициядан олинган фойда ва дивидендлар | C40: =+D40+E40 -> 23609691 | D40: 23325363 | E40: 284328
A41: д. | B41: Бошқа фоизсиз даромадлар | C41: =+D41+E41 -> 1355245755 | D41: 567412819 | E41: 787832936
B42: шундан
A43: д1. | B43: Активлар бўйича эҳтимолий йўқотишларга қарши яратилган захираларни қайтарилиши | C43: =+D43+E43 -> 1287422060 | D43: 519119171 | E43: 768302889
A44: д2. | B44: Ҳисобдан чиқарилган кредитлар қайтарилиши билан боғлиқ даромадлар | C44: =+D44+E44 -> 0 | D44: 0 | E44: 0
...

Sheet Analysis of Interest
B1: ФОИЗЛИ ДАРОМАД ВА ХАРАЖАТЛАР ТАҲЛИЛИ | C1: 4-жадвал
B3: =+'Asset quality'!B3 -> "Ўзсаноатқурилишбанк" АТБ | C3: =+'Asset quality'!Q3 -> 44925
A4: № | B4: Кўрсаткичлар | C4: =+'Asset quality'!T3 -> минг. сўмда
A5: 1. | B5: КРЕДИТ ВА ЛИЗИНГ ОПЕРАЦИЯЛАРИ БЎЙИЧА ФОИЗЛИ ДАРОМАДЛАР
A6: a. | B6: Марказий банкка берилган қисқа муддатли кредитлар | C6: 0
A7: б. | B7: Бошқа банкларга берилган кредитлар | C7: 0
A8: в. | B8: Ҳукуматга берилган кредитлар | C8: 4173
A9: г. | B9: Жисмоний шахсларга берилган кредит ва лизинглар | C9: 670526003
A10: д. | B10: Давлат корхоналарига берилган кредит ва лизинглар | C10: 901937445
A11: е. | B11: Қўшма ва чет эл капитали иштирокидаги корхоналарга берилган кредит ва лизинглар | C11: 695588564
A12: ж. | B12: Хусусий корхоналар, хўжалик ширкатлари ва жамиятларга берилган кредит ва лизинглар | C12: 2274341091
A13: з. | B13: Бошқа кредит ва лизинглар | C13: 49513966
A14: и. | B14: Жами кредит ва лизинг операциялари бўйича фоизли даромад | C14: =SUM(C6:C13) -> 4591911242
A16: 2. | B16: ВАКИЛЛИК ҲИСОБВАРАҚЛАРИ БЎЙИЧА ФОИЗЛИ ДАРОМАДЛАР
A17: a. | B17: Марказий банкдаги ҳисобварақлар бўйича фоизли даромадлар | C17: 35844465
A18: б. | B18: Бошқа банклардаги ҳисобварақлар бўйича фоизли даромадлар | C18: 268881890
B19: Жами вакиллик ҳисобварағи бўйича фоизли даромадлар | C19: =SUM(C17:C18) -> 304726355
A21: 3. | B21: ҚИММАТЛИ ҚОҒОЗЛАР ВА УЛАРГА ҚИЛИНГАН ИНВЕСТИЦИЯЛАР БЎЙИЧА ФОИЗЛИ ДАРОМАДЛАР
A22: a. | B22: Давлат қимматли қоғозлари | C22: 102223104
A23: б. | B23: Марказий банкнинг облигациялари ва бошқа қимматли қоғозлари | C23: 166814732
A24: в. | B24: Давлат корхоналарининг қарз қимматли қоғозлари бўйича фоизли даромадлар | C24: 0
A25: г. | B25: Еврооблигациялар бўйича фоизли даромадлар | C25: 0
A26: д. | B26: Хусусий корхоналарнинг қимматли қоғозлари | C26: 0
A27: е. | B27: Бошқа қимматли қоғозлар | C27: 0
A28: ж. | B28: Жами олди-сотди қимматли қоғозлар бўйича фоизли даромадлар | C28: =SUM(C22:C27) -> 269037836
A30: 4. | B30: ИНВЕСТИЦИЯЛАР БЎЙИЧА ФОИЗЛИ ДАРОМАДЛАР
A31: a. | B31: Давлат қимматли қоғозлари | C31: 0
A32: б. | B32: Марказий банкнинг облигациялари ва бошқа қарз қимматли қоғозларига қилинган инвестициялар бўйича фоизли даромадлар | C32: 0
A33: в. | B33: Корхоналарнинг қарз қимматли қоғозларига қилинган инвестициялар бўйича фоизли даромадлар | C33: 1289908
A34: г. | B34: Еврооблигациялар | C34: 0
A35: д. | B35: Бошқа қимматли қоғозлар | C35: 0
A36: е. | B36: Жами инвестициялар бўйича фоизли даромадлар | C36: =SUM(C31:C35) -> 1289908
A38: 5. | B38: БОШҚА ФОИЗЛИ ДАРОМАДЛАР
A39: a. | B39: Қимматли қоғозлар билан амалга оширилган репо битимлари бўйича фоизли даромадлар | C39: 0
A40: б. | B40: Бошқа фоизли даромадлар | C40: 218264480
A42: 6. | B42: ЖАМИ ФОИЗЛИ ДАРОМАДЛАР | C42: =C14+C19+C28+C36+C39+C40 -> 5385229821
A44: 7. | B44: ДЕПОЗИТЛАР БЎЙИЧА ФОИЗЛИ ХАРАЖАТЛАР
A45: A. | B45: Талаб қилиб олингунча сақланадиган депозитлар
A46: a. | B46: Ҳукумат | C46: 4254521
A47: б. | B47: Жисмоний шахслар | C47: 0
...

Sheet Changes in Equity
A1: ХУСУСИЙ КАПИТАЛДАГИ ЎЗГАРИШЛАР | C1: 7-жадвал
B3: =+'Asset quality'!B3 -> "Ўзсаноатқурилишбанк" АТБ | C3: =+'Asset quality'!Q3 -> 44925
A4: № | B4: Кўрсаткичлар | C4: =+'Asset quality'!T3 -> минг. сўмда
A5: 1. | B5: Ўтган йил учун дастлабки ҳисобланган умумий капитал | C5: 7700913106
A6: 2. | B6: Хусусий капиталдаги ўтган йил учун ҳисоботларда кўрсатилмаган тузатишлар, (соф) | C6: 0
A7: 3. | B7: Ўтган календар йили якуни бўйича балансдаги тузатишлар (3=1-2 ) | C7: =SUM(C5:C6) -> 7700913106
A8: 4. | B8: Йил бошидан соф фойда (зарар) | C8: =+'Income '!C78 -> 588937049 | D8: =+[8]Balance!$C$77 -> 588937049 | E8: =+C8-D8 -> 0
A9: 5. | B9: Жорий йилда сотиш, айирбошлаш, сотиб олиш ёки қайтиб сотиб олиш (соф кирим)
A10: 6. | B10: Жорий йил учун бошланғич қийматига нисбатан баҳолаш қийматининг ошган суммаси | C10: -1001834
A11: 7. | B11: МИНУС: Имтиёзли акциялар бўйича эълон қилинган пул дивидендлари | C11: 1616900
A12: 8. | B12: МИНУС: Оддий акциялар бўйича эълон қилинган пуллик дивидендлар
A13: 9. | B13: Жорий йилнинг соф хусусий капиталига таъсир этувчи бошқа моддалар | C13: -459110228
A14: 10. | B14: Жорий давр якуни бўйича жами хусусий капитал | C14: =C7+SUM(C8:C10)-SUM(C11:C12)+C13 -> 7828121193 | D14: =+[8]Balance!$C$78 -> 7828121193 | E14: =+C14-D14 -> 0
B16: Бошқарув Раис имзоси:
B18: Бош бухгалтер имзоси:

Sheet Loans Receivable
A1: ИҚТИСОДИЁТ ТАРМОҚЛАРИ, МИЖОЗЛАР ТУРЛАРИ, ВА ТАЪМИНОТ ТУРЛАРИ БЎЙИЧА АЖРАТИЛГАН КРЕДИТЛАР ВА ЛИЗИНГЛАР ҲИСОБОТИ | W1: 8-жадвал
B3: =+'Asset quality'!B3 -> "Ўзсаноатқурилишбанк" АТБ | T3: =+'Asset quality'!Q3 -> 44925 | X3: =+'Asset quality'!T3 -> минг. сўмда
A4: № | B4: Иқтисодиёт тармоқлари бўйича | C4: Кредит суммаси | D4: шундан | F4: шундан муаммоли кредитлар | J4: шундан
D5: миллий валютада | E5: хорижий валютада (экв. сўмда) | F5: NPL | G5: шундан | J5: Депозитлар | K5: Ўзбекистон Республикаси Ҳукумати тамонидан кафолатланган кредитлар | L5: шундан | M5: Транспорт воситалари | N5: Инвентарлар | O5: Кўчмас мулк | P5: шундан | R5: Асбоб ускуналар | S5: Векселлар (облигациялар) | T5: Акциялар | U5: Учинчи шахс кафолати | V5: Учинчи шахс кафиллиги | W5: Суғурта полиси | X5: Таъминотсиз | Y5: Бошқа кафолатлар
G6: Қониқарсиз | H6: Шубҳали | I6: Умидсиз | L6: Ўзбекистон Республикаси Ҳукумати томонидан кафолатланган хорижий валютадаги (эквивалент сўмда) кредитлар | P6: турар жой (хонадон) | Q6: тижорат кўчмас мулки
A7: Код | B7: (А) | C7: (Б) | D7: (Б1) | E7: (Б3) | F7: (В) | G7: (В1) | H7: (В2) | I7: (В3) | J7: (Г) | K7: (Д) | L7: (Д1) | M7: (Е) | N7: (Ж) | O7: (З) | P7: (З1) | Q7: (З2) | R7: (И) | S7: (К) | T7: (Л) | U7: (М) | V7: (Н) | W7: (О) | X7: (П) | Y7: (Р)
B8: Саноат
A9: 10 | B9: Давлат корхоналари | C9: =SUM(J9:Y9)-L9-P9-Q9 -> 9559065439 | D9: 2992378874 | E9: 6566686565 | F9: =+G9+H9+I9 -> 0 | G9: 0 | H9: 0 | I9: 0 | J9: 0 | K9: 5110248432 | L9: 4404306552 | M9: 2579996 | N9: 104883818 | O9: =+P9+Q9 -> 55561125 | P9: 0 | Q9: 55561125 | R9: 661917992 | S9: 0 | T9: 135469078 | U9: 0 | V9: 1914735664 | W9: 4024826 | X9: 991196 | Y9: 1568653312
A10: =A9+10 -> 20 | B10: Қўшма ва чет эл капитали иштирокидаги корхоналар | C10: =SUM(J10:Y10)-L10-P10-Q10 -> 6958698729 | D10: 621062088 | E10: 6337636641 | F10: =+G10+H10+I10 -> 344600281 | G10: 46812333 | H10: 288718899 | I10: 9069049 | J10: 561273 | K10: 0 | L10: 0 | M10: 9913428 | N10: 184799033 | O10: =+P10+Q10 -> 1490965564 | P10: 4855793 | Q10: 1486109771 | R10: 2388920405 | S10: 0 | T10: 0 | U10: 0 | V10: 849084580 | W10: 738362324 | X10: 0 | Y10: 1296092122
A11: =A10+10 -> 30 | B11: Хусусий корхоналар | C11: =SUM(J11:Y11)-L11-P11-Q11 -> 9455672521 | D11: 1907106967 | E11: 7548565554 | F11: =+G11+H11+I11 -> 429545142 | G11: 136589558 | H11: 270073650 | I11: 22881934 | J11: 36176 | K11: 0 | L11: 0 | M11: 66396915 | N11: 27988346 | O11: =+P11+Q11 -> 2599824005 | P11: 27105904 | Q11: 2572718101 | R11: 1118503607 | S11: 0 | T11: 0 | U11: 0 | V11: 4862465700 | W11: 556796471 | X11: 0 | Y11: 223661301
A12: =A11+10 -> 40 | B12: Ҳукумат | C12: =SUM(J12:Y12)-L12-P12-Q12 -> 0 | D12: 0 | E12: 0 | F12: =+G12+H12+I12 -> 0 | G12: 0 | H12: 0 | I12: 0 | J12: 0 | K12: 0 | L12: 0 | M12: 0 | N12: 0 | O12: =+P12+Q12 -> 0 | P12: 0 | Q12: 0 | R12: 0 | S12: 0 | T12: 0 | U12: 0 | V12: 0 | W12: 0 | X12: 0 | Y12: 0
A13: =A12+10 -> 50 | B13: Бошқалар | C13: =SUM(J13:Y13)-L13-P13-Q13 -> 0 | D13: 0 | E13: 0 | F13: =+G13+H13+I13 -> 0 | G13: 0 | H13: 0 | I13: 0 | J13: 0 | K13: 0 | L13: 0 | M13: 0 | N13: 0 | O13: =+P13+Q13 -> 0 | P13: 0 | Q13: 0 | R13: 0 | S13: 0 | T13: 0 | U13: 0 | V13: 0 | W13: 0 | X13: 0 | Y13: 0
A14: =A13+10 -> 60 | B14: Жами | C14: =SUM(J14:Y14)-L14-P14-Q14 -> 25973436689 | D14: =SUM(D9:D13) -> 5520547929 | E14: =SUM(E9:E13) -> 20452888760 | F14: =+G14+H14+I14 -> 774145423 | G14: =SUM(G9:G13) -> 183401891 | H14: =SUM(H9:H13) -> 558792549 | I14: =SUM(I9:I13) -> 31950983 | J14: =SUM(J9:J13) -> 597449 | K14: =SUM(K9:K13) -> 5110248432 | L14: =SUM(L9:L13) -> 4404306552 | M14: =SUM(M9:M13) -> 78890339 | N14: =SUM(N9:N13) -> 317671197 | ... Y14: =SUM(Y9:Y13) -> 3088406735
B15: Қишлоқ хўжалиги
A16: 70 | B16: Давлат корхоналари | C16: =SUM(J16:Y16)-L16-P16-Q16 -> 0 | D16: 0 | E16: 0 | F16: =+G16+H16+I16 -> 0 | G16: 0 | H16: 0 | I16: 0 | J16: 0 | K16: 0 | L16: 0 | M16: 0 | N16: 0 | O16: =+P16+Q16 -> 0 | P16: 0 | Q16: 0 | R16: 0 | S16: 0 | T16: 0 | U16: 0 | V16: 0 | W16: 0 | X16: 0 | Y16: 0
A17: =A16+10 -> 80 | B17: Қўшма ва чет эл капитали иштирокидаги корхоналар | C17: =SUM(J17:Y17)-L17-P17-Q17 -> 838902053 | D17: 402022799 | E17: 436879254 | F17: =+G17+H17+I17 -> 32971304 | G17: 19024038 | H17: 13947266 | I17: 0 | J17: 0 | K17: 0 | L17: 0 | M17: 14478125 | N17: 0 | O17: =+P17+Q17 -> 358052465 | P17: 2478414 | Q17: 355574051 | R17: 144725800 | S17: 0 | T17: 0 | U17: 0 | V17: 92397841 | W17: 229247822 | X17: 0 | Y17: 0
A18: =A17+10 -> 90 | B18: Хусусий корхоналар | C18: =SUM(J18:Y18)-L18-P18-Q18 -> 3470971636 | D18: 1885540800 | E18: 1585430836 | F18: =+G18+H18+I18 -> 70014262 | G18: 10087312 | H18: 49837815 | I18: 10089135 | J18: 250000 | K18: 0 | L18: 0 | M18: 39177304 | N18: 0 | O18: =+P18+Q18 -> 705114499 | P18: 25260544 | Q18: 679853955 | R18: 248869958 | S18: 0 | T18: 0 | U18: 0 | V18: 1687360502 | W18: 787230913 | X18: 0 | Y18: 2968460
A19: =A18+10 -> 100 | B19: Фермер хўжалиги | C19: =SUM(J19:Y19)-L19-P19-Q19 -> 171788067 | D19: 69222758 | E19: 102565309 | F19: =+G19+H19+I19 -> 37243840 | G19: 9188880 | H19: 16591663 | I19: 11463297 | J19: 0 | K19: 0 | L19: 0 | M19: 3948793 | N19: 0 | O19: =+P19+Q19 -> 67131807 | P19: 1760740 | Q19: 65371067 | R19: 23770438 | S19: 0 | T19: 0 | U19: 0 | V19: 74042509 | W19: 2894520 | X19: 0 | Y19: 0
A20: =A19+10 -> 110 | B20: Ҳукумат | C20: =SUM(J20:Y20)-L20-P20-Q20 -> 0 | D20: 0 | E20: 0 | F20: =+G20+H20+I20 -> 0 | G20: 0 | H20: 0 | I20: 0 | J20: 0 | K20: 0 | L20: 0 | M20: 0 | N20: 0 | O20: =+P20+Q20 -> 0 | P20: 0 | Q20: 0 | R20: 0 | S20: 0 | T20: 0 | U20: 0 | V20: 0 | W20: 0 | X20: 0 | Y20: 0
A21: =A20+10 -> 120 | B21: Бошқалар | C21: =SUM(J21:Y21)-L21-P21-Q21 -> 0 | D21: 0 | E21: 0 | F21: =+G21+H21+I21 -> 0 | G21: 0 | H21: 0 | I21: 0 | J21: 0 | K21: 0 | L21: 0 | M21: 0 | N21: 0 | O21: =+P21+Q21 -> 0 | P21: 0 | Q21: 0 | R21: 0 | S21: 0 | T21: 0 | U21: 0 | V21: 0 | W21: 0 | X21: 0 | Y21: 0
A22: =A21+10 -> 130 | B22: Жами | C22: =SUM(J22:Y22)-L22-P22-Q22 -> 4481661756 | D22: =SUM(D16:D21) -> 2356786357 | E22: =SUM(E16:E21) -> 2124875399 | F22: =+G22+H22+I22 -> 140229406 | G22: =SUM(G17:G21) -> 38300230 | H22: =SUM(H17:H21) -> 80376744 | I22: =SUM(I17:I21) -> 21552432 | J22: =SUM(J16:J21) -> 250000 | K22: =SUM(K16:K21) -> 0 | L22: =SUM(L16:L21) -> 0 | M22: =SUM(M16:M21) -> 57604222 | N22: =SUM(N16:N21) -> 0 | O22: =SUM(O16:O21) -> 1130298771 | P22: =SUM(P16:P21) -> 29499698 | Q22: =SUM(Q16:Q21) -> 1100799073 | ... Y22: =SUM(Y16:Y21) -> 2968460
B23: Транспорт ва коммуникация
A24: 140 | B24: Давлат корхоналари | C24: =SUM(J24:Y24)-L24-P24-Q24 -> 2946182415 | D24: 4183369 | E24: 2941999046 | F24: =+G24+H24+I24 -> 0 | G24: 0 | H24: 0 | I24: 0 | J24: 958841375 | K24: 1514601374 | L24: 1514601374 | M24: 0 | N24: 0 | O24: =+P24+Q24 -> 281000 | P24: 0 | Q24: 281000 | R24: 40179434 | S24: 0 | T24: 0 | U24: 0 | V24: 432279232 | W24: 0 | X24: 0 | Y24: 0
A25: =A24+10 -> 150 | B25: Қўшма ва чет эл капитали иштирокидаги корхоналар | C25: =SUM(J25:Y25)-L25-P25-Q25 -> 0 | D25: 0 | E25: 0 | F25: =+G25+H25+I25 -> 0 | G25: 0 | H25: 0 | I25: 0 | J25: 0 | K25: 0 | L25: 0 | M25: 0 | N25: 0 | O25: =+P25+Q25 -> 0 | P25: 0 | Q25: 0 | R25: 0 | S25: 0 | T25: 0 | U25: 0 | V25: 0 | W25: 0 | X25: 0 | Y25: 0
A26: =A25+10 -> 160 | B26: Хусусий корхоналар | C26: =SUM(J26:Y26)-L26-P26-Q26 -> 559117995 | D26: 150846747 | E26: 408271248 | F26: =+G26+H26+I26 -> 31632641 | G26: 8383679 | H26: 13866148 | I26: 9382814 | J26: 0 | K26: 0 | L26: 0 | M26: 48382688 | N26: 0 | O26: =+P26+Q26 -> 281442114 | P26: 2296906 | Q26: 279145208 | R26: 33280781 | S26: 0 | T26: 0 | U26: 0 | V26: 165058278 | W26: 30954134 | X26: 0 | Y26: 0
A27: =A26+10 -> 170 | B27: Ҳукумат | C27: =SUM(J27:Y27)-L27-P27-Q27 -> 0 | D27: 0 | E27: 0 | F27: =+G27+H27+I27 -> 0 | G27: 0 | H27: 0 | I27: 0 | J27: 0 | K27: 0 | L27: 0 | M27: 0 | N27: 0 | O27: =+P27+Q27 -> 0 | P27: 0 | Q27: 0 | R27: 0 | S27: 0 | T27: 0 | U27: 0 | V27: 0 | W27: 0 | X27: 0 | Y27: 0
A28: =A27+10 -> 180 | B28: Бошқалар | C28: =SUM(J28:Y28)-L28-P28-Q28 -> 0 | D28: 0 | E28: 0 | F28: =+G28+H28+I28 -> 0 | G28: 0 | H28: 0 | I28: 0 | J28: 0 | K28: 0 | L28: 0 | M28: 0 | N28: 0 | O28: =+P28+Q28 -> 0 | P28: 0 | Q28: 0 | R28: 0 | S28: 0 | T28: 0 | U28: 0 | V28: 0 | W28: 0 | X28: 0 | Y28: 0
A29: =A28+10 -> 190 | B29: Жами | C29: =SUM(J29:Y29)-L29-P29-Q29 -> 3505300410 | D29: =SUM(D24:D28) -> 155030116 | E29: =SUM(E24:E28) -> 3350270294 | F29: =+G29+H29+I29 -> 31632641 | G29: =SUM(G24:G28) -> 8383679 | H29: =SUM(H24:H28) -> 13866148 | I29: =SUM(I24:I28) -> 9382814 | J29: =SUM(J24:J28) -> 958841375 | K29: =SUM(K24:K28) -> 1514601374 | L29: =SUM(L24:L28) -> 1514601374 | M29: =SUM(M24:M28) -> 48382688 | N29: =SUM(N24:N28) -> 0 | ... Y29: =SUM(Y24:Y28) -> 0
B30: Қурилиш соҳаси
A31: 200 | B31: Давлат корхоналари | C31: =SUM(J31:Y31)-L31-P31-Q31 -> 0 | D31: 0 | E31: 0 | F31: =+G31+H31+I31 -> 0 | G31: 0 | H31: 0 | I31: 0 | J31: 0 | K31: 0 | L31: 0 | M31: 0 | N31: 0 | O31: =+P31+Q31 -> 0 | P31: 0 | Q31: 0 | R31: 0 | S31: 0 | T31: 0 | U31: 0 | V31: 0 | W31: 0 | X31: 0 | Y31: 0
A32: =A31+10 -> 210 | B32: Қўшма ва чет эл капитали иштирокидаги корхоналар | C32: =SUM(J32:Y32)-L32-P32-Q32 -> 50217990 | D32: 51106 | E32: 50166884 | F32: =+G32+H32+I32 -> 0 | G32: 0 | H32: 0 | I32: 0 | J32: 0 | K32: 0 | L32: 0 | M32: 2325361 | N32: 0 | O32: =+P32+Q32 -> 32449763 | P32: 0 | Q32: 32449763 | R32: 3415018 | S32: 0 | T32: 0 | U32: 0 | V32: 11786898 | W32: 240950 | X32: 0 | Y32: 0
A33: =A32+10 -> 220 | B33: Хусусий корхоналар | C33: =SUM(J33:Y33)-L33-P33-Q33 -> 1261005857 | D33: 518177848 | E33: 742828009 | F33: =+G33+H33+I33 -> 106874131 | G33: 3404956 | H33: 100045006 | I33: 3424169 | J33: 111077 | K33: 0 | L33: 0 | M33: 32040088 | N33: 172080 | O33: =+P33+Q33 -> 383012929 | P33: 20142780 | Q33: 362870149 | R33: 31732933 | S33: 0 | T33: 0 | U33: 0 | V33: 732626027 | W33: 74348968 | X33: 0 | Y33: 6961755
A34: =A33+10 -> 230 | B34: Ҳукумат | C34: =SUM(J34:Y34)-L34-P34-Q34 -> 0 | D34: 0 | E34: 0 | F34: =+G34+H34+I34 -> 0 | G34: 0 | H34: 0 | I34: 0 | J34: 0 | K34: 0 | L34: 0 | M34: 0 | N34: 0 | O34: =+P34+Q34 -> 0 | P34: 0 | Q34: 0 | R34: 0 | S34: 0 | T34: 0 | U34: 0 | V34: 0 | W34: 0 | X34: 0 | Y34: 0
A35: =A34+10 -> 240 | B35: Бошқалар | C35: =SUM(J35:Y35)-L35-P35-Q35 -> 0 | D35: 0 | E35: 0 | F35: =+G35+H35+I35 -> 0 | G35: 0 | H35: 0 | I35: 0 | J35: 0 | K35: 0 | L35: 0 | M35: 0 | N35: 0 | O35: =+P35+Q35 -> 0 | P35: 0 | Q35: 0 | R35: 0 | S35: 0 | T35: 0 | U35: 0 | V35: 0 | W35: 0 | X35: 0 | Y35: 0
A36: =A35+10 -> 250 | B36: Жами | C36: =SUM(J36:Y36)-L36-P36-Q36 -> 1311223847 | D36: =SUM(D31:D35) -> 518228954 | E36: =SUM(E31:E35) -> 792994893 | F36: =+G36+H36+I36 -> 106874131 | G36: =SUM(G31:G35) -> 3404956 | H36: =SUM(H31:H35) -> 100045006 | I36: =SUM(I31:I35) -> 3424169 | J36: =SUM(J31:J35) -> 111077 | K36: =SUM(K31:K35) -> 0 | L36: =SUM(L31:L35) -> 0 | M36: =SUM(M31:M35) -> 34365449 | N36: =SUM(N31:N35) -> 172080 | ... Y36: =SUM(Y31:Y35) -> 6961755
B37: Савдо ва умумий хизмат
A38: 260 | B38: Давлат корхоналари | C38: =SUM(J38:Y38)-L38-P38-Q38 -> 400000 | D38: 400000 | E38: 0 | F38: =+G38+H38+I38 -> 0 | G38: 0 | H38: 0 | I38: 0 | J38: 0 | K38: 0 | L38: 0 | M38: 0 | N38: 0 | O38: =+P38+Q38 -> 400000 | P38: 0 | Q38: 400000 | R38: 0 | S38: 0 | T38: 0 | U38: 0 | V38: 0 | W38: 0 | X38: 0 | Y38: 0
A39: =A38+10 -> 270 | B39: Қўшма ва чет эл капитали иштирокидаги корхоналар | C39: =SUM(J39:Y39)-L39-P39-Q39 -> 232072283 | D39: 3666673 | E39: 228405610 | F39: =+G39+H39+I39 -> 176151 | G39: 176151 | H39: 0 | I39: 0 | J39: 0 | K39: 0 | L39: 0 | M39: 2677448 | N39: 0 | O39: =+P39+Q39 -> 111780563 | P39: 0 | Q39: 111780563 | R39: 10625758 | S39: 0 | T39: 0 | U39: 0 | V39: 73169728 | W39: 33818786 | X39: 0 | Y39: 0
A40: =A39+10 -> 280 | B40: Хусусий корхоналар | C40: =SUM(J40:Y40)-L40-P40-Q40 -> 2656484827 | D40: 818723732 | E40: 1837761095 | F40: =+G40+H40+I40 -> 155857839 | G40: 112833422 | H40: 33775945 | I40: 9248472 | J40: 150000 | K40: 0 | L40: 0 | M40: 49897108 | N40: 138064027 | O40: =+P40+Q40 -> 1086573961 | P40: 14170538 | Q40: 1072403423 | R40: 132269678 | S40: 0 | T40: 0 | U40: 0 | V40: 894155650 | W40: 355368844 | X40: 0 | Y40: 5559
A41: =A40+10 -> 290 | B41: Ҳукумат | C41: =SUM(J41:Y41)-L41-P41-Q41 -> 0 | D41: 0 | E41: 0 | F41: =+G41+H41+I41 -> 0 | G41: 0 | H41: 0 | I41: 0 | J41: 0 | K41: 0 | L41: 0 | M41: 0 | N41: 0 | O41: =+P41+Q41 -> 0 | P41: 0 | Q41: 0 | R41: 0 | S41: 0 | T41: 0 | U41: 0 | V41: 0 | W41: 0 | X41: 0 | Y41: 0
...

Sheet Aging Analysis
A1: ОЛИНИШИ ЛОЗИМ БЎЛГАН МУДДАТИ ЎТГАН КРЕДИТ ВА МОЛИЯВИЙ ЛИЗИНГ ТАҲЛИЛИ | X1: 9-жадвал
B3: =+'Asset quality'!B3 -> "Ўзсаноатқурилишбанк" АТБ | T3: =+'Asset quality'!Q3 -> 44925 | X3: =+'Asset quality'!T3 -> минг. сўмда
A4: № | B4: Кўрсаткичлар | C4: Жами кредит суммаси | D4: % | E4: Шартлари қайта кўрилган кредит ва лизинглар | F4: % | G4: Суд жараёнидаги қарздорликлар | H4: % | I4: Муддати ўтган | K4: % | L4: шу жумладан, кечиктирилган муддати бўйича
L5: 1-30 кун | N5: 31-60 кун | P5: 61-90 кун | R5: 91-180 кун | T5: 181-365 кун | V5: 366-730 кун | X5: 2 йилдан ортиқ
I6: асосий қарздорлик | J6: фоиз тўловлари | L6: асосий қарздорлик | M6: фоиз тўловлари | N6: асосий қарздорлик | O6: фоиз тўловлари | P6: асосий қарздорлик | Q6: фоиз тўловлари | R6: асосий қарздорлик | S6: фоиз тўловлари | T6: асосий қарздорлик | U6: фоиз тўловлари | V6: асосий қарздорлик | W6: фоиз тўловлари | X6: асосий қарздорлик | Y6: фоиз тўловлари
B7: (А) | C7: (Б) | D7: (В) | E7: (Г) | F7: (Д) | G7: (Е) | H7: (Ж) | I7: (З) | J7: (З1) | K7: (И) | L7: (К) | M7: (К1) | N7: (Л) | O7: (Л1) | P7: (М) | Q7: (М1) | R7: (Н) | S7: (Н1) | T7: (О) | U7: (О1) | V7: (П) | W7: (П1) | X7: (Р) | Y7: (Р1)
B8: Мижозлар тури бўйича
A9: 1 | B9: Марказий банк | C9: =+'Loans Receivable'!C79 -> 0 | D9: =IF(C$22=0,"",C9/C$22) -> 0 | F9: =IF(E$22=0,"",E9/E$22) -> 0 | H9: =IF($G$22=0,"",G9/$G$22) -> 0 | I9: =+L9+N9+P9+R9+T9+V9+X9 -> 0 | J9: =+M9+O9+T9+S9+U9+W9+Y9 -> 0 | K9: =IF($Z$22=0,"",Z9/$Z$22) -> 0 | Z9: =+I9+J9 -> 0
A10: 2 | B10: Бошқа банклар | C10: =+'Loans Receivable'!C78 -> 0 | D10: =IF(C$22=0,"",C10/C$22) -> 0 | F10: =IF(E$22=0,"",E10/E$22) -> 0 | H10: =IF($G$22=0,"",G10/$G$22) -> 0 | I10: =+L10+N10+P10+R10+T10+V10+X10 -> 0 | J10: =+M10+O10+Q10+S10+U10+W10+Y10 -> 0 | K10: =IF($Z$22=0,"",Z10/$Z$22) -> 0 | Z10: =+I10+J10 -> 0
A11: 3 | B11: Ҳукумат | C11: =+'Loans Receivable'!C80 -> 0 | D11: =IF(C$22=0,"",C11/C$22) -> 0 | F11: =IF(E$22=0,"",E11/E$22) -> 0 | H11: =IF($G$22=0,"",G11/$G$22) -> 0 | I11: =+L11+N11+P11+R11+T11+V11+X11 -> 0 | J11: =+M11+O11+Q11+S11+U11+W11+Y11 -> 0 | K11: =IF($Z$22=0,"",Z11/$Z$22) -> 0 | Z11: =+I11+J11 -> 0
A12: 4 | B12: Жисмоний шахслар | C12: =+'Loans Receivable'!C73 -> 5463367169 | D12: =IF(C$22=0,"",C12/C$22) -> 0.11364049 | E12: 9541830 | F12: =IF(E$22=0,"",E12/E$22) -> 0.028943972 | G12: 1711326 | H12: =IF($G$22=0,"",G12/$G$22) -> 0.010942453 | I12: =+L12+N12+P12+R12+T12+V12+X12 -> 7346228 | J12: =+M12+O12+Q12+S12+U12+W12+Y12 -> 4378892 | K12: =IF($Z$22=0,"",Z12/$Z$22) -> 0.016912068 | L12: 1074616 | M12: 2473682 | N12: 813701 | O12: 336955 | P12: 674122 | Q12: 270739 | R12: 1466502 | S12: 348343 | T12: 2583601 | U12: 724568 | V12: 733686 | W12: 224605 | X12: 0 | Y12: 0 | Z12: =+I12+J12 -> 11725120
A13: 5 | B13: Давлат корхоналари | C13: =+'Loans Receivable'!C74 -> 14093170226 | D13: =IF(C$22=0,"",C13/C$22) -> 0.29314427 | E13: 9742376 | F13: =IF(E$22=0,"",E13/E$22) -> 0.029552304 | G13: 0 | H13: =IF($G$22=0,"",G13/$G$22) -> 0 | I13: =+L13+N13+P13+R13+T13+V13+X13 -> 3481735 | J13: =+M13+O13+Q13+S13+U13+W13+Y13 -> 820795 | K13: =IF($Z$22=0,"",Z13/$Z$22) -> 0.0062058794 | L13: 393852 | M13: 446437 | N13: 2666667 | O13: 374358 | P13: 421216 | Q13: 0 | R13: 0 | S13: 0 | T13: 0 | U13: 0 | V13: 0 | W13: 0 | X13: 0 | Y13: 0 | Z13: =+I13+J13 -> 4302530
A14: 6 | B14: Қўшма ва чет эл капитали иштирокидаги корхоналар | C14: =+'Loans Receivable'!C75 -> 9080290501 | D14: =IF(C$22=0,"",C14/C$22) -> 0.18887412 | E14: 9669020 | F14: =IF(E$22=0,"",E14/E$22) -> 0.029329787 | G14: 5188589 | H14: =IF($G$22=0,"",G14/$G$22) -> 0.033176548 | I14: =+L14+N14+P14+R14+T14+V14+X14 -> 47188479 | J14: =+M14+O14+Q14+S14+U14+W14+Y14 -> 54022771 | K14: =IF($Z$22=0,"",Z14/$Z$22) -> 0.14598499 | L14: 3369687 | M14: 51164011 | N14: 3246003 | O14: 258667 | P14: 11680881 | Q14: 0 | R14: 13826655 | S14: 273229 | T14: 15065253 | U14: 2326864 | V14: 0 | W14: 0 | X14: 0 | Y14: 0 | Z14: =+I14+J14 -> 101211250
A15: 7 | B15: Хусусий корхоналар | C15: =+'Loans Receivable'!C76 -> 19254967029 | D15: =IF(C$22=0,"",C15/C$22) -> 0.40051196 | E15: 296813214 | F15: =IF(E$22=0,"",E15/E$22) -> 0.90034651 | G15: 147248642 | H15: =IF($G$22=0,"",G15/$G$22) -> 0.94152797 | I15: =+L15+N15+P15+R15+T15+V15+X15 -> 424144654 | J15: =+M15+O15+Q15+S15+U15+W15+Y15 -> 133005898 | K15: =IF($Z$22=0,"",Z15/$Z$22) -> 0.80362232 | L15: 43241798 | M15: 47119344 | N15: 35396391 | O15: 17670132 | P15: 86198154 | Q15: 8131320 | R15: 116819260 | S15: 22582178 | T15: 133241936 | U15: 36579419 | V15: 9247115 | W15: 923505 | X15: 0 | Y15: 0 | Z15: =+I15+J15 -> 557150552
A16: 8 | B16: Фермер хўжаликлари | C16: =+'Loans Receivable'!C77 -> 171788067 | D16: =IF(C$22=0,"",C16/C$22) -> 0.003573269 | E16: 3660807 | F16: =IF(E$22=0,"",E16/E$22) -> 0.011104609 | G16: 2244718 | H16: =IF($G$22=0,"",G16/$G$22) -> 0.014353034 | I16: =+L16+N16+P16+R16+T16+V16+X16 -> 11246932 | J16: =+M16+O16+Q16+S16+U16+W16+Y16 -> 5744647 | K16: =IF($Z$22=0,"",Z16/$Z$22) -> 0.024508299 | L16: 52541 | M16: 2276772 | N16: 561273 | O16: 969267 | P16: 218906 | Q16: 23478 | R16: 152097 | S16: 136477 | T16: 6225901 | U16: 806374 | V16: 4036214 | W16: 1532279 | X16: 0 | Y16: 0 | Z16: =+I16+J16 -> 16991579
A17: 9 | B17: Нобанк молиявий институтлар | C17: =+'Loans Receivable'!C81 -> 2059286 | D17: =IF(C$22=0,"",C17/C$22) -> 4.2834074e-05 | E17: 0 | F17: =IF(E$22=0,"",E17/E$22) -> 0 | G17: 0 | H17: =IF($G$22=0,"",G17/$G$22) -> 0 | I17: =+L17+N17+P17+R17+T17+V17+X17 -> 0 | J17: =+M17+O17+Q17+S17+U17+W17+Y17 -> 0 | K17: =IF($Z$22=0,"",Z17/$Z$22) -> 0 | L17: 0 | M17: 0 | N17: 0 | O17: 0 | P17: 0 | Q17: 0 | R17: 0 | S17: 0 | T17: 0 | U17: 0 | V17: 0 | W17: 0 | X17: 0 | Y17: 0 | Z17: =+I17+J17 -> 0
A18: 10 | B18: Нодавлат нотижорат ташкилотлар | C18: =+'Loans Receivable'!C82 -> 10242602 | D18: =IF(C$22=0,"",C18/C$22) -> 0.00021305072 | E18: 238287 | F18: =IF(E$22=0,"",E18/E$22) -> 0.00072281441 | G18: 0 | H18: =IF($G$22=0,"",G18/$G$22) -> 0 | I18: =+L18+N18+P18+R18+T18+V18+X18 -> 888693 | J18: =+M18+O18+Q18+S18+U18+W18+Y18 -> 1029274 | K18: =IF($Z$22=0,"",Z18/$Z$22) -> 0.0027664356 | L18: 0 | M18: 346988 | N18: 20791 | O18: 10927 | P18: 17159 | Q18: 10029 | R18: 46086 | S18: 89136 | T18: 195722 | U18: 143457 | V18: 182126 | W18: 94110 | X18: 426809 | Y18: 334627 | Z18: =+I18+J18 -> 1917967
A19: 11 | B19: Бюджет ташкилотлари | C19: =+'Loans Receivable'!C83 -> 0 | D19: =IF(C$22=0,"",C19/C$22) -> 0 | E19: 0 | F19: =IF(E$22=0,"",E19/E$22) -> 0 | G19: 0 | H19: =IF($G$22=0,"",G19/$G$22) -> 0 | I19: =+L19+N19+P19+R19+T19+V19+X19 -> 0 | J19: =+M19+O19+Q19+S19+U19+W19+Y19 -> 0 | K19: =IF($Z$22=0,"",Z19/$Z$22) -> 0 | L19: 0 | M19: 0 | N19: 0 | O19: 0 | P19: 0 | Q19: 0 | R19: 0 | S19: 0 | T19: 0 | U19: 0 | V19: 0 | W19: 0 | X19: 0 | Y19: 0 | Z19: =+I19+J19 -> 0
A20: 12 | B20: Бошқалар | C20: =+'Loans Receivable'!C84 -> 0 | D20: =IF(C$22=0,"",C20/C$22) -> 0 | E20: 0 | F20: =IF(E$22=0,"",E20/E$22) -> 0 | G20: 0 | H20: =IF($G$22=0,"",G20/$G$22) -> 0 | I20: =+L20+N20+P20+R20+T20+V20+X20 -> 0 | J20: =+M20+O20+Q20+S20+U20+W20+Y20 -> 0 | K20: =IF($Z$22=0,"",Z20/$Z$22) -> 0 | L20: 0 | M20: 0 | N20: 0 | O20: 0 | P20: 0 | Q20: 0 | R20: 0 | S20: 0 | T20: 0 | U20: 0 | V20: 0 | W20: 0 | X20: 0 | Y20: 0 | Z20: =+I20+J20 -> 0
Z21: =+I21+J21 -> 0
A22: 13 | B22: Жами кредит ва лизинг суммаси | C22: =SUM(C9:C20) -> 48075884880 | D22: =IF(C$22=0,"",C22/C$22) -> 1 | E22: =SUM(E9:E20) -> 329665534 | F22: =IF(E$22=0,"",E22/E$22) -> 1 | G22: =SUM(G9:G20) -> 156393275 | H22: =IF($G$22=0,"",G22/$G$22) -> 1 | I22: =SUM(I9:I20) -> 494296721 | J22: =SUM(J9:J20) -> 199002277 | K22: =IF($Z$22=0,"",Z22/$Z$22) -> 1 | L22: =SUM(L9:L20) -> 48132494 | M22: =SUM(M9:M20) -> 103827234 | N22: =SUM(N9:N20) -> 42704826 | O22: =SUM(O9:O20) -> 19620306 | P22: =SUM(P9:P20) -> 99210438 | Q22: =SUM(Q9:Q20) -> 8435566 | R22: =SUM(R9:R20) -> 132310600 | S22: =SUM(S9:S20) -> 23429363 | ... Y22: =SUM(Y9:Y20) -> 334627 | Z22: =+I22+J22 -> 693298998
Z23: =+I23+J23 -> 0
B24: Иқтисодиёт соҳалари бўйича | Z24: =+I24+J24 -> 0
A25: 14 | B25: Саноат | C25: =+'Loans Receivable'!C14 -> 25973436689 | D25: =IF(C$35=0,"",C25/C$35) -> 0.54025915 | E25: 150027294 | F25: =IF($E$35=0,"",E25/$E$35) -> 0.45508941 | G25: 91038174 | H25: =IF($G$35=0,"",G25/$G$35) -> 0.58211054 | I25: =+L25+N25+P25+R25+T25+V25+X25 -> 223468386 | J25: =+M25+O25+Q25+S25+U25+W25+Y25 -> 106525185 | K25: =IF($Z$35=0,"",Z25/$Z$35) -> 0.47597584 | L25: 18792123 | M25: 64950098 | N25: 25030864 | O25: 14806158 | P25: 40121655 | Q25: 2324621 | R25: 55627970 | S25: 2629302 | T25: 83749941 | U25: 21762591 | V25: 145833 | W25: 52415 | X25: 0 | Y25: 0 | Z25: =+I25+J25 -> 329993571
A26: 15 | B26: Қишлоқ хўжалиги | C26: =+'Loans Receivable'!C22 -> 4481661756 | D26: =IF(C$35=0,"",C26/C$35) -> 0.093220578 | E26: 90115429 | F26: =IF($E$35=0,"",E26/$E$35) -> 0.27335411 | G26: 14074906 | H26: =IF($G$35=0,"",G26/$G$35) -> 0.089996875 | I26: =+L26+N26+P26+R26+T26+V26+X26 -> 70212702 | J26: =+M26+O26+Q26+S26+U26+W26+Y26 -> 27065280 | K26: =IF($Z$35=0,"",Z26/$Z$35) -> 0.14031173 | L26: 8877669 | M26: 15758057 | N26: 3461787 | O26: 1811421 | P26: 19402635 | Q26: 461247 | R26: 9347300 | S26: 1300830 | T26: 23177876 | U26: 5931353 | V26: 5945435 | W26: 1802372 | X26: 0 | Y26: 0 | Z26: =+I26+J26 -> 97277982
A27: 16 | B27: Транспорт ва коммуникация | C27: =+'Loans Receivable'!C29 -> 3505300410 | D27: =IF(C$35=0,"",C27/C$35) -> 0.072911823 | E27: 4744500 | F27: =IF($E$35=0,"",E27/$E$35) -> 0.014391859 | G27: 9278723 | H27: =IF($G$35=0,"",G27/$G$35) -> 0.059329424 | I27: =+L27+N27+P27+R27+T27+V27+X27 -> 25773249 | J27: =+M27+O27+Q27+S27+U27+W27+Y27 -> 3989332 | K27: =IF($Z$35=0,"",Z27/$Z$35) -> 0.042928925 | L27: 1398426 | M27: 1282817 | N27: 512649 | O27: 193017 | P27: 6734519 | Q27: 98139 | R27: 168882 | S27: 29066 | T27: 11572222 | U27: 2201867 | V27: 5386551 | W27: 184426 | X27: 0 | Y27: 0 | Z27: =+I27+J27 -> 29762581
A28: 17 | B28: Қурилиш соҳаси | C28: =+'Loans Receivable'!C36 -> 1311223847 | D28: =IF(C$35=0,"",C28/C$35) -> 0.027274045 | E28: 8739643 | F28: =IF($E$35=0,"",E28/$E$35) -> 0.026510636 | G28: 19101309 | H28: =IF($G$35=0,"",G28/$G$35) -> 0.12213638 | I28: =+L28+N28+P28+R28+T28+V28+X28 -> 49667336 | J28: =+M28+O28+Q28+S28+U28+W28+Y28 -> 18979950 | K28: =IF($Z$35=0,"",Z28/$Z$35) -> 0.099015412 | L28: 5152208 | M28: 3265904 | N28: 1075051 | O28: 164607 | P28: 1502729 | Q28: 4673 | R28: 25848379 | S28: 11138412 | T28: 15731466 | U28: 4296336 | V28: 357503 | W28: 110018 | X28: 0 | Y28: 0 | Z28: =+I28+J28 -> 68647286
A29: 18 | B29: Савдо ва умумий овқатланиш | C29: =+'Loans Receivable'!C43 -> 2888957110 | D29: =IF(C$35=0,"",C29/C$35) -> 0.060091606 | E29: 56289986 | F29: =IF($E$35=0,"",E29/$E$35) -> 0.17074877 | G29: 13674645 | H29: =IF($G$35=0,"",G29/$G$35) -> 0.087437551 | I29: =+L29+N29+P29+R29+T29+V29+X29 -> 97251982 | J29: =+M29+O29+Q29+S29+U29+W29+Y29 -> 22632924 | K29: =IF($Z$35=0,"",Z29/$Z$35) -> 0.17291949 | L29: 6625092 | M29: 8117954 | N29: 10706096 | O29: 1689674 | P29: 29003647 | Q29: 4801942 | R29: 38386796 | S29: 7554300 | T29: 12192585 | U29: 430060 | V29: 337766 | W29: 38994 | X29: 0 | Y29: 0 | Z29: =+I29+J29 -> 119884906
A30: 19 | B30: Моддий ва техник таъминотни ривожлантириш | C30: =+'Loans Receivable'!C50 -> 1326568151 | D30: =IF(C$35=0,"",C30/C$35) -> 0.027593213 | E30: 0 | F30: =IF($E$35=0,"",E30/$E$35) -> 0 | G30: 4490184 | H30: =IF($G$35=0,"",G30/$G$35) -> 0.028710851 | I30: =+L30+N30+P30+R30+T30+V30+X30 -> 988575 | J30: =+M30+O30+Q30+S30+U30+W30+Y30 -> 741033 | K30: =IF($Z$35=0,"",Z30/$Z$35) -> 0.0024947505 | L30: 917073 | M30: 730013 | N30: 21502 | O30: 1760 | P30: 50000 | Q30: 9260 | R30: 0 | S30: 0 | T30: 0 | U30: 0 | V30: 0 | W30: 0 | X30: 0 | Y30: 0 | Z30: =+I30+J30 -> 1729608
A31: 20 | B31: Уй-жой коммунал хизмати | C31: =+'Loans Receivable'!C58 -> 10242602 | D31: =IF(C$35=0,"",C31/C$35) -> 0.00021305072 | E31: 238287 | F31: =IF($E$35=0,"",E31/$E$35) -> 0.00072281441 | G31: 0 | H31: =IF($G$35=0,"",G31/$G$35) -> 0 | I31: =+L31+N31+P31+R31+T31+V31+X31 -> 888693 | J31: =+M31+O31+Q31+S31+U31+W31+Y31 -> 1029274 | K31: =IF($Z$35=0,"",Z31/$Z$35) -> 0.0027664356 | L31: 0 | M31: 346988 | N31: 20791 | O31: 10927 | P31: 17159 | Q31: 10029 | R31: 46086 | S31: 89136 | T31: 195722 | U31: 143457 | V31: 182126 | W31: 94110 | X31: 426809 | Y31: 334627 | Z31: =+I31+J31 -> 1917967
A32: 21 | B32: Бошқа соҳалар | C32: =+'Loans Receivable'!C70 -> 3115127146 | D32: =IF(C$35=0,"",C32/C$35) -> 0.064796044 | E32: 9968565 | F32: =IF($E$35=0,"",E32/$E$35) -> 0.03023842 | G32: 3024008 | H32: =IF($G$35=0,"",G32/$G$35) -> 0.019335921 | I32: =+L32+N32+P32+R32+T32+V32+X32 -> 18699570 | J32: =+M32+O32+Q32+S32+U32+W32+Y32 -> 13660407 | K32: =IF($Z$35=0,"",Z32/$Z$35) -> 0.046675355 | L32: 5295287 | M32: 6901721 | N32: 1062385 | O32: 605787 | P32: 1703972 | Q32: 454916 | R32: 1418685 | S32: 339974 | T32: 8109000 | U32: 5090450 | V32: 1110241 | W32: 267559 | X32: 0 | Y32: 0 | Z32: =+I32+J32 -> 32359977
A33: 22 | B33: Жисмоний шахслар | C33: =+'Loans Receivable'!C71 -> 5463367169 | D33: =IF(C$35=0,"",C33/C$35) -> 0.11364049 | E33: 9541830 | F33: =IF($E$35=0,"",E33/$E$35) -> 0.028943972 | G33: 1711326 | H33: =IF($G$35=0,"",G33/$G$35) -> 0.010942453 | I33: =+L33+N33+P33+R33+T33+V33+X33 -> 7346228 | J33: =+M33+O33+Q33+S33+U33+W33+Y33 -> 4378892 | K33: =IF($Z$35=0,"",Z33/$Z$35) -> 0.016912068 | L33: 1074616 | M33: 2473682 | N33: 813701 | O33: 336955 | P33: 674122 | Q33: 270739 | R33: 1466502 | S33: 348343 | T33: 2583601 | U33: 724568 | V33: 733686 | W33: 224605 | X33: 0 | Y33: 0 | Z33: =+I33+J33 -> 11725120
Z34: =+I34+J34 -> 0
A35: 23 | B35: Жами кредит ва лизинг суммаси | C35: =SUM(C25:C33) -> 48075884880 | D35: =IF(C$35=0,"",C35/C$35) -> 1 | E35: =SUM(E25:E33) -> 329665534 | F35: =IF($E$35=0,"",E35/$E$35) -> 1 | G35: =SUM(G25:G33) -> 156393275 | H35: =IF($G$35=0,"",G35/$G$35) -> 1 | I35: =SUM(I25:I33) -> 494296721 | J35: =SUM(J25:J33) -> 199002277 | K35: =IF($Z$35=0,"",Z35/$Z$35) -> 1 | L35: =SUM(L25:L33) -> 48132494 | M35: =SUM(M25:M33) -> 103827234 | N35: =SUM(N25:N33) -> 42704826 | O35: =SUM(O25:O33) -> 19620306 | P35: =SUM(P25:P33) -> 99210438 | Q35: =SUM(Q25:Q33) -> 8435566 | R35: =SUM(R25:R33) -> 132310600 | S35: =SUM(S25:S33) -> 23429363 | ... Y35: =SUM(Y25:Y33) -> 334627 | Z35: =+I35+J35 -> 693298998
B37: Бошқарув Раис имзоси:
B39: Бош бухгалтер имзоси:
G42: =+'[8]Bank Assets Analysis'!$S$31 -> 71465006

Sheet Asset Classification
A1: АКТИВЛАР СИФАТИ БЎЙИЧА ТАСНИФЛАНИШИ ТЎҒРИСИДА ҲИСОБОТ | Z1: 10-жадвал
B3: =+'Asset quality'!B3 -> "Ўзсаноатқурилишбанк" АТБ | U3: =+'Asset quality'!Q3 -> 44925 | AB3: =+'Asset quality'!T3 -> минг. сўмда
A4: № | B4: Кўрсаткичлар | C4: Жами суммаси | D4: шундан, хорижий валютада (экв. сўмда) | E4: Стандарт | F4: шундан, хорижий валютада (экв. сўмда) | G4: Стандарт активлар бўйича яратилган захиралар (1%) | H4: шундан, хорижий валютада (экв. сўмда) | I4: Субстандарт | J4: шундан, хорижий валютада (экв. сўмда) | K4: Махсус захиралар (мин 10%) | L4: шундан, хорижий валютада (экв. сўмда) | M4: Қониқарсиз | N4: шундан, хорижий валютада (экв. сўмда) | O4: Махсус захиралар (мин 25%) | P4: шундан, хорижий валютада (экв. сўмда) | Q4: Шубҳали | R4: шундан, хорижий валютада (экв. сўмда) | S4: Махсус захиралар (мин 50%) | T4: шундан, хорижий валютада (экв. сўмда) | U4: Умидсиз | V4: шундан, хорижий валютада (экв. сўмда) | W4: Махсус захиралар (мин 100%) | X4: шундан, хорижий валютада (экв. сўмда) | Y4: Жами махсус захиралар суммаси | Z4: шундан, хорижий валютада (экв. сўмда) | AA4: ҳисобот ойида балансдан ташқари ҳисобдан чиқарилган кредитлар | AB4: ҳисобот ойида балансдан ташқари қайтган кредитлар суммаси
A5: (А) | B5: (Б) | C5: (В) | D5: (В1) | E5: (Г) | F5: (Г1) | G5: (Д) | H5: (Д1) | I5: (Е) | J5: (Е1) | K5: (Ж) | L5: (Ж1) | M5: (З) | N5: (З1) | O5: (И) | P5: (И1) | Q5: (К) | R5: (К1) | S5: (Л) | T5: (Л1) | U5: (М) | V5: (М1) | W5: (Н) | X5: (Н1) | Y5: О=Ж+И+Л+Н | Z5: (О1)=(Ж1)+(И1)+(Л1)+(Н1) | AA5: П | AB5: Р
B6: Мижозлар тури бўйича
A7: 1 | B7: Марказий банк | C7: =E7+I7+M7+Q7+U7 -> 0 | D7: =F7+J7+N7+R7+V7 -> 0 | Y7: =+W7+S7+O7+K7 -> 0 | Z7: =+X7+T7+P7+L7 -> 0 | AC7: =+'Aging Analysis'!C9 -> 0
B8: шундан, таъминланмаган қисми | C8: =E8+I8+M8+Q8+U8 -> 0 | D8: =F8+J8+N8+R8+V8 -> 0 | Y8: =+W8+S8+O8+K8 -> 0 | Z8: =+X8+T8+P8+L8 -> 0
A9: 2 | B9: Бошқа банклар | C9: =E9+I9+M9+Q9+U9 -> 0 | D9: =F9+J9+N9+R9+V9 -> 0 | Y9: =+W9+S9+O9+K9 -> 0 | Z9: =+X9+T9+P9+L9 -> 0 | AC9: =+'Aging Analysis'!C10 -> 0
B10: шундан, таъминланмаган қисми | C10: =E10+I10+M10+Q10+U10 -> 0 | D10: =F10+J10+N10+R10+V10 -> 0 | Y10: =+W10+S10+O10+K10 -> 0 | Z10: =+X10+T10+P10+L10 -> 0
A11: 3 | B11: Ҳукумат | C11: =E11+I11+M11+Q11+U11 -> 0 | D11: =F11+J11+N11+R11+V11 -> 0 | Y11: =+W11+S11+O11+K11 -> 0 | Z11: =+X11+T11+P11+L11 -> 0 | AC11: =+'Aging Analysis'!C11 -> 0
B12: шундан, таъминланмаган қисми | C12: =E12+I12+M12+Q12+U12 -> 0 | D12: =F12+J12+N12+R12+V12 -> 0 | Y12: =+W12+S12+O12+K12 -> 0 | Z12: =+X12+T12+P12+L12 -> 0
A13: 4 | B13: Жисмоний шахслар | C13: =E13+I13+M13+Q13+U13 -> 5463367169 | D13: =F13+J13+N13+R13+V13 -> 0 | E13: 5326427523 | F13: 0 | G13: 53264275 | H13: 0 | I13: 86600966 | J13: 0 | K13: 8592799 | L13: 0 | M13: 25017834 | N13: 0 | O13: 6063606 | P13: 0 | Q13: 18412252 | R13: 0 | S13: 8853606 | T13: 0 | U13: 6908594 | V13: 0 | W13: 6238672 | X13: 0 | Y13: =+W13+S13+O13+K13 -> 29748683 | Z13: =+X13+T13+P13+L13 -> 0 | AA13: 0 | AB13: 16092828 | AC13: =+'Aging Analysis'!C12 -> 5463367169
B14: шундан, таъминланмаган қисми | C14: =E14+I14+M14+Q14+U14 -> 0 | D14: =F14+J14+N14+R14+V14 -> 0 | E14: 0 | F14: 0 | G14: 0 | H14: 0 | I14: 0 | J14: 0 | K14: 0 | L14: 0 | M14: 0 | N14: 0 | O14: 0 | P14: 0 | Q14: 0 | R14: 0 | S14: 0 | T14: 0 | U14: 0 | V14: 0 | W14: 0 | X14: 0 | Y14: =+W14+S14+O14+K14 -> 0 | Z14: =+X14+T14+P14+L14 -> 0
A15: 5 | B15: Давлат корхоналари | C15: =E15+I15+M15+Q15+U15 -> 14093170226 | D15: =F15+J15+N15+R15+V15 -> 9576038371 | E15: 13717203032 | F15: 9508685611 | G15: 110259025 | H15: 0 | I15: 375967194 | J15: 67352760 | K15: 37596719 | L15: 6735276 | M15: 0 | N15: 0 | O15: 0 | P15: 0 | Q15: 0 | R15: 0 | S15: 0 | T15: 0 | U15: 0 | V15: 0 | W15: 0 | X15: 0 | Y15: =+W15+S15+O15+K15 -> 37596719 | Z15: =+X15+T15+P15+L15 -> 6735276 | AA15: 0 | AB15: 0 | AC15: =+'Aging Analysis'!C13 -> 14093170226
B16: шундан, таъминланмаган қисми | C16: =E16+I16+M16+Q16+U16 -> 0 | D16: =F16+J16+N16+R16+V16 -> 0 | E16: 0 | F16: 0 | G16: 0 | H16: 0 | I16: 0 | J16: 0 | K16: 0 | L16: 0 | M16: 0 | N16: 0 | O16: 0 | P16: 0 | Q16: 0 | R16: 0 | S16: 0 | T16: 0 | U16: 0 | V16: 0 | W16: 0 | X16: 0 | Y16: =+W16+S16+O16+K16 -> 0 | Z16: =+X16+T16+P16+L16 -> 0
A17: 6 | B17: Қўшма ва чет эл капитали иштирокидаги корхоналар | C17: =E17+I17+M17+Q17+U17 -> 9080290501 | D17: =F17+J17+N17+R17+V17 -> 7941053189 | E17: 8484483815 | F17: 7364846691 | G17: 84844838 | H17: 0 | I17: 218058951 | J17: 217658951 | K17: 21805895 | L17: 21765895 | M17: 66012521 | N17: 46812333 | O17: 16503130 | P17: 11703083 | Q17: 302666165 | R17: 302666165 | S17: 151333083 | T17: 151333083 | U17: 9069049 | V17: 9069049 | W17: 9069049 | X17: 9069049 | Y17: =+W17+S17+O17+K17 -> 198711157 | Z17: =+X17+T17+P17+L17 -> 193871110 | AA17: 0 | AB17: 0 | AC17: =+'Aging Analysis'!C14 -> 9080290501
B18: шундан, таъминланмаган қисми | C18: =E18+I18+M18+Q18+U18 -> 0 | D18: =F18+J18+N18+R18+V18 -> 0 | E18: 0 | F18: 0 | G18: 0 | H18: 0 | I18: 0 | J18: 0 | K18: 0 | L18: 0 | M18: 0 | N18: 0 | O18: 0 | P18: 0 | Q18: 0 | R18: 0 | S18: 0 | T18: 0 | U18: 0 | V18: 0 | W18: 0 | X18: 0 | Y18: =+W18+S18+O18+K18 -> 0 | Z18: =+X18+T18+P18+L18 -> 0
A19: 7 | B19: Хусусий корхоналар | C19: =E19+I19+M19+Q19+U19 -> 19254967029 | D19: =F19+J19+N19+R19+V19 -> 13208485774 | E19: 16537850982 | F19: 11383471585 | G19: 165378510 | H19: 0 | I19: 1829878783 | J19: 1356486852 | K19: 182987879 | L19: 135648686 | M19: 335528940 | N19: 181918056 | O19: 82728319 | P19: 44413096 | Q19: 490888293 | R19: 252257337 | S19: 245440179 | T19: 126128669 | U19: 60820031 | V19: 34351944 | W19: 60820030 | X19: 34351944 | Y19: =+W19+S19+O19+K19 -> 571976407 | Z19: =+X19+T19+P19+L19 -> 340542395 | AA19: 926786525 | AB19: 46859020 | AC19: =+'Aging Analysis'!C15 -> 19254967029
B20: шундан, таъминланмаган қисми | C20: =E20+I20+M20+Q20+U20 -> 0 | D20: =F20+J20+N20+R20+V20 -> 0 | E20: 0 | F20: 0 | G20: 0 | H20: 0 | I20: 0 | J20: 0 | K20: 0 | L20: 0 | M20: 0 | N20: 0 | O20: 0 | P20: 0 | Q20: 0 | R20: 0 | S20: 0 | T20: 0 | U20: 0 | V20: 0 | W20: 0 | X20: 0 | Y20: =+W20+S20+O20+K20 -> 0 | Z20: =+X20+T20+P20+L20 -> 0
A21: 8 | B21: Фермер хўжалиги | C21: =E21+I21+M21+Q21+U21 -> 171788067 | D21: =F21+J21+N21+R21+V21 -> 102565310 | E21: 89223633 | F21: 50848569 | G21: 892236 | H21: 0 | I21: 45320594 | J21: 43464476 | K21: 4532059 | L21: 4346448 | M21: 9188880 | N21: 0 | O21: 2297220 | P21: 0 | Q21: 16591663 | R21: 8252265 | S21: 8295831 | T21: 4126132 | U21: 11463297 | V21: 0 | W21: 11463297 | X21: 0 | Y21: =+W21+S21+O21+K21 -> 26588407 | Z21: =+X21+T21+P21+L21 -> 8472580 | AA21: 0 | AB21: 5719014 | AC21: =+'Aging Analysis'!C16 -> 171788067
B22: шундан, таъминланмаган қисми | C22: =E22+I22+M22+Q22+U22 -> 0 | D22: =F22+J22+N22+R22+V22 -> 0 | E22: 0 | F22: 0 | G22: 0 | H22: 0 | I22: 0 | J22: 0 | K22: 0 | L22: 0 | M22: 0 | N22: 0 | O22: 0 | P22: 0 | Q22: 0 | R22: 0 | S22: 0 | T22: 0 | U22: 0 | V22: 0 | W22: 0 | X22: 0 | Y22: =+W22+S22+O22+K22 -> 0 | Z22: =+X22+T22+P22+L22 -> 0
A23: 9 | B23: Нобанк молиявий институтлар | C23: =E23+I23+M23+Q23+U23 -> 2059286 | D23: =F23+J23+N23+R23+V23 -> 0 | E23: 2059286 | F23: 0 | G23: 20593 | H23: 0 | I23: 0 | J23: 0 | K23: 0 | L23: 0 | M23: 0 | N23: 0 | O23: 0 | P23: 0 | Q23: 0 | R23: 0 | S23: 0 | T23: 0 | U23: 0 | V23: 0 | W23: 0 | X23: 0 | Y23: =+W23+S23+O23+K23 -> 0 | Z23: =+X23+T23+P23+L23 -> 0 | AA23: 0 | AB23: 0 | AC23: =+'Aging Analysis'!C17 -> 2059286
B24: шундан, таъминланмаган қисми | C24: =E24+I24+M24+Q24+U24 -> 0 | D24: =F24+J24+N24+R24+V24 -> 0 | E24: 0 | F24: 0 | G24: 0 | H24: 0 | I24: 0 | J24: 0 | K24: 0 | L24: 0 | M24: 0 | N24: 0 | O24: 0 | P24: 0 | Q24: 0 | R24: 0 | S24: 0 | T24: 0 | U24: 0 | V24: 0 | W24: 0 | X24: 0 | Y24: =+W24+S24+O24+K24 -> 0 | Z24: =+X24+T24+P24+L24 -> 0
A25: 10 | B25: Нодавлат нотижорат ташкилотлар | C25: =E25+I25+M25+Q25+U25 -> 10242602 | D25: =F25+J25+N25+R25+V25 -> 0 | E25: 3049477 | F25: 0 | G25: 30495 | H25: 0 | I25: 1074164 | J25: 0 | K25: 107416 | L25: 0 | M25: 1041035 | N25: 0 | O25: 195258 | P25: 0 | Q25: 1884435 | R25: 0 | S25: 882546 | T25: 0 | U25: 3193491 | V25: 0 | W25: 3006146 | X25: 0 | Y25: =+W25+S25+O25+K25 -> 4191366 | Z25: =+X25+T25+P25+L25 -> 0 | AA25: 0 | AB25: 1288476 | AC25: =+'Aging Analysis'!C18 -> 10242602
B26: шундан, таъминланмаган қисми | C26: =E26+I26+M26+Q26+U26 -> 0 | D26: =F26+J26+N26+R26+V26 -> 0 | Y26: =+W26+S26+O26+K26 -> 0 | Z26: =+X26+T26+P26+L26 -> 0
A27: 11 | B27: Бюджет ташкилотлари | C27: =E27+I27+M27+Q27+U27 -> 0 | D27: =F27+J27+N27+R27+V27 -> 0 | Y27: =+W27+S27+O27+K27 -> 0 | Z27: =+X27+T27+P27+L27 -> 0 | AA27: 0 | AB27: 0 | AC27: =+'Aging Analysis'!C19 -> 0
B28: шундан, таъминланмаган қисми | C28: =E28+I28+M28+Q28+U28 -> 0 | D28: =F28+J28+N28+R28+V28 -> 0 | Y28: =+W28+S28+O28+K28 -> 0 | Z28: =+X28+T28+P28+L28 -> 0
A29: 12 | B29: Бошқалар | C29: =E29+I29+M29+Q29+U29 -> 0 | D29: =F29+J29+N29+R29+V29 -> 0 | Y29: =+W29+S29+O29+K29 -> 0 | Z29: =+X29+T29+P29+L29 -> 0 | AA29: 0 | AB29: 386400 | AC29: =+'Aging Analysis'!C20 -> 0
B30: шундан, таъминланмаган қисми | C30: =E30+I30+M30+Q30+U30 -> 0 | D30: =F30+J30+N30+R30+V30 -> 0 | Y30: =+W30+S30+O30+K30 -> 0 | Z30: =+X30+T30+P30+L30 -> 0
A31: 13 | B31: Жами кредит ва лизинг суммаси | C31: =+C7+C9+C11+C13+C15+C17+C19+C21+C23+C25+C27+C29 -> 48075884880 | D31: =+D7+D9+D11+D13+D15+D17+D19+D21+D23+D25+D27+D29 -> 30828142644 | E31: =+E7+E9+E11+E13+E15+E17+E19+E21+E23+E25+E27+E29 -> 44160297748 | F31: =+F7+F9+F11+F13+F15+F17+F19+F21+F23+F25+F27+F29 -> 28307852456 | G31: =+G7+G9+G11+G13+G15+G17+G19+G21+G23+G25+G27+G29 -> 414689972 | H31: =+H7+H9+H11+H13+H15+H17+H19+H21+H23+H25+H27+H29 -> 0 | I31: =+I7+I9+I11+I13+I15+I17+I19+I21+I23+I25+I27+I29 -> 2556900652 | J31: =+J7+J9+J11+J13+J15+J17+J19+J21+J23+J25+J27+J29 -> 1684963039 | ... AB31: =+AB7+AB9+AB11+AB13+AB15+AB17+AB19+AB21+AB23+AB25+AB27+AB29 -> 70345738 | AC31: =+'Loans Receivable'!C85 -> 48075884880
B32: шундан, таъминланмаган қисми | C32: =+C8+C10+C12+C14+C16+C18+C20+C22+C24+C26+C28+C30 -> 0 | D32: =+D8+D10+D12+D14+D16+D18+D20+D22+D24+D26+D28+D30 -> 0 | E32: =+E8+E10+E12+E14+E16+E18+E20+E22+E24+E26+E28+E30 -> 0 | F32: =+F8+F10+F12+F14+F16+F18+F20+F22+F24+F26+F28+F30 -> 0 | G32: =+G8+G10+G12+G14+G16+G18+G20+G22+G24+G26+G28+G30 -> 0 | H32: =+H8+H10+H12+H14+H16+H18+H20+H22+H24+H26+H28+H30 -> 0 | I32: =+I8+I10+I12+I14+I16+I18+I20+I22+I24+I26+I28+I30 -> 0 | J32: =+J8+J10+J12+J14+J16+J18+J20+J22+J24+J26+J28+J30 -> 0 | ... Z32: =+Z8+Z10+Z12+Z14+Z16+Z18+Z20+Z22+Z24+Z26+Z28+Z30 -> 0
B33: Иқтисодиёт соҳалари бўйича
A35: 14 | B35: Саноат | C35: =E35+I35+M35+Q35+U35 -> 25973436689 | D35: =F35+J35+N35+R35+V35 -> 20452888759 | E35: 23956057531 | F35: 18751236268 | G35: 212647570 | H35: 0 | I35: 1243233736 | J35: 1012742617 | K35: 124323374 | L35: 101274262 | M35: 183401890 | N35: 163938428 | O35: 45850473 | P35: 40984608 | Q35: 558792549 | R35: 497220482 | S35: 279392307 | T35: 248610241 | U35: 31950983 | V35: 27750964 | W35: 31950983 | X35: 27750964 | Y35: =+W35+S35+O35+K35 -> 481517137 | Z35: =+X35+T35+P35+L35 -> 418620075 | AA35: 926786525 | AB35: 171235 | AC35: =+'Aging Analysis'!C25 -> 25973436689
