Workbook
Name jop: #REF!
Name kol: #REF!
Name RISKTOTASS: SUM('[6]Calculation of Risk Weighted As'!$C$38:$F$38)
Name RISKTOTASS: SUM('[7]Calculation of Risk Weighted As'!$C$41:$G$41)
Name TwentyLargestData: #REF!
Name Е: #REF!

Sheet Asset quality
A1: ИНФОРМАЦИЯ О КАЧЕСТВЕ АКТИВОВ, ОЦЕНИВАЕМЫХ В ЦЕЛЯХ СОЗДАНИЯ РЕЗЕРВА НА ВОЗМОЖНЫЕ ПОТЕРИ | R1: Таблица-2 | U1: №3
B3: АК "Алокабанк" | P3: 44196 | S3: тыс. сум
A4: № | B4: Состав активов* | C4: Остаток | D4: Категория качества | I4: Просроченная задолженность (брутто) | N4: Резерв на возможные потери
I5: итого | J5: до 30 дней | K5: от 31 до 90 дней | L5: от 91 до 180 дней | M5: свыше 180 дней | N5: фактически сформированный
N6: итого | O6: по категориям качества
D7: I | E7: II | F7: III | G7: IV | H7: V | O7: I | P7: II | Q7: III | R7: IV | S7: V
A8: А | B8: Б | C8: В | D8: Г | E8: Д | F8: Е | G8: Ж | H8: З | I8: И | J8: К | K8: Л | L8: М | M8: Н | N8: О | O8: П | P8: Р | Q8: С | R8: Т | S8: У
B9: ВСЕГО АКТИВОВ | C9: =SUM(C10:C60) -> 8108166331 | D9: =SUM(D10:D60) -> 8018633034 | E9: =SUM(E10:E60) -> 92173584 | F9: =SUM(F10:F60) -> 3580002 | G9: =SUM(G10:G60) -> 1568386 | H9: =SUM(H10:H60) -> 2291299 | I9: =SUM(I10:I60) -> 47490418 | J9: =SUM(J10:J60) -> 12969480 | ... S9: =SUM(S10:S60) -> 1518185
A10: 1 | B10: Кассовая наличность и другие платежные документы | C10: =SUM(D10:H10)-N10+O10 -> 252071807 | D10: 252071807 | I10: =SUM(J10:M10) -> 0 | N10: =SUM(O10:S10) -> 0 | T10: 10100
A11: 2 | B11: К получению из ЦБРУ | C11: =SUM(D11:H11)-N11+O11 -> 376855943 | D11: 376855943 | I11: =SUM(J11:M11) -> 0 | N11: =SUM(O11:S11) -> 0 | T11: 10300
A12: 3 | B12: К получению из других банков | C12: =SUM(D12:H12)-N12+O12 -> 445250157 | D12: 445250157 | I12: =SUM(J12:M12) -> 0 | N12: =SUM(O12:S12) -> 0 | T12: 10500
A13: 4 | B13: Ценные бумаги для купли и продажи | C13: =SUM(D13:H13)-N13+O13 -> 370787088 | D13: 370787088 | I13: =SUM(J13:M13) -> 0 | N13: =SUM(O13:S13) -> 0 | T13: 10700
A14: 5 | B14: Инвестиции в ценные бумаги, имеющиеся в наличии для продажи | C14: =SUM(D14:H14)-N14+O14 -> 0 | D14: 0 | I14: =SUM(J14:M14) -> 0 | N14: =SUM(O14:S14) -> 0 | T14: 10800
A15: 6 | B15: Драгоценные металлы, камни и монеты для купли и продажи | C15: =SUM(D15:H15)-N15+O15 -> 251 | D15: 251 | I15: =SUM(J15:M15) -> 0 | N15: =SUM(O15:S15) -> 0 | T15: 10900
A16: 7 | B16: Купленные дебиторские задолженности - Факторинг | C16: =SUM(D16:H16)-N16+O16 -> 0 | D16: 0 | I16: =SUM(J16:M16) -> 0 | N16: =SUM(O16:S16) -> 0 | T16: 11100
A17: 8 | B17: Купленные векселя | C17: =SUM(D17:H17)-N17+O17 -> 0 | D17: 0 | I17: =SUM(J17:M17) -> 0 | N17: =SUM(O17:S17) -> 0 | T17: 11300
A18: 9 | B18: Обязательства клиентов по траттам под аккредитив и/или трастовые документы | C18: =SUM(D18:H18)-N18+O18 -> 8617398 | D18: 8617398 | I18: =SUM(J18:M18) -> 0 | N18: =SUM(O18:S18) -> 0 | T18: 11500
A19: 10 | B19: Обязательства лиентов по непогашенным акцептам банка | C19: =SUM(D19:H19)-N19+O19 -> 0 | D19: 0 | I19: =SUM(J19:M19) -> 0 | N19: =SUM(O19:S19) -> 0 | T19: 11700
A20: 11 | B20: Купленные по сделкам РЕПО ценные бумаги | C20: =SUM(D20:H20)-N20+O20 -> 0 | D20: 0 | I20: =SUM(J20:M20) -> 0 | N20: =SUM(O20:S20) -> 0 | T20: 11800
A21: 12 | B21: Краткосрочные кредиты, предоставленные ЦБРУ | C21: =SUM(D21:H21)-N21+O21 -> 0 | D21: 0 | I21: =SUM(J21:M21) -> 0 | N21: =SUM(O21:S21) -> 0 | T21: 11900
... A24: 15 | B24: Краткосрочные кредиты, предоставленные бюджетным организациям | C24: =SUM(D24:H24)-N24+O24 -> 0 | D24: 0 | I24: =SUM(J24:M24) -> 0 | N24: =SUM(O24:S24) -> 0 | T24: 12400
A25: 16 | B25: Краткосрочные кредиты, предоставленные физическим лицам | C25: =SUM(D25:H25)-N25+O25 -> 148162141 | D25: 148154877 | E25: 14950 | F25: 1698 | G25: 21462 | H25: 71351 | I25: =SUM(J25:M25) -> 795643 | J25: 481223 | K25: 186380 | L25: 31478 | M25: 96562 | N25: =SUM(O25:S25) -> 1722693 | O25: 1620496 | P25: 9385 | Q25: 0 | R25: 21462 | S25: 71350 | T25: 12500
A26: 17 | B26: Краткосрочные кредиты, предоставленные индивидуальным предпринимателям | C26: =SUM(D26:H26)-N26+O26 -> 11443778 | D26: 11443778 | I26: =SUM(J26:M26) -> 0 | J26: 0 | K26: 0 | L26: 0 | M26: 0 | N26: =SUM(O26:S26) -> 125170 | O26: 125170 | T26: 12600
A27: 18 | B27: Краткосрочные кредиты, предоставленные государственным предприятиям, организациям и учреждениям | C27: =SUM(D27:H27)-N27+O27 -> 52510405 | D27: 52510405 | I27: =SUM(J27:M27) -> 0 | J27: 0 | K27: 0 | L27: 0 | M27: 0 | N27: =SUM(O27:S27) -> 574351 | O27: 574351 | T27: 12700
A28: 19 | B28: Краткосрочные кредиты, предоставленные при содействии Государственного фонда поддержки развития предпринимательской деятельности | C28: =SUM(D28:H28)-N28+O28 -> 0 | I28: =SUM(J28:M28) -> 0 | J28: 0 | K28: 0 | L28: 0 | M28: 0 | N28: =SUM(O28:S28) -> 0 | O28: 0 | T28: 12800
A29: 20 | B29: Краткосрочные кредиты, предоставленные предприятиям с участием иностранного капитала | C29: =SUM(D29:H29)-N29+O29 -> 22000000 | D29: 22000000 | I29: =SUM(J29:M29) -> 0 | J29: 0 | K29: 0 | L29: 0 | M29: 0 | N29: =SUM(O29:S29) -> 240633 | O29: 240633 | T29: 12900
A30: 21 | B30: Краткосрочные кредиты, предоставленные негосударственным некоммерческим организациям | C30: =SUM(D30:H30)-N30+O30 -> 0 | I30: =SUM(J30:M30) -> 0 | J30: 0 | K30: 0 | L30: 0 | M30: 0 | N30: =SUM(O30:S30) -> 0 | O30: 0 | T30: 13000
A31: 22 | B31: Краткосрочные кредиты, предоставленные частным предприятиям, хозяйственным товариществам и обществам | C31: =SUM(D31:H31)-N31+O31 -> 378174633 | D31: 374390579 | E31: 4101289 | F31: 23090 | G31: 0 | H31: 0 | I31: =SUM(J31:M31) -> 6115073 | J31: 890406 | K31: 890674 | L31: 209614 | M31: 4124379 | N31: =SUM(O31:S31) -> 4435352 | O31: 4095027 | P31: 317235 | Q31: 23090 | R31: 0 | S31: 0 | T31: 13100
A32: 23 | B32: Краткосрочные кредиты, предоставленные небанковским финансовым институтам | C32: =SUM(D32:H32)-N32+O32 -> 0 | I32: =SUM(J32:M32) -> 0 | J32: 0 | K32: 0 | L32: 0 | M32: 0 | N32: =SUM(O32:S32) -> 0 | O32: 0 | T32: 13200
A33: 24 | B33: Краткосрочные кредиты, предоставленные для производства сельскохозяйственной продукции, закупаемой для государственных нужд | C33: =SUM(D33:H33)-N33+O33 -> 0 | I33: =SUM(J33:M33) -> 0 | J33: 0 | K33: 0 | L33: 0 | M33: 0 | N33: =SUM(O33:S33) -> 0 | O33: 0 | T33: 13300
A34: 25 | B34: Долгосрочные кредиты, предоставленные для производства сельскохозяйственной продукции, закупаемой для государственных нужд | C34: =SUM(D34:H34)-N34+O34 -> 0 | I34: =SUM(J34:M34) -> 0 | J34: 0 | K34: 0 | L34: 0 | M34: 0 | N34: =SUM(O34:S34) -> 0 | O34: 0 | T34: 14300
A35: 26 | B35: Долгосрочные кредиты, предоставленные при содействии Государственного фонда поддержки развития предпринимательской деятельности | C35: =SUM(D35:H35)-N35+O35 -> 7526408 | D35: 7526408 | I35: =SUM(J35:M35) -> 105380 | J35: 62917 | K35: 42463 | L35: 0 | M35: 0 | N35: =SUM(O35:S35) -> 82323 | O35: 82323 | T35: 14400
A36: 27 | B36: Долгосрочные кредиты, предоставленные другим банкам | C36: =SUM(D36:H36)-N36+O36 -> 0 | I36: =SUM(J36:M36) -> 0 | J36: 0 | K36: 0 | L36: 0 | M36: 0 | N36: =SUM(O36:S36) -> 0 | O36: 0 | T36: 14500
A37: 28 | B37: Долгосрочные кредиты, предоставленные правительству | C37: =SUM(D37:H37)-N37+O37 -> 0 | I37: =SUM(J37:M37) -> 0 | J37: 0 | K37: 0 | L37: 0 | M37: 0 | N37: =SUM(O37:S37) -> 0 | O37: 0 | T37: 14700
A38: 29 | B38: Долгосрочные кредиты, предоставленные бюджетным организациям | C38: =SUM(D38:H38)-N38+O38 -> 0 | I38: =SUM(J38:M38) -> 0 | J38: 0 | K38: 0 | L38: 0 | M38: 0 | N38: =SUM(O38:S38) -> 0 | O38: 0 | T38: 14800
A39: 30 | B39: Долгосрочные кредиты, предоставленные физическим лицам | C39: =SUM(D39:H39)-N39+O39 -> 871890514 | D39: 865817982 | E39: 3416846 | F39: 2192229 | G39: 1436376 | H39: 1272415 | I39: =SUM(J39:M39) -> 8184822 | J39: 2667312 | K39: 2919449 | L39: 1332803 | M39: 1265258 | N39: =SUM(O39:S39) -> 11715520 | O39: 9470186 | P39: 727279 | Q39: 470636 | R39: 548116 | S39: 499303 | T39: 14900
A40: 31 | B40: Долгосрочные кредиты, предоставленные индивидуальным предпринимателям | C40: =SUM(D40:H40)-N40+O40 -> 57899605 | D40: 56248350 | E40: 1809771 | F40: 13621 | G40: 0 | H40: 0 | I40: =SUM(J40:M40) -> 614521 | J40: 186583 | K40: 299277 | L40: 122193 | M40: 6468 | N40: =SUM(O40:S40) -> 787373 | O40: 615236 | P40: 168732 | Q40: 3405 | R40: 0 | S40: 0 | T40: 15000
A41: 32 | B41: Долгосрочные кредиты, предоставленные государственным предприятиям, организациям и учреждениям | C41: =SUM(D41:H41)-N41+O41 -> 706562920 | D41: 706562920 | I41: =SUM(J41:M41) -> 0 | J41: 0 | K41: 0 | L41: 0 | M41: 0 | N41: =SUM(O41:S41) -> 7728278 | O41: 7728278 | T41: 15100
A42: 33 | B42: Долгосрочные кредиты, предоставленные негосударственным некоммерческим организациям | C42: =SUM(D42:H42)-N42+O42 -> 14958733 | D42: 10276403 | E42: 5372687 | F42: 0 | I42: =SUM(J42:M42) -> 812510 | J42: 15911 | K42: 83209 | L42: 544318 | M42: 169072 | N42: =SUM(O42:S42) -> 802759 | O42: 112402 | P42: 690357 | Q42: 0 | R42: 0 | S42: 0 | T42: 15200
A43: 34 | B43: Долгосрочные кредиты, предоставленные предприятиям с участием иностранного капитала | C43: =SUM(D43:H43)-N43+O43 -> 431029828 | D43: 409200375 | E43: 22072253 | F43: 0 | I43: =SUM(J43:M43) -> 76626 | J43: 15335 | K43: 30670 | L43: 30621 | M43: 0 | N43: =SUM(O43:S43) -> 4718572 | O43: 4475772 | P43: 242800 | Q43: 0 | R43: 0 | S43: 0 | T43: 15300
...

Sheet Income 
B1: ОТЧЕТ О ФИНАНСОВЫХ РЕЗУЛЬТАТАХ | D1: Таблица-3
B3: =+'Asset quality'!B3 -> АК "Алокабанк" | C3: =+'Asset quality'!P3 -> 44196 | E3: в тыс. сум
A4: № | B4: Категории | C4: Итого | D4: в национальной валюте | E4: в иностранной валюте (в экв. в сумах)
A5: 1. | B5: 1. ПРОЦЕНТНЫЕ ДОХОДЫ
A6: a. | B6: Процентные доходы по счетам в ЦБРУ | C6: =+D6+E6 -> 2418508 | D6: 2418508 | E6: 0
A7: б. | B7: Процентные доходы по счетам в других банках | C7: =+D7+E7 -> 19392899 | D7: 12283332 | E7: 7109567
A8: в. | B8: Процентные доходы по купленным векселям | C8: =+D8+E8 -> 0 | D8: 0 | E8: 0
A9: г. | B9: Процентные доходы по инвестициям | C9: =+D9+E9 -> 0 | D9: 0 | E9: 0
A10: д. | B10: Процентные доходы по счетам купли-продажи ценных бумаг | C10: =+D10+E10 -> 27019780 | D10: 27019780 | E10: 0
A11: е. | B11: Процентные доходы по обязательствам клиентов | C11: =+D11+E11 -> 0 | D11: 0 | E11: 0
A12: ж. | B12: Процентные доходы по обяз-вам клиентов по непогашенным акцептам этого банка | C12: =+D12+E12 -> 14390522 | D12: 6017575 | E12: 8372947
A13: з. | B13: Процент, Дисконт (Скидки) и взносы по кредитным и лизинговым операциям | C13: =+D13+E13 -> 809668910 | D13: 668826621 | E13: 140842289
A14: и. | B14: Процентные доходы по соглашениям о покупке ценных бумаг с обратным выкупом | C14: =+D14+E14 -> 0 | D14: 0 | E14: 0
A15: к. | B15: Другие процентные доходы | C15: =+D15+E15 -> 312983639 | D15: 245717672 | E15: 67265967
A16: л. | B16: Итого процентных доходов | C16: =SUM(C6:C15) -> 1185874258 | D16: =SUM(D6:D15) -> 962283488 | E16: =SUM(E6:E15) -> 223590770 | G16: =+'Analysis of Interest'!C42 -> 1185874258
A18: 2. | B18: ПРОЦЕНТНЫЕ РАСХОДЫ
A19: а. | B19: Процентные расходы по депозитам до востребования | C19: =+D19+E19 -> 2744263 | D19: 2568266 | E19: 175997
A20: б. | B20: Процентные расходы по срочным депозитам | C20: =+D20+E20 -> 405792705 | D20: 361158722 | E20: 44633983
A21: в. | B21: Процентные расходы по счетам к оплате в ЦБРУ | C21: =+D21+E21 -> 0 | D21: 0 | E21: 0
A22: г. | B22: Процентные расходы по счетам к оплате в другие банки | C22: =+D22+E22 -> 55867688 | D22: 35681600 | E22: 20186088
A23: д. | B23: Итого процентных расходов по депозитам | C23: =SUM(C19:C22) -> 464404656 | D23: =SUM(D19:D22) -> 399408588 | E23: =SUM(E19:E22) -> 64996068
A24: е. | B24: Процентные расходы по кредитам к оплате | C24: =+D24+E24 -> 25140419 | D24: 5905209 | E24: 19235210
A25: ж. | B25: Процентные расходы по соглашениям о продаже ц/б с последующим выкупом | C25: =+D25+E25 -> 9175036 | D25: 9175036 | E25: 0
A26: з. | B26: Другие процентные расходы | C26: =+D26+E26 -> 320618142 | D26: 250227780 | E26: 70390362
A27: и. | B27: Итого процентных расходов по займам | C27: =SUM(C24:C26) -> 354933597 | D27: =SUM(D24:D26) -> 265308025 | E27: =SUM(E24:E26) -> 89625572
A28: л. | B28: Итого процентных расходов | C28: =C27+C23 -> 819338253 | D28: =D27+D23 -> 664716613 | E28: =E27+E23 -> 154621640 | G28: =+'Analysis of Interest'!C72 -> 819338253
A30: 3. | B30: ЧИСТЫЕ ПРОЦЕНТНЫЕ ДОХОДЫ ДО ОЦЕНКИ ВОЗМОЖНЫХ УБЫТКОВ ПО АКТИВАМ | C30: =C16-C28 -> 366536005 | D30: =D16-D28 -> 297566875 | E30: =E16-E28 -> 68969130
A31: а. | B31: Минус: Оценка возможных убытков по кредитам и лизингу | C31: =+D31+E31 -> 12410997 | D31: 12056751 | E31: 354246
A32: б. | B32: Минус: Оценка возможных убытков по в ценным бумагам | C32: =+D32+E32 -> 0 | D32: 0 | E32: 0
A33: в. | B33: Минус: Оценка возможных убытков по инвестициям | C33: =+D33+E33 -> 0 | D33: 0 | E33: 0
A34: г. | B34: Минус: Оценка возможных убытков по другим активам | C34: =+D34+E34 -> 1375976 | D34: 1375976 | E34: 0
A35: д. | B35: Чистые процентные доходы после оценки возможных убытков по кредитам и лизингу | C35: =C30-C31-C32-C33-C34 -> 352749032 | D35: =D30-D31-D32-D33-D34 -> 284134148 | E35: =E30-E31-E32-E33-E34 -> 68614884
A37: 4. | B37: БЕСПРОЦЕНТНЫЕ ДОХОДЫ
A38: а. | B38: Доходы от комиссий и платы за услуги | C38: =+D38+E38 -> 193159885 | D38: 185807323 | E38: 7352562
A39: б. | B39: Прибыль в иностранной валюте | C39: =+D39+E39 -> 69811238 | D39: 6140505 | E39: 63670733
A40: в. | B40: Прибыль от коммерческих операций | C40: =+D40+E40 -> 0 | D40: 0 | E40: 0
A41: г. | B41: Прибыль и дивиденды от инвестиций | C41: =+D41+E41 -> 3427132 | D41: 3427132 | E41: 0
A42: д. | B42: Другие беспроцентные доходы | C42: =+D42+E42 -> 28083485 | D42: 23997307 | E42: 4086178
A43: е. | B43: Итого беспроцентных доходов | C43: =SUM(C38:C42) -> 294481740 | D43: =SUM(D38:D42) -> 219372267 | E43: =SUM(E38:E42) -> 75109473
A45: 5. | B45: БЕСПРОЦЕНТНЫЕ РАСХОДЫ
...

Sheet Analysis of Interest
B1: АНАЛИЗ ПРОЦЕНТНЫХ ДОХОДОВ И РАСХОДОВ | C1: Таблица-4
B3: =+'Asset quality'!B3 -> АК "Алокабанк" | C3: =+'Asset quality'!P3 -> 44196
A4: № | B4: Категория | C4: в тыс. сум
A5: 1 . | B5: ПРОЦЕНТНЫЕ ДОХОДЫ ПО КРЕДИТНЫМ И ЛИЗИНГОВЫМ ОПЕРАЦИЯМ
A6: a. | B6: Кредиты и лизинговые операции ЦБРУ | C6: 0
A7: б. | B7: Кредиты и лизинговые операции другим банкам | C7: 0
A8: в. | B8: Кредиты и лизинговые операции Правительству | C8: 0
A9: г. | B9: Кредиты и лизинговые операции физическим лицам | C9: 198040984
A10: д. | B10: Кредиты и лизинговые операции государственным предприятиям | C10: 75953823
A11: е. | B11: Кредиты и лизинговые операции совместным и иностранным предприятиям | C11: 70472407
A12: ж. | B12: Кредиты и лизинговые операции частным товариществам и корпорациям | C12: 445373824
A13: з. | B13: Другие кредиты и лизинговые операции | C13: 19827873
A14: и. | B14: ИТОГО ПРОЦЕНТНЫХ ДОХОДОВ ПО КРЕДИТНЫМ И ЛИЗИНГОВЫМ ОПЕРАЦИЯМ | C14: =SUM(C6:C13) -> 809668911
A16: 2. | B16: ПРОЦЕНТНЫЕ ДОХОДЫ ПО КОРРЕСПОНДЕНТСКИМ СЧЕТАМ
A17: a. | B17: К получению из ЦБРУ | C17: 2418508
A18: б. | B18: К получению из других банков | C18: 19392899
B19: ИТОГО ПРОЦЕНТНЫХ ДОХОДОВ ПО КОРРЕСПОНДЕНТСКИМ СЧЕТАМ | C19: =SUM(C17:C18) -> 21811407
A21: 3. | B21: ПРОЦЕНТНЫЕ ДОХОДЫ ПО СЧЕТАМ КУПЛИ-ПРОДАЖИ Ц/Б
A22: a. | B22: Государственные казначейские ценные бумаги | C22: 9710959
A23: б. | B23: Облигации и ценные бумаги ЦБРУ | C23: 17308821
A24: в. | B24: Ценные бумаги государственных корпораций | C24: 0
A25: г. | B25: Еврооблигации | C25: 0
A26: д. | B26: Частные ценные бумаги | C26: 0
A27: е. | B27: Другие ценные бумаги | C27: 0
A28: ж. | B28: ИТОГО ПРОЦЕНТНЫХ ДОХОДОВ ПО СЧЕТАМ КУПЛИ-ПРОДАЖИ Ц/Б | C28: =SUM(C22:C27) -> 27019780
A30: 4. | B30: ПРОЦЕНТНЫЕ ДОХОДЫ ПО ИНВЕСТИЦИЯМ
A31: a. | B31: Государственные облигации | C31: 0
A32: б. | B32: Облигации и ценные бумаги ЦБРУ | C32: 0
A33: в. | B33: Частные облигации | C33: 0
A34: г. | B34: Еврооблигации | C34: 0
A35: д. | B35: Другие ценные бумаги | C35: 0
A36: е. | B36: ИТОГО ПРОЦЕНТНЫХ ДОХОДОВ ПО ИНВЕСТИЦИЯМ | C36: =SUM(C31:C35) -> 0
A38: 5. | B38: ДРУГИЕ ПРОЦЕНТНЫЕ ДОХОДЫ
A39: a. | B39: Процентные доходы по соглашениям о покупке ц/б c обратным выкупом | C39: 0
A40: б. | B40: Другие процентные доходы | C40: 327374160
A42: 6. | B42: ИТОГО ПРОЦЕНТНЫХ ДОХОДОВ | C42: =C14+C19+C28+C36+C39+C40 -> 1185874258
A44: 7. | B44: ПРОЦЕНТНЫЕ РАСХОДЫ ПО ДЕПОЗИТАМ
A45: A. | B45: Депозиты до востребования
A46: a. | B46: Правительство | C46: 1302247
A47: б. | B47: Физические лица | C47: 4748
...

Sheet Changes in Equity
B1: ИЗМЕНЕНИЯ В СОБСТВЕННОМ КАПИТАЛЕ | C1: Таблица-7
B3: =+'Asset quality'!B3 -> АК "Алокабанк" | C3: =+'Asset quality'!P3 -> 44196
A4: № | B4: Категория | C4: в тыс. сум
A5: 1. | B5: Итого собственного капитала первоначально определенного за прошлый год | C5: 1396370695
A6: 2. | B6: Исправления в собственном капитале не показанные в отчете за прошлый год, чистые | C6: -132057
A7: 3. | B7: Исправленный баланс на конец прошлого календарного года (сумма строк 1 и 2) | C7: =SUM(C5:C6) -> 1396238638
A8: 4. | B8: Чистый прибыль (убыток) по состоянию на дату от начала года | C8: =+'Income '!C76 -> 170000000 | D8: =+[8]Balance!$C$76 -> 170000000
A9: 5. | B9: Продажа, Обмен, Приобретение или выкуп акций, за текущий год (чистая выручка) | C9: 0
A10: 6. | B10: Изменения в оценочной стоимости прироста над первонач. стоимостью, за текущий год (чистые) | C10: 3793523
A11: 7. | B11: МИНУС: Денежные дивиденды объявленные по привилегированным акциям | C11: 0
A12: 8. | B12: МИНУС: Денежные дивиденды объявленные по обыкновенным акциям | C12: 0
A13: 9. | B13: Другие статьи влияющие на собственный капитал за текущий год (чистые) | C13: -1502349
A14: 10. | B14: Итого собственного капитала на конец текущего периода (сумма строк с 3 по 10) | C14: =C7+SUM(C8:C10)-SUM(C11:C12)+C13 -> 1568529812 | D14: =+[8]Balance!$C$77 -> 1568529812
B16: Подпись Председателя правления:
B18: Подпись Главного Бухгалтера:

Sheet Loans Receivable
A1: КРЕДИТЫ И ЛИЗИНГИ К ПОЛУЧЕНИЮ ПО ОТРАСЛЯМ ЭКОНОМИКИ, ТИПАМ КЛИЕНТОВ И ПО ТИПУ ОБЕСПЕЧЕНИЯ | W1: Таблица-8
B3: =+'Asset quality'!B3 -> АК "Алокабанк" | T3: =+'Asset quality'!P3 -> 44196 | X3: тыс. сум
A4: № | B4: Отрасль экономики | C4: Сумма кредита | D4: в национальной валюте | F4: в иностранной валюте (в экв. в сумах) | H4: из них | J4: из них
D5: Сумма | E5: средне-взвешенные процентные ставки | F5: Сумма | G5: средне-взвешенные процентные ставки | H5: Начисляемые кредиты | I5: Кредиты переведённые в статус ненаращивания процентов | J5: Депозиты | K5: Гарантированные Правительством Республики Узбекистан | L5: из них | M5: Транспортные средства | N5: Инвентарь | O5: Недвижимость | P5: из них | R5: Оборудование | S5: Векселя (облигации) | T5: Акции | U5: Гарантия третьей стороны | V5: Поручительства третьей стороны | W5: Страховой полис | X5: Необеспеченные | Y5: Другое обеспечение
L6: Гарантированные Правительством Республики Узбекистан в иностранной валюте (экв.сум) | P6: жилая недвижимость | Q6: коммерческая недвижимость
A7: Код | B7: (А) | C7: (Б) | D7: (Б1) | E7: (Б2) | F7: (Б3) | G7: (Б4) | H7: (В) | I7: (Г) | J7: (Д) | K7: (Е) | L7: (Е1) | M7: (Ж) | N7: (З) | O7: (И) | P7: (И1) | Q7: (И2) | R7: (К) | S7: (Л) | T7: (М) | U7: (Н) | V7: (О) | W7: (П) | X7: (Р) | Y7: (С)
B8: Промышленность
A9: 10 | B9: Физические лица | C9: =SUM(J9:Y9)-L9-P9-Q9 -> 0 | O9: =+P9+Q9 -> 0
A10: =A9+10 -> 20 | B10: Государственные предприятия | C10: =SUM(J10:Y10)-L10-P10-Q10 -> 61193904 | D10: 61193904 | E10: 0.19267973 | H10: 61193904 | I10: 0 | J10: 0 | K10: 0 | M10: 14126062 | O10: =+P10+Q10 -> 36362525 | Q10: 36362525 | R10: 0 | S10: 0 | T10: 0 | U10: 0 | V10: 10705317 | W10: 0 | X10: 0 | Y10: 0
A11: =A10+10 -> 30 | B11: Совместные и иностранные предприятия | C11: =SUM(J11:Y11)-L11-P11-Q11 -> 220704413 | D11: 180690724 | E11: 0.18963013 | F11: 40013689 | G11: 0.08847224 | H11: 220704413 | I11: 0 | J11: 0 | K11: 0 | M11: 659597 | O11: =+P11+Q11 -> 208326179 | Q11: 208326179 | R11: 9953669 | S11: 0 | T11: 0 | U11: 0 | V11: 1535202 | W11: 229766 | X11: 0 | Y11: 0
A12: =A11+10 -> 40 | B12: Частные товарищества и корпорации | C12: =SUM(J12:Y12)-L12-P12-Q12 -> 679011714 | D12: 273162529 | E12: 0.19607391 | F12: 405849185 | G12: 0.07348888 | H12: 678842521 | I12: 169193 | J12: 30300 | K12: 0 | M12: 44263230 | O12: =+P12+Q12 -> 440006984 | Q12: 440006984 | R12: 185753199 | S12: 0 | T12: 0 | U12: 0 | V12: 8654567 | W12: 275107 | X12: 0 | Y12: 28327
A13: =A12+10 -> 50 | B13: Правительство | C13: =SUM(J13:Y13)-L13-P13-Q13 -> 0 | O13: =+P13+Q13 -> 0
A14: =A13+10 -> 60 | B14: Прочие | C14: =SUM(J14:Y14)-L14-P14-Q14 -> 4438396 | D14: 4438396 | E14: 0.21729926 | H14: 4438396 | M14: 2184879 | O14: =+P14+Q14 -> 2205476 | Q14: 2205476 | R14: 0 | S14: 0 | T14: 0 | U14: 0 | V14: 22627 | W14: 25414 | X14: 0 | Y14: 0
A15: =A14+10 -> 70 | B15: Итого по промышленности | C15: =SUM(J15:Y15)-L15-P15-Q15 -> 965348427 | D15: =SUM(D9:D14) -> 519485553 | E15: =IFERROR(((D9*E9)/D15)+((D10*E10)/D15)+((D11*E11)/D15)+((D12*E12)/D15)+((D13*E13)/D15)+((D14*E14)/D15),0) -> 0.19361411 | F15: =SUM(F9:F14) -> 445862874 | G15: =IFERROR(((F9*G9)/F15)+((F10*G10)/F15)+((F11*G11)/F15)+((F12*G12)/F15)+((F13*G13)/F15)+((F14*G14)/F15),0) -> 0.074833552 | H15: =SUM(H9:H14) -> 965179234 | I15: =SUM(I9:I14) -> 169193 | J15: =SUM(J9:J14) -> 30300 | K15: =SUM(K9:K14) -> 0 | L15: =SUM(L9:L14) -> 0 | M15: =SUM(M9:M14) -> 61233768 | N15: =SUM(N9:N14) -> 0 | O15: =SUM(O9:O14) -> 686901164 | ... Y15: =SUM(Y9:Y14) -> 28327
B16: Сельское хозяйство
A17: =A15+10 -> 80 | B17: Физические лица | C17: =SUM(J17:Y17)-L17-P17-Q17 -> 0 | O17: =+P17+Q17 -> 0
A18: =A17+10 -> 90 | B18: Государственные предприятия | C18: =SUM(J18:Y18)-L18-P18-Q18 -> 0 | O18: =+P18+Q18 -> 0
A19: =A18+10 -> 100 | B19: Совместные и иностранные предприятия | C19: =SUM(J19:Y19)-L19-P19-Q19 -> 0 | O19: =+P19+Q19 -> 0
A20: =A19+10 -> 110 | B20: Частные товарищества и корпорации | C20: =SUM(J20:Y20)-L20-P20-Q20 -> 111388171 | D20: 57688485 | E20: 0.19018186 | F20: 53699686 | G20: 0.093366011 | H20: 111353891 | I20: 34280 | M20: 34580459 | N20: 0 | O20: =+P20+Q20 -> 56037268 | Q20: 56037268 | R20: 14985280 | S20: 0 | T20: 0 | U20: 0 | V20: 5675708 | W20: 109456 | X20: 0 | Y20: 0
A21: =A20+10 -> 120 | B21: Фермерское хозяйство | C21: =SUM(J21:Y21)-L21-P21-Q21 -> 0 | O21: =+P21+Q21 -> 0
A22: =A21+10 -> 130 | B22: Правительство | C22: =SUM(J22:Y22)-L22-P22-Q22 -> 0 | O22: =+P22+Q22 -> 0
A23: =A22+10 -> 140 | B23: Прочие | C23: =SUM(J23:Y23)-L23-P23-Q23 -> 2194100 | D23: 2194100 | E23: 0.18993801 | H23: 2194100 | O23: =+P23+Q23 -> 1838080 | Q23: 1838080 | S23: 0 | T23: 0 | U23: 0 | V23: 149227 | W23: 201136 | X23: 0 | Y23: 5657
A24: =A23+10 -> 150 | B24: Итого по сельскому хозяйству | C24: =SUM(J24:Y24)-L24-P24-Q24 -> 113582271 | D24: =SUM(D17:D23) -> 59882585 | E24: =IFERROR(((D17*E17)/D24)+((D18*E18)/D24)+((D19*E19)/D24)+((D20*E20)/D24)+((D21*E21)/D24)+((D22*E22)/D24)+((D23*E23)/D24),0) -> 0.19017293 | F24: =SUM(F17:F23) -> 53699686 | G24: =IFERROR(((F17*G17)/F24)+((F18*G18)/F24)+((F19*G19)/F24)+((F20*G20)/F24)+((F21*G21)/F24)+((F22*G22)/F24)+((F23*G23)/F24),0) -> 0.093366011 | H24: =SUM(H17:H23) -> 113547991 | I24: =SUM(I17:I23) -> 34280 | J24: =SUM(J17:J23) -> 0 | K24: =SUM(K17:K23) -> 0 | L24: =SUM(L17:L23) -> 0 | M24: =SUM(M17:M23) -> 34580459 | N24: =SUM(N17:N23) -> 0 | O24: =SUM(O17:O23) -> 57875348 | ... Y24: =SUM(Y17:Y23) -> 5657
B25: Транспорт и коммуникации
A26: =A24+10 -> 160 | B26: Физические лица | C26: =SUM(J26:Y26)-L26-P26-Q26 -> 0 | O26: =+P26+Q26 -> 0
A27: =A26+10 -> 170 | B27: Государственные предприятия | C27: =SUM(J27:Y27)-L27-P27-Q27 -> 363140450 | D27: 363140450 | E27: 0.12184635 | H27: 363140450 | J27: 216263967 | K27: 0 | M27: 7032 | N27: 0 | O27: =+P27+Q27 -> 133604201 | Q27: 133604201 | R27: 0 | S27: 0 | T27: 0 | U27: 0 | V27: 33600 | W27: 13231650 | X27: 0 | Y27: 0
A28: =A27+10 -> 180 | B28: Совместные и иностранные предприятия | C28: =SUM(J28:Y28)-L28-P28-Q28 -> 99981592 | D28: 99981592 | E28: 0.15 | H28: 99981592 | J28: 0 | K28: 0 | M28: 0 | N28: 0 | O28: =+P28+Q28 -> 99981592 | Q28: 99981592 | R28: 0 | S28: 0 | T28: 0 | U28: 0 | V28: 0 | W28: 0 | X28: 0 | Y28: 0
A29: =A28+10 -> 190 | B29: Частные товарищества и корпорации | C29: =SUM(J29:Y29)-L29-P29-Q29 -> 65589004 | D29: 54445535 | E29: 0.20415534 | F29: 11143469 | G29: 0.094929392 | H29: 65589004 | J29: 45114 | K29: 0 | M29: 39854264 | N29: 0 | O29: =+P29+Q29 -> 25107788 | Q29: 25107788 | R29: 241698 | S29: 0 | T29: 0 | U29: 0 | V29: 251059 | W29: 89081 | X29: 0 | Y29: 0
A30: =A29+10 -> 200 | B30: Правительство | C30: =SUM(J30:Y30)-L30-P30-Q30 -> 0 | O30: =+P30+Q30 -> 0
A31: =A30+10 -> 210 | B31: Прочие | C31: =SUM(J31:Y31)-L31-P31-Q31 -> 14611472 | D31: 14611472 | E31: 0.21427128 | H31: 14611472 | J31: 30430 | K31: 0 | M31: 13837573 | N31: 0 | O31: =+P31+Q31 -> 655997 | Q31: 655997 | R31: 0 | S31: 0 | T31: 0 | U31: 0 | V31: 5796 | W31: 81676 | X31: 0 | Y31: 0
A32: =A31+10 -> 220 | B32: Итого по транспорту и коммуникациям | C32: =SUM(J32:Y32)-L32-P32-Q32 -> 543322518 | D32: =SUM(D26:D31) -> 532179049 | E32: =IFERROR(((D26*E26)/D32)+((D27*E27)/D32)+((D28*E28)/D32)+((D29*E29)/D32)+((D30*E30)/D32)+((D31*E31)/D32),0) -> 0.13809402 | F32: =SUM(F26:F31) -> 11143469 | G32: =IFERROR(((F26*G26)/F32)+((F27*G27)/F32)+((F28*G28)/F32)+((F29*G29)/F32)+((F30*G30)/F32)+((F31*G31)/F32),0) -> 0.094929392 | H32: =SUM(H26:H31) -> 543322518 | I32: =SUM(I26:I31) -> 0 | J32: =SUM(J26:J31) -> 216339511 | K32: =SUM(K26:K31) -> 0 | L32: =SUM(L26:L31) -> 0 | M32: =SUM(M26:M31) -> 53698869 | N32: =SUM(N26:N31) -> 0 | O32: =SUM(O26:O31) -> 259349578 | ... Y32: =SUM(Y26:Y31) -> 0
B33: Строительство
A34: =A32+10 -> 230 | B34: Физические лица | C34: =SUM(J34:Y34)-L34-P34-Q34 -> 0 | O34: =+P34+Q34 -> 0
A35: =A34+10 -> 240 | B35: Государственные предприятия | C35: =SUM(J35:Y35)-L35-P35-Q35 -> 245351 | D35: 245351 | E35: 0.23807764 | H35: 245351 | J35: 0 | K35: 0 | M35: 243716 | N35: 0 | O35: =+P35+Q35 -> 0 | Q35: 0 | R35: 0 | S35: 0 | T35: 0 | U35: 0 | V35: 0 | W35: 1635 | X35: 0 | Y35: 0
A36: =A35+10 -> 250 | B36: Совместные и иностранные предприятия | C36: =SUM(J36:Y36)-L36-P36-Q36 -> 0 | H36: 0 | J36: 0 | K36: 0 | M36: 0 | N36: 0 | O36: =+P36+Q36 -> 0 | Q36: 0 | R36: 0 | S36: 0 | T36: 0 | U36: 0 | V36: 0 | W36: 0 | X36: 0 | Y36: 0
A37: =A36+10 -> 260 | B37: Частные товарищества и корпорации | C37: =SUM(J37:Y37)-L37-P37-Q37 -> 283095278 | D37: 162329475 | E37: 0.20526708 | F37: 120765803 | G37: 0.079655054 | H37: 283095278 | J37: 305412 | K37: 0 | M37: 43361438 | N37: 0 | O37: =+P37+Q37 -> 196853232 | Q37: 196853232 | R37: 40230902 | S37: 0 | T37: 0 | U37: 0 | V37: 2183563 | W37: 160731 | X37: 0 | Y37: 0
A38: =A37+10 -> 270 | B38: Правительство | C38: =SUM(J38:Y38)-L38-P38-Q38 -> 0 | O38: =+P38+Q38 -> 0
A39: =A38+10 -> 280 | B39: Прочие | C39: =SUM(J39:Y39)-L39-P39-Q39 -> 0 | O39: =+P39+Q39 -> 0
A40: =A39+10 -> 290 | B40: Итого по строительству | C40: =SUM(J40:Y40)-L40-P40-Q40 -> 283340629 | D40: =SUM(D34:D39) -> 162574826 | E40: =IFERROR(((D34*E34)/D40)+((D35*E35)/D40)+((D36*E36)/D40)+((D37*E37)/D40)+((D38*E38)/D40)+((D39*E39)/D40),0) -> 0.2053166 | F40: =SUM(F34:F39) -> 120765803 | G40: =IFERROR(((F34*G34)/F40)+((F35*G35)/F40)+((F36*G36)/F40)+((F37*G37)/F40)+((F38*G38)/F40)+((F39*G39)/F40),0) -> 0.079655054 | H40: =SUM(H34:H39) -> 283340629 | I40: =SUM(I34:I39) -> 0 | J40: =SUM(J34:J39) -> 305412 | K40: =SUM(K34:K39) -> 0 | L40: =SUM(L34:L39) -> 0 | M40: =SUM(M34:M39) -> 43605154 | N40: =SUM(N34:N39) -> 0 | O40: =SUM(O34:O39) -> 196853232 | ... Y40: =SUM(Y34:Y39) -> 0
B41: Торговля и общественное питание
...

Sheet Aging Analysis
A1: АНАЛИЗ ПРОСРОЧЕННЫХ КРЕДИТОВ И ФИНАНСОВОГО ЛИЗИНГА К ПОЛУЧЕНИЮ | X1: Таблица-9
B3: =+'Asset quality'!B3 -> АК "Алокабанк" | T3: =+'Asset quality'!P3 -> 44196 | X3: тыс. сум
A4: № | B4: Характеристики | C4: Всего задолжность по кредитам | D4: % | E4: Реструктуризированные кредиты | F4: % | G4: В ходе судебного разбирательства | H4: % | I4: Просроченная задолжность | K4: % | L4: в том числе, анализ временной задолженности
L5: 1-30 дней | N5: 31-60 дней | P5: 61-90 дней | R5: 91-180 дней | T5: 181-365 дней | V5: 366-730 дней | X5: Свыше 2 лет
I6: основной долг | J6: процент | L6: основной долг | M6: процент | N6: основной долг | O6: процент | P6: основной долг | Q6: процент | R6: основной долг | S6: процент | T6: основной долг | U6: процент | V6: основной долг | W6: процент | X6: основной долг | Y6: процент
B7: (А) | C7: (Б) | D7: (В) | E7: (Г) | F7: (Д) | G7: (Е) | H7: (Ж) | I7: (З) | J7: (З1) | K7: (И) | L7: (К) | M7: (К1) | N7: (Л) | O7: (Л1) | P7: (М) | Q7: (М1) | R7: (Н) | S7: (Н1) | T7: (О) | U7: (О1) | V7: (П) | W7: (П1) | X7: (Р) | Y7: (Р1)
B8: По типу клиента
A9: 1 | B9: Центральный банк | C9: =+'Loans Receivable'!C86 -> 0 | D9: =IF(C$22=0,"",C9/C$22) -> 0 | E9: 0 | F9: =IF(E$22=0,"",E9/E$22) -> 0 | H9: =IF($G$22=0,"",G9/$G$22) | I9: =+L9+N9+P9+R9+T9+V9+X9 -> 0 | J9: =+M9+O9+T9+S9+U9+W9+Y9 -> 0 | K9: =IF($Z$22=0,"",Z9/$Z$22) -> 0 | L9: 0 | M9: 0 | N9: 0 | O9: 0 | P9: 0 | Q9: 0 | R9: 0 | S9: 0 | T9: 0 | U9: 0 | V9: 0 | W9: 0 | X9: 0 | Y9: 0 | Z9: =+I9+J9 -> 0
A10: 2 | B10: Другие банки | C10: =+'Loans Receivable'!C85 -> 0 | D10: =IF(C$22=0,"",C10/C$22) -> 0 | E10: 0 | F10: =IF(E$22=0,"",E10/E$22) -> 0 | H10: =IF($G$22=0,"",G10/$G$22) | I10: =+L10+N10+P10+R10+T10+V10+X10 -> 0 | J10: =+M10+O10+Q10+S10+U10+W10+Y10 -> 0 | K10: =IF($Z$22=0,"",Z10/$Z$22) -> 0 | L10: 0 | M10: 0 | N10: 0 | O10: 0 | P10: 0 | Q10: 0 | R10: 0 | S10: 0 | T10: 0 | U10: 0 | V10: 0 | W10: 0 | X10: 0 | Y10: 0 | Z10: =+I10+J10 -> 0
A11: 3 | B11: Правительство | C11: =+'Loans Receivable'!C87 -> 0 | D11: =IF(C$22=0,"",C11/C$22) -> 0 | E11: 0 | F11: =IF(E$22=0,"",E11/E$22) -> 0 | H11: =IF($G$22=0,"",G11/$G$22) | I11: =+L11+N11+P11+R11+T11+V11+X11 -> 0 | J11: =+M11+O11+Q11+S11+U11+W11+Y11 -> 0 | K11: =IF($Z$22=0,"",Z11/$Z$22) -> 0 | L11: 0 | M11: 0 | N11: 0 | O11: 0 | P11: 0 | Q11: 0 | R11: 0 | S11: 0 | T11: 0 | U11: 0 | V11: 0 | W11: 0 | X11: 0 | Y11: 0 | Z11: =+I11+J11 -> 0
A12: 4 | B12: Физические лица | C12: =+'Loans Receivable'!C80 -> 1022400185 | D12: =IF(C$22=0,"",C12/C$22) -> 0.17918183 | E12: 0 | F12: =IF(E$22=0,"",E12/E$22) -> 0 | H12: =IF($G$22=0,"",G12/$G$22) | I12: =+L12+N12+P12+R12+T12+V12+X12 -> 8980464 | J12: =+M12+O12+Q12+S12+U12+W12+Y12 -> 5030869 | K12: =IF($Z$22=0,"",Z12/$Z$22) -> 0.18356932 | L12: 3148535 | M12: 269608 | N12: 1846505 | O12: 725614 | P12: 1259323 | Q12: 527453 | R12: 1364281 | S12: 2357840 | T12: 993057 | U12: 552850 | V12: 362648 | W12: 499973 | X12: 6115 | Y12: 97531 | Z12: =+I12+J12 -> 14011333
A13: 5 | B13: Государственные предприятия | C13: =+'Loans Receivable'!C81 -> 759073325 | D13: =IF(C$22=0,"",C13/C$22) -> 0.1330322 | E13: 13497500 | F13: =IF(E$22=0,"",E13/E$22) -> 0.1404912 | G13: 0 | H13: =IF($G$22=0,"",G13/$G$22) | I13: =+L13+N13+P13+R13+T13+V13+X13 -> 0 | J13: =+M13+O13+Q13+S13+U13+W13+Y13 -> 0 | K13: =IF($Z$22=0,"",Z13/$Z$22) -> 0 | L13: 0 | M13: 0 | N13: 0 | O13: 0 | P13: 0 | Q13: 0 | R13: 0 | S13: 0 | T13: 0 | U13: 0 | V13: 0 | W13: 0 | X13: 0 | Y13: 0 | Z13: =+I13+J13 -> 0
A14: 6 | B14: Совместные и иностранные предприятия | C14: =+'Loans Receivable'!C82 -> 455567628 | D14: =IF(C$22=0,"",C14/C$22) -> 0.079840987 | E14: 0 | F14: =IF(E$22=0,"",E14/E$22) -> 0 | G14: 0 | H14: =IF($G$22=0,"",G14/$G$22) | I14: =+L14+N14+P14+R14+T14+V14+X14 -> 76626 | J14: =+M14+O14+Q14+S14+U14+W14+Y14 -> 2002978 | K14: =IF($Z$22=0,"",Z14/$Z$22) -> 0.027245908 | L14: 15335 | M14: 0 | N14: 15335 | O14: 0 | P14: 15335 | Q14: 7430 | R14: 30621 | S14: 0 | T14: 0 | U14: 0 | V14: 0 | W14: 1995548 | X14: 0 | Y14: 0 | Z14: =+I14+J14 -> 2079604
A15: 7 | B15: Частные товарищества и корпорации | C15: =+'Loans Receivable'!C83 -> 3382356533 | D15: =IF(C$22=0,"",C15/C$22) -> 0.59277848 | E15: 82576130 | F15: =IF(E$22=0,"",E15/E$22) -> 0.8595088 | G15: 0 | H15: =IF($G$22=0,"",G15/$G$22) | I15: =+L15+N15+P15+R15+T15+V15+X15 -> 36289881 | J15: =+M15+O15+Q15+S15+U15+W15+Y15 -> 20610204 | K15: =IF($Z$22=0,"",Z15/$Z$22) -> 0.74547581 | L15: 9532164 | M15: 275289 | N15: 5390049 | O15: 341431 | P15: 2798748 | Q15: 385506 | R15: 6692546 | S15: 13468555 | T15: 5267022 | U15: 5833421 | V15: 6609352 | W15: 289163 | X15: 0 | Y15: 16839 | Z15: =+I15+J15 -> 56900085
A16: 8 | B16: Фермерское хозяйство | C16: =+'Loans Receivable'!C84 -> 0 | D16: =IF(C$22=0,"",C16/C$22) -> 0 | E16: 0 | F16: =IF(E$22=0,"",E16/E$22) -> 0 | H16: =IF($G$22=0,"",G16/$G$22) | I16: =+L16+N16+P16+R16+T16+V16+X16 -> 0 | J16: =+M16+O16+Q16+S16+U16+W16+Y16 -> 0 | K16: =IF($Z$22=0,"",Z16/$Z$22) -> 0 | Z16: =+I16+J16 -> 0
A17: 9 | B17: Небанковские финансовые институты | C17: =+'Loans Receivable'!C88 -> 1424539 | D17: =IF(C$22=0,"",C17/C$22) -> 0.00024965909 | E17: 0 | F17: =IF(E$22=0,"",E17/E$22) -> 0 | H17: =IF($G$22=0,"",G17/$G$22) | I17: =+L17+N17+P17+R17+T17+V17+X17 -> 0 | J17: =+M17+O17+Q17+S17+U17+W17+Y17 -> 0 | K17: =IF($Z$22=0,"",Z17/$Z$22) -> 0 | L17: 0 | M17: 0 | N17: 0 | O17: 0 | P17: 0 | Q17: 0 | R17: 0 | S17: 0 | T17: 0 | U17: 0 | V17: 0 | W17: 0 | X17: 0 | Y17: 0 | Z17: =+I17+J17 -> 0
A18: 10 | B18: Негосударственные некоммерческие организации | C18: =+'Loans Receivable'!C89 -> 15649091 | D18: =IF(C$22=0,"",C18/C$22) -> 0.002742598 | E18: 0 | F18: =IF(E$22=0,"",E18/E$22) -> 0 | H18: =IF($G$22=0,"",G18/$G$22) | I18: =+L18+N18+P18+R18+T18+V18+X18 -> 812510 | J18: =+M18+O18+Q18+S18+U18+W18+Y18 -> 1108916 | K18: =IF($Z$22=0,"",Z18/$Z$22) -> 0.025173541 | L18: 15911 | M18: 328 | N18: 14607 | O18: 6423 | P18: 68602 | Q18: 723 | R18: 544318 | S18: 23988 | T18: 61164 | U18: 304236 | V18: 107908 | W18: 755165 | X18: 0 | Y18: 18053 | Z18: =+I18+J18 -> 1921426
A19: 11 | B19: Бюджетные организации | C19: =+'Loans Receivable'!C90 -> 0 | D19: =IF(C$22=0,"",C19/C$22) -> 0 | E19: 0 | F19: =IF(E$22=0,"",E19/E$22) -> 0 | H19: =IF($G$22=0,"",G19/$G$22) | I19: =+L19+N19+P19+R19+T19+V19+X19 -> 0 | J19: =+M19+O19+Q19+S19+U19+W19+Y19 -> 0 | K19: =IF($Z$22=0,"",Z19/$Z$22) -> 0 | Z19: =+I19+J19 -> 0
A20: 12 | B20: Прочие | C20: =+'Loans Receivable'!C91 -> 69465520 | D20: =IF(C$22=0,"",C20/C$22) -> 0.012174253 | E20: 0 | F20: =IF(E$22=0,"",E20/E$22) -> 0 | H20: =IF($G$22=0,"",G20/$G$22) | I20: =+L20+N20+P20+R20+T20+V20+X20 -> 1330936 | J20: =+M20+O20+Q20+S20+U20+W20+Y20 -> 83821 | K20: =IF($Z$22=0,"",Z20/$Z$22) -> 0.018535423 | L20: 257534 | M20: 3142 | N20: 230587 | O20: 5533 | P20: 190016 | Q20: 9441 | R20: 122193 | S20: 42018 | T20: 161640 | U20: 14802 | V20: 368966 | W20: 8885 | X20: 0 | Y20: 0 | Z20: =+I20+J20 -> 1414757
Z21: =+I21+J21 -> 0
A22: 13 | B22: Итого кредита и лизинга | C22: =SUM(C9:C20) -> 5705936821 | D22: =IF(C$22=0,"",C22/C$22) -> 1 | E22: =SUM(E9:E20) -> 96073630 | F22: =IF(E$22=0,"",E22/E$22) -> 1 | G22: =SUM(G9:G20) -> 0 | H22: =IF($G$22=0,"",G22/$G$22) | I22: =SUM(I9:I20) -> 47490417 | J22: =SUM(J9:J20) -> 28836788 | K22: =IF($Z$22=0,"",Z22/$Z$22) -> 1 | L22: =SUM(L9:L20) -> 12969479 | M22: =SUM(M9:M20) -> 548367 | N22: =SUM(N9:N20) -> 7497083 | O22: =SUM(O9:O20) -> 1079001 | P22: =SUM(P9:P20) -> 4332024 | Q22: =SUM(Q9:Q20) -> 930553 | R22: =SUM(R9:R20) -> 8753959 | S22: =SUM(S9:S20) -> 15892401 | ... Y22: =SUM(Y9:Y20) -> 132423 | Z22: =+I22+J22 -> 76327205
Z23: =+I23+J23 -> 0
B24: По сектору экономики | F24: =IF(E$22=0,"",E24/E$22) -> 0 | Z24: =+I24+J24 -> 0
A25: 14 | B25: Промышленность | C25: =+'Loans Receivable'!C15 -> 965348427 | D25: =IF(C$34=0,"",C25/C$34) -> 0.16918316 | E25: 16357500 | F25: =IF($E$34=0,"",E25/$E$34) -> 0.17026004 | G25: 0 | H25: =IF($G$34=0,"",G25/$G$34) | I25: =+L25+N25+P25+R25+T25+V25+X25 -> 2909434 | J25: =+M25+O25+Q25+S25+U25+W25+Y25 -> 2507999 | K25: =IF($Z$34=0,"",Z25/$Z$34) -> 0.070976436 | L25: 1122196 | M25: 9292 | N25: 677815 | O25: 3243 | P25: 530896 | Q25: 336752 | R25: 154333 | S25: 154279 | T25: 399883 | U25: 0 | V25: 24311 | W25: 2004433 | X25: 0 | Y25: 0 | Z25: =+I25+J25 -> 5417433
A26: 15 | B26: Сельское хозяйство | C26: =+'Loans Receivable'!C24 -> 113582271 | D26: =IF(C$34=0,"",C26/C$34) -> 0.019905981 | E26: 0 | F26: =IF($E$34=0,"",E26/$E$34) -> 0 | G26: 0 | H26: =IF($G$34=0,"",G26/$G$34) | I26: =+L26+N26+P26+R26+T26+V26+X26 -> 4135476 | J26: =+M26+O26+Q26+S26+U26+W26+Y26 -> 792109 | K26: =IF($Z$34=0,"",Z26/$Z$34) -> 0.064558698 | L26: 510497 | M26: 16673 | N26: 228559 | O26: 9671 | P26: 8059 | Q26: 4526 | R26: 28898 | S26: 0 | T26: 2987447 | U26: 758695 | V26: 372016 | W26: 2544 | X26: 0 | Y26: 0 | Z26: =+I26+J26 -> 4927585
A27: 16 | B27: Транспорт и коммуникации | C27: =+'Loans Receivable'!C32 -> 543322518 | D27: =IF(C$34=0,"",C27/C$34) -> 0.095220563 | E27: 0 | F27: =IF($E$34=0,"",E27/$E$34) -> 0 | G27: 0 | H27: =IF($G$34=0,"",G27/$G$34) | I27: =+L27+N27+P27+R27+T27+V27+X27 -> 291329 | J27: =+M27+O27+Q27+S27+U27+W27+Y27 -> 801011 | K27: =IF($Z$34=0,"",Z27/$Z$34) -> 0.01431128 | L27: 110500 | M27: 10003 | N27: 110500 | O27: 13636 | P27: 26877 | Q27: 0 | R27: 43452 | S27: 0 | T27: 0 | U27: 777372 | V27: 0 | W27: 0 | X27: 0 | Y27: 0 | Z27: =+I27+J27 -> 1092340
A28: 17 | B28: Строительство | C28: =+'Loans Receivable'!C40 -> 283340629 | D28: =IF(C$34=0,"",C28/C$34) -> 0.049657162 | E28: 0 | F28: =IF($E$34=0,"",E28/$E$34) -> 0 | G28: 0 | H28: =IF($G$34=0,"",G28/$G$34) | I28: =+L28+N28+P28+R28+T28+V28+X28 -> 5470550 | J28: =+M28+O28+Q28+S28+U28+W28+Y28 -> 30577 | K28: =IF($Z$34=0,"",Z28/$Z$34) -> 0.072072952 | L28: 1231802 | M28: 0 | N28: 750019 | O28: 7634 | P28: 36356 | Q28: 0 | R28: 3452373 | S28: 22943 | T28: 0 | U28: 0 | V28: 0 | W28: 0 | X28: 0 | Y28: 0 | Z28: =+I28+J28 -> 5501127
A29: 18 | B29: Торговля и общественное питание | C29: =+'Loans Receivable'!C48 -> 151920268 | D29: =IF(C$34=0,"",C29/C$34) -> 0.026624947 | E29: 0 | F29: =IF($E$34=0,"",E29/$E$34) -> 0 | G29: 0 | H29: =IF($G$34=0,"",G29/$G$34) | I29: =+L29+N29+P29+R29+T29+V29+X29 -> 4205498 | J29: =+M29+O29+Q29+S29+U29+W29+Y29 -> 71638 | K29: =IF($Z$34=0,"",Z29/$Z$34) -> 0.056036848 | L29: 1179420 | M29: 31123 | N29: 677935 | O29: 1692 | P29: 610767 | Q29: 22690 | R29: 1727676 | S29: 16133 | T29: 9700 | U29: 0 | V29: 0 | W29: 0 | X29: 0 | Y29: 0 | Z29: =+I29+J29 -> 4277136
A30: 19 | B30: Материально-техническое снабжение и сбыт | C30: =+'Loans Receivable'!C56 -> 76942702 | D30: =IF(C$34=0,"",C30/C$34) -> 0.013484675 | E30: 0 | F30: =IF($E$34=0,"",E30/$E$34) -> 0 | G30: 0 | H30: =IF($G$34=0,"",G30/$G$34) | I30: =+L30+N30+P30+R30+T30+V30+X30 -> 0 | J30: =+M30+O30+Q30+S30+U30+W30+Y30 -> 0 | K30: =IF($Z$34=0,"",Z30/$Z$34) -> 0 | L30: 0 | M30: 0 | N30: 0 | O30: 0 | P30: 0 | Q30: 0 | R30: 0 | S30: 0 | T30: 0 | U30: 0 | V30: 0 | W30: 0 | X30: 0 | Y30: 0 | Z30: =+I30+J30 -> 0
A31: 20 | B31: Жилищно-коммунальные услуги | C31: =+'Loans Receivable'!C65 -> 21411004 | D31: =IF(C$34=0,"",C31/C$34) -> 0.0037524082 | E31: 0 | F31: =IF($E$34=0,"",E31/$E$34) -> 0 | G31: 0 | H31: =IF($G$34=0,"",G31/$G$34) | I31: =+L31+N31+P31+R31+T31+V31+X31 -> 687308 | J31: =+M31+O31+Q31+S31+U31+W31+Y31 -> 1042908 | K31: =IF($Z$34=0,"",Z31/$Z$34) -> 0.022668405 | L31: 15911 | M31: 328 | N31: 14607 | O31: 25029 | P31: 62065 | Q31: 723 | R31: 504699 | S31: 23988 | T31: 28472 | U31: 161423 | V31: 61554 | W31: 796525 | X31: 0 | Y31: 34892 | Z31: =+I31+J31 -> 1730216
A32: 21 | B32: Другие сектора | C32: =+'Loans Receivable'!C78 -> 3550069002 | D32: =IF(C$34=0,"",C32/C$34) -> 0.6221711 | E32: 79716130 | F32: =IF($E$34=0,"",E32/$E$34) -> 0.82973996 | G32: 0 | H32: =IF($G$34=0,"",G32/$G$34) | I32: =+L32+N32+P32+R32+T32+V32+X32 -> 29790822 | J32: =+M32+O32+Q32+S32+U32+W32+Y32 -> 23590546 | K32: =IF($Z$34=0,"",Z32/$Z$34) -> 0.69937538 | L32: 8799153 | M32: 480948 | N32: 5037648 | O32: 1018096 | P32: 3057004 | Q32: 565862 | R32: 2842528 | S32: 15675058 | T32: 3057381 | U32: 5007819 | V32: 6990993 | W32: 745232 | X32: 6115 | Y32: 97531 | Z32: =+I32+J32 -> 53381368
Z33: =+I33+J33 -> 0
A34: 22 | B34: Итого кредита и лизинга | C34: =SUM(C25:C32) -> 5705936821 | D34: =IF(C$34=0,"",C34/C$34) -> 1 | E34: =SUM(E25:E32) -> 96073630 | F34: =IF($E$34=0,"",E34/$E$34) -> 1 | G34: =SUM(G25:G32) -> 0 | H34: =IF($G$34=0,"",G34/$G$34) | I34: =SUM(I25:I32) -> 47490417 | J34: =SUM(J25:J32) -> 28836788 | K34: =IF($Z$34=0,"",Z34/$Z$34) -> 1 | L34: =SUM(L25:L32) -> 12969479 | M34: =SUM(M25:M32) -> 548367 | N34: =SUM(N25:N32) -> 7497083 | O34: =SUM(O25:O32) -> 1079001 | P34: =SUM(P25:P32) -> 4332024 | Q34: =SUM(Q25:Q32) -> 930553 | R34: =SUM(R25:R32) -> 8753959 | S34: =SUM(S25:S32) -> 15892401 | ... Y34: =SUM(Y25:Y32) -> 132423 | Z34: =+I34+J34 -> 76327205
B37: Подпись Председателя правления:
B39: Подпись Главного Бухгалтера:

Sheet Asset Classification
A1: ОТЧЕТ О КЛАССИФИКАЦИИ АКТИВОВ ПО СТЕПЕНИ РИСКА | W1: Таблица-10
B2: =+'Asset quality'!B3 -> АК "Алокабанк" | U2: =+'Asset quality'!P3 -> 44196 | Z2: тыс. сум
A3: № | B3: Статьи баланса | C3: Общая сумма | D3: из них, в иностранной валюте (в экв. в сумах) | E3: Стандартные | F3: из них, в иностранной валюте (в экв. в сумах) | G3: Общие резервы (1%) | H3: из них, в иностранной валюте (в экв. в сумах) | I3: Субстандартные | J3: из них, в иностранной валюте (в экв. в сумах) | K3: Специальные резервы (мин 10%) | L3: из них, в иностранной валюте (в экв. в сумах) | M3: Неудовлетворительные | N3: из них, в иностранной валюте (в экв. в сумах) | O3: Специальные резервы (мин 25%) | P3: из них, в иностранной валюте (в экв. в сумах) | Q3: Сомнительные | R3: из них, в иностранной валюте (в экв. в сумах) | S3: Специальные резервы (мин 50%) | T3: из них, в иностранной валюте (в экв. в сумах) | U3: Безнадежные | V3: из них, в иностранной валюте (в экв. в сумах) | W3: Специальные резервы (100%) | X3: из них, в иностранной валюте (в экв. в сумах) | Y3: Совокупная сумма специальных резервов | Z3: из них, в иностранной валюте (в экв. в сумах)
A4: (А) | B4: (Б) | C4: (В) | D4: (В1) | E4: (Г) | F4: (Г1) | G4: (Д) | H4: (Д1) | I4: (Е) | J4: (Е1) | K4: (Ж) | L4: (Ж1) | M4: (З) | N4: (З1) | O4: (И) | P4: (И1) | Q4: (К) | R4: (К1) | S4: (Л) | T4: (Л1) | U4: (М) | V4: (М1) | W4: (Н) | X4: (Н1) | Y4: О=Ж+И+Л+Н | Z4: (О1)=(Ж1)+(И1)+(Л1)+(Н1)
B5: По типу клиента
A6: 1 | B6: Центральный банк | C6: =E6+I6+M6+Q6+U6 -> 0 | D6: =F6+J6+N6+R6+V6 -> 0 | Y6: =+W6+S6+O6+K6 -> 0 | Z6: =+X6+T6+P6+L6 -> 0 | AA6: =+'Aging Analysis'!C9 -> 0
B7: из них необеспеченные | C7: =E7+I7+M7+Q7+U7 -> 0 | D7: =F7+J7+N7+R7+V7 -> 0 | Y7: =+W7+S7+O7+K7 -> 0 | Z7: =+X7+T7+P7+L7 -> 0
A8: 2 | B8: Другие банки | C8: =E8+I8+M8+Q8+U8 -> 0 | D8: =F8+J8+N8+R8+V8 -> 0 | Y8: =+W8+S8+O8+K8 -> 0 | Z8: =+X8+T8+P8+L8 -> 0 | AA8: =+'Aging Analysis'!C10 -> 0
B9: из них необеспеченные | C9: =E9+I9+M9+Q9+U9 -> 0 | D9: =F9+J9+N9+R9+V9 -> 0 | Y9: =+W9+S9+O9+K9 -> 0 | Z9: =+X9+T9+P9+L9 -> 0
A10: 3 | B10: Правительство | C10: =E10+I10+M10+Q10+U10 -> 0 | D10: =F10+J10+N10+R10+V10 -> 0 | Y10: =+W10+S10+O10+K10 -> 0 | Z10: =+X10+T10+P10+L10 -> 0 | AA10: =+'Aging Analysis'!C11 -> 0
B11: из них необеспеченные | C11: =E11+I11+M11+Q11+U11 -> 0 | D11: =F11+J11+N11+R11+V11 -> 0 | Y11: =+W11+S11+O11+K11 -> 0 | Z11: =+X11+T11+P11+L11 -> 0
A12: 4 | B12: Физические лица | C12: =E12+I12+M12+Q12+U12 -> 1022400185 | D12: =F12+J12+N12+R12+V12 -> 0 | E12: 1013972858 | G12: 11090682 | I12: 3431795 | K12: 736664 | M12: 2193928 | O12: 470636 | Q12: 1457838 | S12: 569578 | U12: 1343766 | W12: 570653 | Y12: =+W12+S12+O12+K12 -> 2347531 | Z12: =+X12+T12+P12+L12 -> 0 | AA12: =+'Aging Analysis'!C12 -> 1022400185
B13: из них необеспеченные | C13: =E13+I13+M13+Q13+U13 -> 0 | D13: =F13+J13+N13+R13+V13 -> 0 | G13: 0 | Y13: =+W13+S13+O13+K13 -> 0 | Z13: =+X13+T13+P13+L13 -> 0
A14: 5 | B14: Государственные предприятия | C14: =E14+I14+M14+Q14+U14 -> 759073325 | D14: =F14+J14+N14+R14+V14 -> 314307600 | E14: 759073325 | F14: 314307600 | G14: 8302629 | I14: 0 | M14: 0 | Y14: =+W14+S14+O14+K14 -> 0 | Z14: =+X14+T14+P14+L14 -> 0 | AA14: =+'Aging Analysis'!C13 -> 759073325
B15: из них необеспеченные | C15: =E15+I15+M15+Q15+U15 -> 0 | D15: =F15+J15+N15+R15+V15 -> 0 | G15: 0 | Y15: =+W15+S15+O15+K15 -> 0 | Z15: =+X15+T15+P15+L15 -> 0
A16: 6 | B16: Совместные и иностранные предприятия | C16: =E16+I16+M16+Q16+U16 -> 455567628 | D16: =F16+J16+N16+R16+V16 -> 172192219 | E16: 433495375 | F16: 150365274 | G16: 4741507 | I16: 22072253 | J16: 21826945 | K16: 242801 | L16: 218269 | M16: 0 | Y16: =+W16+S16+O16+K16 -> 242801 | Z16: =+X16+T16+P16+L16 -> 218269 | AA16: =+'Aging Analysis'!C14 -> 455567628
B17: из них необеспеченные | C17: =E17+I17+M17+Q17+U17 -> 0 | D17: =F17+J17+N17+R17+V17 -> 0 | G17: 0 | Y17: =+W17+S17+O17+K17 -> 0 | Z17: =+X17+T17+P17+L17 -> 0
A18: 7 | B18: Частные товарищества и корпорации | C18: =E18+I18+M18+Q18+U18 -> 3382356533 | D18: =F18+J18+N18+R18+V18 -> 1432986517 | E18: 3321497002 | F18: 1425634870 | G18: 36330031 | H18: 238850 | I18: 59487078 | J18: 7328557 | K18: 5051251 | L18: 528058 | M18: 1372453 | N18: 23090 | O18: 573090 | P18: 23090 | Y18: =+W18+S18+O18+K18 -> 5624341 | Z18: =+X18+T18+P18+L18 -> 551148 | AA18: =+'Aging Analysis'!C15 -> 3382356533
B19: из них необеспеченные | C19: =E19+I19+M19+Q19+U19 -> 0 | D19: =F19+J19+N19+R19+V19 -> 0 | G19: 0 | Y19: =+W19+S19+O19+K19 -> 0 | Z19: =+X19+T19+P19+L19 -> 0
A20: 8 | B20: Фермерское хозяйство | C20: =E20+I20+M20+Q20+U20 -> 0 | D20: =F20+J20+N20+R20+V20 -> 0 | G20: 0 | Y20: =+W20+S20+O20+K20 -> 0 | Z20: =+X20+T20+P20+L20 -> 0 | AA20: =+'Aging Analysis'!C16 -> 0
B21: из них необеспеченные | C21: =E21+I21+M21+Q21+U21 -> 0 | D21: =F21+J21+N21+R21+V21 -> 0 | G21: 0 | Y21: =+W21+S21+O21+K21 -> 0 | Z21: =+X21+T21+P21+L21 -> 0
A22: 9 | B22: Небанковские финансовые институты | C22: =E22+I22+M22+Q22+U22 -> 1424539 | D22: =F22+J22+N22+R22+V22 -> 0 | E22: 1424539 | G22: 15581 | I22: 0 | M22: 0 | Y22: =+W22+S22+O22+K22 -> 0 | Z22: =+X22+T22+P22+L22 -> 0 | AA22: =+'Aging Analysis'!C17 -> 1424539
B23: из них необеспеченные | C23: =E23+I23+M23+Q23+U23 -> 0 | D23: =F23+J23+N23+R23+V23 -> 0 | G23: 0 | Y23: =+W23+S23+O23+K23 -> 0 | Z23: =+X23+T23+P23+L23 -> 0
A24: 10 | B24: Негосударственные некоммерческие организации | C24: =E24+I24+M24+Q24+U24 -> 15649091 | D24: =F24+J24+N24+R24+V24 -> 0 | E24: 10276404 | G24: 112402 | I24: 5372687 | K24: 690357 | M24: 0 | Y24: =+W24+S24+O24+K24 -> 690357 | Z24: =+X24+T24+P24+L24 -> 0 | AA24: =+'Aging Analysis'!C18 -> 15649091
B25: из них необеспеченные | C25: =E25+I25+M25+Q25+U25 -> 0 | D25: =F25+J25+N25+R25+V25 -> 0 | G25: 0 | Y25: =+W25+S25+O25+K25 -> 0 | Z25: =+X25+T25+P25+L25 -> 0
A26: 11 | B26: Бюджетные организации | C26: =E26+I26+M26+Q26+U26 -> 0 | D26: =F26+J26+N26+R26+V26 -> 0 | G26: 0 | Y26: =+W26+S26+O26+K26 -> 0 | Z26: =+X26+T26+P26+L26 -> 0 | AA26: =+'Aging Analysis'!C19 -> 0
B27: из них необеспеченные | C27: =E27+I27+M27+Q27+U27 -> 0 | D27: =F27+J27+N27+R27+V27 -> 0 | G27: 0 | Y27: =+W27+S27+O27+K27 -> 0 | Z27: =+X27+T27+P27+L27 -> 0
A28: 12 | B28: Прочие | C28: =E28+I28+M28+Q28+U28 -> 69465520 | D28: =F28+J28+N28+R28+V28 -> 0 | E28: 67642128 | G28: 739859 | I28: 1809771 | K28: 168733 | M28: 13621 | O28: 3405 | Y28: =+W28+S28+O28+K28 -> 172138 | Z28: =+X28+T28+P28+L28 -> 0 | AA28: =+'Aging Analysis'!C20 -> 69465520
B29: из них необеспеченные | C29: =E29+I29+M29+Q29+U29 -> 0 | D29: =F29+J29+N29+R29+V29 -> 0 | E29: 0 | F29: 0 | G29: 0 | H29: 0 | I29: 0 | J29: 0 | K29: 0 | L29: 0 | M29: 0 | N29: 0 | O29: 0 | P29: 0 | Q29: 0 | R29: 0 | S29: 0 | T29: 0 | U29: 0 | V29: 0 | W29: 0 | X29: 0 | Y29: =+W29+S29+O29+K29 -> 0 | Z29: =+X29+T29+P29+L29 -> 0
A30: 13 | B30: Итого кредита и лизинга | C30: =+C6+C8+C10+C12+C14+C16+C18+C20+C22+C24+C26+C28 -> 5705936821 | D30: =+D6+D8+D10+D12+D14+D16+D18+D20+D22+D24+D26+D28 -> 1919486336 | E30: =+E6+E8+E10+E12+E14+E16+E18+E20+E22+E24+E26+E28 -> 5607381631 | F30: =+F6+F8+F10+F12+F14+F16+F18+F20+F22+F24+F26+F28 -> 1890307744 | G30: =+G6+G8+G10+G12+G14+G16+G18+G20+G22+G24+G26+G28 -> 61332691 | H30: =+H6+H8+H10+H12+H14+H16+H18+H20+H22+H24+H26+H28 -> 238850 | I30: =+I6+I8+I10+I12+I14+I16+I18+I20+I22+I24+I26+I28 -> 92173584 | J30: =+J6+J8+J10+J12+J14+J16+J18+J20+J22+J24+J26+J28 -> 29155502 | ... Z30: =+Z6+Z8+Z10+Z12+Z14+Z16+Z18+Z20+Z22+Z24+Z26+Z28 -> 769417
B31: из них необеспеченные | C31: =+C7+C9+C11+C13+C15+C17+C19+C21+C23+C25+C27+C29 -> 0 | D31: =+D7+D9+D11+D13+D15+D17+D19+D21+D23+D25+D27+D29 -> 0 | E31: =+E7+E9+E11+E13+E15+E17+E19+E21+E23+E25+E27+E29 -> 0 | F31: =+F7+F9+F11+F13+F15+F17+F19+F21+F23+F25+F27+F29 -> 0 | G31: =+G7+G9+G11+G13+G15+G17+G19+G21+G23+G25+G27+G29 -> 0 | H31: =+H7+H9+H11+H13+H15+H17+H19+H21+H23+H25+H27+H29 -> 0 | I31: =+I7+I9+I11+I13+I15+I17+I19+I21+I23+I25+I27+I29 -> 0 | J31: =+J7+J9+J11+J13+J15+J17+J19+J21+J23+J25+J27+J29 -> 0 | ... Z31: =+Z7+Z9+Z11+Z13+Z15+Z17+Z19+Z21+Z23+Z25+Z27+Z29 -> 0
B32: По сектору экономики
A34: 14 | B34: Промышленность | C34: =E34+I34+M34+Q34+U34 -> 965348427 | D34: =F34+J34+N34+R34+V34 -> 445862874 | E34: 937080574 | F34: 423578214 | G34: 10249645 | I34: 28267853 | J34: 22284660 | K34: 833239 | L34: 264041 | M34: 0 | Y34: =+W34+S34+O34+K34 -> 833239 | Z34: =+X34+T34+P34+L34 -> 264041 | AA34: =+'Aging Analysis'!C25 -> 965348427
B35: из них необеспеченные | C35: =E35+I35+M35+Q35+U35 -> 0 | D35: =F35+J35+N35+R35+V35 -> 0 | G35: 0 | Y35: =+W35+S35+O35+K35 -> 0 | Z35: =+X35+T35+P35+L35 -> 0
A36: 15 | B36: Сельское хозяйство | C36: =E36+I36+M36+Q36+U36 -> 113582271 | D36: =F36+J36+N36+R36+V36 -> 53699686 | E36: 88912886 | F36: 53699686 | G36: 972516 | I36: 23355764 | K36: 1555587 | M36: 1313621 | O36: 553405 | Y36: =+W36+S36+O36+K36 -> 2108992 | Z36: =+X36+T36+P36+L36 -> 0 | AA36: =+'Aging Analysis'!C26 -> 113582271
B37: из них необеспеченные | C37: =E37+I37+M37+Q37+U37 -> 0 | D37: =F37+J37+N37+R37+V37 -> 0 | G37: 0 | Y37: =+W37+S37+O37+K37 -> 0 | Z37: =+X37+T37+P37+L37 -> 0
A38: 16 | B38: Транспорт и коммуникации | C38: =E38+I38+M38+Q38+U38 -> 543322518 | D38: =F38+J38+N38+R38+V38 -> 11143469 | E38: 543118761 | F38: 11143469 | G38: 5940551 | I38: 203757 | K38: 14747 | M38: 0 | Y38: =+W38+S38+O38+K38 -> 14747 | Z38: =+X38+T38+P38+L38 -> 0 | AA38: =+'Aging Analysis'!C27 -> 543322518
B39: из них необеспеченные | C39: =E39+I39+M39+Q39+U39 -> 0 | D39: =F39+J39+N39+R39+V39 -> 0 | G39: 0 | Y39: =+W39+S39+O39+K39 -> 0 | Z39: =+X39+T39+P39+L39 -> 0
A40: 17 | B40: Строительство | C40: =E40+I40+M40+Q40+U40 -> 283340629 | D40: =F40+J40+N40+R40+V40 -> 120765803 | E40: 282819684 | F40: 120765803 | G40: 3093439 | I40: 520945 | K40: 233213 | M40: 0 | Y40: =+W40+S40+O40+K40 -> 233213 | Z40: =+X40+T40+P40+L40 -> 0 | AA40: =+'Aging Analysis'!C28 -> 283340629
B41: из них необеспеченные | C41: =E41+I41+M41+Q41+U41 -> 0 | D41: =F41+J41+N41+R41+V41 -> 0 | G41: 0 | Y41: =+W41+S41+O41+K41 -> 0 | Z41: =+X41+T41+P41+L41 -> 0
...

Sheet Loans to Affiliated P.
A1: ОТЧЕТ О СДЕЛКАХ, ЗАКЛЮЧЕННЫХ СО СВЯЗАННЫМИ ЛИЦАМИ | S1: Таблица-11
B3: =+'Asset quality'!B3 -> АК "Алокабанк" | N3: =+'Asset quality'!P3 -> 44196 | S3: тыс. сум
A4: № | B4: Наименования клиента | C4: ИНН | D4: Вид деятельности | E4: Код валюты | F4: Номер группы | G4: Текущая задолженность | H4: из них | N4: Пересмотрения | O4: Обеспечения | Q4: Классификация | R4: Резерв | S4: Источник кредита
H5: Кредиты и лизинги | I5: Инвестиции | J5: Аккредитивы | K5: Гарантии | L5: Межбанковские кредиты и депозиты | M5: другие активы* | O5: Вид залога | P5: Сумма залога
B6: А | C6: Б | D6: В | E6: Г | F6: Д | G6: Е | H6: Е1 | I6: Е2 | J6: Е3 | K6: Е4 | L6: Е5 | M6: Е6 | N6: Ж | O6: З | P6: И | Q6: К | R6: Л | S6: М
A7: 1 | B7: "Тошкент Чинни Заводи" МЧЖ | C7: 305646742 | D7: 23490 | E7: 860 | F7: 1 | G7: =SUM(H7:M7) -> 116803254 | H7: 94628083 | M7: 22175171 | Q7: 1
A8: =A7+1 -> 2 | B8: "Алока Актив" МЧЖ | C8: 305186248 | D8: 96190 | E8: 860 | F8: 1 | G8: =SUM(H8:M8) -> 33000000 | I8: 33000000 | Q8: 1
A9: 3 | B9: "Алокализинг" МЧЖ | C9: 305675865 | D9: 64990 | E9: 860 | F9: 2 | G9: =SUM(H9:M9) -> 22310000 | H9: 21100000 | I9: 1210000 | Q9: 1
A10: 4 | B10: "Уздижитал ТВ" МЧЖ | C10: 207027936 | D10: 52300 | E10: 860 | F10: 3 | G10: =SUM(H10:M10) -> 1136155.4 | I10: 1136155.4 | Q10: 1
A11: 5 | B11: "Пеймент Агригайшн Системс" МЧЖ | C11: 305148809 | D11: 58290 | E11: 860 | F11: 4 | G11: =SUM(H11:M11) -> 375000 | I11: 375000 | Q11: 1
A12: 6 | B12: "Оила даврасида газетаси тахририяти" МЧЖ | C12: 207151206 | D12: 87100 | E12: 860 | F12: 5 | G12: =SUM(H12:M12) -> 110548.84 | I12: 110548.84 | Q12: 4 | R12: 55274.42
A13: 7 | B13: АО СК "Алском" | C13: 201941144 | D13: 65120 | E13: 860 | F13: 6 | G13: =SUM(H13:M13) -> 2607352 | I13: 2607352 | Q13: 1
A14: 8 | B14: "Ўзбектелеком" АЖ | C14: 203366731 | D14: 61100 | E14: 860 | F14: 7 | G14: =SUM(H14:M14) -> 455250911 | H14: 349753188 | K14: 104769200 | M14: 728523 | P14: 216400000 | Q14: 1
A15: 9 | B15: "Нано Лизинг Компанияси" МЧЖ | C15: 207137166 | D15: 64910 | E15: 860 | F15: 8 | G15: =SUM(H15:M15) -> 76940143 | H15: 76940143 | Q15: 1
A16: 10 | B16: "IT-INVEST" МЧЖ | C16: 305059128 | D16: 62020 | E16: 860 | F16: 8 | G16: =SUM(H16:M16) -> 3666667 | H16: 3666667 | Q16: 1
A17: 11 | B17: Маматов Улугбек Фуркат угли | C17: 545091429 | D17: 99950 | E17: 860 | F17: 9 | G17: =SUM(H17:M17) -> 987784 | H17: 987784 | P17: 0
A18: 12 | B18: Ибрагимов Азизбек Кэлдибек ўғли | C18: 506643954 | D18: 99950 | E18: 860 | F18: 10 | G18: =SUM(H18:M18) -> 786602 | H18: 786602 | P18: 0
A19: 13 | B19: Халавов Фаррух Истамович | C19: 540576855 | D19: 99950 | E19: 860 | F19: 11 | G19: =SUM(H19:M19) -> 661406 | H19: 661406 | P19: 0
A20: 14 | B20: Ганиев Шерали Алижон угли | C20: 510888885 | D20: 99950 | E20: 860 | F20: 12 | G20: =SUM(H20:M20) -> 623431 | H20: 623431 | P20: 0
A21: 15 | B21: Абдурашидова Нигора Ибрагимовна | C21: 487802528 | D21: 99950 | E21: 860 | F21: 13 | G21: =SUM(H21:M21) -> 535724 | H21: 535724 | P21: 0
A22: 16 | B22: Ходжаниязов Уткир Юсупович | C22: 498628800 | D22: 99950 | E22: 860 | F22: 14 | G22: =SUM(H22:M22) -> 528805 | H22: 528805 | P22: 0
A23: 17 | B23: Хакбердиев Зафар Алишер угли | C23: 508642376 | D23: 99950 | E23: 860 | F23: 15 | G23: =SUM(H23:M23) -> 489574 | H23: 489574 | P23: 20648
A24: 18 | B24: Жумаев Ҳафиз Ҳусенович | C24: 486784282 | D24: 99950 | E24: 860 | F24: 16 | G24: =SUM(H24:M24) -> 487605 | H24: 487605 | P24: 0
A25: 19 | B25: Гуломова Инобат Анваровна | D25: 99950 | E25: 860 | F25: 17 | G25: =SUM(H25:M25) -> 478509 | H25: 478509 | P25: 0
A26: 20 | B26: Пўлатова Ҳилола Ғайрат қизи | C26: 497547744 | D26: 99950 | E26: 860 | F26: 18 | G26: =SUM(H26:M26) -> 476933 | H26: 476933 | P26: 0
A27: 21 | B27: Хасанов Назиржон Набижанович | C27: 496418880 | D27: 99950 | E27: 860 | F27: 19 | G27: =SUM(H27:M27) -> 455866 | H27: 455866 | P27: 0
A28: 22 | B28: Набижонов Муҳаммадносир нодир ўғли | C28: 514610438 | D28: 99950 | E28: 860 | F28: 20 | G28: =SUM(H28:M28) -> 442994 | H28: 442994 | P28: 0
A29: 23 | B29: Аслонов Низомжон Аслонович | C29: 514658789 | D29: 99950 | E29: 860 | F29: 21 | G29: =SUM(H29:M29) -> 433085 | H29: 433085 | P29: 0
A30: 24 | B30: Ботиров Бекзод Косимович | C30: 495549767 | D30: 99950 | E30: 860 | F30: 22 | G30: =SUM(H30:M30) -> 428523 | H30: 428523 | P30: 1
A31: 25 | B31: Абдуллаев Учкун Аширович | C31: 487873266 | D31: 99950 | E31: 860 | F31: 23 | G31: =SUM(H31:M31) -> 412499 | H31: 412499 | P31: 0
A32: 26 | B32: Полвонов Асроржон Абдулхаевич | C32: 509499854 | D32: 99950 | E32: 860 | F32: 24 | G32: =SUM(H32:M32) -> 407274 | H32: 407274 | P32: 0
A33: 27 | B33: Усмонов Шухрат Собиржонович | C33: 501360789 | D33: 99950 | E33: 860 | F33: 25 | G33: =SUM(H33:M33) -> 397087 | H33: 397087 | P33: 0
A34: 28 | B34: Расулов Абдурахмон Муратович | C34: 460627292 | D34: 99950 | E34: 860 | F34: 26 | G34: =SUM(H34:M34) -> 386296 | H34: 386296 | P34: 0
A35: 29 | B35: Ахтамов Шароф Ахтам ўғли | C35: 524032978 | D35: 99950 | E35: 860 | F35: 27 | G35: =SUM(H35:M35) -> 366262 | H35: 366262 | P35: 0
A36: 30 | B36: Мирзаев Мақсуд Баходирович | D36: 99950 | E36: 860 | F36: 28 | G36: =SUM(H36:M36) -> 355231 | H36: 355231 | P36: 0
A37: 31 | B37: Файзиев Сирожиддин Собир ўғли | C37: 511420770 | D37: 99950 | E37: 860 | F37: 29 | G37: =SUM(H37:M37) -> 353560 | H37: 353560 | P37: 0
A38: 32 | B38: Худойбердиев Кахрамон Абдуназарович | C38: 496259336 | D38: 99950 | E38: 860 | F38: 30 | G38: =SUM(H38:M38) -> 352676 | H38: 352676 | P38: 0
A39: 33 | B39: Гайбуллоев Сухроб Одил ўғли | C39: 501987649 | D39: 99950 | E39: 860 | F39: 31 | G39: =SUM(H39:M39) -> 351553 | H39: 351553 | P39: 10770
A40: 34 | B40: Қадомов Махмудбек Баходир ўғли | C40: 538664452 | D40: 99950 | E40: 860 | F40: 32 | G40: =SUM(H40:M40) -> 350422 | H40: 350422 | P40: 0
A41: 35 | B41: Раҳматов Аҳад Комил ўғли | C41: 500261635 | D41: 99950 | E41: 860 | F41: 33 | G41: =SUM(H41:M41) -> 349265 | H41: 349265 | P41: 0
...

Sheet  Largest risk
A1: ОТЧЕТ О КРУПНЫХ РИСКАХ | S1: Таблица-12
B3: =+'Asset quality'!B3 -> АК "Алокабанк" | N3: =+'Asset quality'!P3 -> 44196 | O3: =+#REF! -> #REF! | S3: тыс. сум
A4: № | B4: Наименования клиента | C4: ИНН | D4: Вид деятельности | E4: Код валюты | F4: Номер группы | G4: Текущая задолженность | H4: из них | N4: Пересмотрения | O4: Обеспечения | Q4: Классификация | R4: Резерв | S4: Источник кредита
H5: Кредиты и лизинги | I5: Инвестиции | J5: Аккредитивы | K5: Гарантии | L5: Межбанковские кредиты и депозиты | M5: другие активы* | O5: Вид залога | P5: Сумма залога
B6: А | C6: Б | D6: В | E6: Г | F6: Д | G6: Е | H6: Е1 | I6: Е2 | J6: Е3 | K6: Е4 | L6: Е5 | M6: Е6 | N6: Ж | O6: З | P6: И | Q6: К | R6: Л | S6: М
A7: 1 | B7: АК "Ўзбектелеком" | C7: 203366731 | D7: 52300 | E7: 860 | F7: 1 | G7: =SUM(H7:M7) -> 455250911 | H7: 349753188 | K7: 104769200 | M7: 728523 | O7: 2 | P7: 216400000 | Q7: 4 | U7: 0
A8: 2 | B8: Навоийский горно-метал. ком. | C8: 201204514 | D8: 12411 | E8: 840 | F8: 2 | G8: =SUM(H8:M8) -> 314307600 | H8: 314307600 | Q8: 1
A9: 3 | B9: "Универсал Мобайл Системс" МЧЖ | C9: 303020732 | D9: 52300 | E9: 860 | F9: 3 | G9: =SUM(H9:M9) -> 100241592 | H9: 99981592 | M9: 260000 | Q9: 1
A10: 4 | B10: ХЁАТ "Ориент Финанс банк" | C10: 207086151 | D10: 96120 | E10: 840 | F10: 4 | G10: =SUM(H10:M10) -> 157153800 | L10: 157153800 | Q10: 1
A11: 5 | G11: =SUM(H11:M11) -> 0
A12: 6 | G12: =SUM(H12:M12) -> 0
A13: 7 | G13: =SUM(H13:M13) -> 0
A14: 8 | G14: =SUM(H14:M14) -> 0
A15: 9 | G15: =SUM(H15:M15) -> 0
A16: 10 | G16: =SUM(H16:M16) -> 0
A17: 11 | G17: =SUM(H17:M17) -> 0
A18: 12 | G18: =SUM(H18:M18) -> 0
A19: 13 | G19: =SUM(H19:M19) -> 0
A20: 14 | G20: =SUM(H20:M20) -> 0
A21: 15 | G21: =SUM(H21:M21) -> 0
A22: 16 | G22: =SUM(H22:M22) -> 0
... A66: 60 | G66: =SUM(H66:M66) -> 0
B67: ИТОГО КРУПНЫХ АКТИВОВ | G67: =SUM(G7:G66) -> 1026953903 | H67: =SUM(H7:H66) -> 764042380 | I67: =SUM(I7:I66) -> 0 | J67: =SUM(J7:J66) -> 0 | K67: =SUM(K7:K66) -> 104769200 | L67: =SUM(L7:L66) -> 157153800 | M67: =SUM(M7:M66) -> 988523 | P67: =SUM(P7:P66) -> 216400000
B68: САМЫЙ КРУПНЫЙ АКТИВ, ВЫДАННЫЙ БАНКОМ | G68: =MAX(G7:G66) -> 455250911 | H68: =MAX(H7:H66) -> 349753188 | I68: =MAX(I7:I66) -> 0 | J68: =MAX(J7:J66) -> 0 | K68: =MAX(K7:K66) -> 104769200 | L68: =MAX(L7:L66) -> 157153800 | M68: =MAX(M7:M66) -> 728523 | P68: =MAX(P7:P66) -> 216400000
B71: Подпись Председателя правления:
B73: Подпись Главного Бухгалтера:

Sheet Charge-offs and Recoveries
A1: ОТЧЕТ О CПИСАННЫХ И ВОЗВРАЩЕННЫХ ПЛАТЕЖАХ ИЗ РЕЗЕРВА ВОЗМОЖНЫХ ПОТЕРЬ ПО КРЕДИТАМ И ЛИЗИНГУ | E1: Таблица-13
A3: Часть 1 Списания и возврат | B3: =+'Asset quality'!B3 -> АК "Алокабанк" | E3: =+'Asset quality'!P3 -> 44196
A4: Отрасль экономики | B4: Списание - А | D4: Возврат - Б
B5: Всего | C5: в иностранной валюте | D5: Всего | E5: в иностранной валюте
A6: А | B6: Б | C6: В | D6: Г | E6: Д
A7: 1. Промышленность | B7: 478318 | C7: 0 | D7: 0 | E7: 0
A8: 2. Сельское хозяйство | B8: 0 | C8: 0 | D8: 5408 | E8: 0
A9: 3. Транспорт и коммуникации | B9: 0 | C9: 0 | D9: 0 | E9: 0
A10: 4. Строительство | B10: 0 | C10: 0 | D10: 0 | E10: 0
A11: 5. Торговля и общественное питание | B11: 0 | C11: 0 | D11: 995325 | E11: 0
A12: 6. Материально-техническое снабжение и сбыт | B12: 0 | C12: 0 | D12: 0 | E12: 0
A13: 7. Жилищно-коммунальные услуги | B13: 181207 | C13: 0 | D13: 0 | E13: 0
A14: 8. Другие сектора | B14: 3424292 | C14: 0 | D14: 40235 | E14: 0
A15: 9. Итого | B15: =SUM(B7:B14) -> 4083817 | C15: =SUM(C7:C14) -> 0 | D15: =SUM(D7:D14) -> 1040968 | E15: =SUM(E7:E14) -> 0
A18: Часть 2
A19: Изменения в резерве возможных убытков по кредитам и лизингу
A20: 1. Остаток на начало текущего года | C20: 8904825
A21: 2. Плюс: Возвращенные платежи | C21: =D15 -> 1040968
