Workbook
Name jop: #REF!
Name kol: #REF!
Name TwentyLargestData: #REF!
Name Е: #REF!

Sheet Bank Capital Calc
A1: БАНКНИНГ РЕГУЛЯТИВ КАПИТАЛИ ҲИСОБ-КИТОБИ | C1: 5-жадвал | E1: №6
B3: "Алоқабанк" | C3: 44926
A4: № | B4: Кўрсаткичлар | C4: Жами капитал
A5: I. | B5: I ДАРАЖАЛИ КАПИТАЛ
A6: 1 | B6: I ДАРАЖАЛИ АСОСИЙ КАПИТАЛ
A7: 1.1. | B7: Оддий акциялар, нетто | C7: =+C8-C9 -> 948876837
A8: a | B8: Тўлиқ тўланган оддий акциялар | C8: 948876837
A9: б | B9: Минус: Қайта сотиб олинган оддий акциялар | C9: 0
A10: 1.2. | B10: Қўшимча капитал (оддий) | C10: 3870139
A11: 1.3. | B11: Тақсимланмаган фойда (зарар), шу жумладан капитал захиралар | C11: =+C12+C13-C14-C15 -> 606491024
A12: а | B12: Капитал ва бошқа захиралар | C12: 504719608
A13: б | B13: Тақсимланмаган фойда | C13: 101771416
A14: в | B14: Ўтган даврлар (йиллар) учун зарарлар | C14: 0
A15: г | B15: Жорий йил учун зарар | C15: 0
A16: 1.4. | B16: Озчилик улуш эгаларининг банк йиғма балансига бирлашадиган корхоналардаги улушлари | C16: 0
A17: 1.5. | B17: Девальвация захираси | C17: 0
A18: 1.6. | B18: Чегирмалар ҳисоблангунга қадар жами I даражали асосий капитал | C18: =+C7+C10+C11+C16+C17 -> 1559238000
A19: 1.7. | B19: I даражали асосий капиталдан чегирмалар | C19: =C20+C21+C22+C23+C24 -> 97732118
A20: а | B20: Номоддий активлар (бундан банкнинг дастурий таъминотлари мустасно) | C20: 1885673
A21: б | B21: Бирлашмаган (консолидация қилинмаган) хўжалик юритувчи субъектлар капиталига барча инвестициялар суммаси, шу жумладан ушбу хўжалик юритувчи субъектлар капиталини ташкил қилувчи қарз мажбуриятлари | C21: 95846445
A22: в | B22: Бошқа банкларнинг капиталига қилинган инвестициялар | C22: 0
A23: г | B23: Банк томонидан муаммоли активлар бўйича қўшимча шакллантирилиши лозим бўлган захиралар | C23: 0
A24: д | B24: Банкка алоқадор бир ёки барча шахслар учун таваккалчиликнинг белгиланган энг кўп миқдоридан ортиқ қиймати | C24: =+IF(MAX('[6]Transactions of related parties'!$Z$90-E25*25%,'[6]Transactions of related parties'!$Z$89-E25*50%)<0,0,MAX('[6]Transactions of related parties'!$Z$90-E25*25%,'[6]Transactions of related parties'!$Z$89-E25*50%)) -> 0 | E24: =+'[6]Transactions of related parties'!$Z$89 -> 426909132
A25: I | B25: I ДАРАЖАЛИ АСОСИЙ КАПИТАЛ | C25: =+C18-C19 -> 1461505882 | E25: =C18-C20-C21-C22-C23 -> 1461505882
A26: 2 | B26: I ДАРАЖАЛИ ҚЎШИМЧА КАПИТАЛ
A27: 2.1. | B27: Нокумулятив муддатсиз имтиёзли акциялар | C27: =+C28-C29 -> 2178000
A28: а | B28: Тўлиқ тўланган имтиёзли акциялар | C28: 2178000
A29: б | B29: Минус: Қайтиб сотиб олинган имтиёзли акциялар | C29: 0
A30: 2.2. | B30: Қўшилган капитал (имтиёзли) | C30: 36000
A31: 2.3. | B31: Озчилик улуш эгаларининг банк йиғма балансига бирлашадиган корхоналардаги улушлари | C31: 0
A32: 2.4. | B32: Шўъба корхоналарнинг улушлари (шўъба корхоналар томонидан чиқарилган ва капиталга тенглаштирилган учинчи шахслар эгалик қиладиган воситалар) | C32: 0
A33: II | B33: ЖАМИ I ДАРАЖАЛИ ҚЎШИМЧА КАПИТАЛ | C33: =+C27+C30+C31+C32 -> 2214000
A34: III | B34: ЖАМИ ТЎҒРИЛАНГАН I ДАРАЖАЛИ КАПИТАЛ | C34: =+C25+C33 -> 1463719882
B35: II ДАРАЖАЛИ КАПИТАЛ
A36: 3.1. | B36: Жорий йил соф фойдаси | C36: 228394438
A37: 3.2. | B37: Стандарт активларга яратилган захиралар | C37: =IF(F37<(C45*1.25%),F37,(C45*1.25%)) -> 102193771 | E37: Резервы созданные по стандартным активам | F37: 102193771
A38: 3.3. | B38: Чегирмалардан сўнг I даражали капиталнинг учдан бир қисмидан ошмаган миқдорда аралаш турдаги мажбуриятлар | F38: =+[7]Balance!$C$39+[7]Balance!$C$61+[7]Balance!$C$73 -> 102193771
A39: 3.4. | B39: Субординар қарз | C39: 148235464 | F39: =+F37-F38 -> 0
A40: 3.5. | B40: Активларнинг бошланғич қийматига нисбатан баҳолаш қийматининг ошган суммасининг 45 фоизи миқдори | C40: 2467451
A41: 3.6. | B41: II даражали капиталнинг I даражали капиталдан ортиқча қисми (чегирмаси) | C41: =IF(C42<(C34/3),0,(C42-C34/3)*-1) -> 0
...

Sheet Bank Capital Calc (2)
A1: РАСЧЕТ РЕГУЛЯТИВНОГО КАПИТАЛА БАНКА | C1: Таблица-5
B3: =#REF! -> #REF! | C3: =+#REF! -> #REF!
A4: № | B4: Характеристики | C4: Итого капитала
A5: I. | B5: КАПИТАЛ УРОВНЯ 1
A6: 1 | B6: ОСНОВНОЙ КАПИТАЛ УРОВНЯ 1
A7: 1.1. | B7: Обыкновенные Акции, чистые | C7: Формула
A8: a | B8: Полностью оплаченные обыкновенные акции
A9: б | B9: Минус: Обратно Выкупленные обыкновенные акции
A10: 1.2. | B10: Добавленный капитал - Обыкновенные | C10: 0
A11: 1.3. | B11: Нераспределенная прибыль (убыток), в том числе капитальные резервы | C11: Формула
A12: а | B12: Капитальные резервы
A13: б | B13: Нераспределенная прибыль
A14: в | B14: Убыток за предыдущие периоды
A15: г | B15: Убыток за текущий год
A16: 1.4. | B16: Интерес меньшинства в консолидированных дочерних компаниях (согласно МБС)
A17: 1.5. | B17: Резерв на девальвацию
B18: Итого основного капитала уровня I до вычетов | C18: Формула
A19: 1.6. | B19: Вычеты из суммы основного капитала уровня I | C19: Формула
A20: а | B20: Нематериальные активы
A21: б | B21: Все инвестиции в капитал неконсолидированных хозяйствующих субъектов, в том числе в долговые обязательства, которые образуют капитал хозяйствующих субъектов
A22: в | B22: Инвестиции в капитал других банков
A23: I | B23: ВСЕГО СКОРРЕКТИРОВАННЫЙ ОСНОВНОЙ КАПИТАЛ УРОВНЯ I | C23: Формула
A24: 2 | B24: ДОБАВЛЕННЫЙ КАПИТАЛ УРОВНЯ 1
A25: 2.1. | B25: Некумулятивные бессрочные привилегированные акции | C25: =+C26+C27 -> 0
A26: а | B26: Полностью оплаченные привилегированные акции
A27: б | B27: Минус: Обратно Выкупленные привилегированные акции
A28: 2.2. | B28: Добавленный капитал - Привилегированные | C28: 0
A29: 2.3. | B29: Интерес меньшинства в консолидированных дочерних компаниях | C29: 0
A30: 2.4. | B30: Доля участия дочерних предприятий (выпущенные дочерними предприятиями и находящиеся во владении третьих лиц инструменты, приравненные к капиталу) | C30: 0
A31: II | B31: ВСЕГО ДОБАВЛЕННЫЙ КАПИТАЛ УРОВНЯ I | C31: =+C25+C28+C29+C30 -> 0
A32: III | B32: ВСЕГО СКОРРЕКТИРОВАННЫЙ КАПИТАЛ УРОВНЯ I | C32: Формула
B33: КАПИТАЛ УРОВНЯ II
A34: 3.1. | B34: Прибыль за текущий год
A35: 3.2. | B35: Резервы, создаваемые на стандартные кредиты (активы), в размере не более 1.25% от общей суммы активов, взвешенных с учетом риска | C35: =IF(#REF!<(C43*1.25%),#REF!,(C43*1.25%)) -> #REF!
A36: 3.3. | B36: Излишки оценочной стоимости прироста над первоначальной стоимостью
A37: 3.4. | B37: Другие инструменты капитала (не более 1/3 части капитала 1 уровня после вычетов)
A38: 3.5. | B38: Субординированный долг
A39: 3.6. | B39: Вычеты превышения Капитала Уровня II над Капиталом Уровня I | C39: Формула
B40: Итого капитала Уровня II | C40: =SUM(C34:C38) -> #REF!
A41: IV | B41: СКОРРЕКТИРОВАННЫЙ КАПИТАЛ УРОВНЯ II | C41: Формула
...

Sheet Calculation of Risk Weighted As
A1: ТАВАККАЛЧИЛИКНИ ҲИСОБГА ОЛГАН ҲОЛДАГИ АКТИВЛАР | I1: 6-жадвал
B2: =+'Bank Capital Calc'!B3 -> "Алоқабанк" | G2: =+'Bank Capital Calc'!C3 -> 44926 | I2: минг сўмда
A3: № | B3: Кўрсаткичлар | C3: 0 | D3: 0.2 | E3: 0.35 | F3: 0.5 | G3: 1 | H3: 1.5 | I3: 2
C4: Таваккалчилик | D4: Таваккалчилик | E4: Таваккалчилик | F4: Таваккалчилик | G4: Таваккалчилик | H4: Таваккалчилик | I4: Таваккалчилик
C5: I гуруҳ | D5: II гуруҳ | E5: III гуруҳ | F5: IV гуруҳ | G5: V гуруҳ | H5: VI гуруҳ | I5: VII гуруҳ
B6: (A) | C6: (Б) | D6: (В) | E6: (Г) | F6: (Д) | G6: (Е) | H6: (Ж) | I6: (З)
B7: I. БАЛАНС АКТИВЛАРИ
A8: 1. | B8: Кассадаги нақд пул ва бошқа тўлов ҳужжатлари ва қимматбаҳо металлар | C8: 465425696
A9: 2. | B9: Йўлдаги нақд пуллар ва бошқа тўлов ҳужжатлари | D9: 18515682
A10: 3. | B10: Банкнинг Марказий банкдаги маблағлар | C10: 1355760159 | D10: 265155239
A11: 4. | B11: Бошқа банкларга жойлаштирилган пул маблағлари, жумладан вакиллик ҳисобварақлари, депозитлар ва кредитлар | D11: 149857095 | F11: 1462389386 | G11: 960000
A12: 5. | B12: Қимматли қоғозлар (соф)
A13: а | B13: Ўзбекистон Республикаси Ҳукумати ва Марказий банки томонидан чиқарилган қимматли қоғозлар | C13: 789666477
A14: б | B14: Ипотекани қайта молиялаштириш ташкилотлари томонидан чиқарилган қимматли қоғозлар
A15: в | B15: Хорижий давлатларининг ҳукуматлари ва марказий банклари томонидан чиқарилган қимматли қоғозлар, шунингдек ушбу мамлакатларнинг марказий банклари ва ҳукуматларига нисбатан бошқа талаблар
A16: г | B16: Ўзбекистон Республикаси ҳудудида чиқарилган бошқа қимматли қоғозлар
A17: д | B17: Чет давлатлар томонидан чиқарилган бошқа қимматли қоғозлар
A18: е | B18: РЕПО битимлари бўйича сотиб олинган қимматли қоғозлар
A19: 6. | B19: Миллий валютага деноминация қилинмаган ва миллий валютада молиялаштириш суммасидан ошиб кетган активлар
A20: 7. | B20: Хорижий давлатларнинг давлат секторлари (ҳукуматлар ва марказий банклар бундан мустасно) ва хорижий компаниялар бўйича банк талаблари, шунингдек уларнинг қимматли қоғозлари билан таъминланган ёки кафолатланган активлар (кредитлар ва қимматли қоғозлар бундан мустасно)
A21: 8. | B21: Кредит ва лизинглар, соф
A22: а | B22: Ўзбекистон Республикаси ҳукумати ва Марказий банкига тўғридан-тўғри берилган кредитлар
A23: б | B23: Халқаро молия институтларига берилган кредитлар, халқаро молия ташкилотларининг қимматли қоғозлари билан таъминланган ёки улар томонидан кафолатланган кредитлар қисми
A24: в | B24: Қисман ёки тўлиқ депозит билан таъминланган кредитлар | C24: 687374863
A25: г | B25: Жорий бозор қийматида баҳоланган ва ЎзР Ҳукумати, ЎзР Марказий банки томонидан эмиссия қилинган ёки кафолатланган қимматли қоғозлар кўринишидаги гаров билан таъминланган ёки кафолатланган кредитлар, уларнинг қисмлари.
A26: д | B26: Дастлабки гаров ҳуқуқи банкка тегишли бўлмаган кредитлар
A27: е | B27: Аҳолига кўчмас мулк сотиб олиш учун берилган ва сотиб олинган ёки қурилаётган уй (квартира) билан таъминланган кредитлар | E27: 57629358 | F27: 95700220 | G27: 197517708 | H27: 167341068
A28: ж | B28: Аҳолига берилган бошқа кредитлар | G28: 632712404 | H28: 1083713463 | I28: 106333771
A29: з | B29: Бошқа барча кредит ва лизинглар | G29: 3748038328 | H29: 982834711 | I29: 1206302889
A30: и | B30: Муаммоли кредит ва лизинглар, соф | I30: 139465341
A31: 9. | B31: Банкнинг асосий воситалари ва бошқа хусусий мол-мулклари
A32: а | B32: Банк фаолиятидаги фойдаланиладиган асосий воситалар (амортизацияни чегирган ҳолда) | G32: 1181906279
A33: б | B33: Банкнинг бошқа хусусий мулклари | G33: 0
A34: в | B34: Қарздорликни тўлиқ ёки қисман ундириш мақсадида банк балансига қабул қилинган кўчмас мулк | H34: 149057251
A35: г | B35: Икки йилдан ортиқ вақт мобайнида банк фойдаланмаётган банкнинг кўчмас мулки | H35: 0
A36: 10. | B36: Консолидация қилинмаган хўжалик юритувчи субъектларнинг капиталига киритилган барча инвестициялар, шу жумладан, хўжалик юритувчи субъектларнинг капиталини шакллантирувчи қарз мажбуриятлари, бошқа банкларнинг капиталига қўйилган инвестициялар, соф | C36: 95846445
A37: 11. | B37: Бошқа барча инвестициялар, соф
A38: 12. | B38: Номоддий активлар, соф | C38: 1885673 | G38: 54496316
A39: 13. | B39: Молиявий инструментлар бўйича мижозларнинг мажбуриятлари, соф | G39: 329584914
A40: 14. | B40: Бошқа муаммоли активлар | I40: 12180
...

Sheet Calculation of Risk Weighte нац
A1: МИЛЛИЙ ВАЛЮТАДА ТАВАККАЛЧИЛИКНИ ҲИСОБГА ОЛГАН ҲОЛДАГИ АКТИВЛАР | I1: 6.1-жадвал
B2: =+'Bank Capital Calc'!B3 -> "Алоқабанк" | G2: =+'Bank Capital Calc'!C3 -> 44926 | I2: минг сўмда
A3: № | B3: Кўрсаткичлар | C3: 0 | D3: 0.2 | E3: 0.35 | F3: 0.5 | G3: 1 | H3: 1.5 | I3: 2
C4: Таваккалчилик | D4: Таваккалчилик | E4: Таваккалчилик | F4: Таваккалчилик | G4: Таваккалчилик | H4: Таваккалчилик | I4: Таваккалчилик
C5: I гуруҳ | D5: II гуруҳ | E5: III гуруҳ | F5: IV гуруҳ | G5: V гуруҳ | H5: VI гуруҳ | I5: VII гуруҳ
B6: (A) | C6: (Б) | D6: (В) | E6: (Г) | F6: (Д) | G6: (Е) | H6: (Ж) | I6: (З)
B7: I. БАЛАНС АКТИВЛАРИ
A8: 1. | B8: Кассадаги нақд пул ва бошқа тўлов ҳужжатлари ва қимматбаҳо металлар | C8: 167799552
A9: 2. | B9: Йўлдаги нақд пуллар ва бошқа тўлов ҳужжатлари | D9: 7686000
A10: 3. | B10: Банкнинг Марказий банкдаги маблағлар | C10: 1355760159
A11: 4. | B11: Бошқа банкларга жойлаштирилган пул маблағлари, жумладан вакиллик ҳисобварақлари, депозитлар ва кредитлар | F11: 508043695 | G11: 960000
A12: 5. | B12: Қимматли қоғозлар (соф)
A13: а | B13: Ўзбекистон Республикаси Ҳукумати ва Марказий банки томонидан чиқарилган қимматли қоғозлар | C13: 789666477
A14: б | B14: Ипотекани қайта молиялаштириш ташкилотлари томонидан чиқарилган қимматли қоғозлар
A15: в | B15: Хорижий давлатларининг ҳукуматлари ва марказий банклари томонидан чиқарилган қимматли қоғозлар, шунингдек ушбу мамлакатларнинг марказий банклари ва ҳукуматларига нисбатан бошқа талаблар
A16: г | B16: Ўзбекистон Республикаси ҳудудида чиқарилган бошқа қимматли қоғозлар
A17: д | B17: Чет давлатлар томонидан чиқарилган бошқа қимматли қоғозлар
A18: е | B18: РЕПО битимлари бўйича сотиб олинган қимматли қоғозлар
A19: 6. | B19: Миллий валютага деноминация қилинмаган ва миллий валютада молиялаштириш суммасидан ошиб кетган активлар
A20: 7. | B20: Хорижий давлатларнинг давлат секторлари (ҳукуматлар ва марказий банклар бундан мустасно) ва хорижий компаниялар бўйича банк талаблари, шунингдек уларнинг қимматли қоғозлари билан таъминланган ёки кафолатланган активлар (кредитлар ва қимматли қоғозлар бундан мустасно)
A21: 8. | B21: Кредит ва лизинглар, соф
A22: а | B22: Ўзбекистон Республикаси ҳукумати ва Марказий банкига тўғридан-тўғри берилган кредитлар
A23: б | B23: Халқаро молия институтларига берилган кредитлар, халқаро молия ташкилотларининг қимматли қоғозлари билан таъминланган ёки улар томонидан кафолатланган кредитлар қисми
A24: в | B24: Қисман ёки тўлиқ депозит билан таъминланган кредитлар | C24: 511392962
A25: г | B25: Кредитлар/уларнинг қисмлари жорий бозор баҳосидаги ҳукумат, Марказий банк томонидан чиқарилган ёки кафолатланган қимматли қоғозлар билан таъминланган кредитлар/уларнинг қисмлари, шунингдек ҳукумат ва Марказий банк томонидан кафолатланган кредитлар/уларнинг қисмлари
A26: д | B26: Дастлабки гаров ҳуқуқи банкка тегишли бўлмаган кредитлар
A27: е | B27: Аҳолига кўчмас мулк сотиб олиш учун берилган ва сотиб олинган ёки қурилаётган уй (квартира) билан таъминланган кредитлар | E27: 57629358 | F27: 95700220 | G27: 197517708 | H27: 167341068
A28: ж | B28: Аҳолига берилган бошқа кредитлар | G28: 632712404 | H28: 1083713463 | I28: 106333771
A29: з | B29: Бошқа барча кредит ва лизинглар | G29: 1399220659 | H29: 298744058 | I29: 943460754
A30: и | B30: Муаммоли кредит ва лизинглар, соф | I30: 97835233
A31: 9. | B31: Банкнинг асосий воситалари ва бошқа хусусий мол-мулклари
A32: а | B32: Банк фаолиятидаги фойдаланиладиган асосий воситалар (амортизацияни чегирган ҳолда) | G32: 1181906279
A33: б | B33: Банкнинг бошқа хусусий мулклари
A34: в | B34: Қарздорликни тўлиқ ёки қисман ундириш мақсадида банк балансига қабул қилинган кўчмас мулк | H34: 149057251
A35: г | B35: Икки йилдан ортиқ вақт мобайнида банк фойдаланмаётган банкнинг кўчмас мулки
A36: 10. | B36: Консолидация қилинмаган хўжалик юритувчи субъектларнинг капиталига киритилган барча инвестициялар, шу жумладан, хўжалик юритувчи субъектларнинг капиталини шакллантирувчи қарз мажбуриятлари, бошқа банкларнинг капиталига қўйилган инвестициялар, соф | C36: 95846445
A37: 11. | B37: Бошқа барча инвестициялар, соф
A38: 12. | B38: Номоддий активлар, соф | C38: 1885673 | G38: 54496316
A39: 13. | B39: Молиявий инструментлар бўйича мижозларнинг мажбуриятлари, соф
A40: 14. | B40: Бошқа муаммоли активлар | I40: 12180
...

Sheet Calculation of Risk Weighte ин
A1: ХОРИЖИЙ ВАЛЮТАДА ТАВАККАЛЧИЛИКНИ ҲИСОБГА ОЛГАН ҲОЛДАГИ АКТИВЛАР | I1: 6.2-жадвал
B2: =+'Bank Capital Calc'!B3 -> "Алоқабанк" | G2: =+'Bank Capital Calc'!C3 -> 44926 | I2: минг сўмда
A3: № | B3: Кўрсаткичлар | C3: 0 | D3: 0.2 | E3: 0.35 | F3: 0.5 | G3: 1 | H3: 1.5 | I3: 2
C4: Таваккалчилик | D4: Таваккалчилик | E4: Таваккалчилик | F4: Таваккалчилик | G4: Таваккалчилик | H4: Таваккалчилик | I4: Таваккалчилик
C5: I гуруҳ | D5: II гуруҳ | E5: III гуруҳ | F5: IV гуруҳ | G5: V гуруҳ | H5: VI гуруҳ | I5: VII гуруҳ
B6: (A) | C6: (Б) | D6: (В) | E6: (Г) | F6: (Д) | G6: (Е) | H6: (Ж) | I6: (З)
B7: I. БАЛАНС АКТИВЛАРИ
A8: 1. | B8: Кассадаги нақд пул ва бошқа тўлов ҳужжатлари ва қимматбаҳо металлар | C8: =+'Calculation of Risk Weighted As'!C8-'Calculation of Risk Weighte нац'!C8 -> 297626144
A9: 2. | B9: Йўлдаги нақд пуллар ва бошқа тўлов ҳужжатлари | D9: =+'Calculation of Risk Weighted As'!D9-'Calculation of Risk Weighte нац'!D9 -> 10829682
A10: 3. | B10: Банкнинг Марказий банкдаги маблағлар | C10: =+'Calculation of Risk Weighted As'!C10-'Calculation of Risk Weighte нац'!C10 -> 0 | D10: =+'Calculation of Risk Weighted As'!D10-'Calculation of Risk Weighte нац'!D10 -> 265155239
A11: 4. | B11: Бошқа банкларга жойлаштирилган пул маблағлари, жумладан вакиллик ҳисобварақлари, депозитлар ва кредитлар | D11: =+'Calculation of Risk Weighted As'!D11-'Calculation of Risk Weighte нац'!D11 -> 149857095 | F11: =+'Calculation of Risk Weighted As'!F11-'Calculation of Risk Weighte нац'!F11 -> 954345691 | G11: =+'Calculation of Risk Weighted As'!G11-'Calculation of Risk Weighte нац'!G11 -> 0 | H11: =+'Calculation of Risk Weighted As'!H11-'Calculation of Risk Weighte нац'!H11 -> 0
A12: 5. | B12: Қимматли қоғозлар (соф)
A13: а | B13: Ўзбекистон Республикаси Ҳукумати ва Марказий банки томонидан чиқарилган қимматли қоғозлар | C13: =+'Calculation of Risk Weighted As'!C13-'Calculation of Risk Weighte нац'!C13 -> 0 | D13: =+'Calculation of Risk Weighted As'!D13-'Calculation of Risk Weighte нац'!D13 -> 0
A14: б | B14: Ипотекани қайта молиялаштириш ташкилотлари томонидан чиқарилган қимматли қоғозлар | C14: =+'Calculation of Risk Weighted As'!C14-'Calculation of Risk Weighte нац'!C14 -> 0 | D14: =+'Calculation of Risk Weighted As'!D14-'Calculation of Risk Weighte нац'!D14 -> 0
A15: в | B15: Хорижий давлатларининг ҳукуматлари ва марказий банклари томонидан чиқарилган қимматли қоғозлар, шунингдек ушбу мамлакатларнинг марказий банклари ва ҳукуматларига нисбатан бошқа талаблар | C15: =+'Calculation of Risk Weighted As'!C15-'Calculation of Risk Weighte нац'!C15 -> 0 | D15: =+'Calculation of Risk Weighted As'!D15-'Calculation of Risk Weighte нац'!D15 -> 0 | F15: =+'Calculation of Risk Weighted As'!F15-'Calculation of Risk Weighte нац'!F15 -> 0 | G15: =+'Calculation of Risk Weighted As'!G15-'Calculation of Risk Weighte нац'!G15 -> 0 | H15: =+'Calculation of Risk Weighted As'!H15-'Calculation of Risk Weighte нац'!H15 -> 0
A16: г | B16: Ўзбекистон Республикаси ҳудудида чиқарилган бошқа қимматли қоғозлар | C16: =+'Calculation of Risk Weighted As'!C16-'Calculation of Risk Weighte нац'!C16 -> 0 | D16: =+'Calculation of Risk Weighted As'!D16-'Calculation of Risk Weighte нац'!D16 -> 0 | F16: =+'Calculation of Risk Weighted As'!F16-'Calculation of Risk Weighte нац'!F16 -> 0 | G16: =+'Calculation of Risk Weighted As'!G16-'Calculation of Risk Weighte нац'!G16 -> 0 | H16: =+'Calculation of Risk Weighted As'!H16-'Calculation of Risk Weighte нац'!H16 -> 0
A17: д | B17: Чет давлатлар томонидан чиқарилган бошқа қимматли қоғозлар | C17: =+'Calculation of Risk Weighted As'!C17-'Calculation of Risk Weighte нац'!C17 -> 0 | D17: =+'Calculation of Risk Weighted As'!D17-'Calculation of Risk Weighte нац'!D17 -> 0 | F17: =+'Calculation of Risk Weighted As'!F17-'Calculation of Risk Weighte нац'!F17 -> 0 | G17: =+'Calculation of Risk Weighted As'!G17-'Calculation of Risk Weighte нац'!G17 -> 0 | H17: =+'Calculation of Risk Weighted As'!H17-'Calculation of Risk Weighte нац'!H17 -> 0
A18: е | B18: РЕПО битимлари бўйича сотиб олинган қимматли қоғозлар | C18: =+'Calculation of Risk Weighted As'!C18-'Calculation of Risk Weighte нац'!C18 -> 0 | D18: =+'Calculation of Risk Weighted As'!D18-'Calculation of Risk Weighte нац'!D18 -> 0 | F18: =+'Calculation of Risk Weighted As'!F18-'Calculation of Risk Weighte нац'!F18 -> 0 | G18: =+'Calculation of Risk Weighted As'!G18-'Calculation of Risk Weighte нац'!G18 -> 0 | H18: =+'Calculation of Risk Weighted As'!H18-'Calculation of Risk Weighte нац'!H18 -> 0
A19: 6. | B19: Миллий валютага деноминация қилинмаган ва миллий валютада молиялаштириш суммасидан ошиб кетган активлар | G19: =+'Calculation of Risk Weighted As'!G19-'Calculation of Risk Weighte нац'!G19 -> 0
A20: 7. | B20: Хорижий давлатларнинг давлат секторлари (ҳукуматлар ва марказий банклар бундан мустасно) ва хорижий компаниялар бўйича банк талаблари, шунингдек уларнинг қимматли қоғозлари билан таъминланган ёки кафолатланган активлар (кредитлар ва қимматли қоғозлар бундан мустасно) | C20: =+'Calculation of Risk Weighted As'!C20-'Calculation of Risk Weighte нац'!C20 -> 0 | D20: =+'Calculation of Risk Weighted As'!D20-'Calculation of Risk Weighte нац'!D20 -> 0 | F20: =+'Calculation of Risk Weighted As'!F20-'Calculation of Risk Weighte нац'!F20 -> 0 | G20: =+'Calculation of Risk Weighted As'!G20-'Calculation of Risk Weighte нац'!G20 -> 0 | H20: =+'Calculation of Risk Weighted As'!H20-'Calculation of Risk Weighte нац'!H20 -> 0
A21: 8. | B21: Кредит ва лизинглар, соф
A22: а | B22: Ўзбекистон Республикаси ҳукумати ва Марказий банкига тўғридан-тўғри берилган кредитлар | C22: =+'Calculation of Risk Weighted As'!C22-'Calculation of Risk Weighte нац'!C22 -> 0
A23: б | B23: Халқаро молия институтларига берилган кредитлар, халқаро молия ташкилотларининг қимматли қоғозлари билан таъминланган ёки улар томонидан кафолатланган кредитлар қисми | C23: =+'Calculation of Risk Weighted As'!C23-'Calculation of Risk Weighte нац'!C23 -> 0
A24: в | B24: Қисман ёки тўлиқ депозит билан таъминланган кредитлар | C24: =+'Calculation of Risk Weighted As'!C24-'Calculation of Risk Weighte нац'!C24 -> 175981901 | D24: =+'Calculation of Risk Weighted As'!D24-'Calculation of Risk Weighte нац'!D24 -> 0
A25: г | B25: Кредитлар/уларнинг қисмлари жорий бозор баҳосидаги ҳукумат, Марказий банк томонидан чиқарилган ёки кафолатланган қимматли қоғозлар билан таъминланган кредитлар/уларнинг қисмлари, шунингдек ҳукумат ва Марказий банк томонидан кафолатланган кредитлар/уларнинг қисмлари | C25: =+'Calculation of Risk Weighted As'!C25-'Calculation of Risk Weighte нац'!C25 -> 0
A26: д | B26: Дастлабки гаров ҳуқуқи банкка тегишли бўлмаган кредитлар | G26: =+'Calculation of Risk Weighted As'!G26-'Calculation of Risk Weighte нац'!G26 -> 0
A27: е | B27: Аҳолига кўчмас мулк сотиб олиш учун берилган ва сотиб олинган ёки қурилаётган уй (квартира) билан таъминланган кредитлар | E27: =+'Calculation of Risk Weighted As'!E27-'Calculation of Risk Weighte нац'!E27 -> 0 | F27: =+'Calculation of Risk Weighted As'!F27-'Calculation of Risk Weighte нац'!F27 -> 0 | G27: =+'Calculation of Risk Weighted As'!G27-'Calculation of Risk Weighte нац'!G27 -> 0 | H27: =+'Calculation of Risk Weighted As'!H27-'Calculation of Risk Weighte нац'!H27 -> 0
A28: ж | B28: Аҳолига берилган бошқа кредитлар | G28: =+'Calculation of Risk Weighted As'!G28-'Calculation of Risk Weighte нац'!G28 -> 0 | H28: =+'Calculation of Risk Weighted As'!H28-'Calculation of Risk Weighte нац'!H28 -> 0 | I28: =+'Calculation of Risk Weighted As'!I28-'Calculation of Risk Weighte нац'!I28 -> 0
A29: з | B29: Бошқа барча кредит ва лизинглар | G29: =+'Calculation of Risk Weighted As'!G29-'Calculation of Risk Weighte нац'!G29 -> 2348817669 | H29: =+'Calculation of Risk Weighted As'!H29-'Calculation of Risk Weighte нац'!H29 -> 684090653 | I29: =+'Calculation of Risk Weighted As'!I29-'Calculation of Risk Weighte нац'!I29 -> 262842135
A30: и | B30: Муаммоли кредит ва лизинглар, соф | I30: =+'Calculation of Risk Weighted As'!I30-'Calculation of Risk Weighte нац'!I30 -> 41630108
A31: 9. | B31: Банкнинг асосий воситалари ва бошқа хусусий мол-мулклари
A32: а | B32: Банк фаолиятидаги фойдаланиладиган асосий воситалар (амортизацияни чегирган ҳолда) | G32: =+'Calculation of Risk Weighted As'!G32-'Calculation of Risk Weighte нац'!G32 -> 0
A33: б | B33: Банкнинг бошқа хусусий мулклари | G33: =+'Calculation of Risk Weighted As'!G33-'Calculation of Risk Weighte нац'!G33 -> 0
A34: в | B34: Қарздорликни тўлиқ ёки қисман ундириш мақсадида банк балансига қабул қилинган кўчмас мулк | H34: =+'Calculation of Risk Weighted As'!H34-'Calculation of Risk Weighte нац'!H34 -> 0 | I34: =+'Calculation of Risk Weighted As'!I34-'Calculation of Risk Weighte нац'!I34 -> 0
A35: г | B35: Икки йилдан ортиқ вақт мобайнида банк фойдаланмаётган банкнинг кўчмас мулки | H35: =+'Calculation of Risk Weighted As'!H35-'Calculation of Risk Weighte нац'!H35 -> 0 | I35: =+'Calculation of Risk Weighted As'!I35-'Calculation of Risk Weighte нац'!I35 -> 0
A36: 10. | B36: Консолидация қилинмаган хўжалик юритувчи субъектларнинг капиталига киритилган барча инвестициялар, шу жумладан, хўжалик юритувчи субъектларнинг капиталини шакллантирувчи қарз мажбуриятлари, бошқа банкларнинг капиталига қўйилган инвестициялар, соф | C36: =+'Calculation of Risk Weighted As'!C36-'Calculation of Risk Weighte нац'!C36 -> 0
A37: 11. | B37: Бошқа барча инвестициялар, соф | G37: =+'Calculation of Risk Weighted As'!G37-'Calculation of Risk Weighte нац'!G37 -> 0
A38: 12. | B38: Номоддий активлар, соф | C38: =+'Calculation of Risk Weighted As'!C38-'Calculation of Risk Weighte нац'!C38 -> 0 | G38: =+'Calculation of Risk Weighted As'!G38-'Calculation of Risk Weighte нац'!G38 -> 0
A39: 13. | B39: Молиявий инструментлар бўйича мижозларнинг мажбуриятлари, соф | C39: =+'Calculation of Risk Weighted As'!C39-'Calculation of Risk Weighte нац'!C39 -> 0 | G39: =+'Calculation of Risk Weighted As'!G39-'Calculation of Risk Weighte нац'!G39 -> 329584914 | I39: =+'Calculation of Risk Weighted As'!I39-'Calculation of Risk Weighte нац'!I39 -> 0
A40: 14. | B40: Бошқа муаммоли активлар | I40: =+'Calculation of Risk Weighted As'!I40-'Calculation of Risk Weighte нац'!I40 -> 0
...

Sheet Calculation of Risk
A1: ОПЕРАЦИОН ВА БОЗОР ТАВАККАЛЧИЛИКЛАРИ ҲИСОБ-КИТОБИ | C1: 6а-жадвал | I1: Достаточность капитала - К1 | J1: Коэффициент достаточности капитала I уровня K2 | K1: Доля основного капитала I уровня к регулятивному капиталу | L1: Коэффициент нормы покрытия ликвидности | M1: Норма чистого стабильного финансирования (НЧСФ)
B2: =IF(C3>0," "&TEXT(C3,"д ММММ, гггг"),"Число,Месяц,Год") -> 31 Декабрь, 2022
B3: =+'Bank Capital Calc'!B3 -> "Алоқабанк" | C3: =+'Bank Capital Calc'!C3 -> 44926
A4: № | B4: Кўрсаткичлар номи | C4: минг сўмда
A5: 1. | B5: =+""&(E$10-3)&" йилдаги банкнинг ялпи даромади" -> 2019 йилдаги банкнинг ялпи даромади | C5: =+C6+C8-C7-C9 -> 500138937
A6: а. | B6: фоизли даромад | C6: 1152180044
A7: б. | B7: фоизли харажат | C7: 776657589
A8: в. | B8: фоизсиз даромад | C8: 192806331 | E8: 2022
A9: г. | B9: фоизсиз харажат | C9: 68189849
A10: 2. | B10: =+""&(E$10-2)&" йилдаги банкнинг ялпи даромади" -> 2020 йилдаги банкнинг ялпи даромади | C10: =+C11+C13-C12-C14 -> 490963020 | E10: =IF(E8>H10,H9,E8) -> 2022 | H10: 2022 | I10: 13 | J10: 10 | K10: 0.8 | L10: 100 | M10: 100
A11: а. | B11: фоизли даромад | C11: 1185874258
A12: б. | B12: фоизли харажат | C12: 819338253
A13: в. | B13: фоизсиз даромад | C13: 294481740
A14: г. | B14: фоизсиз харажат | C14: 170054725
A15: 3. | B15: =+""&(E$10-1)&" йилдаги банкнинг ялпи даромади" -> 2021 йилдаги банкнинг ялпи даромади | C15: =+C16+C18-C17-C19 -> 623564273
A16: а. | B16: фоизли даромад | C16: 1206690017
A17: б. | B17: фоизли харажат | C17: 798308535
A18: в. | B18: фоизсиз даромад | C18: 427153372
A19: г. | B19: фоизсиз харажат | C19: 211970581
A20: 4. | B20: Банкнинг ўртача ялпи даромади (оҳирги уч йил давомида) | C20: =(C5+C10+C15)/3 -> 5.3822208e+08
A21: 5. | B21: Операцион таваккалчиликлар қиймати | C21: =+(100/C28)*C20*15% -> 6.2102547e+08
A23: 6. | B23: Валюта позицияси ҳисобварақлари | C23: -194299527
A24: 7. | B24: Кўзда тутилмаган ҳолатлар бўйича талаблар | C24: 157156440 | D24: 92503, 92705, 92716, 92728, 92732
A25: 8. | B25: Кўзда тутилмаган ҳолатлар бўйича мажбуриятлар | C25: 213857460 | D25: 92501, 92701, 92709, 92724, 92736
A26: 9. | B26: Очиқ валюта позицияси, жами | C26: =ABS(C23+(C24-C25)) -> 251000547 | D26: =+C26*0.1 -> 25100055
A27: 10. | B27: Бозор таваккалчилиги суммаси | C27: =+(100/C28)*(C26*10%) -> 1.9307734e+08
A28: 11. | B28: Капитал монандлигига бўлган амалдаги минимал талаб | C28: =VLOOKUP($E$10,$H$3:$I$10,2,0) -> 13
B30: Бошқарув Раис имзоси:
B32: Бош бухгалтер имзоси:
