Workbook
Name jop: #REF!
Name kol: #REF!
Name TwentyLargestData: #REF!
Name Е: #REF!

Sheet Bank Capital Calc
A1: РАСЧЕТ РЕГУЛЯТИВНОГО КАПИТАЛА БАНКА | C1: Таблица-5 | E1: №3
B3: Наименование банка | C3: 44196
A4: № | B4: Характеристики | C4: Итого капитала
A5: I. | B5: КАПИТАЛ УРОВНЯ 1
A6: 1 | B6: ОСНОВНОЙ КАПИТАЛ УРОВНЯ 1
A7: 1.1. | B7: Обыкновенные Акции, чистые | C7: =+C8+C9 -> 1641584276
A8: a | B8: Полностью оплаченные обыкновенные акции | C8: 1641584276
A9: б | B9: Минус: Обратно Выкупленные обыкновенные акции | C9: 0
A10: 1.2. | B10: Добавленный капитал - Обыкновенные
A11: 1.3. | B11: Нераспределенная прибыль (убыток), в том числе капитальные резервы | C11: =+C12+C13-C14-C15 -> -15476437
A12: а | B12: Капитальные резервы | C12: 34361846
A13: б | B13: Нераспределенная прибыль | C13: 0
A14: в | B14: Убыток за предыдущие периоды | C14: 49838283
A15: г | B15: Убыток за текущий год | C15: 0
A16: 1.4. | B16: Интерес меньшинства в консолидированных дочерних компаниях (согласно МБС) | C16: 0
A17: 1.5. | B17: Резерв на девальвацию | C17: 0
B18: Итого основного капитала уровня I до вычетов | C18: =+C7+C10+C11+C16+C17 -> 1626107839
A19: 1.6. | B19: Вычеты из суммы основного капитала уровня I | C19: =C21+C22+C23 -> 6707220
A20: а | B20: Нематериальные активы | C20: 1613409
A21: б | B21: Все инвестиции в капитал неконсолидированных хозяйствующих субъектов, в том числе в долговые обязательства, которые образуют капитал хозяйствующих субъектов | C21: 6707220
A22: в | B22: Инвестиции в капитал других банков | C22: 0
A23: г | B23: Резервы формируемые в соответствии с предписанием Центрального банка | C23: 0
A24: I | B24: ВСЕГО СКОРРЕКТИРОВАННЫЙ ОСНОВНОЙ КАПИТАЛ УРОВНЯ I | C24: =+C18-C19 -> 1619400619
A25: 2 | B25: ДОБАВЛЕННЫЙ КАПИТАЛ УРОВНЯ 1
A26: 2.1. | B26: Некумулятивные бессрочные привилегированные акции | C26: =+C27+C28 -> 144180
A27: а | B27: Полностью оплаченные привилегированные акции | C27: 144180
A28: б | B28: Минус: Обратно Выкупленные привилегированные акции | C28: 0
A29: 2.2. | B29: Добавленный капитал - Привилегированные | C29: 0
A30: 2.3. | B30: Интерес меньшинства в консолидированных дочерних компаниях | C30: 0
A31: 2.4. | B31: Доля участия дочерних предприятий (выпущенные дочерними предприятиями и находящиеся во владении третьих лиц инструменты, приравненные к капиталу) | C31: 0
A32: II | B32: ВСЕГО ДОБАВЛЕННЫЙ КАПИТАЛ УРОВНЯ I | C32: =+C26+C29+C30+C31 -> 144180
A33: III | B33: ВСЕГО СКОРРЕКТИРОВАННЫЙ КАПИТАЛ УРОВНЯ I | C33: =+C24+C32 -> 1619544799
B34: КАПИТАЛ УРОВНЯ II
A35: 3.1. | B35: Прибыль за текущий год | C35: 6530517
A36: 3.2. | B36: Резервы, создаваемые на стандартные кредиты (активы), в размере не более 1.25% от общей суммы активов, взвешенных с учетом риска | C36: =IF(F36<(C44*1.25%),F36,(C44*1.25%)) -> 0 | E36: Резервы созданные по стандартным активам
A37: 3.3. | B37: Излишки оценочной стоимости прироста над первоначальной стоимостью | C37: 5492492 | F37: =+[6]Balance!$C$72 -> 0
A38: 3.4. | B38: Другие инструменты капитала (не более 1/3 части капитала 1 уровня после вычетов) | C38: 0 | F38: =+F36-F37 -> 0
A39: 3.5. | B39: Субординированный долг | C39: 0
A40: 3.6. | B40: Вычеты превышения Капитала Уровня II над Капиталом Уровня I | C40: =IF(C41<(C33/3),0,(C41-C33/3)*-1) -> 0
B41: Итого капитала Уровня II | C41: =SUM(C35:C39) -> 12023009
...

Sheet Bank Capital Calc (2)
A1: РАСЧЕТ РЕГУЛЯТИВНОГО КАПИТАЛА БАНКА | C1: Таблица-5
B3: =#REF! -> #REF! | C3: =+#REF! -> #REF!
A4: № | B4: Характеристики | C4: Итого капитала
A5: I. | B5: КАПИТАЛ УРОВНЯ 1
A6: 1 | B6: ОСНОВНОЙ КАПИТАЛ УРОВНЯ 1
A7: 1.1. | B7: Обыкновенные Акции, чистые | C7: Формула
A8: a | B8: Полностью оплаченные обыкновенные акции
A9: б | B9: Минус: Обратно Выкупленные обыкновенные акции
A10: 1.2. | B10: Добавленный капитал - Обыкновенные | C10: 0
A11: 1.3. | B11: Нераспределенная прибыль (убыток), в том числе капитальные резервы | C11: Формула
A12: а | B12: Капитальные резервы
A13: б | B13: Нераспределенная прибыль
A14: в | B14: Убыток за предыдущие периоды
A15: г | B15: Убыток за текущий год
A16: 1.4. | B16: Интерес меньшинства в консолидированных дочерних компаниях (согласно МБС)
A17: 1.5. | B17: Резерв на девальвацию
B18: Итого основного капитала уровня I до вычетов | C18: Формула
A19: 1.6. | B19: Вычеты из суммы основного капитала уровня I | C19: Формула
A20: а | B20: Нематериальные активы
A21: б | B21: Все инвестиции в капитал неконсолидированных хозяйствующих субъектов, в том числе в долговые обязательства, которые образуют капитал хозяйствующих субъектов
A22: в | B22: Инвестиции в капитал других банков
A23: I | B23: ВСЕГО СКОРРЕКТИРОВАННЫЙ ОСНОВНОЙ КАПИТАЛ УРОВНЯ I | C23: Формула
A24: 2 | B24: ДОБАВЛЕННЫЙ КАПИТАЛ УРОВНЯ 1
A25: 2.1. | B25: Некумулятивные бессрочные привилегированные акции | C25: =+C26+C27 -> 0
A26: а | B26: Полностью оплаченные привилегированные акции
A27: б | B27: Минус: Обратно Выкупленные привилегированные акции
A28: 2.2. | B28: Добавленный капитал - Привилегированные | C28: 0
A29: 2.3. | B29: Интерес меньшинства в консолидированных дочерних компаниях | C29: 0
A30: 2.4. | B30: Доля участия дочерних предприятий (выпущенные дочерними предприятиями и находящиеся во владении третьих лиц инструменты, приравненные к капиталу) | C30: 0
A31: II | B31: ВСЕГО ДОБАВЛЕННЫЙ КАПИТАЛ УРОВНЯ I | C31: =+C25+C28+C29+C30 -> 0
A32: III | B32: ВСЕГО СКОРРЕКТИРОВАННЫЙ КАПИТАЛ УРОВНЯ I | C32: Формула
B33: КАПИТАЛ УРОВНЯ II
A34: 3.1. | B34: Прибыль за текущий год
A35: 3.2. | B35: Резервы, создаваемые на стандартные кредиты (активы), в размере не более 1.25% от общей суммы активов, взвешенных с учетом риска | C35: =IF(#REF!<(C43*1.25%),#REF!,(C43*1.25%)) -> #REF!
A36: 3.3. | B36: Излишки оценочной стоимости прироста над первоначальной стоимостью
A37: 3.4. | B37: Другие инструменты капитала (не более 1/3 части капитала 1 уровня после вычетов)
A38: 3.5. | B38: Субординированный долг
A39: 3.6. | B39: Вычеты превышения Капитала Уровня II над Капиталом Уровня I | C39: Формула
B40: Итого капитала Уровня II | C40: =SUM(C34:C38) -> #REF!
A41: IV | B41: СКОРРЕКТИРОВАННЫЙ КАПИТАЛ УРОВНЯ II | C41: Формула
...

Sheet Calculation of Risk Weighted As
A1: РАСЧЕТ АКТИВОВ ВЗВЕШЕННЫХ С УЧЕТОМ РИСКА | I1: Таблица-6
B2: =+'Bank Capital Calc'!B3 -> Наименование банка | G2: =+'Bank Capital Calc'!C3 -> 44196 | J2: тыс. сум
A3: № | B3: Характеристики | C3: 0 | D3: 0.2 | E3: 0.3 | F3: 0.5 | G3: 1 | H3: 1.5 | I3: 2 | J3: 3
C4: Риск | D4: Риск | E4: Риск | F4: Риск | G4: Риск | H4: Риск | I4: Риск | J4: Риск
C5: I группа | D5: II группа | E5: III группа | F5: IV группа | G5: V группа | H5: VI группа | I5: VII группа | J5: VIII группа
B6: (A) | C6: (Б) | D6: (В) | E6: (Г) | F6: (Д) | G6: (Е) | H6: (Ж) | I6: (З) | J6: (И)
B7: Балансовые Активы
A8: 1. | B8: Касса (наличность и монеты) и Драгоценные металлы | C8: 140761428
A9: 2. | B9: Денежная наличность и другие платежные документы в пути | D9: 8510926
A10: 3. | B10: Корреспондентские и резервные счета в ЦБРУ | C10: 0 | D10: 105262662
A11: 4. | B11: Корр. счета, кредиты и другие требования к банкам | H11: 580224505
A12: 5. | B12: Рыночные ценные бумаги, чистые
A13: а) | B13: Ценные бумаги, выпущенные Правительством Республики Узбекистан и ЦБРУ | C13: 135000000
A14: б) | B14: Ценные бумаги, выпущенные правительствами и центральными банками стран, с низким уровня риска, а также другие требования к центральным банкам и правительствам этих стран | C14: 0
A15: в) | B15: Ценные бумаги, выпущенные банками стран, с низким уровнем риска | D15: 0 | F15: 0
A16: г) | B16: Другие ценные бумаги | C16: 0 | G16: 11874000
A17: 6. | B17: Кредиты и другие активы или их части, обеспеченные наличными деньгами, хранящимися на отдельном блокированном депозитном счете. | C17: 0
A18: 7. | B18: Все требования банка, деноминированные в местную валюту стран не входящих в группу стран с низким уровнем риска, к Центральным банкам и центральным правительствам этих стран | D18: 0
A19: 8. | B19: Активы, обеспеченные ценными бумагами выпущенными банками зарегистрированными в странах с низким уровнем риска | D19: 0 | F19: 0
A20: 9. | B20: Требования банка к международным финансовым организациям, а также активы, гарантированные этими организациями | C20: 0
A21: 10. | B21: Активы или их части, обеспеченные залогом в виде ценных бумаг, оцененных по текущей рыночной стоимости и эмитированных международными финансовыми институтами | D21: 0
A22: 11. | B22: Кредиты и лизинги, чистые
A23: а) | B23: прямые требования к Правительству и Центральному банку Республики Узбекистан | C23: 0 | D23: 0
A24: б) | B24: Гарантированные кредиты международными кредитными организациями | C24: 0
A25: в) | B25: Активы или их части, обеспеченные ценными бумагами, которые оцененные по текущей рыночной стоимости и выпущенными или гарантированными Правительством Республики Узбекистан, Центральным банком Республики Узбекистан или Правительствами стран с низким уровнем риска. | D25: 0
A26: г) | B26: Кредиты на недвижимость обеспеченные приобретаемым или строящимся домом (квартирой) | C26: 0 | F26: 67067856 | G26: 0
A27: д) | B27: Реструктуризированные кредиты и кредиты в статусе "ненаращивания" | G27: 163131023
A28: е) | B28: Кредиты, по которым банк не имеет приоритетного права на залог | G28: 0
A29: ж) | B29: Пересмотренные или пролонгированные кредиты и лизинги более одного раза
A30: з) | B30: Кредиты, выданные населению для приобретения автомобилей | C30: 0 | H30: =45220+4275+148876+29050707 -> 29249078 | I30: =148791710+9029981+274699 -> 158096390 | J30: 18754
A31: и) | B31: Кредиты, выданные юридическим лицам на покупку автомобиля | C31: 0 | H31: 6893065 | J31: =55513753+241168 -> 55754921
A32: к) | B32: Микрозаймы (все нецелевые кредиты) | C32: 0 | G32: 1260211 | H32: 19925016 | I32: 124195374 | J32: 77293
A33: л) | B33: Все другие кредиты (кроме лизинга) | G33: 4911224416
A34: 12. | B34: Кредиты и лизинги в судебном разбирательстве, чистые | H34: 53908309 | K34: =+'[6]Bank Assets Analysis'!$S$33 -> 53908309
A35: 13. | B35: Просроченные кредиты и лизинги, чистые | H35: 58202411 | K35: =+'[6]Bank Assets Analysis'!$C$31+'[6]Bank Assets Analysis'!$C$30 -> 58202411
A36: 14. | B36: Финансовый лизинг, чистые | G36: 5665027
A37: 15. | B37: Основные средств и другое собственное имущество банка
A38: а | B38: Основные средства, используемые в банковской деятельности (минус амортизация) | G38: 165194315
A39: б | B39: Другое банковское собственное имущество | G39: 0
A40: в | B40: Недвижимое имущество принятое на баланс банка в целях полного или частичного погащения задолженности | H40: 1005589
...

Sheet Calculation of Risk Weighte нац
A1: РАСЧЕТ АКТИВОВ ВЗВЕШЕННЫХ С УЧЕТОМ РИСКА В НАЦИОНАЛЬНОЙ ВАЛЮТЕ | I1: Таблица-6.1
B2: =+'Bank Capital Calc'!B3 -> Наименование банка | G2: =+'Bank Capital Calc'!C3 -> 44196 | J2: тыс. сум
A3: № | B3: Характеристики | C3: 0 | D3: 0.2 | E3: 0.3 | F3: 0.5 | G3: 1 | H3: 1.5 | I3: 2 | J3: 3
C4: Риск | D4: Риск | E4: Риск | F4: Риск | G4: Риск | H4: Риск | I4: Риск | J4: Риск
C5: I группа | D5: II группа | E5: III группа | F5: IV группа | G5: V группа | H5: VI группа | I5: VII группа | J5: VIII группа
B6: (A) | C6: (Б) | D6: (В) | E6: (Г) | F6: (Д) | G6: (Е) | H6: (Ж) | I6: (З) | J6: (И)
B7: Балансовые Активы
A8: 1. | B8: Касса (наличность и монеты) и Драгоценные металлы | C8: 62685950
A9: 2. | B9: Денежная наличность и другие платежные документы в пути | D9: 6194945
A10: 3. | B10: Корреспондентские и резервные счета в ЦБРУ | C10: 0 | D10: 105262662
A11: 4. | B11: Корр. счета, кредиты и другие требования к банкам | H11: 324137587
A12: 5. | B12: Рыночные ценные бумаги, чистые
A13: а) | B13: Ценные бумаги, выпущенные Правительством Республики Узбекистан и ЦБРУ | C13: 135000000
A14: б) | B14: Ценные бумаги, выпущенные правительствами и центральными банками стран, с низким уровня риска, а также другие требования к центральным банкам и правительствам этих стран | C14: 0
A15: в) | B15: Ценные бумаги, выпущенные банками стран, с низким уровнем риска | D15: 0 | F15: 0
A16: г) | B16: Другие ценные бумаги | C16: 0 | G16: 11874000
A17: 6. | B17: Кредиты и другие активы или их части, обеспеченные наличными деньгами, хранящимися на отдельном блокированном депозитном счете. | C17: 0
A18: 7. | B18: Все требования банка, деноминированные в местную валюту стран не входящих в группу стран с низким уровнем риска, к Центральным банкам и центральным правительствам этих стран | D18: 0
A19: 8. | B19: Активы, обеспеченные ценными бумагами выпущенными банками зарегистрированными в странах с низким уровнем риска | D19: 0 | F19: 0
A20: 9. | B20: Требования банка к международным финансовым организациям, а также активы, гарантированные этими организациями | C20: 0
A21: 10. | B21: Активы или их части, обеспеченные залогом в виде ценных бумаг, оцененных по текущей рыночной стоимости и эмитированных международными финансовыми институтами | D21: 0
A22: 11. | B22: Кредиты и лизинги, чистые
A23: а) | B23: прямые требования к Правительству и Центральному банку Республики Узбекистан | C23: 0 | D23: 0
A24: б) | B24: Гарантированные кредиты международными кредитными организациями | C24: 0
A25: в) | B25: Активы или их части, обеспеченные ценными бумагами, которые оцененные по текущей рыночной стоимости и выпущенными или гарантированными Правительством Республики Узбекистан, Центральным банком Республики Узбекистан или Правительствами стран с низким уровнем риска. | D25: 0
A26: г) | B26: Кредиты на недвижимость обеспеченные приобретаемым или строящимся домом (квартирой) | C26: 0 | F26: 67067856 | G26: 0
A27: д) | B27: Реструктуризированные кредиты и кредиты в статусе "ненаращивания" | G27: 153506262
A28: е) | B28: Кредиты, по которым банк не имеет приоритетного права на залог | G28: 0
A29: ж) | B29: Пересмотренные или пролонгированные кредиты и лизинги более одного раза | H29: 0
A30: з) | B30: Кредиты, выданные населению для приобретения автомобилей | H30: =45220+4275+148876+29050707 -> 29249078 | I30: =148791710+9029981+274699 -> 158096390 | J30: 18754
A31: и) | B31: Кредиты, выданные юридическим лицам на покупку автомобиля | H31: 6893065 | J31: =55513753+241168 -> 55754921
A32: к) | B32: Микрозаймы (все нецелевые кредиты) | G32: 1260211 | H32: 19925016 | I32: 124195374 | J32: 77293
A33: л) | B33: Все другие кредиты (кроме лизинга) | G33: 2949202946
A34: 12. | B34: Кредиты и лизинги в судебном разбирательстве, чистые | H34: 44283518 | K34: =+'[6]Bank Assets Analysis (нац)'!$C$33 -> 44283518
A35: 13. | B35: Просроченные кредиты и лизинги, чистые | H35: 17260417 | K35: =+'[6]Bank Assets Analysis (нац)'!$C$30+'[6]Bank Assets Analysis (нац)'!$C$31 -> 17260417
A36: 14. | B36: Финансовый лизинг, чистые | G36: 3343451
A37: 15. | B37: Основные средств и другое собственное имущество банка
A38: а | B38: Основные средства, используемые в банковской деятельности (минус амортизация) | G38: 165194315
A39: б | B39: Другое банковское собственное имущество | G39: 0
A40: в | B40: Недвижимое имущество принятое на баланс банка в целях полного или частичного погащения задолженности | H40: 1005589
...

Sheet Calculation of Risk Weighte ин
A1: РАСЧЕТ АКТИВОВ ВЗВЕШЕННЫХ С УЧЕТОМ РИСКА В ИНОСТРАННОЙ ВАЛЮТЕ | I1: Таблица-6.2
B2: =+'Bank Capital Calc'!B3 -> Наименование банка | G2: =+'Bank Capital Calc'!C3 -> 44196 | J2: тыс. сум
A3: № | B3: Характеристики | C3: 0 | D3: 0.2 | E3: 0.3 | F3: 0.5 | G3: 1 | H3: 1.5 | I3: 2 | J3: 3
C4: Риск | D4: Риск | E4: Риск | F4: Риск | G4: Риск | H4: Риск | I4: Риск | J4: Риск
C5: I группа | D5: II группа | E5: III группа | F5: IV группа | G5: V группа | H5: VI группа | I5: VII группа | J5: VIII группа
B6: (A) | C6: (Б) | D6: (В) | E6: (Г) | F6: (Д) | G6: (Е) | H6: (Ж) | I6: (З) | J6: (И)
B7: Балансовые Активы
A8: 1. | B8: Касса (наличность и монеты) и Драгоценные металлы | C8: =+'Calculation of Risk Weighted As'!C8-'Calculation of Risk Weighte нац'!C8 -> 78075478
A9: 2. | B9: Денежная наличность и другие платежные документы в пути | D9: =+'Calculation of Risk Weighted As'!D9-'Calculation of Risk Weighte нац'!D9 -> 2315981
A10: 3. | B10: Корреспондентские и резервные счета в ЦБРУ | D10: =+'Calculation of Risk Weighted As'!D10-'Calculation of Risk Weighte нац'!D10 -> 0
A11: 4. | B11: Корр. счета, кредиты и другие требования к банкам | D11: =+'Calculation of Risk Weighted As'!D11-'Calculation of Risk Weighte нац'!D11 -> 0 | E11: =+'Calculation of Risk Weighted As'!E11-'Calculation of Risk Weighte нац'!E11 -> 0 | F11: =+'Calculation of Risk Weighted As'!F11-'Calculation of Risk Weighte нац'!F11 -> 0 | G11: =+'Calculation of Risk Weighted As'!G11-'Calculation of Risk Weighte нац'!G11 -> 0 | H11: =+'Calculation of Risk Weighted As'!H11-'Calculation of Risk Weighte нац'!H11 -> 256086918
A12: 5. | B12: Рыночные ценные бумаги, чистые
A13: а) | B13: Ценные бумаги, выпущенные Правительством Республики Узбекистан и ЦБРУ | C13: =+'Calculation of Risk Weighted As'!C13-'Calculation of Risk Weighte нац'!C13 -> 0
A14: б) | B14: Ценные бумаги, выпущенные правительствами и центральными банками стран, с низким уровня риска, а также другие требования к центральным банкам и правительствам этих стран | C14: =+'Calculation of Risk Weighted As'!C14-'Calculation of Risk Weighte нац'!C14 -> 0
A15: в) | B15: Ценные бумаги, выпущенные банками стран, с низким уровнем риска | D15: =+'Calculation of Risk Weighted As'!D15-'Calculation of Risk Weighte нац'!D15 -> 0 | F15: =+'Calculation of Risk Weighted As'!F15-'Calculation of Risk Weighte нац'!F15 -> 0
A16: г) | B16: Другие ценные бумаги | C16: =+'Calculation of Risk Weighted As'!C16-'Calculation of Risk Weighte нац'!C16 -> 0 | G16: =+'Calculation of Risk Weighted As'!G16-'Calculation of Risk Weighte нац'!G16 -> 0
A17: 6. | B17: Кредиты и другие активы или их части, обеспеченные наличными деньгами, хранящимися на отдельном блокированном депозитном счете. | C17: =+'Calculation of Risk Weighted As'!C17-'Calculation of Risk Weighte нац'!C17 -> 0
A18: 7. | B18: Все требования банка, деноминированные в местную валюту стран не входящих в группу стран с низким уровнем риска, к Центральным банкам и центральным правительствам этих стран | D18: =+'Calculation of Risk Weighted As'!D18-'Calculation of Risk Weighte нац'!D18 -> 0
A19: 8. | B19: Активы, обеспеченные ценными бумагами выпущенными банками зарегистрированными в странах с низким уровнем риска | D19: =+'Calculation of Risk Weighted As'!D19-'Calculation of Risk Weighte нац'!D19 -> 0 | F19: =+'Calculation of Risk Weighted As'!F19-'Calculation of Risk Weighte нац'!F19 -> 0
A20: 9. | B20: Требования банка к международным финансовым организациям, а также активы, гарантированные этими организациями | C20: =+'Calculation of Risk Weighted As'!C20-'Calculation of Risk Weighte нац'!C20 -> 0
A21: 10. | B21: Активы или их части, обеспеченные залогом в виде ценных бумаг, оцененных по текущей рыночной стоимости и эмитированных международными финансовыми институтами | D21: =+'Calculation of Risk Weighted As'!D21-'Calculation of Risk Weighte нац'!D21 -> 0
A22: 11. | B22: Кредиты и лизинги, чистые
A23: а) | B23: прямые требования к Правительству и Центральному банку Республики Узбекистан | C23: =+'Calculation of Risk Weighted As'!C23-'Calculation of Risk Weighte нац'!C23 -> 0 | D23: =+'Calculation of Risk Weighted As'!D23-'Calculation of Risk Weighte нац'!D23 -> 0
A24: б) | B24: Гарантированные кредиты международными кредитными организациями | C24: =+'Calculation of Risk Weighted As'!C24-'Calculation of Risk Weighte нац'!C24 -> 0
A25: в) | B25: Активы или их части, обеспеченные ценными бумагами, которые оцененные по текущей рыночной стоимости и выпущенными или гарантированными Правительством Республики Узбекистан, Центральным банком Республики Узбекистан или Правительствами стран с низким уровнем риска. | D25: =+'Calculation of Risk Weighted As'!D25-'Calculation of Risk Weighte нац'!D25 -> 0
A26: г) | B26: Кредиты на недвижимость обеспеченные приобретаемым или строящимся домом (квартирой) | C26: =+'Calculation of Risk Weighted As'!C26-'Calculation of Risk Weighte нац'!C26 -> 0 | F26: =+'Calculation of Risk Weighted As'!F26-'Calculation of Risk Weighte нац'!F26 -> 0 | G26: =+'Calculation of Risk Weighted As'!G26-'Calculation of Risk Weighte нац'!G26 -> 0
A27: д) | B27: Реструктуризированные кредиты и кредиты в статусе "ненаращивания" | G27: =+'Calculation of Risk Weighted As'!G27-'Calculation of Risk Weighte нац'!G27 -> 9624761
A28: е) | B28: Кредиты, по которым банк не имеет приоритетного права на залог | G28: =+'Calculation of Risk Weighted As'!G28-'Calculation of Risk Weighte нац'!G28 -> 0
A29: ж) | B29: Пересмотренные или пролонгированные кредиты и лизинги более одного раза | H29: =+'Calculation of Risk Weighted As'!H29-'Calculation of Risk Weighte нац'!H29 -> 0
A30: з) | B30: Кредиты, выданные населению для приобретения автомобилей | C30: =+'Calculation of Risk Weighted As'!C30-'Calculation of Risk Weighte нац'!C30 -> 0 | G30: =+'Calculation of Risk Weighted As'!G30-'Calculation of Risk Weighte нац'!G30 -> 0 | H30: =+'Calculation of Risk Weighted As'!H30-'Calculation of Risk Weighte нац'!H30 -> 0 | I30: =+'Calculation of Risk Weighted As'!I30-'Calculation of Risk Weighte нац'!I30 -> 0 | J30: =+'Calculation of Risk Weighted As'!J30-'Calculation of Risk Weighte нац'!J30 -> 0
A31: и) | B31: Кредиты, выданные юридическим лицам на покупку автомобиля | C31: =+'Calculation of Risk Weighted As'!C31-'Calculation of Risk Weighte нац'!C31 -> 0 | J31: =+'Calculation of Risk Weighted As'!J31-'Calculation of Risk Weighte нац'!J31 -> 0
A32: к) | B32: Микрозаймы (все нецелевые кредиты) | C32: =+'Calculation of Risk Weighted As'!C32-'Calculation of Risk Weighte нац'!C32 -> 0 | G32: =+'Calculation of Risk Weighted As'!G32-'Calculation of Risk Weighte нац'!G32 -> 0 | H32: =+'Calculation of Risk Weighted As'!H32-'Calculation of Risk Weighte нац'!H32 -> 0 | I32: =+'Calculation of Risk Weighted As'!I32-'Calculation of Risk Weighte нац'!I32 -> 0 | J32: =+'Calculation of Risk Weighted As'!J32-'Calculation of Risk Weighte нац'!J32 -> 0
A33: л) | B33: Все другие кредиты (кроме лизинга) | G33: =+'Calculation of Risk Weighted As'!G33-'Calculation of Risk Weighte нац'!G33 -> 1962021470
A34: 12. | B34: Кредиты и лизинги в судебном разбирательстве, чистые | H34: =+'Calculation of Risk Weighted As'!H34-'Calculation of Risk Weighte нац'!H34 -> 9624791 | J34: =+'Calculation of Risk Weighted As'!J34-'Calculation of Risk Weighte нац'!J34 -> 0 | K34: =+'[6]Bank Assets Analysis'!$U$33 -> 9624791
A35: 13. | B35: Просроченные кредиты и лизинги, чистые | H35: =+'Calculation of Risk Weighted As'!H35-'Calculation of Risk Weighte нац'!H35 -> 40941994 | J35: =+'Calculation of Risk Weighted As'!J35-'Calculation of Risk Weighte нац'!J35 -> 0 | K35: =+'[6]Bank Assets Analysis'!$D$30+'[6]Bank Assets Analysis'!$D$31 -> 40941994
A36: 14. | B36: Финансовый лизинг, чистые | G36: =+'Calculation of Risk Weighted As'!G36-'Calculation of Risk Weighte нац'!G36 -> 2321576
A37: 15. | B37: Основные средств и другое собственное имущество банка
A38: а | B38: Основные средства, используемые в банковской деятельности (минус амортизация) | G38: =+'Calculation of Risk Weighted As'!G38-'Calculation of Risk Weighte нац'!G38 -> 0
A39: б | B39: Другое банковское собственное имущество | G39: =+'Calculation of Risk Weighted As'!G39-'Calculation of Risk Weighte нац'!G39 -> 0
A40: в | B40: Недвижимое имущество принятое на баланс банка в целях полного или частичного погащения задолженности | H40: =+'Calculation of Risk Weighted As'!H40-'Calculation of Risk Weighte нац'!H40 -> 0
...

Sheet Calculation of Risk
A1: РАСЧЕТ ПО ОПЕРАЦИОННЫМ И РЫНОЧНЫМ РИСКАМ
B2: =IF(C3>0," "&TEXT(C3,"д ММММ, гггг"),"Число,Месяц,Год") -> 31 Декабрь, 2020 | C2: Таблица-6А
B3: =+'Bank Capital Calc'!B3 -> Наименование банка | C3: =+'Bank Capital Calc'!C3 -> 44196
A4: № | B4: Наименование показателя | C4: в тыс. сум
A5: 1. | B5: =+"Валовый доход банка за "&(E$7-3)&" год" -> Валовый доход банка за 2017 год | C5: =+C6+C8-C7-C9 -> 215368224
A6: а. | B6: процентные доходы | C6: 222901466
A7: б. | B7: процентные расходы | C7: 146139315 | E7: =RIGHT(B2,4) -> 2020
A8: в. | B8: беспроцентные доходы | C8: 164180943
A9: г. | B9: беспроцентные расходы | C9: 25574870
A10: 2. | B10: =+"Валовый доход банка за "&(E$7-2)&" год" -> Валовый доход банка за 2018 год | C10: =+C11+C13-C12-C14 -> 334481566
A11: а. | B11: процентные доходы | C11: 446360945
A12: б. | B12: процентные расходы | C12: 228795878
A13: в. | B13: беспроцентные доходы | C13: 158773389
A14: г. | B14: беспроцентные расходы | C14: 41856890
A15: 3. | B15: =+"Валовый доход банка за "&(E$7-1)&" год" -> Валовый доход банка за 2019 год | C15: =+C16+C18-C17-C19 -> 442429704
A16: а. | B16: процентные доходы | C16: 721477049
A17: б. | B17: процентные расходы | C17: 403296964
A18: в. | B18: беспроцентные доходы | C18: 216790378
A19: г. | B19: беспроцентные расходы | C19: 92540759
A20: 4. | B20: Средний валовый доход банка (за последние три года) | C20: =(C5+C10+C15)/3 -> 3.3075983e+08
A21: 5. | B21: Сумма операционных рисков | C21: =+(100/C28)*C20*15% -> 3.8164596e+08
A23: 6. | B23: Счета валютной позиции (счет 17101 (сумавая часть)) | C23: 75401050
A24: 7. | B24: Продажа на условиях Своп и Форвард (счет 92709, 92732) | C24: 0
A25: 8. | B25: Покупка на условиях Своп и Форвард (счет 92716, 92736) | C25: 0
A26: 9. | B26: Открытая валютная позиция, всего | C26: =ABS(C23+(C24-C25)) -> 75401050 | D26: =+C26*0.1 -> 7540105
A27: 10. | B27: Сумма рыночных рисков | C27: =+(100/C28)*(C26*10%) -> 58000808
A28: 11. | B28: Действуюший минимальное требование к достаточности капитала | C28: 13
A30: Подпись Председателя правления:
A32: Подпись Главного Бухгалтера:
