Workbook
Name jop: #REF!
Name kol: #REF!
Name RISKTOTASS: SUM('[6]Calculation of Risk Weighted As'!$C$38:$F$38)
Name RISKTOTASS: SUM('[7]Calculation of Risk Weighted As'!$C$41:$G$41)
Name TwentyLargestData: #REF!
Name Е: #REF!

Sheet Asset quality
A1: АКТИВЛАР ТАСНИФИ ВА УЛАР БЎЙИЧА ЯРАТИЛГАН ЭҲТИМОЛИЙ ЙЎҚОТИШЛАРНИ ҚОПЛАШ ЗАХИРАЛАРИ ТЎҒРИСИДА ҲИСОБОТ | S1: 2-жадвал | V1: №1
B3: "Ўзсаноатқурилишибанк" АТБ | Q3: 45289 | T3: минг. сўмда
A4: № | B4: Активлар таркиби* | C4: Қолдиқ | D4: Сифат тоифаси | I4: Муддати ўтган қарздорлик (брутто) | O4: Зарарларни қоплаш захираси
I5: Жами | J5: 30 кунгача | K5: 31дан 90 кунгача | L5: 91дан 180 кунгача | M5: 181 дан 365 кунгача | N5: 366 кун ва ундан ортиқ | O5: ҳақиқатдан яратилган захиралар
O6: Жами | P6: сифат тоифаси бўйича
D7: I | E7: II | F7: III | G7: IV | H7: V | P7: I | Q7: II | R7: III | S7: IV | T7: V
A8: А | B8: Б | C8: В | D8: Г | E8: Д | F8: Е | G8: Ж | H8: З | I8: И | J8: К | K8: Л | L8: М | M8: Н | N8: О | O8: П | P8: Р | Q8: С | R8: Т | S8: У | T8: Ф
B9: Жами активлар | C9: =SUM(C10:C58)+C60-C59 -> 74634423198 | D9: =SUM(D10:D58)-D59+D60 -> 67214176078 | E9: =SUM(E10:E58)-E59+E60 -> 7113099068 | F9: =SUM(F10:F58)-F59+F60 -> 597604434 | G9: =SUM(G10:G58)-G59+G60 -> 922834968 | H9: =SUM(H10:H58)-H59+H60 -> 397013815 | I9: =SUM(I10:I60) -> 1409911974 | J9: =SUM(J10:J60) -> 581272080 | K9: =SUM(K10:K60) -> 370487760 | L9: =SUM(L10:L60) -> 163070980 | M9: =SUM(M10:M60) -> 275815334 | N9: =SUM(N10:N60) -> 19265820 | O9: =SUM(O10:O60) -> 2225477374 | P9: =SUM(P10:P60) -> 615172209 | ... T9: =SUM(T10:T60) -> 304276405
A10: 1 | B10: Кассадаги нақд пул ва бошқа тўлов ҳужжатлари | C10: =SUM(D10:H10)-O10+P10 -> 1565389581 | D10: 1565389581 | E10: 0 | F10: 0 | G10: 0 | H10: 0 | I10: =SUM(J10:N10) -> 0 | O10: =SUM(P10:T10) -> 0 | P10: 0 | Q10: 0 | R10: 0 | S10: 0 | T10: 0 | U10: 10100
A11: 2 | B11: Банкнинг Марказий банкдаги маблағлар | C11: =SUM(D11:H11)-O11+P11 -> 2526034447 | D11: 2526034447 | E11: 0 | F11: 0 | G11: 0 | H11: 0 | I11: =SUM(J11:N11) -> 0 | O11: =SUM(P11:T11) -> 0 | P11: 0 | Q11: 0 | R11: 0 | S11: 0 | T11: 0 | U11: 10300
A12: 3 | B12: Бошқа банклар ва молиявий ташкилотлардан олиниши лозим бўлган маблағлар | C12: =SUM(D12:H12)-O12+P12 -> 5562959410 | D12: 5562959410 | E12: 0 | F12: 0 | G12: 0 | H12: 37257367 | I12: =SUM(J12:N12) -> 0 | O12: =SUM(P12:T12) -> 92886961 | P12: 55629594 | Q12: 0 | R12: 0 | S12: 0 | T12: 37257367 | U12: 10500
A13: 4 | B13: Фойда ёки зарар орқали ҳаққоний қийматда баҳоланадиган қимматли қоғозлар | C13: =SUM(D13:H13)-O13+P13 -> 2033306103 | D13: 2033306103 | E13: 0 | F13: 0 | G13: 0 | H13: 0 | I13: =SUM(J13:N13) -> 0 | O13: =SUM(P13:T13) -> 0 | P13: 0 | Q13: 0 | R13: 0 | S13: 0 | T13: 0 | U13: 10700
A14: 5 | B14: Бошқа умумлашган даромад орқали ҳаққоний қийматда баҳоланадиган қимматли қоғозларга қилинган инвестициялар | C14: =SUM(D14:H14)-O14+P14 -> 10000000 | D14: 10000000 | E14: 0 | F14: 0 | G14: 0 | H14: 0 | I14: =SUM(J14:N14) -> 0 | O14: =SUM(P14:T14) -> 0 | P14: 0 | Q14: 0 | R14: 0 | S14: 0 | T14: 0 | U14: 10800
A15: 6 | B15: Олди-сотдига мўлжалланган қимматбаҳо металлар, тошлар ва тангалар | C15: =SUM(D15:H15)-O15+P15 -> 875 | D15: 875 | E15: 0 | F15: 0 | G15: 0 | H15: 0 | I15: =SUM(J15:N15) -> 0 | O15: =SUM(P15:T15) -> 9 | P15: 9 | Q15: 0 | R15: 0 | S15: 0 | T15: 0 | U15: 10900
A16: 7 | B16: Сотиб олинган дебиторлик қарзлари — Факторинг | C16: =SUM(D16:H16)-O16+P16 -> 98000001 | D16: 98000001 | E16: 0 | F16: 0 | G16: 0 | H16: 0 | I16: =SUM(J16:N16) -> 0 | O16: =SUM(P16:T16) -> 980000 | P16: 980000 | Q16: 0 | R16: 0 | S16: 0 | T16: 0 | U16: 11100
A17: 8 | B17: Мижозларнинг аккредитив ва/ёки траст ҳужжатлари билан кафолатланган тратталари бўйича мажбуриятлари | C17: =SUM(D17:H17)-O17+P17 -> 81572337 | D17: 0 | E17: 0 | F17: 0 | G17: 0 | H17: 110235813 | I17: =SUM(J17:N17) -> 0 | O17: =SUM(P17:T17) -> 28663476 | P17: 0 | Q17: 0 | R17: 0 | S17: 0 | T17: 28663476 | U17: 11500
A18: 9 | B18: Банкнинг тўланмаган акцептлари бўйича мижозларнинг мажбуриятлари | C18: =SUM(D18:H18)-O18+P18 -> 0 | D18: 0 | E18: 0 | F18: 0 | G18: 0 | H18: 0 | I18: =SUM(J18:N18) -> 0 | O18: =SUM(P18:T18) -> 0 | P18: 0 | Q18: 0 | R18: 0 | S18: 0 | T18: 0 | U18: 11700
A19: 10 | B19: РЕПО битимлари бўйича сотиб олинган қимматли қоғозлар | C19: =SUM(D19:H19)-O19+P19 -> 0 | D19: 0 | E19: 0 | F19: 0 | G19: 0 | H19: 0 | I19: =SUM(J19:N19) -> 0 | O19: =SUM(P19:T19) -> 0 | P19: 0 | Q19: 0 | R19: 0 | S19: 0 | T19: 0 | U19: 11800
A20: 11 | B20: Марказий банкка берилган қисқа муддатли кредитлар | C20: =SUM(D20:H20)-O20+P20 -> 0 | D20: 0 | E20: 0 | F20: 0 | G20: 0 | H20: 0 | I20: =SUM(J20:N20) -> 0 | O20: =SUM(P20:T20) -> 0 | P20: 0 | Q20: 0 | R20: 0 | S20: 0 | T20: 0 | U20: 11900
A21: 12 | B21: Бошқа банкларга берилган қисқа муддатли кредитлар | C21: =SUM(D21:H21)-O21+P21 -> 0 | D21: 0 | E21: 0 | F21: 0 | G21: 0 | H21: 0 | I21: =SUM(J21:N21) -> 0 | O21: =SUM(P21:T21) -> 0 | P21: 0 | Q21: 0 | R21: 0 | S21: 0 | T21: 0 | U21: 12100
A22: 13 | B22: Ҳукуматга берилган қисқа муддатли кредитлар | C22: =SUM(D22:H22)-O22+P22 -> 0 | D22: 0 | E22: 0 | F22: 0 | G22: 0 | H22: 0 | I22: =SUM(J22:N22) -> 0 | O22: =SUM(P22:T22) -> 0 | P22: 0 | Q22: 0 | R22: 0 | S22: 0 | T22: 0 | U22: 12300
A23: 14 | B23: Бюджет ташкилотларига берилган қисқа муддатли кредитлар | C23: =SUM(D23:H23)-O23+P23 -> 0 | D23: 0 | E23: 0 | F23: 0 | G23: 0 | H23: 0 | I23: =SUM(J23:N23) -> 0 | O23: =SUM(P23:T23) -> 0 | P23: 0 | Q23: 0 | R23: 0 | S23: 0 | T23: 0 | U23: 12400
A24: 15 | B24: Жисмоний шахсларга берилган қисқа муддатли кредитлар | C24: =SUM(D24:H24)-O24+P24 -> 148925943 | D24: 147739621 | E24: 948395 | F24: 311797 | G24: 197836 | H24: 0 | I24: =SUM(J24:N24) -> 976239 | J24: 326455 | K24: 328035 | L24: 235604 | M24: 86145 | N24: 0 | O24: =SUM(P24:T24) -> 1749102 | P24: 1477396 | Q24: 94839 | R24: 77949 | S24: 98918 | T24: 0 | U24: 12500
A25: 16 | B25: Якка тартибдаги тадбиркорларга берилган қисқа муддатли кредитлар | C25: =SUM(D25:H25)-O25+P25 -> 20304028 | D25: 16905572 | E25: 1640587 | F25: 1094056 | G25: 2354312 | H25: 0 | I25: =SUM(J25:N25) -> 4796166 | J25: 653717 | K25: 999727 | L25: 788410 | M25: 2354312 | N25: 0 | O25: =SUM(P25:T25) -> 1859555 | P25: 169056 | Q25: 239828 | R25: 273514 | S25: 1177157 | T25: 0 | U25: 12600
A26: 17 | B26: Давлат корхоналари, ташкилотлари ва муассасаларига берилган қисқа муддатли кредитлар | C26: =SUM(D26:H26)-O26+P26 -> 3986468558 | D26: 3982421725 | E26: 4496481 | F26: 0 | G26: 0 | H26: 0 | I26: =SUM(J26:N26) -> 78885468 | J26: 78885468 | K26: 0 | L26: 0 | M26: 0 | N26: 0 | O26: =SUM(P26:T26) -> 40273865 | P26: 39824217 | Q26: 449648 | R26: 0 | S26: 0 | T26: 0 | U26: 12700
A27: 18 | B27: Тадбиркорлик фаолиятини қўллаб-қувватлаш давлат жамғармаси кўмагида берилган қисқа муддатли кредитлар | C27: =SUM(D27:H27)-O27+P27 -> 149038227 | D27: 137248835 | E27: 7526650 | F27: 0 | G27: 10030814 | H27: 0 | I27: =SUM(J27:N27) -> 10030814 | J27: 0 | K27: 0 | L27: 10030814 | M27: 0 | N27: 0 | O27: =SUM(P27:T27) -> 7140560 | P27: 1372488 | Q27: 3446107 | R27: 0 | S27: 1321965 | T27: 1000000 | U27: 12800
A28: 19 | B28: Чет эл капитали иштирокидаги корхоналарга берилган қисқа муддатли кредитлар | C28: =SUM(D28:H28)-O28+P28 -> 2217667706 | D28: 2213334426 | E28: 2603856 | F28: 810756 | G28: 2763487 | H28: 0 | I28: =SUM(J28:N28) -> 6384711 | J28: 1666667 | K28: 1399356 | L28: 555201 | M28: 2763487 | N28: 0 | O28: =SUM(P28:T28) -> 23978163 | P28: 22133344 | Q28: 260386 | R28: 202689 | S28: 1381744 | T28: 0 | U28: 12900
A29: 20 | B29: Нодавлат нотижорат ташкилотларига берилган қисқа муддатли кредитлар | C29: =SUM(D29:H29)-O29+P29 -> 13281 | D29: 13281 | E29: 0 | F29: 0 | G29: 0 | H29: 0 | I29: =SUM(J29:N29) -> 0 | J29: 0 | K29: 0 | L29: 0 | M29: 0 | N29: 0 | O29: =SUM(P29:T29) -> 133 | P29: 133 | Q29: 0 | R29: 0 | S29: 0 | T29: 0 | U29: 13000
A30: 21 | B30: Хусусий корхоналар, хўжалик ширкатлари ва жамиятларга берилган қисқа муддатли кредитлар | C30: =SUM(D30:H30)-O30+P30 -> 4935705825 | D30: 4619358133 | E30: 271591493 | F30: 48922451 | G30: 84946828 | H30: 350000 | I30: =SUM(J30:N30) -> 175785316 | J30: 23386912 | K30: 23683229 | L30: 43418347 | M30: 84946828 | N30: 350000 | O30: =SUM(P30:T30) -> 135656661 | P30: 46193581 | Q30: 30305809 | R30: 10835797 | S30: 47971474 | T30: 350000 | U30: 13100
A31: 22 | B31: Банк бўлмаган молиявий муассасаларга берилган қисқа муддатли кредитлар | C31: =SUM(D31:H31)-O31+P31 -> 118872 | D31: 118872 | E31: 0 | F31: 0 | G31: 0 | H31: 0 | I31: =SUM(J31:N31) -> 0 | J31: 0 | K31: 0 | L31: 0 | M31: 0 | N31: 0 | O31: =SUM(P31:T31) -> 1189 | P31: 1189 | Q31: 0 | R31: 0 | S31: 0 | T31: 0 | U31: 13200
A32: 23 | B32: Давлат эҳтиёжлари учун харид қилинадиган қишлоқ хўжалиги маҳсулотларини етиштириш учун берилган қисқа муддатли кредитлар | C32: =SUM(D32:H32)-O32+P32 -> 95979403 | D32: 95979403 | E32: 0 | F32: 0 | G32: 0 | H32: 0 | I32: =SUM(J32:N32) -> 0 | J32: 0 | K32: 0 | L32: 0 | M32: 0 | N32: 0 | O32: =SUM(P32:T32) -> 959794 | P32: 959794 | Q32: 0 | R32: 0 | S32: 0 | T32: 0 | U32: 13300
A33: 24 | B33: Давлат эҳтиёжлари учун харид қилинадиган қишлоқ хўжалиги маҳсулотларини етиштириш учун берилган узоқ муддатли кредитлар | C33: =SUM(D33:H33)-O33+P33 -> 1649230335 | D33: 775268383 | E33: 857553659 | F33: 80406648 | G33: 0 | H33: 0 | I33: =SUM(J33:N33) -> 224002222 | J33: 37479137 | K33: 186523085 | L33: 0 | M33: 0 | N33: 0 | O33: =SUM(P33:T33) -> 71751039 | P33: 7752684 | Q33: 43896693 | R33: 20101662 | S33: 0 | T33: 0 | U33: 14300
A34: 25 | B34: Тадбиркорлик фаолиятини қўллаб-қувватлаш давлат жамғармаси кўмагида берилган узоқ муддатли кредитлар | C34: =SUM(D34:H34)-O34+P34 -> 2855036998 | D34: 2045555885 | E34: 572712398 | F34: 147830825 | G34: 344420946 | H34: 16339332 | I34: =SUM(J34:N34) -> 190499105 | J34: 23239708 | K34: 43385102 | L34: 23052318 | M34: 94176217 | N34: 6645760 | O34: =SUM(P34:T34) -> 292277947 | P34: 20455559 | Q34: 46314877 | R34: 36957706 | S34: 172210473 | T34: 16339332 | U34: 14400
A35: 26 | B35: Бошқа банкларга берилган узоқ муддатли кредитлар | C35: =SUM(D35:H35)-O35+P35 -> 0 | D35: 0 | E35: 0 | F35: 0 | G35: 0 | H35: 0 | I35: =SUM(J35:N35) -> 0 | J35: 0 | K35: 0 | L35: 0 | M35: 0 | N35: 0 | O35: =SUM(P35:T35) -> 0 | P35: 0 | Q35: 0 | R35: 0 | S35: 0 | T35: 0 | U35: 14500
... A44: 35 | B44: Хусусий корхоналар, хўжалик ширкатлари ва жамиятларга берилган узоқ муддатли кредитлар | C44: =SUM(D44:H44)-O44+P44 -> 15090322433 | D44: 12646944183 | E44: 2525588929 | F44: 187367280 | G44: 135482702 | H44: 10550000 | I44: =SUM(J44:N44) -> 157068960 | J44: 33790306 | K44: 31195159 | L44: 52427466 | M44: 33656029 | N44: 6000000 | O44: =SUM(P44:T44) -> 542080103 | P44: 126469442 | Q44: 283030583 | R44: 48236636 | S44: 65936734 | T44: 18406708 | U44: 15500
A45: 36 | B45: Лизинг (молиявий ижара) | C45: =SUM(D45:H45)-O45+P45 -> 401306653 | D45: 401306653 | E45: 0 | F45: 0 | G45: 0 | H45: 0 | I45: =SUM(J45:N45) -> 0 | O45: =SUM(P45:T45) -> 4013067 | P45: 4013067 | Q45: 0 | R45: 0 | S45: 0 | T45: 0 | U45: 15600
A46: 37 | B46: Суд ёки ижро иши юритиш жараёнидаги кредитлар ва лизинг | C46: =SUM(D46:H46)-O46+P46 -> 83375035 | D46: 0 | E46: 0 | F46: 12579961 | G46: 145307500 | H46: 0 | I46: =SUM(J46:N46) -> 0 | O46: =SUM(P46:T46) -> 74512426 | P46: 0 | Q46: 7570393 | R46: 3144991 | S46: 72653750 | T46: -8856708 | U46: 15700
A47: 38 | B47: Қарам хўжалик жамиятларига, биргаликдаги корхоналарга ва шўъба хўжалик жамиятларига қилинган инвестициялар | C47: =SUM(D47:H47)-O47+P47 -> 406437548 | D47: 402687552 | E47: 0 | F47: 0 | G47: 7499992 | H47: 3205644 | I47: =SUM(J47:N47) -> 0 | O47: =SUM(P47:T47) -> 10982516 | P47: 4026876 | Q47: 0 | R47: 0 | S47: 3749996 | T47: 3205644 | U47: 15800
A48: 39 | B48: Амортизацияланган қиймати бўйича баҳоланадиган қарз қимматли қоғозларга қилинган инвестициялар | C48: =SUM(D48:H48)-O48+P48 -> 0 | D48: 0 | E48: 0 | F48: 0 | G48: 0 | H48: 0 | I48: =SUM(J48:N48) -> 0 | O48: =SUM(P48:T48) -> 0 | P48: 0 | Q48: 0 | R48: 0 | S48: 0 | T48: 0 | U48: 15900
A49: 40 | B49: Олиниши лозим бўлган ҳисобланган фоизлар | C49: =SUM(D49:H49)-O49+P49 -> 2735021105 | D49: 1929213128 | E49: 779730245 | F49: 66596339 | G49: 123673175 | H49: 9008305 | I49: =SUM(J49:N49) -> 418757540 | J49: ='Aging Analysis'!M22 -> 287015394 | K49: ='Aging Analysis'!O22+'Aging Analysis'!Q22 -> 41476817 | L49: ='Aging Analysis'!S22 -> 28533994 | M49: ='Aging Analysis'!U22 -> 55461275 | N49: ='Aging Analysis'!W22+'Aging Analysis'!Y22 -> 6270060 | O49: =SUM(P49:T49) -> 192492218 | P49: 19292131 | Q49: 173200087 | R49: 0 | S49: 0 | T49: 0 | U49: 16300
...

Sheet Income 
A1: МОЛИЯВИЙ НАТИЖАЛАР ТЎҒРИСИДА ҲИСОБОТ | E1: 3-жадвал
B3: =+'Asset quality'!B3 -> "Ўзсаноатқурилишибанк" АТБ | D3: =+'Asset quality'!Q3 -> 45289 | E3: =+'Asset quality'!T3 -> минг. сўмда
A4: № | B4: Кўрсаткичлар | C4: Жами | D4: миллий валютада | E4: хорижий валютада (экв. сўмда)
A5: 1. | B5: ФОИЗЛИ ДАРОМАДЛАР
A6: a. | B6: Марказий банкдаги ҳисобварақлар бўйича фоизли даромадлар | C6: =+D6+E6 -> 13993151 | D6: 13993151 | E6: 0 | G6: =+'Analysis of Interest'!C17 -> 13993151
A7: б. | B7: Бошқа банклардаги ҳисобварақлар бўйича фоизли даромадлар | C7: =+D7+E7 -> 472306870 | D7: 55384248 | E7: 416922622 | G7: =+'Analysis of Interest'!C18 -> 472306870
A8: в. | B8: Амортизацияланган қиймати бўйича баҳоланадиган қарз қимматли қоғозларга қилинган инвестициялар бўйича фоизли даромадлар | C8: =+D8+E8 -> 626507 | D8: 626507 | E8: 0
A9: г. | B9: Қимматли қоғозлар ва уларга қилинган инвестициялар бўйича фоизли даромадлар | C9: =+D9+E9 -> 398059254 | D9: 387708461 | E9: 10350793 | G9: =+'Analysis of Interest'!C28 -> 398059254
A10: д. | B10: Мижозларнинг мажбуриятлари бўйича ҳисобланган фоизлар | C10: =+D10+E10 -> 0 | D10: 0 | E10: 0
A11: е. | B11: Банкнинг тўланмаган акцептлари юзасидан мижозлар мажбуриятлари бўйича фоизли даромадлар | C11: =+D11+E11 -> 0 | D11: 0 | E11: 0
A12: ж. | B12: Кредит ва лизинг операциялари бўйича фоизлар, дисконтлар (чегирмалар) ва бадаллар | C12: =+D12+E12 -> 6278755813 | D12: 3433027405 | E12: 2845728408 | G12: =+'Analysis of Interest'!C14 -> 6278755813
A13: з. | B13: Қимматли қоғозлар билан амалга оширилган РЕПО битимлари бўйича фоизли даромадлар | C13: =+D13+E13 -> 2784649 | D13: 2784649 | E13: 0 | G13: =+'Analysis of Interest'!C39 -> 2784649
A14: и. | B14: Бошқа фоизли даромадлар | C14: =+D14+E14 -> 13335904 | D14: 13335904 | E14: 0 | G14: =+'Analysis of Interest'!C40 -> 13335904
A15: к. | B15: Жами фоизли даромадлар | C15: =SUM(C6:C14) -> 7179862148 | D15: =SUM(D6:D14) -> 3906860325 | E15: =SUM(E6:E14) -> 3273001823 | G15: =+'Analysis of Interest'!C42 -> 7179862148
A17: 2. | B17: ФОИЗЛИ ХAРAЖAТЛAР
A18: а. | B18: Талаб қилиб олингунча сақланадиган депозитлар бўйича фоизли харажатлар | C18: =+D18+E18 -> 15186418 | D18: 12113448 | E18: 3072970 | G18: =+'Analysis of Interest'!C52 -> 15186418
A19: б. | B19: Муддатли депозитлар бўйича фоизли харажатлар | C19: =+D19+E19 -> 1125844088 | D19: 994421587 | E19: 131422501 | G19: =+'Analysis of Interest'!C61 -> 1125844088
A20: в. | B20: Марказий банкнинг ҳисобварақлари бўйича фоизли харажатлар | C20: =+D20+E20 -> 0 | D20: 0 | E20: 0
A21: г. | B21: Бошқа банкларнинг ҳисобварақлари бўйича фоизли харажатлар | C21: =+D21+E21 -> 562077232 | D21: 319166644 | E21: 242910588
A22: д. | B22: Жами депозитлар бўйича фоизли харажатлар | C22: =SUM(C18:C21) -> 1703107738 | D22: =SUM(D18:D21) -> 1325701679 | E22: =SUM(E18:E21) -> 377406059
A23: е. | B23: Кредитлар бўйича фоизли харажатлар | C23: =+D23+E23 -> 2153234424 | D23: 564507134 | E23: 1588727290 | G23: =+'Analysis of Interest'!C67 -> 2153234424
A24: ж. | B24: Қимматли қоғозлар билан амалга оширилган РЕПО битимлари бўйича фоизли харажатлар | C24: =+D24+E24 -> 24948798 | D24: 24948798 | E24: 0 | G24: =+'Analysis of Interest'!C68 -> 24948798
A25: з. | B25: Бошқа фоизли харажатлар | C25: =+D25+E25 -> 316609174 | D25: 35242946 | E25: 281366228
A26: и. | B26: Жами кредит ва бошқа қарздорликлар бўйича фоизли харажатлар | C26: =SUM(C23:C25) -> 2494792396 | D26: =SUM(D23:D25) -> 624698878 | E26: =SUM(E23:E25) -> 1870093518
A27: к. | B27: Жами фоизли харажатлар | C27: =C26+C22 -> 4197900134 | D27: =D26+D22 -> 1950400557 | E27: =E26+E22 -> 2247499577 | G27: =+'Analysis of Interest'!C72 -> 4197900134
A29: 3. | B29: Активлар бўйича эҳтимолий йўқотишларга қарши яратилган захираларни баҳолашдан олдинги соф даромад | C29: =C15-C27 -> 2981962014 | D29: =D15-D27 -> 1956459768 | E29: =E15-E27 -> 1025502246
A30: а. | B30: Минус: Кредит ва лизинглар бўйича кўрилиши мумкин бўлган зарарларни баҳолаш | C30: =+D30+E30 -> 1676463088 | D30: 683983511 | E30: 992479577
A31: б. | B31: Минус: Қимматли қоғозлар бўйича кўрилиши мумкин бўлган зарарларни баҳолаш | C31: =+D31+E31 -> 0 | D31: 0 | E31: 0
A32: в. | B32: Минус: Инвестициялар бўйича кўрилиши мумкин бўлган зарарларни баҳолаш | C32: =+D32+E32 -> 1874998 | D32: 1874998 | E32: 0
A33: г. | B33: Минус: Бошқа активлар бўйича кўрилиши мумкин бўлган зарарларни баҳолаш | C33: =+D33+E33 -> 593274940 | D33: 400638979 | E33: 192635961
A34: д. | B34: Активлар бўйича эҳтимолий зарарларни баҳолашдан кейинги соф даромад | C34: =C29-C30-C31-C32-C33 -> 710348988 | D34: =D29-D30-D31-D32-D33 -> 869962280 | E34: =E29-E30-E31-E32-E33 -> -159613292
A36: 4. | B36: ФОИЗСИЗ ДАРОМАДЛАР
A37: а. | B37: Кўрсатилган хизматлар ва воситачилик учун олинган даромадлар | C37: =+D37+E37 -> 531777445 | D37: 441030394 | E37: 90747051
A38: б. | B38: Хорижий валюталардаги фойда | C38: =+D38+E38 -> 2075380431 | D38: 267053605 | E38: 1808326826
A39: в. | B39: Тижорат операцияларидан олинган фойда | C39: =+D39+E39 -> 0 | D39: 0 | E39: 0
A40: г. | B40: Инвестициядан олинган фойда ва дивидендлар | C40: =+D40+E40 -> 22179591 | D40: 21922751 | E40: 256840
A41: д. | B41: Активлар бўйича эҳтимолий йўқотишларга қарши яратилган захираларни қайтарилиши | C41: =+D41+E41 -> 115507327 | D41: 102698261 | E41: 12809066
A42: е. | B42: Ҳисобдан чиқарилган кредитлар қайтарилиши билан боғлиқ даромадлар | C42: =+D42+E42 -> 932350041 | D42: 280356779 | E42: 651993262
A43: ж. | B43: Бошқа фоизсиз даромадлар | C43: =+D43+E43 -> 214544073 | D43: 190803609 | E43: 23740464
A44: е. | B44: Жами фоизсиз даромадлар | C44: =SUM(C37:C43) -> 3891738908 | D44: =SUM(D37:D43) -> 1303865399 | E44: =SUM(E37:E43) -> 2587873509
...

Sheet Analysis of Interest
B1: ФОИЗЛИ ДАРОМАД ВА ХАРАЖАТЛАР ТАҲЛИЛИ | C1: 4-жадвал
B3: =+'Asset quality'!B3 -> "Ўзсаноатқурилишибанк" АТБ | C3: =+'Asset quality'!Q3 -> 45289
A4: № | B4: Кўрсаткичлар | C4: =+'Asset quality'!T3 -> минг. сўмда
A5: 1. | B5: КРЕДИТ ВА ЛИЗИНГ ОПЕРАЦИЯЛАРИ БЎЙИЧА ФОИЗЛИ ДАРОМАДЛАР
A6: a. | B6: Марказий банкка берилган қисқа муддатли кредитлар | C6: 0
A7: б. | B7: Бошқа банкларга берилган кредитлар | C7: 0
A8: в. | B8: Ҳукуматга берилган кредитлар | C8: 16027206
A9: г. | B9: Жисмоний шахсларга берилган кредит ва лизинглар | C9: 1249916675
A10: д. | B10: Давлат корхоналарига берилган кредит ва лизинглар | C10: 1161079360
A11: е. | B11: Қўшма ва чет эл капитали иштирокидаги корхоналарга берилган кредит ва лизинглар | C11: 1166410537
A12: ж. | B12: Хусусий корхоналар, хўжалик ширкатлари ва жамиятларга берилган кредит ва лизинглар | C12: 2570519222
A13: з. | B13: Бошқа кредит ва лизинглар | C13: 114802813
A14: и. | B14: Жами кредит ва лизинг операциялари бўйича фоизли даромад | C14: =SUM(C6:C13) -> 6278755813 | E14: =+'Income '!C12 -> 6278755813
A16: 2. | B16: ВАКИЛЛИК ҲИСОБВАРАҚЛАРИ БЎЙИЧА ФОИЗЛИ ДАРОМАДЛАР
A17: a. | B17: Марказий банкдаги ҳисобварақлар бўйича фоизли даромадлар | C17: 13993151 | E17: =+'Income '!C6 -> 13993151
A18: б. | B18: Бошқа банклардаги ҳисобварақлар бўйича фоизли даромадлар | C18: 472306870 | E18: =+'Income '!C7 -> 472306870
B19: Жами вакиллик ҳисобварағи бўйича фоизли даромадлар | C19: =SUM(C17:C18) -> 486300021
A21: 3. | B21: ҚИММАТЛИ ҚОҒОЗЛАР ВА УЛАРГА ҚИЛИНГАН ИНВЕСТИЦИЯЛАР БЎЙИЧА ФОИЗЛИ ДАРОМАДЛАР
A22: a. | B22: Давлат қимматли қоғозлари | C22: 360316265
A23: б. | B23: Марказий банкнинг облигациялари ва бошқа қимматли қоғозлари | C23: 37508742
A24: в. | B24: Давлат корхоналарининг қарз қимматли қоғозлари бўйича фоизли даромадлар | C24: 234247
A25: г. | B25: Еврооблигациялар бўйича фоизли даромадлар | C25: 0
A26: д. | B26: Хусусий корхоналарнинг қимматли қоғозлари | C26: 0
A27: е. | B27: Бошқа қимматли қоғозлар | C27: 0
A28: ж. | B28: Жами олди-сотди қимматли қоғозлар бўйича фоизли даромадлар | C28: =SUM(C22:C27) -> 398059254 | E28: =+'Income '!C9 -> 398059254
A30: 4. | B30: ИНВЕСТИЦИЯЛАР БЎЙИЧА ФОИЗЛИ ДАРОМАДЛАР
A31: a. | B31: Давлат қимматли қоғозлари | C31: 0
A32: б. | B32: Марказий банкнинг облигациялари ва бошқа қарз қимматли қоғозларига қилинган инвестициялар бўйича фоизли даромадлар | C32: 0
A33: в. | B33: Корхоналарнинг қарз қимматли қоғозларига қилинган инвестициялар бўйича фоизли даромадлар | C33: 626507
A34: г. | B34: Еврооблигациялар | C34: 0
A35: д. | B35: Бошқа қимматли қоғозлар | C35: 0
A36: е. | B36: Жами инвестициялар бўйича фоизли даромадлар | C36: =SUM(C31:C35) -> 626507
A38: 5. | B38: БОШҚА ФОИЗЛИ ДАРОМАДЛАР
A39: a. | B39: Қимматли қоғозлар билан амалга оширилган репо битимлари бўйича фоизли даромадлар | C39: 2784649
A40: б. | B40: Бошқа фоизли даромадлар | C40: 13335904 | E40: =+'Income '!C14 -> 13335904
A42: 6. | B42: ЖАМИ ФОИЗЛИ ДАРОМАДЛАР | C42: =C14+C19+C28+C36+C39+C40 -> 7179862148 | E42: =+'Income '!C15 -> 7179862148
A44: 7. | B44: ДЕПОЗИТЛАР БЎЙИЧА ФОИЗЛИ ХАРАЖАТЛАР
A45: A. | B45: Талаб қилиб олингунча сақланадиган депозитлар
A46: a. | B46: Ҳукумат | C46: 7516492
A47: б. | B47: Жисмоний шахслар | C47: 1
...

Sheet Changes in Equity
A1: ХУСУСИЙ КАПИТАЛДАГИ ЎЗГАРИШЛАР | C1: 7-жадвал
B3: =+'Asset quality'!B3 -> "Ўзсаноатқурилишибанк" АТБ | C3: =+'Asset quality'!Q3 -> 45289
A4: № | B4: Кўрсаткичлар | C4: =+'Asset quality'!T3 -> минг. сўмда
A5: 1. | B5: Ўтган йил учун дастлабки ҳисобланган умумий капитал | C5: 7828121193
A6: 2. | B6: Хусусий капиталдаги ўтган йил учун ҳисоботларда кўрсатилмаган тузатишлар, (соф) | C6: 0
A7: 3. | B7: Ўтган календар йили якуни бўйича балансдаги тузатишлар (3=1-2 ) | C7: =SUM(C5:C6) -> 7828121193
A8: 4. | B8: Йил бошидан соф фойда (зарар) | C8: =+'Income '!C77 -> 911684119 | D8: =+[8]Balance!$C$76 -> 911684119 | E8: =+C8-D8 -> 0
A9: 5. | B9: Жорий йилда сотиш, айирбошлаш, сотиб олиш ёки қайтиб сотиб олиш (соф кирим) | C9: -5571976
A10: 6. | B10: Жорий йил учун бошланғич қийматига нисбатан баҳолаш қийматининг ошган суммаси | C10: -1425151
A11: 7. | B11: МИНУС: Имтиёзли акциялар бўйича эълон қилинган пул дивидендлари | C11: 1616900
A12: 8. | B12: МИНУС: Оддий акциялар бўйича эълон қилинган пуллик дивидендлар
A13: 9. | B13: Жорий йилнинг соф хусусий капиталига таъсир этувчи бошқа моддалар | C13: -2831133
A14: 10. | B14: Жорий давр якуни бўйича жами хусусий капитал | C14: =C7+SUM(C8:C10)-SUM(C11:C12)+C13 -> 8728360152 | D14: =+[8]Balance!$C$77 -> 8728360152 | E14: =+C14-D14 -> 0
B16: Бошқарув Раис имзоси:
B18: Бош бухгалтер имзоси:

Sheet Loans Receivable
A1: ИҚТИСОДИЁТ ТАРМОҚЛАРИ, МИЖОЗЛАР ТУРЛАРИ, ВА ТАЪМИНОТ ТУРЛАРИ БЎЙИЧА АЖРАТИЛГАН КРЕДИТЛАР ВА ЛИЗИНГЛАР ҲИСОБОТИ | W1: 8-жадвал
B3: =+'Asset quality'!B3 -> "Ўзсаноатқурилишибанк" АТБ | T3: =+'Asset quality'!Q3 -> 45289 | X3: =+'Asset quality'!T3 -> минг. сўмда
A4: № | B4: Иқтисодиёт тармоқлари бўйича | C4: Кредит суммаси | D4: шундан | F4: шундан муаммоли кредитлар | J4: шундан
D5: миллий валютада | E5: хорижий валютада (экв. сўмда) | F5: NPL | G5: шундан | J5: Депозитлар | K5: Ўзбекистон Республикаси Ҳукумати тамонидан кафолатланган кредитлар | L5: шундан | M5: Транспорт воситалари | N5: Инвентарлар | O5: Кўчмас мулк | P5: шундан | R5: Асбоб ускуналар | S5: Векселлар (облигациялар) | T5: Акциялар | U5: Учинчи шахс кафолати | V5: Учинчи шахс кафиллиги | W5: Суғурта полиси | X5: Таъминотсиз | Y5: Бошқа кафолатлар
G6: Қониқарсиз | H6: Шубҳали | I6: Умидсиз | L6: Ўзбекистон Республикаси Ҳукумати томонидан кафолатланган хорижий валютадаги (эквивалент сўмда) кредитлар | P6: турар жой (хонадон) | Q6: тижорат кўчмас мулки
A7: Код | B7: (А) | C7: (Б) | D7: (Б1) | E7: (Б3) | F7: (В) | G7: (В1) | H7: (В2) | I7: (В3) | J7: (Г) | K7: (Д) | L7: (Д1) | M7: (Е) | N7: (Ж) | O7: (З) | P7: (З1) | Q7: (З2) | R7: (И) | S7: (К) | T7: (Л) | U7: (М) | V7: (Н) | W7: (О) | X7: (П) | Y7: (Р)
B8: Саноат
A9: 10 | B9: Давлат корхоналари | C9: =SUM(J9:Y9)-L9-P9-Q9 -> 9043576442 | D9: 2394277397 | E9: 6649299045 | F9: =+G9+H9+I9 -> 0 | G9: 0 | H9: 0 | I9: 0 | J9: 0 | K9: 4785668881 | L9: 4245386620 | M9: 0 | N9: 377148300 | O9: =+P9+Q9 -> 347845253 | P9: 0 | Q9: 347845253 | R9: 561819579 | S9: 0 | T9: 127632450 | U9: 0 | V9: 1470039773 | W9: 0 | X9: 0 | Y9: 1373422206
A10: =A9+10 -> 20 | B10: Қўшма ва чет эл капитали иштирокидаги корхоналар | C10: =SUM(J10:Y10)-L10-P10-Q10 -> 8066997417 | D10: 435809228 | E10: 7631188189 | F10: =+G10+H10+I10 -> 56216040 | G10: 0 | H10: 46247548 | I10: 9968492 | J10: 1233877 | K10: 0 | L10: 0 | M10: 4844791 | N10: 145131391 | O10: =+P10+Q10 -> 2029463925 | P10: 0 | Q10: 2029463925 | R10: 2661030818 | S10: 0 | T10: 0 | U10: 0 | V10: 1790251356 | W10: 340906107 | X10: 0 | Y10: 1094135152
A11: =A10+10 -> 30 | B11: Хусусий корхоналар | C11: =SUM(J11:Y11)-L11-P11-Q11 -> 12801927212 | D11: 1933287232 | E11: 10868639980 | F11: =+G11+H11+I11 -> 444638825 | G11: 201641115 | H11: 242997710 | I11: 0 | J11: 85489626 | K11: 0 | L11: 0 | M11: 56954934 | N11: 569706122 | O11: =+P11+Q11 -> 3447741382 | P11: 82069057 | Q11: 3365672325 | R11: 2303737768 | S11: 0 | T11: 0 | U11: 0 | V11: 4270803877 | W11: 1376344550 | X11: 0 | Y11: 691148953
A12: =A11+10 -> 40 | B12: Ҳукумат | C12: =SUM(J12:Y12)-L12-P12-Q12 -> 0 | D12: 0 | E12: 0 | F12: =+G12+H12+I12 -> 0 | G12: 0 | H12: 0 | I12: 0 | J12: 0 | K12: 0 | L12: 0 | M12: 0 | N12: 0 | O12: =+P12+Q12 -> 0 | P12: 0 | Q12: 0 | R12: 0 | S12: 0 | T12: 0 | U12: 0 | V12: 0 | W12: 0 | X12: 0 | Y12: 0
A13: =A12+10 -> 50 | B13: Бошқалар | C13: =SUM(J13:Y13)-L13-P13-Q13 -> 0 | D13: 0 | E13: 0 | F13: =+G13+H13+I13 -> 0 | G13: 0 | H13: 0 | I13: 0 | J13: 0 | K13: 0 | L13: 0 | M13: 0 | N13: 0 | O13: =+P13+Q13 -> 0 | P13: 0 | Q13: 0 | R13: 0 | S13: 0 | T13: 0 | U13: 0 | V13: 0 | W13: 0 | X13: 0 | Y13: 0
A14: =A13+10 -> 60 | B14: Жами | C14: =SUM(J14:Y14)-L14-P14-Q14 -> 29912501071 | D14: =SUM(D9:D13) -> 4763373857 | E14: =SUM(E9:E13) -> 25149127214 | F14: =+G14+H14+I14 -> 500854865 | G14: =SUM(G9:G13) -> 201641115 | H14: =SUM(H9:H13) -> 289245258 | I14: =SUM(I9:I13) -> 9968492 | J14: =SUM(J9:J13) -> 86723503 | K14: =SUM(K9:K13) -> 4785668881 | L14: =SUM(L9:L13) -> 4245386620 | M14: =SUM(M9:M13) -> 61799725 | N14: =SUM(N9:N13) -> 1091985813 | ... Y14: =SUM(Y9:Y13) -> 3158706311
B15: Қишлоқ хўжалиги
A16: 70 | B16: Давлат корхоналари | C16: =SUM(J16:Y16)-L16-P16-Q16 -> 0 | D16: 0 | E16: 0 | F16: =+G16+H16+I16 -> 0 | G16: 0 | H16: 0 | I16: 0 | J16: 0 | K16: 0 | L16: 0 | M16: 0 | N16: 0 | O16: =+P16+Q16 -> 0 | P16: 0 | Q16: 0 | R16: 0 | S16: 0 | T16: 0 | U16: 0 | V16: 0 | W16: 0 | X16: 0 | Y16: 0
A17: =A16+10 -> 80 | B17: Қўшма ва чет эл капитали иштирокидаги корхоналар | C17: =SUM(J17:Y17)-L17-P17-Q17 -> 789288690 | D17: 330794749 | E17: 458493941 | F17: =+G17+H17+I17 -> 0 | G17: 0 | H17: 0 | I17: 0 | J17: 41195460 | K17: 0 | L17: 0 | M17: 9015628 | N17: 0 | O17: =+P17+Q17 -> 327185990 | P17: 1556788 | Q17: 325629202 | R17: 121218327 | S17: 0 | T17: 0 | U17: 0 | V17: 25611990 | W17: 265061295 | X17: 0 | Y17: 0
A18: =A17+10 -> 90 | B18: Хусусий корхоналар | C18: =SUM(J18:Y18)-L18-P18-Q18 -> 4015699054 | D18: 2001495554 | E18: 2014203500 | F18: =+G18+H18+I18 -> 260746305 | G18: 107673112 | H18: 153073193 | I18: 0 | J18: 416758 | K18: 0 | L18: 0 | M18: 31454007 | N18: 13003626 | O18: =+P18+Q18 -> 865245645 | P18: 21357688 | Q18: 843887957 | R18: 426787534 | S18: 0 | T18: 0 | U18: 0 | V18: 1489794285 | W18: 1182472123 | X18: 0 | Y18: 6525076
A19: =A18+10 -> 100 | B19: Фермер хўжалиги | C19: =SUM(J19:Y19)-L19-P19-Q19 -> 121348475 | D19: 28204799 | E19: 93143676 | F19: =+G19+H19+I19 -> 16944233 | G19: 1534407 | H19: 15409826 | I19: 0 | J19: 0 | K19: 0 | L19: 0 | M19: 2236327 | N19: 0 | O19: =+P19+Q19 -> 46516068 | P19: 1588577 | Q19: 44927491 | R19: 17209353 | S19: 0 | T19: 0 | U19: 0 | V19: 51389821 | W19: 3996906 | X19: 0 | Y19: 0
A20: =A19+10 -> 110 | B20: Ҳукумат | C20: =SUM(J20:Y20)-L20-P20-Q20 -> 0 | D20: 0 | E20: 0 | F20: =+G20+H20+I20 -> 0 | G20: 0 | H20: 0 | I20: 0 | J20: 0 | K20: 0 | L20: 0 | M20: 0 | N20: 0 | O20: =+P20+Q20 -> 0 | P20: 0 | Q20: 0 | R20: 0 | S20: 0 | T20: 0 | U20: 0 | V20: 0 | W20: 0 | X20: 0 | Y20: 0
A21: =A20+10 -> 120 | B21: Бошқалар | C21: =SUM(J21:Y21)-L21-P21-Q21 -> 0 | D21: 0 | E21: 0 | F21: =+G21+H21+I21 -> 0 | G21: 0 | H21: 0 | I21: 0 | J21: 0 | K21: 0 | L21: 0 | M21: 0 | N21: 0 | O21: =+P21+Q21 -> 0 | P21: 0 | Q21: 0 | R21: 0 | S21: 0 | T21: 0 | U21: 0 | V21: 0 | W21: 0 | X21: 0 | Y21: 0
A22: =A21+10 -> 130 | B22: Жами | C22: =SUM(J22:Y22)-L22-P22-Q22 -> 4926336219 | D22: =SUM(D16:D21) -> 2360495102 | E22: =SUM(E16:E21) -> 2565841117 | F22: =+G22+H22+I22 -> 277690538 | G22: =SUM(G17:G21) -> 109207519 | H22: =SUM(H17:H21) -> 168483019 | I22: =SUM(I17:I21) -> 0 | J22: =SUM(J16:J21) -> 41612218 | K22: =SUM(K16:K21) -> 0 | L22: =SUM(L16:L21) -> 0 | M22: =SUM(M16:M21) -> 42705962 | N22: =SUM(N16:N21) -> 13003626 | O22: =SUM(O16:O21) -> 1238947703 | P22: =SUM(P16:P21) -> 24503053 | Q22: =SUM(Q16:Q21) -> 1214444650 | ... Y22: =SUM(Y16:Y21) -> 6525076
B23: Транспорт ва коммуникация
A24: 140 | B24: Давлат корхоналари | C24: =SUM(J24:Y24)-L24-P24-Q24 -> 3130908071 | D24: 0 | E24: 3130908071 | F24: =+G24+H24+I24 -> 0 | G24: 0 | H24: 0 | I24: 0 | J24: 881006874 | K24: 1583896166 | L24: 1583896166 | M24: 0 | N24: 0 | O24: =+P24+Q24 -> 0 | P24: 0 | Q24: 0 | R24: 17710248 | S24: 0 | T24: 0 | U24: 0 | V24: 528380933 | W24: 0 | X24: 0 | Y24: 119913850
A25: =A24+10 -> 150 | B25: Қўшма ва чет эл капитали иштирокидаги корхоналар | C25: =SUM(J25:Y25)-L25-P25-Q25 -> 0 | D25: 0 | E25: 0 | F25: =+G25+H25+I25 -> 0 | G25: 0 | H25: 0 | I25: 0 | J25: 0 | K25: 0 | L25: 0 | M25: 0 | N25: 0 | O25: =+P25+Q25 -> 0 | P25: 0 | Q25: 0 | R25: 0 | S25: 0 | T25: 0 | U25: 0 | V25: 0 | W25: 0 | X25: 0 | Y25: 0
A26: =A25+10 -> 160 | B26: Хусусий корхоналар | C26: =SUM(J26:Y26)-L26-P26-Q26 -> 837205251 | D26: 120515494 | E26: 716689757 | F26: =+G26+H26+I26 -> 68756122 | G26: 63274014 | H26: 3800001 | I26: 1682107 | J26: 430163 | K26: 0 | L26: 0 | M26: 54758747 | N26: 0 | O26: =+P26+Q26 -> 358447299 | P26: 2884083 | Q26: 355563216 | R26: 33472246 | S26: 0 | T26: 0 | U26: 0 | V26: 180730754 | W26: 209100650 | X26: 0 | Y26: 265392
A27: =A26+10 -> 170 | B27: Ҳукумат | C27: =SUM(J27:Y27)-L27-P27-Q27 -> 0 | D27: 0 | E27: 0 | F27: =+G27+H27+I27 -> 0 | G27: 0 | H27: 0 | I27: 0 | J27: 0 | K27: 0 | L27: 0 | M27: 0 | N27: 0 | O27: =+P27+Q27 -> 0 | P27: 0 | Q27: 0 | R27: 0 | S27: 0 | T27: 0 | U27: 0 | V27: 0 | W27: 0 | X27: 0 | Y27: 0
A28: =A27+10 -> 180 | B28: Бошқалар | C28: =SUM(J28:Y28)-L28-P28-Q28 -> 0 | D28: 0 | E28: 0 | F28: =+G28+H28+I28 -> 0 | G28: 0 | H28: 0 | I28: 0 | J28: 0 | K28: 0 | L28: 0 | M28: 0 | N28: 0 | O28: =+P28+Q28 -> 0 | P28: 0 | Q28: 0 | R28: 0 | S28: 0 | T28: 0 | U28: 0 | V28: 0 | W28: 0 | X28: 0 | Y28: 0
A29: =A28+10 -> 190 | B29: Жами | C29: =SUM(J29:Y29)-L29-P29-Q29 -> 3968113322 | D29: =SUM(D24:D28) -> 120515494 | E29: =SUM(E24:E28) -> 3847597828 | F29: =+G29+H29+I29 -> 68756122 | G29: =SUM(G24:G28) -> 63274014 | H29: =SUM(H24:H28) -> 3800001 | I29: =SUM(I24:I28) -> 1682107 | J29: =SUM(J24:J28) -> 881437037 | K29: =SUM(K24:K28) -> 1583896166 | L29: =SUM(L24:L28) -> 1583896166 | M29: =SUM(M24:M28) -> 54758747 | N29: =SUM(N24:N28) -> 0 | ... Y29: =SUM(Y24:Y28) -> 120179242
B30: Қурилиш соҳаси
A31: 200 | B31: Давлат корхоналари | C31: =SUM(J31:Y31)-L31-P31-Q31 -> 0 | D31: 0 | E31: 0 | F31: =+G31+H31+I31 -> 0 | G31: 0 | H31: 0 | I31: 0 | J31: 0 | K31: 0 | L31: 0 | M31: 0 | N31: 0 | O31: =+P31+Q31 -> 0 | P31: 0 | Q31: 0 | R31: 0 | S31: 0 | T31: 0 | U31: 0 | V31: 0 | W31: 0 | X31: 0 | Y31: 0
A32: =A31+10 -> 210 | B32: Қўшма ва чет эл капитали иштирокидаги корхоналар | C32: =SUM(J32:Y32)-L32-P32-Q32 -> 2516725 | D32: 1170701 | E32: 1346024 | F32: =+G32+H32+I32 -> 810756 | G32: 810756 | H32: 0 | I32: 0 | J32: 0 | K32: 0 | L32: 0 | M32: 139645 | N32: 0 | O32: =+P32+Q32 -> 919363 | P32: 0 | Q32: 919363 | R32: 0 | S32: 0 | T32: 0 | U32: 0 | V32: 1126054 | W32: 331663 | X32: 0 | Y32: 0
A33: =A32+10 -> 220 | B33: Хусусий корхоналар | C33: =SUM(J33:Y33)-L33-P33-Q33 -> 1309241651 | D33: 368458372 | E33: 940783279 | F33: =+G33+H33+I33 -> 93917041 | G33: 42107696 | H33: 51809345 | I33: 0 | J33: 93641 | K33: 0 | L33: 0 | M33: 26385606 | N33: 76350 | O33: =+P33+Q33 -> 440026532 | P33: 6729521 | Q33: 433297011 | R33: 35361268 | S33: 0 | T33: 0 | U33: 0 | V33: 680260077 | W33: 126847315 | X33: 0 | Y33: 190862
A34: =A33+10 -> 230 | B34: Ҳукумат | C34: =SUM(J34:Y34)-L34-P34-Q34 -> 0 | D34: 0 | E34: 0 | F34: =+G34+H34+I34 -> 0 | G34: 0 | H34: 0 | I34: 0 | J34: 0 | K34: 0 | L34: 0 | M34: 0 | N34: 0 | O34: =+P34+Q34 -> 0 | P34: 0 | Q34: 0 | R34: 0 | S34: 0 | T34: 0 | U34: 0 | V34: 0 | W34: 0 | X34: 0 | Y34: 0
A35: =A34+10 -> 240 | B35: Бошқалар | C35: =SUM(J35:Y35)-L35-P35-Q35 -> 0 | D35: 0 | E35: 0 | F35: =+G35+H35+I35 -> 0 | G35: 0 | H35: 0 | I35: 0 | J35: 0 | K35: 0 | L35: 0 | M35: 0 | N35: 0 | O35: =+P35+Q35 -> 0 | P35: 0 | Q35: 0 | R35: 0 | S35: 0 | T35: 0 | U35: 0 | V35: 0 | W35: 0 | X35: 0 | Y35: 0
A36: =A35+10 -> 250 | B36: Жами | C36: =SUM(J36:Y36)-L36-P36-Q36 -> 1311758376 | D36: =SUM(D31:D35) -> 369629073 | E36: =SUM(E31:E35) -> 942129303 | F36: =+G36+H36+I36 -> 94727797 | G36: =SUM(G31:G35) -> 42918452 | H36: =SUM(H31:H35) -> 51809345 | I36: =SUM(I31:I35) -> 0 | J36: =SUM(J31:J35) -> 93641 | K36: =SUM(K31:K35) -> 0 | L36: =SUM(L31:L35) -> 0 | M36: =SUM(M31:M35) -> 26525251 | N36: =SUM(N31:N35) -> 76350 | ... Y36: =SUM(Y31:Y35) -> 190862
B37: Савдо ва умумий хизмат
A38: 260 | B38: Давлат корхоналари | C38: =SUM(J38:Y38)-L38-P38-Q38 -> 0 | D38: 0 | E38: 0 | F38: =+G38+H38+I38 -> 0 | G38: 0 | H38: 0 | I38: 0 | J38: 0 | K38: 0 | L38: 0 | M38: 0 | N38: 0 | O38: =+P38+Q38 -> 0 | P38: 0 | Q38: 0 | R38: 0 | S38: 0 | T38: 0 | U38: 0 | V38: 0 | W38: 0 | X38: 0 | Y38: 0
A39: =A38+10 -> 270 | B39: Қўшма ва чет эл капитали иштирокидаги корхоналар | C39: =SUM(J39:Y39)-L39-P39-Q39 -> 210505732 | D39: 2886030 | E39: 207619702 | F39: =+G39+H39+I39 -> 0 | G39: 0 | H39: 0 | I39: 0 | J39: 0 | K39: 0 | L39: 0 | M39: 5533725 | N39: 0 | O39: =+P39+Q39 -> 46329299 | P39: 0 | Q39: 46329299 | R39: 12183800 | S39: 0 | T39: 0 | U39: 0 | V39: 140778051 | W39: 5680857 | X39: 0 | Y39: 0
A40: =A39+10 -> 280 | B40: Хусусий корхоналар | C40: =SUM(J40:Y40)-L40-P40-Q40 -> 3255933640 | D40: 707116615 | E40: 2548817025 | F40: =+G40+H40+I40 -> 264987535 | G40: 60676560 | H40: 193760975 | I40: 10550000 | J40: 281355 | K40: 0 | L40: 0 | M40: 63006710 | N40: 98572342 | O40: =+P40+Q40 -> 1259278840 | P40: 7623843 | Q40: 1251654997 | R40: 80183014 | S40: 0 | T40: 0 | U40: 0 | V40: 685150388 | W40: 1067567991 | X40: 0 | Y40: 1893000
A41: =A40+10 -> 290 | B41: Ҳукумат | C41: =SUM(J41:Y41)-L41-P41-Q41 -> 0 | D41: =+E41+F41 -> 0 | E41: =+F41+G41 -> 0 | F41: =+G41+H41+I41 -> 0 | G41: =+H41+I41 -> 0 | H41: =+I41+J41 -> 0 | I41: =+J41+K41 -> 0 | J41: =+K41+L41 -> 0 | K41: =+L41+M41 -> 0 | L41: =+M41+N41 -> 0 | M41: =+N41+O41 -> 0 | N41: =+O41+P41 -> 0 | O41: =+P41+Q41 -> 0 | P41: 0 | Q41: 0 | R41: 0 | S41: 0 | T41: 0 | U41: 0 | V41: 0 | W41: 0 | X41: 0 | Y41: 0
...

Sheet Aging Analysis
A1: ОЛИНИШИ ЛОЗИМ БЎЛГАН МУДДАТИ ЎТГАН КРЕДИТ ВА МОЛИЯВИЙ ЛИЗИНГ ТАҲЛИЛИ | X1: 9-жадвал
B3: =+'Asset quality'!B3 -> "Ўзсаноатқурилишибанк" АТБ | T3: =+'Asset quality'!Q3 -> 45289 | X3: =+'Asset quality'!T3 -> минг. сўмда
A4: № | B4: Кўрсаткичлар | C4: Жами кредит суммаси | D4: % | E4: Шартлари қайта кўрилган кредит ва лизинглар | F4: % | G4: Суд жараёнидаги қарздорликлар | H4: % | I4: Муддати ўтган | K4: % | L4: шу жумладан, кечиктирилган муддати бўйича
L5: 1-30 кун | N5: 31-60 кун | P5: 61-90 кун | R5: 91-180 кун | T5: 181-365 кун | V5: 366-730 кун | X5: 2 йилдан ортиқ
I6: асосий қарздорлик | J6: фоиз тўловлари | L6: асосий қарздорлик | M6: фоиз тўловлари | N6: асосий қарздорлик | O6: фоиз тўловлари | P6: асосий қарздорлик | Q6: фоиз тўловлари | R6: асосий қарздорлик | S6: фоиз тўловлари | T6: асосий қарздорлик | U6: фоиз тўловлари | V6: асосий қарздорлик | W6: фоиз тўловлари | X6: асосий қарздорлик | Y6: фоиз тўловлари
B7: (А) | C7: (Б) | D7: (В) | E7: (Г) | F7: (Д) | G7: (Е) | H7: (Ж) | I7: (З) | J7: (З1) | K7: (И) | L7: (К) | M7: (К1) | N7: (Л) | O7: (Л1) | P7: (М) | Q7: (М1) | R7: (Н) | S7: (Н1) | T7: (О) | U7: (О1) | V7: (П) | W7: (П1) | X7: (Р) | Y7: (Р1)
B8: Мижозлар тури бўйича
A9: 1 | B9: Марказий банк | C9: =+'Loans Receivable'!C79 -> 0 | D9: =IF(C$22=0,"",C9/C$22) -> 0 | F9: =IF(E$22=0,"",E9/E$22) -> 0 | H9: =IF($G$22=0,"",G9/$G$22) -> 0 | I9: =+L9+N9+P9+R9+T9+V9+X9 -> 0 | J9: =+M9+O9+T9+S9+U9+W9+Y9 -> 0 | K9: =IF($Z$22=0,"",Z9/$Z$22) -> 0 | Z9: =+I9+J9 -> 0 | AA9: =+C9-Z9 -> 0
A10: 2 | B10: Бошқа банклар | C10: =+'Loans Receivable'!C78 -> 0 | D10: =IF(C$22=0,"",C10/C$22) -> 0 | F10: =IF(E$22=0,"",E10/E$22) -> 0 | H10: =IF($G$22=0,"",G10/$G$22) -> 0 | I10: =+L10+N10+P10+R10+T10+V10+X10 -> 0 | J10: =+M10+O10+Q10+S10+U10+W10+Y10 -> 0 | K10: =IF($Z$22=0,"",Z10/$Z$22) -> 0 | Z10: =+I10+J10 -> 0
A11: 3 | B11: Ҳукумат | C11: =+'Loans Receivable'!C80 -> 0 | D11: =IF(C$22=0,"",C11/C$22) -> 0 | F11: =IF(E$22=0,"",E11/E$22) -> 0 | H11: =IF($G$22=0,"",G11/$G$22) -> 0 | I11: =+L11+N11+P11+R11+T11+V11+X11 -> 0 | J11: =+M11+O11+Q11+S11+U11+W11+Y11 -> 0 | K11: =IF($Z$22=0,"",Z11/$Z$22) -> 0 | Z11: =+I11+J11 -> 0
A12: 4 | B12: Жисмоний шахслар | C12: =+'Loans Receivable'!C73 -> 7814492786 | D12: =IF(C$22=0,"",C12/C$22) -> 0.1367978 | E12: 11346858 | F12: =IF(E$22=0,"",E12/E$22) -> 0.19429271 | G12: 43859 | H12: =IF($G$22=0,"",G12/$G$22) -> 0.00027778647 | I12: =+L12+N12+P12+R12+T12+V12+X12 -> 7856662 | J12: =+M12+O12+Q12+S12+U12+W12+Y12 -> 7474846 | K12: =IF($Z$22=0,"",Z12/$Z$22) -> 0.010874089 | L12: 1748340 | M12: 2291587 | N12: 1245341 | O12: 705234 | P12: 1251712 | Q12: 939523 | R12: 1276984 | S12: 767116 | T12: 2334285 | U12: 2771386 | V12: 0 | W12: 0 | X12: 0 | Y12: 0 | Z12: =+I12+J12 -> 15331508
A13: 5 | B13: Давлат корхоналари | C13: =+'Loans Receivable'!C74 -> 14102735134 | D13: =IF(C$22=0,"",C13/C$22) -> 0.24687759 | E13: 4496481 | F13: =IF(E$22=0,"",E13/E$22) -> 0.076993428 | G13: 0 | H13: =IF($G$22=0,"",G13/$G$22) -> 0 | I13: =+L13+N13+P13+R13+T13+V13+X13 -> 98319866 | J13: =+M13+O13+Q13+S13+U13+W13+Y13 -> 2441554 | K13: =IF($Z$22=0,"",Z13/$Z$22) -> 0.071466462 | L13: 98319866 | M13: 2441554 | N13: 0 | O13: 0 | P13: 0 | Q13: 0 | R13: 0 | S13: 0 | T13: 0 | U13: 0 | V13: 0 | W13: 0 | X13: 0 | Y13: 0 | Z13: =+I13+J13 -> 100761420
A14: 6 | B14: Қўшма ва чет эл капитали иштирокидаги корхоналар | C14: =+'Loans Receivable'!C75 -> 10296625676 | D14: =IF(C$22=0,"",C14/C$22) -> 0.18024916 | E14: 0 | F14: =IF(E$22=0,"",E14/E$22) -> 0 | G14: 0 | H14: =IF($G$22=0,"",G14/$G$22) -> 0 | I14: =+L14+N14+P14+R14+T14+V14+X14 -> 150059657 | J14: =+M14+O14+Q14+S14+U14+W14+Y14 -> 127290347 | K14: =IF($Z$22=0,"",Z14/$Z$22) -> 0.19671441 | L14: 78208666 | M14: 114030712 | N14: 14354547 | O14: 1555895 | P14: 30138339 | Q14: 6264672 | R14: 555201 | S14: 131412 | T14: 20157144 | U14: 2379726 | V14: 6645760 | W14: 2927930 | X14: 0 | Y14: 0 | Z14: =+I14+J14 -> 277350004
A15: 7 | B15: Хусусий корхоналар | C15: =+'Loans Receivable'!C76 -> 24784649546 | D15: =IF(C$22=0,"",C15/C$22) -> 0.43387148 | E15: 40892838 | F15: =IF(E$22=0,"",E15/E$22) -> 0.70020973 | G15: 157843603 | H15: =IF($G$22=0,"",G15/$G$22) -> 0.99972221 | I15: =+L15+N15+P15+R15+T15+V15+X15 -> 728560050 | J15: =+M15+O15+Q15+S15+U15+W15+Y15 -> 277799568 | K15: =IF($Z$22=0,"",Z15/$Z$22) -> 0.71377479 | L15: 113971397 | M15: 165987458 | N15: 177054680 | O15: 18045871 | P15: 104436616 | Q15: 13699389 | R15: 132240698 | S15: 27403948 | T15: 194506659 | U15: 49320772 | V15: 6350000 | W15: 3342130 | X15: 0 | Y15: 0 | Z15: =+I15+J15 -> 1006359618
A16: 8 | B16: Фермер хўжаликлари | C16: =+'Loans Receivable'!C77 -> 121348475 | D16: =IF(C$22=0,"",C16/C$22) -> 0.0021242843 | E16: 1664665 | F16: =IF(E$22=0,"",E16/E$22) -> 0.028504127 | G16: 0 | H16: =IF($G$22=0,"",G16/$G$22) -> 0 | I16: =+L16+N16+P16+R16+T16+V16+X16 -> 6226046 | J16: =+M16+O16+Q16+S16+U16+W16+Y16 -> 3683202 | K16: =IF($Z$22=0,"",Z16/$Z$22) -> 0.0070282742 | L16: 2008417 | M16: 2263948 | N16: 122615 | O16: 97805 | P16: 407093 | Q16: 168428 | R16: 412079 | S16: 215537 | T16: 3275842 | U16: 937484 | V16: 0 | W16: 0 | X16: 0 | Y16: 0 | Z16: =+I16+J16 -> 9909248
A17: 9 | B17: Нобанк молиявий институтлар | C17: =+'Loans Receivable'!C81 -> 2946729 | D17: =IF(C$22=0,"",C17/C$22) -> 5.1584416e-05 | E17: 0 | F17: =IF(E$22=0,"",E17/E$22) -> 0 | G17: 0 | H17: =IF($G$22=0,"",G17/$G$22) -> 0 | I17: =+L17+N17+P17+R17+T17+V17+X17 -> 118872 | J17: =+M17+O17+Q17+S17+U17+W17+Y17 -> 62346 | K17: =IF($Z$22=0,"",Z17/$Z$22) -> 0.00012853143 | L17: 0 | M17: 0 | N17: 0 | O17: 0 | P17: 0 | Q17: 0 | R17: 38743 | S17: 10439 | T17: 80129 | U17: 51907 | V17: 0 | W17: 0 | X17: 0 | Y17: 0 | Z17: =+I17+J17 -> 181218
A18: 10 | B18: Нодавлат нотижорат ташкилотлар | C18: =+'Loans Receivable'!C82 -> 1605566 | D18: =IF(C$22=0,"",C18/C$22) -> 2.8106481e-05 | E18: 0 | F18: =IF(E$22=0,"",E18/E$22) -> 0 | G18: 0 | H18: =IF($G$22=0,"",G18/$G$22) -> 0 | I18: =+L18+N18+P18+R18+T18+V18+X18 -> 13281 | J18: =+M18+O18+Q18+S18+U18+W18+Y18 -> 5677 | K18: =IF($Z$22=0,"",Z18/$Z$22) -> 1.344623e-05 | L18: 0 | M18: 135 | N18: 0 | O18: 0 | P18: 0 | Q18: 0 | R18: 13281 | S18: 5542 | T18: 0 | U18: 0 | V18: 0 | W18: 0 | X18: 0 | Y18: 0 | Z18: =+I18+J18 -> 18958
A19: 11 | B19: Бюджет ташкилотлари | C19: =+'Loans Receivable'!C83 -> 0 | D19: =IF(C$22=0,"",C19/C$22) -> 0 | E19: 0 | F19: =IF(E$22=0,"",E19/E$22) -> 0 | G19: 0 | H19: =IF($G$22=0,"",G19/$G$22) -> 0 | I19: =+L19+N19+P19+R19+T19+V19+X19 -> 0 | J19: =+M19+O19+Q19+S19+U19+W19+Y19 -> 0 | K19: =IF($Z$22=0,"",Z19/$Z$22) -> 0 | L19: 0 | M19: 0 | N19: 0 | O19: 0 | P19: 0 | Q19: 0 | R19: 0 | S19: 0 | T19: 0 | U19: 0 | V19: 0 | W19: 0 | X19: 0 | Y19: 0 | Z19: =+I19+J19 -> 0
A20: 12 | B20: Бошқалар | C20: =+'Loans Receivable'!C84 -> 0 | D20: =IF(C$22=0,"",C20/C$22) -> 0 | E20: 0 | F20: =IF(E$22=0,"",E20/E$22) -> 0 | G20: 0 | H20: =IF($G$22=0,"",G20/$G$22) -> 0 | I20: =+L20+N20+P20+R20+T20+V20+X20 -> 0 | J20: =+M20+O20+Q20+S20+U20+W20+Y20 -> 0 | K20: =IF($Z$22=0,"",Z20/$Z$22) -> 0 | L20: 0 | M20: 0 | N20: 0 | O20: 0 | P20: 0 | Q20: 0 | R20: 0 | S20: 0 | T20: 0 | U20: 0 | V20: 0 | W20: 0 | X20: 0 | Y20: 0 | Z20: =+I20+J20 -> 0
Z21: =+I21+J21 -> 0
A22: 13 | B22: Жами кредит ва лизинг суммаси | C22: =SUM(C9:C20) -> 57124403912 | D22: =IF(C$22=0,"",C22/C$22) -> 1 | E22: =SUM(E9:E20) -> 58400842 | F22: =IF(E$22=0,"",E22/E$22) -> 1 | G22: =SUM(G9:G20) -> 157887462 | H22: =IF($G$22=0,"",G22/$G$22) -> 1 | I22: =SUM(I9:I20) -> 991154434 | J22: =SUM(J9:J20) -> 418757540 | K22: =IF($Z$22=0,"",Z22/$Z$22) -> 1 | L22: =SUM(L9:L20) -> 294256686 | M22: =SUM(M9:M20) -> 287015394 | N22: =SUM(N9:N20) -> 192777183 | O22: =SUM(O9:O20) -> 20404805 | P22: =SUM(P9:P20) -> 136233760 | Q22: =SUM(Q9:Q20) -> 21072012 | R22: =SUM(R9:R20) -> 134536986 | S22: =SUM(S9:S20) -> 28533994 | ... Y22: =SUM(Y9:Y20) -> 0 | Z22: =+I22+J22 -> 1409911974
Z23: =+I23+J23 -> 0
B24: Иқтисодиёт соҳалари бўйича | Z24: =+I24+J24 -> 0
A25: 14 | B25: Саноат | C25: =+'Loans Receivable'!C14 -> 29912501071 | D25: =IF(C$35=0,"",C25/C$35) -> 0.52363787 | E25: 34378217 | F25: =IF($E$35=0,"",E25/$E$35) -> 0.58865961 | G25: 71852496 | H25: =IF($G$35=0,"",G25/$G$35) -> 0.45508678 | I25: =+L25+N25+P25+R25+T25+V25+X25 -> 416894845 | J25: =+M25+O25+Q25+S25+U25+W25+Y25 -> 220635459 | K25: =IF($Z$35=0,"",Z25/$Z$35) -> 0.45217738 | L25: 175273503 | M25: 170354551 | N25: 44261683 | O25: 6392554 | P25: 43153635 | Q25: 9499748 | R25: 71246613 | S25: 18117890 | T25: 76313651 | U25: 13342786 | V25: 6645760 | W25: 2927930 | X25: 0 | Y25: 0 | Z25: =+I25+J25 -> 637530304
A26: 15 | B26: Қишлоқ хўжалиги | C26: =+'Loans Receivable'!C22 -> 4926336219 | D26: =IF(C$35=0,"",C26/C$35) -> 0.086238733 | E26: 2415555 | F26: =IF($E$35=0,"",E26/$E$35) -> 0.041361647 | G26: 0 | H26: =IF($G$35=0,"",G26/$G$35) -> 0 | I26: =+L26+N26+P26+R26+T26+V26+X26 -> 293400607 | J26: =+M26+O26+Q26+S26+U26+W26+Y26 -> 64935267 | K26: =IF($Z$35=0,"",Z26/$Z$35) -> 0.25415478 | L26: 44832372 | M26: 33117186 | N26: 130600236 | O26: 11175199 | P26: 76132630 | Q26: 7675934 | R26: 15063040 | S26: 2232360 | T26: 26772329 | U26: 10734588 | V26: 0 | W26: 0 | X26: 0 | Y26: 0 | Z26: =+I26+J26 -> 358335874
A27: 16 | B27: Транспорт ва коммуникация | C27: =+'Loans Receivable'!C29 -> 3968113322 | D27: =IF(C$35=0,"",C27/C$35) -> 0.069464415 | E27: 899161 | F27: =IF($E$35=0,"",E27/$E$35) -> 0.01539637 | G27: 1 | H27: =IF($G$35=0,"",G27/$G$35) -> 6.3336251e-09 | I27: =+L27+N27+P27+R27+T27+V27+X27 -> 21275638 | J27: =+M27+O27+Q27+S27+U27+W27+Y27 -> 8346740 | K27: =IF($Z$35=0,"",Z27/$Z$35) -> 0.02101009 | L27: 504602 | M27: 4274245 | N27: 2567655 | O27: 97835 | P27: 278902 | Q27: 671682 | R27: 16934495 | S27: 2387538 | T27: 989984 | U27: 915440 | V27: 0 | W27: 0 | X27: 0 | Y27: 0 | Z27: =+I27+J27 -> 29622378
A28: 17 | B28: Қурилиш соҳаси | C28: =+'Loans Receivable'!C36 -> 1311758376 | D28: =IF(C$35=0,"",C28/C$35) -> 0.022963187 | E28: 493875 | F28: =IF($E$35=0,"",E28/$E$35) -> 0.0084566418 | G28: 11510424 | H28: =IF($G$35=0,"",G28/$G$35) -> 0.072902711 | I28: =+L28+N28+P28+R28+T28+V28+X28 -> 29147301 | J28: =+M28+O28+Q28+S28+U28+W28+Y28 -> 21660317 | K28: =IF($Z$35=0,"",Z28/$Z$35) -> 0.036036021 | L28: 3745843 | M28: 13941755 | N28: 664873 | O28: 432698 | P28: 2607789 | Q28: 861982 | R28: 2169141 | S28: 688812 | T28: 19959655 | U28: 5735070 | V28: 0 | W28: 0 | X28: 0 | Y28: 0 | Z28: =+I28+J28 -> 50807618
A29: 18 | B29: Савдо ва умумий овқатланиш | C29: =+'Loans Receivable'!C43 -> 3466439372 | D29: =IF(C$35=0,"",C29/C$35) -> 0.060682285 | E29: 8827176 | F29: =IF($E$35=0,"",E29/$E$35) -> 0.15114809 | G29: 72906866 | H29: =IF($G$35=0,"",G29/$G$35) -> 0.46176476 | I29: =+L29+N29+P29+R29+T29+V29+X29 -> 144642842 | J29: =+M29+O29+Q29+S29+U29+W29+Y29 -> 54210292 | K29: =IF($Z$35=0,"",Z29/$Z$35) -> 0.1410394 | L29: 6544435 | M29: 25602761 | N29: 9349182 | O29: 1090876 | P29: 11089066 | Q29: 830953 | R29: 25026725 | S29: 3600842 | T29: 86633434 | U29: 19935714 | V29: 6000000 | W29: 3149146 | X29: 0 | Y29: 0 | Z29: =+I29+J29 -> 198853134
A30: 19 | B30: Моддий ва техник таъминотни ривожлантириш | C30: =+'Loans Receivable'!C50 -> 2157776262 | D30: =IF(C$35=0,"",C30/C$35) -> 0.037773283 | E30: 0 | F30: =IF($E$35=0,"",E30/$E$35) -> 0 | G30: 0 | H30: =IF($G$35=0,"",G30/$G$35) -> 0 | I30: =+L30+N30+P30+R30+T30+V30+X30 -> 51801776 | J30: =+M30+O30+Q30+S30+U30+W30+Y30 -> 1363411 | K30: =IF($Z$35=0,"",Z30/$Z$35) -> 0.03770816 | L30: 50100000 | M30: 918440 | N30: 447990 | O30: 134319 | P30: 625833 | Q30: 116716 | R30: 246815 | S30: 515 | T30: 31138 | U30: 437 | V30: 350000 | W30: 192984 | X30: 0 | Y30: 0 | Z30: =+I30+J30 -> 53165187
A31: 20 | B31: Уй-жой коммунал хизмати | C31: =+'Loans Receivable'!C58 -> 1605566 | D31: =IF(C$35=0,"",C31/C$35) -> 2.8106481e-05 | E31: 0 | F31: =IF($E$35=0,"",E31/$E$35) -> 0 | G31: 0 | H31: =IF($G$35=0,"",G31/$G$35) -> 0 | I31: =+L31+N31+P31+R31+T31+V31+X31 -> 13281 | J31: =+M31+O31+Q31+S31+U31+W31+Y31 -> 5677 | K31: =IF($Z$35=0,"",Z31/$Z$35) -> 1.344623e-05 | L31: 0 | M31: 135 | N31: 0 | O31: 0 | P31: 0 | Q31: 0 | R31: 13281 | S31: 5542 | T31: 0 | U31: 0 | V31: 0 | W31: 0 | X31: 0 | Y31: 0 | Z31: =+I31+J31 -> 18958
A32: 21 | B32: Бошқа соҳалар | C32: =+'Loans Receivable'!C70 -> 3565380938 | D32: =IF(C$35=0,"",C32/C$35) -> 0.062414322 | E32: 40000 | F32: =IF($E$35=0,"",E32/$E$35) -> 0.00068492163 | G32: 1573816 | H32: =IF($G$35=0,"",G32/$G$35) -> 0.0099679606 | I32: =+L32+N32+P32+R32+T32+V32+X32 -> 26121482 | J32: =+M32+O32+Q32+S32+U32+W32+Y32 -> 40125531 | K32: =IF($Z$35=0,"",Z32/$Z$35) -> 0.046986631 | L32: 11507591 | M32: 36514734 | N32: 3640223 | O32: 376090 | P32: 1094193 | Q32: 475474 | R32: 2559892 | S32: 733379 | T32: 7319583 | U32: 2025854 | V32: 0 | W32: 0 | X32: 0 | Y32: 0 | Z32: =+I32+J32 -> 66247013
A33: 22 | B33: Жисмоний шахслар | C33: =+'Loans Receivable'!C71 -> 7814492786 | D33: =IF(C$35=0,"",C33/C$35) -> 0.1367978 | E33: 11346858 | F33: =IF($E$35=0,"",E33/$E$35) -> 0.19429271 | G33: 43859 | H33: =IF($G$35=0,"",G33/$G$35) -> 0.00027778647 | I33: =+L33+N33+P33+R33+T33+V33+X33 -> 7856662 | J33: =+M33+O33+Q33+S33+U33+W33+Y33 -> 7474846 | K33: =IF($Z$35=0,"",Z33/$Z$35) -> 0.010874089 | L33: 1748340 | M33: 2291587 | N33: 1245341 | O33: 705234 | P33: 1251712 | Q33: 939523 | R33: 1276984 | S33: 767116 | T33: 2334285 | U33: 2771386 | V33: 0 | W33: 0 | X33: 0 | Y33: 0 | Z33: =+I33+J33 -> 15331508
Z34: =+I34+J34 -> 0
A35: 23 | B35: Жами кредит ва лизинг суммаси | C35: =SUM(C25:C33) -> 57124403912 | D35: =IF(C$35=0,"",C35/C$35) -> 1 | E35: =SUM(E25:E33) -> 58400842 | F35: =IF($E$35=0,"",E35/$E$35) -> 1 | G35: =SUM(G25:G33) -> 157887462 | H35: =IF($G$35=0,"",G35/$G$35) -> 1 | I35: =SUM(I25:I33) -> 991154434 | J35: =SUM(J25:J33) -> 418757540 | K35: =IF($Z$35=0,"",Z35/$Z$35) -> 1 | L35: =SUM(L25:L33) -> 294256686 | M35: =SUM(M25:M33) -> 287015394 | N35: =SUM(N25:N33) -> 192777183 | O35: =SUM(O25:O33) -> 20404805 | P35: =SUM(P25:P33) -> 136233760 | Q35: =SUM(Q25:Q33) -> 21072012 | R35: =SUM(R25:R33) -> 134536986 | S35: =SUM(S25:S33) -> 28533994 | ... Y35: =SUM(Y25:Y33) -> 0 | Z35: =+I35+J35 -> 1409911974
B37: Бошқарув Раис имзоси:
B39: Бош бухгалтер имзоси:
G42: =+'[8]Bank Assets Analysis'!$S$31 -> 83375035

Sheet Asset Classification
A1: АКТИВЛАР СИФАТИ БЎЙИЧА ТАСНИФЛАНИШИ ТЎҒРИСИДА ҲИСОБОТ | Z1: 10-жадвал
B3: =+'Asset quality'!B3 -> "Ўзсаноатқурилишибанк" АТБ | U3: =+'Asset quality'!Q3 -> 45289 | AB3: =+'Asset quality'!T3 -> минг. сўмда
A4: № | B4: Кўрсаткичлар | C4: Жами суммаси | D4: шундан, хорижий валютада (экв. сўмда) | E4: Стандарт | F4: шундан, хорижий валютада (экв. сўмда) | G4: Стандарт активлар бўйича яратилган захиралар (1%) | H4: шундан, хорижий валютада (экв. сўмда) | I4: Субстандарт | J4: шундан, хорижий валютада (экв. сўмда) | K4: Махсус захиралар (мин 10%) | L4: шундан, хорижий валютада (экв. сўмда) | M4: Қониқарсиз | N4: шундан, хорижий валютада (экв. сўмда) | O4: Махсус захиралар (мин 25%) | P4: шундан, хорижий валютада (экв. сўмда) | Q4: Шубҳали | R4: шундан, хорижий валютада (экв. сўмда) | S4: Махсус захиралар (мин 50%) | T4: шундан, хорижий валютада (экв. сўмда) | U4: Умидсиз | V4: шундан, хорижий валютада (экв. сўмда) | W4: Махсус захиралар (мин 100%) | X4: шундан, хорижий валютада (экв. сўмда) | Y4: Жами махсус захиралар суммаси | Z4: шундан, хорижий валютада (экв. сўмда) | AA4: ҳисобот ойида балансдан ташқари ҳисобдан чиқарилган кредитлар | AB4: ҳисобот ойида балансдан ташқари қайтган кредитлар суммаси
A5: (А) | B5: (Б) | C5: (В) | D5: (В1) | E5: (Г) | F5: (Г1) | G5: (Д) | H5: (Д1) | I5: (Е) | J5: (Е1) | K5: (Ж) | L5: (Ж1) | M5: (З) | N5: (З1) | O5: (И) | P5: (И1) | Q5: (К) | R5: (К1) | S5: (Л) | T5: (Л1) | U5: (М) | V5: (М1) | W5: (Н) | X5: (Н1) | Y5: О=Ж+И+Л+Н | Z5: (О1)=(Ж1)+(И1)+(Л1)+(Н1) | AA5: П | AB5: Р
B6: Мижозлар тури бўйича
A7: 1 | B7: Марказий банк | C7: =E7+I7+M7+Q7+U7 -> 0 | D7: =F7+J7+N7+R7+V7 -> 0 | Y7: =+W7+S7+O7+K7 -> 0 | Z7: =+X7+T7+P7+L7 -> 0 | AC7: =+'Aging Analysis'!C9 -> 0 | AD7: =+C7-AC7 -> 0
B8: шундан, таъминланмаган қисми | C8: =E8+I8+M8+Q8+U8 -> 0 | D8: =F8+J8+N8+R8+V8 -> 0 | Y8: =+W8+S8+O8+K8 -> 0 | Z8: =+X8+T8+P8+L8 -> 0
A9: 2 | B9: Бошқа банклар | C9: =E9+I9+M9+Q9+U9 -> 0 | D9: =F9+J9+N9+R9+V9 -> 0 | Y9: =+W9+S9+O9+K9 -> 0 | Z9: =+X9+T9+P9+L9 -> 0 | AC9: =+'Aging Analysis'!C10 -> 0 | AD9: =+C9-AC9 -> 0
B10: шундан, таъминланмаган қисми | C10: =E10+I10+M10+Q10+U10 -> 0 | D10: =F10+J10+N10+R10+V10 -> 0 | Y10: =+W10+S10+O10+K10 -> 0 | Z10: =+X10+T10+P10+L10 -> 0
A11: 3 | B11: Ҳукумат | C11: =E11+I11+M11+Q11+U11 -> 0 | D11: =F11+J11+N11+R11+V11 -> 0 | Y11: =+W11+S11+O11+K11 -> 0 | Z11: =+X11+T11+P11+L11 -> 0 | AC11: =+'Aging Analysis'!C11 -> 0 | AD11: =+C11-AC11 -> 0
B12: шундан, таъминланмаган қисми | C12: =E12+I12+M12+Q12+U12 -> 0 | D12: =F12+J12+N12+R12+V12 -> 0 | Y12: =+W12+S12+O12+K12 -> 0 | Z12: =+X12+T12+P12+L12 -> 0
A13: 4 | B13: Жисмоний шахслар | C13: =E13+I13+M13+Q13+U13 -> 7814492786 | D13: =F13+J13+N13+R13+V13 -> 0 | E13: 7625652230 | F13: 0 | G13: 76256522 | H13: 0 | I13: 147846643 | J13: 0 | K13: 14782772 | L13: 0 | M13: 19062315 | N13: 0 | O13: 4765590 | P13: 0 | Q13: 21931598 | R13: 0 | S13: 10965799 | T13: 0 | U13: 0 | V13: 0 | W13: 0 | X13: 0 | Y13: =+W13+S13+O13+K13 -> 30514161 | Z13: =+X13+T13+P13+L13 -> 0 | AA13: 1722561 | AB13: 1562025 | AC13: =+'Aging Analysis'!C12 -> 7814492786 | AD13: =+C13-AC13 -> 0
B14: шундан, таъминланмаган қисми | C14: =E14+I14+M14+Q14+U14 -> 0 | D14: =F14+J14+N14+R14+V14 -> 0 | E14: 0 | F14: 0 | G14: 0 | H14: 0 | I14: 0 | J14: 0 | K14: 0 | L14: 0 | M14: 0 | N14: 0 | O14: 0 | P14: 0 | Q14: 0 | R14: 0 | S14: 0 | T14: 0 | U14: 0 | V14: 0 | W14: 0 | X14: 0 | Y14: =+W14+S14+O14+K14 -> 0 | Z14: =+X14+T14+P14+L14 -> 0
A15: 5 | B15: Давлат корхоналари | C15: =E15+I15+M15+Q15+U15 -> 14102735134 | D15: =F15+J15+N15+R15+V15 -> 9901199639 | E15: 14098238653 | F15: 9901199639 | G15: 150448847 | H15: 0 | I15: 4496481 | J15: 0 | K15: 449648 | L15: 0 | M15: 0 | N15: 0 | O15: 0 | P15: 0 | Q15: 0 | R15: 0 | S15: 0 | T15: 0 | U15: 0 | V15: 0 | W15: 0 | X15: 0 | Y15: =+W15+S15+O15+K15 -> 449648 | Z15: =+X15+T15+P15+L15 -> 0 | AA15: 13166667 | AB15: 0 | AC15: =+'Aging Analysis'!C13 -> 14102735134 | AD15: =+C15-AC15 -> 0
B16: шундан, таъминланмаган қисми | C16: =E16+I16+M16+Q16+U16 -> 0 | D16: =F16+J16+N16+R16+V16 -> 0 | E16: 0 | F16: 0 | G16: 0 | H16: 0 | I16: 0 | J16: 0 | K16: 0 | L16: 0 | M16: 0 | N16: 0 | O16: 0 | P16: 0 | Q16: 0 | R16: 0 | S16: 0 | T16: 0 | U16: 0 | V16: 0 | W16: 0 | X16: 0 | Y16: =+W16+S16+O16+K16 -> 0 | Z16: =+X16+T16+P16+L16 -> 0
A17: 6 | B17: Қўшма ва чет эл капитали иштирокидаги корхоналар | C17: =E17+I17+M17+Q17+U17 -> 10296625676 | D17: =F17+J17+N17+R17+V17 -> 9399133697 | E17: 7302774414 | F17: 6846681407 | G17: 73027744 | H17: 0 | I17: 2936824466 | J17: 2498999738 | K17: 293682447 | L17: 249899974 | M17: 810756 | N17: 0 | O17: 202689 | P17: 0 | Q17: 46247548 | R17: 43484060 | S17: 23123774 | T17: 21742030 | U17: 9968492 | V17: 9968492 | W17: 9968492 | X17: 9968492 | Y17: =+W17+S17+O17+K17 -> 326977402 | Z17: =+X17+T17+P17+L17 -> 281610496 | AA17: 0 | AB17: 0 | AC17: =+'Aging Analysis'!C14 -> 10296625676 | AD17: =+C17-AC17 -> 0
B18: шундан, таъминланмаган қисми | C18: =E18+I18+M18+Q18+U18 -> 0 | D18: =F18+J18+N18+R18+V18 -> 0 | E18: 0 | F18: 0 | G18: 0 | H18: 0 | I18: 0 | J18: 0 | K18: 0 | L18: 0 | M18: 0 | N18: 0 | O18: 0 | P18: 0 | Q18: 0 | R18: 0 | S18: 0 | T18: 0 | U18: 0 | V18: 0 | W18: 0 | X18: 0 | Y18: =+W18+S18+O18+K18 -> 0 | Z18: =+X18+T18+P18+L18 -> 0
A19: 7 | B19: Хусусий корхоналар | C19: =E19+I19+M19+Q19+U19 -> 24784649546 | D19: =F19+J19+N19+R19+V19 -> 18619483630 | E19: 20465632095 | F19: 16120791382 | G19: 204656322 | H19: 0 | I19: 3151391318 | J19: 1742099388 | K19: 306015397 | L19: 164856170 | M19: 484458884 | N19: 263138435 | O19: 121114721 | P19: 65784610 | Q19: 665896409 | R19: 488765692 | S19: 332948207 | T19: 244382848 | U19: 17270840 | V19: 4688733 | W19: 17270840 | X19: 4688733 | Y19: =+W19+S19+O19+K19 -> 777349165 | Z19: =+X19+T19+P19+L19 -> 479712361 | AA19: 276036951 | AB19: 14399898 | AC19: =+'Aging Analysis'!C15 -> 24784649546 | AD19: =+C19-AC19 -> 0
B20: шундан, таъминланмаган қисми | C20: =E20+I20+M20+Q20+U20 -> 0 | D20: =F20+J20+N20+R20+V20 -> 0 | E20: 0 | F20: 0 | G20: 0 | H20: 0 | I20: 0 | J20: 0 | K20: 0 | L20: 0 | M20: 0 | N20: 0 | O20: 0 | P20: 0 | Q20: 0 | R20: 0 | S20: 0 | T20: 0 | U20: 0 | V20: 0 | W20: 0 | X20: 0 | Y20: =+W20+S20+O20+K20 -> 0 | Z20: =+X20+T20+P20+L20 -> 0
A21: 8 | B21: Фермер хўжалиги | C21: =E21+I21+M21+Q21+U21 -> 121348475 | D21: =F21+J21+N21+R21+V21 -> 93143676 | E21: 52486428 | F21: 31214867 | G21: 524864 | H21: 0 | I21: 51917814 | J21: 48554449 | K21: 5191781 | L21: 4855445 | M21: 1534407 | N21: 0 | O21: 383602 | P21: 0 | Q21: 15409826 | R21: 13374360 | S21: 7704913 | T21: 6687180 | U21: 0 | V21: 0 | W21: 0 | X21: 0 | Y21: =+W21+S21+O21+K21 -> 13280296 | Z21: =+X21+T21+P21+L21 -> 11542625 | AA21: 2025920 | AB21: 647389 | AC21: =+'Aging Analysis'!C16 -> 121348475 | AD21: =+C21-AC21 -> 0
B22: шундан, таъминланмаган қисми | C22: =E22+I22+M22+Q22+U22 -> 0 | D22: =F22+J22+N22+R22+V22 -> 0 | E22: 0 | F22: 0 | G22: 0 | H22: 0 | I22: 0 | J22: 0 | K22: 0 | L22: 0 | M22: 0 | N22: 0 | O22: 0 | P22: 0 | Q22: 0 | R22: 0 | S22: 0 | T22: 0 | U22: 0 | V22: 0 | W22: 0 | X22: 0 | Y22: =+W22+S22+O22+K22 -> 0 | Z22: =+X22+T22+P22+L22 -> 0
A23: 9 | B23: Нобанк молиявий институтлар | C23: =E23+I23+M23+Q23+U23 -> 2946729 | D23: =F23+J23+N23+R23+V23 -> 0 | E23: 2500000 | F23: 0 | G23: 25000 | H23: 0 | I23: 0 | J23: 0 | K23: 0 | L23: 0 | M23: 0 | N23: 0 | O23: 0 | P23: 0 | Q23: 446729 | R23: 0 | S23: 223364 | T23: 0 | U23: 0 | V23: 0 | W23: 0 | X23: 0 | Y23: =+W23+S23+O23+K23 -> 223364 | Z23: =+X23+T23+P23+L23 -> 0 | AA23: 0 | AB23: 0 | AC23: =+'Aging Analysis'!C17 -> 2946729 | AD23: =+C23-AC23 -> 0
B24: шундан, таъминланмаган қисми | C24: =E24+I24+M24+Q24+U24 -> 0 | D24: =F24+J24+N24+R24+V24 -> 0 | E24: 0 | F24: 0 | G24: 0 | H24: 0 | I24: 0 | J24: 0 | K24: 0 | L24: 0 | M24: 0 | N24: 0 | O24: 0 | P24: 0 | Q24: 0 | R24: 0 | S24: 0 | T24: 0 | U24: 0 | V24: 0 | W24: 0 | X24: 0 | Y24: =+W24+S24+O24+K24 -> 0 | Z24: =+X24+T24+P24+L24 -> 0
A25: 10 | B25: Нодавлат нотижорат ташкилотлар | C25: =E25+I25+M25+Q25+U25 -> 1605566 | D25: =F25+J25+N25+R25+V25 -> 0 | E25: 1467441 | F25: 0 | G25: 14674 | H25: 0 | I25: 0 | J25: 0 | K25: 0 | L25: 0 | M25: 138125 | N25: 0 | O25: 34531 | P25: 0 | Q25: 0 | R25: 0 | S25: 0 | T25: 0 | U25: 0 | V25: 0 | W25: 0 | X25: 0 | Y25: =+W25+S25+O25+K25 -> 34531 | Z25: =+X25+T25+P25+L25 -> 0 | AA25: 0 | AB25: 0 | AC25: =+'Aging Analysis'!C18 -> 1605566 | AD25: =+C25-AC25 -> 0
B26: шундан, таъминланмаган қисми | C26: =E26+I26+M26+Q26+U26 -> 0 | D26: =F26+J26+N26+R26+V26 -> 0 | Y26: =+W26+S26+O26+K26 -> 0 | Z26: =+X26+T26+P26+L26 -> 0
A27: 11 | B27: Бюджет ташкилотлари | C27: =E27+I27+M27+Q27+U27 -> 0 | D27: =F27+J27+N27+R27+V27 -> 0 | Y27: =+W27+S27+O27+K27 -> 0 | Z27: =+X27+T27+P27+L27 -> 0 | AA27: 0 | AB27: 0 | AC27: =+'Aging Analysis'!C19 -> 0 | AD27: =+C27-AC27 -> 0
B28: шундан, таъминланмаган қисми | C28: =E28+I28+M28+Q28+U28 -> 0 | D28: =F28+J28+N28+R28+V28 -> 0 | Y28: =+W28+S28+O28+K28 -> 0 | Z28: =+X28+T28+P28+L28 -> 0
A29: 12 | B29: Бошқалар | C29: =E29+I29+M29+Q29+U29 -> 0 | D29: =F29+J29+N29+R29+V29 -> 0 | Y29: =+W29+S29+O29+K29 -> 0 | Z29: =+X29+T29+P29+L29 -> 0 | AA29: 1800000 | AB29: 0 | AC29: =+'Aging Analysis'!C20 -> 0 | AD29: =+C29-AC29 -> 0
B30: шундан, таъминланмаган қисми | C30: =E30+I30+M30+Q30+U30 -> 0 | D30: =F30+J30+N30+R30+V30 -> 0 | Y30: =+W30+S30+O30+K30 -> 0 | Z30: =+X30+T30+P30+L30 -> 0
A31: 13 | B31: Жами кредит ва лизинг суммаси | C31: =+C7+C9+C11+C13+C15+C17+C19+C21+C23+C25+C27+C29 -> 57124403912 | D31: =+D7+D9+D11+D13+D15+D17+D19+D21+D23+D25+D27+D29 -> 38012960642 | E31: =+E7+E9+E11+E13+E15+E17+E19+E21+E23+E25+E27+E29 -> 49548751261 | F31: =+F7+F9+F11+F13+F15+F17+F19+F21+F23+F25+F27+F29 -> 32899887295 | G31: =+G7+G9+G11+G13+G15+G17+G19+G21+G23+G25+G27+G29 -> 504953973 | H31: =+H7+H9+H11+H13+H15+H17+H19+H21+H23+H25+H27+H29 -> 0 | I31: =+I7+I9+I11+I13+I15+I17+I19+I21+I23+I25+I27+I29 -> 6292476722 | J31: =+J7+J9+J11+J13+J15+J17+J19+J21+J23+J25+J27+J29 -> 4289653575 | ... AB31: =+AB7+AB9+AB11+AB13+AB15+AB17+AB19+AB21+AB23+AB25+AB27+AB29 -> 16609312 | AC31: =+'Loans Receivable'!C85 -> 57124403912 | AD31: =+C31-AC31 -> 0
