Workbook
Name jop: #REF!
Name kol: #REF!
Name RISKTOTASS: SUM('[6]Calculation of Risk Weighted As'!$C$38:$F$38)
Name RISKTOTASS: SUM('[7]Calculation of Risk Weighted As'!$C$41:$G$41)
Name TwentyLargestData: #REF!
Name Е: #REF!

Sheet Asset quality
A1: ИНФОРМАЦИЯ О КАЧЕСТВЕ АКТИВОВ, ОЦЕНИВАЕМЫХ В ЦЕЛЯХ СОЗДАНИЯ РЕЗЕРВА НА ВОЗМОЖНЫЕ ПОТЕРИ | R1: Таблица-2 | U1: №4
B3: АК "АЛОКАБАНК" | P3: 44561 | S3: тыс. сум
A4: № | B4: Состав активов* | C4: Остаток | D4: Категория качества | I4: Просроченная задолженность (брутто) | N4: Резерв на возможные потери
I5: итого | J5: до 30 дней | K5: от 31 до 90 дней | L5: от 91 до 180 дней | M5: свыше 180 дней | N5: фактически сформированный
N6: итого | O6: по категориям качества
D7: I | E7: II | F7: III | G7: IV | H7: V | O7: I | P7: II | Q7: III | R7: IV | S7: V
A8: А | B8: Б | C8: В | D8: Г | E8: Д | F8: Е | G8: Ж | H8: З | I8: И | J8: К | K8: Л | L8: М | M8: Н | N8: О | O8: П | P8: Р | Q8: С | R8: Т | S8: У
B9: ВСЕГО АКТИВОВ | C9: =SUM(C10:C60) -> 12638456623 | D9: =SUM(D10:D60) -> 11780546199 | E9: =SUM(E10:E60) -> 624369631 | F9: =SUM(F10:F60) -> 74161881 | G9: =SUM(G10:G60) -> 80999105 | H9: =SUM(H10:H60) -> 180403995 | I9: =SUM(I10:I60) -> 98862165 | J9: =SUM(J10:J60) -> 7405420 | ... S9: =SUM(S10:S60) -> 58343002
A10: 1 | B10: Кассовая наличность и другие платежные документы | C10: =SUM(D10:H10)-N10+O10 -> 275813889 | D10: 275813889 | E10: 0 | F10: 0 | G10: 0 | H10: 0 | I10: =SUM(J10:M10) -> 0 | J10: 0 | K10: 0 | L10: 0 | M10: 0 | N10: =SUM(O10:S10) -> 2382993 | O10: 2382993 | P10: 0 | Q10: 0 | R10: 0 | S10: 0 | T10: 10100
A11: 2 | B11: К получению из ЦБРУ | C11: =SUM(D11:H11)-N11+O11 -> 1238811513 | D11: 1238811513 | E11: 0 | F11: 0 | G11: 0 | H11: 0 | I11: =SUM(J11:M11) -> 0 | J11: 0 | K11: 0 | L11: 0 | M11: 0 | N11: =SUM(O11:S11) -> 10703156 | O11: 10703156 | P11: 0 | Q11: 0 | R11: 0 | S11: 0 | T11: 10300
A12: 3 | B12: К получению из других банков | C12: =SUM(D12:H12)-N12+O12 -> 901416758 | D12: 901416758 | E12: 0 | F12: 0 | G12: 0 | H12: 0 | I12: =SUM(J12:M12) -> 0 | J12: 0 | K12: 0 | L12: 0 | M12: 0 | N12: =SUM(O12:S12) -> 7788113 | O12: 7788113 | P12: 0 | Q12: 0 | R12: 0 | S12: 0 | T12: 10500
A13: 4 | B13: Ценные бумаги для купли и продажи | C13: =SUM(D13:H13)-N13+O13 -> 409972435 | D13: 409972435 | E13: 0 | F13: 0 | G13: 0 | H13: 0 | I13: =SUM(J13:M13) -> 0 | J13: 0 | K13: 0 | L13: 0 | M13: 0 | N13: =SUM(O13:S13) -> 3542104 | O13: 3542104 | P13: 0 | Q13: 0 | R13: 0 | S13: 0 | T13: 10700
A14: 5 | B14: Инвестиции в ценные бумаги, имеющиеся в наличии для продажи | C14: =SUM(D14:H14)-N14+O14 -> 0 | D14: 0 | E14: 0 | F14: 0 | G14: 0 | H14: 0 | I14: =SUM(J14:M14) -> 0 | J14: 0 | K14: 0 | L14: 0 | M14: 0 | N14: =SUM(O14:S14) -> 0 | O14: 0 | P14: 0 | Q14: 0 | R14: 0 | S14: 0 | T14: 10800
A15: 6 | B15: Драгоценные металлы, камни и монеты для купли и продажи | C15: =SUM(D15:H15)-N15+O15 -> 251 | D15: 251 | E15: 0 | F15: 0 | G15: 0 | H15: 0 | I15: =SUM(J15:M15) -> 0 | J15: 0 | K15: 0 | L15: 0 | M15: 0 | N15: =SUM(O15:S15) -> 2 | O15: 2 | P15: 0 | Q15: 0 | R15: 0 | S15: 0 | T15: 10900
A16: 7 | B16: Купленные дебиторские задолженности - Факторинг | C16: =SUM(D16:H16)-N16+O16 -> 0 | D16: 0 | E16: 0 | F16: 0 | G16: 0 | H16: 0 | I16: =SUM(J16:M16) -> 0 | J16: 0 | K16: 0 | L16: 0 | M16: 0 | N16: =SUM(O16:S16) -> 0 | O16: 0 | P16: 0 | Q16: 0 | R16: 0 | S16: 0 | T16: 11100
A17: 8 | B17: Купленные векселя | C17: =SUM(D17:H17)-N17+O17 -> 0 | D17: 0 | E17: 0 | F17: 0 | G17: 0 | H17: 0 | I17: =SUM(J17:M17) -> 0 | J17: 0 | K17: 0 | L17: 0 | M17: 0 | N17: =SUM(O17:S17) -> 0 | O17: 0 | P17: 0 | Q17: 0 | R17: 0 | S17: 0 | T17: 11300
A18: 9 | B18: Обязательства клиентов по траттам под аккредитив и/или трастовые документы | C18: =SUM(D18:H18)-N18+O18 -> 532887227 | D18: 533298096 | E18: 0 | F18: 0 | G18: 0 | H18: 0 | I18: =SUM(J18:M18) -> 0 | J18: 0 | K18: 0 | L18: 0 | M18: 0 | N18: =SUM(O18:S18) -> 5018489 | O18: 4607620 | P18: 410869 | Q18: 0 | R18: 0 | S18: 0 | T18: 11500
A19: 10 | B19: Обязательства лиентов по непогашенным акцептам банка | C19: =SUM(D19:H19)-N19+O19 -> 0 | D19: 0 | E19: 0 | F19: 0 | G19: 0 | H19: 0 | I19: =SUM(J19:M19) -> 0 | J19: 0 | K19: 0 | L19: 0 | M19: 0 | N19: =SUM(O19:S19) -> 0 | O19: 0 | P19: 0 | Q19: 0 | R19: 0 | S19: 0 | T19: 11700
A20: 11 | B20: Купленные по сделкам РЕПО ценные бумаги | C20: =SUM(D20:H20)-N20+O20 -> 0 | D20: 0 | E20: 0 | F20: 0 | G20: 0 | H20: 0 | I20: =SUM(J20:M20) -> 0 | J20: 0 | K20: 0 | L20: 0 | M20: 0 | N20: =SUM(O20:S20) -> 0 | O20: 0 | P20: 0 | Q20: 0 | R20: 0 | S20: 0 | T20: 11800
A21: 12 | B21: Краткосрочные кредиты, предоставленные ЦБРУ | C21: =SUM(D21:H21)-N21+O21 -> 0 | D21: 0 | E21: 0 | F21: 0 | G21: 0 | H21: 0 | I21: =SUM(J21:M21) -> 0 | J21: 0 | K21: 0 | L21: 0 | M21: 0 | N21: =SUM(O21:S21) -> 0 | O21: 0 | P21: 0 | Q21: 0 | R21: 0 | S21: 0 | T21: 11900
... A38: 29 | B38: Долгосрочные кредиты, предоставленные бюджетным организациям | C38: =SUM(D38:H38)-N38+O38 -> 0 | D38: 0 | E38: 0 | F38: 0 | G38: 0 | H38: 0 | I38: =SUM(J38:M38) -> 0 | J38: 0 | K38: 0 | L38: 0 | M38: 0 | N38: =SUM(O38:S38) -> 0 | O38: 0 | P38: 0 | Q38: 0 | R38: 0 | S38: 0 | T38: 14800
A39: 30 | B39: Долгосрочные кредиты, предоставленные физическим лицам | C39: =SUM(D39:H39)-N39+O39 -> 1248806200 | D39: =1179541171 -> 1179541171 | E39: 51636184 | F39: 12051203 | G39: 17851792 | H39: 31442317 | I39: =SUM(J39:M39) -> 0 | J39: 0 | K39: 0 | L39: 0 | M39: 0 | N39: =SUM(O39:S39) -> 53907536 | O39: 10191069 | P39: 4843416 | Q39: 2617679 | R39: 10173191 | S39: 26082181 | T39: 14900
A40: 31 | B40: Долгосрочные кредиты, предоставленные индивидуальным предпринимателям | C40: =SUM(D40:H40)-N40+O40 -> 70586477 | D40: 68153947 | E40: 3647182 | F40: 720146 | G40: 178333 | H40: 0 | I40: =SUM(J40:M40) -> 0 | J40: 0 | K40: 0 | L40: 0 | M40: 0 | N40: =SUM(O40:S40) -> 2701971 | O40: 588840 | P40: 349760 | Q40: 159157 | R40: 212474 | S40: 1391740 | T40: 15000
A41: 32 | B41: Долгосрочные кредиты, предоставленные государственным предприятиям, организациям и учреждениям | C41: =SUM(D41:H41)-N41+O41 -> 1005737506 | D41: 945738348 | E41: 59999158 | F41: 0 | G41: 0 | H41: 0 | I41: =SUM(J41:M41) -> 0 | J41: 0 | K41: 0 | L41: 0 | M41: 0 | N41: =SUM(O41:S41) -> 8171046 | O41: 8171046 | P41: 0 | Q41: 0 | R41: 0 | S41: 0 | T41: 15100
A42: 33 | B42: Долгосрочные кредиты, предоставленные негосударственным некоммерческим организациям | C42: =SUM(D42:H42)-N42+O42 -> 6455581 | D42: 1825554 | E42: 140812 | F42: 4069479 | G42: 706833 | H42: 4568220 | I42: =SUM(J42:M42) -> 0 | J42: 0 | K42: 0 | L42: 0 | M42: 0 | N42: =SUM(O42:S42) -> 4871090 | O42: 15773 | P42: 13315 | Q42: 85620 | R42: 194662 | S42: 4561720 | T42: 15200
A43: 34 | B43: Долгосрочные кредиты, предоставленные предприятиям с участием иностранного капитала | C43: =SUM(D43:H43)-N43+O43 -> 312868771 | D43: 313030551 | E43: 0 | F43: 0 | G43: 0 | H43: 0 | I43: =SUM(J43:M43) -> 0 | J43: 0 | K43: 0 | L43: 0 | M43: 0 | N43: =SUM(O43:S43) -> 2866320 | O43: 2704540 | P43: 0 | Q43: 161780 | R43: 0 | S43: 0 | T43: 15300
A44: 35 | B44: Долгосрочные кредиты, предоставленные небанковским финансовым институтам | C44: =SUM(D44:H44)-N44+O44 -> 17380000 | D44: 17380000 | E44: 0 | F44: 0 | G44: 0 | H44: 0 | I44: =SUM(J44:M44) -> 0 | J44: 0 | K44: 0 | L44: 0 | M44: 0 | N44: =SUM(O44:S44) -> 150161 | O44: 150161 | P44: 0 | Q44: 0 | R44: 0 | S44: 0 | T44: 15400
A45: 36 | B45: Долгосрочные кредиты, предоставленные частным предприятиям, хозяйственным товариществам и обществам | C45: =SUM(D45:H45)-N45+O45 -> 4020550690 | D45: 3398119655 | E45: 483794946 | F45: 33090604 | G45: 38841324 | H45: 100705647 | I45: =SUM(J45:M45) -> 0 | J45: 0 | K45: 0 | L45: 0 | M45: 0 | N45: =SUM(O45:S45) -> 63360759 | O45: 29359273 | P45: 14916144 | Q45: 3285403 | R45: 1101377 | S45: 14698562 | T45: 15500
A46: 37 | B46: Лизинг (Финансовая аренда) | C46: =SUM(D46:H46)-N46+O46 -> 305556 | D46: 305556 | E46: 0 | F46: 0 | G46: 0 | H46: 0 | I46: =SUM(J46:M46) -> 0 | J46: 0 | K46: 0 | L46: 0 | M46: 0 | N46: =SUM(O46:S46) -> 2640 | O46: 2640 | P46: 0 | Q46: 0 | R46: 0 | S46: 0 | T46: 15600
A47: 38 | B47: Кредиты и лизинг, находящиеся в процессе судебного разбирательства | C47: =SUM(D47:H47)-N47+O47 -> -1039 | D47: 0 | E47: 0 | F47: 0 | G47: 468212 | H47: 8113272 | I47: =SUM(J47:M47) -> 8581484 | J47: 0 | K47: 0 | L47: 642859 | M47: 7938625 | N47: =SUM(O47:S47) -> 8582523 | O47: 0 | P47: 0 | Q47: 0 | R47: 284106 | S47: 8298417 | T47: 15700
A48: 39 | B48: Инвестиции в зависимые хозяйственные общества, совместные предприятия и дочерние хозяйственные общества | C48: =SUM(D48:H48)-N48+O48 -> 98339066 | D48: 98339066 | E48: 0 | F48: 0 | G48: 0 | H48: 0 | I48: =SUM(J48:M48) -> 0 | J48: 0 | K48: 0 | L48: 0 | M48: 0 | N48: =SUM(O48:S48) -> 849636 | O48: 849636 | P48: 0 | Q48: 0 | R48: 0 | S48: 0 | T48: 15800
A49: 40 | B49: Инвестиции в долговые ценные бумаги, удерживаемые до погашения | C49: =SUM(D49:H49)-N49+O49 -> 0 | D49: 0 | E49: 0 | F49: 0 | G49: 0 | H49: 0 | I49: =SUM(J49:M49) -> 0 | J49: 0 | K49: 0 | L49: 0 | M49: 0 | N49: =SUM(O49:S49) -> 0 | O49: 0 | P49: 0 | Q49: 0 | R49: 0 | S49: 0 | T49: 15900
A50: 41 | B50: Начисленные проценты к получению | C50: =SUM(D50:H50)-N50+O50 -> 163425953 | D50: 142095308 | E50: 6876791 | F50: 1741342 | G50: 5526012 | H50: 7186500 | I50: =SUM(J50:M50) -> 0 | J50: 0 | K50: 0 | L50: 0 | M50: 0 | N50: =SUM(O50:S50) -> 1227683 | O50: 1227683 | P50: 0 | Q50: 0 | R50: 0 | S50: 0 | T50: 16300
A51: 42 | B51: Начисленные беспроцентные доходы к получению | C51: =SUM(D51:H51)-N51+O51 -> 34639224 | D51: 26977595 | E51: 883486 | F51: 744619 | G51: 1712066 | H51: 4321458 | I51: =SUM(J51:M51) -> 0 | J51: 0 | K51: 0 | L51: 0 | M51: 0 | N51: =SUM(O51:S51) -> 233083 | O51: 233083 | P51: 0 | Q51: 0 | R51: 0 | S51: 0 | T51: 16400
... A59: 50 | B59: Транзитные счета по средствам к списанию с пластиковых карт клиентов | C59: =SUM(D59:H59)-N59+O59 -> 71190523 | D59: 71190523 | E59: 0 | F59: 0 | G59: 0 | H59: 0 | I59: =SUM(J59:M59) -> 0 | J59: 0 | K59: 0 | L59: 0 | M59: 0 | N59: =SUM(O59:S59) -> 615076 | O59: 615076 | P59: 0 | Q59: 0 | R59: 0 | S59: 0 | T59: 17400
A60: 51 | B60: Другие активы | C60: =SUM(D60:H60)-N60+O60 -> 388680874 | D60: =389299851-2 -> 389299849 | E60: 0 | F60: 0 | G60: 0 | H60: 0 | I60: =SUM(J60:M60) -> 0 | J60: 0 | K60: 0 | L60: 0 | M60: 0 | N60: =SUM(O60:S60) -> 3982471 | O60: 3363496 | P60: 0 | Q60: 0 | R60: 0 | S60: 618975 | T60: 19900
B62: ЗАБАЛАНСОВЫЕ СТАТЬИ | C62: =SUM(D62:H62) -> 817439577 | D62: =SUM(D63:D64) -> 817439577 | E62: =SUM(E63:E64) -> 0 | F62: =SUM(F63:F64) -> 0 | G62: =SUM(G63:G64) -> 0 | H62: =SUM(H63:H64) -> 0 | I62: =SUM(J62:M62) -> 0 | J62: =SUM(J63:J64) -> 0 | K62: =SUM(K63:K64) -> 0 | L62: =SUM(L63:L64) -> 0 | M62: =SUM(M63:M64) -> 0 | N62: =SUM(N63:N64) -> 0 | O62: =SUM(O63:O64) -> 0 | P62: =SUM(P63:P64) -> 0 | Q62: =SUM(Q63:Q64) -> 0 | ... S62: =SUM(S63:S64) -> 0
A63: 1 | B63: Аккредитивы | C63: =SUM(D63:H63)-N63+O63 -> 573749357 | D63: 573749357 | I63: =SUM(J63:M63) -> 0 | N63: =SUM(O63:S63) -> 0 | T63: 90908-90958
A64: 2 | B64: Гарантии и поручетельства | C64: =SUM(D64:H64)-N64+O64 -> 243690220 | D64: 243690220 | I64: =SUM(J64:M64) -> 0 | N64: =SUM(O64:S64) -> 0 | T64: 90993
B67: Подпись Председателя правления:
...

Sheet Income 
B1: ОТЧЕТ О ФИНАНСОВЫХ РЕЗУЛЬТАТАХ | D1: Таблица-3
B3: =+'Asset quality'!B3 -> АК "АЛОКАБАНК" | C3: =+'Asset quality'!P3 -> 44561 | E3: в тыс. сум
A4: № | B4: Категории | C4: Итого | D4: в национальной валюте | E4: в иностранной валюте (в экв. в сумах)
A5: 1. | B5: 1. ПРОЦЕНТНЫЕ ДОХОДЫ
A6: a. | B6: Процентные доходы по счетам в ЦБРУ | C6: =+D6+E6 -> 701232 | D6: 701232 | E6: 0
A7: б. | B7: Процентные доходы по счетам в других банках | C7: =+D7+E7 -> 15859918 | D7: 8925070 | E7: 6934848
A8: в. | B8: Процентные доходы по купленным векселям | C8: =+D8+E8 -> 0 | D8: 0 | E8: 0
A9: г. | B9: Процентные доходы по инвестициям | C9: =+D9+E9 -> 0 | D9: 0 | E9: 0
A10: д. | B10: Процентные доходы по счетам купли-продажи ценных бумаг | C10: =+D10+E10 -> 46951376 | D10: 46951376 | E10: 0
A11: е. | B11: Процентные доходы по обязательствам клиентов | C11: =+D11+E11 -> 0 | D11: 0 | E11: 0
A12: ж. | B12: Процентные доходы по обяз-вам клиентов по непогашенным акцептам этого банка | C12: =+D12+E12 -> 24017775 | D12: 26468 | E12: 23991307
A13: з. | B13: Процент, Дисконт (Скидки) и взносы по кредитным и лизинговым операциям | C13: =+D13+E13 -> 923550337 | D13: 751711404 | E13: 171838933
A14: и. | B14: Процентные доходы по соглашениям о покупке ценных бумаг с обратным выкупом | C14: =+D14+E14 -> 0 | D14: 0 | E14: 0
A15: к. | B15: Другие процентные доходы | C15: =+D15+E15 -> 195609379 | D15: 195609379 | E15: 0
A16: л. | B16: Итого процентных доходов | C16: =SUM(C6:C15) -> 1206690017 | D16: =SUM(D6:D15) -> 1003924929 | E16: =SUM(E6:E15) -> 202765088 | G16: =+'Analysis of Interest'!C42 -> 1206690017
A18: 2. | B18: ПРОЦЕНТНЫЕ РАСХОДЫ
A19: а. | B19: Процентные расходы по депозитам до востребования | C19: =+D19+E19 -> 4353573 | D19: 4265417 | E19: 88156
A20: б. | B20: Процентные расходы по срочным депозитам | C20: =+D20+E20 -> 394517794 | D20: 356025755 | E20: 38492039
A21: в. | B21: Процентные расходы по счетам к оплате в ЦБРУ | C21: =+D21+E21 -> 0 | D21: 0 | E21: 0
A22: г. | B22: Процентные расходы по счетам к оплате в другие банки | C22: =+D22+E22 -> 109768909 | D22: 88564625 | E22: 21204284
A23: д. | B23: Итого процентных расходов по депозитам | C23: =SUM(C19:C22) -> 508640276 | D23: =SUM(D19:D22) -> 448855797 | E23: =SUM(E19:E22) -> 59784479
A24: е. | B24: Процентные расходы по кредитам к оплате | C24: =+D24+E24 -> 67695285 | D24: 24323774 | E24: 43371511
A25: ж. | B25: Процентные расходы по соглашениям о продаже ц/б с последующим выкупом | C25: =+D25+E25 -> 8059008 | D25: 8059008 | E25: 0
A26: з. | B26: Другие процентные расходы | C26: =+D26+E26 -> 213913966 | D26: 163463770 | E26: 50450196
A27: и. | B27: Итого процентных расходов по займам | C27: =SUM(C24:C26) -> 289668259 | D27: =SUM(D24:D26) -> 195846552 | E27: =SUM(E24:E26) -> 93821707
A28: л. | B28: Итого процентных расходов | C28: =C27+C23 -> 798308535 | D28: =D27+D23 -> 644702349 | E28: =E27+E23 -> 153606186 | G28: =+'Analysis of Interest'!C72 -> 798308535
A30: 3. | B30: ЧИСТЫЕ ПРОЦЕНТНЫЕ ДОХОДЫ ДО ОЦЕНКИ ВОЗМОЖНЫХ УБЫТКОВ ПО АКТИВАМ | C30: =C16-C28 -> 408381482 | D30: =D16-D28 -> 359222580 | E30: =E16-E28 -> 49158902
A31: а. | B31: Минус: Оценка возможных убытков по кредитам и лизингу | C31: =+D31+E31 -> 119121377 | D31: 102654089 | E31: 16467288
A32: б. | B32: Минус: Оценка возможных убытков по в ценным бумагам | C32: =+D32+E32 -> 0 | D32: 0 | E32: 0
A33: в. | B33: Минус: Оценка возможных убытков по инвестициям | C33: =+D33+E33 -> 0 | D33: 0 | E33: 0
A34: г. | B34: Минус: Оценка возможных убытков по другим активам | C34: =+D34+E34 -> 1763430 | D34: 1357315 | E34: 406115
A35: д. | B35: Чистые процентные доходы после оценки возможных убытков по кредитам и лизингу | C35: =C30-C31-C32-C33-C34 -> 287496675 | D35: =D30-D31-D32-D33-D34 -> 255211176 | E35: =E30-E31-E32-E33-E34 -> 32285499
A37: 4. | B37: БЕСПРОЦЕНТНЫЕ ДОХОДЫ
A38: а. | B38: Доходы от комиссий и платы за услуги | C38: =+D38+E38 -> 271963488 | D38: 264439404 | E38: 7524084
A39: б. | B39: Прибыль в иностранной валюте | C39: =+D39+E39 -> 72227659 | D39: 4365084 | E39: 67862575
A40: в. | B40: Прибыль от коммерческих операций | C40: =+D40+E40 -> 0 | D40: 0 | E40: 0
A41: г. | B41: Прибыль и дивиденды от инвестиций | C41: =+D41+E41 -> 9624086 | D41: 9624086 | E41: 0
A42: д. | B42: Другие беспроцентные доходы | C42: =+D42+E42 -> 73338139 | D42: 61461455 | E42: 11876684
B43: в том числе
A44: д1. | B44: Возврат резервов, с формированных на покрытие потерь по активам | C44: =+D44+E44 -> 786600 | D44: 786600 | E44: 0
...

Sheet Analysis of Interest
B1: АНАЛИЗ ПРОЦЕНТНЫХ ДОХОДОВ И РАСХОДОВ | C1: Таблица-4
B3: =+'Asset quality'!B3 -> АК "АЛОКАБАНК" | C3: =+'Asset quality'!P3 -> 44561
A4: № | B4: Категория | C4: в тыс. сум
A5: 1 . | B5: ПРОЦЕНТНЫЕ ДОХОДЫ ПО КРЕДИТНЫМ И ЛИЗИНГОВЫМ ОПЕРАЦИЯМ
A6: a. | B6: Кредиты и лизинговые операции ЦБРУ
A7: б. | B7: Кредиты и лизинговые операции другим банкам | C7: 75366
A8: в. | B8: Кредиты и лизинговые операции Правительству
A9: г. | B9: Кредиты и лизинговые операции физическим лицам | C9: 221788259
A10: д. | B10: Кредиты и лизинговые операции государственным предприятиям | C10: 79865132
A11: е. | B11: Кредиты и лизинговые операции совместным и иностранным предприятиям | C11: 55430278
A12: ж. | B12: Кредиты и лизинговые операции частным товариществам и корпорациям | C12: 548198425
A13: з. | B13: Другие кредиты и лизинговые операции | C13: 18192876
A14: и. | B14: ИТОГО ПРОЦЕНТНЫХ ДОХОДОВ ПО КРЕДИТНЫМ И ЛИЗИНГОВЫМ ОПЕРАЦИЯМ | C14: =SUM(C6:C13) -> 923550336
A16: 2. | B16: ПРОЦЕНТНЫЕ ДОХОДЫ ПО КОРРЕСПОНДЕНТСКИМ СЧЕТАМ
A17: a. | B17: К получению из ЦБРУ | C17: 701233
A18: б. | B18: К получению из других банков | C18: 15859918
B19: ИТОГО ПРОЦЕНТНЫХ ДОХОДОВ ПО КОРРЕСПОНДЕНТСКИМ СЧЕТАМ | C19: =SUM(C17:C18) -> 16561151
A21: 3. | B21: ПРОЦЕНТНЫЕ ДОХОДЫ ПО СЧЕТАМ КУПЛИ-ПРОДАЖИ Ц/Б
A22: a. | B22: Государственные казначейские ценные бумаги | C22: 7552603
A23: б. | B23: Облигации и ценные бумаги ЦБРУ | C23: 39398773
A24: в. | B24: Ценные бумаги государственных корпораций
A25: г. | B25: Еврооблигации | C25: 0
A26: д. | B26: Частные ценные бумаги | C26: 0
A27: е. | B27: Другие ценные бумаги | C27: 0
A28: ж. | B28: ИТОГО ПРОЦЕНТНЫХ ДОХОДОВ ПО СЧЕТАМ КУПЛИ-ПРОДАЖИ Ц/Б | C28: =SUM(C22:C27) -> 46951376
A30: 4. | B30: ПРОЦЕНТНЫЕ ДОХОДЫ ПО ИНВЕСТИЦИЯМ
A31: a. | B31: Государственные облигации | C31: 0
A32: б. | B32: Облигации и ценные бумаги ЦБРУ | C32: 0
A33: в. | B33: Частные облигации | C33: 0
A34: г. | B34: Еврооблигации | C34: 0
A35: д. | B35: Другие ценные бумаги
A36: е. | B36: ИТОГО ПРОЦЕНТНЫХ ДОХОДОВ ПО ИНВЕСТИЦИЯМ | C36: =SUM(C31:C35) -> 0
A38: 5. | B38: ДРУГИЕ ПРОЦЕНТНЫЕ ДОХОДЫ
A39: a. | B39: Процентные доходы по соглашениям о покупке ц/б c обратным выкупом | C39: 0
A40: б. | B40: Другие процентные доходы | C40: 219627154
A42: 6. | B42: ИТОГО ПРОЦЕНТНЫХ ДОХОДОВ | C42: =C14+C19+C28+C36+C39+C40 -> 1206690017
A44: 7. | B44: ПРОЦЕНТНЫЕ РАСХОДЫ ПО ДЕПОЗИТАМ
A45: A. | B45: Депозиты до востребования
A46: a. | B46: Правительство | C46: 1560575
A47: б. | B47: Физические лица | C47: 4230
...

Sheet Changes in Equity
B1: ИЗМЕНЕНИЯ В СОБСТВЕННОМ КАПИТАЛЕ | C1: Таблица-7
B3: =+'Asset quality'!B3 -> АК "АЛОКАБАНК" | C3: =+'Asset quality'!P3 -> 44561
A4: № | B4: Категория | C4: в тыс. сум
A5: 1. | B5: Итого собственного капитала первоначально определенного за прошлый год | C5: 1568529812
A6: 2. | B6: Исправления в собственном капитале не показанные в отчете за прошлый год, чистые | C6: 0
A7: 3. | B7: Исправленный баланс на конец прошлого календарного года (сумма строк 1 и 2) | C7: =SUM(C5:C6) -> 1568529812
A8: 4. | B8: Чистый прибыль (убыток) по состоянию на дату от начала года | C8: =+'Income '!C79 -> 107582490 | D8: =+[8]Balance!$C$76 -> 107582490
A9: 5. | B9: Продажа, Обмен, Приобретение или выкуп акций, за текущий год (чистая выручка) | C9: 0
A10: 6. | B10: Изменения в оценочной стоимости прироста над первонач. стоимостью, за текущий год (чистые) | C10: -294261
A11: 7. | B11: МИНУС: Денежные дивиденды объявленные по привилегированным акциям | C11: 0
A12: 8. | B12: МИНУС: Денежные дивиденды объявленные по обыкновенным акциям | C12: 0
A13: 9. | B13: Другие статьи влияющие на собственный капитал за текущий год (чистые) | C13: -2312098
A14: 10. | B14: Итого собственного капитала на конец текущего периода (сумма строк с 3 по 10) | C14: =C7+SUM(C8:C10)-SUM(C11:C12)+C13 -> 1673505943 | D14: =+[8]Balance!$C$77 -> 1673505943
B16: Подпись Председателя правления:
B18: Подпись Главного Бухгалтера:

Sheet Loans Receivable
A1: КРЕДИТЫ И ЛИЗИНГИ К ПОЛУЧЕНИЮ ПО ОТРАСЛЯМ ЭКОНОМИКИ, ТИПАМ КЛИЕНТОВ И ПО ТИПУ ОБЕСПЕЧЕНИЯ | W1: Таблица-8
B3: =+'Asset quality'!B3 -> АК "АЛОКАБАНК" | T3: =+'Asset quality'!P3 -> 44561 | X3: тыс. сум
A4: № | B4: Отрасль экономики | C4: Сумма кредита | D4: в национальной валюте | F4: в иностранной валюте (в экв. в сумах) | H4: из них | J4: из них
D5: Сумма | E5: средне-взвешенные процентные ставки | F5: Сумма | G5: средне-взвешенные процентные ставки | H5: Начисляемые кредиты | I5: Кредиты переведённые в статус ненаращивания процентов | J5: Депозиты | K5: Гарантированные Правительством Республики Узбекистан | L5: из них | M5: Транспортные средства | N5: Инвентарь | O5: Недвижимость | P5: из них | R5: Оборудование | S5: Векселя (облигации) | T5: Акции | U5: Гарантия третьей стороны | V5: Поручительства третьей стороны | W5: Страховой полис | X5: Необеспеченные | Y5: Другое обеспечение
L6: Гарантированные Правительством Республики Узбекистан в иностранной валюте (экв.сум) | P6: жилая недвижимость | Q6: коммерческая недвижимость
A7: Код | B7: (А) | C7: (Б) | D7: (Б1) | E7: (Б2) | F7: (Б3) | G7: (Б4) | H7: (В) | I7: (Г) | J7: (Д) | K7: (Е) | L7: (Е1) | M7: (Ж) | N7: (З) | O7: (И) | P7: (И1) | Q7: (И2) | R7: (К) | S7: (Л) | T7: (М) | U7: (Н) | V7: (О) | W7: (П) | X7: (Р) | Y7: (С)
B8: Промышленность
A9: 10 | B9: Физические лица | C9: =SUM(J9:Y9)-L9-P9-Q9 -> 0 | D9: 0 | E9: 0 | F9: 0 | G9: 0 | H9: 0 | I9: 0 | J9: 0 | K9: 0 | L9: 0 | M9: 0 | N9: 0 | O9: =+P9+Q9 -> 0 | P9: 0 | Q9: 0 | R9: 0 | S9: 0 | T9: 0 | U9: 0 | V9: 0 | W9: 0 | X9: 0 | Y9: 0
A10: =A9+10 -> 20 | B10: Государственные предприятия | C10: =SUM(J10:Y10)-L10-P10-Q10 -> 403756555 | D10: 70127862 | E10: 0.2288737 | F10: 333628693 | G10: 0.061691647 | H10: 403756555 | I10: 0 | J10: 0 | K10: 0 | L10: 0 | M10: 14625170 | N10: 0 | O10: =+P10+Q10 -> 61467427 | P10: 717453 | Q10: 60749974 | R10: 0 | S10: 0 | T10: 0 | U10: 0 | V10: 2534158 | W10: 325129800 | X10: 0 | Y10: 0
A11: =A10+10 -> 30 | B11: Совместные и иностранные предприятия | C11: =SUM(J11:Y11)-L11-P11-Q11 -> 201843182 | D11: 47604623 | E11: 0.1876824 | F11: 154238559 | G11: 0.089490306 | H11: 200214799 | I11: 1628383 | J11: 0 | K11: 1617795 | L11: 0 | M11: 79947303 | N11: 0 | O11: =+P11+Q11 -> 120278084 | P11: 29848430 | Q11: 90429654 | R11: 0 | S11: 0 | T11: 0 | U11: 0 | V11: 0 | W11: 0 | X11: 0 | Y11: 0
A12: =A11+10 -> 40 | B12: Частные товарищества и корпорации | C12: =SUM(J12:Y12)-L12-P12-Q12 -> 2069879983 | D12: 807943187 | E12: 0.1893187 | F12: 1261936796 | G12: 0.078118988 | H12: 2033929692 | I12: 35950291 | J12: 4003421 | K12: 29116313 | L12: 0 | M12: 578477589 | N12: 0 | O12: =+P12+Q12 -> 1396459937 | P12: 199792818 | Q12: 1196667119 | R12: 0 | S12: 0 | T12: 0 | U12: 0 | V12: 4731736 | W12: 2011318 | X12: 0 | Y12: 55079669
A13: =A12+10 -> 50 | B13: Правительство | C13: =SUM(J13:Y13)-L13-P13-Q13 -> 0 | D13: 0 | E13: 0 | F13: 0 | G13: 0 | H13: 0 | I13: 0 | J13: 0 | K13: 0 | L13: 0 | M13: 0 | N13: 0 | O13: =+P13+Q13 -> 0 | P13: 0 | Q13: 0 | R13: 0 | S13: 0 | T13: 0 | U13: 0 | V13: 0 | W13: 0 | X13: 0 | Y13: 0
A14: =A13+10 -> 60 | B14: Прочие | C14: =SUM(J14:Y14)-L14-P14-Q14 -> 19872982 | D14: 9189694 | E14: 0.20100042 | F14: 10683288 | G14: 0.071424944 | H14: 19235678 | I14: 637304 | J14: 0 | K14: 897333 | L14: 0 | M14: 5061885 | N14: 0 | O14: =+P14+Q14 -> 13910432 | P14: 291159 | Q14: 13619273 | R14: 0 | S14: 0 | T14: 0 | U14: 0 | V14: 0 | W14: 3332 | X14: 0 | Y14: 0
A15: =A14+10 -> 70 | B15: Итого по промышленности | C15: =SUM(J15:Y15)-L15-P15-Q15 -> 2695352702 | D15: =SUM(D9:D14) -> 934865366 | E15: =IFERROR(((D9*E9)/D15)+((D10*E10)/D15)+((D11*E11)/D15)+((D12*E12)/D15)+((D13*E13)/D15)+((D14*E14)/D15),0) -> 0.19231738 | F15: =SUM(F9:F14) -> 1760487336 | G15: =IFERROR(((F9*G9)/F15)+((F10*G10)/F15)+((F11*G11)/F15)+((F12*G12)/F15)+((F13*G13)/F15)+((F14*G14)/F15),0) -> 0.075961489 | H15: =SUM(H9:H14) -> 2657136724 | I15: =SUM(I9:I14) -> 38215978 | J15: =SUM(J9:J14) -> 4003421 | K15: =SUM(K9:K14) -> 31631441 | L15: =SUM(L9:L14) -> 0 | M15: =SUM(M9:M14) -> 678111947 | N15: =SUM(N9:N14) -> 0 | O15: =SUM(O9:O14) -> 1592115880 | ... Y15: =SUM(Y9:Y14) -> 55079669
B16: Сельское хозяйство
A17: =A15+10 -> 80 | B17: Физические лица | C17: =SUM(J17:Y17)-L17-P17-Q17 -> 0 | D17: 0 | E17: 0 | F17: 0 | G17: 0 | H17: 0 | I17: 0 | J17: 0 | K17: 0 | L17: 0 | M17: 0 | N17: 0 | O17: =+P17+Q17 -> 0 | P17: 0 | Q17: 0 | R17: 0 | S17: 0 | T17: 0 | U17: 0 | V17: 0 | W17: 0 | X17: 0 | Y17: 0
A18: =A17+10 -> 90 | B18: Государственные предприятия | C18: =SUM(J18:Y18)-L18-P18-Q18 -> 0 | D18: 0 | E18: 0 | F18: 0 | G18: 0 | H18: 0 | I18: 0 | J18: 0 | K18: 0 | L18: 0 | M18: 0 | N18: 0 | O18: =+P18+Q18 -> 0 | P18: 0 | Q18: 0 | R18: 0 | S18: 0 | T18: 0 | U18: 0 | V18: 0 | W18: 0 | X18: 0 | Y18: 0
A19: =A18+10 -> 100 | B19: Совместные и иностранные предприятия | C19: =SUM(J19:Y19)-L19-P19-Q19 -> 69765 | D19: 69765 | E19: 0.18 | F19: 0 | G19: 0 | H19: 69765 | I19: 0 | J19: 0 | K19: 0 | L19: 0 | M19: 69765 | N19: 0 | O19: =+P19+Q19 -> 0 | P19: 0 | Q19: 0 | R19: 0 | S19: 0 | T19: 0 | U19: 0 | V19: 0 | W19: 0 | X19: 0 | Y19: 0
A20: =A19+10 -> 110 | B20: Частные товарищества и корпорации | C20: =SUM(J20:Y20)-L20-P20-Q20 -> 199500477 | D20: 76507718 | E20: 0.20364522 | F20: 122992759 | G20: 0.076216619 | H20: 192831536 | I20: 6668941 | J20: 2483169 | K20: 16229450 | L20: 0 | M20: 51552038 | N20: 0 | O20: =+P20+Q20 -> 125700152 | P20: 25580483 | Q20: 100119669 | R20: 0 | S20: 0 | T20: 0 | U20: 0 | V20: 1684668 | W20: 0 | X20: 0 | Y20: 1851000
A21: =A20+10 -> 120 | B21: Фермерское хозяйство | C21: =SUM(J21:Y21)-L21-P21-Q21 -> 31561978 | D21: 8275439 | E21: 0.38188963 | F21: 23286539 | G21: 0.11917625 | H21: 31068728 | I21: 493250 | J21: 0 | K21: 493250 | L21: 0 | M21: 2609468 | N21: 0 | O21: =+P21+Q21 -> 28459260 | P21: 533333 | Q21: 27925927 | R21: 0 | S21: 0 | T21: 0 | U21: 0 | V21: 0 | W21: 0 | X21: 0 | Y21: 0
A22: =A21+10 -> 130 | B22: Правительство | C22: =SUM(J22:Y22)-L22-P22-Q22 -> 0 | D22: 0 | E22: 0 | F22: 0 | G22: 0 | H22: 0 | I22: 0 | J22: 0 | K22: 0 | L22: 0 | M22: 0 | N22: 0 | O22: =+P22+Q22 -> 0 | P22: 0 | Q22: 0 | R22: 0 | S22: 0 | T22: 0 | U22: 0 | V22: 0 | W22: 0 | X22: 0 | Y22: 0
A23: =A22+10 -> 140 | B23: Прочие | C23: =SUM(J23:Y23)-L23-P23-Q23 -> 2752863 | D23: 2752863 | E23: 0.20597575 | F23: 0 | G23: 0 | H23: 2118878 | I23: 633985 | J23: 0 | K23: 0 | L23: 0 | M23: 2179986 | N23: 0 | O23: =+P23+Q23 -> 342574 | P23: 59988 | Q23: 282586 | R23: 0 | S23: 0 | T23: 0 | U23: 0 | V23: 230303 | W23: 0 | X23: 0 | Y23: 0
A24: =A23+10 -> 150 | B24: Итого по сельскому хозяйству | C24: =SUM(J24:Y24)-L24-P24-Q24 -> 233885083 | D24: =SUM(D17:D23) -> 87605785 | E24: =IFERROR(((D17*E17)/D24)+((D18*E18)/D24)+((D19*E19)/D24)+((D20*E20)/D24)+((D21*E21)/D24)+((D22*E22)/D24)+((D23*E23)/D24),0) -> 0.22053699 | F24: =SUM(F17:F23) -> 146279298 | G24: =IFERROR(((F17*G17)/F24)+((F18*G18)/F24)+((F19*G19)/F24)+((F20*G20)/F24)+((F21*G21)/F24)+((F22*G22)/F24)+((F23*G23)/F24),0) -> 0.083055461 | H24: =SUM(H17:H23) -> 226088907 | I24: =SUM(I17:I23) -> 7796176 | J24: =SUM(J17:J23) -> 2483169 | K24: =SUM(K17:K23) -> 16722700 | L24: =SUM(L17:L23) -> 0 | M24: =SUM(M17:M23) -> 56411257 | N24: =SUM(N17:N23) -> 0 | O24: =SUM(O17:O23) -> 154501986 | ... Y24: =SUM(Y17:Y23) -> 1851000
B25: Транспорт и коммуникации
A26: =A24+10 -> 160 | B26: Физические лица | C26: =SUM(J26:Y26)-L26-P26-Q26 -> 0 | D26: 0 | E26: 0 | F26: 0 | G26: 0 | H26: 0 | I26: 0 | J26: 0 | K26: 0 | L26: 0 | M26: 0 | N26: 0 | O26: =+P26+Q26 -> 0 | P26: 0 | Q26: 0 | R26: 0 | S26: 0 | T26: 0 | U26: 0 | V26: 0 | W26: 0 | X26: 0 | Y26: 0
A27: =A26+10 -> 170 | B27: Государственные предприятия | C27: =SUM(J27:Y27)-L27-P27-Q27 -> 589323858 | D27: 567756915 | E27: 0.14567962 | F27: 21566943 | G27: 0.07 | H27: 589323858 | I27: 0 | J27: 216263967 | K27: 0 | L27: 0 | M27: 0 | N27: 0 | O27: =+P27+Q27 -> 126566943 | P27: 0 | Q27: 126566943 | R27: 0 | S27: 0 | T27: 0 | U27: 0 | V27: 246492948 | W27: 0 | X27: 0 | Y27: 0
A28: =A27+10 -> 180 | B28: Совместные и иностранные предприятия | C28: =SUM(J28:Y28)-L28-P28-Q28 -> 42849254 | D28: 42849254 | E28: 0.15 | F28: 0 | G28: 0 | H28: 42849254 | I28: 0 | J28: 0 | K28: 0 | L28: 0 | M28: 0 | N28: 0 | O28: =+P28+Q28 -> 42849254 | P28: 0 | Q28: 42849254 | R28: 0 | S28: 0 | T28: 0 | U28: 0 | V28: 0 | W28: 0 | X28: 0 | Y28: 0
A29: =A28+10 -> 190 | B29: Частные товарищества и корпорации | C29: =SUM(J29:Y29)-L29-P29-Q29 -> 172565751 | D29: 152567525 | E29: 0.21039498 | F29: 19998226 | G29: 0.097161077 | H29: 153739240 | I29: 18826511 | J29: 71947 | K29: 2116193 | L29: 0 | M29: 147518330 | N29: 0 | O29: =+P29+Q29 -> 22859281 | P29: 3977288 | Q29: 18881993 | R29: 0 | S29: 0 | T29: 0 | U29: 0 | V29: 0 | W29: 0 | X29: 0 | Y29: 0
A30: =A29+10 -> 200 | B30: Правительство | C30: =SUM(J30:Y30)-L30-P30-Q30 -> 0 | D30: 0 | E30: 0 | F30: 0 | G30: 0 | H30: 0 | I30: 0 | J30: 0 | K30: 0 | L30: 0 | M30: 0 | N30: 0 | O30: =+P30+Q30 -> 0 | P30: 0 | Q30: 0 | R30: 0 | S30: 0 | T30: 0 | U30: 0 | V30: 0 | W30: 0 | X30: 0 | Y30: 0
A31: =A30+10 -> 210 | B31: Прочие | C31: =SUM(J31:Y31)-L31-P31-Q31 -> 22064805 | D31: 22064805 | E31: 0.22706416 | F31: 0 | G31: 0 | H31: 22004191 | I31: 60614 | J31: 0 | K31: 0 | L31: 0 | M31: 21530497 | N31: 0 | O31: =+P31+Q31 -> 440369 | P31: 0 | Q31: 440369 | R31: 0 | S31: 0 | T31: 0 | U31: 0 | V31: 0 | W31: 93939 | X31: 0 | Y31: 0
A32: =A31+10 -> 220 | B32: Итого по транспорту и коммуникациям | C32: =SUM(J32:Y32)-L32-P32-Q32 -> 826803668 | D32: =SUM(D26:D31) -> 785238499 | E32: =IFERROR(((D26*E26)/D32)+((D27*E27)/D32)+((D28*E28)/D32)+((D29*E29)/D32)+((D30*E30)/D32)+((D31*E31)/D32),0) -> 0.16077608 | F32: =SUM(F26:F31) -> 41565169 | G32: =IFERROR(((F26*G26)/F32)+((F27*G27)/F32)+((F28*G28)/F32)+((F29*G29)/F32)+((F30*G30)/F32)+((F31*G31)/F32),0) -> 0.083067994 | H32: =SUM(H26:H31) -> 807916543 | I32: =SUM(I26:I31) -> 18887125 | J32: =SUM(J26:J31) -> 216335914 | K32: =SUM(K26:K31) -> 2116193 | L32: =SUM(L26:L31) -> 0 | M32: =SUM(M26:M31) -> 169048827 | N32: =SUM(N26:N31) -> 0 | O32: =SUM(O26:O31) -> 192715847 | ... Y32: =SUM(Y26:Y31) -> 0
B33: Строительство
A34: =A32+10 -> 230 | B34: Физические лица | C34: =SUM(J34:Y34)-L34-P34-Q34 -> 0 | D34: 0 | E34: 0 | F34: 0 | G34: 0 | H34: 0 | I34: 0 | J34: 0 | K34: 0 | L34: 0 | M34: 0 | N34: 0 | O34: =+P34+Q34 -> 0 | P34: 0 | Q34: 0 | R34: 0 | S34: 0 | T34: 0 | U34: 0 | V34: 0 | W34: 0 | X34: 0 | Y34: 0
A35: =A34+10 -> 240 | B35: Государственные предприятия | C35: =SUM(J35:Y35)-L35-P35-Q35 -> 2105944 | D35: 2105944 | E35: 0.23744138 | F35: 0 | G35: 0 | H35: 2105944 | I35: 0 | J35: 0 | K35: 0 | L35: 0 | M35: 2105944 | N35: 0 | O35: =+P35+Q35 -> 0 | P35: 0 | Q35: 0 | R35: 0 | S35: 0 | T35: 0 | U35: 0 | V35: 0 | W35: 0 | X35: 0 | Y35: 0
A36: =A35+10 -> 250 | B36: Совместные и иностранные предприятия | C36: =SUM(J36:Y36)-L36-P36-Q36 -> 41659965 | D36: 0 | E36: 0 | F36: 41659965 | G36: 0.0799 | H36: 41659965 | I36: 0 | J36: 0 | K36: 0 | L36: 0 | M36: 41659965 | N36: 0 | O36: =+P36+Q36 -> 0 | P36: 0 | Q36: 0 | R36: 0 | S36: 0 | T36: 0 | U36: 0 | V36: 0 | W36: 0 | X36: 0 | Y36: 0
A37: =A36+10 -> 260 | B37: Частные товарищества и корпорации | C37: =SUM(J37:Y37)-L37-P37-Q37 -> 488679857 | D37: 230310927 | E37: 0.19702013 | F37: 258368930 | G37: 0.073487435 | H37: 479037882 | I37: 9641975 | J37: 479711 | K37: 14985938 | L37: 0 | M37: 145672059 | N37: 0 | O37: =+P37+Q37 -> 325951531 | P37: 135817554 | Q37: 190133977 | R37: 0 | S37: 0 | T37: 0 | U37: 0 | V37: 305556 | W37: 1285062 | X37: 0 | Y37: 0
A38: =A37+10 -> 270 | B38: Правительство | C38: =SUM(J38:Y38)-L38-P38-Q38 -> 414350 | D38: 414350 | E38: 0.25 | F38: 0 | G38: 0 | H38: 414350 | I38: 0 | J38: 0 | K38: 0 | L38: 0 | M38: 0 | N38: 0 | O38: =+P38+Q38 -> 414350 | P38: 0 | Q38: 414350 | R38: 0 | S38: 0 | T38: 0 | U38: 0 | V38: 0 | W38: 0 | X38: 0 | Y38: 0
A39: =A38+10 -> 280 | B39: Прочие | C39: =SUM(J39:Y39)-L39-P39-Q39 -> 2143019 | D39: 2143019 | E39: 0.14526414 | F39: 0 | G39: 0 | H39: 2143019 | I39: 0 | J39: 0 | K39: 0 | L39: 0 | M39: 143020 | N39: 0 | O39: =+P39+Q39 -> 1999999 | P39: 0 | Q39: 1999999 | R39: 0 | S39: 0 | T39: 0 | U39: 0 | V39: 0 | W39: 0 | X39: 0 | Y39: 0
A40: =A39+10 -> 290 | B40: Итого по строительству | C40: =SUM(J40:Y40)-L40-P40-Q40 -> 535003135 | D40: =SUM(D34:D39) -> 234974240 | E40: =IFERROR(((D34*E34)/D40)+((D35*E35)/D40)+((D36*E36)/D40)+((D37*E37)/D40)+((D38*E38)/D40)+((D39*E39)/D40),0) -> 0.1970038 | F40: =SUM(F34:F39) -> 300028895 | G40: =IFERROR(((F34*G34)/F40)+((F35*G35)/F40)+((F36*G36)/F40)+((F37*G37)/F40)+((F38*G38)/F40)+((F39*G39)/F40),0) -> 0.07437784 | H40: =SUM(H34:H39) -> 525361160 | I40: =SUM(I34:I39) -> 9641975 | J40: =SUM(J34:J39) -> 479711 | K40: =SUM(K34:K39) -> 14985938 | L40: =SUM(L34:L39) -> 0 | M40: =SUM(M34:M39) -> 189580988 | N40: =SUM(N34:N39) -> 0 | O40: =SUM(O34:O39) -> 328365880 | ... Y40: =SUM(Y34:Y39) -> 0
B41: Торговля и общественное питание
...

Sheet Aging Analysis
A1: АНАЛИЗ ПРОСРОЧЕННЫХ КРЕДИТОВ И ФИНАНСОВОГО ЛИЗИНГА К ПОЛУЧЕНИЮ | X1: Таблица-9
B3: =+'Asset quality'!B3 -> АК "АЛОКАБАНК" | T3: =+'Asset quality'!P3 -> 44561 | X3: тыс. сум
A4: № | B4: Характеристики | C4: Всего задолжность по кредитам | D4: % | E4: Реструктуризированные кредиты | F4: % | G4: В ходе судебного разбирательства | H4: % | I4: Просроченная задолжность | K4: % | L4: в том числе, анализ временной задолженности
L5: 1-30 дней | N5: 31-60 дней | P5: 61-90 дней | R5: 91-180 дней | T5: 181-365 дней | V5: 366-730 дней | X5: Свыше 2 лет
I6: основной долг | J6: процент | L6: основной долг | M6: процент | N6: основной долг | O6: процент | P6: основной долг | Q6: процент | R6: основной долг | S6: процент | T6: основной долг | U6: процент | V6: основной долг | W6: процент | X6: основной долг | Y6: процент
B7: (А) | C7: (Б) | D7: (В) | E7: (Г) | F7: (Д) | G7: (Е) | H7: (Ж) | I7: (З) | J7: (З1) | K7: (И) | L7: (К) | M7: (К1) | N7: (Л) | O7: (Л1) | P7: (М) | Q7: (М1) | R7: (Н) | S7: (Н1) | T7: (О) | U7: (О1) | V7: (П) | W7: (П1) | X7: (Р) | Y7: (Р1)
B8: По типу клиента
A9: 1 | B9: Центральный банк | C9: =+'Loans Receivable'!C86 -> 0 | D9: =IF(C$22=0,"",C9/C$22) -> 0 | F9: =IF(E$22=0,"",E9/E$22) -> 0 | H9: =IF($G$22=0,"",G9/$G$22) -> 0 | I9: =+L9+N9+P9+R9+T9+V9+X9 -> 0 | J9: =+M9+O9+T9+S9+U9+W9+Y9 -> 0 | K9: =IF($Z$22=0,"",Z9/$Z$22) -> 0 | Z9: =+I9+J9 -> 0
A10: 2 | B10: Другие банки | C10: =+'Loans Receivable'!C85 -> 0 | D10: =IF(C$22=0,"",C10/C$22) -> 0 | F10: =IF(E$22=0,"",E10/E$22) -> 0 | H10: =IF($G$22=0,"",G10/$G$22) -> 0 | I10: =+L10+N10+P10+R10+T10+V10+X10 -> 0 | J10: =+M10+O10+Q10+S10+U10+W10+Y10 -> 0 | K10: =IF($Z$22=0,"",Z10/$Z$22) -> 0 | Z10: =+I10+J10 -> 0
A11: 3 | B11: Правительство | C11: =+'Loans Receivable'!C87 -> 660127 | D11: =IF(C$22=0,"",C11/C$22) -> 8.5130291e-05 | F11: =IF(E$22=0,"",E11/E$22) -> 0 | H11: =IF($G$22=0,"",G11/$G$22) -> 0 | I11: =+L11+N11+P11+R11+T11+V11+X11 -> 0 | J11: =+M11+O11+Q11+S11+U11+W11+Y11 -> 0 | K11: =IF($Z$22=0,"",Z11/$Z$22) -> 0 | Z11: =+I11+J11 -> 0
A12: 4 | B12: Физические лица | C12: =+'Loans Receivable'!C80 -> 1328984229 | D12: =IF(C$22=0,"",C12/C$22) -> 0.17138644 | F12: =IF(E$22=0,"",E12/E$22) -> 0 | H12: =IF($G$22=0,"",G12/$G$22) -> 0 | I12: =+L12+N12+P12+R12+T12+V12+X12 -> 21416469 | J12: =+M12+O12+Q12+S12+U12+W12+Y12 -> 8847933 | K12: =IF($Z$22=0,"",Z12/$Z$22) -> 0.26250251 | L12: 6983807 | M12: 1007743 | N12: 1852911 | O12: 469828 | P12: 1107576 | Q12: 326707 | R12: 3971731 | S12: 1389783 | T12: 3354745 | U12: 1563169 | V12: 3240354 | W12: 3808972 | X12: 905345 | Y12: 281731 | Z12: =+I12+J12 -> 30264402
A13: 5 | B13: Государственные предприятия | C13: =+'Loans Receivable'!C81 -> 1012848254 | D13: =IF(C$22=0,"",C13/C$22) -> 0.13061739 | F13: =IF(E$22=0,"",E13/E$22) -> 0 | H13: =IF($G$22=0,"",G13/$G$22) -> 0 | I13: =+L13+N13+P13+R13+T13+V13+X13 -> 750816 | J13: =+M13+O13+Q13+S13+U13+W13+Y13 -> 2258225 | K13: =IF($Z$22=0,"",Z13/$Z$22) -> 0.026099336 | L13: 750816 | M13: 33284 | N13: 0 | O13: 2224941 | R13: 0 | S13: 0 | Z13: =+I13+J13 -> 3009041
A14: 6 | B14: Совместные и иностранные предприятия | C14: =+'Loans Receivable'!C82 -> 286422166 | D14: =IF(C$22=0,"",C14/C$22) -> 0.036937139 | F14: =IF(E$22=0,"",E14/E$22) -> 0 | G14: 10587 | H14: =IF($G$22=0,"",G14/$G$22) -> 0.0012337027 | I14: =+L14+N14+P14+R14+T14+V14+X14 -> 342795 | J14: =+M14+O14+Q14+S14+U14+W14+Y14 -> 514 | K14: =IF($Z$22=0,"",Z14/$Z$22) -> 0.0029777384 | L14: 0 | M14: 0 | N14: 0 | O14: 0 | R14: 0 | S14: 514 | T14: 342795 | U14: 0 | X14: 0 | Y14: 0 | Z14: =+I14+J14 -> 343309
A15: 7 | B15: Частные товарищества и корпорации | C15: =+'Loans Receivable'!C83 -> 4899373487 | D15: =IF(C$22=0,"",C15/C$22) -> 0.63182553 | E15: 44554200 | F15: =IF(E$22=0,"",E15/E$22) -> 1 | G15: 7163339 | H15: =IF($G$22=0,"",G15/$G$22) -> 0.83474362 | I15: =+L15+N15+P15+R15+T15+V15+X15 -> 62040029 | J15: =+M15+O15+Q15+S15+U15+W15+Y15 -> 13553810 | K15: =IF($Z$22=0,"",Z15/$Z$22) -> 0.65567369 | L15: 9371337 | M15: 2211377 | N15: 2621766 | O15: 1412828 | P15: 1168166 | Q15: 294455 | R15: 22342065 | S15: 5456020 | T15: 15886265 | U15: 3082944 | V15: 8414225 | W15: 599682 | X15: 2236205 | Y15: 496504 | Z15: =+I15+J15 -> 75593839
A16: 8 | B16: Фермерское хозяйство | C16: =+'Loans Receivable'!C84 -> 31561978 | D16: =IF(C$22=0,"",C16/C$22) -> 0.0040702477 | F16: =IF(E$22=0,"",E16/E$22) -> 0 | H16: =IF($G$22=0,"",G16/$G$22) -> 0 | I16: =+L16+N16+P16+R16+T16+V16+X16 -> 506408 | J16: =+M16+O16+Q16+S16+U16+W16+Y16 -> 29567 | K16: =IF($Z$22=0,"",Z16/$Z$22) -> 0.0046488538 | L16: 13158 | M16: 20014 | P16: 0 | Q16: 9553 | X16: 493250 | Y16: 0 | Z16: =+I16+J16 -> 535975
A17: 9 | B17: Небанковские финансовые институты | C17: =+'Loans Receivable'!C88 -> 64423145 | D17: =IF(C$22=0,"",C17/C$22) -> 0.0083080394 | F17: =IF(E$22=0,"",E17/E$22) -> 0 | H17: =IF($G$22=0,"",G17/$G$22) -> 0 | I17: =+L17+N17+P17+R17+T17+V17+X17 -> 0 | J17: =+M17+O17+Q17+S17+U17+W17+Y17 -> 0 | K17: =IF($Z$22=0,"",Z17/$Z$22) -> 0 | L17: 0 | M17: 0 | Z17: =+I17+J17 -> 0
A18: 10 | B18: Негосударственные некоммерческие организации | C18: =+'Loans Receivable'!C89 -> 13925281 | D18: =IF(C$22=0,"",C18/C$22) -> 0.0017958109 | F18: =IF(E$22=0,"",E18/E$22) -> 0 | H18: =IF($G$22=0,"",G18/$G$22) -> 0 | I18: =+L18+N18+P18+R18+T18+V18+X18 -> 15570 | J18: =+M18+O18+Q18+S18+U18+W18+Y18 -> 1314 | K18: =IF($Z$22=0,"",Z18/$Z$22) -> 0.00014644573 | L18: 0 | M18: 50 | N18: 982 | O18: 1264 | R18: 0 | S18: 0 | T18: 0 | U18: 0 | V18: 14588 | W18: 0 | X18: 0 | Y18: 0 | Z18: =+I18+J18 -> 16884
A19: 11 | B19: Бюджетные организации | C19: =+'Loans Receivable'!C90 -> 0 | D19: =IF(C$22=0,"",C19/C$22) -> 0 | F19: =IF(E$22=0,"",E19/E$22) -> 0 | H19: =IF($G$22=0,"",G19/$G$22) -> 0 | I19: =+L19+N19+P19+R19+T19+V19+X19 -> 0 | J19: =+M19+O19+Q19+S19+U19+W19+Y19 -> 0 | K19: =IF($Z$22=0,"",Z19/$Z$22) -> 0 | Z19: =+I19+J19 -> 0
A20: 12 | B20: Прочие | C20: =+'Loans Receivable'!C91 -> 116115203 | D20: =IF(C$22=0,"",C20/C$22) -> 0.014974272 | F20: =IF(E$22=0,"",E20/E$22) -> 0 | G20: 1407558 | H20: =IF($G$22=0,"",G20/$G$22) -> 0.16402268 | I20: =+L20+N20+P20+R20+T20+V20+X20 -> 5208594 | J20: =+M20+O20+Q20+S20+U20+W20+Y20 -> 319815 | K20: =IF($Z$22=0,"",Z20/$Z$22) -> 0.047951426 | L20: 762450 | M20: 63465 | N20: 28511 | O20: 4219 | P20: 46545 | Q20: 21801 | R20: 769363 | S20: 187238 | T20: 1073592 | U20: 39440 | V20: 2012376 | W20: 3652 | X20: 515757 | Y20: 0 | Z20: =+I20+J20 -> 5528409
Z21: =+I21+J21 -> 0
A22: 13 | B22: Итого кредита и лизинга | C22: =SUM(C9:C20) -> 7754313870 | D22: =IF(C$22=0,"",C22/C$22) -> 1 | E22: =SUM(E9:E20) -> 44554200 | F22: =IF(E$22=0,"",E22/E$22) -> 1 | G22: =SUM(G9:G20) -> 8581484 | H22: =IF($G$22=0,"",G22/$G$22) -> 1 | I22: =SUM(I9:I20) -> 90280681 | J22: =SUM(J9:J20) -> 25011178 | K22: =IF($Z$22=0,"",Z22/$Z$22) -> 1 | L22: =SUM(L9:L20) -> 17881568 | M22: =SUM(M9:M20) -> 3335933 | N22: =SUM(N9:N20) -> 4504170 | O22: =SUM(O9:O20) -> 4113080 | P22: =SUM(P9:P20) -> 2322287 | Q22: =SUM(Q9:Q20) -> 652516 | R22: =SUM(R9:R20) -> 27083159 | S22: =SUM(S9:S20) -> 7033555 | ... Y22: =SUM(Y9:Y20) -> 778235 | Z22: =+I22+J22 -> 115291859
Z23: =+I23+J23 -> 0
B24: По сектору экономики | F24: =IF(E$22=0,"",E24/E$22) -> 0 | Z24: =+I24+J24 -> 0
A25: 14 | B25: Промышленность | C25: =+'Loans Receivable'!C15 -> 2695352702 | D25: =IF(C$34=0,"",C25/C$34) -> 0.34759396 | E25: 17028003 | F25: =IF($E$34=0,"",E25/$E$34) -> 0.38218626 | G25: 1908777 | H25: =IF($G$34=0,"",G25/$G$34) -> 0.22242971 | I25: =+L25+N25+P25+R25+T25+V25+X25 -> 21315945 | J25: =+M25+O25+Q25+S25+U25+W25+Y25 -> 7824082 | K25: =IF($Z$34=0,"",Z25/$Z$34) -> 0.25275008 | L25: 4989820 | M25: 694619 | N25: 1400145 | O25: 2576206 | P25: 440362 | Q25: 51690 | R25: 4898554 | S25: 1094983 | T25: 8124909 | U25: 2525435 | V25: 478870 | W25: 384644 | X25: 983285 | Y25: 496505 | Z25: =+I25+J25 -> 29140027
A26: 15 | B26: Сельское хозяйство | C26: =+'Loans Receivable'!C24 -> 233885083 | D26: =IF(C$34=0,"",C26/C$34) -> 0.030161931 | E26: 53826 | F26: =IF($E$34=0,"",E26/$E$34) -> 0.0012081016 | G26: 570157 | H26: =IF($G$34=0,"",G26/$G$34) -> 0.066440373 | I26: =+L26+N26+P26+R26+T26+V26+X26 -> 4198127 | J26: =+M26+O26+Q26+S26+U26+W26+Y26 -> 544168 | K26: =IF($Z$34=0,"",Z26/$Z$34) -> 0.041132956 | L26: 777206 | M26: 193249 | N26: 90242 | O26: 90340 | P26: 71734 | Q26: 45482 | R26: 736520 | S26: 203626 | T26: 2029175 | U26: 7819 | V26: 0 | W26: 3652 | X26: 493250 | Y26: 0 | Z26: =+I26+J26 -> 4742295
A27: 16 | B27: Транспорт и коммуникации | C27: =+'Loans Receivable'!C32 -> 826803668 | D27: =IF(C$34=0,"",C27/C$34) -> 0.10662499 | E27: 0 | F27: =IF($E$34=0,"",E27/$E$34) -> 0 | G27: 127871 | H27: =IF($G$34=0,"",G27/$G$34) -> 0.014900803 | I27: =+L27+N27+P27+R27+T27+V27+X27 -> 5107551 | J27: =+M27+O27+Q27+S27+U27+W27+Y27 -> 841528 | K27: =IF($Z$34=0,"",Z27/$Z$34) -> 0.051600165 | L27: 1727340 | M27: 316039 | N27: 11416 | O27: 43719 | P27: 466434 | Q27: 118847 | R27: 654740 | S27: 195014 | T27: 2247621 | U27: 167909 | V27: 0 | W27: 0 | X27: 0 | Y27: 0 | Z27: =+I27+J27 -> 5949079
A28: 17 | B28: Строительство | C28: =+'Loans Receivable'!C40 -> 535003135 | D28: =IF(C$34=0,"",C28/C$34) -> 0.068994258 | E28: 0 | F28: =IF($E$34=0,"",E28/$E$34) -> 0 | G28: 1252173 | H28: =IF($G$34=0,"",G28/$G$34) -> 0.14591567 | I28: =+L28+N28+P28+R28+T28+V28+X28 -> 5072127 | J28: =+M28+O28+Q28+S28+U28+W28+Y28 -> 1219058 | K28: =IF($Z$34=0,"",Z28/$Z$34) -> 0.05456747 | L28: 938081 | M28: 181817 | N28: 471607 | O28: 519589 | P28: 0 | Q28: 94718 | R28: 3217995 | S28: 422934 | T28: 444444 | U28: 0 | V28: 0 | W28: 0 | Z28: =+I28+J28 -> 6291185
A29: 18 | B29: Торговля и общественное питание | C29: =+'Loans Receivable'!C48 -> 706694385 | D29: =IF(C$34=0,"",C29/C$34) -> 0.091135644 | E29: 27472371 | F29: =IF($E$34=0,"",E29/$E$34) -> 0.61660564 | G29: 1206335 | H29: =IF($G$34=0,"",G29/$G$34) -> 0.14057417 | I29: =+L29+N29+P29+R29+T29+V29+X29 -> 20242736 | J29: =+M29+O29+Q29+S29+U29+W29+Y29 -> 4444074 | K29: =IF($Z$34=0,"",Z29/$Z$34) -> 0.21412449 | L29: 2069452 | M29: 742853 | N29: 199978 | O29: 28722 | P29: 236182 | Q29: 14806 | R29: 12456044 | S29: 3524791 | T29: 2314382 | U29: 132902 | V29: 2337303 | W29: 0 | X29: 629395 | Y29: 0 | Z29: =+I29+J29 -> 24686810
A30: 19 | B30: Материально-техническое снабжение и сбыт | C30: =+'Loans Receivable'!C56 -> 83306275 | D30: =IF(C$34=0,"",C30/C$34) -> 0.010743217 | F30: =IF($E$34=0,"",E30/$E$34) -> 0 | G30: 0 | H30: =IF($G$34=0,"",G30/$G$34) -> 0 | I30: =+L30+N30+P30+R30+T30+V30+X30 -> 8649925 | J30: =+M30+O30+Q30+S30+U30+W30+Y30 -> 71914 | K30: =IF($Z$34=0,"",Z30/$Z$34) -> 0.075650086 | L30: 38286 | M30: 3992 | N30: 476780 | O30: 0 | T30: 1175000 | U30: 67922 | V30: 6959859 | W30: 0 | X30: 0 | Y30: 0 | Z30: =+I30+J30 -> 8721839
A31: 20 | B31: Жилищно-коммунальные услуги | C31: =+'Loans Receivable'!C65 -> 62142553 | D31: =IF(C$34=0,"",C31/C$34) -> 0.0080139332 | F31: =IF($E$34=0,"",E31/$E$34) -> 0 | G31: 1553987 | H31: =IF($G$34=0,"",G31/$G$34) -> 0.18108605 | I31: =+L31+N31+P31+R31+T31+V31+X31 -> 1430600 | J31: =+M31+O31+Q31+S31+U31+W31+Y31 -> 220342 | K31: =IF($Z$34=0,"",Z31/$Z$34) -> 0.014319675 | L31: 19834 | M31: 2199 | N31: 1090 | O31: 1426 | R31: 59141 | S31: 1679 | T31: 169621 | U31: 0 | V31: 665157 | W31: 215038 | X31: 515757 | Y31: 0 | Z31: =+I31+J31 -> 1650942
A32: 21 | B32: Другие сектора | C32: =+'Loans Receivable'!C78 -> 2611126069 | D32: =IF(C$34=0,"",C32/C$34) -> 0.33673206 | F32: =IF($E$34=0,"",E32/$E$34) -> 0 | G32: 1962184 | H32: =IF($G$34=0,"",G32/$G$34) -> 0.22865323 | I32: =+L32+N32+P32+R32+T32+V32+X32 -> 24263670 | J32: =+M32+O32+Q32+S32+U32+W32+Y32 -> 9846012 | K32: =IF($Z$34=0,"",Z32/$Z$34) -> 0.29585508 | L32: 7321549 | M32: 1201165 | N32: 1852912 | O32: 853078 | P32: 1107575 | Q32: 326973 | R32: 5060165 | S32: 1590528 | T32: 4152245 | U32: 1783566 | V32: 3240354 | W32: 3808972 | X32: 1528870 | Y32: 281730 | Z32: =+I32+J32 -> 34109682
Z33: =+I33+J33 -> 0
A34: 22 | B34: Итого кредита и лизинга | C34: =SUM(C25:C32) -> 7754313870 | D34: =IF(C$34=0,"",C34/C$34) -> 1 | E34: =SUM(E25:E32) -> 44554200 | F34: =IF($E$34=0,"",E34/$E$34) -> 1 | G34: =SUM(G25:G32) -> 8581484 | H34: =IF($G$34=0,"",G34/$G$34) -> 1 | I34: =SUM(I25:I32) -> 90280681 | J34: =SUM(J25:J32) -> 25011178 | K34: =IF($Z$34=0,"",Z34/$Z$34) -> 1 | L34: =SUM(L25:L32) -> 17881568 | M34: =SUM(M25:M32) -> 3335933 | N34: =SUM(N25:N32) -> 4504170 | O34: =SUM(O25:O32) -> 4113080 | P34: =SUM(P25:P32) -> 2322287 | Q34: =SUM(Q25:Q32) -> 652516 | R34: =SUM(R25:R32) -> 27083159 | S34: =SUM(S25:S32) -> 7033555 | ... Y34: =SUM(Y25:Y32) -> 778235 | Z34: =+I34+J34 -> 115291859
B37: Подпись Председателя правления:
B39: Подпись Главного Бухгалтера:

Sheet Asset Classification
A1: ОТЧЕТ О КЛАССИФИКАЦИИ АКТИВОВ ПО СТЕПЕНИ РИСКА | W1: Таблица-10
B2: =+'Asset quality'!B3 -> АК "АЛОКАБАНК" | U2: =+'Asset quality'!P3 -> 44561 | Z2: тыс. сум
A3: № | B3: Статьи баланса | C3: Общая сумма | D3: из них, в иностранной валюте (в экв. в сумах) | E3: Стандартные | F3: из них, в иностранной валюте (в экв. в сумах) | G3: Общие резервы (1%) | H3: из них, в иностранной валюте (в экв. в сумах) | I3: Субстандартные | J3: из них, в иностранной валюте (в экв. в сумах) | K3: Специальные резервы (мин 10%) | L3: из них, в иностранной валюте (в экв. в сумах) | M3: Неудовлетворительные | N3: из них, в иностранной валюте (в экв. в сумах) | O3: Специальные резервы (мин 25%) | P3: из них, в иностранной валюте (в экв. в сумах) | Q3: Сомнительные | R3: из них, в иностранной валюте (в экв. в сумах) | S3: Специальные резервы (мин 50%) | T3: из них, в иностранной валюте (в экв. в сумах) | U3: Безнадежные | V3: из них, в иностранной валюте (в экв. в сумах) | W3: Специальные резервы (100%) | X3: из них, в иностранной валюте (в экв. в сумах) | Y3: Совокупная сумма специальных резервов | Z3: из них, в иностранной валюте (в экв. в сумах) | AA3: списанные кредиты за баланс в отчётном месяце | AB3: возврат списанных кредитов в отчётном месяце
A4: (А) | B4: (Б) | C4: (В) | D4: (В1) | E4: (Г) | F4: (Г1) | G4: (Д) | H4: (Д1) | I4: (Е) | J4: (Е1) | K4: (Ж) | L4: (Ж1) | M4: (З) | N4: (З1) | O4: (И) | P4: (И1) | Q4: (К) | R4: (К1) | S4: (Л) | T4: (Л1) | U4: (М) | V4: (М1) | W4: (Н) | X4: (Н1) | Y4: О=Ж+И+Л+Н | Z4: (О1)=(Ж1)+(И1)+(Л1)+(Н1) | AA4: П | AB4: Р
B5: По типу клиента
A6: 1 | B6: Центральный банк | C6: =E6+I6+M6+Q6+U6 -> 0 | D6: =F6+J6+N6+R6+V6 -> 0 | Y6: =+W6+S6+O6+K6 -> 0 | Z6: =+X6+T6+P6+L6 -> 0 | AC6: =+'Aging Analysis'!C9 -> 0
B7: из них необеспеченные | C7: =E7+I7+M7+Q7+U7 -> 0 | D7: =F7+J7+N7+R7+V7 -> 0 | Y7: =+W7+S7+O7+K7 -> 0 | Z7: =+X7+T7+P7+L7 -> 0
A8: 2 | B8: Другие банки | C8: =E8+I8+M8+Q8+U8 -> 0 | D8: =F8+J8+N8+R8+V8 -> 0 | Y8: =+W8+S8+O8+K8 -> 0 | Z8: =+X8+T8+P8+L8 -> 0 | AC8: =+'Aging Analysis'!C10 -> 0
B9: из них необеспеченные | C9: =E9+I9+M9+Q9+U9 -> 0 | D9: =F9+J9+N9+R9+V9 -> 0 | Y9: =+W9+S9+O9+K9 -> 0 | Z9: =+X9+T9+P9+L9 -> 0
A10: 3 | B10: Правительство | C10: =E10+I10+M10+Q10+U10 -> 660127 | D10: =F10+J10+N10+R10+V10 -> 0 | E10: 660127 | F10: 0 | G10: 5703 | H10: 0 | I10: 0 | J10: 0 | K10: 0 | L10: 0 | M10: 0 | N10: 0 | O10: 0 | P10: 0 | Q10: 0 | R10: 0 | S10: 0 | T10: 0 | U10: 0 | V10: 0 | W10: 0 | X10: 0 | Y10: =+W10+S10+O10+K10 -> 0 | Z10: =+X10+T10+P10+L10 -> 0 | AC10: =+'Aging Analysis'!C11 -> 660127
B11: из них необеспеченные | C11: =E11+I11+M11+Q11+U11 -> 0 | D11: =F11+J11+N11+R11+V11 -> 0 | E11: 0 | F11: 0 | G11: 0 | H11: 0 | I11: 0 | J11: 0 | K11: 0 | L11: 0 | M11: 0 | N11: 0 | O11: 0 | P11: 0 | Q11: 0 | R11: 0 | S11: 0 | T11: 0 | U11: 0 | V11: 0 | W11: 0 | X11: 0 | Y11: =+W11+S11+O11+K11 -> 0 | Z11: =+X11+T11+P11+L11 -> 0
A12: 4 | B12: Физические лица | C12: =E12+I12+M12+Q12+U12 -> 1328984229 | D12: =F12+J12+N12+R12+V12 -> 0 | E12: 1196175378 | F12: 0 | G12: 10334786 | H12: 0 | I12: 54715259 | J12: 0 | K12: 4895843 | L12: 0 | M12: 13772216 | N12: 0 | O12: 2687207 | P12: 0 | Q12: 22457893 | R12: 0 | S12: =10444374+145542 -> 10589916 | T12: 0 | U12: 41863483 | V12: 0 | W12: 27962194 | X12: 0 | Y12: =+W12+S12+O12+K12 -> 46135160 | Z12: =+X12+T12+P12+L12 -> 0 | AA12: 10700384 | AC12: =+'Aging Analysis'!C12 -> 1328984229
B13: из них необеспеченные | C13: =E13+I13+M13+Q13+U13 -> 0 | D13: =F13+J13+N13+R13+V13 -> 0 | E13: 0 | F13: 0 | G13: 0 | H13: 0 | I13: 0 | J13: 0 | K13: 0 | L13: 0 | M13: 0 | N13: 0 | O13: 0 | P13: 0 | Q13: 0 | R13: 0 | S13: 0 | T13: 0 | U13: 0 | V13: 0 | W13: 0 | X13: 0 | Y13: =+W13+S13+O13+K13 -> 0 | Z13: =+X13+T13+P13+L13 -> 0
A14: 5 | B14: Государственные предприятия | C14: =E14+I14+M14+Q14+U14 -> 1012848254 | D14: =F14+J14+N14+R14+V14 -> 355195636 | E14: 952098280 | F14: 355195636 | G14: 8225994 | H14: 0 | I14: 60749974 | J14: 0 | K14: 75082 | L14: 0 | M14: 0 | N14: 0 | O14: 0 | P14: 0 | Q14: 0 | R14: 0 | S14: 0 | T14: 0 | U14: 0 | V14: 0 | W14: 0 | X14: 0 | Y14: =+W14+S14+O14+K14 -> 75082 | Z14: =+X14+T14+P14+L14 -> 0 | AA14: 25644 | AC14: =+'Aging Analysis'!C13 -> 1012848254
B15: из них необеспеченные | C15: =E15+I15+M15+Q15+U15 -> 0 | D15: =F15+J15+N15+R15+V15 -> 0 | E15: 0 | F15: 0 | G15: 0 | H15: 0 | I15: 0 | J15: 0 | K15: 0 | L15: 0 | M15: 0 | N15: 0 | O15: 0 | P15: 0 | Q15: 0 | R15: 0 | S15: 0 | T15: 0 | U15: 0 | V15: 0 | W15: 0 | X15: 0 | Y15: =+W15+S15+O15+K15 -> 0 | Z15: =+X15+T15+P15+L15 -> 0
A16: 6 | B16: Совместные и иностранные предприятия | C16: =E16+I16+M16+Q16+U16 -> 286422166 | D16: =F16+J16+N16+R16+V16 -> 195898524 | E16: 239967236 | F16: 195898524 | G16: 2073283 | H16: 0 | I16: 44826548 | J16: 0 | K16: 0 | L16: 0 | M16: 1617795 | N16: 0 | O16: 161780 | P16: 0 | Q16: 0 | R16: 0 | S16: 0 | T16: 0 | U16: 10587 | V16: 0 | W16: 35587 | X16: 0 | Y16: =+W16+S16+O16+K16 -> 197367 | Z16: =+X16+T16+P16+L16 -> 0 | AC16: =+'Aging Analysis'!C14 -> 286422166
B17: из них необеспеченные | C17: =E17+I17+M17+Q17+U17 -> 0 | D17: =F17+J17+N17+R17+V17 -> 0 | E17: 0 | F17: 0 | G17: 0 | H17: 0 | I17: 0 | J17: 0 | K17: 0 | L17: 0 | M17: 0 | N17: 0 | O17: 0 | P17: 0 | Q17: 0 | R17: 0 | S17: 0 | T17: 0 | U17: 0 | V17: 0 | W17: 0 | X17: 0 | Y17: =+W17+S17+O17+K17 -> 0 | Z17: =+X17+T17+P17+L17 -> 0
A18: 7 | B18: Частные товарищества и корпорации | C18: =E18+I18+M18+Q18+U18 -> 4899373487 | D18: =F18+J18+N18+R18+V18 -> 2313477171 | E18: 4232045735 | F18: 2123010132 | G18: 36564277 | H18: 387773 | I18: 448813216 | J18: 101657876 | K18: 14065802 | L18: 8960696 | M18: 55373590 | N18: 48446241 | O18: 3354946 | P18: 2080260 | Q18: 50166487 | R18: 5277170 | S18: =5348256-145542 -> 5202714 | T18: 626974 | U18: 112974459 | V18: 35085752 | W18: =20374591+1397824 -> 21772415 | X18: 2951959 | Y18: =+W18+S18+O18+K18 -> 44395877 | Z18: =+X18+T18+P18+L18 -> 14619889 | AA18: 11159578 | AC18: =+'Aging Analysis'!C15 -> 4899373487
B19: из них необеспеченные | C19: =E19+I19+M19+Q19+U19 -> 0 | D19: =F19+J19+N19+R19+V19 -> 0 | E19: 0 | F19: 0 | G19: 0 | H19: 0 | I19: 0 | J19: 0 | K19: 0 | L19: 0 | M19: 0 | N19: 0 | O19: 0 | P19: 0 | Q19: 0 | R19: 0 | S19: 0 | T19: 0 | U19: 0 | V19: 0 | W19: 0 | X19: 0 | Y19: =+W19+S19+O19+K19 -> 0 | Z19: =+X19+T19+P19+L19 -> 0
A20: 8 | B20: Фермерское хозяйство | C20: =E20+I20+M20+Q20+U20 -> 31561978 | D20: =F20+J20+N20+R20+V20 -> 23828423 | E20: =30097106-850791 -> 29246315 | F20: 22217203 | G20: 252684 | H20: 0 | I20: 1822413 | J20: 1611220 | K20: 182241 | L20: 161122 | M20: 0 | N20: 0 | O20: 0 | P20: 0 | Q20: 0 | R20: 0 | S20: 0 | T20: 0 | U20: 493250 | V20: 0 | W20: 493250 | X20: 0 | Y20: =+W20+S20+O20+K20 -> 675491 | Z20: =+X20+T20+P20+L20 -> 161122 | AC20: =+'Aging Analysis'!C16 -> 31561978
B21: из них необеспеченные | C21: =E21+I21+M21+Q21+U21 -> 0 | D21: =F21+J21+N21+R21+V21 -> 0 | E21: 0 | F21: 0 | G21: 0 | H21: 0 | I21: 0 | J21: 0 | K21: 0 | L21: 0 | M21: 0 | N21: 0 | O21: 0 | P21: 0 | Q21: 0 | R21: 0 | S21: 0 | T21: 0 | U21: 0 | V21: 0 | W21: 0 | X21: 0 | Y21: =+W21+S21+O21+K21 -> 0 | Z21: =+X21+T21+P21+L21 -> 0
A22: 9 | B22: Небанковские финансовые институты | C22: =E22+I22+M22+Q22+U22 -> 64423145 | D22: =F22+J22+N22+R22+V22 -> 41906782 | E22: 64423145 | F22: 41906782 | G22: 556607 | H22: 0 | I22: 0 | J22: 0 | K22: 0 | L22: 0 | M22: 0 | N22: 0 | O22: 0 | P22: 0 | Q22: 0 | R22: 0 | S22: 0 | T22: 0 | U22: 0 | V22: 0 | W22: 0 | X22: 0 | Y22: =+W22+S22+O22+K22 -> 0 | Z22: =+X22+T22+P22+L22 -> 0 | AC22: =+'Aging Analysis'!C17 -> 64423145
B23: из них необеспеченные | C23: =E23+I23+M23+Q23+U23 -> 0 | D23: =F23+J23+N23+R23+V23 -> 0 | E23: 0 | F23: 0 | G23: 0 | H23: 0 | I23: 0 | J23: 0 | K23: 0 | L23: 0 | M23: 0 | N23: 0 | O23: 0 | P23: 0 | Q23: 0 | R23: 0 | S23: 0 | T23: 0 | U23: 0 | V23: 0 | W23: 0 | X23: 0 | Y23: =+W23+S23+O23+K23 -> 0 | Z23: =+X23+T23+P23+L23 -> 0
A24: 10 | B24: Негосударственные некоммерческие организации | C24: =E24+I24+M24+Q24+U24 -> 13925281 | D24: =F24+J24+N24+R24+V24 -> 6446959 | E24: =12166088-950000 -> 11216088 | F24: 6446959 | G24: 96905 | H24: 0 | I24: 730999 | J24: 0 | K24: 282308 | L24: 0 | M24: 0 | N24: 0 | O24: 0 | P24: 0 | Q24: 0 | R24: 0 | S24: 0 | T24: 0 | U24: 1978194 | V24: 0 | W24: 342200 | X24: 0 | Y24: =+W24+S24+O24+K24 -> 624508 | Z24: =+X24+T24+P24+L24 -> 0 | AA24: 3028371 | AC24: =+'Aging Analysis'!C18 -> 13925281
B25: из них необеспеченные | C25: =E25+I25+M25+Q25+U25 -> 0 | D25: =F25+J25+N25+R25+V25 -> 0 | E25: 0 | F25: 0 | G25: 0 | H25: 0 | I25: 0 | J25: 0 | K25: 0 | L25: 0 | M25: 0 | N25: 0 | O25: 0 | P25: 0 | Q25: 0 | R25: 0 | S25: 0 | T25: 0 | U25: 0 | V25: 0 | W25: 0 | X25: 0 | Y25: =+W25+S25+O25+K25 -> 0 | Z25: =+X25+T25+P25+L25 -> 0
A26: 11 | B26: Бюджетные организации | C26: =E26+I26+M26+Q26+U26 -> 0 | D26: =F26+J26+N26+R26+V26 -> 0 | E26: 0 | F26: 0 | G26: 0 | H26: 0 | I26: 0 | J26: 0 | K26: 0 | L26: 0 | M26: 0 | N26: 0 | O26: 0 | P26: 0 | Q26: 0 | R26: 0 | S26: 0 | T26: 0 | U26: 0 | V26: 0 | W26: 0 | X26: 0 | Y26: =+W26+S26+O26+K26 -> 0 | Z26: =+X26+T26+P26+L26 -> 0 | AC26: =+'Aging Analysis'!C19 -> 0
B27: из них необеспеченные | C27: =E27+I27+M27+Q27+U27 -> 0 | D27: =F27+J27+N27+R27+V27 -> 0 | E27: 0 | F27: 0 | G27: 0 | H27: 0 | I27: 0 | J27: 0 | K27: 0 | L27: 0 | M27: 0 | N27: 0 | O27: 0 | P27: 0 | Q27: 0 | R27: 0 | S27: 0 | T27: 0 | U27: 0 | V27: 0 | W27: 0 | X27: 0 | Y27: =+W27+S27+O27+K27 -> 0 | Z27: =+X27+T27+P27+L27 -> 0
A28: 12 | B28: Прочие | C28: =E28+I28+M28+Q28+U28 -> 116115203 | D28: =F28+J28+N28+R28+V28 -> 10141407 | E28: =95738441+1800786+1 -> 97539228 | F28: =10141405+2 -> 10141407 | G28: 842726 | H28: 0 | I28: =4950944+1 -> 4950945 | J28: 0 | K28: =1241279-1 -> 1241278 | L28: 0 | M28: 912319 | N28: 0 | O28: 279869 | P28: 0 | Q28: 1136647 | R28: 0 | S28: 251331 | T28: 0 | U28: 11576064 | V28: 0 | W28: 7118381 | X28: 0 | Y28: =+W28+S28+O28+K28 -> 8890859 | Z28: =+X28+T28+P28+L28 -> 0 | AA28: 831401 | AC28: =+'Aging Analysis'!C20 -> 116115203
B29: из них необеспеченные | C29: =E29+I29+M29+Q29+U29 -> 0 | D29: =F29+J29+N29+R29+V29 -> 0 | Y29: =+W29+S29+O29+K29 -> 0 | Z29: =+X29+T29+P29+L29 -> 0
A30: 13 | B30: Итого кредита и лизинга | C30: =+C6+C8+C10+C12+C14+C16+C18+C20+C22+C24+C26+C28 -> 7754313870 | D30: =+D6+D8+D10+D12+D14+D16+D18+D20+D22+D24+D26+D28 -> 2946894902 | E30: =+E6+E8+E10+E12+E14+E16+E18+E20+E22+E24+E26+E28 -> 6823371532 | F30: =+F6+F8+F10+F12+F14+F16+F18+F20+F22+F24+F26+F28 -> 2754816643 | G30: =+G6+G8+G10+G12+G14+G16+G18+G20+G22+G24+G26+G28 -> 58952965 | H30: =+H6+H8+H10+H12+H14+H16+H18+H20+H22+H24+H26+H28 -> 387773 | I30: =+I6+I8+I10+I12+I14+I16+I18+I20+I22+I24+I26+I28 -> 616609354 | J30: =+J6+J8+J10+J12+J14+J16+J18+J20+J22+J24+J26+J28 -> 103269096 | ... AB30: =+AB6+AB8+AB10+AB12+AB14+AB16+AB18+AB20+AB22+AB24+AB26+AB28 -> 0
B31: из них необеспеченные | C31: =+C7+C9+C11+C13+C15+C17+C19+C21+C23+C25+C27+C29 -> 0 | D31: =+D7+D9+D11+D13+D15+D17+D19+D21+D23+D25+D27+D29 -> 0 | E31: =+E7+E9+E11+E13+E15+E17+E19+E21+E23+E25+E27+E29 -> 0 | F31: =+F7+F9+F11+F13+F15+F17+F19+F21+F23+F25+F27+F29 -> 0 | G31: =+G7+G9+G11+G13+G15+G17+G19+G21+G23+G25+G27+G29 -> 0 | H31: =+H7+H9+H11+H13+H15+H17+H19+H21+H23+H25+H27+H29 -> 0 | I31: =+I7+I9+I11+I13+I15+I17+I19+I21+I23+I25+I27+I29 -> 0 | J31: =+J7+J9+J11+J13+J15+J17+J19+J21+J23+J25+J27+J29 -> 0 | ... Z31: =+Z7+Z9+Z11+Z13+Z15+Z17+Z19+Z21+Z23+Z25+Z27+Z29 -> 0
B32: По сектору экономики
A34: 14 | B34: Промышленность | C34: =E34+I34+M34+Q34+U34 -> 2695352702 | D34: =F34+J34+N34+R34+V34 -> 1760487337 | E34: 2279715182 | F34: 1643945482 | G34: 19696417 | H34: 0 | I34: 315188074 | J34: 36287914 | K34: 1618242 | L34: 172960 | M34: 48002941 | N34: 45168189 | O34: 356512 | P34: 0 | Q34: 3135982 | R34: 0 | S34: 690973 | T34: 0 | U34: 49310523 | V34: 35085752 | W34: =9240081+1397824 -> 10637905 | X34: 2951959 | Y34: =+W34+S34+O34+K34 -> 13303632 | Z34: =+X34+T34+P34+L34 -> 3124919 | AA34: 413675 | AC34: =+'Aging Analysis'!C25 -> 2695352702
B35: из них необеспеченные | C35: =E35+I35+M35+Q35+U35 -> 0 | D35: =F35+J35+N35+R35+V35 -> 0 | E35: 0 | F35: 0 | G35: 0 | H35: 0 | I35: 0 | J35: 0 | K35: 0 | L35: 0 | M35: 0 | N35: 0 | O35: 0 | P35: 0 | Q35: 0 | R35: 0 | S35: 0 | T35: 0 | U35: 0 | V35: 0 | W35: 0 | X35: 0 | Y35: =+W35+S35+O35+K35 -> 0 | Z35: =+X35+T35+P35+L35 -> 0
A36: 15 | B36: Сельское хозяйство | C36: =E36+I36+M36+Q36+U36 -> 233885083 | D36: =F36+J36+N36+R36+V36 -> 146279298 | E36: 185470746 | F36: 130192263 | G36: 1602441 | H36: 166782 | I36: 37547420 | J36: 14489979 | K36: 263171 | L36: 161122 | M36: 4182287 | N36: 1597056 | O36: 720633 | P36: 399264 | Q36: 1605227 | R36: 0 | S36: 485621 | T36: 0 | U36: 5079403 | V36: 0 | W36: 1788577 | X36: 0 | Y36: =+W36+S36+O36+K36 -> 3258002 | Z36: =+X36+T36+P36+L36 -> 560386 | AA36: 949693 | AC36: =+'Aging Analysis'!C26 -> 233885083
B37: из них необеспеченные | C37: =E37+I37+M37+Q37+U37 -> 0 | D37: =F37+J37+N37+R37+V37 -> 0 | E37: 0 | F37: 0 | G37: 0 | H37: 0 | I37: 0 | J37: 0 | K37: 0 | L37: 0 | M37: 0 | N37: 0 | O37: 0 | P37: 0 | Q37: 0 | R37: 0 | S37: 0 | T37: 0 | U37: 0 | V37: 0 | W37: 0 | X37: 0 | Y37: =+W37+S37+O37+K37 -> 0 | Z37: =+X37+T37+P37+L37 -> 0
A38: 16 | B38: Транспорт и коммуникации | C38: =E38+I38+M38+Q38+U38 -> 826803668 | D38: =F38+J38+N38+R38+V38 -> 41565170 | E38: =788901478-1 -> 788901477 | F38: 39235905 | G38: 6815997 | H38: 220991 | I38: 12905689 | J38: 1075317 | K38: 682641 | L38: 268829 | M38: 1814186 | N38: 0 | O38: 387864 | P38: 0 | Q38: 3443223 | R38: 1253948 | S38: 1565817 | T38: 626974 | U38: 19739093 | V38: 0 | W38: 1108585 | X38: 0 | Y38: =+W38+S38+O38+K38 -> 3744907 | Z38: =+X38+T38+P38+L38 -> 895803 | AA38: 175451 | AC38: =+'Aging Analysis'!C27 -> 826803668
B39: из них необеспеченные | C39: =E39+I39+M39+Q39+U39 -> 0 | D39: =F39+J39+N39+R39+V39 -> 0 | E39: 0 | F39: 0 | G39: 0 | H39: 0 | I39: 0 | J39: 0 | K39: 0 | L39: 0 | M39: 0 | N39: 0 | O39: 0 | P39: 0 | Q39: 0 | R39: 0 | S39: 0 | T39: 0 | U39: 0 | V39: 0 | W39: 0 | X39: 0 | Y39: =+W39+S39+O39+K39 -> 0 | Z39: =+X39+T39+P39+L39 -> 0
A40: 17 | B40: Строительство | C40: =E40+I40+M40+Q40+U40 -> 535003135 | D40: =F40+J40+N40+R40+V40 -> 300028895 | E40: =468449447+2 -> 468449449 | F40: 282688639 | G40: 4047337 | H40: 0 | I40: 60535377 | J40: 17340256 | K40: 163114 | L40: 0 | M40: 27701 | N40: 0 | O40: 6970 | P40: 0 | Q40: 2916332 | R40: 0 | S40: 915073 | T40: 0 | U40: 3074276 | V40: 0 | W40: 1765520 | X40: 0 | Y40: =+W40+S40+O40+K40 -> 2850677 | Z40: =+X40+T40+P40+L40 -> 0 | AA40: 1340662 | AC40: =+'Aging Analysis'!C28 -> 535003135
