Workbook
Name jop: #REF!
Name kol: #REF!
Name RISKTOTASS: SUM('[6]Calculation of Risk Weighted As'!$C$38:$F$38)
Name RISKTOTASS: SUM('[7]Calculation of Risk Weighted As'!$C$41:$G$41)
Name TwentyLargestData: #REF!
Name Е: #REF!

Sheet Asset quality
A1: ИНФОРМАЦИЯ О КАЧЕСТВЕ АКТИВОВ, ОЦЕНИВАЕМЫХ В ЦЕЛЯХ СОЗДАНИЯ РЕЗЕРВА НА ВОЗМОЖНЫЕ ПОТЕРИ | R1: Таблица-2 | U1: №4
B3: "Ўзсаноатқурилишбанк" АТБ | P3: 44560 | S3: тыс. сум
A4: № | B4: Состав активов* | C4: Остаток | D4: Категория качества | I4: Просроченная задолженность (брутто) | N4: Резерв на возможные потери
I5: итого | J5: до 30 дней | K5: от 31 до 90 дней | L5: от 91 до 180 дней | M5: свыше 180 дней | N5: фактически сформированный
N6: итого | O6: по категориям качества
D7: I | E7: II | F7: III | G7: IV | H7: V | O7: I | P7: II | Q7: III | R7: IV | S7: V
A8: А | B8: Б | C8: В | D8: Г | E8: Д | F8: Е | G8: Ж | H8: З | I8: И | J8: К | K8: Л | L8: М | M8: Н | N8: О | O8: П | P8: Р | Q8: С | R8: Т | S8: У
B9: ВСЕГО АКТИВОВ | C9: =SUM(C10:C60) -> 56511320290 | D9: =SUM(D10:D60) -> 53317941289 | E9: =SUM(E10:E60) -> 2660324543 | F9: =SUM(F10:F60) -> 904022544 | G9: =SUM(G10:G60) -> 209365860 | H9: =SUM(H10:H60) -> 610267679 | I9: =SUM(I10:I60) -> 444927648 | J9: =SUM(J10:J60) -> 82167000 | ... S9: =SUM(S10:S60) -> 608828633
A10: 1 | B10: Кассовая наличность и другие платежные документы | C10: =SUM(D10:H10)-N10+O10 -> 882034858 | D10: 882034858 | I10: =SUM(J10:M10) -> 0 | N10: =SUM(O10:S10) -> 0 | T10: 10100
A11: 2 | B11: К получению из ЦБРУ | C11: =SUM(D11:H11)-N11+O11 -> 3258433287 | D11: 3258433287 | I11: =SUM(J11:M11) -> 0 | N11: =SUM(O11:S11) -> 0 | T11: 10300
A12: 3 | B12: К получению из других банков | C12: =SUM(D12:H12)-N12+O12 -> 5865748703 | D12: 5865748703 | H12: 32812980 | I12: =SUM(J12:M12) -> 0 | N12: =SUM(O12:S12) -> 32812980 | S12: 32812980 | T12: 10500
A13: 4 | B13: Ценные бумаги для купли и продажи | C13: =SUM(D13:H13)-N13+O13 -> 1057702047 | D13: 1057702047 | I13: =SUM(J13:M13) -> 0 | N13: =SUM(O13:S13) -> 0 | T13: 10700
A14: 5 | B14: Инвестиции в ценные бумаги, имеющиеся в наличии для продажи | C14: =SUM(D14:H14)-N14+O14 -> 0 | I14: =SUM(J14:M14) -> 0 | N14: =SUM(O14:S14) -> 0 | T14: 10800
A15: 6 | B15: Драгоценные металлы, камни и монеты для купли и продажи | C15: =SUM(D15:H15)-N15+O15 -> 875 | D15: 875 | I15: =SUM(J15:M15) -> 0 | N15: =SUM(O15:S15) -> 0 | T15: 10900
A16: 7 | B16: Купленные дебиторские задолженности - Факторинг | C16: =SUM(D16:H16)-N16+O16 -> 179149000 | D16: 177213000 | E16: 0 | F16: 0 | G16: 4136000 | H16: 0 | I16: =SUM(J16:M16) -> 0 | J16: 0 | K16: 0 | L16: 0 | M16: 0 | N16: =SUM(O16:S16) -> 3319400 | O16: 1119400 | P16: 0 | Q16: 0 | R16: 2200000 | S16: 0 | T16: 11100
A17: 8 | B17: Купленные векселя | C17: =SUM(D17:H17)-N17+O17 -> 0 | D17: 0 | E17: 0 | F17: 0 | G17: 0 | H17: 0 | I17: =SUM(J17:M17) -> 0 | J17: 0 | K17: 0 | L17: 0 | M17: 0 | N17: =SUM(O17:S17) -> 0 | T17: 11300
A18: 9 | B18: Обязательства клиентов по траттам под аккредитив и/или трастовые документы | C18: =SUM(D18:H18)-N18+O18 -> 0 | D18: 0 | E18: 0 | F18: 0 | G18: 0 | H18: 0 | I18: =SUM(J18:M18) -> 0 | J18: 0 | K18: 0 | L18: 0 | M18: 0 | N18: =SUM(O18:S18) -> 0 | T18: 11500
A19: 10 | B19: Обязательства лиентов по непогашенным акцептам банка | C19: =SUM(D19:H19)-N19+O19 -> 0 | D19: 0 | E19: 0 | F19: 0 | G19: 0 | H19: 0 | I19: =SUM(J19:M19) -> 0 | J19: 0 | K19: 0 | L19: 0 | M19: 0 | N19: =SUM(O19:S19) -> 0 | T19: 11700
A20: 11 | B20: Купленные по сделкам РЕПО ценные бумаги | C20: =SUM(D20:H20)-N20+O20 -> 0 | D20: 0 | E20: 0 | F20: 0 | G20: 0 | H20: 0 | I20: =SUM(J20:M20) -> 0 | J20: 0 | K20: 0 | L20: 0 | M20: 0 | N20: =SUM(O20:S20) -> 0 | T20: 11800
A21: 12 | B21: Краткосрочные кредиты, предоставленные ЦБРУ | C21: =SUM(D21:H21)-N21+O21 -> 0 | D21: 0 | E21: 0 | F21: 0 | G21: 0 | H21: 0 | I21: =SUM(J21:M21) -> 0 | J21: 0 | K21: 0 | L21: 0 | M21: 0 | N21: =SUM(O21:S21) -> 0 | T21: 11900
A22: 13 | B22: Краткосрочные кредиты, предоставленные другим банкам | C22: =SUM(D22:H22)-N22+O22 -> 0 | D22: 0 | E22: 0 | F22: 0 | G22: 0 | H22: 0 | I22: =SUM(J22:M22) -> 0 | J22: 0 | K22: 0 | L22: 0 | M22: 0 | N22: =SUM(O22:S22) -> 0 | T22: 12100
A23: 14 | B23: Краткосрочные кредиты, предоставленные правительству | C23: =SUM(D23:H23)-N23+O23 -> 0 | D23: 0 | E23: 0 | F23: 0 | G23: 0 | H23: 0 | I23: =SUM(J23:M23) -> 0 | J23: 0 | K23: 0 | L23: 0 | M23: 0 | N23: =SUM(O23:S23) -> 0 | T23: 12300
A24: 15 | B24: Краткосрочные кредиты, предоставленные бюджетным организациям | C24: =SUM(D24:H24)-N24+O24 -> 0 | D24: 0 | E24: 0 | F24: 0 | G24: 0 | H24: 0 | I24: =SUM(J24:M24) -> 0 | J24: 0 | K24: 0 | L24: 0 | M24: 0 | N24: =SUM(O24:S24) -> 0 | T24: 12400
A25: 16 | B25: Краткосрочные кредиты, предоставленные физическим лицам | C25: =SUM(D25:H25)-N25+O25 -> 270725377 | D25: 260422937 | E25: 6723460 | F25: 3689520 | G25: 2878431 | H25: 12801703 | I25: =SUM(J25:M25) -> 19975764 | J25: 1125486 | K25: 3230490 | L25: 4195995 | M25: 11423793 | N25: =SUM(O25:S25) -> 19906610 | O25: 4115936 | P25: 675257 | Q25: 849815 | R25: 1440508 | S25: 12825094 | T25: 12500
A26: 17 | B26: Краткосрочные кредиты, предоставленные индивидуальным предпринимателям | C26: =SUM(D26:H26)-N26+O26 -> 5178513 | D26: 5178513 | E26: 0 | F26: 0 | G26: 0 | H26: 0 | I26: =SUM(J26:M26) -> 72191 | J26: 72191 | K26: 0 | L26: 0 | M26: 0 | N26: =SUM(O26:S26) -> 51548 | O26: 51548 | P26: 0 | Q26: 0 | R26: 0 | S26: 0 | T26: 12600
A27: 18 | B27: Краткосрочные кредиты, предоставленные государственным предприятиям, организациям и учреждениям | C27: =SUM(D27:H27)-N27+O27 -> 1172822365 | D27: 1157780426 | E27: 0 | F27: 20055918 | G27: 0 | H27: 0 | I27: =SUM(J27:M27) -> 2830414 | J27: 638933 | K27: 2191481 | L27: 0 | M27: 0 | N27: =SUM(O27:S27) -> 15701024 | O27: 10687045 | P27: 0 | Q27: 5013979 | R27: 0 | S27: 0 | T27: 12700
A28: 19 | B28: Краткосрочные кредиты, предоставленные при содействии Государственного фонда поддержки развития предпринимательской деятельности | C28: =SUM(D28:H28)-N28+O28 -> 385566106 | D28: 352934374 | E28: 23456657 | F28: 10007302 | G28: 8030530 | H28: 5624921 | I28: =SUM(J28:M28) -> 19766502 | J28: 595181 | K28: 8588158 | L28: 4958242 | M28: 5624921 | N28: =SUM(O28:S28) -> 18098290 | O28: 3610612 | P28: 2345666 | Q28: 2501826 | R28: 4015265 | S28: 5624921 | T28: 12800
A29: 20 | B29: Краткосрочные кредиты, предоставленные предприятиям с участием иностранного капитала | C29: =SUM(D29:H29)-N29+O29 -> 1255721060 | D29: 1248300235 | E29: 8245361 | F29: 0 | G29: 0 | H29: 0 | I29: =SUM(J29:M29) -> 0 | J29: 0 | K29: 0 | L29: 0 | M29: 0 | N29: =SUM(O29:S29) -> 9115961 | O29: 8291425 | P29: 824536 | Q29: 0 | R29: 0 | S29: 0 | T29: 12900
A30: 21 | B30: Краткосрочные кредиты, предоставленные негосударственным некоммерческим организациям | C30: =SUM(D30:H30)-N30+O30 -> 4955032 | D30: 4955032 | E30: 0 | F30: 0 | G30: 0 | H30: 17751 | I30: =SUM(J30:M30) -> 17751 | J30: 0 | K30: 0 | L30: 0 | M30: 17751 | N30: =SUM(O30:S30) -> 54898 | O30: 37147 | P30: 0 | Q30: 0 | R30: 0 | S30: 17751 | T30: 13000
A31: 22 | B31: Краткосрочные кредиты, предоставленные частным предприятиям, хозяйственным товариществам и обществам | C31: =SUM(D31:H31)-N31+O31 -> 2222258963 | D31: 2145337513 | E31: 31622585 | F31: 58080297 | G31: 10254530 | H31: 22399936 | I31: =SUM(J31:M31) -> 67443751 | J31: 8950479 | K31: 32910447 | L31: 9112217 | M31: 16470608 | N31: =SUM(O31:S31) -> 64393203 | O31: 18957305 | P31: 3388623 | Q31: 14520074 | R31: 5127265 | S31: 22399936 | T31: 13100
A32: 23 | B32: Краткосрочные кредиты, предоставленные небанковским финансовым институтам | C32: =SUM(D32:H32)-N32+O32 -> 0 | D32: 0 | E32: 0 | F32: 0 | G32: 0 | H32: 0 | I32: =SUM(J32:M32) -> 0 | J32: 0 | K32: 0 | L32: 0 | M32: 0 | N32: =SUM(O32:S32) -> 7332 | O32: 7332 | P32: 0 | Q32: 0 | R32: 0 | S32: 0 | T32: 13200
A33: 24 | B33: Краткосрочные кредиты, предоставленные для производства сельскохозяйственной продукции, закупаемой для государственных нужд | C33: =SUM(D33:H33)-N33+O33 -> 0 | D33: 0 | E33: 0 | F33: 0 | G33: 0 | H33: 0 | I33: =SUM(J33:M33) -> 0 | J33: 0 | K33: 0 | L33: 0 | M33: 0 | N33: =SUM(O33:S33) -> 0 | O33: 0 | P33: 0 | Q33: 0 | R33: 0 | S33: 0 | T33: 13300
A34: 25 | B34: Долгосрочные кредиты, предоставленные для производства сельскохозяйственной продукции, закупаемой для государственных нужд | C34: =SUM(D34:H34)-N34+O34 -> 0 | D34: 0 | E34: 0 | F34: 0 | G34: 0 | H34: 0 | I34: =SUM(J34:M34) -> 0 | J34: 0 | K34: 0 | L34: 0 | M34: 0 | N34: =SUM(O34:S34) -> 0 | O34: 0 | P34: 0 | Q34: 0 | R34: 0 | S34: 0 | T34: 14300
A35: 26 | B35: Долгосрочные кредиты, предоставленные при содействии Государственного фонда поддержки развития предпринимательской деятельности | C35: =SUM(D35:H35)-N35+O35 -> 3689745918 | D35: 2765184094 | E35: 678063715 | F35: 342934995 | G35: 90797045 | H35: 90790490 | I35: =SUM(J35:M35) -> 106023347 | J35: 19007471 | K35: 51203507 | L35: 15199133 | M35: 20613236 | N35: =SUM(O35:S35) -> 311577393 | O35: 33552972 | P35: 65759234 | Q35: 80343503 | R35: 41131194 | S35: 90790490 | T35: 14400
A36: 27 | B36: Долгосрочные кредиты, предоставленные другим банкам | C36: =SUM(D36:H36)-N36+O36 -> 0 | D36: 0 | E36: 0 | F36: 0 | G36: 0 | H36: 0 | I36: =SUM(J36:M36) -> 0 | J36: 0 | K36: 0 | L36: 0 | M36: 0 | N36: =SUM(O36:S36) -> 0 | O36: 0 | P36: 0 | Q36: 0 | R36: 0 | S36: 0 | T36: 14500
... A45: 36 | B45: Долгосрочные кредиты, предоставленные частным предприятиям, хозяйственным товариществам и обществам | C45: =SUM(D45:H45)-N45+O45 -> 10761924846 | D45: 9062510601 | E45: 1602208219 | F45: 289281856 | G45: 58966434 | H45: 263105172 | I45: =SUM(J45:M45) -> 131122318 | J45: 16577137 | K45: 31634183 | L45: 20023445 | M45: 62887553 | N45: =SUM(O45:S45) -> 594978537 | O45: 80831101 | P45: 155889606 | Q45: 68021241 | R45: 28133217 | S45: 262103372 | T45: 15500
A46: 37 | B46: Лизинг (Финансовая аренда) | C46: =SUM(D46:H46)-N46+O46 -> 428270722 | D46: 349829545 | E46: 96421569 | F46: 0 | G46: 0 | H46: 0 | I46: =SUM(J46:M46) -> 0 | N46: =SUM(O46:S46) -> 18160948 | O46: 180556 | P46: 17980392 | Q46: 0 | R46: 0 | S46: 0 | T46: 15600
A47: 38 | B47: Кредиты и лизинг, находящиеся в процессе судебного разбирательства | C47: =SUM(D47:H47)-N47+O47 -> 0 | D47: 0 | E47: 0 | F47: 0 | G47: 0 | H47: 1910833 | I47: =SUM(J47:M47) -> 0 | N47: =SUM(O47:S47) -> 1910833 | O47: 0 | P47: 0 | Q47: 0 | R47: 0 | S47: 1910833 | T47: 15700
A48: 39 | B48: Инвестиции в зависимые хозяйственные общества, совместные предприятия и дочерние хозяйственные общества | C48: =SUM(D48:H48)-N48+O48 -> 143665561 | D48: 143665561 | E48: 0 | F48: 0 | G48: 0 | H48: 8768330 | I48: =SUM(J48:M48) -> 0 | N48: =SUM(O48:S48) -> 8768330 | O48: 0 | P48: 0 | Q48: 0 | R48: 0 | S48: 8768330 | T48: 15800
A49: 40 | B49: Инвестиции в долговые ценные бумаги, удерживаемые до погашения | C49: =SUM(D49:H49)-N49+O49 -> 5850400 | D49: 5850400 | E49: 0 | F49: 0 | G49: 0 | H49: 0 | I49: =SUM(J49:M49) -> 0 | N49: =SUM(O49:S49) -> 0 | T49: 15900
...

Sheet Income 
B1: ОТЧЕТ О ФИНАНСОВЫХ РЕЗУЛЬТАТАХ | D1: Таблица-3
B3: =+'Asset quality'!B3 -> "Ўзсаноатқурилишбанк" АТБ | C3: =+'Asset quality'!P3 -> 44560 | E3: в тыс. сум
A4: № | B4: Категории | C4: Итого | D4: в национальной валюте | E4: в иностранной валюте (в экв. в сумах)
A5: 1. | B5: 1. ПРОЦЕНТНЫЕ ДОХОДЫ
A6: a. | B6: Процентные доходы по счетам в ЦБРУ | C6: =+D6+E6 -> 24773206 | D6: 24773206 | E6: 0
A7: б. | B7: Процентные доходы по счетам в других банках | C7: =+D7+E7 -> 111283999 | D7: 50273714 | E7: 61010285
A8: в. | B8: Процентные доходы по купленным векселям | C8: =+D8+E8 -> 0 | D8: 0 | E8: 0
A9: г. | B9: Процентные доходы по инвестициям | C9: =+D9+E9 -> 7062 | D9: 7062 | E9: 0
A10: д. | B10: Процентные доходы по счетам купли-продажи ценных бумаг | C10: =+D10+E10 -> 141257147 | D10: 141257147 | E10: 0
A11: е. | B11: Процентные доходы по обязательствам клиентов | C11: =+D11+E11 -> 0 | D11: 0 | E11: 0
A12: ж. | B12: Процентные доходы по обяз-вам клиентов по непогашенным акцептам этого банка | C12: =+D12+E12 -> 0 | D12: 0 | E12: 0
A13: з. | B13: Процент, Дисконт (Скидки) и взносы по кредитным и лизинговым операциям | C13: =+D13+E13 -> 3747119677 | D13: 2188567786 | E13: 1558551891
A14: и. | B14: Процентные доходы по соглашениям о покупке ценных бумаг с обратным выкупом | C14: =+D14+E14 -> 0 | D14: 0 | E14: 0
A15: к. | B15: Другие процентные доходы | C15: =+D15+E15 -> 459764028 | D15: 165775235 | E15: 293988793
A16: л. | B16: Итого процентных доходов | C16: =SUM(C6:C15) -> 4484205119 | D16: =SUM(D6:D15) -> 2570654150 | E16: =SUM(E6:E15) -> 1913550969 | G16: =+'Analysis of Interest'!C42 -> 4484205119
A18: 2. | B18: ПРОЦЕНТНЫЕ РАСХОДЫ
A19: а. | B19: Процентные расходы по депозитам до востребования | C19: =+D19+E19 -> 4877042 | D19: 4877042 | E19: 0
A20: б. | B20: Процентные расходы по срочным депозитам | C20: =+D20+E20 -> 570796508 | D20: 408713023 | E20: 162083485
A21: в. | B21: Процентные расходы по счетам к оплате в ЦБРУ | C21: =+D21+E21 -> 0 | D21: 0 | E21: 0
A22: г. | B22: Процентные расходы по счетам к оплате в другие банки | C22: =+D22+E22 -> 68795284 | D22: 44161279 | E22: 24634005
A23: д. | B23: Итого процентных расходов по депозитам | C23: =SUM(C19:C22) -> 644468834 | D23: =SUM(D19:D22) -> 457751344 | E23: =SUM(E19:E22) -> 186717490
A24: е. | B24: Процентные расходы по кредитам к оплате | C24: =+D24+E24 -> 1306417188 | D24: 568203179 | E24: 738214009
A25: ж. | B25: Процентные расходы по соглашениям о продаже ц/б с последующим выкупом | C25: =+D25+E25 -> 1998945 | D25: 1998945 | E25: 0
A26: з. | B26: Другие процентные расходы | C26: =+D26+E26 -> 464440298 | D26: 165136306 | E26: 299303992
A27: и. | B27: Итого процентных расходов по займам | C27: =SUM(C24:C26) -> 1772856431 | D27: =SUM(D24:D26) -> 735338430 | E27: =SUM(E24:E26) -> 1037518001
A28: л. | B28: Итого процентных расходов | C28: =C27+C23 -> 2417325265 | D28: =D27+D23 -> 1193089774 | E28: =E27+E23 -> 1224235491 | G28: =+'Analysis of Interest'!C72 -> 2417325265
A30: 3. | B30: ЧИСТЫЕ ПРОЦЕНТНЫЕ ДОХОДЫ ДО ОЦЕНКИ ВОЗМОЖНЫХ УБЫТКОВ ПО АКТИВАМ | C30: =C16-C28 -> 2066879854 | D30: =D16-D28 -> 1377564376 | E30: =E16-E28 -> 689315478
A31: а. | B31: Минус: Оценка возможных убытков по кредитам и лизингу | C31: =+D31+E31 -> 1408194349 | D31: 651352965 | E31: 756841384
A32: б. | B32: Минус: Оценка возможных убытков по в ценным бумагам | C32: =+D32+E32 -> 0 | D32: 0 | E32: 0
A33: в. | B33: Минус: Оценка возможных убытков по инвестициям | C33: =+D33+E33 -> 2520286 | D33: 2520286 | E33: 0
A34: г. | B34: Минус: Оценка возможных убытков по другим активам | C34: =+D34+E34 -> 36011316 | D34: 3649861 | E34: 32361455
A35: д. | B35: Чистые процентные доходы после оценки возможных убытков по кредитам и лизингу | C35: =C30-C31-C32-C33-C34 -> 620153903 | D35: =D30-D31-D32-D33-D34 -> 720041264 | E35: =E30-E31-E32-E33-E34 -> -99887361
A37: 4. | B37: БЕСПРОЦЕНТНЫЕ ДОХОДЫ
A38: а. | B38: Доходы от комиссий и платы за услуги | C38: =+D38+E38 -> 398095122 | D38: 338710462 | E38: 59384660
A39: б. | B39: Прибыль в иностранной валюте | C39: =+D39+E39 -> 401467426 | D39: 57673432 | E39: 343793994
A40: в. | B40: Прибыль от коммерческих операций | C40: =+D40+E40 -> 0 | D40: -15292 | E40: 15292
A41: г. | B41: Прибыль и дивиденды от инвестиций | C41: =+D41+E41 -> 20024032 | D41: 19961017 | E41: 63015
A42: д. | B42: Другие беспроцентные доходы | C42: =+D42+E42 -> 1344736998 | D42: 392678032 | E42: 952058966
B43: в том числе
A44: д1. | B44: Возврат резервов, с формированных на покрытие потерь по активам | C44: =+D44+E44 -> 1286186514 | D44: 371032293 | E44: 915154221
...

Sheet Analysis of Interest
B1: АНАЛИЗ ПРОЦЕНТНЫХ ДОХОДОВ И РАСХОДОВ | C1: Таблица-4
B3: =+'Asset quality'!B3 -> "Ўзсаноатқурилишбанк" АТБ | C3: =+'Asset quality'!P3 -> 44560
A4: № | B4: Категория | C4: в тыс. сум
A5: 1 . | B5: ПРОЦЕНТНЫЕ ДОХОДЫ ПО КРЕДИТНЫМ И ЛИЗИНГОВЫМ ОПЕРАЦИЯМ
A6: a. | B6: Кредиты и лизинговые операции ЦБРУ | C6: 0
A7: б. | B7: Кредиты и лизинговые операции другим банкам | C7: 19
A8: в. | B8: Кредиты и лизинговые операции Правительству | C8: 12007
A9: г. | B9: Кредиты и лизинговые операции физическим лицам | C9: 578565623
A10: д. | B10: Кредиты и лизинговые операции государственным предприятиям | C10: 902424692
A11: е. | B11: Кредиты и лизинговые операции совместным и иностранным предприятиям | C11: 529303119
A12: ж. | B12: Кредиты и лизинговые операции частным товариществам и корпорациям | C12: 1715606267
A13: з. | B13: Другие кредиты и лизинговые операции | C13: 21207950
A14: и. | B14: ИТОГО ПРОЦЕНТНЫХ ДОХОДОВ ПО КРЕДИТНЫМ И ЛИЗИНГОВЫМ ОПЕРАЦИЯМ | C14: =SUM(C6:C13) -> 3747119677
A16: 2. | B16: ПРОЦЕНТНЫЕ ДОХОДЫ ПО КОРРЕСПОНДЕНТСКИМ СЧЕТАМ
A17: a. | B17: К получению из ЦБРУ | C17: 24773206
A18: б. | B18: К получению из других банков | C18: 111283999
B19: ИТОГО ПРОЦЕНТНЫХ ДОХОДОВ ПО КОРРЕСПОНДЕНТСКИМ СЧЕТАМ | C19: =SUM(C17:C18) -> 136057205
A21: 3. | B21: ПРОЦЕНТНЫЕ ДОХОДЫ ПО СЧЕТАМ КУПЛИ-ПРОДАЖИ Ц/Б
A22: a. | B22: Государственные казначейские ценные бумаги | C22: 42674492
A23: б. | B23: Облигации и ценные бумаги ЦБРУ | C23: 98582655
A24: в. | B24: Ценные бумаги государственных корпораций | C24: 0
A25: г. | B25: Еврооблигации | C25: 0
A26: д. | B26: Частные ценные бумаги | C26: 0
A27: е. | B27: Другие ценные бумаги | C27: 0
A28: ж. | B28: ИТОГО ПРОЦЕНТНЫХ ДОХОДОВ ПО СЧЕТАМ КУПЛИ-ПРОДАЖИ Ц/Б | C28: =SUM(C22:C27) -> 141257147
A30: 4. | B30: ПРОЦЕНТНЫЕ ДОХОДЫ ПО ИНВЕСТИЦИЯМ
A31: a. | B31: Государственные облигации | C31: 0
A32: б. | B32: Облигации и ценные бумаги ЦБРУ | C32: 0
A33: в. | B33: Частные облигации | C33: 7062
A34: г. | B34: Еврооблигации | C34: 0
A35: д. | B35: Другие ценные бумаги | C35: 0
A36: е. | B36: ИТОГО ПРОЦЕНТНЫХ ДОХОДОВ ПО ИНВЕСТИЦИЯМ | C36: =SUM(C31:C35) -> 7062
A38: 5. | B38: ДРУГИЕ ПРОЦЕНТНЫЕ ДОХОДЫ
A39: a. | B39: Процентные доходы по соглашениям о покупке ц/б c обратным выкупом | C39: 0
A40: б. | B40: Другие процентные доходы | C40: 459764028
A42: 6. | B42: ИТОГО ПРОЦЕНТНЫХ ДОХОДОВ | C42: =C14+C19+C28+C36+C39+C40 -> 4484205119
A44: 7. | B44: ПРОЦЕНТНЫЕ РАСХОДЫ ПО ДЕПОЗИТАМ
A45: A. | B45: Депозиты до востребования
A46: a. | B46: Правительство | C46: 3067071
A47: б. | B47: Физические лица | C47: 0
...

Sheet Changes in Equity
B1: ИЗМЕНЕНИЯ В СОБСТВЕННОМ КАПИТАЛЕ | C1: Таблица-7
B3: =+'Asset quality'!B3 -> "Ўзсаноатқурилишбанк" АТБ | C3: =+'Asset quality'!P3 -> 44560
A4: № | B4: Категория | C4: в тыс. сум
A5: 1. | B5: Итого собственного капитала первоначально определенного за прошлый год | C5: 6704348045
A6: 2. | B6: Исправления в собственном капитале не показанные в отчете за прошлый год, чистые | C6: 0
A7: 3. | B7: Исправленный баланс на конец прошлого календарного года (сумма строк 1 и 2) | C7: =SUM(C5:C6) -> 6704348045
A8: 4. | B8: Чистый прибыль (убыток) по состоянию на дату от начала года | C8: =+'Income '!C79 -> 998221670 | D8: =+[8]Balance!$C$76 -> 998221670
A9: 5. | B9: Продажа, Обмен, Приобретение или выкуп акций, за текущий год (чистая выручка) | C9: 0
A10: 6. | B10: Изменения в оценочной стоимости прироста над первонач. стоимостью, за текущий год (чистые) | C10: -967983
A11: 7. | B11: МИНУС: Денежные дивиденды объявленные по привилегированным акциям | C11: 1616900
A12: 8. | B12: МИНУС: Денежные дивиденды объявленные по обыкновенным акциям
A13: 9. | B13: Другие статьи влияющие на собственный капитал за текущий год (чистые) | C13: 928274
A14: 10. | B14: Итого собственного капитала на конец текущего периода (сумма строк с 3 по 10) | C14: =C7+SUM(C8:C10)-SUM(C11:C12)+C13 -> 7700913106 | D14: =+[8]Balance!$C$77 -> 7700913106
B16: Подпись Председателя правления:
B18: Подпись Главного Бухгалтера:

Sheet Loans Receivable
A1: КРЕДИТЫ И ЛИЗИНГИ К ПОЛУЧЕНИЮ ПО ОТРАСЛЯМ ЭКОНОМИКИ, ТИПАМ КЛИЕНТОВ И ПО ТИПУ ОБЕСПЕЧЕНИЯ | W1: Таблица-8
B3: =+'Asset quality'!B3 -> "Ўзсаноатқурилишбанк" АТБ | T3: =+'Asset quality'!P3 -> 44560 | X3: тыс. сум
A4: № | B4: Отрасль экономики | C4: Сумма кредита | D4: в национальной валюте | F4: в иностранной валюте (в экв. в сумах) | H4: из них | J4: из них
D5: Сумма | E5: средне-взвешенные процентные ставки | F5: Сумма | G5: средне-взвешенные процентные ставки | H5: Начисляемые кредиты | I5: Кредиты переведённые в статус ненаращивания процентов | J5: Депозиты | K5: Гарантированные Правительством Республики Узбекистан | L5: из них | M5: Транспортные средства | N5: Инвентарь | O5: Недвижимость | P5: из них | R5: Оборудование | S5: Векселя (облигации) | T5: Акции | U5: Гарантия третьей стороны | V5: Поручительства третьей стороны | W5: Страховой полис | X5: Необеспеченные | Y5: Другое обеспечение
L6: Гарантированные Правительством Республики Узбекистан в иностранной валюте (экв.сум) | P6: жилая недвижимость | Q6: коммерческая недвижимость
A7: Код | B7: (А) | C7: (Б) | D7: (Б1) | E7: (Б2) | F7: (Б3) | G7: (Б4) | H7: (В) | I7: (Г) | J7: (Д) | K7: (Е) | L7: (Е1) | M7: (Ж) | N7: (З) | O7: (И) | P7: (И1) | Q7: (И2) | R7: (К) | S7: (Л) | T7: (М) | U7: (Н) | V7: (О) | W7: (П) | X7: (Р) | Y7: (С)
B8: Промышленность
A9: 10 | B9: Физические лица | C9: =SUM(J9:Y9)-L9-P9-Q9 -> 0 | D9: 0 | E9: 0 | F9: 0 | G9: 0 | H9: 0 | I9: 0 | J9: 0 | K9: 0 | L9: 0 | M9: 0 | N9: 0 | O9: =+P9+Q9 -> 0 | P9: 0 | Q9: 0 | R9: 0 | S9: 0 | T9: 0 | U9: 0 | V9: 0 | W9: 0 | X9: 0 | Y9: 0
A10: =A9+10 -> 20 | B10: Государственные предприятия | C10: =SUM(J10:Y10)-L10-P10-Q10 -> 10901588448 | D10: 3225091450 | E10: 0.1529786 | F10: 7676496998 | G10: 0.033415913 | H10: 10901588448 | I10: 0 | J10: 0 | K10: 5663025588 | L10: 4780389581 | M10: 28300887 | N10: 2700513 | O10: =+P10+Q10 -> 104702325 | P10: 0 | Q10: 104702325 | R10: 593340361 | S10: 0 | T10: 149473257 | U10: 0 | V10: 2196889788 | W10: 8872939 | X10: 184355457 | Y10: 1969927333
A11: =A10+10 -> 30 | B11: Совместные и иностранные предприятия | C11: =SUM(J11:Y11)-L11-P11-Q11 -> 5719876540 | D11: 826864403 | E11: 0.20247594 | F11: 4893012137 | G11: 0.061378042 | H11: 5619043697 | I11: 100832843 | J11: 0 | K11: 0 | L11: 0 | M11: 21345269 | N11: 126401211 | O11: =+P11+Q11 -> 1075928868 | P11: 0 | Q11: 1075928868 | R11: 2358648641 | S11: 0 | T11: 0 | U11: 0 | V11: 732365716 | W11: 780466338 | X11: 0 | Y11: 624720497
A12: =A11+10 -> 40 | B12: Частные товарищества и корпорации | C12: =SUM(J12:Y12)-L12-P12-Q12 -> 9718269506 | D12: 2598006651 | E12: 0.18609702 | F12: 7120262855 | G12: 0.065061377 | H12: 9453685941 | I12: 264583565 | J12: 807588 | K12: 0 | L12: 0 | M12: 72269850 | N12: 24051674 | O12: =+P12+Q12 -> 2565857985 | P12: 0 | Q12: 2565857985 | R12: 1292967858 | S12: 0 | T12: 0 | U12: 0 | V12: 4420062843 | W12: 772189080 | X12: 4136000 | Y12: 565926628
A13: =A12+10 -> 50 | B13: Правительство | C13: =SUM(J13:Y13)-L13-P13-Q13 -> 0 | D13: 0 | E13: 0 | F13: 0 | G13: 0 | H13: 0 | I13: 0 | J13: 0 | K13: 0 | L13: 0 | M13: 0 | N13: 0 | O13: =+P13+Q13 -> 0 | P13: 0 | Q13: 0 | R13: 0 | S13: 0 | T13: 0 | U13: 0 | V13: 0 | W13: 0 | X13: 0 | Y13: 0
A14: =A13+10 -> 60 | B14: Прочие | C14: =SUM(J14:Y14)-L14-P14-Q14 -> 0 | D14: 0 | E14: 0 | F14: 0 | G14: 0 | H14: 0 | I14: 0 | J14: 0 | K14: 0 | L14: 0 | M14: 0 | N14: 0 | O14: =+P14+Q14 -> 0 | P14: 0 | Q14: 0 | R14: 0 | S14: 0 | T14: 0 | U14: 0 | V14: 0 | W14: 0 | X14: 0 | Y14: 0
A15: =A14+10 -> 70 | B15: Итого по промышленности | C15: =SUM(J15:Y15)-L15-P15-Q15 -> 26339734494 | D15: =SUM(D9:D14) -> 6649962504 | E15: =IFERROR(((D9*E9)/D15)+((D10*E10)/D15)+((D11*E11)/D15)+((D12*E12)/D15)+((D13*E13)/D15)+((D14*E14)/D15),0) -> 0.17207186 | F15: =SUM(F9:F14) -> 19689771990 | G15: =IFERROR(((F9*G9)/F15)+((F10*G10)/F15)+((F11*G11)/F15)+((F12*G12)/F15)+((F13*G13)/F15)+((F14*G14)/F15),0) -> 0.051808358 | H15: =SUM(H9:H14) -> 25974318086 | I15: =SUM(I9:I14) -> 365416408 | J15: =SUM(J9:J14) -> 807588 | K15: =SUM(K9:K14) -> 5663025588 | L15: =SUM(L9:L14) -> 4780389581 | M15: =SUM(M9:M14) -> 121916006 | N15: =SUM(N9:N14) -> 153153398 | O15: =SUM(O9:O14) -> 3746489178 | ... Y15: =SUM(Y9:Y14) -> 3160574458
B16: Сельское хозяйство
A17: =A15+10 -> 80 | B17: Физические лица | C17: =SUM(J17:Y17)-L17-P17-Q17 -> 0 | D17: 0 | E17: 0 | F17: 0 | G17: 0 | H17: 0 | I17: 0 | J17: 0 | K17: 0 | L17: 0 | M17: 0 | N17: 0 | O17: =+P17+Q17 -> 0 | P17: 0 | Q17: 0 | R17: 0 | S17: 0 | T17: 0 | U17: 0 | V17: 0 | W17: 0 | X17: 0 | Y17: 0
A18: =A17+10 -> 90 | B18: Государственные предприятия | C18: =SUM(J18:Y18)-L18-P18-Q18 -> 0 | D18: 0 | E18: 0 | F18: 0 | G18: 0 | H18: 0 | I18: 0 | J18: 0 | K18: 0 | L18: 0 | M18: 0 | N18: 0 | O18: =+P18+Q18 -> 0 | P18: 0 | Q18: 0 | R18: 0 | S18: 0 | T18: 0 | U18: 0 | V18: 0 | W18: 0 | X18: 0 | Y18: 0
A19: =A18+10 -> 100 | B19: Совместные и иностранные предприятия | C19: =SUM(J19:Y19)-L19-P19-Q19 -> 467428932 | D19: 167783624 | E19: 0.20540486 | F19: 299645308 | G19: 0.080407866 | H19: 467428932 | I19: 0 | J19: 20271520 | K19: 0 | L19: 0 | M19: 13902225 | N19: 0 | O19: =+P19+Q19 -> 77377698 | P19: 0 | Q19: 77377698 | R19: 54239546 | S19: 0 | T19: 0 | U19: 0 | V19: 18489453 | W19: 283148490 | X19: 0 | Y19: 0
A20: =A19+10 -> 110 | B20: Частные товарищества и корпорации | C20: =SUM(J20:Y20)-L20-P20-Q20 -> 2450112877 | D20: 1103868617 | E20: 0.15172089 | F20: 1346244260 | G20: 0.064523828 | H20: 2378832994 | I20: 71279883 | J20: 201368 | K20: 0 | L20: 0 | M20: 53811738 | N20: 0 | O20: =+P20+Q20 -> 612560342 | P20: 0 | Q20: 612560342 | R20: 132025690 | S20: 0 | T20: 0 | U20: 0 | V20: 1208907558 | W20: 442606181 | X20: 0 | Y20: 0
A21: =A20+10 -> 120 | B21: Фермерское хозяйство | C21: =SUM(J21:Y21)-L21-P21-Q21 -> 225782941 | D21: 95332387 | E21: 0.20482658 | F21: 130450554 | G21: 0.063385128 | H21: 207991833 | I21: 17791108 | J21: 0 | K21: 0 | L21: 0 | M21: 4137819 | N21: 0 | O21: =+P21+Q21 -> 91963803 | P21: 0 | Q21: 91963803 | R21: 39403711 | S21: 0 | T21: 0 | U21: 0 | V21: 87239195 | W21: 3038413 | X21: 0 | Y21: 0
A22: =A21+10 -> 130 | B22: Правительство | C22: =SUM(J22:Y22)-L22-P22-Q22 -> 0 | D22: 0 | E22: 0 | F22: 0 | G22: 0 | H22: 0 | I22: 0 | J22: 0 | K22: 0 | L22: 0 | M22: 0 | N22: 0 | O22: =+P22+Q22 -> 0 | P22: 0 | Q22: 0 | R22: 0 | S22: 0 | T22: 0 | U22: 0 | V22: 0 | W22: 0 | X22: 0 | Y22: 0
A23: =A22+10 -> 140 | B23: Прочие | C23: =SUM(J23:Y23)-L23-P23-Q23 -> 0 | D23: 0 | E23: 0 | F23: 0 | G23: 0 | H23: 0 | I23: 0 | J23: 0 | K23: 0 | L23: 0 | M23: 0 | N23: 0 | O23: =+P23+Q23 -> 0 | P23: 0 | Q23: 0 | R23: 0 | S23: 0 | T23: 0 | U23: 0 | V23: 0 | W23: 0 | X23: 0 | Y23: 0
A24: =A23+10 -> 150 | B24: Итого по сельскому хозяйству | C24: =SUM(J24:Y24)-L24-P24-Q24 -> 3143324750 | D24: =SUM(D17:D23) -> 1366984628 | E24: =IFERROR(((D17*E17)/D24)+((D18*E18)/D24)+((D19*E19)/D24)+((D20*E20)/D24)+((D21*E21)/D24)+((D22*E22)/D24)+((D23*E23)/D24),0) -> 0.16201361 | F24: =SUM(F17:F23) -> 1776340122 | G24: =IFERROR(((F17*G17)/F24)+((F18*G18)/F24)+((F19*G19)/F24)+((F20*G20)/F24)+((F21*G21)/F24)+((F22*G22)/F24)+((F23*G23)/F24),0) -> 0.067119634 | H24: =SUM(H17:H23) -> 3054253759 | I24: =SUM(I17:I23) -> 89070991 | J24: =SUM(J17:J23) -> 20472888 | K24: =SUM(K17:K23) -> 0 | L24: =SUM(L17:L23) -> 0 | M24: =SUM(M17:M23) -> 71851782 | N24: =SUM(N17:N23) -> 0 | O24: =SUM(O17:O23) -> 781901843 | ... Y24: =SUM(Y17:Y23) -> 0
B25: Транспорт и коммуникации
A26: =A24+10 -> 160 | B26: Физические лица | C26: =SUM(J26:Y26)-L26-P26-Q26 -> 0 | D26: 0 | E26: 0 | F26: 0 | G26: 0 | H26: 0 | I26: 0 | J26: 0 | K26: 0 | L26: 0 | M26: 0 | N26: 0 | O26: =+P26+Q26 -> 0 | P26: 0 | Q26: 0 | R26: 0 | S26: 0 | T26: 0 | U26: 0 | V26: 0 | W26: 0 | X26: 0 | Y26: 0
A27: =A26+10 -> 170 | B27: Государственные предприятия | C27: =SUM(J27:Y27)-L27-P27-Q27 -> 2661090173 | D27: 149896707 | E27: 0.15552445 | F27: 2511193466 | G27: 0.045970914 | H27: 2661090173 | I27: 0 | J27: 925716792 | K27: 1419745546 | L27: 1419745546 | M27: 0 | N27: 0 | O27: =+P27+Q27 -> 0 | P27: 0 | Q27: 0 | R27: 40151764 | S27: 0 | T27: 0 | U27: 0 | V27: 140492605 | W27: 0 | X27: 0 | Y27: 134983466
A28: =A27+10 -> 180 | B28: Совместные и иностранные предприятия | C28: =SUM(J28:Y28)-L28-P28-Q28 -> 0 | D28: 0 | E28: 0 | F28: 0 | G28: 0 | H28: 0 | I28: 0 | J28: 0 | K28: 0 | L28: 0 | M28: 0 | N28: 0 | O28: =+P28+Q28 -> 0 | P28: 0 | Q28: 0 | R28: 0 | S28: 0 | T28: 0 | U28: 0 | V28: 0 | W28: 0 | X28: 0 | Y28: 0
A29: =A28+10 -> 190 | B29: Частные товарищества и корпорации | C29: =SUM(J29:Y29)-L29-P29-Q29 -> 802602741 | D29: 232327864 | E29: 0.19310281 | F29: 570274877 | G29: 0.070537949 | H29: 795277354 | I29: 7325387 | J29: 286367 | K29: 0 | L29: 0 | M29: 50781760 | N29: 0 | O29: =+P29+Q29 -> 446610676 | P29: 0 | Q29: 446610676 | R29: 39370581 | S29: 0 | T29: 0 | U29: 0 | V29: 235772789 | W29: 29780568 | X29: 0 | Y29: 0
A30: =A29+10 -> 200 | B30: Правительство | C30: =SUM(J30:Y30)-L30-P30-Q30 -> 0 | D30: 0 | E30: 0 | F30: 0 | G30: 0 | H30: 0 | I30: 0 | J30: 0 | K30: 0 | L30: 0 | M30: 0 | N30: 0 | O30: =+P30+Q30 -> 0 | P30: 0 | Q30: 0 | R30: 0 | S30: 0 | T30: 0 | U30: 0 | V30: 0 | W30: 0 | X30: 0 | Y30: 0
A31: =A30+10 -> 210 | B31: Прочие | C31: =SUM(J31:Y31)-L31-P31-Q31 -> 0 | D31: 0 | E31: 0 | F31: 0 | G31: 0 | H31: 0 | I31: 0 | J31: 0 | K31: 0 | L31: 0 | M31: 0 | N31: 0 | O31: =+P31+Q31 -> 0 | P31: 0 | Q31: 0 | R31: 0 | S31: 0 | T31: 0 | U31: 0 | V31: 0 | W31: 0 | X31: 0 | Y31: 0
A32: =A31+10 -> 220 | B32: Итого по транспорту и коммуникациям | C32: =SUM(J32:Y32)-L32-P32-Q32 -> 3463692914 | D32: =SUM(D26:D31) -> 382224571 | E32: =IFERROR(((D26*E26)/D32)+((D27*E27)/D32)+((D28*E28)/D32)+((D29*E29)/D32)+((D30*E30)/D32)+((D31*E31)/D32),0) -> 0.17836574 | F32: =SUM(F26:F31) -> 3081468343 | G32: =IFERROR(((F26*G26)/F32)+((F27*G27)/F32)+((F28*G28)/F32)+((F29*G29)/F32)+((F30*G30)/F32)+((F31*G31)/F32),0) -> 0.050517436 | H32: =SUM(H26:H31) -> 3456367527 | I32: =SUM(I26:I31) -> 7325387 | J32: =SUM(J26:J31) -> 926003159 | K32: =SUM(K26:K31) -> 1419745546 | L32: =SUM(L26:L31) -> 1419745546 | M32: =SUM(M26:M31) -> 50781760 | N32: =SUM(N26:N31) -> 0 | O32: =SUM(O26:O31) -> 446610676 | ... Y32: =SUM(Y26:Y31) -> 134983466
B33: Строительство
A34: =A32+10 -> 230 | B34: Физические лица | C34: =SUM(J34:Y34)-L34-P34-Q34 -> 0 | D34: 0 | E34: 0 | F34: 0 | G34: 0 | H34: 0 | I34: 0 | J34: 0 | K34: 0 | L34: 0 | M34: 0 | N34: 0 | O34: =+P34+Q34 -> 0 | P34: 0 | Q34: 0 | R34: 0 | S34: 0 | T34: 0 | U34: 0 | V34: 0 | W34: 0 | X34: 0 | Y34: 0
A35: =A34+10 -> 240 | B35: Государственные предприятия | C35: =SUM(J35:Y35)-L35-P35-Q35 -> 6882287 | D35: 6882287 | E35: 0.20801222 | F35: 0 | G35: 0 | H35: 6882287 | I35: 0 | J35: 0 | K35: 0 | L35: 0 | M35: 63160 | N35: 0 | O35: =+P35+Q35 -> 749542 | P35: 0 | Q35: 749542 | R35: 151943 | S35: 0 | T35: 0 | U35: 0 | V35: 5917642 | W35: 0 | X35: 0 | Y35: 0
A36: =A35+10 -> 250 | B36: Совместные и иностранные предприятия | C36: =SUM(J36:Y36)-L36-P36-Q36 -> 61669227 | D36: 135253 | E36: 0.14722624 | F36: 61533974 | G36: 0.091082347 | H36: 61669227 | I36: 0 | J36: 0 | K36: 0 | L36: 0 | M36: 7370880 | N36: 0 | O36: =+P36+Q36 -> 15104184 | P36: 0 | Q36: 15104184 | R36: 10569920 | S36: 0 | T36: 0 | U36: 0 | V36: 28607405 | W36: 16838 | X36: 0 | Y36: 0
A37: =A36+10 -> 260 | B37: Частные товарищества и корпорации | C37: =SUM(J37:Y37)-L37-P37-Q37 -> 755129016 | D37: 337185987 | E37: 0.21626595 | F37: 417943029 | G37: 0.071381125 | H37: 740014039 | I37: 15114977 | J37: 62345 | K37: 0 | L37: 0 | M37: 22713795 | N37: 262779 | O37: =+P37+Q37 -> 234546898 | P37: 0 | Q37: 234546898 | R37: 15497448 | S37: 0 | T37: 0 | U37: 700000 | V37: 443622129 | W37: 37723622 | X37: 0 | Y37: 0
A38: =A37+10 -> 270 | B38: Правительство | C38: =SUM(J38:Y38)-L38-P38-Q38 -> 0 | D38: 0 | E38: 0 | F38: 0 | G38: 0 | H38: 0 | I38: 0 | J38: 0 | K38: 0 | L38: 0 | M38: 0 | N38: 0 | O38: =+P38+Q38 -> 0 | P38: 0 | Q38: 0 | R38: 0 | S38: 0 | T38: 0 | U38: 0 | V38: 0 | W38: 0 | X38: 0 | Y38: 0
A39: =A38+10 -> 280 | B39: Прочие | C39: =SUM(J39:Y39)-L39-P39-Q39 -> 0 | D39: 0 | E39: 0 | F39: 0 | G39: 0 | H39: 0 | I39: 0 | J39: 0 | K39: 0 | L39: 0 | M39: 0 | N39: 0 | O39: =+P39+Q39 -> 0 | P39: 0 | Q39: 0 | R39: 0 | S39: 0 | T39: 0 | U39: 0 | V39: 0 | W39: 0 | X39: 0 | Y39: 0
A40: =A39+10 -> 290 | B40: Итого по строительству | C40: =SUM(J40:Y40)-L40-P40-Q40 -> 823680530 | D40: =SUM(D34:D39) -> 344203527 | E40: =IFERROR(((D34*E34)/D40)+((D35*E35)/D40)+((D36*E36)/D40)+((D37*E37)/D40)+((D38*E38)/D40)+((D39*E39)/D40),0) -> 0.21607379 | F40: =SUM(F34:F39) -> 479477003 | G40: =IFERROR(((F34*G34)/F40)+((F35*G35)/F40)+((F36*G36)/F40)+((F37*G37)/F40)+((F38*G38)/F40)+((F39*G39)/F40),0) -> 0.073909494 | H40: =SUM(H34:H39) -> 808565553 | I40: =SUM(I34:I39) -> 15114977 | J40: =SUM(J34:J39) -> 62345 | K40: =SUM(K34:K39) -> 0 | L40: =SUM(L34:L39) -> 0 | M40: =SUM(M34:M39) -> 30147835 | N40: =SUM(N34:N39) -> 262779 | O40: =SUM(O34:O39) -> 250400624 | ... Y40: =SUM(Y34:Y39) -> 0
B41: Торговля и общественное питание
...

Sheet Aging Analysis
A1: АНАЛИЗ ПРОСРОЧЕННЫХ КРЕДИТОВ И ФИНАНСОВОГО ЛИЗИНГА К ПОЛУЧЕНИЮ | X1: Таблица-9
B3: =+'Asset quality'!B3 -> "Ўзсаноатқурилишбанк" АТБ | T3: =+'Asset quality'!P3 -> 44560 | X3: тыс. сум
A4: № | B4: Характеристики | C4: Всего задолжность по кредитам | D4: % | E4: Реструктуризированные кредиты | F4: % | G4: В ходе судебного разбирательства | H4: % | I4: Просроченная задолжность | K4: % | L4: в том числе, анализ временной задолженности
L5: 1-30 дней | N5: 31-60 дней | P5: 61-90 дней | R5: 91-180 дней | T5: 181-365 дней | V5: 366-730 дней | X5: Свыше 2 лет
I6: основной долг | J6: процент | L6: основной долг | M6: процент | N6: основной долг | O6: процент | P6: основной долг | Q6: процент | R6: основной долг | S6: процент | T6: основной долг | U6: процент | V6: основной долг | W6: процент | X6: основной долг | Y6: процент
B7: (А) | C7: (Б) | D7: (В) | E7: (Г) | F7: (Д) | G7: (Е) | H7: (Ж) | I7: (З) | J7: (З1) | K7: (И) | L7: (К) | M7: (К1) | N7: (Л) | O7: (Л1) | P7: (М) | Q7: (М1) | R7: (Н) | S7: (Н1) | T7: (О) | U7: (О1) | V7: (П) | W7: (П1) | X7: (Р) | Y7: (Р1)
B8: По типу клиента
A9: 1 | B9: Центральный банк | C9: =+'Loans Receivable'!C86 -> 0 | D9: =IF(C$22=0,"",C9/C$22) -> 0 | E9: 0 | F9: =IF(E$22=0,"",E9/E$22) -> 0 | G9: 0 | H9: =IF($G$22=0,"",G9/$G$22) -> 0 | I9: =+L9+N9+P9+R9+T9+V9+X9 -> 0 | J9: =+M9+O9+T9+S9+U9+W9+Y9 -> 0 | K9: =IF($Z$22=0,"",Z9/$Z$22) -> 0 | Z9: =+I9+J9 -> 0
A10: 2 | B10: Другие банки | C10: =+'Loans Receivable'!C85 -> 0 | D10: =IF(C$22=0,"",C10/C$22) -> 0 | E10: 0 | F10: =IF(E$22=0,"",E10/E$22) -> 0 | G10: 0 | H10: =IF($G$22=0,"",G10/$G$22) -> 0 | I10: =+L10+N10+P10+R10+T10+V10+X10 -> 0 | J10: =+M10+O10+Q10+S10+U10+W10+Y10 -> 0 | K10: =IF($Z$22=0,"",Z10/$Z$22) -> 0 | Z10: =+I10+J10 -> 0
A11: 3 | B11: Правительство | C11: =+'Loans Receivable'!C87 -> 0 | D11: =IF(C$22=0,"",C11/C$22) -> 0 | E11: 0 | F11: =IF(E$22=0,"",E11/E$22) -> 0 | G11: 0 | H11: =IF($G$22=0,"",G11/$G$22) -> 0 | I11: =+L11+N11+P11+R11+T11+V11+X11 -> 0 | J11: =+M11+O11+Q11+S11+U11+W11+Y11 -> 0 | K11: =IF($Z$22=0,"",Z11/$Z$22) -> 0 | Z11: =+I11+J11 -> 0
A12: 4 | B12: Физические лица | C12: =+'Loans Receivable'!C80 -> 4259879328 | D12: =IF(C$22=0,"",C12/C$22) -> 0.098727597 | E12: 14416216 | F12: =IF(E$22=0,"",E12/E$22) -> 0.04009696 | G12: 1010074 | H12: =IF($G$22=0,"",G12/$G$22) -> 0.52860402 | I12: =+L12+N12+P12+R12+T12+V12+X12 -> 41545823 | J12: =+M12+O12+Q12+S12+U12+W12+Y12 -> 14225284 | K12: =IF($Z$22=0,"",Z12/$Z$22) -> 0.12602418 | L12: 2422411 | M12: 4376870 | N12: 3093690 | O12: 441474 | P12: 3657488 | Q12: 581374 | R12: 8089091 | S12: 1243620 | T12: 21833121 | U12: 5717566 | V12: 2450022 | W12: 1864380 | X12: 0 | Y12: 0 | Z12: =+I12+J12 -> 55771107
A13: 5 | B13: Государственные предприятия | C13: =+'Loans Receivable'!C81 -> 13986301108 | D13: =IF(C$22=0,"",C13/C$22) -> 0.32414859 | E13: 15200503 | F13: =IF(E$22=0,"",E13/E$22) -> 0.042278359 | G13: 0 | H13: =IF($G$22=0,"",G13/$G$22) -> 0 | I13: =+L13+N13+P13+R13+T13+V13+X13 -> 3352746 | J13: =+M13+O13+Q13+S13+U13+W13+Y13 -> 206207 | K13: =IF($Z$22=0,"",Z13/$Z$22) -> 0.0080420515 | L13: 638933 | M13: 206207 | N13: 0 | O13: 0 | P13: 2191481 | Q13: 0 | R13: 0 | S13: 0 | T13: 522332 | U13: 0 | V13: 0 | W13: 0 | X13: 0 | Y13: 0 | Z13: =+I13+J13 -> 3558953
A14: 6 | B14: Совместные и иностранные предприятия | C14: =+'Loans Receivable'!C82 -> 7071696766 | D14: =IF(C$22=0,"",C14/C$22) -> 0.1638947 | E14: 55656225 | F14: =IF(E$22=0,"",E14/E$22) -> 0.15480105 | G14: 0 | H14: =IF($G$22=0,"",G14/$G$22) -> 0 | I14: =+L14+N14+P14+R14+T14+V14+X14 -> 20549450 | J14: =+M14+O14+Q14+S14+U14+W14+Y14 -> 14767210 | K14: =IF($Z$22=0,"",Z14/$Z$22) -> 0.07980392 | L14: 1486 | M14: 14696435 | N14: 9162150 | O14: 1255 | P14: 10754210 | Q14: 0 | R14: 290992 | S14: 69520 | T14: 340612 | U14: 0 | V14: 0 | W14: 0 | X14: 0 | Y14: 0 | Z14: =+I14+J14 -> 35316660
A15: 7 | B15: Частные товарищества и корпорации | C15: =+'Loans Receivable'!C83 -> 17480739187 | D15: =IF(C$22=0,"",C15/C$22) -> 0.40513621 | E15: 265749354 | F15: =IF(E$22=0,"",E15/E$22) -> 0.73914966 | G15: 817058 | H15: =IF($G$22=0,"",G15/$G$22) -> 0.42759257 | I15: =+L15+N15+P15+R15+T15+V15+X15 -> 294908933 | J15: =+M15+O15+Q15+S15+U15+W15+Y15 -> 33659713 | K15: =IF($Z$22=0,"",Z15/$Z$22) -> 0.74245599 | L15: 43298462 | M15: 15922447 | N15: 16434605 | O15: 2440215 | P15: 86797188 | Q15: 6704140 | R15: 44734418 | S15: 3534306 | T15: 98971352 | U15: 4890801 | V15: 4672908 | W15: 167804 | X15: 0 | Y15: 0 | Z15: =+I15+J15 -> 328568646
A16: 8 | B16: Фермерское хозяйство | C16: =+'Loans Receivable'!C84 -> 225782941 | D16: =IF(C$22=0,"",C16/C$22) -> 0.005232779 | E16: 4938596 | F16: =IF(E$22=0,"",E16/E$22) -> 0.013736107 | G16: 83701 | H16: =IF($G$22=0,"",G16/$G$22) -> 0.043803409 | I16: =+L16+N16+P16+R16+T16+V16+X16 -> 9546698 | J16: =+M16+O16+Q16+S16+U16+W16+Y16 -> 758176 | K16: =IF($Z$22=0,"",Z16/$Z$22) -> 0.023285592 | L16: 1911952 | M16: 143591 | N16: 2252 | O16: 0 | P16: 1366575 | Q16: 209274 | R16: 4304889 | S16: 379826 | T16: 1961030 | U16: 25485 | V16: 0 | W16: 0 | X16: 0 | Y16: 0 | Z16: =+I16+J16 -> 10304874
A17: 9 | B17: Небанковские финансовые институты | C17: =+'Loans Receivable'!C88 -> 3315923 | D17: =IF(C$22=0,"",C17/C$22) -> 7.6850324e-05 | E17: 294767 | F17: =IF(E$22=0,"",E17/E$22) -> 0.00081985873 | G17: 0 | H17: =IF($G$22=0,"",G17/$G$22) -> 0 | I17: =+L17+N17+P17+R17+T17+V17+X17 -> 0 | J17: =+M17+O17+Q17+S17+U17+W17+Y17 -> 0 | K17: =IF($Z$22=0,"",Z17/$Z$22) -> 0 | L17: 0 | M17: 0 | N17: 0 | O17: 0 | P17: 0 | Q17: 0 | R17: 0 | S17: 0 | T17: 0 | U17: 0 | V17: 0 | W17: 0 | X17: 0 | Y17: 0 | Z17: =+I17+J17 -> 0
A18: 10 | B18: Негосударственные некоммерческие организации | C18: =+'Loans Receivable'!C89 -> 120092235 | D18: =IF(C$22=0,"",C18/C$22) -> 0.0027832755 | E18: 3278233 | F18: =IF(E$22=0,"",E18/E$22) -> 0.0091180082 | G18: 0 | H18: =IF($G$22=0,"",G18/$G$22) -> 0 | I18: =+L18+N18+P18+R18+T18+V18+X18 -> 4972783 | J18: =+M18+O18+Q18+S18+U18+W18+Y18 -> 4049901 | K18: =IF($Z$22=0,"",Z18/$Z$22) -> 0.020388269 | L18: 99097 | M18: 1797825 | N18: 56414 | O18: 91361 | P18: 183848 | Q18: 187415 | R18: 391544 | S18: 327523 | T18: 1914340 | U18: 735577 | V18: 2327540 | W18: 910200 | X18: 0 | Y18: 0 | Z18: =+I18+J18 -> 9022684
A19: 11 | B19: Бюджетные организации | C19: =+'Loans Receivable'!C90 -> 0 | D19: =IF(C$22=0,"",C19/C$22) -> 0 | E19: 0 | F19: =IF(E$22=0,"",E19/E$22) -> 0 | G19: 0 | H19: =IF($G$22=0,"",G19/$G$22) -> 0 | I19: =+L19+N19+P19+R19+T19+V19+X19 -> 0 | J19: =+M19+O19+Q19+S19+U19+W19+Y19 -> 0 | K19: =IF($Z$22=0,"",Z19/$Z$22) -> 0 | L19: 0 | M19: 0 | N19: 0 | O19: 0 | P19: 0 | Q19: 0 | R19: 0 | S19: 0 | T19: 0 | U19: 0 | V19: 0 | W19: 0 | X19: 0 | Y19: 0 | Z19: =+I19+J19 -> 0
A20: 12 | B20: Прочие | C20: =+'Loans Receivable'!C91 -> 0 | D20: =IF(C$22=0,"",C20/C$22) -> 0 | E20: 0 | F20: =IF(E$22=0,"",E20/E$22) -> 0 | G20: 0 | H20: =IF($G$22=0,"",G20/$G$22) -> 0 | I20: =+L20+N20+P20+R20+T20+V20+X20 -> 0 | J20: =+M20+O20+Q20+S20+U20+W20+Y20 -> 0 | K20: =IF($Z$22=0,"",Z20/$Z$22) -> 0 | L20: 0 | M20: 0 | O20: 0 | P20: 0 | Q20: 0 | R20: 0 | S20: 0 | T20: 0 | U20: 0 | V20: 0 | W20: 0 | X20: 0 | Y20: 0 | Z20: =+I20+J20 -> 0
Z21: =+I21+J21 -> 0
A22: 13 | B22: Итого кредита и лизинга | C22: =SUM(C9:C20) -> 43147807488 | D22: =IF(C$22=0,"",C22/C$22) -> 1 | E22: =SUM(E9:E20) -> 359533894 | F22: =IF(E$22=0,"",E22/E$22) -> 1 | G22: =SUM(G9:G20) -> 1910833 | H22: =IF($G$22=0,"",G22/$G$22) -> 1 | I22: =SUM(I9:I20) -> 374876433 | J22: =SUM(J9:J20) -> 67666491 | K22: =IF($Z$22=0,"",Z22/$Z$22) -> 1 | L22: =SUM(L9:L20) -> 48372341 | M22: =SUM(M9:M20) -> 37143375 | N22: =SUM(N9:N20) -> 28749111 | O22: =SUM(O9:O20) -> 2974305 | P22: =SUM(P9:P20) -> 104950790 | Q22: =SUM(Q9:Q20) -> 7682203 | R22: =SUM(R9:R20) -> 57810934 | S22: =SUM(S9:S20) -> 5554795 | ... Y22: =SUM(Y9:Y20) -> 0 | Z22: =+I22+J22 -> 442542924
Z23: =+I23+J23 -> 0
B24: По сектору экономики | F24: =IF(E$22=0,"",E24/E$22) -> 0 | Z24: =+I24+J24 -> 0
A25: 14 | B25: Промышленность | C25: =+'Loans Receivable'!C15 -> 26339734494 | D25: =IF(C$34=0,"",C25/C$34) -> 0.6104536 | E25: 162697434 | F25: =IF($E$34=0,"",E25/$E$34) -> 0.45252322 | G25: 0 | H25: =IF($G$34=0,"",G25/$G$34) -> 0 | I25: =+L25+N25+P25+R25+T25+V25+X25 -> 142787007 | J25: =+M25+O25+Q25+S25+U25+W25+Y25 -> 28489847 | K25: =IF($Z$34=0,"",Z25/$Z$34) -> 0.38702879 | L25: 19327454 | M25: 21645443 | N25: 20399655 | O25: 1712079 | P25: 42166720 | Q25: 3458672 | R25: 17697899 | S25: 416002 | T25: 40459007 | U25: 1257651 | V25: 2736272 | W25: 0 | X25: 0 | Y25: 0 | Z25: =+I25+J25 -> 171276854
A26: 15 | B26: Сельское хозяйство | C26: =+'Loans Receivable'!C24 -> 3143324750 | D26: =IF(C$34=0,"",C26/C$34) -> 0.072850162 | E26: 62157529 | F26: =IF($E$34=0,"",E26/$E$34) -> 0.17288364 | G26: 345558 | H26: =IF($G$34=0,"",G26/$G$34) -> 0.18084155 | I26: =+L26+N26+P26+R26+T26+V26+X26 -> 59650799 | J26: =+M26+O26+Q26+S26+U26+W26+Y26 -> 6430208 | K26: =IF($Z$34=0,"",Z26/$Z$34) -> 0.14932112 | L26: 8199895 | M26: 3230304 | N26: 1118128 | O26: 318527 | P26: 25939037 | Q26: 740384 | R26: 14910570 | S26: 1870108 | T26: 8991357 | U26: 270885 | V26: 491812 | W26: 0 | X26: 0 | Y26: 0 | Z26: =+I26+J26 -> 66081007
A27: 16 | B27: Транспорт и коммуникации | C27: =+'Loans Receivable'!C32 -> 3463692914 | D27: =IF(C$34=0,"",C27/C$34) -> 0.080275062 | E27: 47628932 | F27: =IF($E$34=0,"",E27/$E$34) -> 0.13247411 | G27: 0 | H27: =IF($G$34=0,"",G27/$G$34) -> 0 | I27: =+L27+N27+P27+R27+T27+V27+X27 -> 15859341 | J27: =+M27+O27+Q27+S27+U27+W27+Y27 -> 2086690 | K27: =IF($Z$34=0,"",Z27/$Z$34) -> 0.040552069 | L27: 2158501 | M27: 98797 | N27: 1726885 | O27: 161400 | P27: 3508592 | Q27: 101404 | R27: 2108367 | S27: 196784 | T27: 6356996 | U27: 1528305 | V27: 0 | W27: 0 | X27: 0 | Y27: 0 | Z27: =+I27+J27 -> 17946031
A28: 17 | B28: Строительство | C28: =+'Loans Receivable'!C40 -> 823680530 | D28: =IF(C$34=0,"",C28/C$34) -> 0.019089742 | E28: 12457482 | F28: =IF($E$34=0,"",E28/$E$34) -> 0.034648978 | G28: 555201 | H28: =IF($G$34=0,"",G28/$G$34) -> 0.29055443 | I28: =+L28+N28+P28+R28+T28+V28+X28 -> 24888555 | J28: =+M28+O28+Q28+S28+U28+W28+Y28 -> 2994552 | K28: =IF($Z$34=0,"",Z28/$Z$34) -> 0.063006559 | L28: 976461 | M28: 839521 | N28: 1308333 | O28: 235345 | P28: 12806005 | Q28: 1542179 | R28: 3540259 | S28: 296169 | T28: 6129374 | U28: 67367 | V28: 128123 | W28: 13971 | X28: 0 | Y28: 0 | Z28: =+I28+J28 -> 27883107
A29: 18 | B29: Торговля и общественное питание | C29: =+'Loans Receivable'!C48 -> 2451039832 | D29: =IF(C$34=0,"",C29/C$34) -> 0.056805663 | E29: 37380930 | F29: =IF($E$34=0,"",E29/$E$34) -> 0.10397053 | G29: 0 | H29: =IF($G$34=0,"",G29/$G$34) -> 0 | I29: =+L29+N29+P29+R29+T29+V29+X29 -> 51982203 | J29: =+M29+O29+Q29+S29+U29+W29+Y29 -> 5151526 | K29: =IF($Z$34=0,"",Z29/$Z$34) -> 0.12910325 | L29: 13432825 | M29: 2609801 | N29: 941227 | O29: 5156 | P29: 11268177 | Q29: 285755 | R29: 6249392 | S29: 742580 | T29: 19129031 | U29: 1354401 | V29: 961551 | W29: 153833 | X29: 0 | Y29: 0 | Z29: =+I29+J29 -> 57133729
A30: 19 | B30: Материально-техническое снабжение и сбыт | C30: =+'Loans Receivable'!C56 -> 311679287 | D30: =IF(C$34=0,"",C30/C$34) -> 0.0072235255 | E30: 2461485 | F30: =IF($E$34=0,"",E30/$E$34) -> 0.0068463225 | G30: 0 | H30: =IF($G$34=0,"",G30/$G$34) -> 0 | I30: =+L30+N30+P30+R30+T30+V30+X30 -> 4711401 | J30: =+M30+O30+Q30+S30+U30+W30+Y30 -> 274514 | K30: =IF($Z$34=0,"",Z30/$Z$34) -> 0.011266512 | L30: 10179 | M30: 10824 | N30: 0 | O30: 0 | P30: 213196 | Q30: 117712 | R30: 1437544 | S30: 145978 | T30: 3050482 | U30: 0 | V30: 0 | W30: 0 | X30: 0 | Y30: 0 | Z30: =+I30+J30 -> 4985915
A31: 20 | B31: Жилищно-коммунальные услуги | C31: =+'Loans Receivable'!C65 -> 120092235 | D31: =IF(C$34=0,"",C31/C$34) -> 0.0027832755 | E31: 3278233 | F31: =IF($E$34=0,"",E31/$E$34) -> 0.0091180082 | G31: 0 | H31: =IF($G$34=0,"",G31/$G$34) -> 0 | I31: =+L31+N31+P31+R31+T31+V31+X31 -> 4972783 | J31: =+M31+O31+Q31+S31+U31+W31+Y31 -> 4049901 | K31: =IF($Z$34=0,"",Z31/$Z$34) -> 0.020388269 | L31: 99097 | M31: 1797825 | N31: 56414 | O31: 91361 | P31: 183848 | Q31: 187415 | R31: 391544 | S31: 327523 | T31: 1914340 | U31: 735577 | V31: 2327540 | W31: 910200 | X31: 0 | Y31: 0 | Z31: =+I31+J31 -> 9022684
A32: 21 | B32: Другие сектора | C32: =+'Loans Receivable'!C78 -> 6494563446 | D32: =IF(C$34=0,"",C32/C$34) -> 0.15051897 | E32: 31471869 | F32: =IF($E$34=0,"",E32/$E$34) -> 0.087535194 | G32: 1010074 | H32: =IF($G$34=0,"",G32/$G$34) -> 0.52860402 | I32: =+L32+N32+P32+R32+T32+V32+X32 -> 70024344 | J32: =+M32+O32+Q32+S32+U32+W32+Y32 -> 18189253 | K32: =IF($Z$34=0,"",Z32/$Z$34) -> 0.19933343 | L32: 4167929 | M32: 6910860 | N32: 3198469 | O32: 450437 | P32: 8865215 | Q32: 1248682 | R32: 11475359 | S32: 1559651 | T32: 39512200 | U32: 6155243 | V32: 2805172 | W32: 1864380 | X32: 0 | Y32: 0 | Z32: =+I32+J32 -> 88213597
Z33: =+I33+J33 -> 0
A34: 22 | B34: Итого кредита и лизинга | C34: =SUM(C25:C32) -> 43147807488 | D34: =IF(C$34=0,"",C34/C$34) -> 1 | E34: =SUM(E25:E32) -> 359533894 | F34: =IF($E$34=0,"",E34/$E$34) -> 1 | G34: =SUM(G25:G32) -> 1910833 | H34: =IF($G$34=0,"",G34/$G$34) -> 1 | I34: =SUM(I25:I32) -> 374876433 | J34: =SUM(J25:J32) -> 67666491 | K34: =IF($Z$34=0,"",Z34/$Z$34) -> 1 | L34: =SUM(L25:L32) -> 48372341 | M34: =SUM(M25:M32) -> 37143375 | N34: =SUM(N25:N32) -> 28749111 | O34: =SUM(O25:O32) -> 2974305 | P34: =SUM(P25:P32) -> 104950790 | Q34: =SUM(Q25:Q32) -> 7682203 | R34: =SUM(R25:R32) -> 57810934 | S34: =SUM(S25:S32) -> 5554795 | ... Y34: =SUM(Y25:Y32) -> 0 | Z34: =+I34+J34 -> 442542924
B37: Подпись Председателя правления:
B39: Подпись Главного Бухгалтера:

Sheet Asset Classification
A1: ОТЧЕТ О КЛАССИФИКАЦИИ АКТИВОВ ПО СТЕПЕНИ РИСКА | W1: Таблица-10
B2: =+'Asset quality'!B3 -> "Ўзсаноатқурилишбанк" АТБ | U2: =+'Asset quality'!P3 -> 44560 | Z2: тыс. сум
A3: № | B3: Статьи баланса | C3: Общая сумма | D3: из них, в иностранной валюте (в экв. в сумах) | E3: Стандартные | F3: из них, в иностранной валюте (в экв. в сумах) | G3: Общие резервы (1%) | H3: из них, в иностранной валюте (в экв. в сумах) | I3: Субстандартные | J3: из них, в иностранной валюте (в экв. в сумах) | K3: Специальные резервы (мин 10%) | L3: из них, в иностранной валюте (в экв. в сумах) | M3: Неудовлетворительные | N3: из них, в иностранной валюте (в экв. в сумах) | O3: Специальные резервы (мин 25%) | P3: из них, в иностранной валюте (в экв. в сумах) | Q3: Сомнительные | R3: из них, в иностранной валюте (в экв. в сумах) | S3: Специальные резервы (мин 50%) | T3: из них, в иностранной валюте (в экв. в сумах) | U3: Безнадежные | V3: из них, в иностранной валюте (в экв. в сумах) | W3: Специальные резервы (100%) | X3: из них, в иностранной валюте (в экв. в сумах) | Y3: Совокупная сумма специальных резервов | Z3: из них, в иностранной валюте (в экв. в сумах) | AA3: списанные кредиты за баланс в отчётном месяце | AB3: возврат списанных кредитов в отчётном месяце
A4: (А) | B4: (Б) | C4: (В) | D4: (В1) | E4: (Г) | F4: (Г1) | G4: (Д) | H4: (Д1) | I4: (Е) | J4: (Е1) | K4: (Ж) | L4: (Ж1) | M4: (З) | N4: (З1) | O4: (И) | P4: (И1) | Q4: (К) | R4: (К1) | S4: (Л) | T4: (Л1) | U4: (М) | V4: (М1) | W4: (Н) | X4: (Н1) | Y4: О=Ж+И+Л+Н | Z4: (О1)=(Ж1)+(И1)+(Л1)+(Н1) | AA4: П | AB4: Р
B5: По типу клиента
A6: 1 | B6: Центральный банк | C6: =E6+I6+M6+Q6+U6 -> 0 | D6: =F6+J6+N6+R6+V6 -> 0 | Y6: =+W6+S6+O6+K6 -> 0 | Z6: =+X6+T6+P6+L6 -> 0 | AA6: 0 | AB6: 0 | AC6: =+'Aging Analysis'!C9 -> 0
B7: из них необеспеченные | C7: =E7+I7+M7+Q7+U7 -> 0 | D7: =F7+J7+N7+R7+V7 -> 0 | Y7: =+W7+S7+O7+K7 -> 0 | Z7: =+X7+T7+P7+L7 -> 0 | AA7: 0 | AB7: 0
A8: 2 | B8: Другие банки | C8: =E8+I8+M8+Q8+U8 -> 0 | D8: =F8+J8+N8+R8+V8 -> 0 | Y8: =+W8+S8+O8+K8 -> 0 | Z8: =+X8+T8+P8+L8 -> 0 | AA8: 0 | AB8: 0 | AC8: =+'Aging Analysis'!C10 -> 0
B9: из них необеспеченные | C9: =E9+I9+M9+Q9+U9 -> 0 | D9: =F9+J9+N9+R9+V9 -> 0 | Y9: =+W9+S9+O9+K9 -> 0 | Z9: =+X9+T9+P9+L9 -> 0 | AA9: 0 | AB9: 0
A10: 3 | B10: Правительство | C10: =E10+I10+M10+Q10+U10 -> 0 | D10: =F10+J10+N10+R10+V10 -> 0 | Y10: =+W10+S10+O10+K10 -> 0 | Z10: =+X10+T10+P10+L10 -> 0 | AA10: 0 | AB10: 0 | AC10: =+'Aging Analysis'!C11 -> 0
B11: из них необеспеченные | C11: =E11+I11+M11+Q11+U11 -> 0 | D11: =F11+J11+N11+R11+V11 -> 0 | Y11: =+W11+S11+O11+K11 -> 0 | Z11: =+X11+T11+P11+L11 -> 0 | AA11: 0 | AB11: 0
A12: 4 | B12: Физические лица | C12: =E12+I12+M12+Q12+U12 -> 4259879328 | D12: =F12+J12+N12+R12+V12 -> 0 | E12: 3964467868 | F12: 0 | G12: 36423995 | H12: 0 | I12: 132505895 | J12: 0 | K12: 13315831 | L12: 0 | M12: 38467478 | N12: 0 | O12: 9316699 | P12: 0 | Q12: 32190471 | R12: 0 | S12: 16097430 | T12: 0 | U12: 92247616 | V12: 0 | W12: 91661095 | X12: 0 | Y12: =+W12+S12+O12+K12 -> 130391055 | Z12: =+X12+T12+P12+L12 -> 0 | AA12: 30970096 | AB12: 402106 | AC12: =+'Aging Analysis'!C12 -> 4259879328
B13: из них необеспеченные | C13: =E13+I13+M13+Q13+U13 -> 0 | D13: =F13+J13+N13+R13+V13 -> 0 | E13: 0 | F13: 0 | G13: 0 | H13: 0 | I13: 0 | J13: 0 | K13: 0 | L13: 0 | M13: 0 | N13: 0 | O13: 0 | P13: 0 | Q13: 0 | R13: 0 | S13: 0 | T13: 0 | U13: 0 | V13: 0 | W13: 0 | X13: 0 | Y13: =+W13+S13+O13+K13 -> 0 | Z13: =+X13+T13+P13+L13 -> 0 | AA13: 0 | AB13: 0
A14: 5 | B14: Государственные предприятия | C14: =E14+I14+M14+Q14+U14 -> 13986301108 | D14: =F14+J14+N14+R14+V14 -> 10207198252 | E14: 13965095854 | F14: 10207198252 | G14: 132622973 | H14: 0 | I14: 0 | J14: 0 | K14: 0 | L14: 0 | M14: 20055918 | N14: 0 | O14: 5013979 | P14: 0 | Q14: 0 | R14: 0 | S14: 0 | T14: 0 | U14: 1149336 | V14: 0 | W14: 1149336 | X14: 0 | Y14: =+W14+S14+O14+K14 -> 6163315 | Z14: =+X14+T14+P14+L14 -> 0 | AA14: 0 | AB14: 0 | AC14: =+'Aging Analysis'!C13 -> 13986301108
B15: из них необеспеченные | C15: =E15+I15+M15+Q15+U15 -> 0 | D15: =F15+J15+N15+R15+V15 -> 0 | E15: 0 | F15: 0 | G15: 0 | H15: 0 | I15: 0 | J15: 0 | K15: 0 | L15: 0 | M15: 0 | N15: 0 | O15: 0 | P15: 0 | Q15: 0 | R15: 0 | S15: 0 | T15: 0 | U15: 0 | V15: 0 | W15: 0 | X15: 0 | Y15: =+W15+S15+O15+K15 -> 0 | Z15: =+X15+T15+P15+L15 -> 0 | AA15: 0 | AB15: 0
A16: 6 | B16: Совместные и иностранные предприятия | C16: =E16+I16+M16+Q16+U16 -> 7071696766 | D16: =F16+J16+N16+R16+V16 -> 6033788908 | E16: 6694459117 | F16: 5692233005 | G16: 48403599 | H16: 0 | I16: 176072246 | J16: 141524574 | K16: 17607225 | L16: 14152457 | M16: 198923925 | N16: 198839186 | O16: 49730981 | P16: 49709797 | Q16: 1049335 | R16: 0 | S16: 524668 | T16: 0 | U16: 1192143 | V16: 1192143 | W16: 1192143 | X16: 1192143 | Y16: =+W16+S16+O16+K16 -> 69055017 | Z16: =+X16+T16+P16+L16 -> 65054397 | AA16: 0 | AB16: 0 | AC16: =+'Aging Analysis'!C14 -> 7071696766
B17: из них необеспеченные | C17: =E17+I17+M17+Q17+U17 -> 0 | D17: =F17+J17+N17+R17+V17 -> 0 | E17: 0 | F17: 0 | G17: 0 | H17: 0 | I17: 0 | J17: 0 | K17: 0 | L17: 0 | M17: 0 | N17: 0 | O17: 0 | P17: 0 | Q17: 0 | R17: 0 | S17: 0 | T17: 0 | U17: 0 | V17: 0 | W17: 0 | X17: 0 | Y17: =+W17+S17+O17+K17 -> 0 | Z17: =+X17+T17+P17+L17 -> 0 | AA17: 0 | AB17: 0
A18: 7 | B18: Частные товарищества и корпорации | C18: =E18+I18+M18+Q18+U18 -> 17480739187 | D18: =F18+J18+N18+R18+V18 -> 11703391440 | E18: 14026216736 | F18: 8984077621 | G18: 132046504 | H18: 0 | I18: 2311354917 | J18: 1958802939 | K18: 233321646 | L18: 189722638 | M18: 609379340 | N18: 400667794 | O18: 142655367 | P18: 90730354 | Q18: 161870514 | R18: 105016204 | S18: 75449928 | T18: 48240773 | U18: 371917680 | V18: 254826882 | W18: 370915880 | X18: 254826882 | Y18: =+W18+S18+O18+K18 -> 822342821 | Z18: =+X18+T18+P18+L18 -> 583520647 | AA18: 0 | AB18: 0 | AC18: =+'Aging Analysis'!C15 -> 17480739187
B19: из них необеспеченные | C19: =E19+I19+M19+Q19+U19 -> 0 | D19: =F19+J19+N19+R19+V19 -> 0 | E19: 0 | F19: 0 | G19: 0 | H19: 0 | I19: 0 | J19: 0 | K19: 0 | L19: 0 | M19: 0 | N19: 0 | O19: 0 | P19: 0 | Q19: 0 | R19: 0 | S19: 0 | T19: 0 | U19: 0 | V19: 0 | W19: 0 | X19: 0 | Y19: =+W19+S19+O19+K19 -> 0 | Z19: =+X19+T19+P19+L19 -> 0 | AA19: 0 | AB19: 0
A20: 8 | B20: Фермерское хозяйство | C20: =E20+I20+M20+Q20+U20 -> 225782941 | D20: =F20+J20+N20+R20+V20 -> 130450552 | E20: 165041155 | F20: 97566132 | G20: 1419646 | H20: 0 | I20: 24195070 | J20: 8931220 | K20: 2419599 | L20: 893123 | M20: 16312042 | N20: 6396193 | O20: 4078010 | P20: 1599049 | Q20: 9503755 | R20: 7044478 | S20: 4751877 | T20: 3522240 | U20: 10730919 | V20: 10512529 | W20: 10730919 | X20: 10512530 | Y20: =+W20+S20+O20+K20 -> 21980405 | Z20: =+X20+T20+P20+L20 -> 16526942 | AA20: 0 | AB20: 0 | AC20: =+'Aging Analysis'!C16 -> 225782941
B21: из них необеспеченные | C21: =E21+I21+M21+Q21+U21 -> 0 | D21: =F21+J21+N21+R21+V21 -> 0 | E21: 0 | F21: 0 | G21: 0 | H21: 0 | I21: 0 | J21: 0 | K21: 0 | L21: 0 | M21: 0 | N21: 0 | O21: 0 | P21: 0 | Q21: 0 | R21: 0 | S21: 0 | T21: 0 | U21: 0 | V21: 0 | W21: 0 | X21: 0 | Y21: =+W21+S21+O21+K21 -> 0 | Z21: =+X21+T21+P21+L21 -> 0 | AA21: 0 | AB21: 0
A22: 9 | B22: Небанковские финансовые институты | C22: =E22+I22+M22+Q22+U22 -> 3315923 | D22: =F22+J22+N22+R22+V22 -> 0 | E22: 0 | F22: 0 | G22: 61194 | H22: 0 | I22: 3315923 | J22: 0 | K22: 331592 | L22: 0 | M22: 0 | N22: 0 | O22: 0 | P22: 0 | Q22: 0 | R22: 0 | S22: 0 | T22: 0 | U22: 0 | V22: 0 | W22: 0 | X22: 0 | Y22: =+W22+S22+O22+K22 -> 331592 | Z22: =+X22+T22+P22+L22 -> 0 | AA22: 0 | AB22: 0 | AC22: =+'Aging Analysis'!C17 -> 3315923
B23: из них необеспеченные | C23: =E23+I23+M23+Q23+U23 -> 0 | D23: =F23+J23+N23+R23+V23 -> 0 | E23: 0 | F23: 0 | G23: 0 | H23: 0 | I23: 0 | J23: 0 | K23: 0 | L23: 0 | M23: 0 | N23: 0 | O23: 0 | P23: 0 | Q23: 0 | R23: 0 | S23: 0 | T23: 0 | U23: 0 | V23: 0 | W23: 0 | X23: 0 | Y23: =+W23+S23+O23+K23 -> 0 | Z23: =+X23+T23+P23+L23 -> 0 | AA23: 0 | AB23: 0
A24: 10 | B24: Негосударственные некоммерческие организации | C24: =E24+I24+M24+Q24+U24 -> 120092235 | D24: =F24+J24+N24+R24+V24 -> 0 | E24: 49169250 | F24: 0 | G24: 531430 | H24: 0 | I24: 6380160 | J24: 0 | K24: 638016 | L24: 0 | M24: 8383148 | N24: 0 | O24: 1817528 | P24: 0 | Q24: 4721493 | R24: 0 | S24: 2360747 | T24: 0 | U24: 51438184 | V24: 0 | W24: 51438185 | X24: 0 | Y24: =+W24+S24+O24+K24 -> 56254476 | Z24: =+X24+T24+P24+L24 -> 0 | AA24: 0 | AB24: 0 | AC24: =+'Aging Analysis'!C18 -> 120092235
B25: из них необеспеченные | C25: =E25+I25+M25+Q25+U25 -> 0 | D25: =F25+J25+N25+R25+V25 -> 0 | E25: 0 | F25: 0 | G25: 0 | H25: 0 | I25: 0 | J25: 0 | K25: 0 | L25: 0 | M25: 0 | N25: 0 | O25: 0 | P25: 0 | Q25: 0 | R25: 0 | S25: 0 | T25: 0 | U25: 0 | V25: 0 | W25: 0 | X25: 0 | Y25: =+W25+S25+O25+K25 -> 0 | Z25: =+X25+T25+P25+L25 -> 0 | AA25: 0 | AB25: 0
A26: 11 | B26: Бюджетные организации | C26: =E26+I26+M26+Q26+U26 -> 0 | D26: =F26+J26+N26+R26+V26 -> 0 | E26: 0 | F26: 0 | G26: 0 | H26: 0 | I26: 0 | J26: 0 | K26: 0 | L26: 0 | M26: 0 | N26: 0 | O26: 0 | P26: 0 | Q26: 0 | R26: 0 | S26: 0 | T26: 0 | U26: 0 | V26: 0 | W26: 0 | X26: 0 | Y26: =+W26+S26+O26+K26 -> 0 | Z26: =+X26+T26+P26+L26 -> 0 | AA26: 0 | AB26: 0 | AC26: =+'Aging Analysis'!C19 -> 0
B27: из них необеспеченные | C27: =E27+I27+M27+Q27+U27 -> 0 | D27: =F27+J27+N27+R27+V27 -> 0 | E27: 0 | F27: 0 | G27: 0 | H27: 0 | I27: 0 | J27: 0 | K27: 0 | L27: 0 | M27: 0 | N27: 0 | O27: 0 | P27: 0 | Q27: 0 | R27: 0 | S27: 0 | T27: 0 | U27: 0 | V27: 0 | W27: 0 | X27: 0 | Y27: =+W27+S27+O27+K27 -> 0 | Z27: =+X27+T27+P27+L27 -> 0 | AA27: 0 | AB27: 0
A28: 12 | B28: Прочие | C28: =E28+I28+M28+Q28+U28 -> 0 | D28: =F28+J28+N28+R28+V28 -> 0 | E28: 0 | F28: 0 | G28: 0 | H28: 0 | I28: 0 | J28: 0 | K28: 0 | L28: 0 | M28: 0 | N28: 0 | O28: 0 | P28: 0 | Q28: 0 | R28: 0 | S28: 0 | T28: 0 | U28: 0 | V28: 0 | W28: 0 | X28: 0 | Y28: =+W28+S28+O28+K28 -> 0 | Z28: =+X28+T28+P28+L28 -> 0 | AA28: 297298225 | AB28: 4322078 | AC28: =+'Aging Analysis'!C20 -> 0
B29: из них необеспеченные | C29: =E29+I29+M29+Q29+U29 -> 0 | D29: =F29+J29+N29+R29+V29 -> 0 | E29: 0 | F29: 0 | G29: 0 | H29: 0 | I29: 0 | J29: 0 | K29: 0 | L29: 0 | M29: 0 | N29: 0 | O29: 0 | P29: 0 | Q29: 0 | R29: 0 | S29: 0 | T29: 0 | U29: 0 | V29: 0 | W29: 0 | X29: 0 | Y29: =+W29+S29+O29+K29 -> 0 | Z29: =+X29+T29+P29+L29 -> 0 | AA29: 0 | AB29: 0
A30: 13 | B30: Итого кредита и лизинга | C30: =+C6+C8+C10+C12+C14+C16+C18+C20+C22+C24+C26+C28 -> 43147807488 | D30: =+D6+D8+D10+D12+D14+D16+D18+D20+D22+D24+D26+D28 -> 28074829152 | E30: =+E6+E8+E10+E12+E14+E16+E18+E20+E22+E24+E26+E28 -> 38864449980 | F30: =+F6+F8+F10+F12+F14+F16+F18+F20+F22+F24+F26+F28 -> 24981075010 | G30: =+G6+G8+G10+G12+G14+G16+G18+G20+G22+G24+G26+G28 -> 351509341 | H30: =+H6+H8+H10+H12+H14+H16+H18+H20+H22+H24+H26+H28 -> 0 | I30: =+I6+I8+I10+I12+I14+I16+I18+I20+I22+I24+I26+I28 -> 2653824211 | J30: =+J6+J8+J10+J12+J14+J16+J18+J20+J22+J24+J26+J28 -> 2109258733 | ... AB30: =+AB6+AB8+AB10+AB12+AB14+AB16+AB18+AB20+AB22+AB24+AB26+AB28 -> 4724184
B31: из них необеспеченные | C31: =+C7+C9+C11+C13+C15+C17+C19+C21+C23+C25+C27+C29 -> 0 | D31: =+D7+D9+D11+D13+D15+D17+D19+D21+D23+D25+D27+D29 -> 0 | E31: =+E7+E9+E11+E13+E15+E17+E19+E21+E23+E25+E27+E29 -> 0 | F31: =+F7+F9+F11+F13+F15+F17+F19+F21+F23+F25+F27+F29 -> 0 | G31: =+G7+G9+G11+G13+G15+G17+G19+G21+G23+G25+G27+G29 -> 0 | H31: =+H7+H9+H11+H13+H15+H17+H19+H21+H23+H25+H27+H29 -> 0 | I31: =+I7+I9+I11+I13+I15+I17+I19+I21+I23+I25+I27+I29 -> 0 | J31: =+J7+J9+J11+J13+J15+J17+J19+J21+J23+J25+J27+J29 -> 0 | ... Z31: =+Z7+Z9+Z11+Z13+Z15+Z17+Z19+Z21+Z23+Z25+Z27+Z29 -> 0
B32: По сектору экономики
A34: 14 | B34: Промышленность | C34: =E34+I34+M34+Q34+U34 -> 26339734494 | D34: =F34+J34+N34+R34+V34 -> 19689771990 | E34: 24017676507 | F34: 17657450884 | G34: 212769065 | H34: 0 | I34: 1540155198 | J34: 1383019941 | K34: 156602830 | L34: 132551069 | M34: 510574835 | N34: 436119781 | O34: 122228464 | P34: 103639700 | Q34: 91900978 | R34: 61659840 | S34: 40465160 | T34: 26562592 | U34: 179426976 | V34: 151521544 | W34: 179426976 | X34: 151521544 | Y34: =+W34+S34+O34+K34 -> 498723430 | Z34: =+X34+T34+P34+L34 -> 414274905 | AA34: 7502064 | AB34: 0 | AC34: =+'Aging Analysis'!C25 -> 26339734494
B35: из них необеспеченные | C35: =E35+I35+M35+Q35+U35 -> 0 | D35: =F35+J35+N35+R35+V35 -> 0 | E35: 0 | F35: 0 | G35: 0 | H35: 0 | I35: 0 | J35: 0 | K35: 0 | L35: 0 | M35: 0 | N35: 0 | O35: 0 | P35: 0 | Q35: 0 | R35: 0 | S35: 0 | T35: 0 | U35: 0 | V35: 0 | W35: 0 | X35: 0 | Y35: =+W35+S35+O35+K35 -> 0 | Z35: =+X35+T35+P35+L35 -> 0 | AA35: 0 | AB35: 0
A36: 15 | B36: Сельское хозяйство | C36: =E36+I36+M36+Q36+U36 -> 3143324750 | D36: =F36+J36+N36+R36+V36 -> 1776340122 | E36: 2501407678 | F36: 1336822403 | G36: 25454769 | H36: 0 | I36: 345980999 | J36: 271964312 | K36: 34630705 | L36: 27228944 | M36: 209016168 | N36: 101422966 | O36: 52254042 | P36: 25355742 | Q36: 41104177 | R36: 34546725 | S36: 20552089 | T36: 17273363 | U36: 45815728 | V36: 31583716 | W36: 45815728 | X36: 31583716 | Y36: =+W36+S36+O36+K36 -> 153252564 | Z36: =+X36+T36+P36+L36 -> 101441765 | AA36: 2888856 | AB36: 0 | AC36: =+'Aging Analysis'!C26 -> 3143324750
B37: из них необеспеченные | C37: =E37+I37+M37+Q37+U37 -> 0 | D37: =F37+J37+N37+R37+V37 -> 0 | E37: 0 | F37: 0 | G37: 0 | H37: 0 | I37: 0 | J37: 0 | K37: 0 | L37: 0 | M37: 0 | N37: 0 | O37: 0 | P37: 0 | Q37: 0 | R37: 0 | S37: 0 | T37: 0 | U37: 0 | V37: 0 | W37: 0 | X37: 0 | Y37: =+W37+S37+O37+K37 -> 0 | Z37: =+X37+T37+P37+L37 -> 0 | AA37: 0 | AB37: 0
