Workbook
Name jop: #REF!
Name kol: #REF!
Name OLE_LINK19: Balance!$D$34
Name TwentyLargestData: #REF!
Name Е: #REF!

Sheet Balance
A1: СТРУКТУРА БАЛАНСА БАНКА | E1: Таблица-1 | G1: №3
B2: =IF(C3>0," "&TEXT(C3,"д ММММ, гггг"),"Число,Месяц,Год") -> 31 Декабрь, 2020
B3: АКБ"Микрокредитбанк" | C3: 44196 | E3: тыс. сум
A4: № | B4: АКТИВЫ | C4: Итого | D4: в национальной валюте | E4: в иностранной валюте (в экв. в сумах)
A5: 1 | B5: Кассовая наличность и другие платежные документы | C5: =+D5+E5 -> 220312147 | D5: =+'Bank Assets Analysis'!T7 -> 92534448 | E5: =+'Bank Assets Analysis'!U7 -> 127777699 | J5: =+C5-D5-E5 -> 0
A6: 2 | B6: К получению из ЦБРУ | C6: =+D6+E6 -> 380783393 | D6: =+'Bank Assets Analysis'!T9+'Bank Assets Analysis'!T10 -> 335334692 | E6: =+'Bank Assets Analysis'!U9+'Bank Assets Analysis'!U10 -> 45448701 | J6: =+C6-D6-E6 -> 0
A7: 3 | B7: К получению из других банков, чистые | C7: =+'Bank Assets Analysis'!S11 -> 666431398 | D7: =+'Bank Assets Analysis'!T11 -> 231178103 | E7: =+'Bank Assets Analysis'!U11 -> 435253295 | J7: =+C7-D7-E7 -> 0
A8: 3.1. | B8: К получению из других банков, брутто | C8: =+D8+E8 -> 667134942 | D8: 231178103 | E8: 435956839 | J8: =+C8-D8-E8 -> 0
A9: 3.2. | B9: Минус: Резерв возможных убытков | C9: =+D9+E9 -> 703544 | D9: 0 | E9: 703544 | J9: =+C9-D9-E9 -> 0
A10: 4 | B10: Счета купли и продажи, чистые | C10: =+D10+E10 -> 202938240 | D10: =+'Investment Securities'!C29 -> 202938240 | E10: =+'Investment Securities'!D29 -> 0 | J10: =+C10-D10-E10 -> 0
A11: 4.1. | B11: Ценные бумаги для купли продажи, брутто | C11: =+D11+E11 -> 200000000 | D11: =+'Investment Securities'!C26 -> 200000000 | E11: =+'Investment Securities'!D26 -> 0 | J11: =+C11-D11-E11 -> 0
A12: 4.2. | B12: Дисконт и премии по ценным бумагам | C12: =+D12+E12 -> 2938240 | D12: =+'Investment Securities'!C27 -> 2938240 | E12: =+'Investment Securities'!D27 -> 0
A13: 4.3. | B13: Минус: Резерв возможных убытков | C13: =+D13+E13 -> 0 | D13: =+'Investment Securities'!C28 -> 0 | E13: =+'Investment Securities'!D28 -> 0 | J13: =+C13-D13-E13 -> 0
A14: 5 | B14: Драгоценные металлы, монеты, камни, чистые | C14: =+C15-C16 -> 175 | D14: =+'Investment Securities'!C40 -> 175 | E14: =+'Investment Securities'!D40 -> 0 | J14: =+C14-D14-E14 -> 0
A15: 5.1. | B15: Драгоценные металлы, монеты, камни, брутто | C15: =+D15+E15 -> 175 | D15: =+'Investment Securities'!C38 -> 175 | E15: =+'Investment Securities'!D38 -> 0 | J15: =+C15-D15-E15 -> 0
A16: 5.2. | B16: Минус: Резерв возможных убытков | C16: =+D16+E16 -> 0 | D16: =+'Investment Securities'!C39 -> 0 | E16: =+'Investment Securities'!D39 -> 0 | J16: =+C16-D16-E16 -> 0
A17: 6 | B17: Инвестиции, чистые | C17: =+'Investment Securities'!B15 -> 107220 | D17: =+'Investment Securities'!C15 -> 107220 | E17: =+'Investment Securities'!D15 -> 0 | J17: =+C17-D17-E17 -> 0
A18: 6.1. | B18: Инвестиции, брутто | C18: =+D18+E18 -> 107220 | D18: =+'Investment Securities'!C13 -> 107220 | E18: =+'Investment Securities'!D13 -> 0 | J18: =+C18-D18-E18 -> 0
A19: 6.2. | B19: Минус: Резерв возможных убытков | C19: =+D19+E19 -> 0 | D19: =+'Investment Securities'!C14 -> 0 | E19: =+'Investment Securities'!D14 -> 0 | J19: =+C19-D19-E19 -> 0
A20: 7 | B20: Ценные бумаги купленные по соглашению c обратным выкупом, чистые | C20: =+'Bank Assets Analysis'!S35 -> 0 | D20: =+'Bank Assets Analysis'!T35 -> 0 | E20: =+'Bank Assets Analysis'!U35 -> 0 | J20: =+C20-D20-E20 -> 0
A21: 7.1. | B21: Ценные бумаги, купленные по соглашению с обратным выкупом, брутто | C21: =+D21+E21 -> 0 | D21: 0 | E21: 0 | J21: =+C21-D21-E21 -> 0
A22: 7.2. | B22: Резерв возможных убытков | C22: =+D22+E22 -> 0 | D22: 0 | E22: 0 | J22: =+C22-D22-E22 -> 0
A23: 8 | B23: Кредиты и лизинговые операции, чистые | C23: =+'Bank Assets Analysis'!S30+'Bank Assets Analysis'!S31+'Bank Assets Analysis'!S33 -> 8342404404 | D23: =+'Bank Assets Analysis'!T30+'Bank Assets Analysis'!T31+'Bank Assets Analysis'!T33 -> 5472161024 | E23: =+'Bank Assets Analysis'!U30+'Bank Assets Analysis'!U31+'Bank Assets Analysis'!U33 -> 2870243380 | J23: =+C23-D23-E23 -> 0
A24: 8.1. | B24: Кредиты и лизинговые операции, брутто | C24: =+D24+E24 -> 8539798556 | D24: 5618504980 | E24: 2921293576 | J24: =+C24-D24-E24 -> 0
A25: 8.2. | B25: Минус: Резерв возможных убытков | C25: =+D25+E25 -> 197394152 | D25: 146343956 | E25: 51050196 | J25: =+C25-D25-E25 -> 0
A26: 9 | B26: Купленные векселя, чистые | C26: =+'Bank Assets Analysis'!S26 -> 0 | D26: =+'Bank Assets Analysis'!T26 -> 0 | E26: =+'Bank Assets Analysis'!U26 -> 0 | J26: =+C26-D26-E26 -> 0
A27: 9.1. | B27: Купленные векселя, брутто | C27: =+D27+E27 -> 0 | D27: 0 | E27: 0 | J27: =+C27-D27-E27 -> 0
A28: 9.2. | B28: Минус: Резерв возможных убытков | C28: =+D28+E28 -> 0 | D28: 0 | E28: 0 | J28: =+C28-D28-E28 -> 0
A29: 10 | B29: Обязательства клиентов по финансовым инструментам, чистые | C29: =+D29+E29 -> 0 | D29: =+'Bank Assets Analysis'!T27+'Bank Assets Analysis'!T28 -> 0 | E29: =+'Bank Assets Analysis'!U27+'Bank Assets Analysis'!U28 -> 0 | J29: =+C29-D29-E29 -> 0
A30: 10.1. | B30: Обязательства клиентов по финансовым инструментам, брутто | C30: =+D30+E30 -> 0 | D30: 0 | E30: 0 | J30: =+C30-D30-E30 -> 0
A31: 10.2. | B31: Минус: Резерв возможных убытков | C31: =+D31+E31 -> 0 | D31: 0 | E31: 0 | J31: =+C31-D31-E31 -> 0
A32: 11 | B32: Основные средства, чистые | C32: =+'Bank Assets Analysis'!S38 -> 201801025 | D32: =+'Bank Assets Analysis'!T38 -> 201801025 | E32: =+'Bank Assets Analysis'!U38 -> 0 | J32: =+C32-D32-E32 -> 0
A33: 12 | B33: Начисленные процентные и беспроцентные доходы всего, чистые | C33: =+C34+C35-C36 -> 186779795 | D33: =+D34+D35-D36 -> 134890678 | E33: =+E34+E35-E36 -> 51889117 | J33: =+C33-D33-E33 -> 0
A34: 12.1. | B34: Начисленные проценты к получению, брутто | C34: =+'Bank Assets Analysis'!S43 -> 186692854 | D34: =+'Bank Assets Analysis'!T43 -> 134803737 | E34: =+'Bank Assets Analysis'!U43 -> 51889117 | J34: =+C34-D34-E34 -> 0
A35: 12.2. | B35: Начисленные беспроцентные доходы к получению, брутто | C35: =+D35+E35 -> 86941 | D35: 86941 | E35: 0 | J35: =+C35-D35-E35 -> 0
A36: 12.2.1. | B36: Минус: Резерв возможных убытков | C36: =+D36+E36 -> 0 | D36: 0 | E36: 0 | J36: =+C36-D36-E36 -> 0
A37: 13 | B37: Другое собственное имущество банка, чистые | C37: =+'Bank Assets Analysis'!S39 -> 0 | D37: =+'Bank Assets Analysis'!T39 -> 0 | E37: =+'Bank Assets Analysis'!U39 -> 0 | J37: =+C37-D37-E37 -> 0
A38: 13.1. | B38: Другие собственное имущество, взысканное по кредитам и лизингу, брутто | C38: =+D38+E38 -> 0 | D38: 0 | E38: 0 | J38: =+C38-D38-E38 -> 0
A39: 13.2. | B39: Другое собственное имущество банка, брутто | C39: =+D39+E39 -> 0 | D39: 0 | E39: 0 | J39: =+C39-D39-E39 -> 0
A40: 13.3. | B40: Минус:Накопленный износ и резервы на возможные убытки | C40: =+D40+E40 -> 0 | D40: 0 | E40: 0 | J40: =+C40-D40-E40 -> 0
...

Sheet Bank Capital Calc (2)
A1: РАСЧЕТ РЕГУЛЯТИВНОГО КАПИТАЛА БАНКА | C1: Таблица-5
B3: =Balance!B3 -> АКБ"Микрокредитбанк" | C3: =+Balance!C3 -> 44196
A4: № | B4: Характеристики | C4: Итого капитала
A5: I. | B5: КАПИТАЛ УРОВНЯ 1
A6: 1 | B6: ОСНОВНОЙ КАПИТАЛ УРОВНЯ 1
A7: 1.1. | B7: Обыкновенные Акции, чистые | C7: Формула
A8: a | B8: Полностью оплаченные обыкновенные акции
A9: б | B9: Минус: Обратно Выкупленные обыкновенные акции
A10: 1.2. | B10: Добавленный капитал - Обыкновенные | C10: 0
A11: 1.3. | B11: Нераспределенная прибыль (убыток), в том числе капитальные резервы | C11: Формула
A12: а | B12: Капитальные резервы
A13: б | B13: Нераспределенная прибыль
A14: в | B14: Убыток за предыдущие периоды
A15: г | B15: Убыток за текущий год
A16: 1.4. | B16: Интерес меньшинства в консолидированных дочерних компаниях (согласно МБС)
A17: 1.5. | B17: Резерв на девальвацию
B18: Итого основного капитала уровня I до вычетов | C18: Формула
A19: 1.6. | B19: Вычеты из суммы основного капитала уровня I | C19: Формула
A20: а | B20: Нематериальные активы
A21: б | B21: Все инвестиции в капитал неконсолидированных хозяйствующих субъектов, в том числе в долговые обязательства, которые образуют капитал хозяйствующих субъектов
A22: в | B22: Инвестиции в капитал других банков
A23: I | B23: ВСЕГО СКОРРЕКТИРОВАННЫЙ ОСНОВНОЙ КАПИТАЛ УРОВНЯ I | C23: Формула
A24: 2 | B24: ДОБАВЛЕННЫЙ КАПИТАЛ УРОВНЯ 1
A25: 2.1. | B25: Некумулятивные бессрочные привилегированные акции | C25: =+C26+C27 -> 0
A26: а | B26: Полностью оплаченные привилегированные акции
A27: б | B27: Минус: Обратно Выкупленные привилегированные акции
A28: 2.2. | B28: Добавленный капитал - Привилегированные | C28: 0
A29: 2.3. | B29: Интерес меньшинства в консолидированных дочерних компаниях | C29: 0
A30: 2.4. | B30: Доля участия дочерних предприятий (выпущенные дочерними предприятиями и находящиеся во владении третьих лиц инструменты, приравненные к капиталу) | C30: 0
A31: II | B31: ВСЕГО ДОБАВЛЕННЫЙ КАПИТАЛ УРОВНЯ I | C31: =+C25+C28+C29+C30 -> 0
A32: III | B32: ВСЕГО СКОРРЕКТИРОВАННЫЙ КАПИТАЛ УРОВНЯ I | C32: Формула
B33: КАПИТАЛ УРОВНЯ II
A34: 3.1. | B34: Прибыль за текущий год
A35: 3.2. | B35: Резервы, создаваемые на стандартные кредиты (активы), в размере не более 1.25% от общей суммы активов, взвешенных с учетом риска | C35: =IF(Balance!C72<(C43*1.25%),Balance!C72,(C43*1.25%)) -> #REF!
A36: 3.3. | B36: Излишки оценочной стоимости прироста над первоначальной стоимостью
A37: 3.4. | B37: Другие инструменты капитала (не более 1/3 части капитала 1 уровня после вычетов)
A38: 3.5. | B38: Субординированный долг
A39: 3.6. | B39: Вычеты превышения Капитала Уровня II над Капиталом Уровня I | C39: Формула
B40: Итого капитала Уровня II | C40: =SUM(C34:C38) -> #REF!
A41: IV | B41: СКОРРЕКТИРОВАННЫЙ КАПИТАЛ УРОВНЯ II | C41: Формула
...

Sheet Liquidity Analysis
B1: АНАЛИЗ ЛИКВИДНОСТИ | E1: Таблица-16
B2: =Balance!B3 -> АКБ"Микрокредитбанк" | C2: =+Balance!B2 -> 31 Декабрь, 2020 | E2: в тыс. сум
A3: № | B3: Ликвидные активы | C3: Сумма | D3: Нацвалюта | E3: Инвалюта
B5: Часть 1. Высоколиквидные активы | C5: в процентах
A6: 1.1. | B6: Наличные денежные средства | C6: =+'Bank Assets Analysis'!S7-'Bank Assets Analysis'!S8 -> 220312147 | D6: =+'Bank Assets Analysis'!T7-'Bank Assets Analysis'!T8 -> 92534448 | E6: =+'Bank Assets Analysis'!U7-'Bank Assets Analysis'!U8 -> 127777699
A7: 1.2. | B7: К получению из ЦБРУ не учитывая сумму обязательных резервов банка(ФОР) | C7: =+'Bank Assets Analysis'!S9 -> 359385307 | D7: =+'Bank Assets Analysis'!T9 -> 313936606 | E7: =+'Bank Assets Analysis'!U9 -> 45448701
A8: 1.3. | B8: Ценные бумаги, выпущенные Правительством Республики Узбекистан и ЦБРУ | C8: =+'Bank Assets Analysis'!S20-'Bank Assets Analysis'!S21+'Bank Assets Analysis'!S36 -> 200000000 | D8: =+'Bank Assets Analysis'!T20-'Bank Assets Analysis'!T21+'Bank Assets Analysis'!T36 -> 200000000 | E8: =+'Bank Assets Analysis'!U20-'Bank Assets Analysis'!U21+'Bank Assets Analysis'!U36 -> 0
A9: 1.4. | B9: Денежные средства на корсчетах открытых в иностранных банках с рейтингом не ниже инвестиционного и в местных банках имеющих кредитный рейтинг | C9: =+E9 -> 428640233 | E9: =+'Bank Assets Analysis'!D12+'Bank Assets Analysis'!D13 -> 428640233
A10: 1.5. | B10: Депозиты размещенные на условиях овернайт в иностранной валюте с рейтингом не ниже инвестиционного | C10: =+E10 -> 0 | E10: =+'Bank Assets Analysis'!F15 -> 0
A11: 1.6. | B11: Ценные бумаги выпущенные МВФ, входящие организации в группу Всемирного банка, МФК, АБР, Азиатский банк инфроструктуры и инвестиции, ЕБРР, Европейский инвестиционный банк, Исламский банк развития и Банк развития Европейского союза | C11: =+'Bank Assets Analysis'!S23 -> 0 | D11: =+'Bank Assets Analysis'!T23 -> 0 | E11: =+'Bank Assets Analysis'!U23 -> 0
A12: 1.7. | B12: Правительственные ценные бумаги стран с низкой степенью странового риска | C12: =+'Bank Assets Analysis'!S22 -> 0 | D12: =+'Bank Assets Analysis'!T22 -> 0 | E12: =+'Bank Assets Analysis'!U22 -> 0
A13: 1.8. | B13: Всего высоколиквидных активов | C13: =SUM(C6:C12)-'Bank Liabilities Analysis'!U25+194716877 -> 1403054564 | D13: =SUM(D6:D12)+194716877 -> 801187931 | E13: =SUM(E6:E12)-'Bank Liabilities Analysis'!U25 -> 601866633 | F13: =SUM(C6:C12)-'Bank Liabilities Analysis'!U25 -> 1208337687 | G13: =SUM(D6:D12) -> 606471054 | H13: =SUM(E6:E12)-'Bank Liabilities Analysis'!U25 -> 601866633
B14: Часть 2. Экономические нормативы - Ликвидность
A15: 2.1. | B15: Расчет коэффициента высоколиквидных активов к всего активам | C15: =IFERROR((+C16/C17),0) -> 0.13644521 | D15: =IFERROR((+D16/D17),0) -> 0.11938191 | E15: =IFERROR((+E16/E17),0) -> 0.16850597
A16: 2.1.1. | B16: Высоколиквидные активы | C16: =+C13 -> 1403054564 | D16: =+D13 -> 801187931 | E16: =+E13 -> 601866633
A17: 2.1.2. | B17: Всего активов | C17: =+Balance!C45 -> 10282915665 | D17: =+Balance!D45 -> 6711133420 | E17: =+Balance!E45 -> 3571782245
A18: 2.2. | B18: Расчет коэффициента высоколиквидных активов к краткосрочным обязательствам | C18: =IFERROR((+C19/C20),0) -> 0.37763754 | D18: =IFERROR((+D19/D20),0) -> 0.34826895 | E18: =IFERROR((+E19/E20),0) -> 0.42538925
A19: 2.2.1. | B19: Высоколиквидные активы | C19: =+C13 -> 1403054564 | D19: =+D13 -> 801187931 | E19: =+E13 -> 601866633
A20: 2.2.2. | B20: Краткосрочные обязательства | C20: =+'Bank Liabilities Analysis'!C39+'Bank Liabilities Analysis'!E39+'Bank Liabilities Analysis'!G39+'Bank Liabilities Analysis'!I39+'Bank Liabilities Analysis'!K39+'Bank Liabilities Analysis'!M39 -> 3715347186 | D20: =+C20-E20 -> 2300486242 | E20: =+'Bank Liabilities Analysis'!D39+'Bank Liabilities Analysis'!F39+'Bank Liabilities Analysis'!H39+'Bank Liabilities Analysis'!J39+'Bank Liabilities Analysis'!L39+'Bank Liabilities Analysis'!N39 -> 1414860944
A21: 2.3. | B21: Коэффициент покрытия ликвидности (действующий норматив)* | C21: =IFERROR((+C22/C23),0) -> 2.3646901 | D21: =IFERROR((+D22/D23),0) -> 1.8285311 | E21: =IFERROR((+E22/E23),0) -> 3.8786024
A22: 2.3.1. | B22: Высоколиквидные активы | C22: =+C13 -> 1403054564 | D22: =+D13 -> 801187931 | E22: =+E13 -> 601866633
A23: 2.3.2. | B23: Чистый отток в последующие 30 дней | C23: =+'Bank Assets Analysis'!X61 -> 5.9333548e+08 | D23: =+'Bank Assets Analysis (нац)'!S54 -> 4.3815932e+08 | E23: =+'Bank Assets Analysis'!Z61 -> 1.5517616e+08
B24: Сумма оттока за 30 дней | C24: =+'Bank Assets Analysis'!X63 -> 7.2071359e+08 | D24: =+'Bank Assets Analysis (нац)'!S56 -> 5.2720965e+08 | E24: =+'Bank Assets Analysis'!Z63 -> 1.9350394e+08 | F24: все расходы за 30 денй умноженная на коэффициенты
B25: Сумма притока за 30 дней | C25: =+'Bank Assets Analysis'!X64 -> 1.2737811e+08 | D25: =+'Bank Assets Analysis (нац)'!S58 -> 89050327 | E25: =+'Bank Assets Analysis'!Z64 -> 38327783 | F25: Ликвидные активы за 30 дней
A26: 2.4. | B26: Коэффициент покрытия ликвидности (внедряемый норматив)** | C26: =IFERROR((+C27/C28),0) -> 1.172964 | D26: =IFERROR((+D27/D28),0) -> 1.1490837 | E26: =IFERROR((+E27/E28),0) -> 1.2063366
A27: 2.4.1. | B27: Высоколиквидные активы | C27: =+C13 -> 1403054564 | D27: =+D13 -> 801187931 | E27: =+E13 -> 601866633
A28: 2.4.2. | B28: Чистый отток в последующие 30 дней | C28: =+'Bank Assets Analysis'!AC61 -> 1.1961617e+09 | D28: =+'Bank Assets Analysis (нац)'!V54 -> 6.9724073e+08 | E28: =+'Bank Assets Analysis'!AE61 -> 4.9892098e+08
B29: Сумма оттока за 30 дней | C29: =+'Bank Assets Analysis'!AC63 -> 1.3343121e+09 | D29: =+'Bank Assets Analysis (нац)'!V56 -> 7.9395111e+08 | E29: =+'Bank Assets Analysis'!AE63 -> 5.40361e+08
B30: Сумма притока за 30 дней | C30: =+'Bank Assets Analysis'!AC66 -> 1.381504e+08 | D30: =+'Bank Assets Analysis (нац)'!V58 -> 96710380 | E30: =+'Bank Assets Analysis'!AE66 -> 41440020
A31: 2.5. | B31: Норма чистого стабильного финансирования | C31: =IFERROR((C32/C37),0) -> 1.188397 | D31: =IFERROR((D32/D37),0) -> 1.2444545 | E31: =IFERROR((E32/E37),0) -> 1.0806276
A32: 2.6. | B32: Доступная сумма стабильного финансирования | C32: =SUM(C33:C36) -> 7.6821726e+09 | D32: =SUM(D33:D36) -> 5.2919006e+09 | E32: =SUM(E33:E36) -> 2.3902721e+09
A33: 2.6.1. | B33: Собственный капитал | C33: =Balance!C77 -> 1738289532 | D33: =Balance!D77 -> 1738289532 | E33: =Balance!E77 -> 0
A34: 2.6.2. | B34: Обязательства свыше 1 года | C34: ='Bank Liabilities Analysis'!O39+'Bank Liabilities Analysis'!Q39 -> 4829278947 | D34: =+'Bank Liabilities Analysis (нац)'!I40+'Bank Liabilities Analysis (нац)'!J40 -> 2863465176 | E34: ='Bank Liabilities Analysis'!P39+'Bank Liabilities Analysis'!R39 -> 1965813771
A35: 2.6.3. | B35: 30% других бессрочных обязательств | C35: =+('Bank Liabilities Analysis'!C39)*0.3 -> 2.4420139e+08 | D35: =+('Bank Liabilities Analysis (нац)'!C40)*0.3 -> 2.0151693e+08 | E35: =+('Bank Liabilities Analysis'!D39)*0.3 -> 42684454
A36: 2.6.4. | B36: 30% других обязательств менее 1 года | C36: =+('Bank Liabilities Analysis'!E39+'Bank Liabilities Analysis'!G39+'Bank Liabilities Analysis'!I39+'Bank Liabilities Analysis'!K39+'Bank Liabilities Analysis'!M39)*0.3 -> 8.7040277e+08 | D36: =+('Bank Liabilities Analysis (нац)'!D40+'Bank Liabilities Analysis (нац)'!E40+'Bank Liabilities Analysis (нац)'!F40+'Bank Liabilities Analysis (нац)'!G40+'Bank Liabilities Analysis (нац)'!H40)*0.3 -> 4.8862894e+08 | E36: =+('Bank Liabilities Analysis'!F39+'Bank Liabilities Analysis'!H39+'Bank Liabilities Analysis'!J39+'Bank Liabilities Analysis'!L39+'Bank Liabilities Analysis'!N39)*0.3 -> 381773829
A37: 2.7. | B37: Необходимая сумма стабильного финансирования | C37: =SUM(C38:C43) -> 6464315176 | D37: =SUM(D38:D43) -> 4.2523858e+09 | E37: =SUM(E38:E43) -> 2.2119294e+09
A38: 2.7.1. | B38: Активы свыше 1 года | C38: =+'Bank Assets Analysis'!O45-'Bank Assets Analysis'!O38+'Bank Assets Analysis'!Q45-'Bank Assets Analysis'!Q38 -> 4734103612 | D38: =+C38-E38 -> 2986482565 | E38: =+'Bank Assets Analysis'!P45-'Bank Assets Analysis'!P41-'Bank Assets Analysis'!P38+'Bank Assets Analysis'!R45-'Bank Assets Analysis'!R41-'Bank Assets Analysis'!R38 -> 1747621047
A39: 2.7.2. | B39: Банковские помещения, мебель и оборудование, чистые | C39: =+'Bank Assets Analysis'!S38 -> 201801025 | D39: =+'Bank Assets Analysis'!T38 -> 201801025 | E39: =+'Bank Assets Analysis'!U38 -> 0
A40: 2.7.3. | B40: Кредиты и лизинги и авансы в процессе судебного разбирательства, чистые или не взысканные в установленном порядке | C40: =+'Bank Assets Analysis'!C29+'Bank Assets Analysis'!C30+'Bank Assets Analysis'!C31+'Bank Assets Analysis'!C33 -> 91809428 | D40: =+'Bank Assets Analysis (нац)'!C29+'Bank Assets Analysis (нац)'!C30+'Bank Assets Analysis (нац)'!C31+'Bank Assets Analysis (нац)'!C33 -> 85440009 | E40: =+'Bank Assets Analysis'!D29+'Bank Assets Analysis'!D30+'Bank Assets Analysis'!D31+'Bank Assets Analysis'!D33 -> 6369419
A41: 2.7.4. | B41: Активы в процессе судебного разбирательства или не взысканные в установленном порядке(не указанные в строке 2.7.4.) | C41: =+D41+E41 -> 0 | E41: 0
...

Sheet Bank Assets Analysis
A1: АНАЛИЗ АКТИВОВ БАНКА | AC1: Таблица-17
B2: =Balance!B3 -> АКБ"Микрокредитбанк" | T2: =+Balance!B2 -> 31 Декабрь, 2020 | AE2: в тыс. сум
A3: № | B3: Характеристики | C3: Срок погашения (в днях) | S3: ВСЕГО | T3: из них | V3: Расчет коэффициента покрытия ликвидности (действующий норматив) | AA3: Расчет коэффициента покрытия ликвидности (внедряемый норматив)
C4: Бессрочные | E4: От 1 до 7 дней | G4: От 8 до 30 дней | I4: От 31 до 90 дней | K4: От 91 до 180 дней | M4: От 181 до 365 дней | O4: От 366 до 730 дней | Q4: Свыше 2 лет
C5: Сумма | D5: в том числе, в иностранной валюте (в экв. в сумах) | E5: Сумма | F5: в том числе, в иностранной валюте (в экв. в сумах) | G5: Сумма | H5: в том числе, в иностранной валюте (в экв. в сумах) | I5: Сумма | J5: в том числе, в иностранной валюте (в экв. в сумах) | K5: Сумма | L5: в том числе, в иностранной валюте (в экв. в сумах) | M5: Сумма | N5: в том числе, в иностранной валюте (в экв. в сумах) | O5: Сумма | P5: в том числе, в иностранной валюте (в экв. в сумах) | Q5: Сумма | R5: в том числе, в иностранной валюте (в экв. в сумах) | T5: в национальной валюте | U5: в иностранной валюте (в экв. в сумах) | V5: Коэффициент | W5: Сумма активов | X5: Высоко-ликвидные активы/приток | Y5: Сумма активов (в иностранной валюте) | Z5: Высоко-ликвидные активы/приток (в иностранной валюте) | AA5: Коэффициент | AB5: Сумма активов | AC5: Высоко-ликвидные активы/приток | AD5: Сумма активов (в иностранной валюте) | AE5: Высоко-ликвидные активы/приток (в иностранной валюте)
B6: АКТИВЫ
A7: 1. | B7: Кассовая наличность и другие платежные документы | C7: 220312147 | D7: 127777699 | S7: =+C7+E7+G7+I7+K7+M7+O7+Q7 -> 220312147 | T7: =+S7-U7 -> 92534448 | U7: =+D7+F7+H7+J7+L7+N7+P7+R7 -> 127777699 | V7: 1 | W7: =+S7-S8 -> 220312147 | X7: =+W7*V7 -> 220312147 | Y7: =+U7-U8 -> 127777699 | Z7: =+Y7*V7 -> 127777699 | AA7: 1 | AB7: =+S7-S8 -> 220312147 | AC7: =+AB7*AA7 -> 220312147 | AD7: =+U7-U8 -> 127777699 | AE7: =+AD7*AA7 -> 127777699
A8: 1.1 | B8: в том числе чеки и другие платежные документы | S8: =+C8+E8+G8+I8+K8+M8+O8+Q8 -> 0 | T8: =+S8-U8 -> 0 | U8: =+E8+G8+I8+K8+M8+O8+Q8+S8 -> 0
A9: 2. | B9: К получению из ЦБРУ не учитывая сумму обязательных резервов банка(ФОР) | C9: 359385307 | D9: 45448701 | S9: =+C9+E9+G9+I9+K9+M9+O9+Q9 -> 359385307 | T9: =+S9-U9 -> 313936606 | U9: =+D9+F9+H9+J9+L9+N9+P9+R9 -> 45448701 | V9: 1 | W9: =+S9 -> 359385307 | X9: =+W9*V9 -> 359385307 | Y9: =+U9 -> 45448701 | Z9: =+Y9*V9 -> 45448701 | AA9: 1 | AB9: =S9 -> 359385307 | AC9: =+AB9*AA9 -> 359385307 | AD9: =+U9 -> 45448701 | AE9: =+AD9*AA9 -> 45448701
A10: 2.1 | B10: К получению из ЦБРУ (сумма обязательных резервов банка(ФОР)) | G10: 21398086 | H10: 0 | S10: =+C10+E10+G10+I10+K10+M10+O10+Q10 -> 21398086 | T10: =+S10-U10 -> 21398086 | U10: =+D10+F10+H10+J10+L10+N10+P10+R10 -> 0 | V10: 0 | AA10: 0
A11: 3. | B11: К получению из других банков | C11: =SUM(C12:C18)-C15 -> 440531648 | D11: =SUM(D12:D18)-D15 -> 435253295 | E11: =SUM(E12:E18)-E15 -> 0 | F11: =SUM(F12:F18)-F15 -> 0 | G11: =SUM(G12:G18)-G15 -> 0 | H11: =SUM(H12:H18)-H15 -> 0 | I11: =SUM(I12:I18)-I15 -> 40000000 | J11: =SUM(J12:J18)-J15 -> 0 | ... R11: =SUM(R12:R18)-R15 -> 0 | S11: =+C11+E11+G11+I11+K11+M11+O11+Q11 -> 666431398 | T11: =+S11-U11 -> 231178103 | U11: =+D11+F11+H11+J11+L11+N11+P11+R11 -> 435253295
A12: 3.1 | B12: Кор счета в банках с низким уровнем риска (ностро) | C12: 1312439 | D12: 1312439 | S12: =+C12+E12+G12+I12+K12+M12+O12+Q12 -> 1312439 | T12: =+S12-U12 -> 0 | U12: =+D12+F12+H12+J12+L12+N12+P12+R12 -> 1312439 | V12: 1 | W12: =+C12 -> 1312439 | X12: =+W12*V12 -> 1312439 | Y12: =+D12 -> 1312439 | Z12: =+Y12*V12 -> 1312439 | AA12: 1 | AB12: =+C12 -> 1312439 | AC12: =+AB12*AA12 -> 1312439 | AD12: =+D12 -> 1312439 | AE12: =+AD12*AA12 -> 1312439
A13: 3.2 | B13: Кор счета в местных банках (ностро) имеющих кредитный рейтинг | C13: 427327794 | D13: 427327794 | S13: =+C13 -> 427327794 | T13: =+S13-U13 -> 0 | U13: =+D13 -> 427327794 | V13: 1 | W13: =+C13 -> 427327794 | X13: =+W13*V13 -> 427327794 | Y13: =+D13 -> 427327794 | Z13: =+Y13*V13 -> 427327794 | AA13: 1 | AB13: =+C13 -> 427327794 | AC13: =+AB13*AA13 -> 427327794 | AD13: =+D13 -> 427327794 | AE13: =+AD13*AA13 -> 427327794
A14: 3.3 | B14: Депозиты размещенные на условиях овернайт | S14: =+E14 -> 0 | T14: =+S14-U14 -> 0 | U14: =+F14 -> 0 | V14: 1 | W14: =+E14-E15 -> 0 | X14: =+W14*V14 -> 0 | Y14: =+F14-F15 -> 0 | Z14: =+Y14*V14 -> 0 | AA14: 1 | AB14: =+E14-E15 -> 0 | AC14: =+AB14*AA14 -> 0 | AD14: =+F14-F15 -> 0 | AE14: =+AD14*AA14 -> 0
A15: 3.3.1. | B15: в том числе депозиты размещенные на условиях овернайт в иностранной валюте с рейтингом не ниже инвестиционного. | S15: =+E15 -> 0 | T15: =+S15-U15 -> 0 | U15: =+F15 -> 0 | V15: 1 | W15: =+E15 -> 0 | X15: =+W15*V15 -> 0 | Y15: =+F15 -> 0 | Z15: =+Y15*V15 -> 0 | AA15: 1 | AB15: =+E15 -> 0 | AC15: =+AB15*AA15 -> 0 | AD15: =+F15 -> 0 | AE15: =+AD15*AA15 -> 0
A16: 3.4 | B16: К получению из других банков - депозиты | C16: 6665069 | D16: 6613062 | I16: 40000000 | K16: 47569200 | M16: 101000000 | O16: 3000000 | Q16: 34330550 | S16: =+C16+E16+G16+I16+K16+M16+O16+Q16 -> 232564819 | T16: =+S16-U16 -> 225951757 | U16: =+D16+F16+H16+J16+L16+N16+P16+R16 -> 6613062 | V16: 1 | W16: =+C16+E16+G16 -> 6665069 | X16: =+W16*V16 -> 6665069 | Y16: =+D16+F16+H16 -> 6613062 | Z16: =+Y16*V16 -> 6613062 | AA16: 1 | AB16: =+C16+E16+G16+E12+G12+E13+G13+E14-E15 -> 6665069 | AC16: =+AB16*AA16 -> 6665069 | AD16: =+D16+F16+H16+F12+H12+F13+H13+F14-F15 -> 6613062 | AE16: =+AD16*AA16 -> 6613062
A17: 3.5 | B17: К получению из других банков по расчетам пластиковых карт | C17: 4724609 | D17: 0 | S17: =+C17+E17+G17+I17+K17+M17+O17+Q17 -> 4724609 | T17: =+S17-U17 -> 4724609 | U17: =+D17+F17+H17+J17+L17+N17+P17+R17 -> 0 | V17: 0.5 | W17: =+C17+E17+G17 -> 4724609 | X17: =+W17*V17 -> 2362304.5 | Y17: =+D17+F17+H17 -> 0 | Z17: =+Y17*V17 -> 0 | AA17: 1 | AB17: =+C17+E17+G17 -> 4724609 | AC17: =+AB17*AA17 -> 4724609 | AD17: =+D17+F17+H17 -> 0 | AE17: =+AD17*AA17 -> 0
A18: 3.6 | B18: Другие статьи | C18: 501737 | D18: 0 | S18: =+C18+E18+G18+I18+K18+M18+O18+Q18 -> 501737 | T18: =+S18-U18 -> 501737 | U18: =+D18+F18+H18+J18+L18+N18+P18+R18 -> 0 | V18: 0.3 | W18: =+C18+E18+G18 -> 501737 | X18: =+W18*V18 -> 150521.1 | Y18: =+D18+F18+H18 -> 0 | Z18: =+Y18*V18 -> 0 | AA18: 1 | AB18: =+C18+E18+G18 -> 501737 | AC18: =+AB18*AA18 -> 501737 | AD18: =+D18+F18+H18 -> 0 | AE18: =+AD18*AA18 -> 0
A19: 4. | B19: Счета купли и продажи, чистые | C19: =SUM(C20:C25)-C21 -> 2938414 | D19: =SUM(D20:D25)-D21 -> 0 | E19: =SUM(E20:E25)-E21 -> 0 | F19: =SUM(F20:F25)-F21 -> 0 | G19: =SUM(G20:G25)-G21 -> 48000000 | H19: =SUM(H20:H25)-H21 -> 0 | I19: =SUM(I20:I25)-I21 -> 0 | J19: =SUM(J20:J25)-J21 -> 0 | ... R19: =SUM(R20:R25)-R21 -> 0 | S19: =+C19+E19+G19+I19+K19+M19+O19+Q19 -> 202938414 | T19: =+S19-U19 -> 202938414 | U19: =+D19+F19+H19+J19+L19+N19+P19+R19 -> 0
A20: 4.1 | B20: Ценные бумаги, выпущенные Правительством Республики Узбекистан и ЦБРУ (векселя, облигации и другие долговые ценные бумаги) | C20: 0 | D20: 0 | E20: 0 | F20: 0 | G20: 48000000 | H20: 0 | I20: 0 | J20: 0 | K20: 102000000 | L20: 0 | M20: 50000000 | N20: 0 | O20: 0 | P20: 0 | Q20: 0 | R20: 0 | S20: =+C20+E20+G20+I20+K20+M20+O20+Q20 -> 200000000 | T20: =+S20-U20 -> 200000000 | U20: =+D20+F20+H20+J20+L20+N20+P20+R20 -> 0 | V20: 1 | W20: =+S20-S21 -> 200000000 | X20: =+W20*V20 -> 200000000 | Y20: =+U20-U21 -> 0 | Z20: =+Y20*V20 -> 0 | AA20: 1 | AB20: =+S20-S21 -> 200000000 | AC20: =+AB20*AA20 -> 200000000 | AD20: =+U20-U21 -> 0 | AE20: =+AD20*AA20 -> 0
A21: 4.1.1 | B21: в том числе, Ценные бумаги, выпущенные Правительством Республики Узбекистан и ЦБРУ (векселя, облигации и другие долговые ценные бумаги) под залогом | S21: =+C21+E21+G21+I21+K21+M21+O21+Q21 -> 0 | T21: =+S21-U21 -> 0 | U21: =+D21+F21+H21+J21+L21+N21+P21+R21 -> 0 | V21: 1 | W21: =+C21+E21+G21 -> 0 | X21: =+W21*V21 -> 0 | Y21: =+D21+F21+H21 -> 0 | Z21: =+Y21*V21 -> 0 | AA21: 1 | AB21: =+C21+E21+G21 -> 0 | AC21: =+AB21*AA21 -> 0 | AD21: =+D21+F21+H21 -> 0 | AE21: =+AD21*AA21 -> 0
A22: 4.2 | B22: Правительственные ценные бумаги стран с низкой степенью странового риска | S22: =+C22+E22+G22+I22+K22+M22+O22+Q22 -> 0 | T22: =+S22-U22 -> 0 | U22: =+D22+F22+H22+J22+L22+N22+P22+R22 -> 0 | V22: 1 | W22: =+S22 -> 0 | X22: =+W22*V22 -> 0 | Y22: =+U22 -> 0 | Z22: =+Y22*V22 -> 0 | AA22: 1 | AB22: =+S22 -> 0 | AC22: =+AB22*AA22 -> 0 | AD22: =+U22 -> 0 | AE22: =+AD22*AA22 -> 0
A23: 4.3 | B23: Ценные бумаги выпущенные МВФ, входящие организации в группу Всемирного банка, МФК, АБР, Азиатский банк инфроструктуры и инвестиции, ЕБРР, Европейский инвестиционный банк, Исламский банк развития и Банк развития Европейского союза | S23: =+C23+E23+G23+I23+K23+M23+O23+Q23 -> 0 | T23: =+S23-U23 -> 0 | U23: =+D23+F23+H23+J23+L23+N23+P23+R23 -> 0 | V23: 1 | W23: =+S23 -> 0 | X23: =+W23*V23 -> 0 | Y23: =+U23 -> 0 | Z23: =+Y23*V23 -> 0 | AA23: 1 | AB23: =+S23 -> 0 | AC23: =+AB23*AA23 -> 0 | AD23: =+U23 -> 0 | AE23: =+AD23*AA23 -> 0
A24: 4.4 | B24: Ценные бумаги ведущих транснациональных компаний с рейтингом не ниже инвестиционного | S24: =+C24+E24+G24+I24+K24+M24+O24+Q24 -> 0 | T24: =+S24-U24 -> 0 | U24: =+D24+F24+H24+J24+L24+N24+P24+R24 -> 0 | V24: 1 | W24: =+S24 -> 0 | X24: =+W24*V24 -> 0 | Y24: =+U24 -> 0 | Z24: =+Y24*V24 -> 0 | AA24: 1 | AB24: =+S24 -> 0 | AC24: =+AB24*AA24 -> 0 | AD24: =+U24 -> 0 | AE24: =+AD24*AA24 -> 0
A25: 4.5 | B25: Другие | C25: 2938414 | D25: 0 | S25: =+C25+E25+G25+I25+K25+M25+O25+Q25 -> 2938414 | T25: =+S25-U25 -> 2938414 | U25: =+D25+F25+H25+J25+L25+N25+P25+R25 -> 0 | V25: 0 | AA25: 0
A26: 5. | B26: Купленные векселя, чистые | S26: =+C26+E26+G26+I26+K26+M26+O26+Q26 -> 0 | T26: =+S26-U26 -> 0 | U26: =+D26+F26+H26+J26+L26+N26+P26+R26 -> 0 | V26: 0.3 | W26: =+C26+E26+G26 -> 0 | X26: =+W26*V26 -> 0 | Y26: =+D26+F26+H26 -> 0 | Z26: =+Y26*V26 -> 0 | AA26: 0.3 | AB26: =+E26+G26 -> 0 | AC26: =+AB26*AA26 -> 0 | AD26: =+F26+H26 -> 0 | AE26: =+AD26*AA26 -> 0
A27: 6. | B27: Обязательства клиентов по траттам под аккредитивы или трастовые документы | S27: =+C27+E27+G27+I27+K27+M27+O27+Q27 -> 0 | T27: =+S27-U27 -> 0 | U27: =+D27+F27+H27+J27+L27+N27+P27+R27 -> 0 | V27: 0.3 | W27: =+C27+E27+G27 -> 0 | X27: =+W27*V27 -> 0 | Y27: =+D27+F27+H27 -> 0 | Z27: =+Y27*V27 -> 0 | AA27: 0.5 | AB27: =+E27+G27 -> 0 | AC27: =+AB27*AA27 -> 0 | AD27: =+F27+H27 -> 0 | AE27: =+AD27*AA27 -> 0
A28: 7. | B28: Обязательства клиентов по непогашенным акцептам этого банка | S28: =+C28+E28+G28+I28+K28+M28+O28+Q28 -> 0 | T28: =+S28-U28 -> 0 | U28: =+D28+F28+H28+J28+L28+N28+P28+R28 -> 0 | V28: 0.3 | W28: =+C28+E28+G28 -> 0 | X28: =+W28*V28 -> 0 | Y28: =+D28+F28+H28 -> 0 | Z28: =+Y28*V28 -> 0 | AA28: 0.3 | AB28: =+E28+G28 -> 0 | AC28: =+AB28*AA28 -> 0 | AD28: =+F28+H28 -> 0 | AE28: =+AD28*AA28 -> 0
A29: 8. | B29: Кредиты и лизинги, предоставленные ЦБРУ, чистые | S29: =+C29+E29+G29+I29+K29+M29+O29+Q29 -> 0 | T29: =+S29-U29 -> 0 | U29: =+D29+F29+H29+J29+L29+N29+P29+R29 -> 0 | V29: 1 | W29: =+C29+E29+G29 -> 0 | X29: =+W29*V29 -> 0 | Y29: =+D29+F29+H29 -> 0 | Z29: =+Y29*V29 -> 0 | AA29: 1 | AB29: =+C29+E29+G29 -> 0 | AC29: =+AB29*AA29 -> 0 | AD29: =+D29+F29+H29 -> 0 | AE29: =+AD29*AA29 -> 0
A30: 9. | B30: Кредиты и лизинги, предоставленные другим банкам, чистые | S30: =+C30+E30+G30+I30+K30+M30+O30+Q30 -> 0 | T30: =+S30-U30 -> 0 | U30: =+D30+F30+H30+J30+L30+N30+P30+R30 -> 0 | V30: 0.5 | W30: =+E30+G30 -> 0 | X30: =+W30*V30 -> 0 | Y30: =F30+H30 -> 0 | Z30: =+Y30*V30 -> 0 | AA30: 0.5 | AB30: =+E30+G30 -> 0 | AC30: =+AB30*AA30 -> 0 | AD30: =+F30+H30 -> 0 | AE30: =+AD30*AA30 -> 0
A31: 10 | B31: Кредиты и лизинги, предоставленные другим клиентам, чистые | C31: 91834482 | D31: 6369419 | E31: 157359937 | F31: 26913310 | G31: 53906229 | H31: 26913310 | I31: 640161029 | J31: 188388519 | K31: 1098984494 | L31: 397510618 | M31: 1603410225 | N31: 476527157 | O31: 2239130671 | P31: 772987367 | Q31: 2457642391 | R31: 974633680 | S31: =+C31+E31+G31+I31+K31+M31+O31+Q31 -> 8342429458 | T31: =+S31-U31 -> 5472186078 | U31: =+D31+F31+H31+J31+L31+N31+P31+R31 -> 2870243380 | V31: 0.3 | W31: =+E31+G31 -> 211266166 | X31: =+W31*V31 -> 63379850 | Y31: =F31+H31 -> 53826620 | Z31: =+Y31*V31 -> 16147986 | AA31: 0.5 | AB31: =+E31+G31 -> 211266166 | AC31: =+AB31*AA31 -> 105633083 | AD31: =+F31+H31 -> 53826620 | AE31: =+AD31*AA31 -> 26913310
A32: 10.1 | B32: в том числе, кредиты и лизинги, предоставленные физическим лицам, чистые | C32: 0 | D32: 0 | E32: 56372153 | F32: 0 | G32: 16870841 | H32: 0 | I32: 184961398 | J32: 0 | K32: 313432680 | L32: 0 | M32: 533129992 | N32: 0 | O32: 682443985 | P32: 0 | Q32: 565889805 | R32: 0 | S32: =+C32+E32+G32+I32+K32+M32+O32+Q32 -> 2353100854 | T32: =+S32-U32 -> 2353100854 | U32: =+D32+F32+H32+J32+L32+N32+P32+R32 -> 0 | V32: 0 | W32: =+E32+G32 -> 73242994 | X32: =+W32*V32 -> 0 | Y32: =F32+H32 -> 0 | Z32: =+Y32*V32 -> 0 | AA32: 0 | AB32: =+E32+G32 -> 73242994 | AC32: =+AB32*AA32 -> 0 | AD32: =+F32+H32 -> 0 | AE32: =+AD32*AA32 -> 0
A33: 11 | B33: Кредиты и лизинги и авансы в процессе судебного разбирательства, чистые | C33: -25054 | D33: 0 | S33: =+C33+E33+G33+I33+K33+M33+O33+Q33 -> -25054 | T33: =+S33-U33 -> -25054 | U33: =+D33+F33+H33+J33+L33+N33+P33+R33 -> 0 | V33: 0 | AA33: 0
A34: 12. | B34: Инвестиции, чистые | C34: 107220 | R34: 0 | S34: =+C34+E34+G34+I34+K34+M34+O34+Q34 -> 107220 | T34: =+S34-U34 -> 107220 | U34: =+D34+F34+H34+J34+L34+N34+P34+R34 -> 0 | V34: 0 | AA34: 0
A35: 13. | B35: Ценные бумаги купленные по соглашению с обратным выкупом | C35: =+C36+C37 -> 0 | D35: =+D36+D37 -> 0 | E35: =+E36+E37 -> 0 | F35: =+F36+F37 -> 0 | G35: =+G36+G37 -> 0 | H35: =+H36+H37 -> 0 | I35: =+I36+I37 -> 0 | J35: =+J36+J37 -> 0 | ... R35: =+R36+R37 -> 0 | S35: =+C35+E35+G35+I35+K35+M35+O35+Q35 -> 0 | T35: =+S35-U35 -> 0 | U35: =+D35+F35+H35+J35+L35+N35+P35+R35 -> 0
A36: 13.1 | B36: Ценные бумаги Правительства и ЦБ купленные по соглашению с обратным выкупом (РЕПО) | S36: =+C36+E36+G36+I36+K36+M36+O36+Q36 -> 0 | T36: =+S36-U36 -> 0 | U36: =+D36+F36+H36+J36+L36+N36+P36+R36 -> 0 | V36: 1 | W36: =+S36 -> 0 | X36: =+W36*V36 -> 0 | Y36: =+U36 -> 0 | Z36: =+Y36*V36 -> 0 | AA36: 1 | AB36: =+S36 -> 0 | AC36: =+AB36*AA36 -> 0 | AD36: =+U36 -> 0 | AE36: =+AD36*AA36 -> 0
A37: 13.2 | B37: Другие ценные бумаги купленные по соглашению с обратным выкупом (РЕПО) | S37: =+C37+E37+G37+I37+K37+M37+O37+Q37 -> 0 | T37: =+S37-U37 -> 0 | U37: =+D37+F37+H37+J37+L37+N37+P37+R37 -> 0 | V37: 0 | AA37: 0
A38: 14. | B38: Основные средства, чистые | C38: 201801025 | D38: 0 | S38: =+C38+E38+G38+I38+K38+M38+O38+Q38 -> 201801025 | T38: =+S38-U38 -> 201801025 | U38: =+D38+F38+H38+J38+L38+N38+P38+R38 -> 0 | V38: 0 | AA38: 0
A39: 15. | B39: Другое собственное имущество банка, чистые | S39: =+C39+E39+G39+I39+K39+M39+O39+Q39 -> 0 | T39: =+S39-U39 -> 0 | U39: =+D39+F39+H39+J39+L39+N39+P39+R39 -> 0 | V39: 0 | AA39: 0
A40: 16. | B40: Нереализованная прибыль при ревальвации по сделкам "форвард" | S40: =+C40+E40+G40+I40+K40+M40+O40+Q40 -> 0 | T40: =+S40-U40 -> 0 | U40: =+D40+F40+H40+J40+L40+N40+P40+R40 -> 0 | V40: 0 | AA40: 0
...

Sheet Bank Assets Analysis (нац)
A2: АНАЛИЗ АКТИВОВ БАНКА В НАЦИОНАЛЬНОЙ ВАЛЮТЕ | O2: Таблица-17А
B3: =Balance!B3 -> АКБ"Микрокредитбанк" | J3: =+Balance!B2 -> 31 Декабрь, 2020 | Q3: =+Balance!E3 -> тыс. сум
A4: № | B4: Характеристики | C4: Срок погашения (в днях) | K4: ВСЕГО | L4: Расчет коэффициента покрытия ликвидности (действующий норматив) | O4: Расчет коэффициента покрытия ликвидности (внедряемый норматив)
C5: Бессрочные | D5: От 1 до 7 дней | E5: От 8 до 30 дней | F5: От 31 до 90 дней | G5: От 91 до 180 дней | H5: От 181 до 365 дней | I5: От 366 до 730 дней | J5: Свыше 2 лет | L5: Коэффициент | M5: Сумма активов | N5: Высоко-ликвидные активы/приток | O5: Коэффициент | P5: Сумма активов | Q5: Высоко-ликвидные активы/приток
B6: АКТИВЫ
A7: 1. | B7: Наличность и другие кассовые документы | C7: =+'Bank Assets Analysis'!C7-'Bank Assets Analysis'!D7 -> 92534448 | D7: =+'Bank Assets Analysis'!E7-'Bank Assets Analysis'!F7 -> 0 | E7: =+'Bank Assets Analysis'!G7-'Bank Assets Analysis'!H7 -> 0 | F7: =+'Bank Assets Analysis'!I7-'Bank Assets Analysis'!J7 -> 0 | G7: =+'Bank Assets Analysis'!K7-'Bank Assets Analysis'!L7 -> 0 | H7: =+'Bank Assets Analysis'!M7-'Bank Assets Analysis'!N7 -> 0 | I7: =+'Bank Assets Analysis'!O7-'Bank Assets Analysis'!P7 -> 0 | J7: =+'Bank Assets Analysis'!Q7-'Bank Assets Analysis'!R7 -> 0 | K7: =+C7+D7+E7+F7+G7+H7+I7+J7 -> 92534448 | L7: 1 | M7: =+K7-K8 -> 92534448 | N7: =+M7*L7 -> 92534448 | O7: 1 | P7: =+K7-K8 -> 92534448 | Q7: =+P7*O7 -> 92534448
A8: 1.1 | B8: в том числе чеки и другие платежные документы | C8: =+'Bank Assets Analysis'!C8-'Bank Assets Analysis'!D8 -> 0 | D8: =+'Bank Assets Analysis'!E8-'Bank Assets Analysis'!F8 -> 0 | E8: =+'Bank Assets Analysis'!G8-'Bank Assets Analysis'!H8 -> 0 | F8: =+'Bank Assets Analysis'!I8-'Bank Assets Analysis'!J8 -> 0 | G8: =+'Bank Assets Analysis'!K8-'Bank Assets Analysis'!L8 -> 0 | H8: =+'Bank Assets Analysis'!M8-'Bank Assets Analysis'!N8 -> 0 | I8: =+'Bank Assets Analysis'!O8-'Bank Assets Analysis'!P8 -> 0 | J8: =+'Bank Assets Analysis'!Q8-'Bank Assets Analysis'!R8 -> 0 | K8: =+C8+D8+E8+F8+G8+H8+I8+J8 -> 0 | L8: 0 | O8: 0
A9: 2. | B9: К получению из ЦБРУ не учитывая сумму обязательных резервов банка(ФОР) | C9: =+'Bank Assets Analysis'!C9-'Bank Assets Analysis'!D9 -> 313936606 | D9: =+'Bank Assets Analysis'!E9-'Bank Assets Analysis'!F9 -> 0 | E9: =+'Bank Assets Analysis'!G9-'Bank Assets Analysis'!H9 -> 0 | F9: =+'Bank Assets Analysis'!I9-'Bank Assets Analysis'!J9 -> 0 | G9: =+'Bank Assets Analysis'!K9-'Bank Assets Analysis'!L9 -> 0 | H9: =+'Bank Assets Analysis'!M9-'Bank Assets Analysis'!N9 -> 0 | I9: =+'Bank Assets Analysis'!O9-'Bank Assets Analysis'!P9 -> 0 | J9: =+'Bank Assets Analysis'!Q9-'Bank Assets Analysis'!R9 -> 0 | K9: =+C9+D9+E9+F9+G9+H9+I9+J9 -> 313936606 | L9: 1 | M9: =+K9 -> 313936606 | N9: =+M9*L9 -> 313936606 | O9: 1 | P9: =+K9 -> 313936606 | Q9: =+P9*O9 -> 313936606
A10: 2.1 | B10: К получению из ЦБРУ (сумма обязательных резервов банка(ФОР)) | C10: =+'Bank Assets Analysis'!C10-'Bank Assets Analysis'!D10 -> 0 | D10: =+'Bank Assets Analysis'!E10-'Bank Assets Analysis'!F10 -> 0 | E10: =+'Bank Assets Analysis'!G10-'Bank Assets Analysis'!H10 -> 21398086 | F10: =+'Bank Assets Analysis'!I10-'Bank Assets Analysis'!J10 -> 0 | G10: =+'Bank Assets Analysis'!K10-'Bank Assets Analysis'!L10 -> 0 | H10: =+'Bank Assets Analysis'!M10-'Bank Assets Analysis'!N10 -> 0 | I10: =+'Bank Assets Analysis'!O10-'Bank Assets Analysis'!P10 -> 0 | J10: =+'Bank Assets Analysis'!Q10-'Bank Assets Analysis'!R10 -> 0 | K10: =+C10+D10+E10+F10+G10+H10+I10+J10 -> 21398086 | L10: 0 | N10: =+M10*L10 -> 0 | O10: 0 | Q10: =+P10*O10 -> 0
A11: 3. | B11: К получению из других банков | C11: =SUM(C12:C18)-C15 -> 5278353 | D11: =SUM(D12:D18)-D15 -> 0 | E11: =SUM(E12:E18)-E15 -> 0 | F11: =SUM(F12:F18)-F15 -> 40000000 | G11: =SUM(G12:G18)-G15 -> 47569200 | H11: =SUM(H12:H18)-H15 -> 101000000 | I11: =SUM(I12:I18)-I15 -> 3000000 | J11: =SUM(J12:J18)-J15 -> 34330550 | K11: =+C11+D11+E11+F11+G11+H11+I11+J11 -> 231178103 | N11: =+M11*L11 -> 0 | Q11: =+P11*O11 -> 0
A12: 3.1 | B12: К получению со счетов в банках стран с низким уровнем риска (ностро, депозиты), но размещенные не в качестве обеспечения | C12: =+'Bank Assets Analysis'!C12-'Bank Assets Analysis'!D12 -> 0 | D12: =+'Bank Assets Analysis'!E12-'Bank Assets Analysis'!F12 -> 0 | E12: =+'Bank Assets Analysis'!G12-'Bank Assets Analysis'!H12 -> 0 | F12: =+'Bank Assets Analysis'!I12-'Bank Assets Analysis'!J12 -> 0 | G12: =+'Bank Assets Analysis'!K12-'Bank Assets Analysis'!L12 -> 0 | H12: =+'Bank Assets Analysis'!M12-'Bank Assets Analysis'!N12 -> 0 | I12: =+'Bank Assets Analysis'!O12-'Bank Assets Analysis'!P12 -> 0 | J12: =+'Bank Assets Analysis'!Q12-'Bank Assets Analysis'!R12 -> 0 | K12: =+C12+D12+E12+F12+G12+H12+I12+J12 -> 0 | L12: 1 | M12: =+C12 -> 0 | N12: =+M12*L12 -> 0 | O12: 1 | P12: =+C12 -> 0 | Q12: =+P12*O12 -> 0
A13: 3.2 | B13: Депозиты размещенные в местных банках имеющие рейтинг не ниже В- или В3 | C13: =+'Bank Assets Analysis'!C13-'Bank Assets Analysis'!D13 -> 0 | D13: =+'Bank Assets Analysis'!E13-'Bank Assets Analysis'!F13 -> 0 | E13: =+'Bank Assets Analysis'!G13-'Bank Assets Analysis'!H13 -> 0 | F13: =+'Bank Assets Analysis'!I13-'Bank Assets Analysis'!J13 -> 0 | G13: =+'Bank Assets Analysis'!K13-'Bank Assets Analysis'!L13 -> 0 | H13: =+'Bank Assets Analysis'!M13-'Bank Assets Analysis'!N13 -> 0 | I13: =+'Bank Assets Analysis'!O13-'Bank Assets Analysis'!P13 -> 0 | J13: =+'Bank Assets Analysis'!Q13-'Bank Assets Analysis'!R13 -> 0 | K13: =+C13+D13+E13+F13+G13+H13+I13+J13 -> 0 | L13: 1 | M13: =+C13 -> 0 | N13: =+M13*L13 -> 0 | O13: 1 | P13: =+C13 -> 0 | Q13: =+P13*O13 -> 0
A14: 3.3 | B14: Депозиты размещенные на условиях овернайт | C14: =+'Bank Assets Analysis'!C14-'Bank Assets Analysis'!D14 -> 0 | D14: =+'Bank Assets Analysis'!E14-'Bank Assets Analysis'!F14 -> 0 | E14: =+'Bank Assets Analysis'!G14-'Bank Assets Analysis'!H14 -> 0 | F14: =+'Bank Assets Analysis'!I14-'Bank Assets Analysis'!J14 -> 0 | G14: =+'Bank Assets Analysis'!K14-'Bank Assets Analysis'!L14 -> 0 | H14: =+'Bank Assets Analysis'!M14-'Bank Assets Analysis'!N14 -> 0 | I14: =+'Bank Assets Analysis'!O14-'Bank Assets Analysis'!P14 -> 0 | J14: =+'Bank Assets Analysis'!Q14-'Bank Assets Analysis'!R14 -> 0 | K14: =+C14+D14+E14+F14+G14+H14+I14+J14 -> 0 | L14: 1 | M14: =+C14-C15 -> 0 | N14: =+M14*L14 -> 0 | O14: 1 | P14: =+C14-C15 -> 0 | Q14: =+P14*O14 -> 0
A15: 3.3.1. | B15: в том числе Депозиты размещенные на условиях овернайт в иностранной валюте с рейтингом не ниже инвестиционного. | C15: =+'Bank Assets Analysis'!C15-'Bank Assets Analysis'!D15 -> 0 | D15: =+'Bank Assets Analysis'!E15-'Bank Assets Analysis'!F15 -> 0 | E15: =+'Bank Assets Analysis'!G15-'Bank Assets Analysis'!H15 -> 0 | F15: =+'Bank Assets Analysis'!I15-'Bank Assets Analysis'!J15 -> 0 | G15: =+'Bank Assets Analysis'!K15-'Bank Assets Analysis'!L15 -> 0 | H15: =+'Bank Assets Analysis'!M15-'Bank Assets Analysis'!N15 -> 0 | I15: =+'Bank Assets Analysis'!O15-'Bank Assets Analysis'!P15 -> 0 | J15: =+'Bank Assets Analysis'!Q15-'Bank Assets Analysis'!R15 -> 0 | K15: =+C15+D15+E15+F15+G15+H15+I15+J15 -> 0 | L15: 1 | M15: =+D15 -> 0 | N15: =+M15*L15 -> 0 | O15: 1 | P15: =+C15 -> 0 | Q15: =+P15*O15 -> 0
A16: 3.4 | B16: К получению из других банков - депозиты | C16: =+'Bank Assets Analysis'!C16-'Bank Assets Analysis'!D16 -> 52007 | D16: =+'Bank Assets Analysis'!E16-'Bank Assets Analysis'!F16 -> 0 | E16: =+'Bank Assets Analysis'!G16-'Bank Assets Analysis'!H16 -> 0 | F16: =+'Bank Assets Analysis'!I16-'Bank Assets Analysis'!J16 -> 40000000 | G16: =+'Bank Assets Analysis'!K16-'Bank Assets Analysis'!L16 -> 47569200 | H16: =+'Bank Assets Analysis'!M16-'Bank Assets Analysis'!N16 -> 101000000 | I16: =+'Bank Assets Analysis'!O16-'Bank Assets Analysis'!P16 -> 3000000 | J16: =+'Bank Assets Analysis'!Q16-'Bank Assets Analysis'!R16 -> 34330550 | K16: =+C16+D16+E16+F16+G16+H16+I16+J16 -> 225951757 | L16: 1 | M16: =+C16+D16+E16 -> 52007 | N16: =+M16*L16 -> 52007 | O16: 1 | P16: =+C16+D16+E16+D12+D13+D14-D15 -> 52007 | Q16: =+P16*O16 -> 52007
A17: 3.5 | B17: К получению из других банков по расчетам пластиковых карт | C17: =+'Bank Assets Analysis'!C17-'Bank Assets Analysis'!D17 -> 4724609 | D17: =+'Bank Assets Analysis'!E17-'Bank Assets Analysis'!F17 -> 0 | E17: =+'Bank Assets Analysis'!G17-'Bank Assets Analysis'!H17 -> 0 | F17: =+'Bank Assets Analysis'!I17-'Bank Assets Analysis'!J17 -> 0 | G17: =+'Bank Assets Analysis'!K17-'Bank Assets Analysis'!L17 -> 0 | H17: =+'Bank Assets Analysis'!M17-'Bank Assets Analysis'!N17 -> 0 | I17: =+'Bank Assets Analysis'!O17-'Bank Assets Analysis'!P17 -> 0 | J17: =+'Bank Assets Analysis'!Q17-'Bank Assets Analysis'!R17 -> 0 | K17: =+C17+D17+E17+F17+G17+H17+I17+J17 -> 4724609 | L17: 0.5 | M17: =+C17+D17+E17 -> 4724609 | N17: =+M17*L17 -> 2362304.5 | O17: 1 | P17: =+C17+D17+E17 -> 4724609 | Q17: =+P17*O17 -> 4724609
A18: 3.6 | B18: Другие статьи | C18: =+'Bank Assets Analysis'!C18-'Bank Assets Analysis'!D18 -> 501737 | D18: =+'Bank Assets Analysis'!E18-'Bank Assets Analysis'!F18 -> 0 | E18: =+'Bank Assets Analysis'!G18-'Bank Assets Analysis'!H18 -> 0 | F18: =+'Bank Assets Analysis'!I18-'Bank Assets Analysis'!J18 -> 0 | G18: =+'Bank Assets Analysis'!K18-'Bank Assets Analysis'!L18 -> 0 | H18: =+'Bank Assets Analysis'!M18-'Bank Assets Analysis'!N18 -> 0 | I18: =+'Bank Assets Analysis'!O18-'Bank Assets Analysis'!P18 -> 0 | J18: =+'Bank Assets Analysis'!Q18-'Bank Assets Analysis'!R18 -> 0 | K18: =+C18+D18+E18+F18+G18+H18+I18+J18 -> 501737 | L18: 0.3 | M18: =+C18+D18+E18 -> 501737 | N18: =+M18*L18 -> 150521.1 | O18: 1 | P18: =+C18+D18+E18 -> 501737 | Q18: =+P18*O18 -> 501737
A19: 4. | B19: Счета купли и продажи, чистые | C19: =SUM(C20:C25)-C21 -> 2938414 | D19: =SUM(D20:D25)-D21 -> 0 | E19: =SUM(E20:E25)-E21 -> 48000000 | F19: =SUM(F20:F25)-F21 -> 0 | G19: =SUM(G20:G25)-G21 -> 102000000 | H19: =SUM(H20:H25)-H21 -> 50000000 | I19: =SUM(I20:I25)-I21 -> 0 | J19: =SUM(J20:J25)-J21 -> 0 | K19: =+C19+D19+E19+F19+G19+H19+I19+J19 -> 202938414 | N19: =+M19*L19 -> 0 | Q19: =+P19*O19 -> 0
A20: 4.1 | B20: Ценные бумаги, выпущенные Правительством Республики Узбекистан и ЦБРУ (векселя, облигации и другие долговые ценные бумаги) | C20: =+'Bank Assets Analysis'!C20-'Bank Assets Analysis'!D20 -> 0 | D20: =+'Bank Assets Analysis'!E20-'Bank Assets Analysis'!F20 -> 0 | E20: =+'Bank Assets Analysis'!G20-'Bank Assets Analysis'!H20 -> 48000000 | F20: =+'Bank Assets Analysis'!I20-'Bank Assets Analysis'!J20 -> 0 | G20: =+'Bank Assets Analysis'!K20-'Bank Assets Analysis'!L20 -> 102000000 | H20: =+'Bank Assets Analysis'!M20-'Bank Assets Analysis'!N20 -> 50000000 | I20: =+'Bank Assets Analysis'!O20-'Bank Assets Analysis'!P20 -> 0 | J20: =+'Bank Assets Analysis'!Q20-'Bank Assets Analysis'!R20 -> 0 | K20: =+C20+D20+E20+F20+G20+H20+I20+J20 -> 200000000 | L20: 1 | M20: =+K20-K21 -> 200000000 | N20: =+M20*L20 -> 200000000 | O20: 1 | P20: =+K20-K21 -> 200000000 | Q20: =+P20*O20 -> 200000000
A21: 4.1.1 | B21: в том числе, Ценные бумаги, выпущенные Правительством Республики Узбекистан и ЦБРУ (векселя, облигации и другие долговые ценные бумаги) под залогом | C21: =+'Bank Assets Analysis'!C21-'Bank Assets Analysis'!D21 -> 0 | D21: =+'Bank Assets Analysis'!E21-'Bank Assets Analysis'!F21 -> 0 | E21: =+'Bank Assets Analysis'!G21-'Bank Assets Analysis'!H21 -> 0 | F21: =+'Bank Assets Analysis'!I21-'Bank Assets Analysis'!J21 -> 0 | G21: =+'Bank Assets Analysis'!K21-'Bank Assets Analysis'!L21 -> 0 | H21: =+'Bank Assets Analysis'!M21-'Bank Assets Analysis'!N21 -> 0 | I21: =+'Bank Assets Analysis'!O21-'Bank Assets Analysis'!P21 -> 0 | J21: =+'Bank Assets Analysis'!Q21-'Bank Assets Analysis'!R21 -> 0 | K21: =+C21+D21+E21+F21+G21+H21+I21+J21 -> 0 | L21: 1 | M21: =SUM(C21:E21) -> 0 | N21: =+M21*L21 -> 0 | O21: 1 | P21: =SUM(C21:E21) -> 0 | Q21: =+P21*O21 -> 0
A22: 4.2 | B22: Правительственные ценные бумаги стран с низкой степенью странового риска | C22: =+'Bank Assets Analysis'!C22-'Bank Assets Analysis'!D22 -> 0 | D22: =+'Bank Assets Analysis'!E22-'Bank Assets Analysis'!F22 -> 0 | E22: =+'Bank Assets Analysis'!G22-'Bank Assets Analysis'!H22 -> 0 | F22: =+'Bank Assets Analysis'!I22-'Bank Assets Analysis'!J22 -> 0 | G22: =+'Bank Assets Analysis'!K22-'Bank Assets Analysis'!L22 -> 0 | H22: =+'Bank Assets Analysis'!M22-'Bank Assets Analysis'!N22 -> 0 | I22: =+'Bank Assets Analysis'!O22-'Bank Assets Analysis'!P22 -> 0 | J22: =+'Bank Assets Analysis'!Q22-'Bank Assets Analysis'!R22 -> 0 | K22: =+C22+D22+E22+F22+G22+H22+I22+J22 -> 0 | L22: 1 | M22: =+K22 -> 0 | N22: =+M22*L22 -> 0 | O22: 1 | P22: =+K22 -> 0 | Q22: =+P22*O22 -> 0
A23: 4.3 | B23: Ценные бумаги выпущенные МВФ, входящие организации в группу Всемирного банка, МФК, АБР, Азиатский банк инфроструктуры и инвестиции, ЕБРР, Европейский инвестиционный банк, Исламский банк развития и Банк развития Европейского союза | C23: =+'Bank Assets Analysis'!C23-'Bank Assets Analysis'!D23 -> 0 | D23: =+'Bank Assets Analysis'!E23-'Bank Assets Analysis'!F23 -> 0 | E23: =+'Bank Assets Analysis'!G23-'Bank Assets Analysis'!H23 -> 0 | F23: =+'Bank Assets Analysis'!I23-'Bank Assets Analysis'!J23 -> 0 | G23: =+'Bank Assets Analysis'!K23-'Bank Assets Analysis'!L23 -> 0 | H23: =+'Bank Assets Analysis'!M23-'Bank Assets Analysis'!N23 -> 0 | I23: =+'Bank Assets Analysis'!O23-'Bank Assets Analysis'!P23 -> 0 | J23: =+'Bank Assets Analysis'!Q23-'Bank Assets Analysis'!R23 -> 0 | K23: =+C23+D23+E23+F23+G23+H23+I23+J23 -> 0 | L23: 1 | M23: =+K23 -> 0 | N23: =+M23*L23 -> 0 | O23: 1 | P23: =+K23 -> 0 | Q23: =+P23*O23 -> 0
A24: 4.4 | B24: Ценные бумаги ведущих транснациональных компаний с низким уровнем странового риска | C24: =+'Bank Assets Analysis'!C24-'Bank Assets Analysis'!D24 -> 0 | D24: =+'Bank Assets Analysis'!E24-'Bank Assets Analysis'!F24 -> 0 | E24: =+'Bank Assets Analysis'!G24-'Bank Assets Analysis'!H24 -> 0 | F24: =+'Bank Assets Analysis'!I24-'Bank Assets Analysis'!J24 -> 0 | G24: =+'Bank Assets Analysis'!K24-'Bank Assets Analysis'!L24 -> 0 | H24: =+'Bank Assets Analysis'!M24-'Bank Assets Analysis'!N24 -> 0 | I24: =+'Bank Assets Analysis'!O24-'Bank Assets Analysis'!P24 -> 0 | J24: =+'Bank Assets Analysis'!Q24-'Bank Assets Analysis'!R24 -> 0 | K24: =+C24+D24+E24+F24+G24+H24+I24+J24 -> 0 | L24: 1 | M24: =+K24 -> 0 | N24: =+M24*L24 -> 0 | O24: 1 | P24: =+D24+E24 -> 0 | Q24: =+P24*O24 -> 0
A25: 4.5 | B25: Другие | C25: =+'Bank Assets Analysis'!C25-'Bank Assets Analysis'!D25 -> 2938414 | D25: =+'Bank Assets Analysis'!E25-'Bank Assets Analysis'!F25 -> 0 | E25: =+'Bank Assets Analysis'!G25-'Bank Assets Analysis'!H25 -> 0 | F25: =+'Bank Assets Analysis'!I25-'Bank Assets Analysis'!J25 -> 0 | G25: =+'Bank Assets Analysis'!K25-'Bank Assets Analysis'!L25 -> 0 | H25: =+'Bank Assets Analysis'!M25-'Bank Assets Analysis'!N25 -> 0 | I25: =+'Bank Assets Analysis'!O25-'Bank Assets Analysis'!P25 -> 0 | J25: =+'Bank Assets Analysis'!Q25-'Bank Assets Analysis'!R25 -> 0 | K25: =+C25+D25+E25+F25+G25+H25+I25+J25 -> 2938414 | L25: 0 | O25: 0
A26: 5. | B26: Купленные векселя, чистые | C26: =+'Bank Assets Analysis'!C26-'Bank Assets Analysis'!D26 -> 0 | D26: =+'Bank Assets Analysis'!E26-'Bank Assets Analysis'!F26 -> 0 | E26: =+'Bank Assets Analysis'!G26-'Bank Assets Analysis'!H26 -> 0 | F26: =+'Bank Assets Analysis'!I26-'Bank Assets Analysis'!J26 -> 0 | G26: =+'Bank Assets Analysis'!K26-'Bank Assets Analysis'!L26 -> 0 | H26: =+'Bank Assets Analysis'!M26-'Bank Assets Analysis'!N26 -> 0 | I26: =+'Bank Assets Analysis'!O26-'Bank Assets Analysis'!P26 -> 0 | J26: =+'Bank Assets Analysis'!Q26-'Bank Assets Analysis'!R26 -> 0 | K26: =+C26+D26+E26+F26+G26+H26+I26+J26 -> 0 | L26: 0.3 | M26: =+C26+D26+E26 -> 0 | N26: =+M26*L26 -> 0 | O26: 0.3 | P26: =+D26+E26 -> 0 | Q26: =+P26*O26 -> 0
A27: 6. | B27: Обязательства клиентов по траттам под аккредитивы или трастовые документы | C27: =+'Bank Assets Analysis'!C27-'Bank Assets Analysis'!D27 -> 0 | D27: =+'Bank Assets Analysis'!E27-'Bank Assets Analysis'!F27 -> 0 | E27: =+'Bank Assets Analysis'!G27-'Bank Assets Analysis'!H27 -> 0 | F27: =+'Bank Assets Analysis'!I27-'Bank Assets Analysis'!J27 -> 0 | G27: =+'Bank Assets Analysis'!K27-'Bank Assets Analysis'!L27 -> 0 | H27: =+'Bank Assets Analysis'!M27-'Bank Assets Analysis'!N27 -> 0 | I27: =+'Bank Assets Analysis'!O27-'Bank Assets Analysis'!P27 -> 0 | J27: =+'Bank Assets Analysis'!Q27-'Bank Assets Analysis'!R27 -> 0 | K27: =+C27+D27+E27+F27+G27+H27+I27+J27 -> 0 | L27: 0.3 | M27: =+C27+D27+E27 -> 0 | N27: =+M27*L27 -> 0 | O27: 0.3 | P27: =+D27+E27 -> 0 | Q27: =+P27*O27 -> 0
A28: 7. | B28: Обязательства клиентов по непогашенным акцептам этого банка | C28: =+'Bank Assets Analysis'!C28-'Bank Assets Analysis'!D28 -> 0 | D28: =+'Bank Assets Analysis'!E28-'Bank Assets Analysis'!F28 -> 0 | E28: =+'Bank Assets Analysis'!G28-'Bank Assets Analysis'!H28 -> 0 | F28: =+'Bank Assets Analysis'!I28-'Bank Assets Analysis'!J28 -> 0 | G28: =+'Bank Assets Analysis'!K28-'Bank Assets Analysis'!L28 -> 0 | H28: =+'Bank Assets Analysis'!M28-'Bank Assets Analysis'!N28 -> 0 | I28: =+'Bank Assets Analysis'!O28-'Bank Assets Analysis'!P28 -> 0 | J28: =+'Bank Assets Analysis'!Q28-'Bank Assets Analysis'!R28 -> 0 | K28: =+C28+D28+E28+F28+G28+H28+I28+J28 -> 0 | L28: 0.3 | M28: =+C28+D28+E28 -> 0 | N28: =+M28*L28 -> 0 | O28: 0.3 | P28: =+D28+E28 -> 0 | Q28: =+P28*O28 -> 0
A29: 8. | B29: Кредиты и лизинги, предоставленные ЦБРУ, чистые | C29: =+'Bank Assets Analysis'!C29-'Bank Assets Analysis'!D29 -> 0 | D29: =+'Bank Assets Analysis'!E29-'Bank Assets Analysis'!F29 -> 0 | E29: =+'Bank Assets Analysis'!G29-'Bank Assets Analysis'!H29 -> 0 | F29: =+'Bank Assets Analysis'!I29-'Bank Assets Analysis'!J29 -> 0 | G29: =+'Bank Assets Analysis'!K29-'Bank Assets Analysis'!L29 -> 0 | H29: =+'Bank Assets Analysis'!M29-'Bank Assets Analysis'!N29 -> 0 | I29: =+'Bank Assets Analysis'!O29-'Bank Assets Analysis'!P29 -> 0 | J29: =+'Bank Assets Analysis'!Q29-'Bank Assets Analysis'!R29 -> 0 | K29: =+C29+D29+E29+F29+G29+H29+I29+J29 -> 0 | L29: 1 | M29: =+C29+D29+E29 -> 0 | N29: =+M29*L29 -> 0 | O29: 1 | P29: =C29+D29+E29 -> 0 | Q29: =+P29*O29 -> 0
A30: 9. | B30: Кредиты и лизинги, предоставленные другим банкам, чистые | C30: =+'Bank Assets Analysis'!C30-'Bank Assets Analysis'!D30 -> 0 | D30: =+'Bank Assets Analysis'!E30-'Bank Assets Analysis'!F30 -> 0 | E30: =+'Bank Assets Analysis'!G30-'Bank Assets Analysis'!H30 -> 0 | F30: =+'Bank Assets Analysis'!I30-'Bank Assets Analysis'!J30 -> 0 | G30: =+'Bank Assets Analysis'!K30-'Bank Assets Analysis'!L30 -> 0 | H30: =+'Bank Assets Analysis'!M30-'Bank Assets Analysis'!N30 -> 0 | I30: =+'Bank Assets Analysis'!O30-'Bank Assets Analysis'!P30 -> 0 | J30: =+'Bank Assets Analysis'!Q30-'Bank Assets Analysis'!R30 -> 0 | K30: =+C30+D30+E30+F30+G30+H30+I30+J30 -> 0 | L30: 0.5 | M30: =D30+E30 -> 0 | N30: =+M30*L30 -> 0 | O30: 0.5 | P30: =+D30+E30 -> 0 | Q30: =+P30*O30 -> 0
A31: 10 | B31: Кредиты и лизинги, предоставленные другим клиентам, чистые | C31: =+'Bank Assets Analysis'!C31-'Bank Assets Analysis'!D31 -> 85465063 | D31: =+'Bank Assets Analysis'!E31-'Bank Assets Analysis'!F31 -> 130446627 | E31: =+'Bank Assets Analysis'!G31-'Bank Assets Analysis'!H31 -> 26992919 | F31: =+'Bank Assets Analysis'!I31-'Bank Assets Analysis'!J31 -> 451772510 | G31: =+'Bank Assets Analysis'!K31-'Bank Assets Analysis'!L31 -> 701473876 | H31: =+'Bank Assets Analysis'!M31-'Bank Assets Analysis'!N31 -> 1126883068 | I31: =+'Bank Assets Analysis'!O31-'Bank Assets Analysis'!P31 -> 1466143304 | J31: =+'Bank Assets Analysis'!Q31-'Bank Assets Analysis'!R31 -> 1483008711 | K31: =+C31+D31+E31+F31+G31+H31+I31+J31 -> 5472186078 | L31: 0.3 | M31: =D31+E31 -> 157439546 | N31: =+M31*L31 -> 47231864 | O31: 0.5 | P31: =+D31+E31 -> 157439546 | Q31: =+P31*O31 -> 78719773
A32: 10.1 | B32: в том числе, кредиты и лизинги, предоставленные физическим лицам, чистые | C32: =+'Bank Assets Analysis'!C32-'Bank Assets Analysis'!D32 -> 0 | D32: =+'Bank Assets Analysis'!E32-'Bank Assets Analysis'!F32 -> 56372153 | E32: =+'Bank Assets Analysis'!G32-'Bank Assets Analysis'!H32 -> 16870841 | F32: =+'Bank Assets Analysis'!I32-'Bank Assets Analysis'!J32 -> 184961398 | G32: =+'Bank Assets Analysis'!K32-'Bank Assets Analysis'!L32 -> 313432680 | H32: =+'Bank Assets Analysis'!M32-'Bank Assets Analysis'!N32 -> 533129992 | I32: =+'Bank Assets Analysis'!O32-'Bank Assets Analysis'!P32 -> 682443985 | J32: =+'Bank Assets Analysis'!Q32-'Bank Assets Analysis'!R32 -> 565889805 | K32: =+C32+D32+E32+F32+G32+H32+I32+J32 -> 2353100854 | L32: 0 | O32: 0
A33: 11 | B33: Кредиты и лизинги и авансы в процессе судебного разбирательства, чистые | C33: =+'Bank Assets Analysis'!C33-'Bank Assets Analysis'!D33 -> -25054 | D33: =+'Bank Assets Analysis'!E33-'Bank Assets Analysis'!F33 -> 0 | E33: =+'Bank Assets Analysis'!G33-'Bank Assets Analysis'!H33 -> 0 | F33: =+'Bank Assets Analysis'!I33-'Bank Assets Analysis'!J33 -> 0 | G33: =+'Bank Assets Analysis'!K33-'Bank Assets Analysis'!L33 -> 0 | H33: =+'Bank Assets Analysis'!M33-'Bank Assets Analysis'!N33 -> 0 | I33: =+'Bank Assets Analysis'!O33-'Bank Assets Analysis'!P33 -> 0 | J33: =+'Bank Assets Analysis'!Q33-'Bank Assets Analysis'!R33 -> 0 | K33: =+C33+D33+E33+F33+G33+H33+I33+J33 -> -25054 | L33: 0 | O33: 0
A34: 12. | B34: Инвестиции, чистые | C34: =+'Bank Assets Analysis'!C34-'Bank Assets Analysis'!D34 -> 107220 | D34: =+'Bank Assets Analysis'!E34-'Bank Assets Analysis'!F34 -> 0 | E34: =+'Bank Assets Analysis'!G34-'Bank Assets Analysis'!H34 -> 0 | F34: =+'Bank Assets Analysis'!I34-'Bank Assets Analysis'!J34 -> 0 | G34: =+'Bank Assets Analysis'!K34-'Bank Assets Analysis'!L34 -> 0 | H34: =+'Bank Assets Analysis'!M34-'Bank Assets Analysis'!N34 -> 0 | I34: =+'Bank Assets Analysis'!O34-'Bank Assets Analysis'!P34 -> 0 | J34: =+'Bank Assets Analysis'!Q34-'Bank Assets Analysis'!R34 -> 0 | K34: =+C34+D34+E34+F34+G34+H34+I34+J34 -> 107220 | L34: 0 | O34: 0
A35: 13. | B35: Ценные бумаги купленные по соглашению с обратным выкупом | C35: =+C36+C37 -> 0 | D35: =+D36+D37 -> 0 | E35: =+E36+E37 -> 0 | F35: =+F36+F37 -> 0 | G35: =+G36+G37 -> 0 | H35: =+H36+H37 -> 0 | I35: =+I36+I37 -> 0 | J35: =+J36+J37 -> 0 | K35: =+C35+D35+E35+F35+G35+H35+I35+J35 -> 0
A36: 13.1 | B36: Ценные бумаги Правительства и ЦБ купленные по соглашению с обратным выкупом (РЕПО) | C36: =+'Bank Assets Analysis'!C36-'Bank Assets Analysis'!D36 -> 0 | D36: =+'Bank Assets Analysis'!E36-'Bank Assets Analysis'!F36 -> 0 | E36: =+'Bank Assets Analysis'!G36-'Bank Assets Analysis'!H36 -> 0 | F36: =+'Bank Assets Analysis'!I36-'Bank Assets Analysis'!J36 -> 0 | G36: =+'Bank Assets Analysis'!K36-'Bank Assets Analysis'!L36 -> 0 | H36: =+'Bank Assets Analysis'!M36-'Bank Assets Analysis'!N36 -> 0 | I36: =+'Bank Assets Analysis'!O36-'Bank Assets Analysis'!P36 -> 0 | J36: =+'Bank Assets Analysis'!Q36-'Bank Assets Analysis'!R36 -> 0 | K36: =+C36+D36+E36+F36+G36+H36+I36+J36 -> 0 | L36: 1 | M36: =+K36 -> 0 | N36: =+M36*L36 -> 0 | O36: 1 | P36: =+K36 -> 0 | Q36: =+P36*O36 -> 0
A37: 13.2 | B37: Другие ценные бумаги купленные по соглашению с обратным выкупом (РЕПО) | C37: =+'Bank Assets Analysis'!C37-'Bank Assets Analysis'!D37 -> 0 | D37: =+'Bank Assets Analysis'!E37-'Bank Assets Analysis'!F37 -> 0 | E37: =+'Bank Assets Analysis'!G37-'Bank Assets Analysis'!H37 -> 0 | F37: =+'Bank Assets Analysis'!I37-'Bank Assets Analysis'!J37 -> 0 | G37: =+'Bank Assets Analysis'!K37-'Bank Assets Analysis'!L37 -> 0 | H37: =+'Bank Assets Analysis'!M37-'Bank Assets Analysis'!N37 -> 0 | I37: =+'Bank Assets Analysis'!O37-'Bank Assets Analysis'!P37 -> 0 | J37: =+'Bank Assets Analysis'!Q37-'Bank Assets Analysis'!R37 -> 0 | K37: =+C37+D37+E37+F37+G37+H37+I37+J37 -> 0 | L37: 0 | O37: 0 | Q37: =+P37*O37 -> 0
A38: 14. | B38: Основные средства, чистые | C38: =+'Bank Assets Analysis'!C38-'Bank Assets Analysis'!D38 -> 201801025 | D38: =+'Bank Assets Analysis'!E38-'Bank Assets Analysis'!F38 -> 0 | E38: =+'Bank Assets Analysis'!G38-'Bank Assets Analysis'!H38 -> 0 | F38: =+'Bank Assets Analysis'!I38-'Bank Assets Analysis'!J38 -> 0 | G38: =+'Bank Assets Analysis'!K38-'Bank Assets Analysis'!L38 -> 0 | H38: =+'Bank Assets Analysis'!M38-'Bank Assets Analysis'!N38 -> 0 | I38: =+'Bank Assets Analysis'!O38-'Bank Assets Analysis'!P38 -> 0 | J38: =+'Bank Assets Analysis'!Q38-'Bank Assets Analysis'!R38 -> 0 | K38: =+C38+D38+E38+F38+G38+H38+I38+J38 -> 201801025 | L38: 0 | O38: 0 | Q38: =+P38*O38 -> 0
A39: 15. | B39: Другое собственное имущество банка, чистые | C39: =+'Bank Assets Analysis'!C39-'Bank Assets Analysis'!D39 -> 0 | D39: =+'Bank Assets Analysis'!E39-'Bank Assets Analysis'!F39 -> 0 | E39: =+'Bank Assets Analysis'!G39-'Bank Assets Analysis'!H39 -> 0 | F39: =+'Bank Assets Analysis'!I39-'Bank Assets Analysis'!J39 -> 0 | G39: =+'Bank Assets Analysis'!K39-'Bank Assets Analysis'!L39 -> 0 | H39: =+'Bank Assets Analysis'!M39-'Bank Assets Analysis'!N39 -> 0 | I39: =+'Bank Assets Analysis'!O39-'Bank Assets Analysis'!P39 -> 0 | J39: =+'Bank Assets Analysis'!Q39-'Bank Assets Analysis'!R39 -> 0 | K39: =+C39+D39+E39+F39+G39+H39+I39+J39 -> 0 | L39: 0 | O39: 0 | Q39: =+P39*O39 -> 0
A40: 16. | B40: Нереализованная прибыль при ревальвации по сделкам "форвард" | C40: =+'Bank Assets Analysis'!C40-'Bank Assets Analysis'!D40 -> 0 | D40: =+'Bank Assets Analysis'!E40-'Bank Assets Analysis'!F40 -> 0 | E40: =+'Bank Assets Analysis'!G40-'Bank Assets Analysis'!H40 -> 0 | F40: =+'Bank Assets Analysis'!I40-'Bank Assets Analysis'!J40 -> 0 | G40: =+'Bank Assets Analysis'!K40-'Bank Assets Analysis'!L40 -> 0 | H40: =+'Bank Assets Analysis'!M40-'Bank Assets Analysis'!N40 -> 0 | I40: =+'Bank Assets Analysis'!O40-'Bank Assets Analysis'!P40 -> 0 | J40: =+'Bank Assets Analysis'!Q40-'Bank Assets Analysis'!R40 -> 0 | K40: =+C40+D40+E40+F40+G40+H40+I40+J40 -> 0 | L40: 0 | O40: 0 | Q40: =+P40*O40 -> 0
A41: 17. | B41: Счета купли-продажи валюты и валютные позиции | C41: =+'Bank Assets Analysis'!C41-'Bank Assets Analysis'!D41 -> -2562616 | K41: =+C41+D41+E41+F41+G41+H41+I41+J41 -> -2562616 | L41: 0 | O41: 0 | Q41: =+P41*O41 -> 0
...

Sheet Bank Liabilities Analysis
A1: АНАЛИЗ ОБЯЗАТЕЛЬСТВ БАНКА | AB1: Таблица-18
B2: =Balance!B3 -> АКБ"Микрокредитбанк" | T2: =+Balance!B2 -> 31 Декабрь, 2020 | AC2: в тыс. сум
