Workbook
Name jop: #REF!
Name kol: #REF!
Name RISKTOTASS: SUM('[6]Calculation of Risk Weighted As'!$C$38:$F$38)
Name RISKTOTASS: SUM('[7]Calculation of Risk Weighted As'!$C$41:$G$41)
Name TwentyLargestData: #REF!
Name Е: #REF!

Sheet Asset quality
A1: ИНФОРМАЦИЯ О КАЧЕСТВЕ АКТИВОВ, ОЦЕНИВАЕМЫХ В ЦЕЛЯХ СОЗДАНИЯ РЕЗЕРВА НА ВОЗМОЖНЫЕ ПОТЕРИ | R1: Таблица-2 | U1: №3
B3: АКБ "Микрокредитбанк" | P3: 44196 | S3: тыс. сум
A4: № | B4: Состав активов* | C4: Остаток | D4: Категория качества | I4: Просроченная задолженность (брутто) | N4: Резерв на возможные потери
I5: итого | J5: до 30 дней | K5: от 31 до 90 дней | L5: от 91 до 180 дней | M5: свыше 180 дней | N5: фактически сформированный
N6: итого | O6: по категориям качества
D7: I | E7: II | F7: III | G7: IV | H7: V | O7: I | P7: II | Q7: III | R7: IV | S7: V
A8: А | B8: Б | C8: В | D8: Г | E8: Д | F8: Е | G8: Ж | H8: З | I8: И | J8: К | K8: Л | L8: М | M8: Н | N8: О | O8: П | P8: Р | Q8: С | R8: Т | S8: У
B9: ВСЕГО АКТИВОВ | C9: =SUM(C10:C60) -> 10282915665 | D9: =SUM(D10:D60) -> 8864423041 | E9: =SUM(E10:E60) -> 1540989857 | F9: =SUM(F10:F60) -> 34473291 | G9: =SUM(G10:G60) -> 35919024 | H9: =SUM(H10:H60) -> 16214626 | I9: =SUM(I10:I60) -> 165011663 | J9: =SUM(J10:J60) -> 58106162 | ... S9: =SUM(S10:S60) -> 16214626
A10: 1 | B10: Кассовая наличность и другие платежные документы | C10: =SUM(D10:H10)-N10+O10 -> 220312147 | D10: 220312147 | E10: 0 | F10: 0 | G10: 0 | H10: 0 | I10: =SUM(J10:M10) -> 0 | J10: 0 | K10: 0 | L10: 0 | M10: 0 | N10: =SUM(O10:S10) -> 0 | O10: 0 | P10: 0 | Q10: 0 | R10: 0 | S10: 0 | T10: 10100
A11: 2 | B11: К получению из ЦБРУ | C11: =SUM(D11:H11)-N11+O11 -> 380783393 | D11: 380783393 | E11: 0 | F11: 0 | G11: 0 | H11: 0 | I11: =SUM(J11:M11) -> 0 | J11: 0 | K11: 0 | L11: 0 | M11: 0 | N11: =SUM(O11:S11) -> 0 | O11: 0 | P11: 0 | Q11: 0 | R11: 0 | S11: 0 | T11: 10300
A12: 3 | B12: К получению из других банков | C12: =SUM(D12:H12)-N12+O12 -> 666431396 | D12: 667134940 | E12: 0 | F12: 0 | G12: 0 | H12: 0 | I12: =SUM(J12:M12) -> 0 | J12: 0 | K12: 0 | L12: 0 | M12: 0 | N12: =SUM(O12:S12) -> 703544 | O12: 0 | P12: 703544 | Q12: 0 | R12: 0 | S12: 0 | T12: 10500
A13: 4 | B13: Ценные бумаги для купли и продажи | C13: =SUM(D13:H13)-N13+O13 -> 202938240 | D13: 202938240 | E13: 0 | F13: 0 | G13: 0 | H13: 0 | I13: =SUM(J13:M13) -> 0 | J13: 0 | K13: 0 | L13: 0 | M13: 0 | N13: =SUM(O13:S13) -> 0 | O13: 0 | P13: 0 | Q13: 0 | R13: 0 | S13: 0 | T13: 10700
A14: 5 | B14: Инвестиции в ценные бумаги, имеющиеся в наличии для продажи | C14: =SUM(D14:H14)-N14+O14 -> 0 | D14: 0 | E14: 0 | F14: 0 | G14: 0 | H14: 0 | I14: =SUM(J14:M14) -> 0 | J14: 0 | K14: 0 | L14: 0 | M14: 0 | N14: =SUM(O14:S14) -> 0 | O14: 0 | P14: 0 | Q14: 0 | R14: 0 | S14: 0 | T14: 10800
A15: 6 | B15: Драгоценные металлы, камни и монеты для купли и продажи | C15: =SUM(D15:H15)-N15+O15 -> 175 | D15: 175 | E15: 0 | F15: 0 | G15: 0 | H15: 0 | I15: =SUM(J15:M15) -> 0 | J15: 0 | K15: 0 | L15: 0 | M15: 0 | N15: =SUM(O15:S15) -> 0 | O15: 0 | P15: 0 | Q15: 0 | R15: 0 | S15: 0 | T15: 10900
A16: 7 | B16: Купленные дебиторские задолженности - Факторинг | C16: =SUM(D16:H16)-N16+O16 -> 17769574 | D16: 18077238 | E16: 0 | F16: 0 | G16: 0 | H16: 0 | I16: =SUM(J16:M16) -> 992738 | J16: 302846 | K16: 189564 | L16: 500328 | M16: 0 | N16: =SUM(O16:S16) -> 307664 | O16: 0 | P16: 0 | Q16: 0 | R16: 307664 | S16: 0 | T16: 11100
A17: 8 | B17: Купленные векселя | C17: =SUM(D17:H17)-N17+O17 -> 0 | D17: 0 | E17: 0 | F17: 0 | G17: 0 | H17: 0 | I17: =SUM(J17:M17) -> 0 | J17: 0 | K17: 0 | L17: 0 | M17: 0 | N17: =SUM(O17:S17) -> 0 | O17: 0 | P17: 0 | Q17: 0 | R17: 0 | S17: 0 | T17: 11300
A18: 9 | B18: Обязательства клиентов по траттам под аккредитив и/или трастовые документы | C18: =SUM(D18:H18)-N18+O18 -> 0 | D18: 0 | E18: 0 | F18: 0 | G18: 0 | H18: 0 | I18: =SUM(J18:M18) -> 0 | J18: 0 | K18: 0 | L18: 0 | M18: 0 | N18: =SUM(O18:S18) -> 0 | O18: 0 | P18: 0 | Q18: 0 | R18: 0 | S18: 0 | T18: 11500
A19: 10 | B19: Обязательства лиентов по непогашенным акцептам банка | C19: =SUM(D19:H19)-N19+O19 -> 0 | D19: 0 | E19: 0 | F19: 0 | G19: 0 | H19: 0 | I19: =SUM(J19:M19) -> 0 | J19: 0 | K19: 0 | L19: 0 | M19: 0 | N19: =SUM(O19:S19) -> 0 | O19: 0 | P19: 0 | Q19: 0 | R19: 0 | S19: 0 | T19: 11700
A20: 11 | B20: Купленные по сделкам РЕПО ценные бумаги | C20: =SUM(D20:H20)-N20+O20 -> 0 | D20: 0 | E20: 0 | F20: 0 | G20: 0 | H20: 0 | I20: =SUM(J20:M20) -> 0 | J20: 0 | K20: 0 | L20: 0 | M20: 0 | N20: =SUM(O20:S20) -> 0 | O20: 0 | P20: 0 | Q20: 0 | R20: 0 | S20: 0 | T20: 11800
A21: 12 | B21: Краткосрочные кредиты, предоставленные ЦБРУ | C21: =SUM(D21:H21)-N21+O21 -> 0 | D21: 0 | E21: 0 | F21: 0 | G21: 0 | H21: 0 | I21: =SUM(J21:M21) -> 0 | J21: 0 | K21: 0 | L21: 0 | M21: 0 | N21: =SUM(O21:S21) -> 0 | O21: 0 | P21: 0 | Q21: 0 | R21: 0 | S21: 0 | T21: 11900
... A60: 51 | B60: Другие активы | C60: =SUM(D60:H60)-N60+O60 -> 73631502 | D60: 82457871 | E60: 0 | F60: 0 | G60: 0 | H60: 0 | I60: =SUM(J60:M60) -> 0 | J60: 0 | K60: 0 | L60: 0 | M60: 0 | N60: =SUM(O60:S60) -> 8826369 | O60: 0 | P60: 8826369 | Q60: 0 | R60: 0 | S60: 0 | T60: 19900
B62: ЗАБАЛАНСОВЫЕ СТАТЬИ | C62: =SUM(D62:H62) -> 126598793 | D62: =SUM(D63:D64) -> 126598793 | E62: =SUM(E63:E64) -> 0 | F62: =SUM(F63:F64) -> 0 | G62: =SUM(G63:G64) -> 0 | H62: =SUM(H63:H64) -> 0 | I62: =SUM(J62:M62) -> 0 | J62: =SUM(J63:J64) -> 0 | K62: =SUM(K63:K64) -> 0 | L62: =SUM(L63:L64) -> 0 | M62: =SUM(M63:M64) -> 0 | N62: =SUM(N63:N64) -> 0 | O62: =SUM(O63:O64) -> 0 | P62: =SUM(P63:P64) -> 0 | Q62: =SUM(Q63:Q64) -> 0 | ... S62: =SUM(S63:S64) -> 0
A63: 1 | B63: Аккредитивы | C63: =SUM(D63:H63)-N63+O63 -> 5891080 | D63: 5891080 | I63: =SUM(J63:M63) -> 0 | N63: =SUM(O63:S63) -> 0 | T63: 90908-90958
A64: 2 | B64: Гарантии и поручетельства | C64: =SUM(D64:H64)-N64+O64 -> 120707713 | D64: 120707713 | I64: =SUM(J64:M64) -> 0 | N64: =SUM(O64:S64) -> 0 | T64: 90993
B67: Подпись Председателя правления:
B69: Подпись Главного Бухгалтера:
B71: Состав активов банка формируется в соответсвии с Планом счетов
C72: =+[8]Balance!$C$45 -> 10282915665

Sheet Income 
B1: ОТЧЕТ О ФИНАНСОВЫХ РЕЗУЛЬТАТАХ | D1: Таблица-3
B3: =+'Asset quality'!B3 -> АКБ "Микрокредитбанк" | C3: =+'Asset quality'!P3 -> 44196 | E3: в тыс. сум
A4: № | B4: Категории | C4: Итого | D4: в национальной валюте | E4: в иностранной валюте (в экв. в сумах)
A5: 1. | B5: 1. ПРОЦЕНТНЫЕ ДОХОДЫ
A6: a. | B6: Процентные доходы по счетам в ЦБРУ | C6: =+D6+E6 -> 997178 | D6: 997178
A7: б. | B7: Процентные доходы по счетам в других банках | C7: =+D7+E7 -> 44869998 | D7: 44869998
A8: в. | B8: Процентные доходы по купленным векселям | C8: =+D8+E8 -> 0 | D8: 0
A9: г. | B9: Процентные доходы по инвестициям | C9: =+D9+E9 -> 439759 | D9: 439759
A10: д. | B10: Процентные доходы по счетам купли-продажи ценных бумаг | C10: =+D10+E10 -> 22827406 | D10: 22827406
A11: е. | B11: Процентные доходы по обязательствам клиентов | C11: =+D11+E11 -> 0 | D11: 0
A12: ж. | B12: Процентные доходы по обяз-вам клиентов по непогашенным акцептам этого банка | C12: =+D12+E12 -> 0 | D12: 0
A13: з. | B13: Процент, Дисконт (Скидки) и взносы по кредитным и лизинговым операциям | C13: =+D13+E13 -> 970220612 | D13: 970220612
A14: и. | B14: Процентные доходы по соглашениям о покупке ценных бумаг с обратным выкупом | C14: =+D14+E14 -> 0 | D14: 0
A15: к. | B15: Другие процентные доходы | C15: =+D15+E15 -> 361508054 | D15: 361508054
A16: л. | B16: Итого процентных доходов | C16: =SUM(C6:C15) -> 1400863007 | D16: =SUM(D6:D15) -> 1400863007 | E16: =SUM(E6:E15) -> 0 | G16: =+'Analysis of Interest'!C42 -> 1400863007
A18: 2. | B18: ПРОЦЕНТНЫЕ РАСХОДЫ
A19: а. | B19: Процентные расходы по депозитам до востребования | C19: =+D19+E19 -> 5884243 | D19: 5884243
A20: б. | B20: Процентные расходы по срочным депозитам | C20: =+D20+E20 -> 190404626 | D20: 190404626
A21: в. | B21: Процентные расходы по счетам к оплате в ЦБРУ | C21: =+D21+E21 -> 0 | D21: 0
A22: г. | B22: Процентные расходы по счетам к оплате в другие банки | C22: =+D22+E22 -> 113814181 | D22: 113814181
A23: д. | B23: Итого процентных расходов по депозитам | C23: =SUM(C19:C22) -> 310103050 | D23: =SUM(D19:D22) -> 310103050 | E23: =SUM(E19:E22) -> 0
A24: е. | B24: Процентные расходы по кредитам к оплате | C24: =+D24+E24 -> 199829463 | D24: 199829463
A25: ж. | B25: Процентные расходы по соглашениям о продаже ц/б с последующим выкупом | C25: =+D25+E25 -> 2222268 | D25: 2222268
A26: з. | B26: Другие процентные расходы | C26: =+D26+E26 -> 361849530 | D26: 361849530
A27: и. | B27: Итого процентных расходов по займам | C27: =SUM(C24:C26) -> 563901261 | D27: =SUM(D24:D26) -> 563901261 | E27: =SUM(E24:E26) -> 0
A28: л. | B28: Итого процентных расходов | C28: =C27+C23 -> 874004311 | D28: =D27+D23 -> 874004311 | E28: =E27+E23 -> 0 | G28: =+'Analysis of Interest'!C72 -> 874004311
A30: 3. | B30: ЧИСТЫЕ ПРОЦЕНТНЫЕ ДОХОДЫ ДО ОЦЕНКИ ВОЗМОЖНЫХ УБЫТКОВ ПО АКТИВАМ | C30: =C16-C28 -> 526858696 | D30: =D16-D28 -> 526858696 | E30: =E16-E28 -> 0
A31: а. | B31: Минус: Оценка возможных убытков по кредитам и лизингу | C31: =+D31+E31 -> 199222532 | D31: 199222532
A32: б. | B32: Минус: Оценка возможных убытков по в ценным бумагам | C32: =+D32+E32 -> 0 | D32: 0
A33: в. | B33: Минус: Оценка возможных убытков по инвестициям | C33: =+D33+E33 -> 0 | D33: 0
A34: г. | B34: Минус: Оценка возможных убытков по другим активам | C34: =+D34+E34 -> 1852889 | D34: 1852889
A35: д. | B35: Чистые процентные доходы после оценки возможных убытков по кредитам и лизингу | C35: =C30-C31-C32-C33-C34 -> 325783275 | D35: =D30-D31-D32-D33-D34 -> 325783275 | E35: =E30-E31-E32-E33-E34 -> 0
A37: 4. | B37: БЕСПРОЦЕНТНЫЕ ДОХОДЫ
A38: а. | B38: Доходы от комиссий и платы за услуги | C38: =+D38+E38 -> 96683089 | D38: 96683089
A39: б. | B39: Прибыль в иностранной валюте | C39: =+D39+E39 -> 114855708 | D39: 0 | E39: 114855708
A40: в. | B40: Прибыль от коммерческих операций | C40: =+D40+E40 -> 2182 | D40: 2182
A41: г. | B41: Прибыль и дивиденды от инвестиций | C41: =+D41+E41 -> 158968 | D41: 158968
A42: д. | B42: Другие беспроцентные доходы | C42: =+D42+E42 -> 111447456 | D42: 111447456
A43: е. | B43: Итого беспроцентных доходов | C43: =SUM(C38:C42) -> 323147403 | D43: =SUM(D38:D42) -> 208291695 | E43: =SUM(E38:E42) -> 114855708
A45: 5. | B45: БЕСПРОЦЕНТНЫЕ РАСХОДЫ
...

Sheet Analysis of Interest
B1: АНАЛИЗ ПРОЦЕНТНЫХ ДОХОДОВ И РАСХОДОВ | C1: Таблица-4
B3: =+'Asset quality'!B3 -> АКБ "Микрокредитбанк" | C3: =+'Asset quality'!P3 -> 44196
A4: № | B4: Категория | C4: в тыс. сум
A5: 1 . | B5: ПРОЦЕНТНЫЕ ДОХОДЫ ПО КРЕДИТНЫМ И ЛИЗИНГОВЫМ ОПЕРАЦИЯМ
A6: a. | B6: Кредиты и лизинговые операции ЦБРУ | C6: 0
A7: б. | B7: Кредиты и лизинговые операции другим банкам | C7: 8033
A8: в. | B8: Кредиты и лизинговые операции Правительству | C8: 2091
A9: г. | B9: Кредиты и лизинговые операции физическим лицам | C9: 334380571
A10: д. | B10: Кредиты и лизинговые операции государственным предприятиям | C10: 8873283
A11: е. | B11: Кредиты и лизинговые операции совместным и иностранным предприятиям | C11: 30511822
A12: ж. | B12: Кредиты и лизинговые операции частным товариществам и корпорациям | C12: 550675830
A13: з. | B13: Другие кредиты и лизинговые операции | C13: 45768982
A14: и. | B14: ИТОГО ПРОЦЕНТНЫХ ДОХОДОВ ПО КРЕДИТНЫМ И ЛИЗИНГОВЫМ ОПЕРАЦИЯМ | C14: =SUM(C6:C13) -> 970220612
A16: 2. | B16: ПРОЦЕНТНЫЕ ДОХОДЫ ПО КОРРЕСПОНДЕНТСКИМ СЧЕТАМ
A17: a. | B17: К получению из ЦБРУ | C17: 997178
A18: б. | B18: К получению из других банков | C18: 44869998
B19: ИТОГО ПРОЦЕНТНЫХ ДОХОДОВ ПО КОРРЕСПОНДЕНТСКИМ СЧЕТАМ | C19: =SUM(C17:C18) -> 45867176
A21: 3. | B21: ПРОЦЕНТНЫЕ ДОХОДЫ ПО СЧЕТАМ КУПЛИ-ПРОДАЖИ Ц/Б
A22: a. | B22: Государственные казначейские ценные бумаги | C22: 22827406
A23: б. | B23: Облигации и ценные бумаги ЦБРУ | C23: 0
A24: в. | B24: Ценные бумаги государственных корпораций | C24: 0
A25: г. | B25: Еврооблигации | C25: 0
A26: д. | B26: Частные ценные бумаги | C26: 0
A27: е. | B27: Другие ценные бумаги | C27: 0
A28: ж. | B28: ИТОГО ПРОЦЕНТНЫХ ДОХОДОВ ПО СЧЕТАМ КУПЛИ-ПРОДАЖИ Ц/Б | C28: =SUM(C22:C27) -> 22827406
A30: 4. | B30: ПРОЦЕНТНЫЕ ДОХОДЫ ПО ИНВЕСТИЦИЯМ
A31: a. | B31: Государственные облигации | C31: 0
A32: б. | B32: Облигации и ценные бумаги ЦБРУ | C32: 0
A33: в. | B33: Частные облигации | C33: 0
A34: г. | B34: Еврооблигации | C34: 0
A35: д. | B35: Другие ценные бумаги | C35: 439759
A36: е. | B36: ИТОГО ПРОЦЕНТНЫХ ДОХОДОВ ПО ИНВЕСТИЦИЯМ | C36: =SUM(C31:C35) -> 439759
A38: 5. | B38: ДРУГИЕ ПРОЦЕНТНЫЕ ДОХОДЫ
A39: a. | B39: Процентные доходы по соглашениям о покупке ц/б c обратным выкупом | C39: 0
A40: б. | B40: Другие процентные доходы | C40: 361508054
A42: 6. | B42: ИТОГО ПРОЦЕНТНЫХ ДОХОДОВ | C42: =C14+C19+C28+C36+C39+C40 -> 1400863007
A44: 7. | B44: ПРОЦЕНТНЫЕ РАСХОДЫ ПО ДЕПОЗИТАМ
A45: A. | B45: Депозиты до востребования
A46: a. | B46: Правительство | C46: 40000
A47: б. | B47: Физические лица | C47: 100779
...

Sheet Changes in Equity
B1: ИЗМЕНЕНИЯ В СОБСТВЕННОМ КАПИТАЛЕ | C1: Таблица-7
B3: =+'Asset quality'!B3 -> АКБ "Микрокредитбанк" | C3: =+'Asset quality'!P3 -> 44196
A4: № | B4: Категория | C4: в тыс. сум
A5: 1. | B5: Итого собственного капитала первоначально определенного за прошлый год | C5: 1625105476
A6: 2. | B6: Исправления в собственном капитале не показанные в отчете за прошлый год, чистые | C6: 0
A7: 3. | B7: Исправленный баланс на конец прошлого календарного года (сумма строк 1 и 2) | C7: =SUM(C5:C6) -> 1625105476
A8: 4. | B8: Чистый прибыль (убыток) по состоянию на дату от начала года | C8: =+'Income '!C76 -> 100028858 | D8: =+[8]Balance!$C$76 -> 100028858
A9: 5. | B9: Продажа, Обмен, Приобретение или выкуп акций, за текущий год (чистая выручка) | C9: 0
A10: 6. | B10: Изменения в оценочной стоимости прироста над первонач. стоимостью, за текущий год (чистые) | C10: 0
A11: 7. | B11: МИНУС: Денежные дивиденды объявленные по привилегированным акциям | C11: 0
A12: 8. | B12: МИНУС: Денежные дивиденды объявленные по обыкновенным акциям | C12: 0
A13: 9. | B13: Другие статьи влияющие на собственный капитал за текущий год (чистые) | C13: 13155198
A14: 10. | B14: Итого собственного капитала на конец текущего периода (сумма строк с 3 по 10) | C14: =C7+SUM(C8:C10)-SUM(C11:C12)+C13 -> 1738289532 | D14: =+[8]Balance!$C$77 -> 1738289532
B16: Подпись Председателя правления:
B18: Подпись Главного Бухгалтера:

Sheet Loans Receivable
A1: КРЕДИТЫ И ЛИЗИНГИ К ПОЛУЧЕНИЮ ПО ОТРАСЛЯМ ЭКОНОМИКИ, ТИПАМ КЛИЕНТОВ И ПО ТИПУ ОБЕСПЕЧЕНИЯ | W1: Таблица-8
B3: =+'Asset quality'!B3 -> АКБ "Микрокредитбанк" | T3: =+'Asset quality'!P3 -> 44196 | X3: тыс. сум
A4: № | B4: Отрасль экономики | C4: Сумма кредита | D4: в национальной валюте | F4: в иностранной валюте (в экв. в сумах) | H4: из них | J4: из них
D5: Сумма | E5: средне-взвешенные процентные ставки | F5: Сумма | G5: средне-взвешенные процентные ставки | H5: Начисляемые кредиты | I5: Кредиты переведённые в статус ненаращивания процентов | J5: Депозиты | K5: Гарантированные Правительством Республики Узбекистан | L5: из них | M5: Транспортные средства | N5: Инвентарь | O5: Недвижимость | P5: из них | R5: Оборудование | S5: Векселя (облигации) | T5: Акции | U5: Гарантия третьей стороны | V5: Поручительства третьей стороны | W5: Страховой полис | X5: Необеспеченные | Y5: Другое обеспечение
L6: Гарантированные Правительством Республики Узбекистан в иностранной валюте (экв.сум) | P6: жилая недвижимость | Q6: коммерческая недвижимость
A7: Код | B7: (А) | C7: (Б) | D7: (Б1) | E7: (Б2) | F7: (Б3) | G7: (Б4) | H7: (В) | I7: (Г) | J7: (Д) | K7: (Е) | L7: (Е1) | M7: (Ж) | N7: (З) | O7: (И) | P7: (И1) | Q7: (И2) | R7: (К) | S7: (Л) | T7: (М) | U7: (Н) | V7: (О) | W7: (П) | X7: (Р) | Y7: (С)
B8: Промышленность
A9: 10 | B9: Физические лица | C9: =SUM(J9:Y9)-L9-P9-Q9 -> 211918805 | D9: 211918805 | E9: 0.12276754 | H9: 211918805 | J9: 0 | K9: 0 | L9: 0 | M9: 55167 | N9: 0 | O9: =+P9+Q9 -> 46537 | P9: 0 | Q9: 46537 | R9: 0 | S9: 0 | T9: 0 | U9: 0 | V9: 24421212 | W9: 187395889 | X9: 0 | Y9: 0
A10: =A9+10 -> 20 | B10: Государственные предприятия | C10: =SUM(J10:Y10)-L10-P10-Q10 -> 799470 | D10: 799470 | E10: 0.18317147 | H10: 799470 | I10: 0 | J10: 0 | K10: 0 | L10: 0 | M10: 0 | N10: 0 | O10: =+P10+Q10 -> 799470 | P10: 0 | Q10: 799470 | R10: 0 | S10: 0 | T10: 0 | U10: 0 | V10: 0 | W10: 0 | X10: 0 | Y10: 0
A11: =A10+10 -> 30 | B11: Совместные и иностранные предприятия | C11: =SUM(J11:Y11)-L11-P11-Q11 -> 116384043 | D11: 62870858 | E11: 0.19490422 | F11: 53513185 | G11: 0.11969436 | H11: 116384043 | I11: 0 | J11: 0 | K11: 0 | L11: 0 | M11: 3800684 | N11: 0 | O11: =+P11+Q11 -> 76278245 | P11: 0 | Q11: 76278245 | R11: 0 | S11: 0 | T11: 0 | U11: 0 | V11: 8852168 | W11: 27452946 | X11: 0 | Y11: 0
A12: =A11+10 -> 40 | B12: Частные товарищества и корпорации | C12: =SUM(J12:Y12)-L12-P12-Q12 -> 1908584088 | D12: 663743584 | E12: 0.15119777 | F12: 1244840504 | G12: 0.097011272 | H12: 1901887166 | I12: 6696922 | J12: 126667 | K12: 0 | L12: 0 | M12: 145201308 | N12: 0 | O12: =+P12+Q12 -> 1278159383 | P12: 0 | Q12: 1278159383 | R12: 13401538 | S12: 0 | T12: 0 | U12: 0 | V12: 142412896 | W12: 328990798 | X12: 0 | Y12: 291498
A13: =A12+10 -> 50 | B13: Правительство | C13: =SUM(J13:Y13)-L13-P13-Q13 -> 0 | O13: =+P13+Q13 -> 0
A14: =A13+10 -> 60 | B14: Прочие | C14: =SUM(J14:Y14)-L14-P14-Q14 -> 0 | O14: =+P14+Q14 -> 0
A15: =A14+10 -> 70 | B15: Итого по промышленности | C15: =SUM(J15:Y15)-L15-P15-Q15 -> 2237686406 | D15: =SUM(D9:D14) -> 939332717 | E15: =IFERROR(((D9*E9)/D15)+((D10*E10)/D15)+((D11*E11)/D15)+((D12*E12)/D15)+((D13*E13)/D15)+((D14*E14)/D15),0) -> 0.14773629 | F15: =SUM(F9:F14) -> 1298353689 | G15: =IFERROR(((F9*G9)/F15)+((F10*G10)/F15)+((F11*G11)/F15)+((F12*G12)/F15)+((F13*G13)/F15)+((F14*G14)/F15),0) -> 0.097946183 | H15: =SUM(H9:H14) -> 2230989484 | I15: =SUM(I9:I14) -> 6696922 | J15: =SUM(J9:J14) -> 126667 | K15: =SUM(K9:K14) -> 0 | L15: =SUM(L9:L14) -> 0 | M15: =SUM(M9:M14) -> 149057159 | N15: =SUM(N9:N14) -> 0 | O15: =SUM(O9:O14) -> 1355283635 | ... Y15: =SUM(Y9:Y14) -> 291498
B16: Сельское хозяйство
A17: =A15+10 -> 80 | B17: Физические лица | C17: =SUM(J17:Y17)-L17-P17-Q17 -> 1039851491 | D17: 1039851491 | E17: 0.11880396 | H17: 1039851491 | J17: 0 | K17: 0 | L17: 0 | M17: 941199 | N17: 0 | O17: =+P17+Q17 -> 251128 | P17: 0 | Q17: 251128 | R17: 0 | S17: 0 | T17: 0 | U17: 0 | V17: 115285355 | W17: 923341148 | X17: 0 | Y17: 32661
A18: =A17+10 -> 90 | B18: Государственные предприятия | C18: =SUM(J18:Y18)-L18-P18-Q18 -> 65047852 | D18: 65047852 | E18: 0.061996959 | H18: 65047852 | J18: 0 | K18: 0 | L18: 0 | M18: 72171 | N18: 0 | O18: =+P18+Q18 -> 556000 | P18: 0 | Q18: 556000 | R18: 0 | S18: 0 | T18: 0 | U18: 0 | V18: 64419681 | W18: 0 | X18: 0 | Y18: 0
A19: =A18+10 -> 100 | B19: Совместные и иностранные предприятия | C19: =SUM(J19:Y19)-L19-P19-Q19 -> 38351368 | D19: 35488486 | E19: 0.20300851 | F19: 2862882 | G19: 0.07 | H19: 38351368 | J19: 0 | K19: 0 | L19: 0 | M19: 210082 | N19: 0 | O19: =+P19+Q19 -> 37885958 | P19: 0 | Q19: 37885958 | R19: 0 | S19: 0 | T19: 0 | U19: 0 | V19: 255328 | W19: 0 | X19: 0 | Y19: 0
A20: =A19+10 -> 110 | B20: Частные товарищества и корпорации | C20: =SUM(J20:Y20)-L20-P20-Q20 -> 870395796 | D20: 547710613 | E20: 0.18156176 | F20: 322685183 | G20: 0.078188891 | H20: 808522910 | I20: 61872886 | J20: 0 | K20: 0 | L20: 0 | M20: 69718048 | N20: 0 | O20: =+P20+Q20 -> 710462133 | P20: 0 | Q20: 710462133 | R20: 3515348 | S20: 0 | T20: 0 | U20: 0 | V20: 15382151 | W20: 71318116 | X20: 0 | Y20: 0
A21: =A20+10 -> 120 | B21: Фермерское хозяйство | C21: =SUM(J21:Y21)-L21-P21-Q21 -> 153457167 | D21: 126122456 | E21: 0.18882059 | F21: 27334711 | G21: 0.062484242 | H21: 150414802 | I21: 3042365 | J21: 131000 | K21: 0 | L21: 0 | M21: 21241525 | N21: 0 | O21: =+P21+Q21 -> 128231217 | P21: 200000 | Q21: 128031217 | R21: 26285 | S21: 0 | T21: 0 | U21: 0 | V21: 2550294 | W21: 1214521 | X21: 62325 | Y21: 0
A22: =A21+10 -> 130 | B22: Правительство | C22: =SUM(J22:Y22)-L22-P22-Q22 -> 0 | O22: =+P22+Q22 -> 0
A23: =A22+10 -> 140 | B23: Прочие | C23: =SUM(J23:Y23)-L23-P23-Q23 -> 0 | O23: =+P23+Q23 -> 0
A24: =A23+10 -> 150 | B24: Итого по сельскому хозяйству | C24: =SUM(J24:Y24)-L24-P24-Q24 -> 2167103674 | D24: =SUM(D17:D23) -> 1814220898 | E24: =IFERROR(((D17*E17)/D24)+((D18*E18)/D24)+((D19*E19)/D24)+((D20*E20)/D24)+((D21*E21)/D24)+((D22*E22)/D24)+((D23*E23)/D24),0) -> 0.14222829 | F24: =SUM(F17:F23) -> 352882776 | G24: =IFERROR(((F17*G17)/F24)+((F18*G18)/F24)+((F19*G19)/F24)+((F20*G20)/F24)+((F21*G21)/F24)+((F22*G22)/F24)+((F23*G23)/F24),0) -> 0.076905955 | H24: =SUM(H17:H23) -> 2102188423 | I24: =SUM(I17:I23) -> 64915251 | J24: =SUM(J17:J23) -> 131000 | K24: =SUM(K17:K23) -> 0 | L24: =SUM(L17:L23) -> 0 | M24: =SUM(M17:M23) -> 92183025 | N24: =SUM(N17:N23) -> 0 | O24: =SUM(O17:O23) -> 877386436 | ... Y24: =SUM(Y17:Y23) -> 32661
B25: Транспорт и коммуникации
A26: =A24+10 -> 160 | B26: Физические лица | C26: =SUM(J26:Y26)-L26-P26-Q26 -> 169202559 | D26: 169202559 | E26: 0.27309122 | H26: 169202559 | J26: 0 | K26: 0 | L26: 0 | M26: 163337476 | N26: 0 | O26: =+P26+Q26 -> 0 | P26: 0 | Q26: 0 | R26: 0 | S26: 0 | T26: 0 | U26: 0 | V26: 4692 | W26: 5860391 | X26: 0 | Y26: 0
A27: =A26+10 -> 170 | B27: Государственные предприятия | C27: =SUM(J27:Y27)-L27-P27-Q27 -> 703537 | D27: 703537 | E27: 0.24318862 | H27: 703537 | J27: 0 | K27: 0 | L27: 0 | M27: 477801 | N27: 0 | O27: =+P27+Q27 -> 225736 | P27: 0 | Q27: 225736 | R27: 0 | S27: 0 | T27: 0 | U27: 0 | V27: 0 | W27: 0 | X27: 0 | Y27: 0
A28: =A27+10 -> 180 | B28: Совместные и иностранные предприятия | C28: =SUM(J28:Y28)-L28-P28-Q28 -> 57926044 | D28: 5541444 | E28: 0.25014936 | F28: 52384600 | G28: 0.09 | H28: 57926044 | J28: 0 | K28: 0 | L28: 0 | M28: 957280 | N28: 0 | O28: =+P28+Q28 -> 56953831 | P28: 0 | Q28: 56953831 | R28: 0 | S28: 0 | T28: 0 | U28: 0 | V28: 14933 | W28: 0 | X28: 0 | Y28: 0
A29: =A28+10 -> 190 | B29: Частные товарищества и корпорации | C29: =SUM(J29:Y29)-L29-P29-Q29 -> 307907993 | D29: 163638859 | E29: 0.2350322 | F29: 144269134 | G29: 0.11349141 | H29: 307612768 | I29: 295225 | J29: 1296105 | K29: 0 | L29: 0 | M29: 114210528 | N29: 0 | O29: =+P29+Q29 -> 184454517 | P29: 0 | Q29: 184454517 | R29: 0 | S29: 0 | T29: 0 | U29: 0 | V29: 2498073 | W29: 5448770 | X29: 0 | Y29: 0
A30: =A29+10 -> 200 | B30: Правительство | C30: =SUM(J30:Y30)-L30-P30-Q30 -> 0 | J30: 0 | K30: 0 | L30: 0 | M30: 0 | N30: 0 | O30: =+P30+Q30 -> 0 | P30: 0 | Q30: 0 | R30: 0 | S30: 0 | T30: 0 | U30: 0 | V30: 0 | W30: 0 | X30: 0 | Y30: 0
A31: =A30+10 -> 210 | B31: Прочие | C31: =SUM(J31:Y31)-L31-P31-Q31 -> 0 | J31: 0 | K31: 0 | L31: 0 | M31: 0 | N31: 0 | O31: =+P31+Q31 -> 0 | P31: 0 | Q31: 0 | R31: 0 | S31: 0 | T31: 0 | U31: 0 | V31: 0 | W31: 0 | X31: 0 | Y31: 0
A32: =A31+10 -> 220 | B32: Итого по транспорту и коммуникациям | C32: =SUM(J32:Y32)-L32-P32-Q32 -> 535740133 | D32: =SUM(D26:D31) -> 339086399 | E32: =IFERROR(((D26*E26)/D32)+((D27*E27)/D32)+((D28*E28)/D32)+((D29*E29)/D32)+((D30*E30)/D32)+((D31*E31)/D32),0) -> 0.25428744 | F32: =SUM(F26:F31) -> 196653734 | G32: =IFERROR(((F26*G26)/F32)+((F27*G27)/F32)+((F28*G28)/F32)+((F29*G29)/F32)+((F30*G30)/F32)+((F31*G31)/F32),0) -> 0.10723377 | H32: =SUM(H26:H31) -> 535444908 | I32: =SUM(I26:I31) -> 295225 | J32: =SUM(J26:J31) -> 1296105 | K32: =SUM(K26:K31) -> 0 | L32: =SUM(L26:L31) -> 0 | M32: =SUM(M26:M31) -> 278983085 | N32: =SUM(N26:N31) -> 0 | O32: =SUM(O26:O31) -> 241634084 | ... Y32: =SUM(Y26:Y31) -> 0
B33: Строительство
A34: =A32+10 -> 230 | B34: Физические лица | C34: =SUM(J34:Y34)-L34-P34-Q34 -> 146864 | D34: 146864 | E34: 0.15 | H34: 146864 | J34: 0 | K34: 0 | L34: 0 | M34: 0 | N34: 0 | O34: =+P34+Q34 -> 0 | P34: 0 | Q34: 0 | R34: 0 | S34: 0 | T34: 0 | U34: 0 | V34: 0 | W34: 146864 | X34: 0 | Y34: 0
A35: =A34+10 -> 240 | B35: Государственные предприятия | C35: =SUM(J35:Y35)-L35-P35-Q35 -> 455247 | D35: 455247 | E35: 0.28 | H35: 455247 | J35: 0 | K35: 0 | L35: 0 | M35: 0 | N35: 0 | O35: =+P35+Q35 -> 40432 | P35: 0 | Q35: 40432 | R35: 0 | S35: 0 | T35: 0 | U35: 0 | V35: 414815 | W35: 0 | X35: 0 | Y35: 0
A36: =A35+10 -> 250 | B36: Совместные и иностранные предприятия | C36: =SUM(J36:Y36)-L36-P36-Q36 -> 4108321 | D36: 4108321 | E36: 0.21080974 | H36: 4108321 | J36: 0 | K36: 0 | L36: 0 | M36: 0 | N36: 0 | O36: =+P36+Q36 -> 4108321 | P36: 0 | Q36: 4108321 | R36: 0 | S36: 0 | T36: 0 | U36: 0 | V36: 0 | W36: 0 | X36: 0 | Y36: 0
A37: =A36+10 -> 260 | B37: Частные товарищества и корпорации | C37: =SUM(J37:Y37)-L37-P37-Q37 -> 369639589 | D37: 350014939 | E37: 0.14704973 | F37: 19624650 | G37: 0.08 | H37: 357280620 | I37: 12358969 | J37: 0 | K37: 0 | L37: 0 | M37: 5581390 | N37: 0 | O37: =+P37+Q37 -> 352547603 | P37: 0 | Q37: 352547603 | R37: 1242236 | S37: 0 | T37: 0 | U37: 0 | V37: 6677214 | W37: 3591146 | X37: 0 | Y37: 0
A38: =A37+10 -> 270 | B38: Правительство | C38: =SUM(J38:Y38)-L38-P38-Q38 -> 0 | O38: =+P38+Q38 -> 0
A39: =A38+10 -> 280 | B39: Прочие | C39: =SUM(J39:Y39)-L39-P39-Q39 -> 0 | O39: =+P39+Q39 -> 0
A40: =A39+10 -> 290 | B40: Итого по строительству | C40: =SUM(J40:Y40)-L40-P40-Q40 -> 374350021 | D40: =SUM(D34:D39) -> 354725371 | E40: =IFERROR(((D34*E34)/D40)+((D35*E35)/D40)+((D36*E36)/D40)+((D37*E37)/D40)+((D38*E38)/D40)+((D39*E39)/D40),0) -> 0.14796003 | F40: =SUM(F34:F39) -> 19624650 | G40: =IFERROR(((F34*G34)/F40)+((F35*G35)/F40)+((F36*G36)/F40)+((F37*G37)/F40)+((F38*G38)/F40)+((F39*G39)/F40),0) -> 0.08 | H40: =SUM(H34:H39) -> 361991052 | I40: =SUM(I34:I39) -> 12358969 | J40: =SUM(J34:J39) -> 0 | K40: =SUM(K34:K39) -> 0 | L40: =SUM(L34:L39) -> 0 | M40: =SUM(M34:M39) -> 5581390 | N40: =SUM(N34:N39) -> 0 | O40: =SUM(O34:O39) -> 356696356 | ... Y40: =SUM(Y34:Y39) -> 0
B41: Торговля и общественное питание
...

Sheet Aging Analysis
A1: АНАЛИЗ ПРОСРОЧЕННЫХ КРЕДИТОВ И ФИНАНСОВОГО ЛИЗИНГА К ПОЛУЧЕНИЮ | X1: Таблица-9
B3: =+'Asset quality'!B3 -> АКБ "Микрокредитбанк" | T3: =+'Asset quality'!P3 -> 44196 | X3: тыс. сум
A4: № | B4: Характеристики | C4: Всего задолжность по кредитам | D4: % | E4: Реструктуризированные кредиты | F4: % | G4: В ходе судебного разбирательства | H4: % | I4: Просроченная задолжность | K4: % | L4: в том числе, анализ временной задолженности
L5: 1-30 дней | N5: 31-60 дней | P5: 61-90 дней | R5: 91-180 дней | T5: 181-365 дней | V5: 366-730 дней | X5: Свыше 2 лет
I6: основной долг | J6: процент | L6: основной долг | M6: процент | N6: основной долг | O6: процент | P6: основной долг | Q6: процент | R6: основной долг | S6: процент | T6: основной долг | U6: процент | V6: основной долг | W6: процент | X6: основной долг | Y6: процент
B7: (А) | C7: (Б) | D7: (В) | E7: (Г) | F7: (Д) | G7: (Е) | H7: (Ж) | I7: (З) | J7: (З1) | K7: (И) | L7: (К) | M7: (К1) | N7: (Л) | O7: (Л1) | P7: (М) | Q7: (М1) | R7: (Н) | S7: (Н1) | T7: (О) | U7: (О1) | V7: (П) | W7: (П1) | X7: (Р) | Y7: (Р1)
B8: По типу клиента
A9: 1 | B9: Центральный банк | C9: =+'Loans Receivable'!C86 -> 0 | D9: =IF(C$22=0,"",C9/C$22) -> 0 | E9: 0 | F9: =IF(E$22=0,"",E9/E$22) | G9: 0 | H9: =IF($G$22=0,"",G9/$G$22) -> 0 | I9: =+L9+N9+P9+R9+T9+V9+X9 -> 0 | J9: =+M9+O9+T9+S9+U9+W9+Y9 -> 0 | K9: =IF($Z$22=0,"",Z9/$Z$22) -> 0 | L9: 0 | M9: 0 | N9: 0 | O9: 0 | P9: 0 | Q9: 0 | R9: 0 | S9: 0 | T9: 0 | U9: 0 | V9: 0 | W9: 0 | X9: 0 | Y9: 0 | Z9: =+I9+J9 -> 0
A10: 2 | B10: Другие банки | C10: =+'Loans Receivable'!C85 -> 0 | D10: =IF(C$22=0,"",C10/C$22) -> 0 | E10: 0 | F10: =IF(E$22=0,"",E10/E$22) | G10: 0 | H10: =IF($G$22=0,"",G10/$G$22) -> 0 | I10: =+L10+N10+P10+R10+T10+V10+X10 -> 0 | J10: =+M10+O10+Q10+S10+U10+W10+Y10 -> 0 | K10: =IF($Z$22=0,"",Z10/$Z$22) -> 0 | L10: 0 | M10: 0 | N10: 0 | O10: 0 | P10: 0 | Q10: 0 | R10: 0 | S10: 0 | T10: 0 | U10: 0 | V10: 0 | W10: 0 | X10: 0 | Y10: 0 | Z10: =+I10+J10 -> 0
A11: 3 | B11: Правительство | C11: =+'Loans Receivable'!C87 -> 0 | D11: =IF(C$22=0,"",C11/C$22) -> 0 | E11: 0 | F11: =IF(E$22=0,"",E11/E$22) | G11: 0 | H11: =IF($G$22=0,"",G11/$G$22) -> 0 | I11: =+L11+N11+P11+R11+T11+V11+X11 -> 5751 | J11: =+M11+O11+Q11+S11+U11+W11+Y11 -> 1078 | K11: =IF($Z$22=0,"",Z11/$Z$22) -> 4.1384955e-05 | L11: 1989 | M11: 566 | N11: 1989 | O11: 512 | P11: 1773 | Q11: 0 | R11: 0 | S11: 0 | T11: 0 | U11: 0 | V11: 0 | W11: 0 | X11: 0 | Y11: 0 | Z11: =+I11+J11 -> 6829
A12: 4 | B12: Физические лица | C12: =+'Loans Receivable'!C80 -> 2395810747 | D12: =IF(C$22=0,"",C12/C$22) -> 0.28054652 | E12: 0 | F12: =IF(E$22=0,"",E12/E$22) | G12: 848725 | H12: =IF($G$22=0,"",G12/$G$22) -> 0.11999923 | I12: =+L12+N12+P12+R12+T12+V12+X12 -> 17658686 | J12: =+M12+O12+Q12+S12+U12+W12+Y12 -> 19250098 | K12: =IF($Z$22=0,"",Z12/$Z$22) -> 0.2236738 | L12: 8250480 | M12: 7195079 | N12: 5125149 | O12: 5018387 | P12: 2971331 | Q12: 3134135 | R12: 1172271 | S12: 3620387 | T12: 130480 | U12: 168414 | V12: 8975 | W12: 105425 | X12: 0 | Y12: 8271 | Z12: =+I12+J12 -> 36908784
A13: 5 | B13: Государственные предприятия | C13: =+'Loans Receivable'!C81 -> 207833727 | D13: =IF(C$22=0,"",C13/C$22) -> 0.024337076 | E13: 0 | F13: =IF(E$22=0,"",E13/E$22) | G13: 0 | H13: =IF($G$22=0,"",G13/$G$22) -> 0 | I13: =+L13+N13+P13+R13+T13+V13+X13 -> 529357 | J13: =+M13+O13+Q13+S13+U13+W13+Y13 -> 52478 | K13: =IF($Z$22=0,"",Z13/$Z$22) -> 0.0035260236 | L13: 108412 | M13: 34389 | N13: 74218 | O13: 1183 | P13: 56777 | Q13: 1223 | R13: 74758 | S13: 8045 | T13: 135242 | U13: 4417 | V13: 79950 | W13: 3221 | X13: 0 | Y13: 0 | Z13: =+I13+J13 -> 581835
A14: 6 | B14: Совместные и иностранные предприятия | C14: =+'Loans Receivable'!C82 -> 233817919 | D14: =IF(C$22=0,"",C14/C$22) -> 0.027379793 | E14: 0 | F14: =IF(E$22=0,"",E14/E$22) | G14: 0 | H14: =IF($G$22=0,"",G14/$G$22) -> 0 | I14: =+L14+N14+P14+R14+T14+V14+X14 -> 226577 | J14: =+M14+O14+Q14+S14+U14+W14+Y14 -> 1629798 | K14: =IF($Z$22=0,"",Z14/$Z$22) -> 0.011249963 | L14: 103212 | M14: 528880 | N14: 123365 | O14: 476468 | P14: 0 | Q14: 457688 | R14: 0 | S14: 166762 | T14: 0 | U14: 0 | V14: 0 | W14: 0 | X14: 0 | Y14: 0 | Z14: =+I14+J14 -> 1856375
A15: 7 | B15: Частные товарищества и корпорации | C15: =+'Loans Receivable'!C83 -> 5506977228 | D15: =IF(C$22=0,"",C15/C$22) -> 0.64486032 | E15: 0 | F15: =IF(E$22=0,"",E15/E$22) | G15: 3209962 | H15: =IF($G$22=0,"",G15/$G$22) -> 0.45384895 | I15: =+L15+N15+P15+R15+T15+V15+X15 -> 64207482 | J15: =+M15+O15+Q15+S15+U15+W15+Y15 -> 46997390 | K15: =IF($Z$22=0,"",Z15/$Z$22) -> 0.6739213 | L15: 16359917 | M15: 19010115 | N15: 22782498 | O15: 13854234 | P15: 16751608 | Q15: 7357666 | R15: 5355996 | S15: 5334510 | T15: 2362103 | U15: 1247993 | V15: 593006 | W15: 192872 | X15: 2354 | Y15: 0 | Z15: =+I15+J15 -> 111204872
A16: 8 | B16: Фермерское хозяйство | C16: =+'Loans Receivable'!C84 -> 153457167 | D16: =IF(C$22=0,"",C16/C$22) -> 0.017969647 | E16: 0 | F16: =IF(E$22=0,"",E16/E$22) | G16: 2815255 | H16: =IF($G$22=0,"",G16/$G$22) -> 0.39804226 | I16: =+L16+N16+P16+R16+T16+V16+X16 -> 1986760 | J16: =+M16+O16+Q16+S16+U16+W16+Y16 -> 2460150 | K16: =IF($Z$22=0,"",Z16/$Z$22) -> 0.026949065 | L16: 806880 | M16: 1305542 | N16: 547279 | O16: 795238 | P16: 472202 | Q16: 303177 | R16: 34592 | S16: 11855 | T16: 58065 | U16: 34913 | V16: 67742 | W16: 9425 | X16: 0 | Y16: 0 | Z16: =+I16+J16 -> 4446910
A17: 9 | B17: Небанковские финансовые институты | C17: =+'Loans Receivable'!C88 -> 0 | D17: =IF(C$22=0,"",C17/C$22) -> 0 | E17: 0 | F17: =IF(E$22=0,"",E17/E$22) | G17: 0 | H17: =IF($G$22=0,"",G17/$G$22) -> 0 | I17: =+L17+N17+P17+R17+T17+V17+X17 -> 0 | J17: =+M17+O17+Q17+S17+U17+W17+Y17 -> 0 | K17: =IF($Z$22=0,"",Z17/$Z$22) -> 0 | L17: 0 | M17: 0 | N17: 0 | O17: 0 | P17: 0 | Q17: 0 | R17: 0 | S17: 0 | T17: 0 | U17: 0 | V17: 0 | W17: 0 | X17: 0 | Y17: 0 | Z17: =+I17+J17 -> 0
A18: 10 | B18: Негосударственные некоммерческие организации | C18: =+'Loans Receivable'!C89 -> 41726791 | D18: =IF(C$22=0,"",C18/C$22) -> 0.0048861564 | F18: =IF(E$22=0,"",E18/E$22) | G18: 0 | H18: =IF($G$22=0,"",G18/$G$22) -> 0 | I18: =+L18+N18+P18+R18+T18+V18+X18 -> 1243160 | J18: =+M18+O18+Q18+S18+U18+W18+Y18 -> 134026 | K18: =IF($Z$22=0,"",Z18/$Z$22) -> 0.0083459921 | L18: 249862 | M18: 38052 | N18: 220533 | O18: 63579 | P18: 166501 | Q18: 30850 | R18: 118914 | S18: 1545 | T18: 183900 | U18: 0 | V18: 284241 | W18: 0 | X18: 19209 | Y18: 0 | Z18: =+I18+J18 -> 1377186
A19: 11 | B19: Бюджетные организации | C19: =+'Loans Receivable'!C90 -> 0 | D19: =IF(C$22=0,"",C19/C$22) -> 0 | E19: 0 | F19: =IF(E$22=0,"",E19/E$22) | G19: 0 | H19: =IF($G$22=0,"",G19/$G$22) -> 0 | I19: =+L19+N19+P19+R19+T19+V19+X19 -> 0 | J19: =+M19+O19+Q19+S19+U19+W19+Y19 -> 0 | K19: =IF($Z$22=0,"",Z19/$Z$22) -> 0 | L19: 0 | M19: 0 | N19: 0 | O19: 0 | P19: 0 | Q19: 0 | R19: 0 | S19: 0 | T19: 0 | U19: 0 | V19: 0 | W19: 0 | X19: 0 | Y19: 0 | Z19: =+I19+J19 -> 0
A20: 12 | B20: Прочие | C20: =+'Loans Receivable'!C91 -> 174977 | D20: =IF(C$22=0,"",C20/C$22) -> 2.0489593e-05 | E20: 0 | F20: =IF(E$22=0,"",E20/E$22) | G20: 198812 | H20: =IF($G$22=0,"",G20/$G$22) -> 0.02810956 | I20: =+L20+N20+P20+R20+T20+V20+X20 -> 5976709 | J20: =+M20+O20+Q20+S20+U20+W20+Y20 -> 2652159 | K20: =IF($Z$22=0,"",Z20/$Z$22) -> 0.052292475 | L20: 2903961 | M20: 1208828 | N20: 1679873 | O20: 857537 | P20: 848353 | Q20: 483721 | R20: 434038 | S20: 78463 | T20: 88854 | U20: 15337 | V20: 17912 | W20: 8273 | X20: 3718 | Y20: 0 | Z20: =+I20+J20 -> 8628868
Z21: =+I21+J21 -> 0
A22: 13 | B22: Итого кредита и лизинга | C22: =SUM(C9:C20) -> 8539798556 | D22: =IF(C$22=0,"",C22/C$22) -> 1 | E22: =SUM(E9:E20) -> 0 | F22: =IF(E$22=0,"",E22/E$22) | G22: =SUM(G9:G20) -> 7072754 | H22: =IF($G$22=0,"",G22/$G$22) -> 1 | I22: =SUM(I9:I20) -> 91834482 | J22: =SUM(J9:J20) -> 73177177 | K22: =IF($Z$22=0,"",Z22/$Z$22) -> 1 | L22: =SUM(L9:L20) -> 28784713 | M22: =SUM(M9:M20) -> 29321451 | N22: =SUM(N9:N20) -> 30554904 | O22: =SUM(O9:O20) -> 21067138 | P22: =SUM(P9:P20) -> 21268545 | Q22: =SUM(Q9:Q20) -> 11768460 | R22: =SUM(R9:R20) -> 7190569 | S22: =SUM(S9:S20) -> 9221567 | ... Y22: =SUM(Y9:Y20) -> 8271 | Z22: =+I22+J22 -> 165011659
Z23: =+I23+J23 -> 0
B24: По сектору экономики | F24: =IF(E$22=0,"",E24/E$22) | Z24: =+I24+J24 -> 0
A25: 14 | B25: Промышленность | C25: =+'Loans Receivable'!C15 -> 2237686406 | D25: =IF(C$34=0,"",C25/C$34) -> 0.26203035 | E25: 0 | F25: =IF($E$34=0,"",E25/$E$34) | G25: 1053977 | H25: =IF($G$34=0,"",G25/$G$34) -> 0.14901932 | I25: =+L25+N25+P25+R25+T25+V25+X25 -> 9870898 | J25: =+M25+O25+Q25+S25+U25+W25+Y25 -> 11856464 | K25: =IF($Z$34=0,"",Z25/$Z$34) -> 0.13167168 | L25: 3979407 | M25: 4581182 | N25: 2480363 | O25: 4247484 | P25: 1396318 | Q25: 2247797 | R25: 1039185 | S25: 217711 | T25: 611917 | U25: 430458 | V25: 359990 | W25: 131832 | X25: 3718 | Y25: 0 | Z25: =+I25+J25 -> 21727362
A26: 15 | B26: Сельское хозяйство | C26: =+'Loans Receivable'!C24 -> 2167103674 | D26: =IF(C$34=0,"",C26/C$34) -> 0.2537652 | E26: 0 | F26: =IF($E$34=0,"",E26/$E$34) | G26: 3161247 | H26: =IF($G$34=0,"",G26/$G$34) -> 0.44696125 | I26: =+L26+N26+P26+R26+T26+V26+X26 -> 27967422 | J26: =+M26+O26+Q26+S26+U26+W26+Y26 -> 17378250 | K26: =IF($Z$34=0,"",Z26/$Z$34) -> 0.27480284 | L26: 2919044 | M26: 7588627 | N26: 11990024 | O26: 3835362 | P26: 11016967 | Q26: 1932022 | R26: 1091666 | S26: 3937979 | T26: 830237 | U26: 73033 | V26: 119484 | W26: 11227 | X26: 0 | Y26: 0 | Z26: =+I26+J26 -> 45345672
A27: 16 | B27: Транспорт и коммуникации | C27: =+'Loans Receivable'!C32 -> 535740133 | D27: =IF(C$34=0,"",C27/C$34) -> 0.062734516 | E27: 0 | F27: =IF($E$34=0,"",E27/$E$34) | G27: 185225 | H27: =IF($G$34=0,"",G27/$G$34) -> 0.026188526 | I27: =+L27+N27+P27+R27+T27+V27+X27 -> 2514458 | J27: =+M27+O27+Q27+S27+U27+W27+Y27 -> 1447277 | K27: =IF($Z$34=0,"",Z27/$Z$34) -> 0.024008819 | L27: 736688 | M27: 704612 | N27: 543592 | O27: 522090 | P27: 400291 | Q27: 174123 | R27: 348218 | S27: 24859 | T27: 485669 | U27: 21593 | V27: 0 | W27: 0 | X27: 0 | Y27: 0 | Z27: =+I27+J27 -> 3961735
A28: 17 | B28: Строительство | C28: =+'Loans Receivable'!C40 -> 374350021 | D28: =IF(C$34=0,"",C28/C$34) -> 0.043835931 | E28: 0 | F28: =IF($E$34=0,"",E28/$E$34) | G28: 0 | H28: =IF($G$34=0,"",G28/$G$34) -> 0 | I28: =+L28+N28+P28+R28+T28+V28+X28 -> 5747912 | J28: =+M28+O28+Q28+S28+U28+W28+Y28 -> 6034074 | K28: =IF($Z$34=0,"",Z28/$Z$34) -> 0.071400931 | L28: 2294193 | M28: 2516824 | N28: 1487154 | O28: 1586669 | P28: 1005957 | Q28: 1271010 | R28: 936838 | S28: 52988 | T28: 23770 | U28: 584991 | V28: 0 | W28: 21592 | X28: 0 | Y28: 0 | Z28: =+I28+J28 -> 11781986
A29: 18 | B29: Торговля и общественное питание | C29: =+'Loans Receivable'!C48 -> 757760211 | D29: =IF(C$34=0,"",C29/C$34) -> 0.088732797 | E29: 0 | F29: =IF($E$34=0,"",E29/$E$34) | G29: 654374 | H29: =IF($G$34=0,"",G29/$G$34) -> 0.092520396 | I29: =+L29+N29+P29+R29+T29+V29+X29 -> 16889227 | J29: =+M29+O29+Q29+S29+U29+W29+Y29 -> 8884322 | K29: =IF($Z$34=0,"",Z29/$Z$34) -> 0.15619229 | L29: 6252572 | M29: 3389961 | N29: 5812791 | O29: 3393686 | P29: 2783827 | Q29: 1732023 | R29: 1451689 | S29: 283534 | T29: 321717 | U29: 47716 | V29: 266631 | W29: 37402 | X29: 0 | Y29: 0 | Z29: =+I29+J29 -> 25773549
A30: 19 | B30: Материально-техническое снабжение и сбыт | C30: =+'Loans Receivable'!C56 -> 1372056029 | D30: =IF(C$34=0,"",C30/C$34) -> 0.16066609 | E30: 0 | F30: =IF($E$34=0,"",E30/$E$34) | G30: 0 | H30: =IF($G$34=0,"",G30/$G$34) -> 0 | I30: =+L30+N30+P30+R30+T30+V30+X30 -> 2500 | J30: =+M30+O30+Q30+S30+U30+W30+Y30 -> 454150 | K30: =IF($Z$34=0,"",Z30/$Z$34) -> 0.0027673802 | L30: 2500 | M30: 6175 | N30: 0 | O30: 2553 | P30: 0 | Q30: 6896 | R30: 0 | S30: 438526 | T30: 0 | U30: 0 | V30: 0 | W30: 0 | X30: 0 | Y30: 0 | Z30: =+I30+J30 -> 456650
A31: 20 | B31: Жилищно-коммунальные услуги | C31: =+'Loans Receivable'!C65 -> 107626665 | D31: =IF(C$34=0,"",C31/C$34) -> 0.012602951 | E31: 0 | F31: =IF($E$34=0,"",E31/$E$34) | G31: 0 | H31: =IF($G$34=0,"",G31/$G$34) -> 0 | I31: =+L31+N31+P31+R31+T31+V31+X31 -> 59969 | J31: =+M31+O31+Q31+S31+U31+W31+Y31 -> 9308 | K31: =IF($Z$34=0,"",Z31/$Z$34) -> 0.00041983094 | L31: 26578 | M31: 2110 | N31: 11169 | O31: 3430 | P31: 8889 | Q31: 3705 | R31: 13333 | S31: 63 | T31: 0 | U31: 0 | V31: 0 | W31: 0 | X31: 0 | Y31: 0 | Z31: =+I31+J31 -> 69277
A32: 21 | B32: Другие сектора | C32: =+'Loans Receivable'!C78 -> 987475417 | D32: =IF(C$34=0,"",C32/C$34) -> 0.11563217 | E32: 0 | F32: =IF($E$34=0,"",E32/$E$34) | G32: 2017931 | H32: =IF($G$34=0,"",G32/$G$34) -> 0.2853105 | I32: =+L32+N32+P32+R32+T32+V32+X32 -> 28782096 | J32: =+M32+O32+Q32+S32+U32+W32+Y32 -> 27113332 | K32: =IF($Z$34=0,"",Z32/$Z$34) -> 0.33873623 | L32: 12573731 | M32: 10531960 | N32: 8229811 | O32: 7475864 | P32: 4656296 | Q32: 4400884 | R32: 2309640 | S32: 4265907 | T32: 685334 | U32: 313283 | V32: 305721 | W32: 117163 | X32: 21563 | Y32: 8271 | Z32: =+I32+J32 -> 55895428
Z33: =+I33+J33 -> 0
A34: 22 | B34: Итого кредита и лизинга | C34: =SUM(C25:C32) -> 8539798556 | D34: =IF(C$34=0,"",C34/C$34) -> 1 | E34: =SUM(E25:E32) -> 0 | F34: =IF($E$34=0,"",E34/$E$34) | G34: =SUM(G25:G32) -> 7072754 | H34: =IF($G$34=0,"",G34/$G$34) -> 1 | I34: =SUM(I25:I32) -> 91834482 | J34: =SUM(J25:J32) -> 73177177 | K34: =IF($Z$34=0,"",Z34/$Z$34) -> 1 | L34: =SUM(L25:L32) -> 28784713 | M34: =SUM(M25:M32) -> 29321451 | N34: =SUM(N25:N32) -> 30554904 | O34: =SUM(O25:O32) -> 21067138 | P34: =SUM(P25:P32) -> 21268545 | Q34: =SUM(Q25:Q32) -> 11768460 | R34: =SUM(R25:R32) -> 7190569 | S34: =SUM(S25:S32) -> 9221567 | ... Y34: =SUM(Y25:Y32) -> 8271 | Z34: =+I34+J34 -> 165011659
B37: Подпись Председателя правления:
B39: Подпись Главного Бухгалтера:

Sheet Asset Classification
A1: ОТЧЕТ О КЛАССИФИКАЦИИ АКТИВОВ ПО СТЕПЕНИ РИСКА | W1: Таблица-10
B2: =+'Asset quality'!B3 -> АКБ "Микрокредитбанк" | U2: =+'Asset quality'!P3 -> 44196 | Z2: тыс. сум
A3: № | B3: Статьи баланса | C3: Общая сумма | D3: из них, в иностранной валюте (в экв. в сумах) | E3: Стандартные | F3: из них, в иностранной валюте (в экв. в сумах) | G3: Общие резервы (1%) | H3: из них, в иностранной валюте (в экв. в сумах) | I3: Субстандартные | J3: из них, в иностранной валюте (в экв. в сумах) | K3: Специальные резервы (мин 10%) | L3: из них, в иностранной валюте (в экв. в сумах) | M3: Неудовлетворительные | N3: из них, в иностранной валюте (в экв. в сумах) | O3: Специальные резервы (мин 25%) | P3: из них, в иностранной валюте (в экв. в сумах) | Q3: Сомнительные | R3: из них, в иностранной валюте (в экв. в сумах) | S3: Специальные резервы (мин 50%) | T3: из них, в иностранной валюте (в экв. в сумах) | U3: Безнадежные | V3: из них, в иностранной валюте (в экв. в сумах) | W3: Специальные резервы (100%) | X3: из них, в иностранной валюте (в экв. в сумах) | Y3: Совокупная сумма специальных резервов | Z3: из них, в иностранной валюте (в экв. в сумах)
A4: (А) | B4: (Б) | C4: (В) | D4: (В1) | E4: (Г) | F4: (Г1) | G4: (Д) | H4: (Д1) | I4: (Е) | J4: (Е1) | K4: (Ж) | L4: (Ж1) | M4: (З) | N4: (З1) | O4: (И) | P4: (И1) | Q4: (К) | R4: (К1) | S4: (Л) | T4: (Л1) | U4: (М) | V4: (М1) | W4: (Н) | X4: (Н1) | Y4: О=Ж+И+Л+Н | Z4: (О1)=(Ж1)+(И1)+(Л1)+(Н1)
B5: По типу клиента
A6: 1 | B6: Центральный банк | C6: =E6+I6+M6+Q6+U6 -> 0 | D6: =F6+J6+N6+R6+V6 -> 0 | Y6: =+W6+S6+O6+K6 -> 0 | Z6: =+X6+T6+P6+L6 -> 0 | AA6: =+'Aging Analysis'!C9 -> 0
B7: из них необеспеченные | C7: =E7+I7+M7+Q7+U7 -> 0 | D7: =F7+J7+N7+R7+V7 -> 0 | Y7: =+W7+S7+O7+K7 -> 0 | Z7: =+X7+T7+P7+L7 -> 0 | AA7: =+AA6-C6 -> 0
A8: 2 | B8: Другие банки | C8: =E8+I8+M8+Q8+U8 -> 0 | D8: =F8+J8+N8+R8+V8 -> 0 | Y8: =+W8+S8+O8+K8 -> 0 | Z8: =+X8+T8+P8+L8 -> 0 | AA8: =+'Aging Analysis'!C10 -> 0
B9: из них необеспеченные | C9: =E9+I9+M9+Q9+U9 -> 0 | D9: =F9+J9+N9+R9+V9 -> 0 | Y9: =+W9+S9+O9+K9 -> 0 | Z9: =+X9+T9+P9+L9 -> 0 | AA9: =+AA8-C8 -> 0
A10: 3 | B10: Правительство | C10: =E10+I10+M10+Q10+U10 -> 0 | D10: =F10+J10+N10+R10+V10 -> 0 | Y10: =+W10+S10+O10+K10 -> 0 | Z10: =+X10+T10+P10+L10 -> 0 | AA10: =+'Aging Analysis'!C11 -> 0
B11: из них необеспеченные | C11: =E11+I11+M11+Q11+U11 -> 0 | D11: =F11+J11+N11+R11+V11 -> 0 | Y11: =+W11+S11+O11+K11 -> 0 | Z11: =+X11+T11+P11+L11 -> 0 | AA11: =+AA10-C10 -> 0
A12: 4 | B12: Физические лица | C12: =E12+I12+M12+Q12+U12 -> 2395810747 | D12: =F12+J12+N12+R12+V12 -> 0 | E12: 1988169241 | F12: 0 | G12: 0 | H12: 0 | I12: 377969015 | J12: 0 | K12: 37816072 | L12: 0 | M12: 22359606 | N12: 0 | O12: 5589901 | P12: 0 | Q12: 5061752 | R12: 0 | S12: 2530876 | T12: 0 | U12: 2251133 | V12: 0 | W12: 2251133 | X12: 0 | Y12: =+W12+S12+O12+K12 -> 48187982 | Z12: =+X12+T12+P12+L12 -> 0 | AA12: =+'Aging Analysis'!C12 -> 2395810747
B13: из них необеспеченные | C13: =E13+I13+M13+Q13+U13 -> 0 | D13: =F13+J13+N13+R13+V13 -> 0 | Y13: =+W13+S13+O13+K13 -> 0 | Z13: =+X13+T13+P13+L13 -> 0 | AA13: =+AA12-C12 -> 0
A14: 5 | B14: Государственные предприятия | C14: =E14+I14+M14+Q14+U14 -> 207833727 | D14: =F14+J14+N14+R14+V14 -> 0 | E14: 196933727 | F14: 0 | G14: 0 | H14: 0 | I14: 10900000 | J14: 0 | K14: 1090000 | L14: 0 | M14: 0 | N14: 0 | O14: 0 | P14: 0 | Q14: 0 | R14: 0 | S14: 0 | T14: 0 | U14: 0 | V14: 0 | W14: 0 | X14: 0 | Y14: =+W14+S14+O14+K14 -> 1090000 | Z14: =+X14+T14+P14+L14 -> 0 | AA14: =+'Aging Analysis'!C13 -> 207833727
B15: из них необеспеченные | C15: =E15+I15+M15+Q15+U15 -> 0 | D15: =F15+J15+N15+R15+V15 -> 0 | Y15: =+W15+S15+O15+K15 -> 0 | Z15: =+X15+T15+P15+L15 -> 0 | AA15: =+AA14-C14 -> 0
A16: 6 | B16: Совместные и иностранные предприятия | C16: =E16+I16+M16+Q16+U16 -> 233817919 | D16: =F16+J16+N16+R16+V16 -> 108760666 | E16: 149637525 | F16: 29919367 | G16: 0 | H16: 0 | I16: 84062247 | J16: 78841299 | K16: 8406225 | L16: 7884130 | M16: 0 | N16: 0 | O16: 0 | P16: 0 | Q16: 118147 | R16: 0 | S16: 59074 | T16: 0 | U16: 0 | V16: 0 | W16: 0 | X16: 0 | Y16: =+W16+S16+O16+K16 -> 8465299 | Z16: =+X16+T16+P16+L16 -> 7884130 | AA16: =+'Aging Analysis'!C14 -> 233817919
B17: из них необеспеченные | C17: =E17+I17+M17+Q17+U17 -> 0 | D17: =F17+J17+N17+R17+V17 -> 0 | Y17: =+W17+S17+O17+K17 -> 0 | Z17: =+X17+T17+P17+L17 -> 0 | AA17: =+AA16-C16 -> 0
A18: 7 | B18: Частные товарищества и корпорации | C18: =E18+I18+M18+Q18+U18 -> 5506977228 | D18: =F18+J18+N18+R18+V18 -> 2680428998 | E18: 4425383897 | F18: 2260308333 | G18: 0 | H18: 0 | I18: 1027438960 | J18: 420120665 | K18: 103169931 | L18: 41934742 | M18: 12110446 | N18: 0 | O18: 3027611 | P18: 0 | Q18: 30739125 | R18: 0 | S18: 15427063 | T18: 0 | U18: 11304800 | V18: 0 | W18: 11304800 | X18: 0 | Y18: =+W18+S18+O18+K18 -> 132929405 | Z18: =+X18+T18+P18+L18 -> 41934742 | AA18: =+'Aging Analysis'!C15 -> 5506977228
B19: из них необеспеченные | C19: =E19+I19+M19+Q19+U19 -> 0 | D19: =F19+J19+N19+R19+V19 -> 0 | Y19: =+W19+S19+O19+K19 -> 0 | Z19: =+X19+T19+P19+L19 -> 0 | AA19: =+AA18-C18 -> 0
A20: 8 | B20: Фермерское хозяйство | C20: =E20+I20+M20+Q20+U20 -> 153457167 | D20: =F20+J20+N20+R20+V20 -> 27334711 | E20: 110183801 | F20: 15021469 | G20: 0 | H20: 0 | I20: 40611434 | J20: 12313242 | K20: 4061143 | L20: 1231324 | M20: 3239 | N20: 0 | O20: 810 | P20: 0 | Q20: 0 | S20: 0 | T20: 0 | U20: 2658693 | V20: 0 | W20: 2658693 | X20: 0 | Y20: =+W20+S20+O20+K20 -> 6720646 | Z20: =+X20+T20+P20+L20 -> 1231324 | AA20: =+'Aging Analysis'!C16 -> 153457167
B21: из них необеспеченные | C21: =E21+I21+M21+Q21+U21 -> 0 | D21: =F21+J21+N21+R21+V21 -> 0 | Y21: =+W21+S21+O21+K21 -> 0 | Z21: =+X21+T21+P21+L21 -> 0 | AA21: =+AA20-C20 -> 0
A22: 9 | B22: Небанковские финансовые институты | C22: =E22+I22+M22+Q22+U22 -> 0 | D22: =F22+J22+N22+R22+V22 -> 0 | E22: 0 | F22: 0 | G22: 0 | H22: 0 | I22: 0 | J22: 0 | K22: 0 | L22: 0 | M22: 0 | N22: 0 | O22: 0 | P22: 0 | Q22: 0 | R22: 0 | S22: 0 | T22: 0 | U22: 0 | V22: 0 | W22: 0 | X22: 0 | Y22: =+W22+S22+O22+K22 -> 0 | Z22: =+X22+T22+P22+L22 -> 0 | AA22: =+'Aging Analysis'!C17 -> 0
B23: из них необеспеченные | C23: =E23+I23+M23+Q23+U23 -> 0 | D23: =F23+J23+N23+R23+V23 -> 0 | Y23: =+W23+S23+O23+K23 -> 0 | Z23: =+X23+T23+P23+L23 -> 0 | AA23: =+AA22-C22 -> 0
A24: 10 | B24: Негосударственные некоммерческие организации | C24: =E24+I24+M24+Q24+U24 -> 41726791 | D24: =F24+J24+N24+R24+V24 -> 0 | E24: 41718590 | F24: 0 | G24: 0 | H24: 0 | I24: 8201 | J24: 0 | K24: 820 | L24: 0 | M24: 0 | N24: 0 | O24: 0 | P24: 0 | Q24: 0 | R24: 0 | S24: 0 | T24: 0 | U24: 0 | V24: 0 | W24: 0 | X24: 0 | Y24: =+W24+S24+O24+K24 -> 820 | Z24: =+X24+T24+P24+L24 -> 0 | AA24: =+'Aging Analysis'!C18 -> 41726791
B25: из них необеспеченные | C25: =E25+I25+M25+Q25+U25 -> 0 | D25: =F25+J25+N25+R25+V25 -> 0 | Y25: =+W25+S25+O25+K25 -> 0 | Z25: =+X25+T25+P25+L25 -> 0 | AA25: =+AA24-C24 -> 0
A26: 11 | B26: Бюджетные организации | C26: =E26+I26+M26+Q26+U26 -> 0 | D26: =F26+J26+N26+R26+V26 -> 0 | E26: 0 | F26: 0 | G26: 0 | H26: 0 | I26: 0 | J26: 0 | K26: 0 | L26: 0 | M26: 0 | N26: 0 | O26: 0 | P26: 0 | Q26: 0 | R26: 0 | S26: 0 | T26: 0 | U26: 0 | V26: 0 | W26: 0 | X26: 0 | Y26: =+W26+S26+O26+K26 -> 0 | Z26: =+X26+T26+P26+L26 -> 0 | AA26: =+'Aging Analysis'!C19 -> 0
B27: из них необеспеченные | C27: =E27+I27+M27+Q27+U27 -> 0 | D27: =F27+J27+N27+R27+V27 -> 0 | Y27: =+W27+S27+O27+K27 -> 0 | Z27: =+X27+T27+P27+L27 -> 0 | AA27: =+AA26-C26 -> 0
A28: 12 | B28: Прочие | C28: =E28+I28+M28+Q28+U28 -> 174977 | D28: =F28+J28+N28+R28+V28 -> 0 | E28: 174977 | F28: 0 | G28: 0 | H28: 0 | I28: 0 | J28: 0 | K28: 0 | L28: 0 | M28: 0 | N28: 0 | O28: 0 | Q28: 0 | R28: 0 | S28: 0 | T28: 0 | U28: 0 | V28: 0 | W28: 0 | X28: 0 | Y28: =+W28+S28+O28+K28 -> 0 | Z28: =+X28+T28+P28+L28 -> 0 | AA28: =+'Aging Analysis'!C20 -> 174977
B29: из них необеспеченные | C29: =E29+I29+M29+Q29+U29 -> 0 | D29: =F29+J29+N29+R29+V29 -> 0 | Y29: =+W29+S29+O29+K29 -> 0 | Z29: =+X29+T29+P29+L29 -> 0 | AA29: =+AA28-C28 -> 0
A30: 13 | B30: Итого кредита и лизинга | C30: =+C6+C8+C10+C12+C14+C16+C18+C20+C22+C24+C26+C28 -> 8539798556 | D30: =+D6+D8+D10+D12+D14+D16+D18+D20+D22+D24+D26+D28 -> 2816524375 | E30: =+E6+E8+E10+E12+E14+E16+E18+E20+E22+E24+E26+E28 -> 6912201758 | F30: =+F6+F8+F10+F12+F14+F16+F18+F20+F22+F24+F26+F28 -> 2305249169 | G30: =+G6+G8+G10+G12+G14+G16+G18+G20+G22+G24+G26+G28 -> 0 | H30: =+H6+H8+H10+H12+H14+H16+H18+H20+H22+H24+H26+H28 -> 0 | I30: =+I6+I8+I10+I12+I14+I16+I18+I20+I22+I24+I26+I28 -> 1540989857 | J30: =+J6+J8+J10+J12+J14+J16+J18+J20+J22+J24+J26+J28 -> 511275206 | ... Z30: =+Z6+Z8+Z10+Z12+Z14+Z16+Z18+Z20+Z22+Z24+Z26+Z28 -> 51050196
B31: из них необеспеченные | C31: =+C7+C9+C11+C13+C15+C17+C19+C21+C23+C25+C27+C29 -> 0 | D31: =+D7+D9+D11+D13+D15+D17+D19+D21+D23+D25+D27+D29 -> 0 | E31: =+E7+E9+E11+E13+E15+E17+E19+E21+E23+E25+E27+E29 -> 0 | F31: =+F7+F9+F11+F13+F15+F17+F19+F21+F23+F25+F27+F29 -> 0 | G31: =+G7+G9+G11+G13+G15+G17+G19+G21+G23+G25+G27+G29 -> 0 | H31: =+H7+H9+H11+H13+H15+H17+H19+H21+H23+H25+H27+H29 -> 0 | I31: =+I7+I9+I11+I13+I15+I17+I19+I21+I23+I25+I27+I29 -> 0 | J31: =+J7+J9+J11+J13+J15+J17+J19+J21+J23+J25+J27+J29 -> 0 | ... Z31: =+Z7+Z9+Z11+Z13+Z15+Z17+Z19+Z21+Z23+Z25+Z27+Z29 -> 0
B32: По сектору экономики
A34: 14 | B34: Промышленность | C34: =E34+I34+M34+Q34+U34 -> 2237686406 | D34: =F34+J34+N34+R34+V34 -> 1298353689 | E34: 1824656663 | F34: 1066841849 | G34: 0 | H34: 0 | I34: 406373276 | J34: 231511840 | K34: 40570363 | L34: 23073859 | M34: 2854310 | N34: 0 | O34: 713578 | P34: 0 | Q34: 1850822 | R34: 0 | S34: 925411 | T34: 0 | U34: 1951335 | V34: 0 | W34: 1951335 | X34: 0 | Y34: =+W34+S34+O34+K34 -> 44160687 | Z34: =+X34+T34+P34+L34 -> 23073859 | AA34: =+'Aging Analysis'!C25 -> 2237686406
B35: из них необеспеченные | C35: =E35+I35+M35+Q35+U35 -> 0 | D35: =F35+J35+N35+R35+V35 -> 0 | Y35: =+W35+S35+O35+K35 -> 0 | Z35: =+X35+T35+P35+L35 -> 0 | AA35: =+AA34-C34 -> 0
A36: 15 | B36: Сельское хозяйство | C36: =E36+I36+M36+Q36+U36 -> 2167103674 | D36: =F36+J36+N36+R36+V36 -> 352882775 | E36: 1618847517 | F36: 232810109 | G36: 0 | H36: 0 | I36: 502209375 | J36: 120072666 | K36: 50227687 | L36: 12007267 | M36: 16112426 | N36: 0 | O36: 4028106 | P36: 0 | Q36: 23574190 | R36: 0 | S36: 11787095 | T36: 0 | U36: 6360166 | V36: 0 | W36: 6360166 | X36: 0 | Y36: =+W36+S36+O36+K36 -> 72403054 | Z36: =+X36+T36+P36+L36 -> 12007267 | AA36: =+'Aging Analysis'!C26 -> 2167103674
B37: из них необеспеченные | C37: =E37+I37+M37+Q37+U37 -> 0 | D37: =F37+J37+N37+R37+V37 -> 0 | Y37: =+W37+S37+O37+K37 -> 0 | Z37: =+X37+T37+P37+L37 -> 0 | AA37: =+AA36-C36 -> 0
A38: 16 | B38: Транспорт и коммуникации | C38: =E38+I38+M38+Q38+U38 -> 535740133 | D38: =F38+J38+N38+R38+V38 -> 196653734 | E38: 395472529 | F38: 104758856 | G38: 0 | H38: 0 | I38: 135184009 | J38: 91894878 | K38: 13518401 | L38: 9189488 | M38: 560024 | N38: 0 | O38: 140006 | P38: 0 | Q38: 1310310 | R38: 0 | S38: 655155 | T38: 0 | U38: 3213261 | V38: 0 | W38: 3213261 | X38: 0 | Y38: =+W38+S38+O38+K38 -> 17526823 | Z38: =+X38+T38+P38+L38 -> 9189488 | AA38: =+'Aging Analysis'!C27 -> 535740133
B39: из них необеспеченные | C39: =E39+I39+M39+Q39+U39 -> 0 | D39: =F39+J39+N39+R39+V39 -> 0 | Y39: =+W39+S39+O39+K39 -> 0 | Z39: =+X39+T39+P39+L39 -> 0 | AA39: =+AA38-C38 -> 0
A40: 17 | B40: Строительство | C40: =E40+I40+M40+Q40+U40 -> 374350021 | D40: =F40+J40+N40+R40+V40 -> 19624650 | E40: 291994997 | F40: 19624650 | G40: 0 | H40: 0 | I40: 81509125 | J40: 0 | K40: 8650913 | L40: 0 | M40: 605658 | N40: 0 | O40: 151414 | P40: 0 | Q40: 0 | R40: 0 | S40: 0 | T40: 0 | U40: 240241 | V40: 0 | W40: 240241 | X40: 0 | Y40: =+W40+S40+O40+K40 -> 9042568 | Z40: =+X40+T40+P40+L40 -> 0 | AA40: =+'Aging Analysis'!C28 -> 374350021
B41: из них необеспеченные | C41: =E41+I41+M41+Q41+U41 -> 0 | D41: =F41+J41+N41+R41+V41 -> 0 | Y41: =+W41+S41+O41+K41 -> 0 | Z41: =+X41+T41+P41+L41 -> 0 | AA41: =+AA40-C40 -> 0
...

Sheet Loans to Affiliated P.
A1: ОТЧЕТ О СДЕЛКАХ, ЗАКЛЮЧЕННЫХ СО СВЯЗАННЫМИ ЛИЦАМИ | S1: Таблица-11
B3: =+'Asset quality'!B3 -> АКБ "Микрокредитбанк" | N3: =+'Asset quality'!P3 -> 44196 | S3: тыс. сум
A4: № | B4: Наименования клиента | C4: ИНН | D4: Вид деятельности | E4: Код валюты | F4: Номер группы | G4: Текущая задолженность | H4: из них | N4: Пересмотрения | O4: Обеспечения | Q4: Классификация | R4: Резерв | S4: Источник кредита
H5: Кредиты и лизинги | I5: Инвестиции | J5: Аккредитивы | K5: Гарантии | L5: Межбанковские кредиты и депозиты | M5: другие активы* | O5: Вид залога | P5: Сумма залога
B6: А | C6: Б | D6: В | E6: Г | F6: Д | G6: Е | H6: Е1 | I6: Е2 | J6: Е3 | K6: Е4 | L6: Е5 | M6: Е6 | N6: Ж | O6: З | P6: И | Q6: К | R6: Л | S6: М
A7: 1 | B7: Исматуллоев Акрам Акмалович | C7: AA5013105 | D7: Физические лица | E7: 000 | F7: 1 | G7: =SUM(H7:M7) -> 243460.56 | H7: 243460.56 | R7: 0 | S7: 11-Собственные
A8: 2 | B8: Гуччиев Илхом Турсункулович | C8: CT1907643 | D8: Физические лица | E8: 000 | F8: 2 | G8: =SUM(H8:M8) -> 0 | H8: 0 | R8: 0 | S8: 11-Собственные
A9: 3 | B9: Пулатова Муниса Тоировна | C9: AA1343647 | D9: Физические лица | E9: 000 | F9: 3 | G9: =SUM(H9:M9) -> 46095.409 | H9: 46095.409 | R9: 0 | S9: 11-Собственные
A10: 4 | B10: Умаров Сарвар Салахиддинович | C10: AB5528260 | D10: Физические лица | E10: 000 | F10: 4 | G10: =SUM(H10:M10) -> 48348.292 | H10: 48348.292 | R10: 0 | S10: 11-Собственные
A11: 5 | B11: Ахмаджонов Абдулазиз Абдусатторович | C11: AA1266275 | D11: Физические лица | E11: 000 | F11: 5 | G11: =SUM(H11:M11) -> 0 | H11: 0 | R11: 0 | S11: 11-Собственные
A12: 6 | B12: Тогаев Даврон Дусмамат уғли | C12: CT1881274 | D12: Физические лица | E12: 000 | F12: 6 | G12: =SUM(H12:M12) -> 34527.646 | H12: 34527.646 | R12: 0 | S12: 11-Собственные
A13: 7 | B13: Саматов Юнус Уралович | C13: CS0384112 | D13: Физические лица | E13: 000 | F13: 7 | G13: =SUM(H13:M13) -> 20913.278 | H13: 20913.278 | R13: 0 | S13: 11-Собственные
A14: 8 | B14: Каримкулов Хикматулло | C14: BG0108618 | D14: Физические лица | E14: 000 | F14: 8 | G14: =SUM(H14:M14) -> 16632.785 | H14: 16632.785 | R14: 0 | S14: 11-Собственные
A15: 9 | B15: Саксонов Азизбек Нурбобоевич | C15: CE2612031 | D15: Физические лица | E15: 000 | F15: 9 | G15: =SUM(H15:M15) -> 14826.673 | H15: 14826.673 | R15: 0 | S15: 11-Собственные
A16: 10 | B16: Бабаджанов Шухрат Адилбекович | C16: AA1901433 | D16: Физические лица | E16: 000 | F16: 10 | G16: =SUM(H16:M16) -> 20124.334 | H16: 20124.334 | R16: 0 | S16: 11-Собственные
A17: 11 | B17: Бегматов Бобур Яхшиевич | C17: CN2398457 | D17: Физические лица | E17: 000 | F17: 11 | G17: =SUM(H17:M17) -> 10073.722 | H17: 10073.722 | R17: 0 | S17: 11-Собственные
A18: 12 | B18: Муминов Юсуп Машарипович | C18: CE2162465 | D18: Физические лица | E18: 000 | F18: 12 | G18: =SUM(H18:M18) -> 7080 | H18: 7080 | R18: 0 | S18: 11-Собственные
... A31: 25 | B31: Эрдонаев Олим Тожиевич | C31: CS1661937 | D31: Физические лица | E31: 000 | F31: 30 | G31: =SUM(H31:M31) -> 19320.954 | H31: 19320.954 | R31: 0 | S31: 11-Собственные
A32: 26 | B32: OCHILOV SARVAR NURMANOVICH | C32: AA1176596 | D32: Физические лица | E32: 000 | F32: 65 | G32: 1000 | H32: 0 | R32: 0 | S32: 11-Собственные
A33: 27 | B33: Кушназаров Акбар Нарханович | C33: AA1814951 | D33: Физические лица | E33: 000 | F33: 32 | G33: =SUM(H33:M33) -> 28460.47 | H33: 28460.47 | R33: 0 | S33: 11-Собственные
A34: 28 | B34: Mamarakhimov Abror Xaldarovich | C34: AA1545194 | D34: Физические лица | E34: 000 | F34: 34 | G34: =SUM(H34:M34) -> 26125 | H34: 26125 | R34: 0 | S34: 11-Собственные
A35: 29 | B35: KHOLOV TAKHIR SADULLAYEVICH | C35: AA1598158 | D35: Физические лица | E35: 000 | F35: 35 | G35: =SUM(H35:M35) -> 200445.8 | H35: 200445.8 | R35: 0 | S35: 11-Собственные
A36: 30 | B36: ARAMOV RASHID RAVSHANOVICH | C36: AA1574588 | D36: Физические лица | E36: 000 | F36: 36 | G36: =SUM(H36:M36) -> 105680.96 | H36: 105680.96 | R36: 0 | S36: 11-Собственные
A37: 31 | B37: SOLIEV SARDORBEK XOLMIRZAYEVICH | C37: AA1507783 | D37: Физические лица | E37: 000 | F37: 37 | G37: =SUM(H37:M37) -> 110377.89 | H37: 110377.89 | R37: 0 | S37: 11-Собственные
A38: 32 | B38: SIDDIKOV SHOKHRUKH IBRAGIMJONOVICH | C38: AA0281567 | D38: Физические лица | E38: 000 | F38: 38 | G38: =SUM(H38:M38) -> 117000.57 | H38: 117000.57 | R38: 0 | S38: 11-Собственные
A39: 33 | B39: JURAYEV ZARIPJAN YULDASHEVICH | C39: AA0727084 | D39: Физические лица | E39: 000 | F39: 39 | G39: =SUM(H39:M39) -> 0 | H39: 0 | R39: 0 | S39: 11-Собственные
A40: 34 | B40: OMONOV OTAJON JURAQULOVICH | C40: AA8332674 | D40: Физические лица | E40: 000 | F40: 40 | G40: =SUM(H40:M40) -> 106001.82 | H40: 106001.82 | R40: 0 | S40: 11-Собственные
A41: 35 | B41: Пардаев Эшдавлат Абдумуминович | C41: CS0139454 | D41: Физические лица | E41: 000 | F41: 63 | G41: 826929.28 | H41: 80266.109 | R41: 0 | S41: 11-Собственные
A42: 36 | B42: ISKANOV ILKHOMJON XOLDOROVICH | C42: AA1086982 | D42: Физические лица | E42: 000 | F42: 42 | G42: =SUM(H42:M42) -> 15978 | H42: 15978 | R42: 0 | S42: 11-Собственные
A43: 37 | B43: MUQIMOV AZAMAT SAIDOVICH | C43: AA0093700 | D43: Физические лица | E43: 000 | F43: 43 | G43: =SUM(H43:M43) -> 4052.7821 | H43: 4052.7821 | R43: 0 | S43: 11-Собственные
A44: 38 | B44: BESHIMOV AZAMAT XAMROBOYEVICH | C44: AB9725681 | D44: Физические лица | E44: 000 | F44: 45 | G44: =SUM(H44:M44) -> 107994.24 | H44: 107994.24 | R44: 0 | S44: 11-Собственные
A45: 39 | B45: NARZULLAYEV YAKUB BOBOMURODOVICH | C45: AB9773826 | D45: Физические лица | E45: 000 | F45: 46 | G45: =SUM(H45:M45) -> 2000.0794 | H45: 2000.0794 | R45: 0 | S45: 11-Собственные
A46: 40 | B46: TOPILOV SHERZOD SAIDKARIMOVICH | C46: AA1771771 | D46: Физические лица | E46: 000 | F46: 47 | G46: =SUM(H46:M46) -> 1903.9384 | H46: 1903.9384 | R46: 0 | S46: 11-Собственные
A47: 41 | B47: AZLAROV ABDULLA ABDULXAYEVICH | C47: AB0145415 | D47: Физические лица | E47: 000 | F47: 48 | G47: =SUM(H47:M47) -> 98193.866 | H47: 98193.866 | R47: 0 | S47: 11-Собственные
A48: 42 | B48: MADUMAROV XUSNIDDIN KOMILOVICH | C48: AA0620069 | D48: Физические лица | E48: 000 | F48: 49 | G48: =SUM(H48:M48) -> 104123.76 | H48: 104123.76 | R48: 0 | S48: 11-Собственные
A49: 43 | B49: ESHMATOV MASRUR QURBONOVICH | C49: AA1344338 | D49: Физические лица | E49: 000 | F49: 50 | G49: =SUM(H49:M49) -> 9971.3918 | H49: 9971.3918 | R49: 0 | S49: 11-Собственные
A50: 44 | B50: TAYLAKOV ISMOIL RAMIZOVICH | C50: AA4589423 | D50: Физические лица | E50: 000 | F50: 51 | G50: =SUM(H50:M50) -> 4054.5336 | H50: 4054.5336 | R50: 0 | S50: 11-Собственные
A51: 45 | B51: MIRZAEV BAKHODIR XUSANOVICH | C51: AA6739140 | D51: Физические лица | E51: 000 | F51: 52 | G51: =SUM(H51:M51) -> 89852.353 | H51: 89852.353 | R51: 0 | S51: 11-Собственные
A52: 46 | B52: JUMAYEV NURALI ISOXONOVICH | C52: AA1395310 | D52: Физические лица | E52: 000 | F52: 53 | G52: =SUM(H52:M52) -> 99999.155 | H52: 99999.155 | R52: 0 | S52: 11-Собственные
A53: 47 | B53: OTAQOZIYEV ABRORJON ABDULLAYEVICH | C53: AB6494562 | D53: Физические лица | E53: 000 | F53: 54 | G53: =SUM(H53:M53) -> 113987.83 | H53: 113987.83 | R53: 0 | S53: 11-Собственные
...

Sheet  Largest risk
A1: ОТЧЕТ О КРУПНЫХ РИСКАХ | S1: Таблица-12
B3: =+'Asset quality'!B3 -> АКБ "Микрокредитбанк" | N3: =+'Asset quality'!P3 -> 44196 | O3: =+#REF! -> #REF! | S3: тыс. сум
A4: № | B4: Наименования клиента | C4: ИНН | D4: Вид деятельности | E4: Код валюты | F4: Номер группы | G4: Текущая задолженность | H4: из них | N4: Пересмотрения | O4: Обеспечения | Q4: Классификация | R4: Резерв | S4: Источник кредита
H5: Кредиты и лизинги | I5: Инвестиции | J5: Аккредитивы | K5: Гарантии | L5: Межбанковские кредиты и депозиты | M5: другие активы* | O5: Вид залога | P5: Сумма залога
B6: А | C6: Б | D6: В | E6: Г | F6: Д | G6: Е | H6: Е1 | I6: Е2 | J6: Е3 | K6: Е4 | L6: Е5 | M6: Е6 | N6: Ж | O6: З | P6: И | Q6: К | R6: Л | S6: М
A7: 1 | B7: ИП ООО "EPSILON DEVELOPMENT COMPANY" | C7: 305922787 | D7: нефт | E7: 840 | F7: 2 | G7: =+H7+M7 -> 372356820 | H7: 369646200 | M7: 2710620 | U7: 0
A8: 2 | B8: ООО "SESAME" | C8: 306892604 | D8: нефт | E8: 840 | F8: 1 | G8: =+H8+M8 -> 460153398 | H8: 456822406 | M8: 3330992
A9: 3 | G9: =SUM(H9:M9) -> 0
A10: 4 | G10: 0
A11: 5 | G11: =SUM(H11:M11) -> 0
A12: 6 | G12: =SUM(H12:M12) -> 0
A13: 7 | G13: =SUM(H13:M13) -> 0
A14: 8 | G14: =SUM(H14:M14) -> 0
A15: 9 | G15: =SUM(H15:M15) -> 0
A16: 10 | G16: =SUM(H16:M16) -> 0
A17: 11 | G17: =SUM(H17:M17) -> 0
A18: 12 | G18: =SUM(H18:M18) -> 0
A19: 13 | G19: =SUM(H19:M19) -> 0
A20: 14 | G20: =SUM(H20:M20) -> 0
A21: 15 | G21: =SUM(H21:M21) -> 0
A22: 16 | G22: =SUM(H22:M22) -> 0
... A66: 60 | G66: =SUM(H66:M66) -> 0
B67: ИТОГО КРУПНЫХ АКТИВОВ | G67: =SUM(G7:G66) -> 832510218 | H67: =SUM(H7:H66) -> 826468606 | I67: =SUM(I7:I66) -> 0 | J67: =SUM(J7:J66) -> 0 | K67: =SUM(K7:K66) -> 0 | L67: =SUM(L7:L66) -> 0 | M67: =SUM(M7:M66) -> 6041612 | P67: =SUM(P7:P66) -> 0
